File: Rubber Stress Relaxation Raw Data - Small Samples-20210211/Specimen_RawData_2.csv
Specimen properties : Specimen label,"GAI2S1R2"
Specimen properties : Anvil height,"5.90000",mm
Specimen properties : Diameter,"5.46000",mm
Test : Rate 1,"2.40000",mm/min
Test : Start of hold value,"20.00000",%
Test : Duration,"120.00000",s

Extension,Load,Compressive stress,Time,PIP count,Compressive extension,Compressive strain (Extension)
(mm),(N),(MPa),(s),,(mm),(mm/mm)
"0.00063","0.02075","0.00089","0.00000","0.00000","0.00063","0.00011"
"0.00313","0.15827","0.00676","0.22000","0.00000","0.00313","0.00053"
"0.01396","0.81113","0.03464","0.44000","0.00000","0.01396","0.00237"
"0.02583","1.38419","0.05912","0.66000","0.00000","0.02583","0.00438"
"0.03542","1.75008","0.07474","0.88000","0.00000","0.03542","0.00600"
"0.04396","2.04329","0.08727","1.10000","0.00000","0.04396","0.00745"
"0.05292","2.33818","0.09986","1.32000","0.00000","0.05292","0.00897"
"0.06208","2.63005","0.11233","1.54000","0.00000","0.06208","0.01052"
"0.07104","2.91751","0.12461","1.76000","0.00000","0.07104","0.01204"
"0.07979","3.15259","0.13465","1.98000","0.00000","0.07979","0.01352"
"0.08813","3.39458","0.14498","2.20000","0.00000","0.08813","0.01494"
"0.09708","3.65822","0.15624","2.42000","0.00000","0.09708","0.01645"
"0.10604","3.90935","0.16697","2.64000","0.00000","0.10604","0.01797"
"0.11500","4.15821","0.17760","2.86000","0.00000","0.11500","0.01949"
"0.12333","4.37731","0.18695","3.08000","0.00000","0.12333","0.02090"
"0.13208","4.61323","0.19703","3.30000","0.00000","0.13208","0.02239"
"0.14104","4.87205","0.20808","3.52000","0.00000","0.14104","0.02391"
"0.14979","5.09614","0.21765","3.74000","0.00000","0.14979","0.02539"
"0.15896","5.35354","0.22865","3.96000","0.00000","0.15896","0.02694"
"0.16771","5.57783","0.23823","4.18000","0.00000","0.16771","0.02843"
"0.17625","5.81173","0.24822","4.40000","0.00000","0.17625","0.02987"
"0.18521","6.04726","0.25828","4.62000","0.00000","0.18521","0.03139"
"0.19417","6.28081","0.26825","4.84000","0.00000","0.19417","0.03291"
"0.20292","6.50574","0.27786","5.06000","0.00000","0.20292","0.03439"
"0.21146","6.71263","0.28669","5.28000","0.00000","0.21146","0.03584"
"0.22021","6.95359","0.29698","5.50000","0.00000","0.22021","0.03732"
"0.22917","7.18444","0.30684","5.72000","0.00000","0.22917","0.03884"
"0.23813","7.41157","0.31654","5.94000","0.00000","0.23813","0.04036"
"0.24688","7.63742","0.32619","6.16000","0.00000","0.24688","0.04184"
"0.25563","7.85630","0.33554","6.38000","0.00000","0.25563","0.04333"
"0.26438","8.08975","0.34551","6.60000","0.00000","0.26438","0.04481"
"0.27313","8.31794","0.35526","6.82000","0.00000","0.27313","0.04629"
"0.28208","8.53623","0.36458","7.04000","0.00000","0.28208","0.04781"
"0.29083","8.74158","0.37335","7.26000","0.00000","0.29083","0.04929"
"0.29979","8.97461","0.38330","7.48000","0.00000","0.29979","0.05081"
"0.30854","9.20459","0.39312","7.70000","0.00000","0.30854","0.05230"
"0.31729","9.41266","0.40201","7.92000","0.00000","0.31729","0.05378"
"0.32604","9.63631","0.41156","8.14000","0.00000","0.32604","0.05526"
"0.33500","9.86491","0.42133","8.36000","0.00000","0.33500","0.05678"
"0.34354","10.08334","0.43065","8.58000","0.00000","0.34354","0.05823"
"0.35229","10.30963","0.44032","8.80000","0.00000","0.35229","0.05971"
"0.36104","10.51153","0.44894","9.02000","0.00000","0.36104","0.06119"
"0.37000","10.74416","0.45888","9.24000","0.00000","0.37000","0.06271"
"0.37875","10.96916","0.46849","9.46000","0.00000","0.37875","0.06419"
"0.38729","11.16670","0.47692","9.68000","0.00000","0.38729","0.06564"
"0.39625","11.41330","0.48746","9.90000","0.00000","0.39625","0.06716"
"0.40521","11.62606","0.49654","10.12000","0.00000","0.40521","0.06868"
"0.41417","11.87271","0.50708","10.34000","0.00000","0.41417","0.07020"
"0.42292","12.09196","0.51644","10.56000","0.00000","0.42292","0.07168"
"0.43167","12.29853","0.52526","10.78000","0.00000","0.43167","0.07316"
"0.44021","12.50471","0.53407","11.00000","0.00000","0.44021","0.07461"
"0.44896","12.74910","0.54451","11.22000","0.00000","0.44896","0.07609"
"0.45813","12.98586","0.55462","11.44000","0.00000","0.45812","0.07765"
"0.46667","13.19815","0.56369","11.66000","0.00000","0.46667","0.07910"
"0.47542","13.42008","0.57317","11.88000","0.00000","0.47542","0.08058"
"0.48417","13.65007","0.58299","12.10000","0.00000","0.48417","0.08206"
"0.49354","13.91436","0.59428","12.32000","0.00000","0.49354","0.08365"
"0.50208","14.09281","0.60190","12.54000","0.00000","0.50208","0.08510"
"0.51083","14.31296","0.61130","12.76000","0.00000","0.51083","0.08658"
"0.51938","14.53721","0.62088","12.98000","0.00000","0.51938","0.08803"
"0.52833","14.78226","0.63134","13.20000","0.00000","0.52833","0.08955"
"0.53729","15.02160","0.64157","13.42000","0.00000","0.53729","0.09107"
"0.54583","15.21884","0.64999","13.64000","0.00000","0.54583","0.09251"
"0.55458","15.45356","0.66001","13.86000","0.00000","0.55458","0.09400"
"0.56333","15.68419","0.66986","14.08000","0.00000","0.56333","0.09548"
"0.57250","15.94152","0.68085","14.30000","0.00000","0.57250","0.09703"
"0.58146","16.17292","0.69074","14.52000","0.00000","0.58146","0.09855"
"0.58979","16.37654","0.69943","14.74000","0.00000","0.58979","0.09996"
"0.59833","16.60181","0.70906","14.96000","0.00000","0.59833","0.10141"
"0.60750","16.84911","0.71962","15.18000","0.00000","0.60750","0.10297"
"0.61667","17.11442","0.73095","15.40000","0.00000","0.61667","0.10452"
"0.62521","17.32508","0.73995","15.62000","0.00000","0.62521","0.10597"
"0.63396","17.55823","0.74990","15.84000","0.00000","0.63396","0.10745"
"0.64250","17.77575","0.75919","16.06000","0.00000","0.64250","0.10890"
"0.65167","18.04144","0.77054","16.28000","0.00000","0.65167","0.11045"
"0.66063","18.29110","0.78120","16.50000","0.00000","0.66063","0.11197"
"0.66917","18.49853","0.79006","16.72000","0.00000","0.66917","0.11342"
"0.67771","18.73858","0.80032","16.94000","0.00000","0.67771","0.11487"
"0.68667","18.98737","0.81094","17.16000","0.00000","0.68667","0.11638"
"0.69583","19.27145","0.82307","17.38000","0.00000","0.69583","0.11794"
"0.70479","19.50074","0.83287","17.60000","0.00000","0.70479","0.11946"
"0.71333","19.72159","0.84230","17.82000","0.00000","0.71333","0.12090"
"0.72167","19.95001","0.85206","18.04000","0.00000","0.72167","0.12232"
"0.73063","20.22181","0.86366","18.26000","0.00000","0.73063","0.12383"
"0.73979","20.45849","0.87377","18.48000","0.00000","0.73979","0.12539"
"0.74854","20.70735","0.88440","18.70000","0.00000","0.74854","0.12687"
"0.75688","20.93448","0.89410","18.92000","0.00000","0.75688","0.12828"
"0.76563","21.19867","0.90539","19.14000","0.00000","0.76563","0.12977"
"0.77479","21.47669","0.91726","19.36000","0.00000","0.77479","0.13132"
"0.78396","21.74518","0.92873","19.58000","0.00000","0.78396","0.13287"
"0.79229","21.95506","0.93769","19.80000","0.00000","0.79229","0.13429"
"0.80083","22.21459","0.94877","20.02000","0.00000","0.80083","0.13573"
"0.80979","22.49040","0.96055","20.24000","0.00000","0.80979","0.13725"
"0.81896","22.75498","0.97185","20.46000","0.00000","0.81896","0.13881"
"0.82792","23.01478","0.98295","20.68000","0.00000","0.82792","0.14032"
"0.83625","23.21991","0.99171","20.90000","0.00000","0.83625","0.14174"
"0.84500","23.48302","1.00295","21.12000","0.00000","0.84500","0.14322"
"0.85396","23.75588","1.01460","21.34000","0.00000","0.85396","0.14474"
"0.86292","24.01826","1.02581","21.56000","0.00000","0.86292","0.14626"
"0.87167","24.26951","1.03654","21.78000","0.00000","0.87167","0.14774"
"0.88000","24.50335","1.04653","22.00000","0.00000","0.88000","0.14915"
"0.88896","24.78692","1.05864","22.22000","0.00000","0.88896","0.15067"
"0.89812","25.07890","1.07111","22.44000","0.00000","0.89812","0.15222"
"0.90729","25.35330","1.08283","22.66000","0.00000","0.90729","0.15378"
"0.91563","25.57534","1.09231","22.88000","0.00000","0.91562","0.15519"
"0.92417","25.85590","1.10429","23.10000","0.00000","0.92417","0.15664"
"0.93313","26.16077","1.11731","23.32000","0.00000","0.93313","0.15816"
"0.94208","26.45205","1.12976","23.54000","0.00000","0.94208","0.15968"
"0.95104","26.71251","1.14088","23.76000","0.00000","0.95104","0.16119"
"0.95938","26.95544","1.15125","23.98000","0.00000","0.95937","0.16261"
"0.96812","27.25596","1.16409","24.20000","0.00000","0.96812","0.16409"
"0.97708","27.55480","1.17685","24.42000","0.00000","0.97708","0.16561"
"0.98583","27.83589","1.18886","24.64000","0.00000","0.98583","0.16709"
"0.99479","28.12123","1.20104","24.86000","0.00000","0.99479","0.16861"
"1.00333","28.36615","1.21150","25.08000","0.00000","1.00333","0.17006"
"1.01229","28.69604","1.22559","25.30000","0.00000","1.01229","0.17157"
"1.02125","29.00891","1.23896","25.52000","0.00000","1.02125","0.17309"
"1.03021","29.30383","1.25155","25.74000","0.00000","1.03021","0.17461"
"1.03896","29.56161","1.26256","25.96000","0.00000","1.03896","0.17609"
"1.04750","29.87480","1.27594","26.18000","0.00000","1.04750","0.17754"
"1.05646","30.19197","1.28948","26.40000","0.00000","1.05646","0.17906"
"1.06521","30.45971","1.30092","26.62000","0.00000","1.06521","0.18054"
"1.07417","30.76361","1.31390","26.84000","0.00000","1.07417","0.18206"
"1.08292","31.07209","1.32707","27.06000","0.00000","1.08292","0.18355"
"1.09167","31.39779","1.34098","27.28000","0.00000","1.09167","0.18503"
"1.10042","31.68835","1.35339","27.50000","0.00000","1.10042","0.18651"
"1.10938","31.99996","1.36670","27.72000","0.00000","1.10938","0.18803"
"1.11813","32.30265","1.37963","27.94000","0.00000","1.11813","0.18951"
"1.12688","32.64016","1.39405","28.16000","0.00000","1.12688","0.19100"
"1.13583","32.95611","1.40754","28.38000","0.00000","1.13583","0.19251"
"1.14458","33.24331","1.41981","28.60000","0.00000","1.14458","0.19400"
"1.15313","33.57226","1.43386","28.82000","0.00000","1.15313","0.19544"
"1.16208","33.90798","1.44819","29.04000","0.00000","1.16208","0.19696"
"1.17083","34.22125","1.46157","29.26000","0.00000","1.17083","0.19845"
"1.17958","34.57367","1.47663","29.48000","0.00000","1.17958","0.19993"
"1.18167","34.16327","1.45910","29.68400","0.00000","1.18167","0.20028"
"1.18167","33.65174","1.43725","29.90400","0.00000","1.18167","0.20028"
"1.18167","33.28641","1.42165","30.12400","0.00000","1.18167","0.20028"
"1.18167","33.00912","1.40980","30.34400","0.00000","1.18167","0.20028"
"1.18125","32.77745","1.39991","30.56400","0.00000","1.18125","0.20021"
"1.18125","32.57198","1.39113","30.78400","0.00000","1.18125","0.20021"
"1.18104","32.38940","1.38334","31.00400","0.00000","1.18104","0.20018"
"1.18104","32.23317","1.37666","31.22400","0.00000","1.18104","0.20018"
"1.18083","32.08117","1.37017","31.44400","0.00000","1.18083","0.20014"
"1.18083","31.94164","1.36421","31.66400","0.00000","1.18083","0.20014"
"1.18063","31.82343","1.35916","31.88400","0.00000","1.18063","0.20011"
"1.18063","31.70500","1.35411","32.10400","0.00000","1.18063","0.20011"
"1.18042","31.58203","1.34885","32.32400","0.00000","1.18042","0.20007"
"1.18042","31.50557","1.34559","32.54400","0.00000","1.18042","0.20007"
"1.18042","31.41208","1.34160","32.76400","0.00000","1.18042","0.20007"
"1.18042","31.32216","1.33776","32.98400","0.00000","1.18042","0.20007"
"1.18042","31.25168","1.33474","33.20400","0.00000","1.18042","0.20007"
"1.18042","31.17764","1.33158","33.42400","0.00000","1.18042","0.20007"
"1.18042","31.11162","1.32876","33.64400","0.00000","1.18042","0.20007"
"1.18042","31.04261","1.32582","33.86400","0.00000","1.18042","0.20007"
"1.18042","30.98008","1.32314","34.08400","0.00000","1.18042","0.20007"
"1.18042","30.90611","1.31999","34.30400","0.00000","1.18042","0.20007"
"1.18042","30.84894","1.31754","34.52400","0.00000","1.18042","0.20007"
"1.18042","30.77941","1.31457","34.74400","0.00000","1.18042","0.20007"
"1.18042","30.72674","1.31233","34.96400","0.00000","1.18042","0.20007"
"1.18042","30.68022","1.31034","35.18400","0.00000","1.18042","0.20007"
"1.18042","30.61551","1.30757","35.40400","0.00000","1.18042","0.20007"
"1.18042","30.57314","1.30576","35.62400","0.00000","1.18042","0.20007"
"1.18042","30.52405","1.30367","35.84400","0.00000","1.18042","0.20007"
"1.18042","30.45335","1.30065","36.06400","0.00000","1.18042","0.20007"
"1.18042","30.42026","1.29924","36.28400","0.00000","1.18042","0.20007"
"1.18042","30.38233","1.29762","36.50400","0.00000","1.18042","0.20007"
"1.18042","30.32862","1.29532","36.72400","0.00000","1.18042","0.20007"
"1.18042","30.29046","1.29369","36.94400","0.00000","1.18042","0.20007"
"1.18042","30.24228","1.29163","37.16400","0.00000","1.18042","0.20007"
"1.18042","30.20992","1.29025","37.38400","0.00000","1.18042","0.20007"
"1.18042","30.16342","1.28827","37.60400","0.00000","1.18042","0.20007"
"1.18042","30.12345","1.28656","37.82400","0.00000","1.18042","0.20007"
"1.18042","30.09377","1.28529","38.04400","0.00000","1.18042","0.20007"
"1.18042","30.04328","1.28313","38.26400","0.00000","1.18042","0.20007"
"1.18042","30.01273","1.28183","38.48400","0.00000","1.18042","0.20007"
"1.18042","29.97640","1.28028","38.70400","0.00000","1.18042","0.20007"
"1.18042","29.93632","1.27857","38.92400","0.00000","1.18042","0.20007"
"1.18042","29.91274","1.27756","39.14400","0.00000","1.18042","0.20007"
"1.18042","29.87621","1.27600","39.36400","0.00000","1.18042","0.20007"
"1.18042","29.82775","1.27393","39.58400","0.00000","1.18042","0.20007"
"1.18042","29.81142","1.27323","39.80400","0.00000","1.18042","0.20007"
"1.18042","29.77822","1.27181","40.02400","0.00000","1.18042","0.20007"
"1.18042","29.75518","1.27083","40.24400","0.00000","1.18042","0.20007"
"1.18042","29.71879","1.26928","40.46400","0.00000","1.18042","0.20007"
"1.18042","29.68353","1.26777","40.68400","0.00000","1.18042","0.20007"
"1.18042","29.67639","1.26746","40.90400","0.00000","1.18042","0.20007"
"1.18042","29.63336","1.26563","41.12400","0.00000","1.18042","0.20007"
"1.18042","29.60627","1.26447","41.34400","0.00000","1.18042","0.20007"
"1.18042","29.56939","1.26289","41.56400","0.00000","1.18042","0.20007"
"1.18042","29.54465","1.26184","41.78400","0.00000","1.18042","0.20007"
"1.18042","29.54373","1.26180","42.00400","0.00000","1.18042","0.20007"
"1.18042","29.49595","1.25976","42.22400","0.00000","1.18042","0.20007"
"1.18042","29.45584","1.25805","42.44400","0.00000","1.18042","0.20007"
"1.18042","29.44522","1.25759","42.66400","0.00000","1.18042","0.20007"
"1.18042","29.42702","1.25681","42.88400","0.00000","1.18042","0.20007"
"1.18042","29.39749","1.25555","43.10400","0.00000","1.18042","0.20007"
"1.18042","29.36570","1.25420","43.32400","0.00000","1.18042","0.20007"
"1.18042","29.34165","1.25317","43.54400","0.00000","1.18042","0.20007"
"1.18042","29.32668","1.25253","43.76400","0.00000","1.18042","0.20007"
"1.18042","29.29660","1.25124","43.98400","0.00000","1.18042","0.20007"
"1.18042","29.26471","1.24988","44.20400","0.00000","1.18042","0.20007"
"1.18042","29.25959","1.24966","44.42400","0.00000","1.18042","0.20007"
"1.18042","29.22663","1.24826","44.64400","0.00000","1.18042","0.20007"
"1.18042","29.20700","1.24742","44.86400","0.00000","1.18042","0.20007"
"1.18042","29.19042","1.24671","45.08400","0.00000","1.18042","0.20007"
"1.18042","29.15651","1.24526","45.30400","0.00000","1.18042","0.20007"
"1.18042","29.14097","1.24460","45.52400","0.00000","1.18042","0.20007"
"1.18042","29.13135","1.24419","45.74400","0.00000","1.18042","0.20007"
"1.18042","29.10127","1.24290","45.96400","0.00000","1.18042","0.20007"
"1.18042","29.08129","1.24205","46.18400","0.00000","1.18042","0.20007"
"1.18042","29.06877","1.24151","46.40400","0.00000","1.18042","0.20007"
"1.18042","29.03876","1.24023","46.62400","0.00000","1.18042","0.20007"
"1.18042","29.01844","1.23936","46.84400","0.00000","1.18042","0.20007"
"1.18042","29.00332","1.23872","47.06400","0.00000","1.18042","0.20007"
"1.18042","28.98345","1.23787","47.28400","0.00000","1.18042","0.20007"
"1.18042","28.96877","1.23724","47.50400","0.00000","1.18042","0.20007"
"1.18042","28.94586","1.23626","47.72400","0.00000","1.18042","0.20007"
"1.18042","28.93011","1.23559","47.94400","0.00000","1.18042","0.20007"
"1.18042","28.91647","1.23501","48.16400","0.00000","1.18042","0.20007"
"1.18042","28.89389","1.23404","48.38400","0.00000","1.18042","0.20007"
"1.18042","28.87663","1.23331","48.60400","0.00000","1.18042","0.20007"
"1.18042","28.85698","1.23247","48.82400","0.00000","1.18042","0.20007"
"1.18042","28.83768","1.23164","49.04400","0.00000","1.18042","0.20007"
"1.18042","28.82388","1.23105","49.26400","0.00000","1.18042","0.20007"
"1.18042","28.81679","1.23075","49.48400","0.00000","1.18042","0.20007"
"1.18042","28.78605","1.22944","49.70400","0.00000","1.18042","0.20007"
"1.18042","28.77591","1.22901","49.92400","0.00000","1.18042","0.20007"
"1.18042","28.75575","1.22814","50.14400","0.00000","1.18042","0.20007"
"1.18042","28.74517","1.22769","50.36400","0.00000","1.18042","0.20007"
"1.18042","28.72907","1.22701","50.58400","0.00000","1.18042","0.20007"
"1.18042","28.71035","1.22621","50.80400","0.00000","1.18042","0.20007"
"1.18042","28.69122","1.22539","51.02400","0.00000","1.18042","0.20007"
"1.18042","28.67679","1.22477","51.24400","0.00000","1.18042","0.20007"
"1.18042","28.66757","1.22438","51.46400","0.00000","1.18042","0.20007"
"1.18042","28.65289","1.22375","51.68400","0.00000","1.18042","0.20007"
"1.18042","28.62784","1.22268","51.90400","0.00000","1.18042","0.20007"
"1.18042","28.62133","1.22240","52.12400","0.00000","1.18042","0.20007"
"1.18042","28.59838","1.22142","52.34400","0.00000","1.18042","0.20007"
"1.18042","28.58316","1.22077","52.56400","0.00000","1.18042","0.20007"
"1.18042","28.57333","1.22035","52.78400","0.00000","1.18042","0.20007"
"1.18042","28.55713","1.21966","53.00400","0.00000","1.18042","0.20007"
"1.18042","28.54058","1.21896","53.22400","0.00000","1.18042","0.20007"
"1.18042","28.53095","1.21854","53.44400","0.00000","1.18042","0.20007"
"1.18042","28.51811","1.21800","53.66400","0.00000","1.18042","0.20007"
"1.18042","28.50222","1.21732","53.88400","0.00000","1.18042","0.20007"
"1.18042","28.49185","1.21687","54.10400","0.00000","1.18042","0.20007"
"1.18042","28.47580","1.21619","54.32400","0.00000","1.18042","0.20007"
"1.18042","28.46414","1.21569","54.54400","0.00000","1.18042","0.20007"
"1.18042","28.45142","1.21515","54.76400","0.00000","1.18042","0.20007"
"1.18042","28.43789","1.21457","54.98400","0.00000","1.18042","0.20007"
"1.18042","28.42145","1.21387","55.20400","0.00000","1.18042","0.20007"
"1.18042","28.41060","1.21340","55.42400","0.00000","1.18042","0.20007"
"1.18042","28.39632","1.21279","55.64400","0.00000","1.18042","0.20007"
"1.18042","28.38797","1.21244","55.86400","0.00000","1.18042","0.20007"
"1.18042","28.36772","1.21157","56.08400","0.00000","1.18042","0.20007"
"1.18042","28.35608","1.21108","56.30400","0.00000","1.18042","0.20007"
"1.18042","28.33887","1.21034","56.52400","0.00000","1.18042","0.20007"
"1.18042","28.32822","1.20989","56.74400","0.00000","1.18042","0.20007"
"1.18042","28.32204","1.20962","56.96400","0.00000","1.18042","0.20007"
"1.18042","28.30811","1.20903","57.18400","0.00000","1.18042","0.20007"
"1.18042","28.28946","1.20823","57.40400","0.00000","1.18042","0.20007"
"1.18042","28.27841","1.20776","57.62400","0.00000","1.18042","0.20007"
"1.18042","28.26507","1.20719","57.84400","0.00000","1.18042","0.20007"
"1.18042","28.25354","1.20670","58.06400","0.00000","1.18042","0.20007"
"1.18042","28.25679","1.20683","58.28400","0.00000","1.18042","0.20007"
"1.18042","28.23978","1.20611","58.50400","0.00000","1.18042","0.20007"
"1.18042","28.21919","1.20523","58.72400","0.00000","1.18042","0.20007"
"1.18042","28.21537","1.20507","58.94400","0.00000","1.18042","0.20007"
"1.18042","28.20141","1.20447","59.16400","0.00000","1.18042","0.20007"
"1.18042","28.19508","1.20420","59.38400","0.00000","1.18042","0.20007"
"1.18042","28.18644","1.20383","59.60400","0.00000","1.18042","0.20007"
"1.18042","28.16929","1.20310","59.82400","0.00000","1.18042","0.20007"
"1.18042","28.15386","1.20244","60.04400","0.00000","1.18042","0.20007"
"1.18042","28.14481","1.20205","60.26400","0.00000","1.18042","0.20007"
"1.18042","28.13233","1.20152","60.48400","0.00000","1.18042","0.20007"
"1.18042","28.12378","1.20115","60.70400","0.00000","1.18042","0.20007"
"1.18042","28.11294","1.20069","60.92400","0.00000","1.18042","0.20007"
"1.18042","28.10788","1.20047","61.14400","0.00000","1.18042","0.20007"
"1.18042","28.09433","1.19990","61.36400","0.00000","1.18042","0.20007"
"1.18042","28.07940","1.19926","61.58400","0.00000","1.18042","0.20007"
"1.18042","28.06353","1.19858","61.80400","0.00000","1.18042","0.20007"
"1.18042","28.05394","1.19817","62.02400","0.00000","1.18042","0.20007"
"1.18042","28.04518","1.19780","62.24400","0.00000","1.18042","0.20007"
"1.18042","28.03844","1.19751","62.46400","0.00000","1.18042","0.20007"
"1.18042","28.02936","1.19712","62.68400","0.00000","1.18042","0.20007"
"1.18042","28.01482","1.19650","62.90400","0.00000","1.18042","0.20007"
"1.18042","28.00510","1.19608","63.12400","0.00000","1.18042","0.20007"
"1.18042","28.00035","1.19588","63.34400","0.00000","1.18042","0.20007"
"1.18042","27.98825","1.19537","63.56400","0.00000","1.18042","0.20007"
"1.18042","27.97989","1.19501","63.78400","0.00000","1.18042","0.20007"
"1.18042","27.96534","1.19439","64.00400","0.00000","1.18042","0.20007"
"1.18042","27.96241","1.19426","64.22400","0.00000","1.18042","0.20007"
"1.18042","27.94546","1.19354","64.44400","0.00000","1.18042","0.20007"
"1.18042","27.93431","1.19306","64.66400","0.00000","1.18042","0.20007"
"1.18042","27.93053","1.19290","64.88400","0.00000","1.18042","0.20007"
"1.18042","27.92311","1.19258","65.10400","0.00000","1.18042","0.20007"
"1.18042","27.92629","1.19272","65.32400","0.00000","1.18042","0.20007"
"1.18042","27.91202","1.19211","65.54400","0.00000","1.18042","0.20007"
"1.18042","27.89789","1.19151","65.76400","0.00000","1.18042","0.20007"
"1.18042","27.88125","1.19080","65.98400","0.00000","1.18042","0.20007"
"1.18042","27.86815","1.19024","66.20400","0.00000","1.18042","0.20007"
"1.18042","27.86625","1.19015","66.42400","0.00000","1.18042","0.20007"
"1.18042","27.86188","1.18997","66.64400","0.00000","1.18042","0.20007"
"1.18042","27.85498","1.18967","66.86400","0.00000","1.18042","0.20007"
"1.18042","27.83847","1.18897","67.08400","0.00000","1.18042","0.20007"
"1.18042","27.83144","1.18867","67.30400","0.00000","1.18042","0.20007"
"1.18042","27.81967","1.18817","67.52400","0.00000","1.18042","0.20007"
"1.18042","27.82144","1.18824","67.74400","0.00000","1.18042","0.20007"
"1.18042","27.79931","1.18730","67.96400","0.00000","1.18042","0.20007"
"1.18042","27.80037","1.18734","68.18400","0.00000","1.18042","0.20007"
"1.18042","27.80009","1.18733","68.40400","0.00000","1.18042","0.20007"
"1.18042","27.76675","1.18590","68.62400","0.00000","1.18042","0.20007"
"1.18042","27.74823","1.18511","68.84400","0.00000","1.18042","0.20007"
"1.18042","27.75114","1.18524","69.06400","0.00000","1.18042","0.20007"
"1.18042","27.75266","1.18530","69.28400","0.00000","1.18042","0.20007"
"1.18042","27.75267","1.18530","69.50400","0.00000","1.18042","0.20007"
"1.18042","27.72760","1.18423","69.72400","0.00000","1.18042","0.20007"
"1.18042","27.71258","1.18359","69.94400","0.00000","1.18042","0.20007"
"1.18042","27.73831","1.18469","70.16400","0.00000","1.18042","0.20007"
"1.18042","27.71909","1.18387","70.38400","0.00000","1.18042","0.20007"
"1.18042","27.68872","1.18257","70.60400","0.00000","1.18042","0.20007"
"1.18042","27.68608","1.18246","70.82400","0.00000","1.18042","0.20007"
"1.18042","27.67130","1.18183","71.04400","0.00000","1.18042","0.20007"
"1.18042","27.67327","1.18191","71.26400","0.00000","1.18042","0.20007"
"1.18042","27.65696","1.18122","71.48400","0.00000","1.18042","0.20007"
"1.18042","27.65919","1.18131","71.70400","0.00000","1.18042","0.20007"
"1.18042","27.65322","1.18106","71.92400","0.00000","1.18042","0.20007"
"1.18042","27.63927","1.18046","72.14400","0.00000","1.18042","0.20007"
"1.18042","27.63334","1.18021","72.36400","0.00000","1.18042","0.20007"
"1.18042","27.63212","1.18016","72.58400","0.00000","1.18042","0.20007"
"1.18042","27.61707","1.17951","72.80400","0.00000","1.18042","0.20007"
"1.18042","27.60974","1.17920","73.02400","0.00000","1.18042","0.20007"
"1.18042","27.60205","1.17887","73.24400","0.00000","1.18042","0.20007"
"1.18042","27.59709","1.17866","73.46400","0.00000","1.18042","0.20007"
"1.18042","27.59180","1.17843","73.68400","0.00000","1.18042","0.20007"
"1.18042","27.58463","1.17813","73.90400","0.00000","1.18042","0.20007"
"1.18042","27.58125","1.17798","74.12400","0.00000","1.18042","0.20007"
"1.18042","27.57223","1.17760","74.34400","0.00000","1.18042","0.20007"
"1.18042","27.54507","1.17644","74.56400","0.00000","1.18042","0.20007"
"1.18042","27.54483","1.17643","74.78400","0.00000","1.18042","0.20007"
"1.18042","27.55521","1.17687","75.00400","0.00000","1.18042","0.20007"
"1.18042","27.53670","1.17608","75.22400","0.00000","1.18042","0.20007"
"1.18042","27.52617","1.17563","75.44400","0.00000","1.18042","0.20007"
"1.18042","27.52174","1.17544","75.66400","0.00000","1.18042","0.20007"
"1.18042","27.51941","1.17534","75.88400","0.00000","1.18042","0.20007"
"1.18042","27.51124","1.17499","76.10400","0.00000","1.18042","0.20007"
"1.18042","27.49817","1.17443","76.32400","0.00000","1.18042","0.20007"
"1.18042","27.49666","1.17437","76.54400","0.00000","1.18042","0.20007"
"1.18042","27.49670","1.17437","76.76400","0.00000","1.18042","0.20007"
"1.18042","27.46420","1.17298","76.98400","0.00000","1.18042","0.20007"
"1.18042","27.51071","1.17497","77.20400","0.00000","1.18042","0.20007"
"1.18042","27.46991","1.17323","77.42400","0.00000","1.18042","0.20007"
"1.18042","27.44664","1.17223","77.64400","0.00000","1.18042","0.20007"
"1.18042","27.45651","1.17265","77.86400","0.00000","1.18042","0.20007"
"1.18042","27.44826","1.17230","78.08400","0.00000","1.18042","0.20007"
"1.18042","27.43387","1.17169","78.30400","0.00000","1.18042","0.20007"
"1.18042","27.43088","1.17156","78.52400","0.00000","1.18042","0.20007"
"1.18042","27.44065","1.17198","78.74400","0.00000","1.18042","0.20007"
"1.18042","27.41159","1.17074","78.96400","0.00000","1.18042","0.20007"
"1.18042","27.41574","1.17091","79.18400","0.00000","1.18042","0.20007"
"1.18042","27.41227","1.17077","79.40400","0.00000","1.18042","0.20007"
"1.18042","27.39074","1.16985","79.62400","0.00000","1.18042","0.20007"
"1.18042","27.39221","1.16991","79.84400","0.00000","1.18042","0.20007"
"1.18042","27.38461","1.16958","80.06400","0.00000","1.18042","0.20007"
"1.18042","27.37151","1.16902","80.28400","0.00000","1.18042","0.20007"
"1.18042","27.37244","1.16906","80.50400","0.00000","1.18042","0.20007"
"1.18042","27.37157","1.16903","80.72400","0.00000","1.18042","0.20007"
"1.18042","27.34390","1.16785","80.94400","0.00000","1.18042","0.20007"
"1.18042","27.36014","1.16854","81.16400","0.00000","1.18042","0.20007"
"1.18042","27.34051","1.16770","81.38400","0.00000","1.18042","0.20007"
"1.18042","27.33249","1.16736","81.60400","0.00000","1.18042","0.20007"
"1.18042","27.34277","1.16780","81.82400","0.00000","1.18042","0.20007"
"1.18042","27.32395","1.16699","82.04400","0.00000","1.18042","0.20007"
"1.18042","27.30741","1.16629","82.26400","0.00000","1.18042","0.20007"
"1.18042","27.32078","1.16686","82.48400","0.00000","1.18042","0.20007"
"1.18042","27.32591","1.16708","82.70400","0.00000","1.18042","0.20007"
"1.18042","27.30539","1.16620","82.92400","0.00000","1.18042","0.20007"
"1.18042","27.28182","1.16519","83.14400","0.00000","1.18042","0.20007"
"1.18042","27.29908","1.16593","83.36400","0.00000","1.18042","0.20007"
"1.18042","27.27973","1.16510","83.58400","0.00000","1.18042","0.20007"
"1.18042","27.28435","1.16530","83.80400","0.00000","1.18042","0.20007"
"1.18042","27.25934","1.16423","84.02400","0.00000","1.18042","0.20007"
"1.18042","27.27110","1.16474","84.24400","0.00000","1.18042","0.20007"
"1.18042","27.25420","1.16401","84.46400","0.00000","1.18042","0.20007"
"1.18042","27.25260","1.16395","84.68400","0.00000","1.18042","0.20007"
"1.18042","27.24996","1.16383","84.90400","0.00000","1.18042","0.20007"
"1.18042","27.23279","1.16310","85.12400","0.00000","1.18042","0.20007"
"1.18042","27.23053","1.16300","85.34400","0.00000","1.18042","0.20007"
"1.18042","27.21933","1.16253","85.56400","0.00000","1.18042","0.20007"
"1.18042","27.23420","1.16316","85.78400","0.00000","1.18042","0.20007"
"1.18042","27.22153","1.16262","86.00400","0.00000","1.18042","0.20007"
"1.18042","27.19743","1.16159","86.22400","0.00000","1.18042","0.20007"
"1.18042","27.18998","1.16127","86.44400","0.00000","1.18042","0.20007"
"1.18042","27.19569","1.16152","86.66400","0.00000","1.18042","0.20007"
"1.18042","27.19458","1.16147","86.88400","0.00000","1.18042","0.20007"
"1.18042","27.18518","1.16107","87.10400","0.00000","1.18042","0.20007"
"1.18042","27.17571","1.16066","87.32400","0.00000","1.18042","0.20007"
"1.18042","27.17875","1.16079","87.54400","0.00000","1.18042","0.20007"
"1.18042","27.17340","1.16056","87.76400","0.00000","1.18042","0.20007"
"1.18042","27.15965","1.15998","87.98400","0.00000","1.18042","0.20007"
"1.18042","27.14298","1.15926","88.20400","0.00000","1.18042","0.20007"
"1.18042","27.17159","1.16049","88.42400","0.00000","1.18042","0.20007"
"1.18042","27.16520","1.16021","88.64400","0.00000","1.18042","0.20007"
"1.18042","27.12552","1.15852","88.86400","0.00000","1.18042","0.20007"
"1.18042","27.11578","1.15810","89.08400","0.00000","1.18042","0.20007"
"1.18042","27.14577","1.15938","89.30400","0.00000","1.18042","0.20007"
"1.18042","27.12682","1.15857","89.52400","0.00000","1.18042","0.20007"
"1.18042","27.09929","1.15740","89.74400","0.00000","1.18042","0.20007"
"1.18042","27.11612","1.15812","89.96400","0.00000","1.18042","0.20007"
"1.18042","27.07715","1.15645","90.18400","0.00000","1.18042","0.20007"
"1.18042","27.10480","1.15763","90.40400","0.00000","1.18042","0.20007"
"1.18042","27.11650","1.15813","90.62400","0.00000","1.18042","0.20007"
"1.18042","27.10051","1.15745","90.84400","0.00000","1.18042","0.20007"
"1.18042","27.08360","1.15673","91.06400","0.00000","1.18042","0.20007"
"1.18042","27.07611","1.15641","91.28400","0.00000","1.18042","0.20007"
"1.18042","27.06908","1.15611","91.50400","0.00000","1.18042","0.20007"
"1.18042","27.05688","1.15559","91.72400","0.00000","1.18042","0.20007"
"1.18042","27.06985","1.15614","91.94400","0.00000","1.18042","0.20007"
"1.18042","27.06310","1.15585","92.16400","0.00000","1.18042","0.20007"
"1.18042","27.05221","1.15539","92.38400","0.00000","1.18042","0.20007"
"1.18042","27.04509","1.15508","92.60400","0.00000","1.18042","0.20007"
"1.18042","27.04664","1.15515","92.82400","0.00000","1.18042","0.20007"
"1.18042","27.04502","1.15508","93.04400","0.00000","1.18042","0.20007"
"1.18042","27.03043","1.15446","93.26400","0.00000","1.18042","0.20007"
"1.18042","27.02226","1.15411","93.48400","0.00000","1.18042","0.20007"
"1.18042","27.02032","1.15403","93.70400","0.00000","1.18042","0.20007"
"1.18042","27.02795","1.15435","93.92400","0.00000","1.18042","0.20007"
"1.18042","27.01654","1.15386","94.14400","0.00000","1.18042","0.20007"
"1.18042","26.99933","1.15313","94.36400","0.00000","1.18042","0.20007"
"1.18042","26.98798","1.15264","94.58400","0.00000","1.18042","0.20007"
"1.18042","27.00515","1.15338","94.80400","0.00000","1.18042","0.20007"
"1.18042","26.99931","1.15313","95.02400","0.00000","1.18042","0.20007"
"1.18042","26.98190","1.15238","95.24400","0.00000","1.18042","0.20007"
"1.18042","26.98138","1.15236","95.46400","0.00000","1.18042","0.20007"
"1.18042","26.98872","1.15268","95.68400","0.00000","1.18042","0.20007"
"1.18042","26.96933","1.15185","95.90400","0.00000","1.18042","0.20007"
"1.18042","26.95519","1.15124","96.12400","0.00000","1.18042","0.20007"
"1.18042","26.96315","1.15158","96.34400","0.00000","1.18042","0.20007"
"1.18042","26.96596","1.15170","96.56400","0.00000","1.18042","0.20007"
"1.18042","26.94892","1.15098","96.78400","0.00000","1.18042","0.20007"
"1.18042","26.94218","1.15069","97.00400","0.00000","1.18042","0.20007"
"1.18042","26.93449","1.15036","97.22400","0.00000","1.18042","0.20007"
"1.18042","26.94050","1.15062","97.44400","0.00000","1.18042","0.20007"
"1.18042","26.94080","1.15063","97.66400","0.00000","1.18042","0.20007"
"1.18042","26.91394","1.14948","97.88400","0.00000","1.18042","0.20007"
"1.18042","26.92159","1.14981","98.10400","0.00000","1.18042","0.20007"
"1.18042","26.91758","1.14964","98.32400","0.00000","1.18042","0.20007"
"1.18042","26.90760","1.14921","98.54400","0.00000","1.18042","0.20007"
"1.18042","26.89787","1.14880","98.76400","0.00000","1.18042","0.20007"
"1.18042","26.90600","1.14914","98.98400","0.00000","1.18042","0.20007"
"1.18042","26.89777","1.14879","99.20400","0.00000","1.18042","0.20007"
"1.18042","26.86681","1.14747","99.42400","0.00000","1.18042","0.20007"
"1.18042","26.92728","1.15005","99.64400","0.00000","1.18042","0.20007"
"1.18042","26.93858","1.15053","99.86400","0.00000","1.18042","0.20007"
"1.18042","26.87399","1.14778","100.08400","0.00000","1.18042","0.20007"
"1.18042","26.86523","1.14740","100.30400","0.00000","1.18042","0.20007"
"1.18042","26.88533","1.14826","100.52400","0.00000","1.18042","0.20007"
"1.18042","26.85163","1.14682","100.74400","0.00000","1.18042","0.20007"
"1.18042","26.85387","1.14692","100.96400","0.00000","1.18042","0.20007"
"1.18042","26.86392","1.14735","101.18400","0.00000","1.18042","0.20007"
"1.18042","26.84746","1.14664","101.40400","0.00000","1.18042","0.20007"
"1.18042","26.84893","1.14671","101.62400","0.00000","1.18042","0.20007"
"1.18042","26.85822","1.14710","101.84400","0.00000","1.18042","0.20007"
"1.18042","26.83858","1.14626","102.06400","0.00000","1.18042","0.20007"
"1.18042","26.83253","1.14601","102.28400","0.00000","1.18042","0.20007"
"1.18042","26.83027","1.14591","102.50400","0.00000","1.18042","0.20007"
"1.18042","26.82378","1.14563","102.72400","0.00000","1.18042","0.20007"
"1.18042","26.81350","1.14519","102.94400","0.00000","1.18042","0.20007"
"1.18042","26.81499","1.14526","103.16400","0.00000","1.18042","0.20007"
"1.18042","26.79207","1.14428","103.38400","0.00000","1.18042","0.20007"
"1.18042","26.81694","1.14534","103.60400","0.00000","1.18042","0.20007"
"1.18042","26.80275","1.14473","103.82400","0.00000","1.18042","0.20007"
"1.18042","26.80770","1.14494","104.04400","0.00000","1.18042","0.20007"
"1.18042","26.79332","1.14433","104.26400","0.00000","1.18042","0.20007"
"1.18042","26.77099","1.14338","104.48400","0.00000","1.18042","0.20007"
"1.18042","26.77437","1.14352","104.70400","0.00000","1.18042","0.20007"
"1.18042","26.77171","1.14341","104.92400","0.00000","1.18042","0.20007"
"1.18042","26.77318","1.14347","105.14400","0.00000","1.18042","0.20007"
"1.18042","26.77630","1.14360","105.36400","0.00000","1.18042","0.20007"
"1.18042","26.78241","1.14386","105.58400","0.00000","1.18042","0.20007"
"1.18042","26.74209","1.14214","105.80400","0.00000","1.18042","0.20007"
"1.18042","26.75900","1.14286","106.02400","0.00000","1.18042","0.20007"
"1.18042","26.76652","1.14319","106.24400","0.00000","1.18042","0.20007"
"1.18042","26.73572","1.14187","106.46400","0.00000","1.18042","0.20007"
"1.18042","26.75895","1.14286","106.68400","0.00000","1.18042","0.20007"
"1.18042","26.74669","1.14234","106.90400","0.00000","1.18042","0.20007"
"1.18042","26.67792","1.13940","107.12400","0.00000","1.18042","0.20007"
"1.18042","26.71806","1.14112","107.34400","0.00000","1.18042","0.20007"
"1.18042","26.75676","1.14277","107.56400","0.00000","1.18042","0.20007"
"1.18042","26.73657","1.14191","107.78400","0.00000","1.18042","0.20007"
"1.18042","26.71811","1.14112","108.00400","0.00000","1.18042","0.20007"
"1.18042","26.70025","1.14036","108.22400","0.00000","1.18042","0.20007"
"1.18042","26.71655","1.14105","108.44400","0.00000","1.18042","0.20007"
"1.18042","26.71117","1.14082","108.66400","0.00000","1.18042","0.20007"
"1.18042","26.69531","1.14014","108.88400","0.00000","1.18042","0.20007"
"1.18042","26.69326","1.14006","109.10400","0.00000","1.18042","0.20007"
"1.18042","26.69823","1.14027","109.32400","0.00000","1.18042","0.20007"
"1.18042","26.68743","1.13981","109.54400","0.00000","1.18042","0.20007"
"1.18042","26.68314","1.13962","109.76400","0.00000","1.18042","0.20007"
"1.18042","26.67320","1.13920","109.98400","0.00000","1.18042","0.20007"
"1.18042","26.67716","1.13937","110.20400","0.00000","1.18042","0.20007"
"1.18042","26.67382","1.13923","110.42400","0.00000","1.18042","0.20007"
"1.18042","26.66475","1.13884","110.64400","0.00000","1.18042","0.20007"
"1.18042","26.66343","1.13878","110.86400","0.00000","1.18042","0.20007"
"1.18042","26.66091","1.13867","111.08400","0.00000","1.18042","0.20007"
"1.18042","26.65840","1.13857","111.30400","0.00000","1.18042","0.20007"
"1.18042","26.64851","1.13815","111.52400","0.00000","1.18042","0.20007"
"1.18042","26.64778","1.13811","111.74400","0.00000","1.18042","0.20007"
"1.18042","26.64503","1.13800","111.96400","0.00000","1.18042","0.20007"
"1.18042","26.64173","1.13786","112.18400","0.00000","1.18042","0.20007"
"1.18042","26.63076","1.13739","112.40400","0.00000","1.18042","0.20007"
"1.18042","26.63416","1.13753","112.62400","0.00000","1.18042","0.20007"
"1.18042","26.62547","1.13716","112.84400","0.00000","1.18042","0.20007"
"1.18042","26.63094","1.13740","113.06400","0.00000","1.18042","0.20007"
"1.18042","26.61511","1.13672","113.28400","0.00000","1.18042","0.20007"
"1.18042","26.61351","1.13665","113.50400","0.00000","1.18042","0.20007"
"1.18042","26.62118","1.13698","113.72400","0.00000","1.18042","0.20007"
"1.18042","26.61210","1.13659","113.94400","0.00000","1.18042","0.20007"
"1.18042","26.60546","1.13631","114.16400","0.00000","1.18042","0.20007"
"1.18042","26.60008","1.13608","114.38400","0.00000","1.18042","0.20007"
"1.18042","26.60435","1.13626","114.60400","0.00000","1.18042","0.20007"
"1.18042","26.59543","1.13588","114.82400","0.00000","1.18042","0.20007"
"1.18042","26.59674","1.13593","115.04400","0.00000","1.18042","0.20007"
"1.18042","26.58731","1.13553","115.26400","0.00000","1.18042","0.20007"
"1.18042","26.58211","1.13531","115.48400","0.00000","1.18042","0.20007"
"1.18042","26.57822","1.13514","115.70400","0.00000","1.18042","0.20007"
"1.18042","26.57827","1.13515","115.92400","0.00000","1.18042","0.20007"
"1.18042","26.57072","1.13482","116.14400","0.00000","1.18042","0.20007"
"1.18042","26.56337","1.13451","116.36400","0.00000","1.18042","0.20007"
"1.18042","26.56260","1.13448","116.58400","0.00000","1.18042","0.20007"
"1.18042","26.55285","1.13406","116.80400","0.00000","1.18042","0.20007"
"1.18042","26.55928","1.13433","117.02400","0.00000","1.18042","0.20007"
"1.18042","26.54630","1.13378","117.24400","0.00000","1.18042","0.20007"
"1.18042","26.55263","1.13405","117.46400","0.00000","1.18042","0.20007"
"1.18042","26.54351","1.13366","117.68400","0.00000","1.18042","0.20007"
"1.18042","26.54766","1.13384","117.90400","0.00000","1.18042","0.20007"
"1.18042","26.53920","1.13348","118.12400","0.00000","1.18042","0.20007"
"1.18042","26.53056","1.13311","118.34400","0.00000","1.18042","0.20007"
"1.18042","26.52717","1.13296","118.56400","0.00000","1.18042","0.20007"
"1.18042","26.52772","1.13299","118.78400","0.00000","1.18042","0.20007"
"1.18042","26.52598","1.13291","119.00400","0.00000","1.18042","0.20007"
"1.18042","26.51760","1.13255","119.22400","0.00000","1.18042","0.20007"
"1.18042","26.52051","1.13268","119.44400","0.00000","1.18042","0.20007"
"1.18042","26.51345","1.13238","119.66400","0.00000","1.18042","0.20007"
"1.18042","26.50820","1.13215","119.88400","0.00000","1.18042","0.20007"
"1.18042","26.49581","1.13162","120.10400","0.00000","1.18042","0.20007"
"1.18042","26.50230","1.13190","120.32400","0.00000","1.18042","0.20007"
"1.18042","26.49691","1.13167","120.54400","0.00000","1.18042","0.20007"
"1.18042","26.49423","1.13156","120.76400","0.00000","1.18042","0.20007"
"1.18042","26.48463","1.13115","120.98400","0.00000","1.18042","0.20007"
"1.18042","26.48690","1.13124","121.20400","0.00000","1.18042","0.20007"
"1.18042","26.48503","1.13116","121.42400","0.00000","1.18042","0.20007"
"1.18042","26.48101","1.13099","121.64400","0.00000","1.18042","0.20007"
"1.18042","26.47665","1.13081","121.86400","0.00000","1.18042","0.20007"
"1.18042","26.47114","1.13057","122.08400","0.00000","1.18042","0.20007"
"1.18042","26.46494","1.13031","122.30400","0.00000","1.18042","0.20007"
"1.18042","26.46878","1.13047","122.52400","0.00000","1.18042","0.20007"
"1.18042","26.47142","1.13058","122.74400","0.00000","1.18042","0.20007"
"1.18042","26.46323","1.13023","122.96400","0.00000","1.18042","0.20007"
"1.18042","26.45957","1.13008","123.18400","0.00000","1.18042","0.20007"
"1.18042","26.45158","1.12973","123.40400","0.00000","1.18042","0.20007"
"1.18042","26.44489","1.12945","123.62400","0.00000","1.18042","0.20007"
"1.18042","26.44379","1.12940","123.84400","0.00000","1.18042","0.20007"
"1.18042","26.43390","1.12898","124.06400","0.00000","1.18042","0.20007"
"1.18042","26.43317","1.12895","124.28400","0.00000","1.18042","0.20007"
"1.18042","26.43775","1.12914","124.50400","0.00000","1.18042","0.20007"
"1.18042","26.43348","1.12896","124.72400","0.00000","1.18042","0.20007"
"1.18042","26.42315","1.12852","124.94400","0.00000","1.18042","0.20007"
"1.18042","26.42586","1.12864","125.16400","0.00000","1.18042","0.20007"
"1.18042","26.42654","1.12867","125.38400","0.00000","1.18042","0.20007"
"1.18042","26.41849","1.12832","125.60400","0.00000","1.18042","0.20007"
"1.18042","26.41785","1.12829","125.82400","0.00000","1.18042","0.20007"
"1.18042","26.41345","1.12811","126.04400","0.00000","1.18042","0.20007"
"1.18042","26.41557","1.12820","126.26400","0.00000","1.18042","0.20007"
"1.18042","26.40260","1.12764","126.48400","0.00000","1.18042","0.20007"
"1.18042","26.40458","1.12773","126.70400","0.00000","1.18042","0.20007"
"1.18042","26.39594","1.12736","126.92400","0.00000","1.18042","0.20007"
"1.18042","26.39493","1.12732","127.14400","0.00000","1.18042","0.20007"
"1.18042","26.38800","1.12702","127.36400","0.00000","1.18042","0.20007"
"1.18042","26.39445","1.12729","127.58400","0.00000","1.18042","0.20007"
"1.18042","26.38513","1.12690","127.80400","0.00000","1.18042","0.20007"
"1.18042","26.38123","1.12673","128.02400","0.00000","1.18042","0.20007"
"1.18042","26.37227","1.12635","128.24400","0.00000","1.18042","0.20007"
"1.18042","26.37446","1.12644","128.46400","0.00000","1.18042","0.20007"
"1.18042","26.36834","1.12618","128.68400","0.00000","1.18042","0.20007"
"1.18042","26.37172","1.12632","128.90400","0.00000","1.18042","0.20007"
"1.18042","26.36259","1.12593","129.12400","0.00000","1.18042","0.20007"
"1.18042","26.36508","1.12604","129.34400","0.00000","1.18042","0.20007"
"1.18042","26.35857","1.12576","129.56400","0.00000","1.18042","0.20007"
"1.18042","26.36009","1.12583","129.78400","0.00000","1.18042","0.20007"
"1.18042","26.35790","1.12573","130.00400","0.00000","1.18042","0.20007"
"1.18042","26.34408","1.12514","130.22400","0.00000","1.18042","0.20007"
"1.18042","26.34455","1.12516","130.44400","0.00000","1.18042","0.20007"
"1.18042","26.34115","1.12502","130.66400","0.00000","1.18042","0.20007"
"1.18042","26.33810","1.12489","130.88400","0.00000","1.18042","0.20007"
"1.18042","26.33653","1.12482","131.10400","0.00000","1.18042","0.20007"
"1.18042","26.32977","1.12453","131.32400","0.00000","1.18042","0.20007"
"1.18042","26.32110","1.12416","131.54400","0.00000","1.18042","0.20007"
"1.18042","26.32593","1.12437","131.76400","0.00000","1.18042","0.20007"
"1.18042","26.32533","1.12434","131.98400","0.00000","1.18042","0.20007"
"1.18042","26.32156","1.12418","132.20400","0.00000","1.18042","0.20007"
"1.18042","26.31627","1.12396","132.42400","0.00000","1.18042","0.20007"
"1.18042","26.31186","1.12377","132.64400","0.00000","1.18042","0.20007"
"1.18042","26.30628","1.12353","132.86400","0.00000","1.18042","0.20007"
"1.18042","26.30712","1.12357","133.08400","0.00000","1.18042","0.20007"
"1.18042","26.30140","1.12332","133.30400","0.00000","1.18042","0.20007"
"1.18042","26.30357","1.12341","133.52400","0.00000","1.18042","0.20007"
"1.18042","26.29694","1.12313","133.74400","0.00000","1.18042","0.20007"
"1.18042","26.29793","1.12317","133.96400","0.00000","1.18042","0.20007"
"1.18042","26.28825","1.12276","134.18400","0.00000","1.18042","0.20007"
"1.18042","26.28547","1.12264","134.40400","0.00000","1.18042","0.20007"
"1.18042","26.29177","1.12291","134.62400","0.00000","1.18042","0.20007"
"1.18042","26.27969","1.12239","134.84400","0.00000","1.18042","0.20007"
"1.18042","26.27284","1.12210","135.06400","0.00000","1.18042","0.20007"
"1.18042","26.27764","1.12231","135.28400","0.00000","1.18042","0.20007"
"1.18042","26.27026","1.12199","135.50400","0.00000","1.18042","0.20007"
"1.18042","26.26350","1.12170","135.72400","0.00000","1.18042","0.20007"
"1.18042","26.27275","1.12210","135.94400","0.00000","1.18042","0.20007"
"1.18042","26.26756","1.12188","136.16400","0.00000","1.18042","0.20007"
"1.18042","26.26191","1.12163","136.38400","0.00000","1.18042","0.20007"
"1.18042","26.25692","1.12142","136.60400","0.00000","1.18042","0.20007"
"1.18042","26.25835","1.12148","136.82400","0.00000","1.18042","0.20007"
"1.18042","26.25541","1.12136","137.04400","0.00000","1.18042","0.20007"
"1.18042","26.25203","1.12121","137.26400","0.00000","1.18042","0.20007"
"1.18042","26.25099","1.12117","137.48400","0.00000","1.18042","0.20007"
"1.18042","26.24532","1.12093","137.70400","0.00000","1.18042","0.20007"
"1.18042","26.24018","1.12071","137.92400","0.00000","1.18042","0.20007"
"1.18042","26.23358","1.12042","138.14400","0.00000","1.18042","0.20007"
"1.18042","26.23049","1.12029","138.36400","0.00000","1.18042","0.20007"
"1.18042","26.22895","1.12023","138.58400","0.00000","1.18042","0.20007"
"1.18042","26.22909","1.12023","138.80400","0.00000","1.18042","0.20007"
"1.18042","26.23135","1.12033","139.02400","0.00000","1.18042","0.20007"
"1.18042","26.21878","1.11979","139.24400","0.00000","1.18042","0.20007"
"1.18042","26.21659","1.11970","139.46400","0.00000","1.18042","0.20007"
"1.18042","26.21658","1.11970","139.68400","0.00000","1.18042","0.20007"
"1.18042","26.22058","1.11987","139.90400","0.00000","1.18042","0.20007"
"1.18042","26.21642","1.11969","140.12400","0.00000","1.18042","0.20007"
"1.18042","26.20403","1.11916","140.34400","0.00000","1.18042","0.20007"
"1.18042","26.20488","1.11920","140.56400","0.00000","1.18042","0.20007"
"1.18042","26.20137","1.11905","140.78400","0.00000","1.18042","0.20007"
"1.18042","26.20330","1.11913","141.00400","0.00000","1.18042","0.20007"
"1.18042","26.19121","1.11861","141.22400","0.00000","1.18042","0.20007"
"1.18042","26.18875","1.11851","141.44400","0.00000","1.18042","0.20007"
"1.18042","26.18629","1.11840","141.66400","0.00000","1.18042","0.20007"
"1.18042","26.19251","1.11867","141.88400","0.00000","1.18042","0.20007"
"1.18042","26.18208","1.11822","142.10400","0.00000","1.18042","0.20007"
"1.18042","26.18654","1.11841","142.32400","0.00000","1.18042","0.20007"
"1.18042","26.18252","1.11824","142.54400","0.00000","1.18042","0.20007"
"1.18042","26.17189","1.11779","142.76400","0.00000","1.18042","0.20007"
"1.18042","26.16973","1.11770","142.98400","0.00000","1.18042","0.20007"
"1.18042","26.17050","1.11773","143.20400","0.00000","1.18042","0.20007"
"1.18042","26.17141","1.11777","143.42400","0.00000","1.18042","0.20007"
"1.18042","26.16264","1.11739","143.64400","0.00000","1.18042","0.20007"
"1.18042","26.16233","1.11738","143.86400","0.00000","1.18042","0.20007"
"1.18042","26.15330","1.11700","144.08400","0.00000","1.18042","0.20007"
"1.18042","26.16183","1.11736","144.30400","0.00000","1.18042","0.20007"
"1.18042","26.15087","1.11689","144.52400","0.00000","1.18042","0.20007"
"1.18042","26.15627","1.11712","144.74400","0.00000","1.18042","0.20007"
"1.18042","26.14576","1.11667","144.96400","0.00000","1.18042","0.20007"
"1.18042","26.14825","1.11678","145.18400","0.00000","1.18042","0.20007"
"1.18042","26.14053","1.11645","145.40400","0.00000","1.18042","0.20007"
"1.18042","26.13953","1.11641","145.62400","0.00000","1.18042","0.20007"
"1.18042","26.13680","1.11629","145.84400","0.00000","1.18042","0.20007"
"1.18042","26.13568","1.11624","146.06400","0.00000","1.18042","0.20007"
"1.18042","26.13572","1.11624","146.28400","0.00000","1.18042","0.20007"
"1.18042","26.13025","1.11601","146.50400","0.00000","1.18042","0.20007"
"1.18042","26.12498","1.11579","146.72400","0.00000","1.18042","0.20007"
"1.18042","26.12638","1.11585","146.94400","0.00000","1.18042","0.20007"
"1.18042","26.11365","1.11530","147.16400","0.00000","1.18042","0.20007"
"1.18042","26.11358","1.11530","147.38400","0.00000","1.18042","0.20007"
"1.18042","26.11699","1.11544","147.60400","0.00000","1.18042","0.20007"
"1.18042","26.10640","1.11499","147.82400","0.00000","1.18042","0.20007"
"1.18042","26.11419","1.11532","148.04400","0.00000","1.18042","0.20007"
"1.18042","26.11443","1.11534","148.26400","0.00000","1.18042","0.20007"
"1.18042","26.11016","1.11515","148.48400","0.00000","1.18042","0.20007"
"1.18042","26.10285","1.11484","148.70400","0.00000","1.18042","0.20007"
"1.18042","26.09617","1.11456","148.92400","0.00000","1.18042","0.20007"
"1.18042","26.09453","1.11449","149.14400","0.00000","1.18042","0.20007"
"1.18042","26.09222","1.11439","149.36400","0.00000","1.18042","0.20007"
"1.18042","26.08879","1.11424","149.49400","0.00000","1.18042","0.20007"