File: Rubber Stress Relaxation Raw Data - Small Samples-20210211/Specimen_RawData_1.csv
Specimen properties : Specimen label,"GAI2S1R1"
Specimen properties : Anvil height,"6.00000",mm
Specimen properties : Diameter,"5.41000",mm
Test : Rate 1,"0.24000",mm/min
Test : Start of hold value,"20.00000",%
Test : Duration,"120.00000",s

Extension,Load,Compressive stress,Time,PIP count,Compressive extension,Compressive strain (Extension)
(mm),(N),(MPa),(s),,(mm),(mm/mm)
"0.00000","-0.00770","-0.00033","0.00000","0.00000","0.00000","0.00000"
"0.00063","0.00356","0.00015","0.61000","0.00000","0.00063","0.00010"
"0.00458","0.23348","0.01016","1.22000","0.00000","0.00458","0.00076"
"0.00729","0.32763","0.01425","1.83000","0.00000","0.00729","0.00122"
"0.00958","0.41630","0.01811","2.44000","0.00000","0.00958","0.00160"
"0.01208","0.50829","0.02211","3.05000","0.00000","0.01208","0.00201"
"0.01458","0.57761","0.02513","3.66000","0.00000","0.01458","0.00243"
"0.01708","0.67290","0.02927","4.27000","0.00000","0.01708","0.00285"
"0.01958","0.73818","0.03211","4.88000","0.00000","0.01958","0.00326"
"0.02188","0.81406","0.03541","5.49000","0.00000","0.02188","0.00365"
"0.02458","0.89357","0.03887","6.10000","0.00000","0.02458","0.00410"
"0.02708","0.96265","0.04188","6.71000","0.00000","0.02708","0.00451"
"0.02958","1.03555","0.04505","7.32000","0.00000","0.02958","0.00493"
"0.03188","1.10340","0.04800","7.93000","0.00000","0.03188","0.00531"
"0.03417","1.17564","0.05114","8.54000","0.00000","0.03417","0.00569"
"0.03667","1.23577","0.05376","9.15000","0.00000","0.03667","0.00611"
"0.03896","1.30917","0.05695","9.76000","0.00000","0.03896","0.00649"
"0.04146","1.37507","0.05982","10.37000","0.00000","0.04146","0.00691"
"0.04396","1.45498","0.06330","10.98000","0.00000","0.04396","0.00733"
"0.04625","1.51661","0.06598","11.59000","0.00000","0.04625","0.00771"
"0.04875","1.59599","0.06943","12.20000","0.00000","0.04875","0.00813"
"0.05125","1.65913","0.07218","12.81000","0.00000","0.05125","0.00854"
"0.05375","1.73126","0.07531","13.42000","0.00000","0.05375","0.00896"
"0.05625","1.79708","0.07818","14.03000","0.00000","0.05625","0.00938"
"0.05875","1.87143","0.08141","14.64000","0.00000","0.05875","0.00979"
"0.06125","1.93956","0.08438","15.25000","0.00000","0.06125","0.01021"
"0.06375","1.99338","0.08672","15.86000","0.00000","0.06375","0.01063"
"0.06604","2.06133","0.08967","16.47000","0.00000","0.06604","0.01101"
"0.06854","2.13679","0.09296","17.08000","0.00000","0.06854","0.01142"
"0.07083","2.19012","0.09528","17.69000","0.00000","0.07083","0.01181"
"0.07333","2.25594","0.09814","18.30000","0.00000","0.07333","0.01222"
"0.07583","2.33522","0.10159","18.91000","0.00000","0.07583","0.01264"
"0.07813","2.39682","0.10427","19.52000","0.00000","0.07813","0.01302"
"0.08042","2.44938","0.10655","20.13000","0.00000","0.08042","0.01340"
"0.08292","2.52002","0.10963","20.74000","0.00000","0.08292","0.01382"
"0.08521","2.58814","0.11259","21.35000","0.00000","0.08521","0.01420"
"0.08792","2.66542","0.11595","21.96000","0.00000","0.08792","0.01465"
"0.09021","2.73262","0.11888","22.57000","0.00000","0.09021","0.01503"
"0.09271","2.79293","0.12150","23.18000","0.00000","0.09271","0.01545"
"0.09521","2.86159","0.12449","23.79000","0.00000","0.09521","0.01587"
"0.09771","2.92562","0.12727","24.40000","0.00000","0.09771","0.01628"
"0.10021","2.99266","0.13019","25.01000","0.00000","0.10021","0.01670"
"0.10271","3.06297","0.13325","25.62000","0.00000","0.10271","0.01712"
"0.10521","3.12848","0.13610","26.23000","0.00000","0.10521","0.01753"
"0.10750","3.19083","0.13881","26.84000","0.00000","0.10750","0.01792"
"0.11000","3.25340","0.14153","27.45000","0.00000","0.11000","0.01833"
"0.11250","3.30429","0.14375","28.06000","0.00000","0.11250","0.01875"
"0.11479","3.38078","0.14707","28.67000","0.00000","0.11479","0.01913"
"0.11729","3.42852","0.14915","29.28000","0.00000","0.11729","0.01955"
"0.11958","3.49025","0.15183","29.89000","0.00000","0.11958","0.01993"
"0.12188","3.55015","0.15444","30.50000","0.00000","0.12188","0.02031"
"0.12438","3.60633","0.15688","31.11000","0.00000","0.12438","0.02073"
"0.12688","3.66877","0.15960","31.72000","0.00000","0.12688","0.02115"
"0.12917","3.72552","0.16207","32.33000","0.00000","0.12917","0.02153"
"0.13167","3.78359","0.16460","32.94000","0.00000","0.13167","0.02194"
"0.13417","3.84908","0.16745","33.55000","0.00000","0.13417","0.02236"
"0.13667","3.91421","0.17028","34.16000","0.00000","0.13667","0.02278"
"0.13917","3.97055","0.17273","34.77000","0.00000","0.13917","0.02319"
"0.14167","4.02697","0.17518","35.38000","0.00000","0.14167","0.02361"
"0.14417","4.09337","0.17807","35.99000","0.00000","0.14417","0.02403"
"0.14667","4.14928","0.18050","36.60000","0.00000","0.14667","0.02444"
"0.14896","4.19991","0.18271","37.21000","0.00000","0.14896","0.02483"
"0.15146","4.25706","0.18519","37.82000","0.00000","0.15146","0.02524"
"0.15396","4.31800","0.18784","38.43000","0.00000","0.15396","0.02566"
"0.15625","4.35943","0.18965","39.04000","0.00000","0.15625","0.02604"
"0.15875","4.41709","0.19216","39.65000","0.00000","0.15875","0.02646"
"0.16104","4.46378","0.19419","40.26000","0.00000","0.16104","0.02684"
"0.16354","4.53310","0.19720","40.87000","0.00000","0.16354","0.02726"
"0.16583","4.59319","0.19982","41.48000","0.00000","0.16583","0.02764"
"0.16833","4.63188","0.20150","42.09000","0.00000","0.16833","0.02806"
"0.17083","4.70481","0.20467","42.70000","0.00000","0.17083","0.02847"
"0.17333","4.76158","0.20714","43.31000","0.00000","0.17333","0.02889"
"0.17583","4.82335","0.20983","43.92000","0.00000","0.17583","0.02931"
"0.17833","4.88295","0.21242","44.53000","0.00000","0.17833","0.02972"
"0.18083","4.93624","0.21474","45.14000","0.00000","0.18083","0.03014"
"0.18313","4.99055","0.21710","45.75000","0.00000","0.18313","0.03052"
"0.18563","5.03507","0.21904","46.36000","0.00000","0.18563","0.03094"
"0.18812","5.09452","0.22162","46.97000","0.00000","0.18812","0.03135"
"0.19042","5.15518","0.22426","47.58000","0.00000","0.19042","0.03174"
"0.19292","5.20123","0.22627","48.19000","0.00000","0.19292","0.03215"
"0.19542","5.25915","0.22879","48.80000","0.00000","0.19542","0.03257"
"0.19771","5.31247","0.23111","49.41000","0.00000","0.19771","0.03295"
"0.20000","5.35463","0.23294","50.02000","0.00000","0.20000","0.03333"
"0.20250","5.41170","0.23542","50.63000","0.00000","0.20250","0.03375"
"0.20479","5.45821","0.23745","51.24000","0.00000","0.20479","0.03413"
"0.20729","5.52856","0.24051","51.85000","0.00000","0.20729","0.03455"
"0.20979","5.58674","0.24304","52.46000","0.00000","0.20979","0.03497"
"0.21229","5.63190","0.24500","53.07000","0.00000","0.21229","0.03538"
"0.21479","5.69351","0.24768","53.68000","0.00000","0.21479","0.03580"
"0.21729","5.75400","0.25031","54.29000","0.00000","0.21729","0.03622"
"0.21958","5.80306","0.25245","54.90000","0.00000","0.21958","0.03660"
"0.22208","5.85295","0.25462","55.51000","0.00000","0.22208","0.03701"
"0.22458","5.90477","0.25687","56.12000","0.00000","0.22458","0.03743"
"0.22708","5.96433","0.25946","56.73000","0.00000","0.22708","0.03785"
"0.22938","6.00607","0.26128","57.34000","0.00000","0.22938","0.03823"
"0.23188","6.07212","0.26415","57.95000","0.00000","0.23188","0.03865"
"0.23438","6.10424","0.26555","58.56000","0.00000","0.23438","0.03906"
"0.23688","6.18340","0.26899","59.17000","0.00000","0.23688","0.03948"
"0.23938","6.22346","0.27074","59.78000","0.00000","0.23938","0.03990"
"0.24167","6.26513","0.27255","60.39000","0.00000","0.24167","0.04028"
"0.24396","6.31401","0.27468","61.00000","0.00000","0.24396","0.04066"
"0.24646","6.34829","0.27617","61.61000","0.00000","0.24646","0.04108"
"0.24875","6.41203","0.27894","62.22000","0.00000","0.24875","0.04146"
"0.25125","6.47698","0.28177","62.83000","0.00000","0.25125","0.04188"
"0.25375","6.52496","0.28385","63.44000","0.00000","0.25375","0.04229"
"0.25625","6.57458","0.28601","64.05000","0.00000","0.25625","0.04271"
"0.25854","6.63615","0.28869","64.66000","0.00000","0.25854","0.04309"
"0.26125","6.70676","0.29176","65.27000","0.00000","0.26125","0.04354"
"0.26354","6.74348","0.29336","65.88000","0.00000","0.26354","0.04392"
"0.26625","6.79387","0.29555","66.49000","0.00000","0.26625","0.04438"
"0.26854","6.85144","0.29806","67.10000","0.00000","0.26854","0.04476"
"0.27104","6.89084","0.29977","67.71000","0.00000","0.27104","0.04517"
"0.27354","6.94997","0.30234","68.32000","0.00000","0.27354","0.04559"
"0.27604","7.00806","0.30487","68.93000","0.00000","0.27604","0.04601"
"0.27833","7.05232","0.30679","69.54000","0.00000","0.27833","0.04639"
"0.28063","7.09428","0.30862","70.15000","0.00000","0.28063","0.04677"
"0.28313","7.15180","0.31112","70.76000","0.00000","0.28313","0.04719"
"0.28542","7.20433","0.31341","71.37000","0.00000","0.28542","0.04757"
"0.28771","7.24920","0.31536","71.98000","0.00000","0.28771","0.04795"
"0.29042","7.30190","0.31765","72.59000","0.00000","0.29042","0.04840"
"0.29292","7.37688","0.32091","73.20000","0.00000","0.29292","0.04882"
"0.29542","7.43601","0.32349","73.81000","0.00000","0.29542","0.04924"
"0.29792","7.48686","0.32570","74.42000","0.00000","0.29792","0.04965"
"0.30021","7.50793","0.32661","75.03000","0.00000","0.30021","0.05003"
"0.30271","7.58330","0.32989","75.64000","0.00000","0.30271","0.05045"
"0.30521","7.63324","0.33207","76.25000","0.00000","0.30521","0.05087"
"0.30750","7.69798","0.33488","76.86000","0.00000","0.30750","0.05125"
"0.31000","7.73981","0.33670","77.47000","0.00000","0.31000","0.05167"
"0.31250","7.79290","0.33901","78.08000","0.00000","0.31250","0.05208"
"0.31479","7.84827","0.34142","78.69000","0.00000","0.31479","0.05247"
"0.31750","7.90311","0.34381","79.30000","0.00000","0.31750","0.05292"
"0.31979","7.95489","0.34606","79.91000","0.00000","0.31979","0.05330"
"0.32229","8.00333","0.34817","80.52000","0.00000","0.32229","0.05372"
"0.32458","8.05177","0.35027","81.13000","0.00000","0.32458","0.05410"
"0.32708","8.10008","0.35237","81.74000","0.00000","0.32708","0.05451"
"0.32937","8.15645","0.35483","82.35000","0.00000","0.32937","0.05490"
"0.33188","8.20740","0.35704","82.96000","0.00000","0.33188","0.05531"
"0.33438","8.26177","0.35941","83.57000","0.00000","0.33438","0.05573"
"0.33687","8.32311","0.36208","84.18000","0.00000","0.33687","0.05615"
"0.33917","8.37045","0.36414","84.79000","0.00000","0.33917","0.05653"
"0.34167","8.42962","0.36671","85.40000","0.00000","0.34167","0.05694"
"0.34417","8.47692","0.36877","86.01000","0.00000","0.34417","0.05736"
"0.34667","8.52608","0.37091","86.62000","0.00000","0.34667","0.05778"
"0.34896","8.59199","0.37377","87.23000","0.00000","0.34896","0.05816"
"0.35146","8.63453","0.37562","87.84000","0.00000","0.35146","0.05858"
"0.35396","8.68924","0.37800","88.45000","0.00000","0.35396","0.05899"
"0.35646","8.73283","0.37990","89.06000","0.00000","0.35646","0.05941"
"0.35896","8.79827","0.38275","89.67000","0.00000","0.35896","0.05983"
"0.36125","8.84758","0.38489","90.28000","0.00000","0.36125","0.06021"
"0.36375","8.90054","0.38720","90.89000","0.00000","0.36375","0.06063"
"0.36625","8.94158","0.38898","91.50000","0.00000","0.36625","0.06104"
"0.36854","8.98695","0.39096","92.11000","0.00000","0.36854","0.06142"
"0.37083","9.04596","0.39352","92.72000","0.00000","0.37083","0.06181"
"0.37354","9.10568","0.39612","93.33000","0.00000","0.37354","0.06226"
"0.37583","9.16565","0.39873","93.94000","0.00000","0.37583","0.06264"
"0.37833","9.21558","0.40090","94.55000","0.00000","0.37833","0.06306"
"0.38063","9.26276","0.40295","95.16000","0.00000","0.38063","0.06344"
"0.38313","9.31837","0.40537","95.77000","0.00000","0.38313","0.06385"
"0.38563","9.37806","0.40797","96.38000","0.00000","0.38563","0.06427"
"0.38813","9.41668","0.40965","96.99000","0.00000","0.38813","0.06469"
"0.39042","9.48011","0.41241","97.60000","0.00000","0.39042","0.06507"
"0.39292","9.53124","0.41463","98.21000","0.00000","0.39292","0.06549"
"0.39542","9.57729","0.41664","98.82000","0.00000","0.39542","0.06590"
"0.39771","9.63108","0.41898","99.43000","0.00000","0.39771","0.06628"
"0.40021","9.67993","0.42110","100.04000","0.00000","0.40021","0.06670"
"0.40271","9.73443","0.42347","100.65000","0.00000","0.40271","0.06712"
"0.40521","9.78818","0.42581","101.26000","0.00000","0.40521","0.06753"
"0.40771","9.83964","0.42805","101.87000","0.00000","0.40771","0.06795"
"0.41000","9.89298","0.43037","102.48000","0.00000","0.41000","0.06833"
"0.41250","9.94693","0.43272","103.09000","0.00000","0.41250","0.06875"
"0.41479","9.98949","0.43457","103.70000","0.00000","0.41479","0.06913"
"0.41708","10.05321","0.43734","104.31000","0.00000","0.41708","0.06951"
"0.41979","10.10439","0.43957","104.92000","0.00000","0.41979","0.06997"
"0.42208","10.15704","0.44186","105.53000","0.00000","0.42208","0.07035"
"0.42458","10.22284","0.44472","106.14000","0.00000","0.42458","0.07076"
"0.42688","10.26242","0.44644","106.75000","0.00000","0.42688","0.07115"
"0.42938","10.32107","0.44899","107.36000","0.00000","0.42938","0.07156"
"0.43187","10.37358","0.45128","107.97000","0.00000","0.43187","0.07198"
"0.43438","10.42358","0.45345","108.58000","0.00000","0.43438","0.07240"
"0.43667","10.47216","0.45557","109.19000","0.00000","0.43667","0.07278"
"0.43917","10.52844","0.45801","109.80000","0.00000","0.43917","0.07319"
"0.44167","10.58703","0.46056","110.41000","0.00000","0.44167","0.07361"
"0.44417","10.62953","0.46241","111.02000","0.00000","0.44417","0.07403"
"0.44667","10.68817","0.46496","111.63000","0.00000","0.44667","0.07444"
"0.44896","10.73988","0.46721","112.24000","0.00000","0.44896","0.07483"
"0.45146","10.78952","0.46937","112.85000","0.00000","0.45146","0.07524"
"0.45396","10.85322","0.47214","113.46000","0.00000","0.45396","0.07566"
"0.45625","10.89635","0.47402","114.07000","0.00000","0.45625","0.07604"
"0.45875","10.95058","0.47638","114.68000","0.00000","0.45875","0.07646"
"0.46104","11.00261","0.47864","115.29000","0.00000","0.46104","0.07684"
"0.46354","11.06075","0.48117","115.90000","0.00000","0.46354","0.07726"
"0.46583","11.10237","0.48298","116.51000","0.00000","0.46583","0.07764"
"0.46854","11.15895","0.48544","117.12000","0.00000","0.46854","0.07809"
"0.47104","11.21702","0.48797","117.73000","0.00000","0.47104","0.07851"
"0.47354","11.28020","0.49072","118.34000","0.00000","0.47354","0.07892"
"0.47583","11.32625","0.49272","118.95000","0.00000","0.47583","0.07931"
"0.47833","11.36578","0.49444","119.56000","0.00000","0.47833","0.07972"
"0.48063","11.42710","0.49711","120.17000","0.00000","0.48063","0.08010"
"0.48313","11.47931","0.49938","120.78000","0.00000","0.48312","0.08052"
"0.48583","11.55337","0.50260","121.39000","0.00000","0.48583","0.08097"
"0.48813","11.58849","0.50413","122.00000","0.00000","0.48813","0.08135"
"0.49063","11.65176","0.50688","122.61000","0.00000","0.49063","0.08177"
"0.49312","11.69631","0.50882","123.22000","0.00000","0.49312","0.08219"
"0.49542","11.75359","0.51131","123.83000","0.00000","0.49542","0.08257"
"0.49792","11.80600","0.51359","124.44000","0.00000","0.49792","0.08299"
"0.50042","11.85734","0.51583","125.05000","0.00000","0.50042","0.08340"
"0.50292","11.92256","0.51866","125.66000","0.00000","0.50292","0.08382"
"0.50521","11.96599","0.52055","126.27000","0.00000","0.50521","0.08420"
"0.50750","12.01993","0.52290","126.88000","0.00000","0.50750","0.08458"
"0.51000","12.08391","0.52568","127.49000","0.00000","0.51000","0.08500"
"0.51250","12.13886","0.52807","128.10000","0.00000","0.51250","0.08542"
"0.51500","12.18555","0.53010","128.71000","0.00000","0.51500","0.08583"
"0.51729","12.22920","0.53200","129.32000","0.00000","0.51729","0.08622"
"0.51958","12.29036","0.53466","129.93000","0.00000","0.51958","0.08660"
"0.52208","12.33015","0.53639","130.54000","0.00000","0.52208","0.08701"
"0.52458","12.39779","0.53934","131.15000","0.00000","0.52458","0.08743"
"0.52708","12.45989","0.54204","131.76000","0.00000","0.52708","0.08785"
"0.52958","12.50535","0.54402","132.37000","0.00000","0.52958","0.08826"
"0.53208","12.58565","0.54751","132.98000","0.00000","0.53208","0.08868"
"0.53458","12.59105","0.54774","133.59000","0.00000","0.53458","0.08910"
"0.53688","12.66728","0.55106","134.20000","0.00000","0.53688","0.08948"
"0.53938","12.72135","0.55341","134.81000","0.00000","0.53938","0.08990"
"0.54167","12.77380","0.55569","135.42000","0.00000","0.54167","0.09028"
"0.54417","12.82498","0.55792","136.03000","0.00000","0.54417","0.09069"
"0.54646","12.87459","0.56008","136.64000","0.00000","0.54646","0.09108"
"0.54896","12.93620","0.56276","137.25000","0.00000","0.54896","0.09149"
"0.55146","12.99732","0.56542","137.86000","0.00000","0.55146","0.09191"
"0.55375","13.04476","0.56748","138.47000","0.00000","0.55375","0.09229"
"0.55625","13.09917","0.56985","139.08000","0.00000","0.55625","0.09271"
"0.55875","13.16309","0.57263","139.69000","0.00000","0.55875","0.09313"
"0.56125","13.21096","0.57471","140.30000","0.00000","0.56125","0.09354"
"0.56375","13.27150","0.57735","140.91000","0.00000","0.56375","0.09396"
"0.56625","13.32869","0.57983","141.52000","0.00000","0.56625","0.09438"
"0.56875","13.38211","0.58216","142.13000","0.00000","0.56875","0.09479"
"0.57125","13.43423","0.58442","142.74000","0.00000","0.57125","0.09521"
"0.57354","13.49162","0.58692","143.35000","0.00000","0.57354","0.09559"
"0.57604","13.53451","0.58879","143.96000","0.00000","0.57604","0.09601"
"0.57854","13.59909","0.59160","144.57000","0.00000","0.57854","0.09642"
"0.58083","13.65114","0.59386","145.18000","0.00000","0.58083","0.09681"
"0.58333","13.70525","0.59621","145.79000","0.00000","0.58333","0.09722"
"0.58562","13.74505","0.59795","146.40000","0.00000","0.58562","0.09760"
"0.58813","13.81234","0.60087","147.01000","0.00000","0.58813","0.09802"
"0.59063","13.87455","0.60358","147.62000","0.00000","0.59063","0.09844"
"0.59292","13.93122","0.60605","148.23000","0.00000","0.59292","0.09882"
"0.59542","13.97374","0.60789","148.84000","0.00000","0.59542","0.09924"
"0.59771","14.03320","0.61048","149.45000","0.00000","0.59771","0.09962"
"0.60021","14.08786","0.61286","150.06000","0.00000","0.60021","0.10003"
"0.60271","14.13614","0.61496","150.67000","0.00000","0.60271","0.10045"
"0.60521","14.20296","0.61787","151.28000","0.00000","0.60521","0.10087"
"0.60750","14.25854","0.62028","151.89000","0.00000","0.60750","0.10125"
"0.61000","14.31249","0.62263","152.50000","0.00000","0.61000","0.10167"
"0.61271","14.37634","0.62541","153.11000","0.00000","0.61271","0.10212"
"0.61500","14.43565","0.62799","153.72000","0.00000","0.61500","0.10250"
"0.61750","14.48157","0.62999","154.33000","0.00000","0.61750","0.10292"
"0.62000","14.52884","0.63204","154.94000","0.00000","0.62000","0.10333"
"0.62229","14.57077","0.63387","155.55000","0.00000","0.62229","0.10372"
"0.62458","14.62279","0.63613","156.16000","0.00000","0.62458","0.10410"
"0.62708","14.69525","0.63928","156.77000","0.00000","0.62708","0.10451"
"0.62958","14.76653","0.64238","157.38000","0.00000","0.62958","0.10493"
"0.63208","14.80688","0.64414","157.99000","0.00000","0.63208","0.10535"
"0.63438","14.86514","0.64667","158.60000","0.00000","0.63438","0.10573"
"0.63688","14.91625","0.64890","159.21000","0.00000","0.63688","0.10615"
"0.63917","14.97402","0.65141","159.82000","0.00000","0.63917","0.10653"
"0.64167","15.03651","0.65413","160.43000","0.00000","0.64167","0.10694"
"0.64438","15.10196","0.65698","161.04000","0.00000","0.64438","0.10740"
"0.64667","15.14713","0.65894","161.65000","0.00000","0.64667","0.10778"
"0.64917","15.21252","0.66178","162.26000","0.00000","0.64917","0.10819"
"0.65167","15.25657","0.66370","162.87000","0.00000","0.65167","0.10861"
"0.65417","15.31082","0.66606","163.48000","0.00000","0.65417","0.10903"
"0.65667","15.36781","0.66854","164.09000","0.00000","0.65667","0.10944"
"0.65896","15.42571","0.67106","164.70000","0.00000","0.65896","0.10983"
"0.66146","15.49091","0.67390","165.31000","0.00000","0.66146","0.11024"
"0.66354","15.52036","0.67518","165.92000","0.00000","0.66354","0.11059"
"0.66604","15.59369","0.67837","166.53000","0.00000","0.66604","0.11101"
"0.66854","15.65028","0.68083","167.14000","0.00000","0.66854","0.11142"
"0.67104","15.71124","0.68348","167.75000","0.00000","0.67104","0.11184"
"0.67333","15.75742","0.68549","168.36000","0.00000","0.67333","0.11222"
"0.67583","15.82660","0.68850","168.97000","0.00000","0.67583","0.11264"
"0.67833","15.88227","0.69092","169.58000","0.00000","0.67833","0.11306"
"0.68063","15.91637","0.69240","170.19000","0.00000","0.68063","0.11344"
"0.68333","16.00481","0.69625","170.80000","0.00000","0.68333","0.11389"
"0.68563","16.05935","0.69862","171.41000","0.00000","0.68563","0.11427"
"0.68813","16.10607","0.70066","172.02000","0.00000","0.68813","0.11469"
"0.69063","16.17027","0.70345","172.63000","0.00000","0.69063","0.11510"
"0.69313","16.23559","0.70629","173.24000","0.00000","0.69313","0.11552"
"0.69563","16.28378","0.70839","173.85000","0.00000","0.69563","0.11594"
"0.69813","16.33937","0.71081","174.46000","0.00000","0.69813","0.11635"
"0.70042","16.40188","0.71352","175.07000","0.00000","0.70042","0.11674"
"0.70292","16.45117","0.71567","175.68000","0.00000","0.70292","0.11715"
"0.70521","16.51568","0.71848","176.29000","0.00000","0.70521","0.11753"
"0.70771","16.56322","0.72054","176.90000","0.00000","0.70771","0.11795"
"0.71000","16.63101","0.72349","177.51000","0.00000","0.71000","0.11833"
"0.71250","16.68870","0.72600","178.12000","0.00000","0.71250","0.11875"
"0.71479","16.73464","0.72800","178.73000","0.00000","0.71479","0.11913"
"0.71729","16.79909","0.73080","179.34000","0.00000","0.71729","0.11955"
"0.71979","16.85342","0.73317","179.95000","0.00000","0.71979","0.11997"
"0.72229","16.91821","0.73599","180.56000","0.00000","0.72229","0.12038"
"0.72458","16.97711","0.73855","181.17000","0.00000","0.72458","0.12076"
"0.72708","17.04489","0.74150","181.78000","0.00000","0.72708","0.12118"
"0.72979","17.11226","0.74443","182.39000","0.00000","0.72979","0.12163"
"0.73229","17.15236","0.74617","183.00000","0.00000","0.73229","0.12205"
"0.73458","17.21181","0.74876","183.61000","0.00000","0.73458","0.12243"
"0.73708","17.27732","0.75161","184.22000","0.00000","0.73708","0.12285"
"0.73958","17.33331","0.75404","184.83000","0.00000","0.73958","0.12326"
"0.74188","17.38468","0.75628","185.44000","0.00000","0.74188","0.12365"
"0.74417","17.43692","0.75855","186.05000","0.00000","0.74417","0.12403"
"0.74667","17.48754","0.76075","186.66000","0.00000","0.74667","0.12444"
"0.74896","17.55130","0.76353","187.27000","0.00000","0.74896","0.12483"
"0.75146","17.61613","0.76635","187.88000","0.00000","0.75146","0.12524"
"0.75396","17.67670","0.76898","188.49000","0.00000","0.75396","0.12566"
"0.75625","17.73131","0.77136","189.10000","0.00000","0.75625","0.12604"
"0.75875","17.80091","0.77439","189.71000","0.00000","0.75875","0.12646"
"0.76125","17.85050","0.77654","190.32000","0.00000","0.76125","0.12687"
"0.76375","17.91487","0.77934","190.93000","0.00000","0.76375","0.12729"
"0.76604","17.97791","0.78209","191.54000","0.00000","0.76604","0.12767"
"0.76875","18.03928","0.78476","192.15000","0.00000","0.76875","0.12812"
"0.77125","18.12143","0.78833","192.76000","0.00000","0.77125","0.12854"
"0.77375","18.16714","0.79032","193.37000","0.00000","0.77375","0.12896"
"0.77625","18.21392","0.79235","193.98000","0.00000","0.77625","0.12937"
"0.77854","18.29098","0.79571","194.59000","0.00000","0.77854","0.12976"
"0.78104","18.33721","0.79772","195.20000","0.00000","0.78104","0.13017"
"0.78333","18.37328","0.79929","195.81000","0.00000","0.78333","0.13056"
"0.78583","18.44247","0.80230","196.42000","0.00000","0.78583","0.13097"
"0.78833","18.51263","0.80535","197.03000","0.00000","0.78833","0.13139"
"0.79063","18.55774","0.80731","197.64000","0.00000","0.79062","0.13177"
"0.79313","18.63420","0.81064","198.25000","0.00000","0.79313","0.13219"
"0.79542","18.68316","0.81277","198.86000","0.00000","0.79542","0.13257"
"0.79792","18.75221","0.81577","199.47000","0.00000","0.79792","0.13299"
"0.80021","18.81513","0.81851","200.08000","0.00000","0.80021","0.13337"
"0.80271","18.87875","0.82128","200.69000","0.00000","0.80271","0.13378"
"0.80521","18.93925","0.82391","201.30000","0.00000","0.80521","0.13420"
"0.80771","18.99968","0.82654","201.91000","0.00000","0.80771","0.13462"
"0.81021","19.05909","0.82912","202.52000","0.00000","0.81021","0.13503"
"0.81271","19.13186","0.83229","203.13000","0.00000","0.81271","0.13545"
"0.81521","19.18306","0.83451","203.74000","0.00000","0.81521","0.13587"
"0.81771","19.24346","0.83714","204.35000","0.00000","0.81771","0.13628"
"0.82000","19.30495","0.83982","204.96000","0.00000","0.82000","0.13667"
"0.82250","19.36144","0.84227","205.57000","0.00000","0.82250","0.13708"
"0.82479","19.40778","0.84429","206.18000","0.00000","0.82479","0.13747"
"0.82708","19.47059","0.84702","206.79000","0.00000","0.82708","0.13785"
"0.82958","19.53679","0.84990","207.40000","0.00000","0.82958","0.13826"
"0.83188","19.59687","0.85252","208.01000","0.00000","0.83188","0.13865"
"0.83438","19.66232","0.85536","208.62000","0.00000","0.83438","0.13906"
"0.83688","19.72383","0.85804","209.23000","0.00000","0.83688","0.13948"
"0.83917","19.78541","0.86072","209.84000","0.00000","0.83917","0.13986"
"0.84167","19.85393","0.86370","210.45000","0.00000","0.84167","0.14028"
"0.84417","19.91180","0.86622","211.06000","0.00000","0.84417","0.14069"
"0.84667","19.98634","0.86946","211.67000","0.00000","0.84667","0.14111"
"0.84917","20.04605","0.87206","212.28000","0.00000","0.84917","0.14153"
"0.85167","20.10748","0.87473","212.89000","0.00000","0.85167","0.14194"
"0.85417","20.16365","0.87717","213.50000","0.00000","0.85417","0.14236"
"0.85667","20.23582","0.88031","214.11000","0.00000","0.85667","0.14278"
"0.85917","20.28716","0.88254","214.72000","0.00000","0.85917","0.14319"
"0.86146","20.35225","0.88538","215.33000","0.00000","0.86146","0.14358"
"0.86396","20.40475","0.88766","215.94000","0.00000","0.86396","0.14399"
"0.86625","20.46970","0.89049","216.55000","0.00000","0.86625","0.14438"
"0.86875","20.52920","0.89307","217.16000","0.00000","0.86875","0.14479"
"0.87104","20.59867","0.89610","217.77000","0.00000","0.87104","0.14517"
"0.87333","20.64408","0.89807","218.38000","0.00000","0.87333","0.14556"
"0.87583","20.72357","0.90153","218.99000","0.00000","0.87583","0.14597"
"0.87833","20.79787","0.90476","219.60000","0.00000","0.87833","0.14639"
"0.88083","20.85272","0.90715","220.21000","0.00000","0.88083","0.14681"
"0.88333","20.90630","0.90948","220.82000","0.00000","0.88333","0.14722"
"0.88563","20.98242","0.91279","221.43000","0.00000","0.88563","0.14760"
"0.88813","21.05383","0.91590","222.04000","0.00000","0.88813","0.14802"
"0.89062","21.11246","0.91845","222.65000","0.00000","0.89062","0.14844"
"0.89333","21.18672","0.92168","223.26000","0.00000","0.89333","0.14889"
"0.89563","21.24334","0.92414","223.87000","0.00000","0.89563","0.14927"
"0.89812","21.30834","0.92697","224.48000","0.00000","0.89812","0.14969"
"0.90062","21.36866","0.92959","225.09000","0.00000","0.90062","0.15010"
"0.90292","21.42401","0.93200","225.70000","0.00000","0.90292","0.15049"
"0.90542","21.49633","0.93515","226.31000","0.00000","0.90542","0.15090"
"0.90792","21.55252","0.93759","226.92000","0.00000","0.90792","0.15132"
"0.91021","21.61089","0.94013","227.53000","0.00000","0.91021","0.15170"
"0.91250","21.66700","0.94257","228.14000","0.00000","0.91250","0.15208"
"0.91500","21.73916","0.94571","228.75000","0.00000","0.91500","0.15250"
"0.91729","21.79156","0.94799","229.36000","0.00000","0.91729","0.15288"
"0.91979","21.86653","0.95125","229.97000","0.00000","0.91979","0.15330"
"0.92229","21.93728","0.95433","230.58000","0.00000","0.92229","0.15372"
"0.92479","22.00191","0.95714","231.19000","0.00000","0.92479","0.15413"
"0.92729","22.07092","0.96014","231.80000","0.00000","0.92729","0.15455"
"0.92979","22.14913","0.96355","232.41000","0.00000","0.92979","0.15497"
"0.93229","22.21162","0.96626","233.02000","0.00000","0.93229","0.15538"
"0.93479","22.26419","0.96855","233.63000","0.00000","0.93479","0.15580"
"0.93708","22.34115","0.97190","234.24000","0.00000","0.93708","0.15618"
"0.93958","22.38469","0.97379","234.85000","0.00000","0.93958","0.15660"
"0.94208","22.44546","0.97644","235.46000","0.00000","0.94208","0.15701"
"0.94437","22.51360","0.97940","236.07000","0.00000","0.94437","0.15740"
"0.94688","22.58904","0.98268","236.68000","0.00000","0.94688","0.15781"
"0.94938","22.63845","0.98483","237.29000","0.00000","0.94938","0.15823"
"0.95167","22.69963","0.98749","237.90000","0.00000","0.95167","0.15861"
"0.95396","22.75391","0.98986","238.51000","0.00000","0.95396","0.15899"
"0.95646","22.82692","0.99303","239.12000","0.00000","0.95646","0.15941"
"0.95875","22.88362","0.99550","239.73000","0.00000","0.95875","0.15979"
"0.96146","22.97441","0.99945","240.34000","0.00000","0.96146","0.16024"
"0.96375","23.03183","1.00195","240.95000","0.00000","0.96375","0.16062"
"0.96625","23.10265","1.00503","241.56000","0.00000","0.96625","0.16104"
"0.96875","23.17735","1.00828","242.17000","0.00000","0.96875","0.16146"
"0.97125","23.25707","1.01174","242.78000","0.00000","0.97125","0.16187"
"0.97375","23.31859","1.01442","243.39000","0.00000","0.97375","0.16229"
"0.97625","23.38956","1.01751","244.00000","0.00000","0.97625","0.16271"
"0.97854","23.44479","1.01991","244.61000","0.00000","0.97854","0.16309"
"0.98104","23.52096","1.02322","245.22000","0.00000","0.98104","0.16351"
"0.98354","23.56898","1.02531","245.83000","0.00000","0.98354","0.16392"
"0.98604","23.62337","1.02768","246.44000","0.00000","0.98604","0.16434"
"0.98833","23.69147","1.03064","247.05000","0.00000","0.98833","0.16472"
"0.99083","23.76840","1.03399","247.66000","0.00000","0.99083","0.16514"
"0.99313","23.81995","1.03623","248.27000","0.00000","0.99313","0.16552"
"0.99542","23.88398","1.03902","248.88000","0.00000","0.99542","0.16590"
"0.99792","23.95321","1.04203","249.49000","0.00000","0.99792","0.16632"
"1.00042","24.02347","1.04508","250.10000","0.00000","1.00042","0.16674"
"1.00292","24.09720","1.04829","250.71000","0.00000","1.00292","0.16715"
"1.00521","24.16444","1.05122","251.32000","0.00000","1.00521","0.16753"
"1.00771","24.22980","1.05406","251.93000","0.00000","1.00771","0.16795"
"1.01021","24.30400","1.05729","252.54000","0.00000","1.01021","0.16837"
"1.01271","24.37695","1.06046","253.15000","0.00000","1.01271","0.16878"
"1.01521","24.44619","1.06347","253.76000","0.00000","1.01521","0.16920"
"1.01771","24.51254","1.06636","254.37000","0.00000","1.01771","0.16962"
"1.02021","24.58709","1.06960","254.98000","0.00000","1.02021","0.17003"
"1.02250","24.63563","1.07171","255.59000","0.00000","1.02250","0.17042"
"1.02500","24.71389","1.07512","256.20000","0.00000","1.02500","0.17083"
"1.02750","24.77146","1.07762","256.81000","0.00000","1.02750","0.17125"
"1.03000","24.84430","1.08079","257.42000","0.00000","1.03000","0.17167"
"1.03229","24.90478","1.08342","258.03000","0.00000","1.03229","0.17205"
"1.03458","24.96300","1.08596","258.64000","0.00000","1.03458","0.17243"
"1.03688","25.03277","1.08899","259.25000","0.00000","1.03688","0.17281"
"1.03938","25.09391","1.09165","259.86000","0.00000","1.03938","0.17323"
"1.04167","25.15931","1.09450","260.47000","0.00000","1.04167","0.17361"
"1.04438","25.24449","1.09820","261.08000","0.00000","1.04438","0.17406"
"1.04688","25.33225","1.10202","261.69000","0.00000","1.04688","0.17448"
"1.04917","25.39663","1.10482","262.30000","0.00000","1.04917","0.17486"
"1.05167","25.44943","1.10712","262.91000","0.00000","1.05167","0.17528"
"1.05417","25.52623","1.11046","263.52000","0.00000","1.05417","0.17569"
"1.05646","25.59709","1.11354","264.13000","0.00000","1.05646","0.17608"
"1.05896","25.66923","1.11668","264.74000","0.00000","1.05896","0.17649"
"1.06125","25.72048","1.11891","265.35000","0.00000","1.06125","0.17688"
"1.06375","25.80750","1.12269","265.96000","0.00000","1.06375","0.17729"
"1.06646","25.87426","1.12560","266.57000","0.00000","1.06646","0.17774"
"1.06896","25.95285","1.12902","267.18000","0.00000","1.06896","0.17816"
"1.07146","26.00982","1.13150","267.79000","0.00000","1.07146","0.17858"
"1.07375","26.06623","1.13395","268.40000","0.00000","1.07375","0.17896"
"1.07604","26.12267","1.13641","269.01000","0.00000","1.07604","0.17934"
"1.07833","26.19710","1.13964","269.62000","0.00000","1.07833","0.17972"
"1.08083","26.27419","1.14300","270.23000","0.00000","1.08083","0.18014"
"1.08333","26.34448","1.14605","270.84000","0.00000","1.08333","0.18056"
"1.08583","26.41693","1.14921","271.45000","0.00000","1.08583","0.18097"
"1.08812","26.47317","1.15165","272.06000","0.00000","1.08812","0.18135"
"1.09063","26.54789","1.15490","272.67000","0.00000","1.09063","0.18177"
"1.09313","26.61884","1.15799","273.28000","0.00000","1.09313","0.18219"
"1.09563","26.69251","1.16119","273.89000","0.00000","1.09563","0.18260"
"1.09812","26.76747","1.16446","274.50000","0.00000","1.09812","0.18302"
"1.10063","26.83107","1.16722","275.11000","0.00000","1.10063","0.18344"
"1.10292","26.88177","1.16943","275.72000","0.00000","1.10292","0.18382"
"1.10542","26.96078","1.17287","276.33000","0.00000","1.10542","0.18424"
"1.10792","27.05034","1.17676","276.94000","0.00000","1.10792","0.18465"
"1.11042","27.10783","1.17926","277.55000","0.00000","1.11042","0.18507"
"1.11271","27.17948","1.18238","278.16000","0.00000","1.11271","0.18545"
"1.11521","27.23069","1.18461","278.77000","0.00000","1.11521","0.18587"
"1.11771","27.30559","1.18787","279.38000","0.00000","1.11771","0.18628"
"1.12000","27.38029","1.19111","279.99000","0.00000","1.12000","0.18667"
"1.12250","27.45148","1.19421","280.60000","0.00000","1.12250","0.18708"
"1.12500","27.52408","1.19737","281.21000","0.00000","1.12500","0.18750"
"1.12750","27.60699","1.20098","281.82000","0.00000","1.12750","0.18792"
"1.13000","27.67511","1.20394","282.43000","0.00000","1.13000","0.18833"
"1.13229","27.74028","1.20678","283.04000","0.00000","1.13229","0.18872"
"1.13479","27.81612","1.21007","283.65000","0.00000","1.13479","0.18913"
"1.13729","27.89921","1.21369","284.26000","0.00000","1.13729","0.18955"
"1.13958","27.96500","1.21655","284.87000","0.00000","1.13958","0.18993"
"1.14208","28.02028","1.21896","285.48000","0.00000","1.14208","0.19035"
"1.14458","28.09781","1.22233","286.09000","0.00000","1.14458","0.19076"
"1.14688","28.17505","1.22569","286.70000","0.00000","1.14688","0.19115"
"1.14938","28.24364","1.22867","287.31000","0.00000","1.14938","0.19156"
"1.15188","28.30902","1.23152","287.92000","0.00000","1.15188","0.19198"
"1.15417","28.37990","1.23460","288.53000","0.00000","1.15417","0.19236"
"1.15667","28.45358","1.23781","289.14000","0.00000","1.15667","0.19278"
"1.15917","28.53112","1.24118","289.75000","0.00000","1.15917","0.19319"
"1.16146","28.57717","1.24318","290.36000","0.00000","1.16146","0.19358"
"1.16396","28.67187","1.24730","290.97000","0.00000","1.16396","0.19399"
"1.16646","28.75744","1.25102","291.58000","0.00000","1.16646","0.19441"
"1.16896","28.83737","1.25450","292.19000","0.00000","1.16896","0.19483"
"1.17146","28.90944","1.25764","292.80000","0.00000","1.17146","0.19524"
"1.17375","28.99227","1.26124","293.41000","0.00000","1.17375","0.19563"
"1.17625","29.05410","1.26393","294.02000","0.00000","1.17625","0.19604"
"1.17875","29.13121","1.26728","294.63000","0.00000","1.17875","0.19646"
"1.18104","29.18097","1.26945","295.24000","0.00000","1.18104","0.19684"
"1.18354","29.26145","1.27295","295.85000","0.00000","1.18354","0.19726"
"1.18604","29.35768","1.27714","296.46000","0.00000","1.18604","0.19767"
"1.18854","29.43389","1.28045","297.07000","0.00000","1.18854","0.19809"
"1.19083","29.50349","1.28348","297.68000","0.00000","1.19083","0.19847"
"1.19333","29.56372","1.28610","298.29000","0.00000","1.19333","0.19889"
"1.19583","29.64011","1.28942","298.90000","0.00000","1.19583","0.19931"
"1.19833","29.72130","1.29296","299.51000","0.00000","1.19833","0.19972"
"1.20021","29.73295","1.29346","300.11200","0.00000","1.20021","0.20003"
"1.20021","29.51602","1.28402","300.72200","0.00000","1.20021","0.20003"
"1.20021","29.36897","1.27763","301.33200","0.00000","1.20021","0.20003"
"1.20021","29.24671","1.27231","301.94200","0.00000","1.20021","0.20003"
"1.20021","29.13855","1.26760","302.55200","0.00000","1.20021","0.20003"
"1.20021","29.04782","1.26366","303.16200","0.00000","1.20021","0.20003"
"1.19958","28.92631","1.25837","303.77200","0.00000","1.19958","0.19993"
"1.19958","28.85482","1.25526","304.38200","0.00000","1.19958","0.19993"
"1.19958","28.78914","1.25240","304.99200","0.00000","1.19958","0.19993"
"1.19958","28.72325","1.24954","305.60200","0.00000","1.19958","0.19993"
"1.20021","28.73257","1.24994","306.21200","0.00000","1.20021","0.20003"
"1.20021","28.65340","1.24650","306.82200","0.00000","1.20021","0.20003"
"1.20021","28.59413","1.24392","307.43200","0.00000","1.20021","0.20003"
"1.19958","28.52961","1.24111","308.04200","0.00000","1.19958","0.19993"
"1.19958","28.43878","1.23716","308.65200","0.00000","1.19958","0.19993"
"1.19958","28.40080","1.23551","309.26200","0.00000","1.19958","0.19993"
"1.19958","28.36373","1.23390","309.87200","0.00000","1.19958","0.19993"
"1.19958","28.33158","1.23250","310.48200","0.00000","1.19958","0.19993"
"1.20021","28.31877","1.23194","311.09200","0.00000","1.20021","0.20003"
"1.20021","28.28104","1.23030","311.70200","0.00000","1.20021","0.20003"
"1.20021","28.22979","1.22807","312.31200","0.00000","1.20021","0.20003"
"1.19958","28.14833","1.22453","312.92200","0.00000","1.19958","0.19993"
"1.19958","28.11864","1.22324","313.53200","0.00000","1.19958","0.19993"
"1.19958","28.07892","1.22151","314.14200","0.00000","1.19958","0.19993"
"1.19958","28.05712","1.22056","314.75200","0.00000","1.19958","0.19993"
"1.19958","28.03477","1.21959","315.36200","0.00000","1.19958","0.19993"
"1.20021","28.04453","1.22001","315.97200","0.00000","1.20021","0.20003"
"1.20021","28.00740","1.21840","316.58200","0.00000","1.20021","0.20003"
"1.20021","27.97866","1.21715","317.19200","0.00000","1.20021","0.20003"
"1.19958","27.88467","1.21306","317.80200","0.00000","1.19958","0.19993"
"1.19958","27.86432","1.21217","318.41200","0.00000","1.19958","0.19993"
"1.19958","27.83832","1.21104","319.02200","0.00000","1.19958","0.19993"
"1.19958","27.81744","1.21013","319.63200","0.00000","1.19958","0.19993"
"1.19958","27.80639","1.20965","320.24200","0.00000","1.19958","0.19993"
"1.20021","27.82574","1.21049","320.85200","0.00000","1.20021","0.20003"
"1.20021","27.79656","1.20922","321.46200","0.00000","1.20021","0.20003"
"1.20021","27.74926","1.20717","322.07200","0.00000","1.20021","0.20003"
"1.19958","27.67985","1.20415","322.68200","0.00000","1.19958","0.19993"
"1.19958","27.65946","1.20326","323.29200","0.00000","1.19958","0.19993"
"1.19958","27.63709","1.20229","323.90200","0.00000","1.19958","0.19993"
"1.19958","27.62729","1.20186","324.51200","0.00000","1.19958","0.19993"
"1.19958","27.61500","1.20133","325.12200","0.00000","1.19958","0.19993"
"1.20021","27.62375","1.20171","325.73200","0.00000","1.20021","0.20003"
"1.20021","27.59971","1.20066","326.34200","0.00000","1.20021","0.20003"
"1.19958","27.52859","1.19757","326.95200","0.00000","1.19958","0.19993"
"1.19958","27.49591","1.19614","327.56200","0.00000","1.19958","0.19993"
"1.19958","27.48050","1.19547","328.17200","0.00000","1.19958","0.19993"
"1.19958","27.46175","1.19466","328.78200","0.00000","1.19958","0.19993"
"1.19958","27.45063","1.19418","329.39200","0.00000","1.19958","0.19993"
"1.20021","27.48724","1.19577","330.00200","0.00000","1.20021","0.20003"
"1.20021","27.44956","1.19413","330.61200","0.00000","1.20021","0.20003"
"1.20021","27.43667","1.19357","331.22200","0.00000","1.20021","0.20003"
"1.19958","27.34596","1.18962","331.83200","0.00000","1.19958","0.19993"
"1.19958","27.33522","1.18915","332.44200","0.00000","1.19958","0.19993"
"1.19958","27.32563","1.18874","333.05200","0.00000","1.19958","0.19993"
"1.19958","27.31319","1.18820","333.66200","0.00000","1.19958","0.19993"
"1.19958","27.30394","1.18779","334.27200","0.00000","1.19958","0.19993"
"1.20021","27.34660","1.18965","334.88200","0.00000","1.20021","0.20003"
"1.20021","27.31295","1.18819","335.49200","0.00000","1.20021","0.20003"
"1.20021","27.28798","1.18710","336.10200","0.00000","1.20021","0.20003"
"1.19979","27.21105","1.18375","336.71200","0.00000","1.19979","0.19997"
"1.19979","27.20447","1.18347","337.32200","0.00000","1.19979","0.19997"
"1.19979","27.19205","1.18293","337.93200","0.00000","1.19979","0.19997"
"1.19979","27.17562","1.18221","338.54200","0.00000","1.19979","0.19997"
"1.19979","27.16272","1.18165","339.15200","0.00000","1.19979","0.19997"
"1.19979","27.14703","1.18097","339.76200","0.00000","1.19979","0.19997"
"1.19979","27.13994","1.18066","340.37200","0.00000","1.19979","0.19997"
"1.19979","27.11519","1.17958","340.98200","0.00000","1.19979","0.19997"
"1.19979","27.10413","1.17910","341.59200","0.00000","1.19979","0.19997"
"1.19979","27.08048","1.17807","342.20200","0.00000","1.19979","0.19997"
"1.19979","27.07433","1.17780","342.81200","0.00000","1.19979","0.19997"
"1.19979","27.05918","1.17715","343.42200","0.00000","1.19979","0.19997"
"1.19979","27.04096","1.17635","344.03200","0.00000","1.19979","0.19997"
"1.19979","27.02432","1.17563","344.64200","0.00000","1.19979","0.19997"
"1.19979","27.01905","1.17540","345.25200","0.00000","1.19979","0.19997"
"1.19979","26.99783","1.17448","345.86200","0.00000","1.19979","0.19997"
"1.19979","26.98137","1.17376","346.47200","0.00000","1.19979","0.19997"
"1.19979","26.97355","1.17342","347.08200","0.00000","1.19979","0.19997"
"1.19979","26.96539","1.17307","347.69200","0.00000","1.19979","0.19997"
"1.19979","26.94668","1.17225","348.30200","0.00000","1.19979","0.19997"
"1.19979","26.92723","1.17141","348.91200","0.00000","1.19979","0.19997"
"1.19979","26.92437","1.17128","349.52200","0.00000","1.19979","0.19997"
"1.19979","26.90611","1.17049","350.13200","0.00000","1.19979","0.19997"
"1.19979","26.89825","1.17014","350.74200","0.00000","1.19979","0.19997"
"1.19979","26.88553","1.16959","351.35200","0.00000","1.19979","0.19997"
"1.19979","26.86884","1.16887","351.96200","0.00000","1.19979","0.19997"
"1.19979","26.85990","1.16848","352.57200","0.00000","1.19979","0.19997"
"1.19979","26.84563","1.16786","353.18200","0.00000","1.19979","0.19997"
"1.19979","26.82976","1.16717","353.79200","0.00000","1.19979","0.19997"
"1.19979","26.82819","1.16710","354.40200","0.00000","1.19979","0.19997"
"1.19979","26.80242","1.16598","355.01200","0.00000","1.19979","0.19997"
"1.19979","26.79661","1.16572","355.62200","0.00000","1.19979","0.19997"
"1.19979","26.78344","1.16515","356.23200","0.00000","1.19979","0.19997"
"1.19979","26.78023","1.16501","356.84200","0.00000","1.19979","0.19997"
"1.19979","26.76536","1.16436","357.45200","0.00000","1.19979","0.19997"
"1.19979","26.74298","1.16339","358.06200","0.00000","1.19979","0.19997"
"1.19979","26.73749","1.16315","358.67200","0.00000","1.19979","0.19997"
"1.19979","26.72466","1.16259","359.28200","0.00000","1.19979","0.19997"
"1.19979","26.71658","1.16224","359.89200","0.00000","1.19979","0.19997"
"1.19979","26.70655","1.16181","360.50200","0.00000","1.19979","0.19997"
"1.19979","26.69446","1.16128","361.11200","0.00000","1.19979","0.19997"
"1.19979","26.68510","1.16087","361.72200","0.00000","1.19979","0.19997"
"1.19979","26.67132","1.16027","362.33200","0.00000","1.19979","0.19997"
"1.19979","26.65680","1.15964","362.94200","0.00000","1.19979","0.19997"
"1.19979","26.65798","1.15969","363.55200","0.00000","1.19979","0.19997"
"1.19979","26.63611","1.15874","364.16200","0.00000","1.19979","0.19997"
"1.19979","26.63558","1.15872","364.77200","0.00000","1.19979","0.19997"
"1.19979","26.61491","1.15782","365.38200","0.00000","1.19979","0.19997"
"1.19979","26.60939","1.15758","365.99200","0.00000","1.19979","0.19997"
"1.19979","26.60620","1.15744","366.60200","0.00000","1.19979","0.19997"
"1.19979","26.59155","1.15680","367.21200","0.00000","1.19979","0.19997"
"1.19979","26.57826","1.15622","367.82200","0.00000","1.19979","0.19997"
"1.19979","26.56462","1.15563","368.43200","0.00000","1.19979","0.19997"
"1.19979","26.56406","1.15561","369.04200","0.00000","1.19979","0.19997"
"1.19979","26.54589","1.15482","369.65200","0.00000","1.19979","0.19997"
"1.19979","26.53823","1.15448","370.26200","0.00000","1.19979","0.19997"
"1.19979","26.52438","1.15388","370.87200","0.00000","1.19979","0.19997"
"1.19979","26.52474","1.15390","371.48200","0.00000","1.19979","0.19997"
"1.19979","26.50974","1.15324","372.09200","0.00000","1.19979","0.19997"
"1.19979","26.50738","1.15314","372.70200","0.00000","1.19979","0.19997"
"1.19979","26.49872","1.15276","373.31200","0.00000","1.19979","0.19997"
"1.19979","26.48516","1.15217","373.92200","0.00000","1.19979","0.19997"
"1.19979","26.47552","1.15175","374.53200","0.00000","1.19979","0.19997"
"1.19979","26.46765","1.15141","375.14200","0.00000","1.19979","0.19997"
"1.19979","26.45738","1.15097","375.75200","0.00000","1.19979","0.19997"
"1.19979","26.45314","1.15078","376.36200","0.00000","1.19979","0.19997"
"1.19979","26.44072","1.15024","376.97200","0.00000","1.19979","0.19997"
"1.19979","26.43695","1.15008","377.58200","0.00000","1.19979","0.19997"
"1.19979","26.42570","1.14959","378.19200","0.00000","1.19979","0.19997"
"1.19979","26.41697","1.14921","378.80200","0.00000","1.19979","0.19997"
"1.19979","26.41028","1.14892","379.41200","0.00000","1.19979","0.19997"
"1.19979","26.40326","1.14861","380.02200","0.00000","1.19979","0.19997"
"1.19979","26.39305","1.14817","380.63200","0.00000","1.19979","0.19997"
"1.19979","26.38641","1.14788","381.24200","0.00000","1.19979","0.19997"
"1.19979","26.37064","1.14719","381.85200","0.00000","1.19979","0.19997"
"1.19979","26.37075","1.14720","382.46200","0.00000","1.19979","0.19997"
"1.19979","26.36237","1.14683","383.07200","0.00000","1.19979","0.19997"
"1.19979","26.34744","1.14618","383.68200","0.00000","1.19979","0.19997"
"1.19979","26.34168","1.14593","384.29200","0.00000","1.19979","0.19997"
"1.19979","26.33747","1.14575","384.90200","0.00000","1.19979","0.19997"
"1.19979","26.33124","1.14548","385.51200","0.00000","1.19979","0.19997"
"1.19979","26.31449","1.14475","386.12200","0.00000","1.19979","0.19997"
"1.19979","26.30736","1.14444","386.73200","0.00000","1.19979","0.19997"
"1.19979","26.29522","1.14391","387.34200","0.00000","1.19979","0.19997"
"1.19979","26.28977","1.14367","387.95200","0.00000","1.19979","0.19997"
"1.19979","26.28608","1.14351","388.56200","0.00000","1.19979","0.19997"
"1.19979","26.28099","1.14329","389.17200","0.00000","1.19979","0.19997"
"1.19979","26.27839","1.14318","389.78200","0.00000","1.19979","0.19997"
"1.19979","26.26050","1.14240","390.39200","0.00000","1.19979","0.19997"
"1.19979","26.25559","1.14219","391.00200","0.00000","1.19979","0.19997"
"1.19979","26.24778","1.14185","391.61200","0.00000","1.19979","0.19997"
"1.19979","26.23974","1.14150","392.22200","0.00000","1.19979","0.19997"
"1.19979","26.23149","1.14114","392.83200","0.00000","1.19979","0.19997"
"1.19979","26.22714","1.14095","393.44200","0.00000","1.19979","0.19997"
"1.19979","26.21588","1.14046","394.05200","0.00000","1.19979","0.19997"
"1.19979","26.20924","1.14017","394.66200","0.00000","1.19979","0.19997"
"1.19979","26.20461","1.13997","395.27200","0.00000","1.19979","0.19997"
"1.19979","26.19312","1.13947","395.88200","0.00000","1.19979","0.19997"
"1.19979","26.18665","1.13919","396.49200","0.00000","1.19979","0.19997"
"1.19979","26.18220","1.13899","397.10200","0.00000","1.19979","0.19997"
"1.19979","26.17925","1.13887","397.71200","0.00000","1.19979","0.19997"
"1.19979","26.16612","1.13830","398.32200","0.00000","1.19979","0.19997"
"1.19979","26.15845","1.13796","398.93200","0.00000","1.19979","0.19997"
"1.19979","26.14421","1.13734","399.54200","0.00000","1.19979","0.19997"
"1.19979","26.14462","1.13736","400.15200","0.00000","1.19979","0.19997"
"1.19979","26.13477","1.13693","400.76200","0.00000","1.19979","0.19997"
"1.19979","26.13015","1.13673","401.37200","0.00000","1.19979","0.19997"
"1.19979","26.12372","1.13645","401.98200","0.00000","1.19979","0.19997"
"1.19979","26.11236","1.13596","402.59200","0.00000","1.19979","0.19997"
"1.19979","26.10799","1.13577","403.20200","0.00000","1.19979","0.19997"
"1.19979","26.10240","1.13552","403.81200","0.00000","1.19979","0.19997"
"1.19979","26.09190","1.13507","404.42200","0.00000","1.19979","0.19997"
"1.19979","26.08582","1.13480","405.03200","0.00000","1.19979","0.19997"
"1.19979","26.08298","1.13468","405.64200","0.00000","1.19979","0.19997"
"1.19979","26.07322","1.13425","406.25200","0.00000","1.19979","0.19997"
"1.19979","26.07334","1.13426","406.86200","0.00000","1.19979","0.19997"
"1.19979","26.05383","1.13341","407.47200","0.00000","1.19979","0.19997"
"1.19979","26.05751","1.13357","408.08200","0.00000","1.19979","0.19997"
"1.19979","26.04479","1.13302","408.69200","0.00000","1.19979","0.19997"
"1.19979","26.04523","1.13304","409.30200","0.00000","1.19979","0.19997"
"1.19979","26.03885","1.13276","409.91200","0.00000","1.19979","0.19997"
"1.19979","26.02494","1.13215","410.52200","0.00000","1.19979","0.19997"
"1.19979","26.01603","1.13177","411.13200","0.00000","1.19979","0.19997"
"1.19979","26.01613","1.13177","411.74200","0.00000","1.19979","0.19997"
"1.19979","26.00812","1.13142","412.35200","0.00000","1.19979","0.19997"
"1.19979","26.00246","1.13118","412.96200","0.00000","1.19979","0.19997"
"1.19979","25.99658","1.13092","413.57200","0.00000","1.19979","0.19997"
"1.19979","25.98525","1.13043","414.18200","0.00000","1.19979","0.19997"
"1.19979","25.98747","1.13052","414.79200","0.00000","1.19979","0.19997"
"1.19979","25.98266","1.13031","415.40200","0.00000","1.19979","0.19997"
"1.19979","25.96293","1.12946","416.01200","0.00000","1.19979","0.19997"
"1.19979","25.96409","1.12951","416.62200","0.00000","1.19979","0.19997"
"1.19979","25.95946","1.12930","417.23200","0.00000","1.19979","0.19997"
"1.19979","25.94804","1.12881","417.84200","0.00000","1.19979","0.19997"
"1.19979","25.94262","1.12857","418.45200","0.00000","1.19979","0.19997"
"1.19979","25.93690","1.12832","419.06200","0.00000","1.19979","0.19997"
"1.19979","25.93385","1.12819","419.67200","0.00000","1.19979","0.19997"
"1.19979","25.93386","1.12819","419.92200","0.00000","1.19979","0.19997"