File: Rubber Stress Relaxation Raw Data - Small Samples-20210211/Specimen_RawData_7.csv
Specimen properties : Specimen label,"GCI2S1R1"
Specimen properties : Anvil height,"6.00000",mm
Specimen properties : Diameter,"6.00000",mm
Test : Rate 1,"0.24000",mm/min
Test : Start of hold value,"20.00000",%
Test : Duration,"120.00000",s

Extension,Load,Compressive stress,Time,PIP count,Compressive extension,Compressive strain (Extension)
(mm),(N),(MPa),(s),,(mm),(mm/mm)
"0.00000","-0.00855","-0.00030","0.00000","0.00000","0.00000","0.00000"
"0.00167","0.09047","0.00320","0.61000","0.00000","0.00167","0.00028"
"0.00458","0.24351","0.00861","1.22000","0.00000","0.00458","0.00076"
"0.00729","0.36406","0.01288","1.83000","0.00000","0.00729","0.00122"
"0.00958","0.47395","0.01676","2.44000","0.00000","0.00958","0.00160"
"0.01229","0.56003","0.01981","3.05000","0.00000","0.01229","0.00205"
"0.01458","0.65867","0.02330","3.66000","0.00000","0.01458","0.00243"
"0.01708","0.74736","0.02643","4.27000","0.00000","0.01708","0.00285"
"0.01958","0.83588","0.02956","4.88000","0.00000","0.01958","0.00326"
"0.02208","0.90912","0.03215","5.49000","0.00000","0.02208","0.00368"
"0.02458","0.99488","0.03519","6.10000","0.00000","0.02458","0.00410"
"0.02708","1.07381","0.03798","6.71000","0.00000","0.02708","0.00451"
"0.02958","1.13557","0.04016","7.32000","0.00000","0.02958","0.00493"
"0.03208","1.21303","0.04290","7.93000","0.00000","0.03208","0.00535"
"0.03438","1.28499","0.04545","8.54000","0.00000","0.03438","0.00573"
"0.03688","1.35107","0.04778","9.15000","0.00000","0.03688","0.00615"
"0.03917","1.42333","0.05034","9.76000","0.00000","0.03917","0.00653"
"0.04167","1.48220","0.05242","10.37000","0.00000","0.04167","0.00694"
"0.04417","1.55645","0.05505","10.98000","0.00000","0.04417","0.00736"
"0.04646","1.62885","0.05761","11.59000","0.00000","0.04646","0.00774"
"0.04875","1.68322","0.05953","12.20000","0.00000","0.04875","0.00813"
"0.05125","1.74660","0.06177","12.81000","0.00000","0.05125","0.00854"
"0.05354","1.80515","0.06384","13.42000","0.00000","0.05354","0.00892"
"0.05604","1.86743","0.06605","14.03000","0.00000","0.05604","0.00934"
"0.05854","1.94508","0.06879","14.64000","0.00000","0.05854","0.00976"
"0.06104","2.00627","0.07096","15.25000","0.00000","0.06104","0.01017"
"0.06354","2.06713","0.07311","15.86000","0.00000","0.06354","0.01059"
"0.06583","2.14071","0.07571","16.47000","0.00000","0.06583","0.01097"
"0.06833","2.18401","0.07724","17.08000","0.00000","0.06833","0.01139"
"0.07083","2.24117","0.07927","17.69000","0.00000","0.07083","0.01181"
"0.07333","2.31612","0.08192","18.30000","0.00000","0.07333","0.01222"
"0.07583","2.38506","0.08435","18.91000","0.00000","0.07583","0.01264"
"0.07833","2.43485","0.08612","19.52000","0.00000","0.07833","0.01306"
"0.08063","2.49347","0.08819","20.13000","0.00000","0.08063","0.01344"
"0.08292","2.55711","0.09044","20.74000","0.00000","0.08292","0.01382"
"0.08542","2.61761","0.09258","21.35000","0.00000","0.08542","0.01424"
"0.08792","2.67884","0.09474","21.96000","0.00000","0.08792","0.01465"
"0.09021","2.73365","0.09668","22.57000","0.00000","0.09021","0.01503"
"0.09271","2.80380","0.09916","23.18000","0.00000","0.09271","0.01545"
"0.09521","2.86481","0.10132","23.79000","0.00000","0.09521","0.01587"
"0.09771","2.92209","0.10335","24.40000","0.00000","0.09771","0.01628"
"0.10000","2.97198","0.10511","25.01000","0.00000","0.10000","0.01667"
"0.10250","3.04939","0.10785","25.62000","0.00000","0.10250","0.01708"
"0.10500","3.10988","0.10999","26.23000","0.00000","0.10500","0.01750"
"0.10750","3.16501","0.11194","26.84000","0.00000","0.10750","0.01792"
"0.11000","3.22673","0.11412","27.45000","0.00000","0.11000","0.01833"
"0.11250","3.28075","0.11603","28.06000","0.00000","0.11250","0.01875"
"0.11500","3.33876","0.11808","28.67000","0.00000","0.11500","0.01917"
"0.11750","3.39556","0.12009","29.28000","0.00000","0.11750","0.01958"
"0.11979","3.46420","0.12252","29.89000","0.00000","0.11979","0.01997"
"0.12208","3.50655","0.12402","30.50000","0.00000","0.12208","0.02035"
"0.12458","3.57639","0.12649","31.11000","0.00000","0.12458","0.02076"
"0.12688","3.62393","0.12817","31.72000","0.00000","0.12688","0.02115"
"0.12917","3.67720","0.13005","32.33000","0.00000","0.12917","0.02153"
"0.13167","3.74362","0.13240","32.94000","0.00000","0.13167","0.02194"
"0.13438","3.80644","0.13463","33.55000","0.00000","0.13438","0.02240"
"0.13667","3.85991","0.13652","34.16000","0.00000","0.13667","0.02278"
"0.13917","3.91900","0.13861","34.77000","0.00000","0.13917","0.02319"
"0.14146","3.97701","0.14066","35.38000","0.00000","0.14146","0.02358"
"0.14417","4.03775","0.14281","35.99000","0.00000","0.14417","0.02403"
"0.14646","4.09807","0.14494","36.60000","0.00000","0.14646","0.02441"
"0.14896","4.15913","0.14710","37.21000","0.00000","0.14896","0.02483"
"0.15146","4.22063","0.14927","37.82000","0.00000","0.15146","0.02524"
"0.15396","4.27873","0.15133","38.43000","0.00000","0.15396","0.02566"
"0.15646","4.33508","0.15332","39.04000","0.00000","0.15646","0.02608"
"0.15875","4.38156","0.15497","39.65000","0.00000","0.15875","0.02646"
"0.16125","4.45376","0.15752","40.26000","0.00000","0.16125","0.02688"
"0.16375","4.50095","0.15919","40.87000","0.00000","0.16375","0.02729"
"0.16604","4.56768","0.16155","41.48000","0.00000","0.16604","0.02767"
"0.16833","4.61487","0.16322","42.09000","0.00000","0.16833","0.02806"
"0.17083","4.67828","0.16546","42.70000","0.00000","0.17083","0.02847"
"0.17333","4.73247","0.16738","43.31000","0.00000","0.17333","0.02889"
"0.17563","4.78995","0.16941","43.92000","0.00000","0.17563","0.02927"
"0.17813","4.85172","0.17159","44.53000","0.00000","0.17813","0.02969"
"0.18063","4.91017","0.17366","45.14000","0.00000","0.18063","0.03010"
"0.18313","4.97374","0.17591","45.75000","0.00000","0.18313","0.03052"
"0.18563","5.03229","0.17798","46.36000","0.00000","0.18563","0.03094"
"0.18812","5.08496","0.17984","46.97000","0.00000","0.18812","0.03135"
"0.19063","5.15152","0.18220","47.58000","0.00000","0.19063","0.03177"
"0.19312","5.21340","0.18439","48.19000","0.00000","0.19312","0.03219"
"0.19542","5.26493","0.18621","48.80000","0.00000","0.19542","0.03257"
"0.19792","5.32544","0.18835","49.41000","0.00000","0.19792","0.03299"
"0.20042","5.38412","0.19042","50.02000","0.00000","0.20042","0.03340"
"0.20271","5.43637","0.19227","50.63000","0.00000","0.20271","0.03378"
"0.20521","5.49650","0.19440","51.24000","0.00000","0.20521","0.03420"
"0.20750","5.55256","0.19638","51.85000","0.00000","0.20750","0.03458"
"0.20979","5.60062","0.19808","52.46000","0.00000","0.20979","0.03497"
"0.21229","5.66927","0.20051","53.07000","0.00000","0.21229","0.03538"
"0.21479","5.72619","0.20252","53.68000","0.00000","0.21479","0.03580"
"0.21729","5.79481","0.20495","54.29000","0.00000","0.21729","0.03622"
"0.21979","5.84628","0.20677","54.90000","0.00000","0.21979","0.03663"
"0.22229","5.91907","0.20934","55.51000","0.00000","0.22229","0.03705"
"0.22458","5.98399","0.21164","56.12000","0.00000","0.22458","0.03743"
"0.22708","6.03367","0.21340","56.73000","0.00000","0.22708","0.03785"
"0.22958","6.09299","0.21550","57.34000","0.00000","0.22958","0.03826"
"0.23208","6.15857","0.21781","57.95000","0.00000","0.23208","0.03868"
"0.23458","6.21334","0.21975","58.56000","0.00000","0.23458","0.03910"
"0.23688","6.27240","0.22184","59.17000","0.00000","0.23688","0.03948"
"0.23938","6.32755","0.22379","59.78000","0.00000","0.23938","0.03990"
"0.24188","6.38470","0.22581","60.39000","0.00000","0.24188","0.04031"
"0.24417","6.43574","0.22762","61.00000","0.00000","0.24417","0.04069"
"0.24667","6.49682","0.22978","61.61000","0.00000","0.24667","0.04111"
"0.24896","6.54811","0.23159","62.22000","0.00000","0.24896","0.04149"
"0.25125","6.61319","0.23389","62.83000","0.00000","0.25125","0.04188"
"0.25375","6.66668","0.23579","63.44000","0.00000","0.25375","0.04229"
"0.25625","6.73452","0.23819","64.05000","0.00000","0.25625","0.04271"
"0.25875","6.78896","0.24011","64.66000","0.00000","0.25875","0.04313"
"0.26104","6.84402","0.24206","65.27000","0.00000","0.26104","0.04351"
"0.26354","6.90536","0.24423","65.88000","0.00000","0.26354","0.04392"
"0.26604","6.97156","0.24657","66.49000","0.00000","0.26604","0.04434"
"0.26854","7.02243","0.24837","67.10000","0.00000","0.26854","0.04476"
"0.27104","7.08604","0.25062","67.71000","0.00000","0.27104","0.04517"
"0.27354","7.14239","0.25261","68.32000","0.00000","0.27354","0.04559"
"0.27604","7.19802","0.25458","68.93000","0.00000","0.27604","0.04601"
"0.27833","7.24361","0.25619","69.54000","0.00000","0.27833","0.04639"
"0.28083","7.30663","0.25842","70.15000","0.00000","0.28083","0.04681"
"0.28333","7.35711","0.26020","70.76000","0.00000","0.28333","0.04722"
"0.28563","7.41667","0.26231","71.37000","0.00000","0.28563","0.04760"
"0.28792","7.46261","0.26394","71.98000","0.00000","0.28792","0.04799"
"0.29042","7.51023","0.26562","72.59000","0.00000","0.29042","0.04840"
"0.29271","7.56744","0.26764","73.20000","0.00000","0.29271","0.04878"
"0.29521","7.62896","0.26982","73.81000","0.00000","0.29521","0.04920"
"0.29771","7.67042","0.27129","74.42000","0.00000","0.29771","0.04962"
"0.30021","7.74143","0.27380","75.03000","0.00000","0.30021","0.05003"
"0.30250","7.79413","0.27566","75.64000","0.00000","0.30250","0.05042"
"0.30500","7.85180","0.27770","76.25000","0.00000","0.30500","0.05083"
"0.30750","7.89729","0.27931","76.86000","0.00000","0.30750","0.05125"
"0.31000","7.96077","0.28155","77.47000","0.00000","0.31000","0.05167"
"0.31229","8.00910","0.28326","78.08000","0.00000","0.31229","0.05205"
"0.31479","8.07432","0.28557","78.69000","0.00000","0.31479","0.05247"
"0.31729","8.11287","0.28693","79.30000","0.00000","0.31729","0.05288"
"0.31979","8.17498","0.28913","79.91000","0.00000","0.31979","0.05330"
"0.32229","8.22947","0.29106","80.52000","0.00000","0.32229","0.05372"
"0.32479","8.29223","0.29328","81.13000","0.00000","0.32479","0.05413"
"0.32729","8.33712","0.29487","81.74000","0.00000","0.32729","0.05455"
"0.32958","8.37444","0.29619","82.35000","0.00000","0.32958","0.05493"
"0.33188","8.43596","0.29836","82.96000","0.00000","0.33188","0.05531"
"0.33438","8.49320","0.30039","83.57000","0.00000","0.33438","0.05573"
"0.33667","8.54327","0.30216","84.18000","0.00000","0.33667","0.05611"
"0.33917","8.59806","0.30409","84.79000","0.00000","0.33917","0.05653"
"0.34167","8.65314","0.30604","85.40000","0.00000","0.34167","0.05694"
"0.34417","8.71153","0.30811","86.01000","0.00000","0.34417","0.05736"
"0.34646","8.76850","0.31012","86.62000","0.00000","0.34646","0.05774"
"0.34896","8.82159","0.31200","87.23000","0.00000","0.34896","0.05816"
"0.35167","8.87617","0.31393","87.84000","0.00000","0.35167","0.05861"
"0.35417","8.93523","0.31602","88.45000","0.00000","0.35417","0.05903"
"0.35646","8.98738","0.31786","89.06000","0.00000","0.35646","0.05941"
"0.35896","9.04034","0.31974","89.67000","0.00000","0.35896","0.05983"
"0.36125","9.09041","0.32151","90.28000","0.00000","0.36125","0.06021"
"0.36375","9.14779","0.32354","90.89000","0.00000","0.36375","0.06063"
"0.36625","9.20107","0.32542","91.50000","0.00000","0.36625","0.06104"
"0.36854","9.24041","0.32681","92.11000","0.00000","0.36854","0.06142"
"0.37104","9.28856","0.32852","92.72000","0.00000","0.37104","0.06184"
"0.37333","9.34317","0.33045","93.33000","0.00000","0.37333","0.06222"
"0.37583","9.40620","0.33268","93.94000","0.00000","0.37583","0.06264"
"0.37813","9.45894","0.33454","94.55000","0.00000","0.37813","0.06302"
"0.38063","9.51345","0.33647","95.16000","0.00000","0.38063","0.06344"
"0.38313","9.56575","0.33832","95.77000","0.00000","0.38313","0.06385"
"0.38563","9.62718","0.34049","96.38000","0.00000","0.38563","0.06427"
"0.38813","9.68002","0.34236","96.99000","0.00000","0.38813","0.06469"
"0.39062","9.73734","0.34439","97.60000","0.00000","0.39062","0.06510"
"0.39313","9.79745","0.34651","98.21000","0.00000","0.39313","0.06552"
"0.39542","9.84089","0.34805","98.82000","0.00000","0.39542","0.06590"
"0.39792","9.89088","0.34982","99.43000","0.00000","0.39792","0.06632"
"0.40021","9.94887","0.35187","100.04000","0.00000","0.40021","0.06670"
"0.40271","10.00603","0.35389","100.65000","0.00000","0.40271","0.06712"
"0.40521","10.06533","0.35599","101.26000","0.00000","0.40521","0.06753"
"0.40771","10.10645","0.35744","101.87000","0.00000","0.40771","0.06795"
"0.41021","10.15965","0.35932","102.48000","0.00000","0.41021","0.06837"
"0.41250","10.21319","0.36122","103.09000","0.00000","0.41250","0.06875"
"0.41500","10.26557","0.36307","103.70000","0.00000","0.41500","0.06917"
"0.41729","10.29796","0.36422","104.31000","0.00000","0.41729","0.06955"
"0.41979","10.36706","0.36666","104.92000","0.00000","0.41979","0.06997"
"0.42229","10.43189","0.36895","105.53000","0.00000","0.42229","0.07038"
"0.42479","10.48686","0.37090","106.14000","0.00000","0.42479","0.07080"
"0.42708","10.54280","0.37288","106.75000","0.00000","0.42708","0.07118"
"0.42958","10.59770","0.37482","107.36000","0.00000","0.42958","0.07160"
"0.43208","10.65524","0.37685","107.97000","0.00000","0.43208","0.07201"
"0.43458","10.70905","0.37876","108.58000","0.00000","0.43458","0.07243"
"0.43688","10.74506","0.38003","109.19000","0.00000","0.43688","0.07281"
"0.43938","10.80812","0.38226","109.80000","0.00000","0.43938","0.07323"
"0.44188","10.87220","0.38453","110.41000","0.00000","0.44188","0.07365"
"0.44438","10.91167","0.38592","111.02000","0.00000","0.44438","0.07406"
"0.44688","10.95281","0.38738","111.63000","0.00000","0.44688","0.07448"
"0.44917","11.00498","0.38922","112.24000","0.00000","0.44917","0.07486"
"0.45167","11.07559","0.39172","112.85000","0.00000","0.45167","0.07528"
"0.45417","11.12927","0.39362","113.46000","0.00000","0.45417","0.07569"
"0.45646","11.17971","0.39540","114.07000","0.00000","0.45646","0.07608"
"0.45875","11.22766","0.39710","114.68000","0.00000","0.45875","0.07646"
"0.46125","11.28934","0.39928","115.29000","0.00000","0.46125","0.07688"
"0.46375","11.34653","0.40130","115.90000","0.00000","0.46375","0.07729"
"0.46625","11.40076","0.40322","116.51000","0.00000","0.46625","0.07771"
"0.46875","11.45587","0.40517","117.12000","0.00000","0.46875","0.07813"
"0.47104","11.50362","0.40686","117.73000","0.00000","0.47104","0.07851"
"0.47354","11.56826","0.40914","118.34000","0.00000","0.47354","0.07892"
"0.47604","11.61433","0.41077","118.95000","0.00000","0.47604","0.07934"
"0.47833","11.66997","0.41274","119.56000","0.00000","0.47833","0.07972"
"0.48083","11.71451","0.41432","120.17000","0.00000","0.48083","0.08014"
"0.48333","11.76565","0.41612","120.78000","0.00000","0.48333","0.08056"
"0.48562","11.82096","0.41808","121.39000","0.00000","0.48562","0.08094"
"0.48792","11.87267","0.41991","122.00000","0.00000","0.48792","0.08132"
"0.49042","11.93090","0.42197","122.61000","0.00000","0.49042","0.08174"
"0.49312","11.99084","0.42409","123.22000","0.00000","0.49312","0.08219"
"0.49563","12.03419","0.42562","123.83000","0.00000","0.49563","0.08260"
"0.49792","12.09326","0.42771","124.44000","0.00000","0.49792","0.08299"
"0.50042","12.14393","0.42950","125.05000","0.00000","0.50042","0.08340"
"0.50271","12.21091","0.43187","125.66000","0.00000","0.50271","0.08378"
"0.50500","12.23796","0.43283","126.27000","0.00000","0.50500","0.08417"
"0.50750","12.28835","0.43461","126.88000","0.00000","0.50750","0.08458"
"0.51000","12.37333","0.43762","127.49000","0.00000","0.51000","0.08500"
"0.51250","12.42249","0.43936","128.10000","0.00000","0.51250","0.08542"
"0.51479","12.44776","0.44025","128.71000","0.00000","0.51479","0.08580"
"0.51729","12.53074","0.44318","129.32000","0.00000","0.51729","0.08622"
"0.51979","12.58929","0.44526","129.93000","0.00000","0.51979","0.08663"
"0.52229","12.63743","0.44696","130.54000","0.00000","0.52229","0.08705"
"0.52458","12.68186","0.44853","131.15000","0.00000","0.52458","0.08743"
"0.52708","12.73810","0.45052","131.76000","0.00000","0.52708","0.08785"
"0.52958","12.78287","0.45210","132.37000","0.00000","0.52958","0.08826"
"0.53208","12.84715","0.45437","132.98000","0.00000","0.53208","0.08868"
"0.53438","12.90772","0.45652","133.59000","0.00000","0.53438","0.08906"
"0.53688","12.95393","0.45815","134.20000","0.00000","0.53688","0.08948"
"0.53938","13.00819","0.46007","134.81000","0.00000","0.53938","0.08990"
"0.54188","13.06792","0.46218","135.42000","0.00000","0.54188","0.09031"
"0.54438","13.12330","0.46414","136.03000","0.00000","0.54438","0.09073"
"0.54667","13.16855","0.46574","136.64000","0.00000","0.54667","0.09111"
"0.54917","13.23125","0.46796","137.25000","0.00000","0.54917","0.09153"
"0.55146","13.28892","0.47000","137.86000","0.00000","0.55146","0.09191"
"0.55396","13.34183","0.47187","138.47000","0.00000","0.55396","0.09233"
"0.55625","13.40412","0.47407","139.08000","0.00000","0.55625","0.09271"
"0.55875","13.45331","0.47581","139.69000","0.00000","0.55875","0.09313"
"0.56125","13.50886","0.47778","140.30000","0.00000","0.56125","0.09354"
"0.56375","13.55692","0.47948","140.91000","0.00000","0.56375","0.09396"
"0.56625","13.61690","0.48160","141.52000","0.00000","0.56625","0.09438"
"0.56854","13.65844","0.48307","142.13000","0.00000","0.56854","0.09476"
"0.57104","13.72381","0.48538","142.74000","0.00000","0.57104","0.09517"
"0.57354","13.78402","0.48751","143.35000","0.00000","0.57354","0.09559"
"0.57604","13.84005","0.48949","143.96000","0.00000","0.57604","0.09601"
"0.57854","13.89260","0.49135","144.57000","0.00000","0.57854","0.09642"
"0.58104","13.95870","0.49369","145.18000","0.00000","0.58104","0.09684"
"0.58333","14.00531","0.49534","145.79000","0.00000","0.58333","0.09722"
"0.58583","14.05187","0.49698","146.40000","0.00000","0.58583","0.09764"
"0.58833","14.12431","0.49955","147.01000","0.00000","0.58833","0.09806"
"0.59083","14.17099","0.50120","147.62000","0.00000","0.59083","0.09847"
"0.59312","14.22868","0.50324","148.23000","0.00000","0.59312","0.09885"
"0.59542","14.26783","0.50462","148.84000","0.00000","0.59542","0.09924"
"0.59792","14.32349","0.50659","149.45000","0.00000","0.59792","0.09965"
"0.60042","14.38805","0.50887","150.06000","0.00000","0.60042","0.10007"
"0.60271","14.44240","0.51080","150.67000","0.00000","0.60271","0.10045"
"0.60521","14.50070","0.51286","151.28000","0.00000","0.60521","0.10087"
"0.60750","14.55864","0.51491","151.89000","0.00000","0.60750","0.10125"
"0.61000","14.61046","0.51674","152.50000","0.00000","0.61000","0.10167"
"0.61250","14.66858","0.51880","153.11000","0.00000","0.61250","0.10208"
"0.61500","14.72614","0.52083","153.72000","0.00000","0.61500","0.10250"
"0.61750","14.77438","0.52254","154.33000","0.00000","0.61750","0.10292"
"0.62000","14.84004","0.52486","154.94000","0.00000","0.62000","0.10333"
"0.62250","14.89164","0.52668","155.55000","0.00000","0.62250","0.10375"
"0.62479","14.95559","0.52895","156.16000","0.00000","0.62479","0.10413"
"0.62729","15.01174","0.53093","156.77000","0.00000","0.62729","0.10455"
"0.62979","15.06826","0.53293","157.38000","0.00000","0.62979","0.10497"
"0.63208","15.10664","0.53429","157.99000","0.00000","0.63208","0.10535"
"0.63438","15.16951","0.53651","158.60000","0.00000","0.63438","0.10573"
"0.63688","15.22657","0.53853","159.21000","0.00000","0.63688","0.10615"
"0.63938","15.27788","0.54034","159.82000","0.00000","0.63938","0.10656"
"0.64188","15.33034","0.54220","160.43000","0.00000","0.64188","0.10698"
"0.64417","15.39563","0.54451","161.04000","0.00000","0.64417","0.10736"
"0.64667","15.44634","0.54630","161.65000","0.00000","0.64667","0.10778"
"0.64917","15.51024","0.54856","162.26000","0.00000","0.64917","0.10819"
"0.65146","15.56378","0.55046","162.87000","0.00000","0.65146","0.10858"
"0.65417","15.62752","0.55271","163.48000","0.00000","0.65417","0.10903"
"0.65667","15.67995","0.55456","164.09000","0.00000","0.65667","0.10944"
"0.65917","15.74222","0.55677","164.70000","0.00000","0.65917","0.10986"
"0.66146","15.78942","0.55844","165.31000","0.00000","0.66146","0.11024"
"0.66396","15.84700","0.56047","165.92000","0.00000","0.66396","0.11066"
"0.66646","15.89987","0.56234","166.53000","0.00000","0.66646","0.11108"
"0.66875","15.96956","0.56481","167.14000","0.00000","0.66875","0.11146"
"0.67125","16.01222","0.56632","167.75000","0.00000","0.67125","0.11188"
"0.67354","16.05235","0.56774","168.36000","0.00000","0.67354","0.11226"
"0.67583","16.11754","0.57004","168.97000","0.00000","0.67583","0.11264"
"0.67833","16.18587","0.57246","169.58000","0.00000","0.67833","0.11306"
"0.68083","16.24218","0.57445","170.19000","0.00000","0.68083","0.11347"
"0.68333","16.30233","0.57658","170.80000","0.00000","0.68333","0.11389"
"0.68563","16.34938","0.57824","171.41000","0.00000","0.68563","0.11427"
"0.68813","16.41370","0.58052","172.02000","0.00000","0.68813","0.11469"
"0.69063","16.47328","0.58262","172.63000","0.00000","0.69063","0.11510"
"0.69313","16.53395","0.58477","173.24000","0.00000","0.69313","0.11552"
"0.69542","16.58920","0.58672","173.85000","0.00000","0.69542","0.11590"
"0.69792","16.65023","0.58888","174.46000","0.00000","0.69792","0.11632"
"0.70063","16.71731","0.59125","175.07000","0.00000","0.70063","0.11677"
"0.70292","16.77035","0.59313","175.68000","0.00000","0.70292","0.11715"
"0.70542","16.81810","0.59482","176.29000","0.00000","0.70542","0.11757"
"0.70792","16.87710","0.59691","176.90000","0.00000","0.70792","0.11799"
"0.71021","16.93351","0.59890","177.51000","0.00000","0.71021","0.11837"
"0.71250","16.97128","0.60024","178.12000","0.00000","0.71250","0.11875"
"0.71500","17.04149","0.60272","178.73000","0.00000","0.71500","0.11917"
"0.71750","17.09733","0.60469","179.34000","0.00000","0.71750","0.11958"
"0.72000","17.17356","0.60739","179.95000","0.00000","0.72000","0.12000"
"0.72229","17.23031","0.60940","180.56000","0.00000","0.72229","0.12038"
"0.72458","17.27436","0.61096","181.17000","0.00000","0.72458","0.12076"
"0.72708","17.34239","0.61336","181.78000","0.00000","0.72708","0.12118"
"0.72958","17.39537","0.61524","182.39000","0.00000","0.72958","0.12160"
"0.73208","17.45901","0.61749","183.00000","0.00000","0.73208","0.12201"
"0.73458","17.51182","0.61935","183.61000","0.00000","0.73458","0.12243"
"0.73688","17.56596","0.62127","184.22000","0.00000","0.73688","0.12281"
"0.73958","17.64194","0.62396","184.83000","0.00000","0.73958","0.12326"
"0.74208","17.69569","0.62586","185.44000","0.00000","0.74208","0.12368"
"0.74438","17.74837","0.62772","186.05000","0.00000","0.74438","0.12406"
"0.74687","17.80219","0.62962","186.66000","0.00000","0.74687","0.12448"
"0.74938","17.85899","0.63163","187.27000","0.00000","0.74938","0.12490"
"0.75167","17.92511","0.63397","187.88000","0.00000","0.75167","0.12528"
"0.75396","17.96129","0.63525","188.49000","0.00000","0.75396","0.12566"
"0.75646","18.03075","0.63771","189.10000","0.00000","0.75646","0.12608"
"0.75896","18.10519","0.64034","189.71000","0.00000","0.75896","0.12649"
"0.76125","18.15214","0.64200","190.32000","0.00000","0.76125","0.12687"
"0.76375","18.21122","0.64409","190.93000","0.00000","0.76375","0.12729"
"0.76604","18.28276","0.64662","191.54000","0.00000","0.76604","0.12767"
"0.76854","18.34184","0.64871","192.15000","0.00000","0.76854","0.12809"
"0.77104","18.40863","0.65107","192.76000","0.00000","0.77104","0.12851"
"0.77354","18.47024","0.65325","193.37000","0.00000","0.77354","0.12892"
"0.77604","18.51939","0.65499","193.98000","0.00000","0.77604","0.12934"
"0.77854","18.59513","0.65767","194.59000","0.00000","0.77854","0.12976"
"0.78104","18.65075","0.65964","195.20000","0.00000","0.78104","0.13017"
"0.78354","18.71056","0.66175","195.81000","0.00000","0.78354","0.13059"
"0.78604","18.76939","0.66383","196.42000","0.00000","0.78604","0.13101"
"0.78833","18.82330","0.66574","197.03000","0.00000","0.78833","0.13139"
"0.79083","18.88500","0.66792","197.64000","0.00000","0.79083","0.13181"
"0.79313","18.92002","0.66916","198.25000","0.00000","0.79313","0.13219"
"0.79542","18.99221","0.67171","198.86000","0.00000","0.79542","0.13257"
"0.79792","19.06690","0.67435","199.47000","0.00000","0.79792","0.13299"
"0.80042","19.11480","0.67605","200.08000","0.00000","0.80042","0.13340"
"0.80271","19.17916","0.67832","200.69000","0.00000","0.80271","0.13378"
"0.80521","19.24362","0.68060","201.30000","0.00000","0.80521","0.13420"
"0.80771","19.30643","0.68283","201.91000","0.00000","0.80771","0.13462"
"0.81000","19.37821","0.68536","202.52000","0.00000","0.81000","0.13500"
"0.81250","19.43790","0.68748","203.13000","0.00000","0.81250","0.13542"
"0.81500","19.48713","0.68922","203.74000","0.00000","0.81500","0.13583"
"0.81750","19.56424","0.69194","204.35000","0.00000","0.81750","0.13625"
"0.82000","19.62498","0.69409","204.96000","0.00000","0.82000","0.13667"
"0.82250","19.68769","0.69631","205.57000","0.00000","0.82250","0.13708"
"0.82500","19.73844","0.69810","206.18000","0.00000","0.82500","0.13750"
"0.82750","19.80297","0.70039","206.79000","0.00000","0.82750","0.13792"
"0.82979","19.86110","0.70244","207.40000","0.00000","0.82979","0.13830"
"0.83208","19.90483","0.70399","208.01000","0.00000","0.83208","0.13868"
"0.83458","19.97394","0.70643","208.62000","0.00000","0.83458","0.13910"
"0.83708","20.03999","0.70877","209.23000","0.00000","0.83708","0.13951"
"0.83938","20.09891","0.71085","209.84000","0.00000","0.83938","0.13990"
"0.84188","20.16294","0.71312","210.45000","0.00000","0.84188","0.14031"
"0.84417","20.22617","0.71535","211.06000","0.00000","0.84417","0.14069"
"0.84667","20.28792","0.71754","211.67000","0.00000","0.84667","0.14111"
"0.84917","20.35329","0.71985","212.28000","0.00000","0.84917","0.14153"
"0.85167","20.43114","0.72260","212.89000","0.00000","0.85167","0.14194"
"0.85396","20.48290","0.72443","213.50000","0.00000","0.85396","0.14233"
"0.85667","20.55200","0.72688","214.11000","0.00000","0.85667","0.14278"
"0.85917","20.62309","0.72939","214.72000","0.00000","0.85917","0.14319"
"0.86167","20.68438","0.73156","215.33000","0.00000","0.86167","0.14361"
"0.86396","20.73934","0.73350","215.94000","0.00000","0.86396","0.14399"
"0.86646","20.80478","0.73582","216.55000","0.00000","0.86646","0.14441"
"0.86896","20.86426","0.73792","217.16000","0.00000","0.86896","0.14483"
"0.87146","20.91540","0.73973","217.77000","0.00000","0.87146","0.14524"
"0.87354","20.97135","0.74171","218.38000","0.00000","0.87354","0.14559"
"0.87604","21.04497","0.74431","218.99000","0.00000","0.87604","0.14601"
"0.87854","21.10114","0.74630","219.60000","0.00000","0.87854","0.14642"
"0.88083","21.16829","0.74868","220.21000","0.00000","0.88083","0.14681"
"0.88313","21.21915","0.75047","220.82000","0.00000","0.88313","0.14719"
"0.88583","21.29445","0.75314","221.43000","0.00000","0.88583","0.14764"
"0.88813","21.36370","0.75559","222.04000","0.00000","0.88813","0.14802"
"0.89062","21.43312","0.75804","222.65000","0.00000","0.89062","0.14844"
"0.89312","21.49071","0.76008","223.26000","0.00000","0.89312","0.14885"
"0.89563","21.55932","0.76250","223.87000","0.00000","0.89563","0.14927"
"0.89812","21.62229","0.76473","224.48000","0.00000","0.89812","0.14969"
"0.90062","21.70273","0.76758","225.09000","0.00000","0.90062","0.15010"
"0.90313","21.77364","0.77008","225.70000","0.00000","0.90313","0.15052"
"0.90542","21.82376","0.77186","226.31000","0.00000","0.90542","0.15090"
"0.90792","21.88413","0.77399","226.92000","0.00000","0.90792","0.15132"
"0.91042","21.94917","0.77629","227.53000","0.00000","0.91042","0.15174"
"0.91271","22.00266","0.77819","228.14000","0.00000","0.91271","0.15212"
"0.91521","22.05372","0.77999","228.75000","0.00000","0.91521","0.15253"
"0.91750","22.13584","0.78290","229.36000","0.00000","0.91750","0.15292"
"0.92000","22.19491","0.78498","229.97000","0.00000","0.92000","0.15333"
"0.92229","22.23562","0.78642","230.58000","0.00000","0.92229","0.15372"
"0.92479","22.33176","0.78982","231.19000","0.00000","0.92479","0.15413"
"0.92729","22.40628","0.79246","231.80000","0.00000","0.92729","0.15455"
"0.92958","22.45588","0.79421","232.41000","0.00000","0.92958","0.15493"
"0.93208","22.52088","0.79651","233.02000","0.00000","0.93208","0.15535"
"0.93458","22.60051","0.79933","233.63000","0.00000","0.93458","0.15576"
"0.93708","22.66472","0.80160","234.24000","0.00000","0.93708","0.15618"
"0.93958","22.75066","0.80464","234.85000","0.00000","0.93958","0.15660"
"0.94208","22.80619","0.80660","235.46000","0.00000","0.94208","0.15701"
"0.94458","22.87366","0.80899","236.07000","0.00000","0.94458","0.15743"
"0.94708","22.94551","0.81153","236.68000","0.00000","0.94708","0.15785"
"0.94938","22.99813","0.81339","237.29000","0.00000","0.94938","0.15823"
"0.95187","23.06026","0.81559","237.90000","0.00000","0.95187","0.15865"
"0.95417","23.11289","0.81745","238.51000","0.00000","0.95417","0.15903"
"0.95646","23.18709","0.82008","239.12000","0.00000","0.95646","0.15941"
"0.95896","23.25454","0.82246","239.73000","0.00000","0.95896","0.15983"
"0.96125","23.31821","0.82471","240.34000","0.00000","0.96125","0.16021"
"0.96375","23.38805","0.82718","240.95000","0.00000","0.96375","0.16062"
"0.96625","23.46507","0.82991","241.56000","0.00000","0.96625","0.16104"
"0.96875","23.53644","0.83243","242.17000","0.00000","0.96875","0.16146"
"0.97125","23.61321","0.83515","242.78000","0.00000","0.97125","0.16187"
"0.97354","23.67769","0.83743","243.39000","0.00000","0.97354","0.16226"
"0.97604","23.75190","0.84005","244.00000","0.00000","0.97604","0.16267"
"0.97854","23.81269","0.84220","244.61000","0.00000","0.97854","0.16309"
"0.98104","23.88140","0.84463","245.22000","0.00000","0.98104","0.16351"
"0.98354","23.94913","0.84703","245.83000","0.00000","0.98354","0.16392"
"0.98604","24.02270","0.84963","246.44000","0.00000","0.98604","0.16434"
"0.98854","24.08533","0.85184","247.05000","0.00000","0.98854","0.16476"
"0.99083","24.15543","0.85432","247.66000","0.00000","0.99083","0.16514"
"0.99333","24.22819","0.85690","248.27000","0.00000","0.99333","0.16556"
"0.99583","24.29660","0.85932","248.88000","0.00000","0.99583","0.16597"
"0.99813","24.35936","0.86154","249.49000","0.00000","0.99813","0.16635"
"1.00063","24.40452","0.86313","250.10000","0.00000","1.00063","0.16677"
"1.00292","24.47211","0.86552","250.71000","0.00000","1.00292","0.16715"
"1.00542","24.56145","0.86868","251.32000","0.00000","1.00542","0.16757"
"1.00771","24.62340","0.87087","251.93000","0.00000","1.00771","0.16795"
"1.01021","24.69188","0.87330","252.54000","0.00000","1.01021","0.16837"
"1.01250","24.77127","0.87610","253.15000","0.00000","1.01250","0.16875"
"1.01500","24.85335","0.87901","253.76000","0.00000","1.01500","0.16917"
"1.01771","24.92951","0.88170","254.37000","0.00000","1.01771","0.16962"
"1.02021","25.00246","0.88428","254.98000","0.00000","1.02021","0.17003"
"1.02250","25.06844","0.88661","255.59000","0.00000","1.02250","0.17042"
"1.02500","25.14080","0.88917","256.20000","0.00000","1.02500","0.17083"
"1.02750","25.19878","0.89122","256.81000","0.00000","1.02750","0.17125"
"1.03000","25.26535","0.89358","257.42000","0.00000","1.03000","0.17167"
"1.03229","25.34019","0.89623","258.03000","0.00000","1.03229","0.17205"
"1.03479","25.41705","0.89894","258.64000","0.00000","1.03479","0.17247"
"1.03729","25.48467","0.90134","259.25000","0.00000","1.03729","0.17288"
"1.03958","25.56054","0.90402","259.86000","0.00000","1.03958","0.17326"
"1.04188","25.59751","0.90533","260.47000","0.00000","1.04188","0.17365"
"1.04438","25.68336","0.90836","261.08000","0.00000","1.04438","0.17406"
"1.04667","25.75114","0.91076","261.69000","0.00000","1.04667","0.17444"
"1.04917","25.83490","0.91372","262.30000","0.00000","1.04917","0.17486"
"1.05167","25.90921","0.91635","262.91000","0.00000","1.05167","0.17528"
"1.05417","25.98632","0.91908","263.52000","0.00000","1.05417","0.17569"
"1.05667","26.06752","0.92195","264.13000","0.00000","1.05667","0.17611"
"1.05917","26.14282","0.92461","264.74000","0.00000","1.05917","0.17653"
"1.06167","26.22091","0.92737","265.35000","0.00000","1.06167","0.17694"
"1.06417","26.30169","0.93023","265.96000","0.00000","1.06417","0.17736"
"1.06646","26.36466","0.93246","266.57000","0.00000","1.06646","0.17774"
"1.06896","26.44430","0.93528","267.18000","0.00000","1.06896","0.17816"
"1.07146","26.49599","0.93710","267.79000","0.00000","1.07146","0.17858"
"1.07396","26.56262","0.93946","268.40000","0.00000","1.07396","0.17899"
"1.07625","26.64541","0.94239","269.01000","0.00000","1.07625","0.17938"
"1.07875","26.72486","0.94520","269.62000","0.00000","1.07875","0.17979"
"1.08104","26.78723","0.94740","270.23000","0.00000","1.08104","0.18017"
"1.08333","26.83152","0.94897","270.84000","0.00000","1.08333","0.18056"
"1.08583","26.92517","0.95228","271.45000","0.00000","1.08583","0.18097"
"1.08833","27.00516","0.95511","272.06000","0.00000","1.08833","0.18139"
"1.09063","27.06491","0.95723","272.67000","0.00000","1.09063","0.18177"
"1.09313","27.16499","0.96076","273.28000","0.00000","1.09313","0.18219"
"1.09563","27.24251","0.96351","273.89000","0.00000","1.09563","0.18260"
"1.09812","27.32695","0.96649","274.50000","0.00000","1.09812","0.18302"
"1.10063","27.41235","0.96951","275.11000","0.00000","1.10063","0.18344"
"1.10313","27.47875","0.97186","275.72000","0.00000","1.10313","0.18385"
"1.10563","27.55656","0.97461","276.33000","0.00000","1.10563","0.18427"
"1.10813","27.62745","0.97712","276.94000","0.00000","1.10813","0.18469"
"1.11042","27.69681","0.97957","277.55000","0.00000","1.11042","0.18507"
"1.11292","27.76686","0.98205","278.16000","0.00000","1.11292","0.18549"
"1.11542","27.85618","0.98521","278.77000","0.00000","1.11542","0.18590"
"1.11771","27.91995","0.98747","279.38000","0.00000","1.11771","0.18628"
"1.12021","27.99529","0.99013","279.99000","0.00000","1.12021","0.18670"
"1.12250","28.04880","0.99202","280.60000","0.00000","1.12250","0.18708"
"1.12479","28.13193","0.99496","281.21000","0.00000","1.12479","0.18747"
"1.12729","28.21214","0.99780","281.82000","0.00000","1.12729","0.18788"
"1.12979","28.28799","1.00048","282.43000","0.00000","1.12979","0.18830"
"1.13229","28.38376","1.00387","283.04000","0.00000","1.13229","0.18872"
"1.13458","28.45746","1.00648","283.65000","0.00000","1.13458","0.18910"
"1.13708","28.53943","1.00938","284.26000","0.00000","1.13708","0.18951"
"1.13958","28.61488","1.01204","284.87000","0.00000","1.13958","0.18993"
"1.14188","28.69736","1.01496","285.48000","0.00000","1.14188","0.19031"
"1.14438","28.78687","1.01813","286.09000","0.00000","1.14438","0.19073"
"1.14688","28.86792","1.02099","286.70000","0.00000","1.14688","0.19115"
"1.14938","28.91663","1.02272","287.31000","0.00000","1.14938","0.19156"
"1.15167","28.98874","1.02527","287.92000","0.00000","1.15167","0.19194"
"1.15417","29.09466","1.02901","288.53000","0.00000","1.15417","0.19236"
"1.15688","29.18646","1.03226","289.14000","0.00000","1.15688","0.19281"
"1.15917","29.25314","1.03462","289.75000","0.00000","1.15917","0.19319"
"1.16167","29.31703","1.03688","290.36000","0.00000","1.16167","0.19361"
"1.16396","29.38210","1.03918","290.97000","0.00000","1.16396","0.19399"
"1.16646","29.48222","1.04272","291.58000","0.00000","1.16646","0.19441"
"1.16875","29.55585","1.04532","292.19000","0.00000","1.16875","0.19479"
"1.17125","29.62238","1.04768","292.80000","0.00000","1.17125","0.19521"
"1.17354","29.71830","1.05107","293.41000","0.00000","1.17354","0.19559"
"1.17625","29.80545","1.05415","294.02000","0.00000","1.17625","0.19604"
"1.17854","29.88745","1.05705","294.63000","0.00000","1.17854","0.19642"
"1.18104","29.96318","1.05973","295.24000","0.00000","1.18104","0.19684"
"1.18354","30.05255","1.06289","295.85000","0.00000","1.18354","0.19726"
"1.18604","30.14220","1.06606","296.46000","0.00000","1.18604","0.19767"
"1.18854","30.21353","1.06858","297.07000","0.00000","1.18854","0.19809"
"1.19083","30.28966","1.07128","297.68000","0.00000","1.19083","0.19847"
"1.19333","30.34841","1.07336","298.29000","0.00000","1.19333","0.19889"
"1.19583","30.45352","1.07707","298.90000","0.00000","1.19583","0.19931"
"1.19833","30.53192","1.07985","299.51000","0.00000","1.19833","0.19972"
"1.20021","30.54893","1.08045","300.11200","0.00000","1.20021","0.20003"
"1.20021","30.33888","1.07302","300.72200","0.00000","1.20021","0.20003"
"1.20021","30.20552","1.06830","301.33200","0.00000","1.20021","0.20003"
"1.20021","30.05879","1.06311","301.94200","0.00000","1.20021","0.20003"
"1.20021","29.95916","1.05959","302.55200","0.00000","1.20021","0.20003"
"1.20021","29.85657","1.05596","303.16200","0.00000","1.20021","0.20003"
"1.20021","29.77954","1.05324","303.77200","0.00000","1.20021","0.20003"
"1.20021","29.69717","1.05032","304.38200","0.00000","1.20021","0.20003"
"1.19938","29.57104","1.04586","304.99200","0.00000","1.19938","0.19990"
"1.19979","29.54274","1.04486","305.60200","0.00000","1.19979","0.19997"
"1.19979","29.47033","1.04230","306.21200","0.00000","1.19979","0.19997"
"1.19979","29.41069","1.04019","306.82200","0.00000","1.19979","0.19997"
"1.19979","29.36159","1.03845","307.43200","0.00000","1.19979","0.19997"
"1.19979","29.31063","1.03665","308.04200","0.00000","1.19979","0.19997"
"1.19979","29.26531","1.03505","308.65200","0.00000","1.19979","0.19997"
"1.19979","29.20853","1.03304","309.26200","0.00000","1.19979","0.19997"
"1.19979","29.16275","1.03142","309.87200","0.00000","1.19979","0.19997"
"1.19979","29.12233","1.02999","310.48200","0.00000","1.19979","0.19997"
"1.19979","29.07915","1.02846","311.09200","0.00000","1.19979","0.19997"
"1.19979","29.04324","1.02719","311.70200","0.00000","1.19979","0.19997"
"1.19979","29.00738","1.02593","312.31200","0.00000","1.19979","0.19997"
"1.19979","28.97110","1.02464","312.92200","0.00000","1.19979","0.19997"
"1.19979","28.92943","1.02317","313.53200","0.00000","1.19979","0.19997"
"1.19979","28.89854","1.02208","314.14200","0.00000","1.19979","0.19997"
"1.19979","28.86334","1.02083","314.75200","0.00000","1.19979","0.19997"
"1.19979","28.82641","1.01953","315.36200","0.00000","1.19979","0.19997"
"1.19979","28.79647","1.01847","315.97200","0.00000","1.19979","0.19997"
"1.19979","28.76338","1.01730","316.58200","0.00000","1.19979","0.19997"
"1.19979","28.73121","1.01616","317.19200","0.00000","1.19979","0.19997"
"1.19979","28.71046","1.01542","317.80200","0.00000","1.19979","0.19997"
"1.19979","28.67442","1.01415","318.41200","0.00000","1.19979","0.19997"
"1.19979","28.64794","1.01321","319.02200","0.00000","1.19979","0.19997"
"1.19979","28.61993","1.01222","319.63200","0.00000","1.19979","0.19997"
"1.19979","28.58693","1.01106","320.24200","0.00000","1.19979","0.19997"
"1.19979","28.56714","1.01036","320.85200","0.00000","1.19979","0.19997"
"1.19979","28.53861","1.00935","321.46200","0.00000","1.19979","0.19997"
"1.19979","28.51622","1.00855","322.07200","0.00000","1.19979","0.19997"
"1.19979","28.48658","1.00751","322.68200","0.00000","1.19979","0.19997"
"1.19979","28.46761","1.00684","323.29200","0.00000","1.19979","0.19997"
"1.19979","28.44395","1.00600","323.90200","0.00000","1.19979","0.19997"
"1.19979","28.41558","1.00500","324.51200","0.00000","1.19979","0.19997"
"1.19979","28.39915","1.00441","325.12200","0.00000","1.19979","0.19997"
"1.19979","28.37650","1.00361","325.73200","0.00000","1.19979","0.19997"
"1.19979","28.34995","1.00267","326.34200","0.00000","1.19979","0.19997"
"1.19979","28.32838","1.00191","326.95200","0.00000","1.19979","0.19997"
"1.19979","28.30630","1.00113","327.56200","0.00000","1.19979","0.19997"
"1.19979","28.27751","1.00011","328.17200","0.00000","1.19979","0.19997"
"1.19979","28.26554","0.99969","328.78200","0.00000","1.19979","0.19997"
"1.19979","28.23942","0.99877","329.39200","0.00000","1.19979","0.19997"
"1.19979","28.22593","0.99829","330.00200","0.00000","1.19979","0.19997"
"1.19979","28.20444","0.99753","330.61200","0.00000","1.19979","0.19997"
"1.19979","28.18676","0.99690","331.22200","0.00000","1.19979","0.19997"
"1.19979","28.17813","0.99660","331.83200","0.00000","1.19979","0.19997"
"1.19979","28.13774","0.99517","332.44200","0.00000","1.19979","0.19997"
"1.19979","28.13158","0.99495","333.05200","0.00000","1.19979","0.19997"
"1.19979","28.11786","0.99447","333.66200","0.00000","1.19979","0.19997"
"1.19979","28.09413","0.99363","334.27200","0.00000","1.19979","0.19997"
"1.19979","28.07566","0.99297","334.88200","0.00000","1.19979","0.19997"
"1.19979","28.06466","0.99258","335.49200","0.00000","1.19979","0.19997"
"1.19979","28.04188","0.99178","336.10200","0.00000","1.19979","0.19997"
"1.19979","28.02934","0.99134","336.71200","0.00000","1.19979","0.19997"
"1.19979","28.00949","0.99063","337.32200","0.00000","1.19979","0.19997"
"1.19979","27.99510","0.99012","337.93200","0.00000","1.19979","0.19997"
"1.19979","27.97970","0.98958","338.54200","0.00000","1.19979","0.19997"
"1.19979","27.95839","0.98883","339.15200","0.00000","1.19979","0.19997"
"1.19979","27.94410","0.98832","339.76200","0.00000","1.19979","0.19997"
"1.19979","27.93379","0.98796","340.37200","0.00000","1.19979","0.19997"
"1.19979","27.91523","0.98730","340.98200","0.00000","1.19979","0.19997"
"1.19979","27.90235","0.98684","341.59200","0.00000","1.19979","0.19997"
"1.19979","27.88548","0.98625","342.20200","0.00000","1.19979","0.19997"
"1.19979","27.85957","0.98533","342.81200","0.00000","1.19979","0.19997"
"1.19979","27.85500","0.98517","343.42200","0.00000","1.19979","0.19997"
"1.19979","27.84682","0.98488","344.03200","0.00000","1.19979","0.19997"
"1.19979","27.82699","0.98418","344.64200","0.00000","1.19979","0.19997"
"1.19979","27.81438","0.98373","345.25200","0.00000","1.19979","0.19997"
"1.19979","27.79543","0.98306","345.86200","0.00000","1.19979","0.19997"
"1.19979","27.78137","0.98256","346.47200","0.00000","1.19979","0.19997"
"1.19979","27.77771","0.98244","347.08200","0.00000","1.19979","0.19997"
"1.19979","27.74927","0.98143","347.69200","0.00000","1.19979","0.19997"
"1.19979","27.74446","0.98126","348.30200","0.00000","1.19979","0.19997"
"1.19979","27.73167","0.98081","348.91200","0.00000","1.19979","0.19997"
"1.19979","27.71911","0.98036","349.52200","0.00000","1.19979","0.19997"
"1.19979","27.69563","0.97953","350.13200","0.00000","1.19979","0.19997"
"1.19979","27.68910","0.97930","350.74200","0.00000","1.19979","0.19997"
"1.19979","27.67676","0.97887","351.35200","0.00000","1.19979","0.19997"
"1.19979","27.66437","0.97843","351.96200","0.00000","1.19979","0.19997"
"1.19979","27.65078","0.97795","352.57200","0.00000","1.19979","0.19997"
"1.19979","27.64583","0.97777","353.18200","0.00000","1.19979","0.19997"
"1.19979","27.63127","0.97726","353.79200","0.00000","1.19979","0.19997"
"1.19979","27.61512","0.97669","354.40200","0.00000","1.19979","0.19997"
"1.19979","27.60711","0.97640","355.01200","0.00000","1.19979","0.19997"
"1.19979","27.60063","0.97617","355.62200","0.00000","1.19979","0.19997"
"1.19979","27.58057","0.97546","356.23200","0.00000","1.19979","0.19997"
"1.19979","27.57165","0.97515","356.84200","0.00000","1.19979","0.19997"
"1.19979","27.55377","0.97452","357.45200","0.00000","1.19979","0.19997"
"1.19979","27.54514","0.97421","358.06200","0.00000","1.19979","0.19997"
"1.19979","27.54002","0.97403","358.67200","0.00000","1.19979","0.19997"
"1.19979","27.52411","0.97347","359.28200","0.00000","1.19979","0.19997"
"1.19979","27.50918","0.97294","359.89200","0.00000","1.19979","0.19997"
"1.19979","27.50613","0.97283","360.50200","0.00000","1.19979","0.19997"
"1.19979","27.50051","0.97263","361.11200","0.00000","1.19979","0.19997"
"1.19979","27.47517","0.97174","361.72200","0.00000","1.19979","0.19997"
"1.19979","27.47687","0.97180","362.33200","0.00000","1.19979","0.19997"
"1.19979","27.46352","0.97132","362.94200","0.00000","1.19979","0.19997"
"1.19979","27.44836","0.97079","363.55200","0.00000","1.19979","0.19997"
"1.19979","27.44261","0.97058","364.16200","0.00000","1.19979","0.19997"
"1.19979","27.43447","0.97030","364.77200","0.00000","1.19979","0.19997"
"1.19979","27.42136","0.96983","365.38200","0.00000","1.19979","0.19997"
"1.19979","27.40290","0.96918","365.99200","0.00000","1.19979","0.19997"
"1.19979","27.39841","0.96902","366.60200","0.00000","1.19979","0.19997"
"1.19979","27.39614","0.96894","367.21200","0.00000","1.19979","0.19997"
"1.19979","27.37988","0.96837","367.82200","0.00000","1.19979","0.19997"
"1.19979","27.36079","0.96769","368.43200","0.00000","1.19979","0.19997"
"1.19979","27.35973","0.96765","369.04200","0.00000","1.19979","0.19997"
"1.19979","27.35394","0.96745","369.65200","0.00000","1.19979","0.19997"
"1.19979","27.33829","0.96689","370.26200","0.00000","1.19979","0.19997"
"1.19979","27.33542","0.96679","370.87200","0.00000","1.19979","0.19997"
"1.19979","27.32001","0.96625","371.48200","0.00000","1.19979","0.19997"
"1.19979","27.31486","0.96607","372.09200","0.00000","1.19979","0.19997"
"1.19979","27.30886","0.96585","372.70200","0.00000","1.19979","0.19997"
"1.19979","27.29757","0.96545","373.31200","0.00000","1.19979","0.19997"
"1.19979","27.28403","0.96498","373.92200","0.00000","1.19979","0.19997"
"1.19979","27.26867","0.96443","374.53200","0.00000","1.19979","0.19997"
"1.19979","27.26073","0.96415","375.14200","0.00000","1.19979","0.19997"
"1.19979","27.25796","0.96405","375.75200","0.00000","1.19979","0.19997"
"1.19979","27.24168","0.96348","376.36200","0.00000","1.19979","0.19997"
"1.19979","27.23716","0.96332","376.97200","0.00000","1.19979","0.19997"
"1.19979","27.22243","0.96280","377.58200","0.00000","1.19979","0.19997"
"1.19979","27.21802","0.96264","378.19200","0.00000","1.19979","0.19997"
"1.19979","27.21139","0.96241","378.80200","0.00000","1.19979","0.19997"
"1.19979","27.20250","0.96209","379.41200","0.00000","1.19979","0.19997"
"1.19979","27.19688","0.96189","380.02200","0.00000","1.19979","0.19997"
"1.19979","27.18054","0.96132","380.63200","0.00000","1.19979","0.19997"
"1.19979","27.17699","0.96119","381.24200","0.00000","1.19979","0.19997"
"1.19979","27.16632","0.96081","381.85200","0.00000","1.19979","0.19997"
"1.19979","27.16292","0.96069","382.46200","0.00000","1.19979","0.19997"
"1.19979","27.15358","0.96036","383.07200","0.00000","1.19979","0.19997"
"1.19979","27.13658","0.95976","383.68200","0.00000","1.19979","0.19997"
"1.19979","27.13855","0.95983","384.29200","0.00000","1.19979","0.19997"
"1.19979","27.12855","0.95948","384.90200","0.00000","1.19979","0.19997"
"1.19979","27.11721","0.95908","385.51200","0.00000","1.19979","0.19997"
"1.19979","27.11386","0.95896","386.12200","0.00000","1.19979","0.19997"
"1.19979","27.09293","0.95822","386.73200","0.00000","1.19979","0.19997"
"1.19979","27.08627","0.95798","387.34200","0.00000","1.19979","0.19997"
"1.19979","27.08745","0.95802","387.95200","0.00000","1.19979","0.19997"
"1.19979","27.08414","0.95791","388.56200","0.00000","1.19979","0.19997"
"1.19979","27.07297","0.95751","389.17200","0.00000","1.19979","0.19997"
"1.19979","27.05527","0.95688","389.78200","0.00000","1.19979","0.19997"
"1.19979","27.05693","0.95694","390.39200","0.00000","1.19979","0.19997"
"1.19979","27.03708","0.95624","391.00200","0.00000","1.19979","0.19997"
"1.19979","27.04053","0.95636","391.61200","0.00000","1.19979","0.19997"
"1.19979","27.02663","0.95587","392.22200","0.00000","1.19979","0.19997"
"1.19979","27.01789","0.95556","392.83200","0.00000","1.19979","0.19997"
"1.19979","27.01356","0.95541","393.44200","0.00000","1.19979","0.19997"
"1.19979","27.00631","0.95515","394.05200","0.00000","1.19979","0.19997"
"1.19979","26.99754","0.95484","394.66200","0.00000","1.19979","0.19997"
"1.19979","26.99026","0.95459","395.27200","0.00000","1.19979","0.19997"
"1.19979","26.98419","0.95437","395.88200","0.00000","1.19979","0.19997"
"1.19979","26.97186","0.95393","396.49200","0.00000","1.19979","0.19997"
"1.19979","26.97863","0.95417","397.10200","0.00000","1.19979","0.19997"
"1.19979","26.96668","0.95375","397.71200","0.00000","1.19979","0.19997"
"1.19979","26.95055","0.95318","398.32200","0.00000","1.19979","0.19997"
"1.19979","26.94884","0.95312","398.93200","0.00000","1.19979","0.19997"
"1.19979","26.94531","0.95300","399.54200","0.00000","1.19979","0.19997"
"1.19979","26.94177","0.95287","400.15200","0.00000","1.19979","0.19997"
"1.19979","26.92320","0.95221","400.76200","0.00000","1.19979","0.19997"
"1.19979","26.92503","0.95228","401.37200","0.00000","1.19979","0.19997"
"1.19979","26.91324","0.95186","401.98200","0.00000","1.19979","0.19997"
"1.19979","26.90538","0.95158","402.59200","0.00000","1.19979","0.19997"
"1.19979","26.89848","0.95134","403.20200","0.00000","1.19979","0.19997"
"1.19979","26.88987","0.95103","403.81200","0.00000","1.19979","0.19997"
"1.19979","26.88855","0.95099","404.42200","0.00000","1.19979","0.19997"
"1.19979","26.87569","0.95053","405.03200","0.00000","1.19979","0.19997"
"1.19979","26.87370","0.95046","405.64200","0.00000","1.19979","0.19997"
"1.19979","26.86584","0.95018","406.25200","0.00000","1.19979","0.19997"
"1.19979","26.86051","0.95000","406.86200","0.00000","1.19979","0.19997"
"1.19979","26.84632","0.94949","407.47200","0.00000","1.19979","0.19997"
"1.19979","26.84804","0.94956","408.08200","0.00000","1.19979","0.19997"
"1.19979","26.83728","0.94917","408.69200","0.00000","1.19979","0.19997"
"1.19979","26.82797","0.94885","409.30200","0.00000","1.19979","0.19997"
"1.19979","26.81865","0.94852","409.91200","0.00000","1.19979","0.19997"
"1.19979","26.82145","0.94861","410.52200","0.00000","1.19979","0.19997"
"1.19979","26.81201","0.94828","411.13200","0.00000","1.19979","0.19997"
"1.19979","26.80629","0.94808","411.74200","0.00000","1.19979","0.19997"
"1.19979","26.80062","0.94788","412.35200","0.00000","1.19979","0.19997"
"1.19979","26.78902","0.94747","412.96200","0.00000","1.19979","0.19997"
"1.19979","26.78239","0.94723","413.57200","0.00000","1.19979","0.19997"
"1.19979","26.78185","0.94721","414.18200","0.00000","1.19979","0.19997"
"1.19979","26.77852","0.94710","414.79200","0.00000","1.19979","0.19997"
"1.19979","26.76852","0.94674","415.40200","0.00000","1.19979","0.19997"
"1.19979","26.75857","0.94639","416.01200","0.00000","1.19979","0.19997"
"1.19979","26.75616","0.94631","416.62200","0.00000","1.19979","0.19997"
"1.19979","26.74762","0.94600","417.23200","0.00000","1.19979","0.19997"
"1.19979","26.74279","0.94583","417.84200","0.00000","1.19979","0.19997"
"1.19979","26.73609","0.94560","418.45200","0.00000","1.19979","0.19997"
"1.19979","26.72574","0.94523","419.06200","0.00000","1.19979","0.19997"
"1.19979","26.72383","0.94516","419.67200","0.00000","1.19979","0.19997"
"1.19979","26.71756","0.94494","419.91200","0.00000","1.19979","0.19997"