File: Rubber Stress Relaxation Raw Data - Small Samples-20210211/Specimen_RawData_4.csv
Specimen properties : Specimen label,"GBI2S1R1"
Specimen properties : Anvil height,"5.90000",mm
Specimen properties : Diameter,"5.62000",mm
Test : Rate 1,"0.24000",mm/min
Test : Start of hold value,"20.00000",%
Test : Duration,"120.00000",s

Extension,Load,Compressive stress,Time,PIP count,Compressive extension,Compressive strain (Extension)
(mm),(N),(MPa),(s),,(mm),(mm/mm)
"0.00000","-0.01087","-0.00044","0.00000","0.00000","0.00000","0.00000"
"0.00146","0.07003","0.00282","0.61000","0.00000","0.00146","0.00025"
"0.00417","0.19716","0.00795","1.22000","0.00000","0.00417","0.00071"
"0.00687","0.31372","0.01265","1.83000","0.00000","0.00687","0.00117"
"0.00938","0.40275","0.01624","2.44000","0.00000","0.00938","0.00159"
"0.01188","0.49120","0.01980","3.05000","0.00000","0.01188","0.00201"
"0.01438","0.58236","0.02348","3.66000","0.00000","0.01438","0.00244"
"0.01688","0.65798","0.02652","4.27000","0.00000","0.01688","0.00286"
"0.01938","0.73963","0.02982","4.88000","0.00000","0.01938","0.00328"
"0.02167","0.80739","0.03255","5.49000","0.00000","0.02167","0.00367"
"0.02417","0.88116","0.03552","6.10000","0.00000","0.02417","0.00410"
"0.02667","0.95886","0.03865","6.71000","0.00000","0.02667","0.00452"
"0.02917","1.01771","0.04103","7.32000","0.00000","0.02917","0.00494"
"0.03146","1.07863","0.04348","7.93000","0.00000","0.03146","0.00533"
"0.03375","1.15284","0.04647","8.54000","0.00000","0.03375","0.00572"
"0.03625","1.21651","0.04904","9.15000","0.00000","0.03625","0.00614"
"0.03875","1.28513","0.05181","9.76000","0.00000","0.03875","0.00657"
"0.04125","1.34621","0.05427","10.37000","0.00000","0.04125","0.00699"
"0.04354","1.41422","0.05701","10.98000","0.00000","0.04354","0.00738"
"0.04604","1.47611","0.05951","11.59000","0.00000","0.04604","0.00780"
"0.04833","1.53416","0.06185","12.20000","0.00000","0.04833","0.00819"
"0.05083","1.60200","0.06458","12.81000","0.00000","0.05083","0.00862"
"0.05333","1.66581","0.06715","13.42000","0.00000","0.05333","0.00904"
"0.05583","1.72825","0.06967","14.03000","0.00000","0.05583","0.00946"
"0.05833","1.78393","0.07191","14.64000","0.00000","0.05833","0.00989"
"0.06063","1.84548","0.07440","15.25000","0.00000","0.06062","0.01028"
"0.06312","1.89932","0.07657","15.86000","0.00000","0.06312","0.01070"
"0.06583","1.97051","0.07944","16.47000","0.00000","0.06583","0.01116"
"0.06833","2.02573","0.08166","17.08000","0.00000","0.06833","0.01158"
"0.07063","2.08206","0.08393","17.69000","0.00000","0.07063","0.01197"
"0.07313","2.13731","0.08616","18.30000","0.00000","0.07313","0.01239"
"0.07563","2.18504","0.08808","18.91000","0.00000","0.07563","0.01282"
"0.07792","2.24049","0.09032","19.52000","0.00000","0.07792","0.01321"
"0.08042","2.30142","0.09278","20.13000","0.00000","0.08042","0.01363"
"0.08292","2.34301","0.09445","20.74000","0.00000","0.08292","0.01405"
"0.08542","2.40403","0.09691","21.35000","0.00000","0.08542","0.01448"
"0.08771","2.45791","0.09908","21.96000","0.00000","0.08771","0.01487"
"0.09000","2.49745","0.10068","22.57000","0.00000","0.09000","0.01525"
"0.09229","2.55966","0.10319","23.18000","0.00000","0.09229","0.01564"
"0.09500","2.61779","0.10553","23.79000","0.00000","0.09500","0.01610"
"0.09729","2.66293","0.10735","24.40000","0.00000","0.09729","0.01649"
"0.09979","2.71824","0.10958","25.01000","0.00000","0.09979","0.01691"
"0.10229","2.76453","0.11144","25.62000","0.00000","0.10229","0.01734"
"0.10479","2.82413","0.11385","26.23000","0.00000","0.10479","0.01776"
"0.10729","2.87140","0.11575","26.84000","0.00000","0.10729","0.01819"
"0.10958","2.93353","0.11826","27.45000","0.00000","0.10958","0.01857"
"0.11208","2.97857","0.12007","28.06000","0.00000","0.11208","0.01900"
"0.11458","3.02993","0.12214","28.67000","0.00000","0.11458","0.01942"
"0.11708","3.06959","0.12374","29.28000","0.00000","0.11708","0.01984"
"0.11958","3.11762","0.12568","29.89000","0.00000","0.11958","0.02027"
"0.12208","3.16949","0.12777","30.50000","0.00000","0.12208","0.02069"
"0.12438","3.21577","0.12964","31.11000","0.00000","0.12438","0.02108"
"0.12667","3.27213","0.13191","31.72000","0.00000","0.12667","0.02147"
"0.12896","3.31648","0.13370","32.33000","0.00000","0.12896","0.02186"
"0.13146","3.37362","0.13600","32.94000","0.00000","0.13146","0.02228"
"0.13396","3.41701","0.13775","33.55000","0.00000","0.13396","0.02270"
"0.13625","3.46133","0.13953","34.16000","0.00000","0.13625","0.02309"
"0.13875","3.52061","0.14192","34.77000","0.00000","0.13875","0.02352"
"0.14125","3.57069","0.14394","35.38000","0.00000","0.14125","0.02394"
"0.14375","3.61209","0.14561","35.99000","0.00000","0.14375","0.02436"
"0.14625","3.66380","0.14770","36.60000","0.00000","0.14625","0.02479"
"0.14875","3.72514","0.15017","37.21000","0.00000","0.14875","0.02521"
"0.15125","3.77216","0.15206","37.82000","0.00000","0.15125","0.02564"
"0.15375","3.83141","0.15445","38.43000","0.00000","0.15375","0.02606"
"0.15604","3.86781","0.15592","39.04000","0.00000","0.15604","0.02645"
"0.15854","3.91288","0.15774","39.65000","0.00000","0.15854","0.02687"
"0.16104","3.95956","0.15962","40.26000","0.00000","0.16104","0.02730"
"0.16354","4.00873","0.16160","40.87000","0.00000","0.16354","0.02772"
"0.16583","4.04601","0.16310","41.48000","0.00000","0.16583","0.02811"
"0.16813","4.08553","0.16470","42.09000","0.00000","0.16813","0.02850"
"0.17042","4.14127","0.16694","42.70000","0.00000","0.17042","0.02888"
"0.17292","4.19322","0.16904","43.31000","0.00000","0.17292","0.02931"
"0.17542","4.24526","0.17114","43.92000","0.00000","0.17542","0.02973"
"0.17771","4.29364","0.17309","44.53000","0.00000","0.17771","0.03012"
"0.18021","4.34625","0.17521","45.14000","0.00000","0.18021","0.03054"
"0.18271","4.40387","0.17753","45.75000","0.00000","0.18271","0.03097"
"0.18521","4.44249","0.17909","46.36000","0.00000","0.18521","0.03139"
"0.18750","4.49415","0.18117","46.97000","0.00000","0.18750","0.03178"
"0.19000","4.53742","0.18291","47.58000","0.00000","0.19000","0.03220"
"0.19250","4.58388","0.18479","48.19000","0.00000","0.19250","0.03263"
"0.19500","4.62305","0.18637","48.80000","0.00000","0.19500","0.03305"
"0.19729","4.68487","0.18886","49.41000","0.00000","0.19729","0.03344"
"0.19979","4.73347","0.19082","50.02000","0.00000","0.19979","0.03386"
"0.20250","4.78677","0.19297","50.63000","0.00000","0.20250","0.03432"
"0.20500","4.82737","0.19460","51.24000","0.00000","0.20500","0.03475"
"0.20729","4.87592","0.19656","51.85000","0.00000","0.20729","0.03513"
"0.20958","4.91852","0.19828","52.46000","0.00000","0.20958","0.03552"
"0.21208","4.96373","0.20010","53.07000","0.00000","0.21208","0.03595"
"0.21438","5.01588","0.20220","53.68000","0.00000","0.21438","0.03633"
"0.21667","5.04739","0.20347","54.29000","0.00000","0.21667","0.03672"
"0.21938","5.10667","0.20586","54.90000","0.00000","0.21938","0.03718"
"0.22187","5.16044","0.20803","55.51000","0.00000","0.22187","0.03761"
"0.22438","5.20945","0.21000","56.12000","0.00000","0.22438","0.03803"
"0.22667","5.25523","0.21185","56.73000","0.00000","0.22667","0.03842"
"0.22917","5.29954","0.21364","57.34000","0.00000","0.22917","0.03884"
"0.23167","5.35875","0.21602","57.95000","0.00000","0.23167","0.03927"
"0.23417","5.40320","0.21782","58.56000","0.00000","0.23417","0.03969"
"0.23646","5.44564","0.21953","59.17000","0.00000","0.23646","0.04008"
"0.23896","5.49173","0.22138","59.78000","0.00000","0.23896","0.04050"
"0.24146","5.53781","0.22324","60.39000","0.00000","0.24146","0.04093"
"0.24396","5.58636","0.22520","61.00000","0.00000","0.24396","0.04135"
"0.24646","5.63112","0.22700","61.61000","0.00000","0.24646","0.04177"
"0.24875","5.66847","0.22851","62.22000","0.00000","0.24875","0.04216"
"0.25104","5.71506","0.23039","62.83000","0.00000","0.25104","0.04255"
"0.25333","5.76126","0.23225","63.44000","0.00000","0.25333","0.04294"
"0.25583","5.80478","0.23400","64.05000","0.00000","0.25583","0.04336"
"0.25833","5.86965","0.23662","64.66000","0.00000","0.25833","0.04379"
"0.26083","5.92556","0.23887","65.27000","0.00000","0.26083","0.04421"
"0.26333","5.96158","0.24032","65.88000","0.00000","0.26333","0.04463"
"0.26583","6.01736","0.24257","66.49000","0.00000","0.26583","0.04506"
"0.26833","6.05534","0.24410","67.10000","0.00000","0.26833","0.04548"
"0.27083","6.11437","0.24648","67.71000","0.00000","0.27083","0.04590"
"0.27313","6.15374","0.24807","68.32000","0.00000","0.27313","0.04629"
"0.27562","6.20698","0.25022","68.93000","0.00000","0.27562","0.04672"
"0.27792","6.24281","0.25166","69.54000","0.00000","0.27792","0.04710"
"0.28042","6.28603","0.25340","70.15000","0.00000","0.28042","0.04753"
"0.28292","6.33755","0.25548","70.76000","0.00000","0.28292","0.04795"
"0.28542","6.38458","0.25738","71.37000","0.00000","0.28542","0.04838"
"0.28792","6.41920","0.25877","71.98000","0.00000","0.28792","0.04880"
"0.29021","6.46894","0.26078","72.59000","0.00000","0.29021","0.04919"
"0.29271","6.51148","0.26249","73.20000","0.00000","0.29271","0.04961"
"0.29500","6.57502","0.26505","73.81000","0.00000","0.29500","0.05000"
"0.29729","6.61141","0.26652","74.42000","0.00000","0.29729","0.05039"
"0.30000","6.66972","0.26887","75.03000","0.00000","0.30000","0.05085"
"0.30229","6.71837","0.27083","75.64000","0.00000","0.30229","0.05124"
"0.30479","6.75252","0.27221","76.25000","0.00000","0.30479","0.05166"
"0.30729","6.80616","0.27437","76.86000","0.00000","0.30729","0.05208"
"0.30979","6.85737","0.27644","77.47000","0.00000","0.30979","0.05251"
"0.31229","6.89995","0.27815","78.08000","0.00000","0.31229","0.05293"
"0.31458","6.95328","0.28030","78.69000","0.00000","0.31458","0.05332"
"0.31708","6.99482","0.28198","79.30000","0.00000","0.31708","0.05374"
"0.31958","7.04471","0.28399","79.91000","0.00000","0.31958","0.05417"
"0.32208","7.09956","0.28620","80.52000","0.00000","0.32208","0.05459"
"0.32438","7.14144","0.28789","81.13000","0.00000","0.32438","0.05498"
"0.32688","7.18186","0.28952","81.74000","0.00000","0.32688","0.05540"
"0.32937","7.22743","0.29135","82.35000","0.00000","0.32937","0.05583"
"0.33188","7.28067","0.29350","82.96000","0.00000","0.33188","0.05625"
"0.33417","7.32230","0.29518","83.57000","0.00000","0.33417","0.05664"
"0.33646","7.36215","0.29679","84.18000","0.00000","0.33646","0.05703"
"0.33896","7.40995","0.29871","84.79000","0.00000","0.33896","0.05745"
"0.34146","7.44429","0.30010","85.40000","0.00000","0.34146","0.05787"
"0.34396","7.50141","0.30240","86.01000","0.00000","0.34396","0.05830"
"0.34625","7.55227","0.30445","86.62000","0.00000","0.34625","0.05869"
"0.34875","7.60026","0.30638","87.23000","0.00000","0.34875","0.05911"
"0.35104","7.64614","0.30823","87.84000","0.00000","0.35104","0.05950"
"0.35354","7.69559","0.31023","88.45000","0.00000","0.35354","0.05992"
"0.35604","7.73676","0.31189","89.06000","0.00000","0.35604","0.06035"
"0.35833","7.78546","0.31385","89.67000","0.00000","0.35833","0.06073"
"0.36083","7.83674","0.31592","90.28000","0.00000","0.36083","0.06116"
"0.36333","7.87460","0.31744","90.89000","0.00000","0.36333","0.06158"
"0.36583","7.91915","0.31924","91.50000","0.00000","0.36583","0.06201"
"0.36813","7.96692","0.32116","92.11000","0.00000","0.36813","0.06239"
"0.37063","8.00990","0.32290","92.72000","0.00000","0.37063","0.06282"
"0.37313","8.06205","0.32500","93.33000","0.00000","0.37313","0.06324"
"0.37563","8.11408","0.32710","93.94000","0.00000","0.37563","0.06367"
"0.37813","8.15493","0.32874","94.55000","0.00000","0.37813","0.06409"
"0.38042","8.20284","0.33068","95.16000","0.00000","0.38042","0.06448"
"0.38292","8.24972","0.33257","95.77000","0.00000","0.38292","0.06490"
"0.38521","8.29536","0.33441","96.38000","0.00000","0.38521","0.06529"
"0.38771","8.34923","0.33658","96.99000","0.00000","0.38771","0.06571"
"0.39021","8.38593","0.33806","97.60000","0.00000","0.39021","0.06614"
"0.39271","8.43453","0.34002","98.21000","0.00000","0.39271","0.06656"
"0.39500","8.47792","0.34176","98.82000","0.00000","0.39500","0.06695"
"0.39750","8.53489","0.34406","99.43000","0.00000","0.39750","0.06737"
"0.40000","8.58016","0.34589","100.04000","0.00000","0.40000","0.06780"
"0.40229","8.62860","0.34784","100.65000","0.00000","0.40229","0.06819"
"0.40479","8.66700","0.34939","101.26000","0.00000","0.40479","0.06861"
"0.40708","8.71710","0.35141","101.87000","0.00000","0.40708","0.06900"
"0.40958","8.76695","0.35342","102.48000","0.00000","0.40958","0.06942"
"0.41208","8.80856","0.35509","103.09000","0.00000","0.41208","0.06984"
"0.41458","8.85847","0.35711","103.70000","0.00000","0.41458","0.07027"
"0.41708","8.90726","0.35907","104.31000","0.00000","0.41708","0.07069"
"0.41958","8.95096","0.36083","104.92000","0.00000","0.41958","0.07112"
"0.42208","9.00153","0.36287","105.53000","0.00000","0.42208","0.07154"
"0.42437","9.05293","0.36494","106.14000","0.00000","0.42437","0.07193"
"0.42688","9.08870","0.36639","106.75000","0.00000","0.42688","0.07235"
"0.42917","9.13873","0.36840","107.36000","0.00000","0.42917","0.07274"
"0.43167","9.19168","0.37054","107.97000","0.00000","0.43167","0.07316"
"0.43396","9.24184","0.37256","108.58000","0.00000","0.43396","0.07355"
"0.43646","9.28768","0.37441","109.19000","0.00000","0.43646","0.07398"
"0.43896","9.33278","0.37623","109.80000","0.00000","0.43896","0.07440"
"0.44146","9.37438","0.37790","110.41000","0.00000","0.44146","0.07482"
"0.44396","9.43096","0.38018","111.02000","0.00000","0.44396","0.07525"
"0.44625","9.46130","0.38141","111.63000","0.00000","0.44625","0.07564"
"0.44875","9.50949","0.38335","112.24000","0.00000","0.44875","0.07606"
"0.45104","9.56722","0.38568","112.85000","0.00000","0.45104","0.07645"
"0.45375","9.61293","0.38752","113.46000","0.00000","0.45375","0.07691"
"0.45625","9.66783","0.38973","114.07000","0.00000","0.45625","0.07733"
"0.45875","9.70599","0.39127","114.68000","0.00000","0.45875","0.07775"
"0.46104","9.75523","0.39326","115.29000","0.00000","0.46104","0.07814"
"0.46354","9.80202","0.39514","115.90000","0.00000","0.46354","0.07857"
"0.46583","9.85196","0.39716","116.51000","0.00000","0.46583","0.07895"
"0.46833","9.89127","0.39874","117.12000","0.00000","0.46833","0.07938"
"0.47083","9.94650","0.40097","117.73000","0.00000","0.47083","0.07980"
"0.47333","9.99257","0.40282","118.34000","0.00000","0.47333","0.08023"
"0.47563","10.03491","0.40453","118.95000","0.00000","0.47563","0.08061"
"0.47813","10.08622","0.40660","119.56000","0.00000","0.47812","0.08104"
"0.48063","10.13380","0.40852","120.17000","0.00000","0.48063","0.08146"
"0.48313","10.18386","0.41053","120.78000","0.00000","0.48313","0.08189"
"0.48542","10.22206","0.41207","121.39000","0.00000","0.48542","0.08227"
"0.48771","10.27683","0.41428","122.00000","0.00000","0.48771","0.08266"
"0.49021","10.32341","0.41616","122.61000","0.00000","0.49021","0.08309"
"0.49271","10.37250","0.41814","123.22000","0.00000","0.49271","0.08351"
"0.49521","10.42279","0.42017","123.83000","0.00000","0.49521","0.08393"
"0.49750","10.46955","0.42205","124.44000","0.00000","0.49750","0.08432"
"0.50021","10.51334","0.42382","125.05000","0.00000","0.50021","0.08478"
"0.50250","10.57193","0.42618","125.66000","0.00000","0.50250","0.08517"
"0.50500","10.60969","0.42770","126.27000","0.00000","0.50500","0.08559"
"0.50729","10.65533","0.42954","126.88000","0.00000","0.50729","0.08598"
"0.50979","10.70199","0.43142","127.49000","0.00000","0.50979","0.08641"
"0.51208","10.74800","0.43328","128.10000","0.00000","0.51208","0.08679"
"0.51458","10.80068","0.43540","128.71000","0.00000","0.51458","0.08722"
"0.51708","10.84601","0.43723","129.32000","0.00000","0.51708","0.08764"
"0.51938","10.89151","0.43906","129.93000","0.00000","0.51938","0.08803"
"0.52188","10.94236","0.44111","130.54000","0.00000","0.52188","0.08845"
"0.52417","10.98555","0.44285","131.15000","0.00000","0.52417","0.08884"
"0.52667","11.05418","0.44562","131.76000","0.00000","0.52667","0.08927"
"0.52917","11.09415","0.44723","132.37000","0.00000","0.52917","0.08969"
"0.53167","11.14362","0.44922","132.98000","0.00000","0.53167","0.09011"
"0.53438","11.20150","0.45156","133.59000","0.00000","0.53438","0.09057"
"0.53667","11.24187","0.45319","134.20000","0.00000","0.53667","0.09096"
"0.53917","11.29862","0.45547","134.81000","0.00000","0.53917","0.09138"
"0.54167","11.33597","0.45698","135.42000","0.00000","0.54167","0.09181"
"0.54396","11.37827","0.45868","136.03000","0.00000","0.54396","0.09220"
"0.54646","11.42649","0.46063","136.64000","0.00000","0.54646","0.09262"
"0.54896","11.47338","0.46252","137.25000","0.00000","0.54896","0.09304"
"0.55125","11.52922","0.46477","137.86000","0.00000","0.55125","0.09343"
"0.55354","11.56892","0.46637","138.47000","0.00000","0.55354","0.09382"
"0.55604","11.61698","0.46831","139.08000","0.00000","0.55604","0.09424"
"0.55854","11.66756","0.47035","139.69000","0.00000","0.55854","0.09467"
"0.56104","11.72340","0.47260","140.30000","0.00000","0.56104","0.09509"
"0.56333","11.76730","0.47437","140.91000","0.00000","0.56333","0.09548"
"0.56583","11.81079","0.47612","141.52000","0.00000","0.56583","0.09590"
"0.56813","11.86548","0.47832","142.13000","0.00000","0.56813","0.09629"
"0.57063","11.91086","0.48015","142.74000","0.00000","0.57063","0.09672"
"0.57313","11.96893","0.48249","143.35000","0.00000","0.57313","0.09714"
"0.57563","12.01476","0.48434","143.96000","0.00000","0.57563","0.09756"
"0.57812","12.06396","0.48633","144.57000","0.00000","0.57812","0.09799"
"0.58062","12.12201","0.48867","145.18000","0.00000","0.58062","0.09841"
"0.58313","12.16153","0.49026","145.79000","0.00000","0.58313","0.09883"
"0.58562","12.21401","0.49237","146.40000","0.00000","0.58562","0.09926"
"0.58792","12.26303","0.49435","147.01000","0.00000","0.58792","0.09965"
"0.59021","12.30521","0.49605","147.62000","0.00000","0.59021","0.10004"
"0.59250","12.33497","0.49725","148.23000","0.00000","0.59250","0.10042"
"0.59500","12.40208","0.49996","148.84000","0.00000","0.59500","0.10085"
"0.59750","12.45595","0.50213","149.45000","0.00000","0.59750","0.10127"
"0.60000","12.50378","0.50406","150.06000","0.00000","0.60000","0.10169"
"0.60229","12.55067","0.50595","150.67000","0.00000","0.60229","0.10208"
"0.60479","12.59774","0.50784","151.28000","0.00000","0.60479","0.10251"
"0.60729","12.64505","0.50975","151.89000","0.00000","0.60729","0.10293"
"0.60958","12.69085","0.51160","152.50000","0.00000","0.60958","0.10332"
"0.61229","12.75388","0.51414","153.11000","0.00000","0.61229","0.10378"
"0.61479","12.80244","0.51610","153.72000","0.00000","0.61479","0.10420"
"0.61729","12.84811","0.51794","154.33000","0.00000","0.61729","0.10463"
"0.61979","12.91237","0.52053","154.94000","0.00000","0.61979","0.10505"
"0.62208","12.94780","0.52196","155.55000","0.00000","0.62208","0.10544"
"0.62458","13.00042","0.52408","156.16000","0.00000","0.62458","0.10586"
"0.62688","13.04401","0.52583","156.77000","0.00000","0.62688","0.10625"
"0.62938","13.09425","0.52786","157.38000","0.00000","0.62938","0.10667"
"0.63167","13.13225","0.52939","157.99000","0.00000","0.63167","0.10706"
"0.63417","13.18922","0.53169","158.60000","0.00000","0.63417","0.10749"
"0.63646","13.24231","0.53383","159.21000","0.00000","0.63646","0.10787"
"0.63896","13.30542","0.53637","159.82000","0.00000","0.63896","0.10830"
"0.64146","13.35389","0.53833","160.43000","0.00000","0.64146","0.10872"
"0.64375","13.40496","0.54038","161.04000","0.00000","0.64375","0.10911"
"0.64625","13.45608","0.54245","161.65000","0.00000","0.64625","0.10953"
"0.64875","13.50032","0.54423","162.26000","0.00000","0.64875","0.10996"
"0.65125","13.56078","0.54667","162.87000","0.00000","0.65125","0.11038"
"0.65375","13.61461","0.54884","163.48000","0.00000","0.65375","0.11081"
"0.65625","13.65983","0.55066","164.09000","0.00000","0.65625","0.11123"
"0.65875","13.71434","0.55286","164.70000","0.00000","0.65875","0.11165"
"0.66125","13.77935","0.55548","165.31000","0.00000","0.66125","0.11208"
"0.66354","13.82143","0.55717","165.92000","0.00000","0.66354","0.11246"
"0.66604","13.85885","0.55868","166.53000","0.00000","0.66604","0.11289"
"0.66854","13.91245","0.56084","167.14000","0.00000","0.66854","0.11331"
"0.67083","13.96229","0.56285","167.75000","0.00000","0.67083","0.11370"
"0.67313","14.00468","0.56456","168.36000","0.00000","0.67313","0.11409"
"0.67563","14.06154","0.56685","168.97000","0.00000","0.67563","0.11451"
"0.67813","14.11672","0.56908","169.58000","0.00000","0.67813","0.11494"
"0.68042","14.16481","0.57102","170.19000","0.00000","0.68042","0.11532"
"0.68292","14.21348","0.57298","170.80000","0.00000","0.68292","0.11575"
"0.68542","14.27642","0.57552","171.41000","0.00000","0.68542","0.11617"
"0.68771","14.32104","0.57731","172.02000","0.00000","0.68771","0.11656"
"0.69021","14.37765","0.57960","172.63000","0.00000","0.69021","0.11698"
"0.69271","14.42608","0.58155","173.24000","0.00000","0.69271","0.11741"
"0.69500","14.47854","0.58366","173.85000","0.00000","0.69500","0.11780"
"0.69771","14.52214","0.58542","174.46000","0.00000","0.69771","0.11826"
"0.70021","14.59662","0.58842","175.07000","0.00000","0.70021","0.11868"
"0.70271","14.63371","0.58992","175.68000","0.00000","0.70271","0.11910"
"0.70500","14.70030","0.59260","176.29000","0.00000","0.70500","0.11949"
"0.70750","14.74973","0.59460","176.90000","0.00000","0.70750","0.11992"
"0.71000","14.78732","0.59611","177.51000","0.00000","0.71000","0.12034"
"0.71229","14.82971","0.59782","178.12000","0.00000","0.71229","0.12073"
"0.71458","14.89465","0.60044","178.73000","0.00000","0.71458","0.12112"
"0.71708","14.94200","0.60235","179.34000","0.00000","0.71708","0.12154"
"0.71958","14.99718","0.60457","179.95000","0.00000","0.71958","0.12196"
"0.72188","15.05896","0.60706","180.56000","0.00000","0.72188","0.12235"
"0.72438","15.10476","0.60891","181.17000","0.00000","0.72438","0.12278"
"0.72688","15.16246","0.61123","181.78000","0.00000","0.72688","0.12320"
"0.72938","15.21821","0.61348","182.39000","0.00000","0.72938","0.12362"
"0.73167","15.27792","0.61589","183.00000","0.00000","0.73167","0.12401"
"0.73417","15.31669","0.61745","183.61000","0.00000","0.73417","0.12444"
"0.73667","15.36960","0.61958","184.22000","0.00000","0.73667","0.12486"
"0.73937","15.45418","0.62299","184.83000","0.00000","0.73937","0.12532"
"0.74167","15.49443","0.62462","185.44000","0.00000","0.74167","0.12571"
"0.74417","15.52542","0.62587","186.05000","0.00000","0.74417","0.12613"
"0.74667","15.59284","0.62858","186.66000","0.00000","0.74667","0.12655"
"0.74896","15.64332","0.63062","187.27000","0.00000","0.74896","0.12694"
"0.75146","15.68736","0.63239","187.88000","0.00000","0.75146","0.12737"
"0.75375","15.74067","0.63454","188.49000","0.00000","0.75375","0.12775"
"0.75625","15.77959","0.63611","189.10000","0.00000","0.75625","0.12818"
"0.75854","15.84891","0.63891","189.71000","0.00000","0.75854","0.12857"
"0.76104","15.90370","0.64111","190.32000","0.00000","0.76104","0.12899"
"0.76333","15.95324","0.64311","190.93000","0.00000","0.76333","0.12938"
"0.76583","16.00693","0.64528","191.54000","0.00000","0.76583","0.12980"
"0.76833","16.05036","0.64703","192.15000","0.00000","0.76833","0.13023"
"0.77083","16.10959","0.64941","192.76000","0.00000","0.77083","0.13065"
"0.77313","16.15822","0.65137","193.37000","0.00000","0.77313","0.13104"
"0.77563","16.21924","0.65383","193.98000","0.00000","0.77563","0.13146"
"0.77812","16.27259","0.65599","194.59000","0.00000","0.77812","0.13189"
"0.78063","16.33839","0.65864","195.20000","0.00000","0.78063","0.13231"
"0.78313","16.38674","0.66059","195.81000","0.00000","0.78313","0.13273"
"0.78563","16.43039","0.66235","196.42000","0.00000","0.78563","0.13316"
"0.78813","16.48958","0.66473","197.03000","0.00000","0.78812","0.13358"
"0.79063","16.53511","0.66657","197.64000","0.00000","0.79062","0.13400"
"0.79292","16.58344","0.66852","198.25000","0.00000","0.79292","0.13439"
"0.79521","16.64553","0.67102","198.86000","0.00000","0.79521","0.13478"
"0.79771","16.70287","0.67333","199.47000","0.00000","0.79771","0.13520"
"0.80000","16.75899","0.67559","200.08000","0.00000","0.80000","0.13559"
"0.80250","16.80236","0.67734","200.69000","0.00000","0.80250","0.13602"
"0.80479","16.87280","0.68018","201.30000","0.00000","0.80479","0.13641"
"0.80729","16.92979","0.68248","201.91000","0.00000","0.80729","0.13683"
"0.80979","16.99066","0.68493","202.52000","0.00000","0.80979","0.13725"
"0.81208","17.04779","0.68724","203.13000","0.00000","0.81208","0.13764"
"0.81479","17.11126","0.68979","203.74000","0.00000","0.81479","0.13810"
"0.81729","17.16005","0.69176","204.35000","0.00000","0.81729","0.13852"
"0.81979","17.22980","0.69457","204.96000","0.00000","0.81979","0.13895"
"0.82208","17.27636","0.69645","205.57000","0.00000","0.82208","0.13934"
"0.82479","17.34213","0.69910","206.18000","0.00000","0.82479","0.13980"
"0.82708","17.39399","0.70119","206.79000","0.00000","0.82708","0.14018"
"0.82958","17.45024","0.70346","207.40000","0.00000","0.82958","0.14061"
"0.83188","17.50096","0.70550","208.01000","0.00000","0.83188","0.14100"
"0.83417","17.55904","0.70785","208.62000","0.00000","0.83417","0.14138"
"0.83667","17.61575","0.71013","209.23000","0.00000","0.83667","0.14181"
"0.83896","17.67071","0.71235","209.84000","0.00000","0.83896","0.14220"
"0.84146","17.72496","0.71453","210.45000","0.00000","0.84146","0.14262"
"0.84396","17.78633","0.71701","211.06000","0.00000","0.84396","0.14304"
"0.84646","17.84944","0.71955","211.67000","0.00000","0.84646","0.14347"
"0.84896","17.92096","0.72244","212.28000","0.00000","0.84896","0.14389"
"0.85125","17.96869","0.72436","212.89000","0.00000","0.85125","0.14428"
"0.85375","18.03258","0.72693","213.50000","0.00000","0.85375","0.14470"
"0.85625","18.10283","0.72977","214.11000","0.00000","0.85625","0.14513"
"0.85875","18.16237","0.73217","214.72000","0.00000","0.85875","0.14555"
"0.86125","18.23086","0.73493","215.33000","0.00000","0.86125","0.14597"
"0.86375","18.28652","0.73717","215.94000","0.00000","0.86375","0.14640"
"0.86625","18.34169","0.73940","216.55000","0.00000","0.86625","0.14682"
"0.86854","18.39892","0.74170","217.16000","0.00000","0.86854","0.14721"
"0.87104","18.44759","0.74366","217.77000","0.00000","0.87104","0.14763"
"0.87354","18.50835","0.74611","218.38000","0.00000","0.87354","0.14806"
"0.87583","18.56600","0.74844","218.99000","0.00000","0.87583","0.14845"
"0.87833","18.62963","0.75100","219.60000","0.00000","0.87833","0.14887"
"0.88063","18.68668","0.75330","220.21000","0.00000","0.88063","0.14926"
"0.88292","18.74711","0.75574","220.82000","0.00000","0.88292","0.14965"
"0.88542","18.80479","0.75806","221.43000","0.00000","0.88542","0.15007"
"0.88792","18.86429","0.76046","222.04000","0.00000","0.88792","0.15049"
"0.89042","18.94402","0.76368","222.65000","0.00000","0.89042","0.15092"
"0.89271","18.98980","0.76552","223.26000","0.00000","0.89271","0.15131"
"0.89521","19.06349","0.76849","223.87000","0.00000","0.89521","0.15173"
"0.89771","19.14235","0.77167","224.48000","0.00000","0.89771","0.15215"
"0.90021","19.19921","0.77396","225.09000","0.00000","0.90021","0.15258"
"0.90271","19.25720","0.77630","225.70000","0.00000","0.90271","0.15300"
"0.90521","19.32729","0.77913","226.31000","0.00000","0.90521","0.15343"
"0.90771","19.40391","0.78222","226.92000","0.00000","0.90771","0.15385"
"0.91000","19.44845","0.78401","227.53000","0.00000","0.91000","0.15424"
"0.91250","19.49276","0.78580","228.14000","0.00000","0.91250","0.15466"
"0.91500","19.56498","0.78871","228.75000","0.00000","0.91500","0.15508"
"0.91729","19.62608","0.79117","229.36000","0.00000","0.91729","0.15547"
"0.91979","19.69064","0.79377","229.97000","0.00000","0.91979","0.15590"
"0.92188","19.73801","0.79568","230.58000","0.00000","0.92188","0.15625"
"0.92437","19.81785","0.79890","231.19000","0.00000","0.92437","0.15667"
"0.92688","19.87499","0.80121","231.80000","0.00000","0.92687","0.15710"
"0.92937","19.95081","0.80426","232.41000","0.00000","0.92938","0.15752"
"0.93167","20.00643","0.80651","233.02000","0.00000","0.93167","0.15791"
"0.93417","20.07486","0.80926","233.63000","0.00000","0.93417","0.15833"
"0.93667","20.14935","0.81227","234.24000","0.00000","0.93667","0.15876"
"0.93938","20.22002","0.81512","234.85000","0.00000","0.93938","0.15922"
"0.94167","20.28632","0.81779","235.46000","0.00000","0.94167","0.15960"
"0.94417","20.35663","0.82062","236.07000","0.00000","0.94417","0.16003"
"0.94667","20.41088","0.82281","236.68000","0.00000","0.94667","0.16045"
"0.94917","20.48375","0.82575","237.29000","0.00000","0.94917","0.16088"
"0.95167","20.54858","0.82836","237.90000","0.00000","0.95167","0.16130"
"0.95396","20.60995","0.83083","238.51000","0.00000","0.95396","0.16169"
"0.95646","20.67339","0.83339","239.12000","0.00000","0.95646","0.16211"
"0.95896","20.73863","0.83602","239.73000","0.00000","0.95896","0.16254"
"0.96125","20.78852","0.83803","240.34000","0.00000","0.96125","0.16292"
"0.96354","20.84980","0.84050","240.95000","0.00000","0.96354","0.16331"
"0.96583","20.92976","0.84373","241.56000","0.00000","0.96583","0.16370"
"0.96833","21.00126","0.84661","242.17000","0.00000","0.96833","0.16412"
"0.97083","21.06993","0.84938","242.78000","0.00000","0.97083","0.16455"
"0.97333","21.13604","0.85204","243.39000","0.00000","0.97333","0.16497"
"0.97583","21.20275","0.85473","244.00000","0.00000","0.97583","0.16540"
"0.97833","21.28783","0.85816","244.61000","0.00000","0.97833","0.16582"
"0.98083","21.35847","0.86101","245.22000","0.00000","0.98083","0.16624"
"0.98333","21.43980","0.86429","245.83000","0.00000","0.98333","0.16667"
"0.98563","21.50196","0.86679","246.44000","0.00000","0.98563","0.16706"
"0.98813","21.56707","0.86942","247.05000","0.00000","0.98813","0.16748"
"0.99063","21.64436","0.87253","247.66000","0.00000","0.99063","0.16790"
"0.99292","21.71336","0.87532","248.27000","0.00000","0.99292","0.16829"
"0.99542","21.77963","0.87799","248.88000","0.00000","0.99542","0.16871"
"0.99792","21.84069","0.88045","249.49000","0.00000","0.99792","0.16914"
"1.00021","21.91517","0.88345","250.10000","0.00000","1.00021","0.16953"
"1.00250","21.97518","0.88587","250.71000","0.00000","1.00250","0.16992"
"1.00500","22.04237","0.88858","251.32000","0.00000","1.00500","0.17034"
"1.00729","22.12791","0.89203","251.93000","0.00000","1.00729","0.17073"
"1.00979","22.18472","0.89432","252.54000","0.00000","1.00979","0.17115"
"1.01229","22.27511","0.89796","253.15000","0.00000","1.01229","0.17157"
"1.01479","22.34859","0.90092","253.76000","0.00000","1.01479","0.17200"
"1.01729","22.42540","0.90402","254.37000","0.00000","1.01729","0.17242"
"1.01979","22.51286","0.90754","254.98000","0.00000","1.01979","0.17285"
"1.02208","22.57885","0.91021","255.59000","0.00000","1.02208","0.17323"
"1.02458","22.64986","0.91307","256.20000","0.00000","1.02458","0.17366"
"1.02708","22.73866","0.91665","256.81000","0.00000","1.02708","0.17408"
"1.02958","22.80091","0.91916","257.42000","0.00000","1.02958","0.17451"
"1.03188","22.87307","0.92207","258.03000","0.00000","1.03188","0.17489"
"1.03438","22.95891","0.92553","258.64000","0.00000","1.03438","0.17532"
"1.03688","23.02655","0.92825","259.25000","0.00000","1.03688","0.17574"
"1.03938","23.10439","0.93139","259.86000","0.00000","1.03938","0.17617"
"1.04167","23.16675","0.93390","260.47000","0.00000","1.04167","0.17655"
"1.04396","23.23952","0.93684","261.08000","0.00000","1.04396","0.17694"
"1.04646","23.31690","0.93996","261.69000","0.00000","1.04646","0.17737"
"1.04896","23.39986","0.94330","262.30000","0.00000","1.04896","0.17779"
"1.05125","23.48576","0.94676","262.91000","0.00000","1.05125","0.17818"
"1.05375","23.57405","0.95032","263.52000","0.00000","1.05375","0.17860"
"1.05625","23.64056","0.95301","264.13000","0.00000","1.05625","0.17903"
"1.05875","23.71838","0.95614","264.74000","0.00000","1.05875","0.17945"
"1.06104","23.80371","0.95958","265.35000","0.00000","1.06104","0.17984"
"1.06375","23.89259","0.96316","265.96000","0.00000","1.06375","0.18030"
"1.06625","23.97382","0.96644","266.57000","0.00000","1.06625","0.18072"
"1.06875","24.06018","0.96992","267.18000","0.00000","1.06875","0.18114"
"1.07104","24.13024","0.97275","267.79000","0.00000","1.07104","0.18153"
"1.07354","24.21214","0.97605","268.40000","0.00000","1.07354","0.18196"
"1.07604","24.31056","0.98001","269.01000","0.00000","1.07604","0.18238"
"1.07833","24.37584","0.98265","269.62000","0.00000","1.07833","0.18277"
"1.08083","24.45381","0.98579","270.23000","0.00000","1.08083","0.18319"
"1.08312","24.53148","0.98892","270.84000","0.00000","1.08312","0.18358"
"1.08563","24.61734","0.99238","271.45000","0.00000","1.08563","0.18400"
"1.08812","24.69786","0.99563","272.06000","0.00000","1.08812","0.18443"
"1.09042","24.76743","0.99843","272.67000","0.00000","1.09042","0.18482"
"1.09292","24.87383","1.00272","273.28000","0.00000","1.09292","0.18524"
"1.09542","24.97747","1.00690","273.89000","0.00000","1.09542","0.18566"
"1.09792","25.06202","1.01031","274.50000","0.00000","1.09792","0.18609"
"1.10042","25.14189","1.01353","275.11000","0.00000","1.10042","0.18651"
"1.10271","25.23602","1.01732","275.72000","0.00000","1.10271","0.18690"
"1.10521","25.31211","1.02039","276.33000","0.00000","1.10521","0.18732"
"1.10771","25.39776","1.02384","276.94000","0.00000","1.10771","0.18775"
"1.11000","25.48979","1.02755","277.55000","0.00000","1.11000","0.18814"
"1.11229","25.56597","1.03062","278.16000","0.00000","1.11229","0.18852"
"1.11479","25.66343","1.03455","278.77000","0.00000","1.11479","0.18895"
"1.11729","25.74992","1.03804","279.38000","0.00000","1.11729","0.18937"
"1.11979","25.84761","1.04198","279.99000","0.00000","1.11979","0.18980"
"1.12208","25.92087","1.04493","280.60000","0.00000","1.12208","0.19018"
"1.12458","26.01104","1.04856","281.21000","0.00000","1.12458","0.19061"
"1.12708","26.10856","1.05250","281.82000","0.00000","1.12708","0.19103"
"1.12938","26.18554","1.05560","282.43000","0.00000","1.12938","0.19142"
"1.13188","26.28228","1.05950","283.04000","0.00000","1.13188","0.19184"
"1.13438","26.38366","1.06359","283.65000","0.00000","1.13438","0.19227"
"1.13688","26.48005","1.06747","284.26000","0.00000","1.13688","0.19269"
"1.13938","26.57290","1.07121","284.87000","0.00000","1.13938","0.19311"
"1.14167","26.67434","1.07530","285.48000","0.00000","1.14167","0.19350"
"1.14417","26.75839","1.07869","286.09000","0.00000","1.14417","0.19393"
"1.14667","26.86827","1.08312","286.70000","0.00000","1.14667","0.19435"
"1.14896","26.95024","1.08643","287.31000","0.00000","1.14896","0.19474"
"1.15146","27.05795","1.09077","287.92000","0.00000","1.15146","0.19516"
"1.15396","27.15864","1.09483","288.53000","0.00000","1.15396","0.19559"
"1.15646","27.25044","1.09853","289.14000","0.00000","1.15646","0.19601"
"1.15896","27.32935","1.10171","289.75000","0.00000","1.15896","0.19643"
"1.16125","27.42831","1.10570","290.36000","0.00000","1.16125","0.19682"
"1.16375","27.52166","1.10946","290.97000","0.00000","1.16375","0.19725"
"1.16625","27.61620","1.11327","291.58000","0.00000","1.16625","0.19767"
"1.16875","27.71124","1.11710","292.19000","0.00000","1.16875","0.19809"
"1.17083","27.79620","1.12053","292.80000","0.00000","1.17083","0.19845"
"1.17333","27.89677","1.12458","293.41000","0.00000","1.17333","0.19887"
"1.17583","28.00457","1.12893","294.02000","0.00000","1.17583","0.19929"
"1.17833","28.08872","1.13232","294.63000","0.00000","1.17833","0.19972"
"1.18021","28.13790","1.13430","295.22800","0.00000","1.18021","0.20004"
"1.18042","27.97272","1.12764","295.83800","0.00000","1.18042","0.20007"
"1.18042","27.85569","1.12293","296.44800","0.00000","1.18042","0.20007"
"1.18042","27.75449","1.11885","297.05800","0.00000","1.18042","0.20007"
"1.18042","27.66920","1.11541","297.66800","0.00000","1.18042","0.20007"
"1.18042","27.59854","1.11256","298.27800","0.00000","1.18042","0.20007"
"1.18000","27.51203","1.10907","298.88800","0.00000","1.18000","0.20000"
"1.18000","27.45625","1.10682","299.49800","0.00000","1.18000","0.20000"
"1.18000","27.40030","1.10457","300.10800","0.00000","1.18000","0.20000"
"1.18000","27.34929","1.10251","300.71800","0.00000","1.18000","0.20000"
"1.18000","27.29555","1.10035","301.32800","0.00000","1.18000","0.20000"
"1.18000","27.24995","1.09851","301.93800","0.00000","1.18000","0.20000"
"1.18000","27.20773","1.09681","302.54800","0.00000","1.18000","0.20000"
"1.18000","27.16801","1.09520","303.15800","0.00000","1.18000","0.20000"
"1.18000","27.13379","1.09383","303.76800","0.00000","1.18000","0.20000"
"1.18000","27.09970","1.09245","304.37800","0.00000","1.18000","0.20000"
"1.18000","27.05754","1.09075","304.98800","0.00000","1.18000","0.20000"
"1.18000","27.01821","1.08917","305.59800","0.00000","1.18000","0.20000"
"1.18000","26.99056","1.08805","306.20800","0.00000","1.18000","0.20000"
"1.18000","26.95533","1.08663","306.81800","0.00000","1.18000","0.20000"
"1.18000","26.92679","1.08548","307.42800","0.00000","1.18000","0.20000"
"1.18000","26.89784","1.08431","308.03800","0.00000","1.18000","0.20000"
"1.18000","26.86528","1.08300","308.64800","0.00000","1.18000","0.20000"
"1.18000","26.83284","1.08169","309.25800","0.00000","1.18000","0.20000"
"1.18000","26.81244","1.08087","309.86800","0.00000","1.18000","0.20000"
"1.18000","26.78068","1.07959","310.47800","0.00000","1.18000","0.20000"
"1.18000","26.76974","1.07915","311.08800","0.00000","1.18000","0.20000"
"1.18000","26.73623","1.07780","311.69800","0.00000","1.18000","0.20000"
"1.18000","26.70220","1.07643","312.30800","0.00000","1.18000","0.20000"
"1.18000","26.68177","1.07560","312.91800","0.00000","1.18000","0.20000"
"1.18000","26.67027","1.07514","313.52800","0.00000","1.18000","0.20000"
"1.18000","26.62397","1.07327","314.13800","0.00000","1.18000","0.20000"
"1.18000","26.62637","1.07337","314.74800","0.00000","1.18000","0.20000"
"1.18000","26.60066","1.07233","315.35800","0.00000","1.18000","0.20000"
"1.18000","26.57374","1.07125","315.96800","0.00000","1.18000","0.20000"
"1.18000","26.54409","1.07005","316.57800","0.00000","1.18000","0.20000"
"1.18000","26.53595","1.06972","317.18800","0.00000","1.18000","0.20000"
"1.18000","26.51522","1.06889","317.79800","0.00000","1.18000","0.20000"
"1.18000","26.49617","1.06812","318.40800","0.00000","1.18000","0.20000"
"1.18000","26.47699","1.06735","319.01800","0.00000","1.18000","0.20000"
"1.18000","26.45328","1.06639","319.62800","0.00000","1.18000","0.20000"
"1.18000","26.43609","1.06570","320.23800","0.00000","1.18000","0.20000"
"1.18000","26.41343","1.06479","320.84800","0.00000","1.18000","0.20000"
"1.18000","26.40769","1.06455","321.45800","0.00000","1.18000","0.20000"
"1.18000","26.38227","1.06353","322.06800","0.00000","1.18000","0.20000"
"1.18000","26.35882","1.06258","322.67800","0.00000","1.18000","0.20000"
"1.18000","26.34464","1.06201","323.28800","0.00000","1.18000","0.20000"
"1.18000","26.32629","1.06127","323.89800","0.00000","1.18000","0.20000"
"1.18000","26.31295","1.06074","324.50800","0.00000","1.18000","0.20000"
"1.18000","26.30259","1.06032","325.11800","0.00000","1.18000","0.20000"
"1.18000","26.28367","1.05955","325.72800","0.00000","1.18000","0.20000"
"1.18000","26.27654","1.05927","326.33800","0.00000","1.18000","0.20000"
"1.18000","26.25972","1.05859","326.94800","0.00000","1.18000","0.20000"
"1.18000","26.24192","1.05787","327.55800","0.00000","1.18000","0.20000"
"1.18000","26.22489","1.05719","328.16800","0.00000","1.18000","0.20000"
"1.18000","26.21564","1.05681","328.77800","0.00000","1.18000","0.20000"
"1.18000","26.19304","1.05590","329.38800","0.00000","1.18000","0.20000"
"1.18000","26.18685","1.05565","329.99800","0.00000","1.18000","0.20000"
"1.18000","26.17268","1.05508","330.60800","0.00000","1.18000","0.20000"
"1.18000","26.15583","1.05440","331.21800","0.00000","1.18000","0.20000"
"1.18000","26.13990","1.05376","331.82800","0.00000","1.18000","0.20000"
"1.18000","26.12195","1.05304","332.43800","0.00000","1.18000","0.20000"
"1.18000","26.11068","1.05258","333.04800","0.00000","1.18000","0.20000"
"1.18000","26.09455","1.05193","333.65800","0.00000","1.18000","0.20000"
"1.18000","26.08075","1.05137","334.26800","0.00000","1.18000","0.20000"
"1.18000","26.07057","1.05096","334.87800","0.00000","1.18000","0.20000"
"1.18000","26.05886","1.05049","335.48800","0.00000","1.18000","0.20000"
"1.18000","26.05047","1.05015","336.09800","0.00000","1.18000","0.20000"
"1.18000","26.03361","1.04947","336.70800","0.00000","1.18000","0.20000"
"1.18000","26.03208","1.04941","337.31800","0.00000","1.18000","0.20000"
"1.18000","26.01664","1.04879","337.92800","0.00000","1.18000","0.20000"
"1.18000","26.00497","1.04832","338.53800","0.00000","1.18000","0.20000"
"1.18000","25.98955","1.04770","339.14800","0.00000","1.18000","0.20000"
"1.18000","25.97959","1.04730","339.75800","0.00000","1.18000","0.20000"
"1.18000","25.96913","1.04688","340.36800","0.00000","1.18000","0.20000"
"1.18000","25.95253","1.04621","340.97800","0.00000","1.18000","0.20000"
"1.18000","25.93930","1.04567","341.58800","0.00000","1.18000","0.20000"
"1.18000","25.93098","1.04534","342.19800","0.00000","1.18000","0.20000"
"1.18000","25.91372","1.04464","342.80800","0.00000","1.18000","0.20000"
"1.18000","25.91234","1.04459","343.41800","0.00000","1.18000","0.20000"
"1.18000","25.89405","1.04385","344.02800","0.00000","1.18000","0.20000"
"1.18000","25.88526","1.04349","344.63800","0.00000","1.18000","0.20000"
"1.18000","25.87929","1.04325","345.24800","0.00000","1.18000","0.20000"
"1.18000","25.87204","1.04296","345.85800","0.00000","1.18000","0.20000"
"1.18000","25.84807","1.04199","346.46800","0.00000","1.18000","0.20000"
"1.18000","25.84491","1.04187","347.07800","0.00000","1.18000","0.20000"
"1.18000","25.81782","1.04078","347.68800","0.00000","1.18000","0.20000"
"1.18000","25.83246","1.04137","348.29800","0.00000","1.18000","0.20000"
"1.18000","25.80385","1.04021","348.90800","0.00000","1.18000","0.20000"
"1.18000","25.80993","1.04046","349.51800","0.00000","1.18000","0.20000"
"1.18000","25.80726","1.04035","350.12800","0.00000","1.18000","0.20000"
"1.18000","25.76996","1.03885","350.73800","0.00000","1.18000","0.20000"
"1.18000","25.76658","1.03871","351.34800","0.00000","1.18000","0.20000"
"1.18000","25.75529","1.03825","351.95800","0.00000","1.18000","0.20000"
"1.18000","25.75050","1.03806","352.56800","0.00000","1.18000","0.20000"
"1.18000","25.74156","1.03770","353.17800","0.00000","1.18000","0.20000"
"1.18000","25.75051","1.03806","353.78800","0.00000","1.18000","0.20000"
"1.18000","25.71599","1.03667","354.39800","0.00000","1.18000","0.20000"
"1.18000","25.72998","1.03723","355.00800","0.00000","1.18000","0.20000"
"1.18000","25.70719","1.03632","355.61800","0.00000","1.18000","0.20000"
"1.18000","25.70232","1.03612","356.22800","0.00000","1.18000","0.20000"
"1.18000","25.69844","1.03596","356.83800","0.00000","1.18000","0.20000"
"1.18000","25.67582","1.03505","357.44800","0.00000","1.18000","0.20000"
"1.18000","25.67745","1.03512","358.05800","0.00000","1.18000","0.20000"
"1.18000","25.66382","1.03457","358.66800","0.00000","1.18000","0.20000"
"1.18000","25.65787","1.03433","359.27800","0.00000","1.18000","0.20000"
"1.18000","25.64478","1.03380","359.88800","0.00000","1.18000","0.20000"
"1.18000","25.64863","1.03396","360.49800","0.00000","1.18000","0.20000"
"1.18000","25.63541","1.03342","361.10800","0.00000","1.18000","0.20000"
"1.18000","25.62934","1.03318","361.71800","0.00000","1.18000","0.20000"
"1.18000","25.60589","1.03223","362.32800","0.00000","1.18000","0.20000"
"1.18000","25.61387","1.03255","362.93800","0.00000","1.18000","0.20000"
"1.18000","25.59840","1.03193","363.54800","0.00000","1.18000","0.20000"
"1.18000","25.58165","1.03125","364.15800","0.00000","1.18000","0.20000"
"1.18000","25.59418","1.03176","364.76800","0.00000","1.18000","0.20000"
"1.18000","25.56063","1.03041","365.37800","0.00000","1.18000","0.20000"
"1.18000","25.56421","1.03055","365.98800","0.00000","1.18000","0.20000"
"1.18000","25.54952","1.02996","366.59800","0.00000","1.18000","0.20000"
"1.18000","25.55066","1.03001","367.20800","0.00000","1.18000","0.20000"
"1.18000","25.54266","1.02968","367.81800","0.00000","1.18000","0.20000"
"1.18000","25.52785","1.02909","368.42800","0.00000","1.18000","0.20000"
"1.18000","25.52863","1.02912","369.03800","0.00000","1.18000","0.20000"
"1.18000","25.51896","1.02873","369.64800","0.00000","1.18000","0.20000"
"1.18000","25.51053","1.02839","370.25800","0.00000","1.18000","0.20000"
"1.18000","25.49537","1.02778","370.86800","0.00000","1.18000","0.20000"
"1.18000","25.49033","1.02757","371.47800","0.00000","1.18000","0.20000"
"1.18000","25.49213","1.02765","372.08800","0.00000","1.18000","0.20000"
"1.18000","25.48552","1.02738","372.69800","0.00000","1.18000","0.20000"
"1.18000","25.47604","1.02700","373.30800","0.00000","1.18000","0.20000"
"1.18000","25.46696","1.02663","373.91800","0.00000","1.18000","0.20000"
"1.18000","25.45386","1.02610","374.52800","0.00000","1.18000","0.20000"
"1.18000","25.45476","1.02614","375.13800","0.00000","1.18000","0.20000"
"1.18000","25.44202","1.02563","375.74800","0.00000","1.18000","0.20000"
"1.18000","25.43829","1.02548","376.35800","0.00000","1.18000","0.20000"
"1.18000","25.42259","1.02484","376.96800","0.00000","1.18000","0.20000"
"1.18000","25.43067","1.02517","377.57800","0.00000","1.18000","0.20000"
"1.18000","25.41638","1.02459","378.18800","0.00000","1.18000","0.20000"
"1.18000","25.41293","1.02445","378.79800","0.00000","1.18000","0.20000"
"1.18000","25.40249","1.02403","379.40800","0.00000","1.18000","0.20000"
"1.18000","25.39552","1.02375","380.01800","0.00000","1.18000","0.20000"
"1.18000","25.39686","1.02381","380.62800","0.00000","1.18000","0.20000"
"1.18000","25.38162","1.02319","381.23800","0.00000","1.18000","0.20000"
"1.18000","25.37761","1.02303","381.84800","0.00000","1.18000","0.20000"
"1.18000","25.36730","1.02261","382.45800","0.00000","1.18000","0.20000"
"1.18000","25.36539","1.02254","383.06800","0.00000","1.18000","0.20000"
"1.18000","25.35340","1.02205","383.67800","0.00000","1.18000","0.20000"
"1.18000","25.35637","1.02217","384.28800","0.00000","1.18000","0.20000"
"1.18000","25.33715","1.02140","384.89800","0.00000","1.18000","0.20000"
"1.18000","25.33729","1.02140","385.50800","0.00000","1.18000","0.20000"
"1.18000","25.32485","1.02090","386.11800","0.00000","1.18000","0.20000"
"1.18000","25.32752","1.02101","386.72800","0.00000","1.18000","0.20000"
"1.18000","25.31784","1.02062","387.33800","0.00000","1.18000","0.20000"
"1.18000","25.30195","1.01998","387.94800","0.00000","1.18000","0.20000"
"1.18000","25.29975","1.01989","388.55800","0.00000","1.18000","0.20000"
"1.18000","25.30273","1.02001","389.16800","0.00000","1.18000","0.20000"
"1.18000","25.30286","1.02002","389.77800","0.00000","1.18000","0.20000"
"1.18000","25.28338","1.01923","390.38800","0.00000","1.18000","0.20000"
"1.18000","25.27897","1.01905","390.99800","0.00000","1.18000","0.20000"
"1.18000","25.27416","1.01886","391.60800","0.00000","1.18000","0.20000"
"1.18000","25.26335","1.01842","392.21800","0.00000","1.18000","0.20000"
"1.18000","25.26560","1.01851","392.82800","0.00000","1.18000","0.20000"
"1.18000","25.26439","1.01847","393.43800","0.00000","1.18000","0.20000"
"1.18000","25.25707","1.01817","394.04800","0.00000","1.18000","0.20000"
"1.18000","25.23804","1.01740","394.65800","0.00000","1.18000","0.20000"
"1.18000","25.23507","1.01728","395.26800","0.00000","1.18000","0.20000"
"1.18000","25.23315","1.01721","395.87800","0.00000","1.18000","0.20000"
"1.18000","25.22129","1.01673","396.48800","0.00000","1.18000","0.20000"
"1.18000","25.21332","1.01641","397.09800","0.00000","1.18000","0.20000"
"1.18000","25.21385","1.01643","397.70800","0.00000","1.18000","0.20000"
"1.18000","25.21358","1.01642","398.31800","0.00000","1.18000","0.20000"
"1.18000","25.20067","1.01590","398.92800","0.00000","1.18000","0.20000"
"1.18000","25.19699","1.01575","399.53800","0.00000","1.18000","0.20000"
"1.18000","25.19277","1.01558","400.14800","0.00000","1.18000","0.20000"
"1.18000","25.17902","1.01502","400.75800","0.00000","1.18000","0.20000"
"1.18000","25.17715","1.01495","401.36800","0.00000","1.18000","0.20000"
"1.18000","25.17434","1.01484","401.97800","0.00000","1.18000","0.20000"
"1.18000","25.16243","1.01436","402.58800","0.00000","1.18000","0.20000"
"1.18000","25.15884","1.01421","403.19800","0.00000","1.18000","0.20000"
"1.18000","25.15661","1.01412","403.80800","0.00000","1.18000","0.20000"
"1.18000","25.15672","1.01413","404.41800","0.00000","1.18000","0.20000"
"1.18000","25.15092","1.01389","405.02800","0.00000","1.18000","0.20000"
"1.18000","25.14139","1.01351","405.63800","0.00000","1.18000","0.20000"
"1.18000","25.13998","1.01345","406.24800","0.00000","1.18000","0.20000"
"1.18000","25.13736","1.01334","406.85800","0.00000","1.18000","0.20000"
"1.18000","25.13480","1.01324","407.46800","0.00000","1.18000","0.20000"
"1.18000","25.11998","1.01264","408.07800","0.00000","1.18000","0.20000"
"1.18000","25.11660","1.01251","408.68800","0.00000","1.18000","0.20000"
"1.18000","25.10623","1.01209","409.29800","0.00000","1.18000","0.20000"
"1.18000","25.10091","1.01188","409.90800","0.00000","1.18000","0.20000"
"1.18000","25.10456","1.01202","410.51800","0.00000","1.18000","0.20000"
"1.18000","25.09916","1.01180","411.12800","0.00000","1.18000","0.20000"
"1.18000","25.09122","1.01148","411.73800","0.00000","1.18000","0.20000"
"1.18000","25.08261","1.01114","412.34800","0.00000","1.18000","0.20000"
"1.18000","25.06839","1.01056","412.95800","0.00000","1.18000","0.20000"
"1.18000","25.07127","1.01068","413.56800","0.00000","1.18000","0.20000"
"1.18000","25.06963","1.01061","414.17800","0.00000","1.18000","0.20000"
"1.18000","25.06653","1.01049","414.78800","0.00000","1.18000","0.20000"
"1.18000","25.06537","1.01044","415.01800","0.00000","1.18000","0.20000"