File: Rubber Stress Relaxation Raw Data - Small Samples-20210211/Specimen_RawData_8.csv
Specimen properties : Specimen label,"GCIS1R2"
Specimen properties : Anvil height,"5.98000",mm
Specimen properties : Diameter,"5.40000",mm
Test : Rate 1,"2.40000",mm/min
Test : Start of hold value,"20.00000",%
Test : Duration,"120.00000",s

Extension,Load,Compressive stress,Time,PIP count,Compressive extension,Compressive strain (Extension)
(mm),(N),(MPa),(s),,(mm),(mm/mm)
"-0.00021","0.02553","0.00111","0.00000","0.00000","-0.00021","-0.00003"
"0.00292","0.16287","0.00711","0.22000","0.00000","0.00292","0.00049"
"0.01562","0.87245","0.03809","0.44000","0.00000","0.01562","0.00261"
"0.02583","1.28993","0.05632","0.66000","0.00000","0.02583","0.00432"
"0.03458","1.60568","0.07011","0.88000","0.00000","0.03458","0.00578"
"0.04354","1.91829","0.08376","1.10000","0.00000","0.04354","0.00728"
"0.05229","2.21054","0.09652","1.32000","0.00000","0.05229","0.00874"
"0.06125","2.49625","0.10900","1.54000","0.00000","0.06125","0.01024"
"0.06958","2.75471","0.12028","1.76000","0.00000","0.06958","0.01164"
"0.07875","3.05719","0.13349","1.98000","0.00000","0.07875","0.01317"
"0.08771","3.33009","0.14540","2.20000","0.00000","0.08771","0.01467"
"0.09667","3.61776","0.15797","2.42000","0.00000","0.09667","0.01616"
"0.10542","3.87988","0.16941","2.64000","0.00000","0.10542","0.01763"
"0.11396","4.13330","0.18048","2.86000","0.00000","0.11396","0.01906"
"0.12271","4.39584","0.19194","3.08000","0.00000","0.12271","0.02052"
"0.13187","4.67890","0.20430","3.30000","0.00000","0.13187","0.02205"
"0.14063","4.94242","0.21581","3.52000","0.00000","0.14063","0.02352"
"0.14917","5.19473","0.22682","3.74000","0.00000","0.14917","0.02494"
"0.15771","5.45656","0.23825","3.96000","0.00000","0.15771","0.02637"
"0.16667","5.74202","0.25072","4.18000","0.00000","0.16667","0.02787"
"0.17542","6.01834","0.26278","4.40000","0.00000","0.17542","0.02933"
"0.18458","6.29654","0.27493","4.62000","0.00000","0.18458","0.03087"
"0.19333","6.56514","0.28666","4.84000","0.00000","0.19333","0.03233"
"0.20208","6.84345","0.29881","5.06000","0.00000","0.20208","0.03379"
"0.21104","7.14551","0.31200","5.28000","0.00000","0.21104","0.03529"
"0.22000","7.43600","0.32468","5.50000","0.00000","0.22000","0.03679"
"0.22854","7.70315","0.33635","5.72000","0.00000","0.22854","0.03822"
"0.23688","7.98316","0.34858","5.94000","0.00000","0.23688","0.03961"
"0.24583","8.29324","0.36212","6.16000","0.00000","0.24583","0.04111"
"0.25479","8.58709","0.37495","6.38000","0.00000","0.25479","0.04261"
"0.26375","8.85997","0.38686","6.60000","0.00000","0.26375","0.04411"
"0.27250","9.12813","0.39857","6.82000","0.00000","0.27250","0.04557"
"0.28125","9.39610","0.41027","7.04000","0.00000","0.28125","0.04703"
"0.29021","9.67171","0.42230","7.26000","0.00000","0.29021","0.04853"
"0.29896","9.93092","0.43362","7.48000","0.00000","0.29896","0.04999"
"0.30792","10.18668","0.44479","7.70000","0.00000","0.30792","0.05149"
"0.31667","10.42865","0.45536","7.92000","0.00000","0.31667","0.05295"
"0.32542","10.69117","0.46682","8.14000","0.00000","0.32542","0.05442"
"0.33417","10.95022","0.47813","8.36000","0.00000","0.33417","0.05588"
"0.34292","11.18612","0.48843","8.58000","0.00000","0.34292","0.05734"
"0.35167","11.42726","0.49896","8.80000","0.00000","0.35167","0.05881"
"0.36062","11.68686","0.51029","9.02000","0.00000","0.36062","0.06031"
"0.36938","11.93723","0.52123","9.24000","0.00000","0.36938","0.06177"
"0.37792","12.16286","0.53108","9.46000","0.00000","0.37792","0.06320"
"0.38667","12.40181","0.54151","9.68000","0.00000","0.38667","0.06466"
"0.39563","12.65421","0.55253","9.90000","0.00000","0.39563","0.06616"
"0.40458","12.89830","0.56319","10.12000","0.00000","0.40458","0.06766"
"0.41313","13.14201","0.57383","10.34000","0.00000","0.41313","0.06908"
"0.42208","13.38921","0.58463","10.56000","0.00000","0.42208","0.07058"
"0.43083","13.62772","0.59504","10.78000","0.00000","0.43083","0.07205"
"0.44000","13.88903","0.60645","11.00000","0.00000","0.44000","0.07358"
"0.44875","14.12718","0.61685","11.22000","0.00000","0.44875","0.07504"
"0.45729","14.34586","0.62640","11.44000","0.00000","0.45729","0.07647"
"0.46583","14.58852","0.63699","11.66000","0.00000","0.46583","0.07790"
"0.47479","14.83527","0.64777","11.88000","0.00000","0.47479","0.07940"
"0.48375","15.09587","0.65914","12.10000","0.00000","0.48375","0.08089"
"0.49250","15.34057","0.66983","12.32000","0.00000","0.49250","0.08236"
"0.50125","15.58167","0.68036","12.54000","0.00000","0.50125","0.08382"
"0.51000","15.82493","0.69098","12.76000","0.00000","0.51000","0.08528"
"0.51917","16.08782","0.70246","12.98000","0.00000","0.51917","0.08682"
"0.52792","16.32566","0.71284","13.20000","0.00000","0.52792","0.08828"
"0.53646","16.55982","0.72307","13.42000","0.00000","0.53646","0.08971"
"0.54500","16.79617","0.73339","13.64000","0.00000","0.54500","0.09114"
"0.55396","17.06277","0.74503","13.86000","0.00000","0.55396","0.09264"
"0.56313","17.32248","0.75637","14.08000","0.00000","0.56313","0.09417"
"0.57167","17.53765","0.76576","14.30000","0.00000","0.57167","0.09560"
"0.58042","17.78306","0.77648","14.52000","0.00000","0.58042","0.09706"
"0.58917","18.03618","0.78753","14.74000","0.00000","0.58917","0.09852"
"0.59813","18.31053","0.79951","14.96000","0.00000","0.59813","0.10002"
"0.60729","18.56539","0.81064","15.18000","0.00000","0.60729","0.10155"
"0.61563","18.77895","0.81996","15.40000","0.00000","0.61563","0.10295"
"0.62417","19.02186","0.83057","15.62000","0.00000","0.62417","0.10438"
"0.63313","19.31281","0.84327","15.84000","0.00000","0.63313","0.10587"
"0.64250","19.59896","0.85577","16.06000","0.00000","0.64250","0.10744"
"0.65104","19.81152","0.86505","16.28000","0.00000","0.65104","0.10887"
"0.65979","20.07009","0.87634","16.50000","0.00000","0.65979","0.11033"
"0.66833","20.30929","0.88678","16.72000","0.00000","0.66833","0.11176"
"0.67729","20.58236","0.89871","16.94000","0.00000","0.67729","0.11326"
"0.68625","20.84994","0.91039","17.16000","0.00000","0.68625","0.11476"
"0.69479","21.07726","0.92032","17.38000","0.00000","0.69479","0.11619"
"0.70333","21.32489","0.93113","17.60000","0.00000","0.70333","0.11761"
"0.71229","21.60764","0.94347","17.82000","0.00000","0.71229","0.11911"
"0.72167","21.90975","0.95667","18.04000","0.00000","0.72167","0.12068"
"0.73042","22.15877","0.96754","18.26000","0.00000","0.73042","0.12214"
"0.73917","22.39864","0.97801","18.48000","0.00000","0.73917","0.12361"
"0.74750","22.63512","0.98834","18.70000","0.00000","0.74750","0.12500"
"0.75646","22.92593","1.00104","18.92000","0.00000","0.75646","0.12650"
"0.76563","23.20503","1.01322","19.14000","0.00000","0.76562","0.12803"
"0.77417","23.44251","1.02359","19.36000","0.00000","0.77417","0.12946"
"0.78250","23.64600","1.03248","19.58000","0.00000","0.78250","0.13085"
"0.79125","23.94456","1.04551","19.80000","0.00000","0.79125","0.13232"
"0.80042","24.24991","1.05885","20.02000","0.00000","0.80042","0.13385"
"0.80958","24.51372","1.07036","20.24000","0.00000","0.80958","0.13538"
"0.81813","24.74117","1.08030","20.46000","0.00000","0.81813","0.13681"
"0.82646","25.00830","1.09196","20.68000","0.00000","0.82646","0.13820"
"0.83563","25.30972","1.10512","20.90000","0.00000","0.83563","0.13974"
"0.84479","25.60737","1.11812","21.12000","0.00000","0.84479","0.14127"
"0.85375","25.86643","1.12943","21.34000","0.00000","0.85375","0.14277"
"0.86208","26.09398","1.13936","21.56000","0.00000","0.86208","0.14416"
"0.87063","26.37950","1.15183","21.78000","0.00000","0.87063","0.14559"
"0.87979","26.71179","1.16634","22.00000","0.00000","0.87979","0.14712"
"0.88875","26.99266","1.17861","22.22000","0.00000","0.88875","0.14862"
"0.89750","27.26532","1.19051","22.44000","0.00000","0.89750","0.15008"
"0.90583","27.50408","1.20094","22.66000","0.00000","0.90583","0.15148"
"0.91479","27.80209","1.21395","22.88000","0.00000","0.91479","0.15298"
"0.92375","28.10941","1.22737","23.10000","0.00000","0.92375","0.15447"
"0.93292","28.41213","1.24058","23.32000","0.00000","0.93292","0.15601"
"0.94125","28.65412","1.25115","23.54000","0.00000","0.94125","0.15740"
"0.95000","28.92718","1.26307","23.76000","0.00000","0.95000","0.15886"
"0.95896","29.26178","1.27768","23.98000","0.00000","0.95896","0.16036"
"0.96792","29.57572","1.29139","24.20000","0.00000","0.96792","0.16186"
"0.97688","29.85660","1.30366","24.42000","0.00000","0.97688","0.16336"
"0.98521","30.10530","1.31452","24.64000","0.00000","0.98521","0.16475"
"0.99375","30.39606","1.32721","24.86000","0.00000","0.99375","0.16618"
"1.00292","30.73009","1.34180","25.08000","0.00000","1.00292","0.16771"
"1.01167","31.00509","1.35380","25.30000","0.00000","1.01167","0.16918"
"1.02062","31.33478","1.36820","25.52000","0.00000","1.02062","0.17067"
"1.02917","31.59294","1.37947","25.74000","0.00000","1.02917","0.17210"
"1.03792","31.90446","1.39307","25.96000","0.00000","1.03792","0.17356"
"1.04688","32.21845","1.40678","26.18000","0.00000","1.04688","0.17506"
"1.05563","32.51733","1.41983","26.40000","0.00000","1.05563","0.17653"
"1.06458","32.82362","1.43321","26.62000","0.00000","1.06458","0.17802"
"1.07313","33.11079","1.44575","26.84000","0.00000","1.07313","0.17945"
"1.08208","33.44357","1.46028","27.06000","0.00000","1.08208","0.18095"
"1.09083","33.73344","1.47293","27.28000","0.00000","1.09083","0.18241"
"1.09979","34.05492","1.48697","27.50000","0.00000","1.09979","0.18391"
"1.10854","34.36667","1.50058","27.72000","0.00000","1.10854","0.18537"
"1.11729","34.68629","1.51454","27.94000","0.00000","1.11729","0.18684"
"1.12625","35.01262","1.52879","28.16000","0.00000","1.12625","0.18834"
"1.13500","35.32232","1.54231","28.38000","0.00000","1.13500","0.18980"
"1.14396","35.62687","1.55561","28.60000","0.00000","1.14396","0.19130"
"1.15271","35.94421","1.56946","28.82000","0.00000","1.15271","0.19276"
"1.16146","36.27439","1.58388","29.04000","0.00000","1.16146","0.19422"
"1.17021","36.59938","1.59807","29.26000","0.00000","1.17021","0.19569"
"1.17896","36.89639","1.61104","29.48000","0.00000","1.17896","0.19715"
"1.18771","37.22249","1.62528","29.70000","0.00000","1.18771","0.19861"
"1.19604","37.55275","1.63970","29.90800","0.00000","1.19604","0.20001"
"1.19750","36.94165","1.61302","30.12800","0.00000","1.19750","0.20025"
"1.19750","36.39144","1.58899","30.34800","0.00000","1.19750","0.20025"
"1.19750","36.00709","1.57221","30.56800","0.00000","1.19750","0.20025"
"1.19750","35.69837","1.55873","30.78800","0.00000","1.19750","0.20025"
"1.19708","35.42181","1.54665","31.00800","0.00000","1.19708","0.20018"
"1.19687","35.20467","1.53717","31.22800","0.00000","1.19687","0.20015"
"1.19687","35.00915","1.52864","31.44800","0.00000","1.19687","0.20015"
"1.19667","34.82368","1.52054","31.66800","0.00000","1.19667","0.20011"
"1.19667","34.66910","1.51379","31.88800","0.00000","1.19667","0.20011"
"1.19646","34.52023","1.50729","32.10800","0.00000","1.19646","0.20008"
"1.19646","34.37012","1.50073","32.32800","0.00000","1.19646","0.20008"
"1.19625","34.24218","1.49515","32.54800","0.00000","1.19625","0.20004"
"1.19625","34.13361","1.49041","32.76800","0.00000","1.19625","0.20004"
"1.19604","34.01809","1.48536","32.98800","0.00000","1.19604","0.20001"
"1.19604","33.91164","1.48071","33.20800","0.00000","1.19604","0.20001"
"1.19604","33.82628","1.47699","33.42800","0.00000","1.19604","0.20001"
"1.19604","33.72766","1.47268","33.64800","0.00000","1.19604","0.20001"
"1.19604","33.65394","1.46946","33.86800","0.00000","1.19604","0.20001"
"1.19604","33.56912","1.46576","34.08800","0.00000","1.19604","0.20001"
"1.19604","33.48899","1.46226","34.30800","0.00000","1.19604","0.20001"
"1.19604","33.42119","1.45930","34.52800","0.00000","1.19604","0.20001"
"1.19604","33.34034","1.45577","34.74800","0.00000","1.19604","0.20001"
"1.19604","33.27322","1.45284","34.96800","0.00000","1.19604","0.20001"
"1.19604","33.20651","1.44993","35.18800","0.00000","1.19604","0.20001"
"1.19604","33.14412","1.44720","35.40800","0.00000","1.19604","0.20001"
"1.19604","33.07693","1.44427","35.62800","0.00000","1.19604","0.20001"
"1.19604","33.01682","1.44164","35.84800","0.00000","1.19604","0.20001"
"1.19604","32.96498","1.43938","36.06800","0.00000","1.19604","0.20001"
"1.19604","32.91261","1.43709","36.28800","0.00000","1.19604","0.20001"
"1.19604","32.85707","1.43467","36.50800","0.00000","1.19604","0.20001"
"1.19604","32.80065","1.43220","36.72800","0.00000","1.19604","0.20001"
"1.19604","32.74567","1.42980","36.94800","0.00000","1.19604","0.20001"
"1.19604","32.69838","1.42774","37.16800","0.00000","1.19604","0.20001"
"1.19604","32.65143","1.42569","37.38800","0.00000","1.19604","0.20001"
"1.19604","32.60426","1.42363","37.60800","0.00000","1.19604","0.20001"
"1.19604","32.55460","1.42146","37.82800","0.00000","1.19604","0.20001"
"1.19604","32.51040","1.41953","38.04800","0.00000","1.19604","0.20001"
"1.19604","32.46870","1.41771","38.26800","0.00000","1.19604","0.20001"
"1.19604","32.41509","1.41537","38.48800","0.00000","1.19604","0.20001"
"1.19604","32.38388","1.41401","38.70800","0.00000","1.19604","0.20001"
"1.19604","32.33968","1.41208","38.92800","0.00000","1.19604","0.20001"
"1.19604","32.30119","1.41040","39.14800","0.00000","1.19604","0.20001"
"1.19604","32.25517","1.40839","39.36800","0.00000","1.19604","0.20001"
"1.19604","32.22729","1.40717","39.58800","0.00000","1.19604","0.20001"
"1.19604","32.17645","1.40495","39.80800","0.00000","1.19604","0.20001"
"1.19604","32.15214","1.40389","40.02800","0.00000","1.19604","0.20001"
"1.19604","32.11296","1.40218","40.24800","0.00000","1.19604","0.20001"
"1.19604","32.06867","1.40024","40.46800","0.00000","1.19604","0.20001"
"1.19604","32.03977","1.39898","40.68800","0.00000","1.19604","0.20001"
"1.19604","32.01254","1.39779","40.90800","0.00000","1.19604","0.20001"
"1.19604","31.97347","1.39609","41.12800","0.00000","1.19604","0.20001"
"1.19604","31.94750","1.39495","41.34800","0.00000","1.19604","0.20001"
"1.19604","31.90231","1.39298","41.56800","0.00000","1.19604","0.20001"
"1.19604","31.87806","1.39192","41.78800","0.00000","1.19604","0.20001"
"1.19604","31.84703","1.39057","42.00800","0.00000","1.19604","0.20001"
"1.19604","31.81202","1.38904","42.22800","0.00000","1.19604","0.20001"
"1.19604","31.78395","1.38781","42.44800","0.00000","1.19604","0.20001"
"1.19604","31.75639","1.38661","42.66800","0.00000","1.19604","0.20001"
"1.19604","31.72473","1.38523","42.88800","0.00000","1.19604","0.20001"
"1.19604","31.69597","1.38397","43.10800","0.00000","1.19604","0.20001"
"1.19604","31.67146","1.38290","43.32800","0.00000","1.19604","0.20001"
"1.19604","31.63696","1.38139","43.54800","0.00000","1.19604","0.20001"
"1.19604","31.61874","1.38060","43.76800","0.00000","1.19604","0.20001"
"1.19604","31.58257","1.37902","43.98800","0.00000","1.19604","0.20001"
"1.19604","31.55905","1.37799","44.20800","0.00000","1.19604","0.20001"
"1.19604","31.53686","1.37702","44.42800","0.00000","1.19604","0.20001"
"1.19604","31.51870","1.37623","44.64800","0.00000","1.19604","0.20001"
"1.19604","31.48019","1.37455","44.86800","0.00000","1.19604","0.20001"
"1.19604","31.46239","1.37377","45.08800","0.00000","1.19604","0.20001"
"1.19604","31.43608","1.37262","45.30800","0.00000","1.19604","0.20001"
"1.19604","31.40990","1.37148","45.52800","0.00000","1.19604","0.20001"
"1.19604","31.37930","1.37014","45.74800","0.00000","1.19604","0.20001"
"1.19604","31.36010","1.36930","45.96800","0.00000","1.19604","0.20001"
"1.19604","31.32974","1.36798","46.18800","0.00000","1.19604","0.20001"
"1.19604","31.31911","1.36751","46.40800","0.00000","1.19604","0.20001"
"1.19604","31.29459","1.36644","46.62800","0.00000","1.19604","0.20001"
"1.19604","31.26957","1.36535","46.84800","0.00000","1.19604","0.20001"
"1.19604","31.24829","1.36442","47.06800","0.00000","1.19604","0.20001"
"1.19604","31.22128","1.36324","47.28800","0.00000","1.19604","0.20001"
"1.19604","31.20802","1.36266","47.50800","0.00000","1.19604","0.20001"
"1.19604","31.18944","1.36185","47.72800","0.00000","1.19604","0.20001"
"1.19604","31.15743","1.36046","47.94800","0.00000","1.19604","0.20001"
"1.19604","31.14100","1.35974","48.16800","0.00000","1.19604","0.20001"
"1.19604","31.12280","1.35894","48.38800","0.00000","1.19604","0.20001"
"1.19604","31.09992","1.35794","48.60800","0.00000","1.19604","0.20001"
"1.19604","31.08012","1.35708","48.82800","0.00000","1.19604","0.20001"
"1.19604","31.06485","1.35641","49.04800","0.00000","1.19604","0.20001"
"1.19604","31.03936","1.35530","49.26800","0.00000","1.19604","0.20001"
"1.19604","31.01883","1.35440","49.48800","0.00000","1.19604","0.20001"
"1.19604","30.99686","1.35344","49.70800","0.00000","1.19604","0.20001"
"1.19604","30.97935","1.35268","49.92800","0.00000","1.19604","0.20001"
"1.19604","30.96502","1.35205","50.14800","0.00000","1.19604","0.20001"
"1.19604","30.94291","1.35109","50.36800","0.00000","1.19604","0.20001"
"1.19604","30.92926","1.35049","50.58800","0.00000","1.19604","0.20001"
"1.19604","30.89939","1.34919","50.80800","0.00000","1.19604","0.20001"
"1.19604","30.88129","1.34840","51.02800","0.00000","1.19604","0.20001"
"1.19604","30.86998","1.34790","51.24800","0.00000","1.19604","0.20001"
"1.19604","30.86180","1.34755","51.46800","0.00000","1.19604","0.20001"
"1.19604","30.83422","1.34634","51.68800","0.00000","1.19604","0.20001"
"1.19604","30.81850","1.34566","51.90800","0.00000","1.19604","0.20001"
"1.19604","30.79539","1.34465","52.12800","0.00000","1.19604","0.20001"
"1.19604","30.78665","1.34427","52.34800","0.00000","1.19604","0.20001"
"1.19604","30.76337","1.34325","52.56800","0.00000","1.19604","0.20001"
"1.19604","30.75438","1.34286","52.78800","0.00000","1.19604","0.20001"
"1.19604","30.73008","1.34180","53.00800","0.00000","1.19604","0.20001"
"1.19604","30.71852","1.34129","53.22800","0.00000","1.19604","0.20001"
"1.19604","30.69909","1.34044","53.44800","0.00000","1.19604","0.20001"
"1.19604","30.68117","1.33966","53.66800","0.00000","1.19604","0.20001"
"1.19604","30.67210","1.33926","53.88800","0.00000","1.19604","0.20001"
"1.19604","30.65225","1.33840","54.10800","0.00000","1.19604","0.20001"
"1.19604","30.63737","1.33775","54.32800","0.00000","1.19604","0.20001"
"1.19604","30.62794","1.33734","54.54800","0.00000","1.19604","0.20001"
"1.19604","30.60154","1.33618","54.76800","0.00000","1.19604","0.20001"
"1.19604","30.59010","1.33568","54.98800","0.00000","1.19604","0.20001"
"1.19604","30.57315","1.33494","55.20800","0.00000","1.19604","0.20001"
"1.19604","30.55932","1.33434","55.42800","0.00000","1.19604","0.20001"
"1.19604","30.54473","1.33370","55.64800","0.00000","1.19604","0.20001"
"1.19604","30.52231","1.33272","55.86800","0.00000","1.19604","0.20001"
"1.19604","30.52130","1.33268","56.08800","0.00000","1.19604","0.20001"
"1.19604","30.50163","1.33182","56.30800","0.00000","1.19604","0.20001"
"1.19604","30.48621","1.33115","56.52800","0.00000","1.19604","0.20001"
"1.19604","30.47390","1.33061","56.74800","0.00000","1.19604","0.20001"
"1.19604","30.45117","1.32962","56.96800","0.00000","1.19604","0.20001"
"1.19604","30.44242","1.32924","57.18800","0.00000","1.19604","0.20001"
"1.19604","30.42675","1.32855","57.40800","0.00000","1.19604","0.20001"
"1.19604","30.40919","1.32778","57.62800","0.00000","1.19604","0.20001"
"1.19604","30.39919","1.32735","57.84800","0.00000","1.19604","0.20001"
"1.19604","30.38514","1.32673","58.06800","0.00000","1.19604","0.20001"
"1.19604","30.36978","1.32606","58.28800","0.00000","1.19604","0.20001"
"1.19604","30.35880","1.32558","58.50800","0.00000","1.19604","0.20001"
"1.19604","30.34616","1.32503","58.72800","0.00000","1.19604","0.20001"
"1.19604","30.34071","1.32479","58.94800","0.00000","1.19604","0.20001"
"1.19604","30.32121","1.32394","59.16800","0.00000","1.19604","0.20001"
"1.19604","30.30201","1.32310","59.38800","0.00000","1.19604","0.20001"
"1.19604","30.28261","1.32226","59.60800","0.00000","1.19604","0.20001"
"1.19604","30.28250","1.32225","59.82800","0.00000","1.19604","0.20001"
"1.19604","30.27333","1.32185","60.04800","0.00000","1.19604","0.20001"
"1.19604","30.26415","1.32145","60.26800","0.00000","1.19604","0.20001"
"1.19604","30.24458","1.32060","60.48800","0.00000","1.19604","0.20001"
"1.19604","30.23174","1.32004","60.70800","0.00000","1.19604","0.20001"
"1.19604","30.22189","1.31961","60.92800","0.00000","1.19604","0.20001"
"1.19604","30.20991","1.31908","61.14800","0.00000","1.19604","0.20001"
"1.19604","30.18695","1.31808","61.36800","0.00000","1.19604","0.20001"
"1.19604","30.18273","1.31790","61.58800","0.00000","1.19604","0.20001"
"1.19604","30.16464","1.31711","61.80800","0.00000","1.19604","0.20001"
"1.19604","30.16393","1.31708","62.02800","0.00000","1.19604","0.20001"
"1.19604","30.14583","1.31628","62.24800","0.00000","1.19604","0.20001"
"1.19604","30.13800","1.31594","62.46800","0.00000","1.19604","0.20001"
"1.19604","30.11656","1.31501","62.68800","0.00000","1.19604","0.20001"
"1.19604","30.11004","1.31472","62.90800","0.00000","1.19604","0.20001"
"1.19604","30.10083","1.31432","63.12800","0.00000","1.19604","0.20001"
"1.19604","30.08927","1.31382","63.34800","0.00000","1.19604","0.20001"
"1.19604","30.07753","1.31330","63.56800","0.00000","1.19604","0.20001"
"1.19604","30.06164","1.31261","63.78800","0.00000","1.19604","0.20001"
"1.19604","30.05492","1.31232","64.00800","0.00000","1.19604","0.20001"
"1.19604","30.04159","1.31173","64.22800","0.00000","1.19604","0.20001"
"1.19604","30.03074","1.31126","64.44800","0.00000","1.19604","0.20001"
"1.19604","30.02172","1.31087","64.66800","0.00000","1.19604","0.20001"
"1.19604","30.01572","1.31060","64.88800","0.00000","1.19604","0.20001"
"1.19604","30.00163","1.30999","65.10800","0.00000","1.19604","0.20001"
"1.19604","29.99282","1.30960","65.32800","0.00000","1.19604","0.20001"
"1.19604","29.97828","1.30897","65.54800","0.00000","1.19604","0.20001"
"1.19604","29.97726","1.30892","65.76800","0.00000","1.19604","0.20001"
"1.19604","29.96349","1.30832","65.98800","0.00000","1.19604","0.20001"
"1.19604","29.95068","1.30776","66.20800","0.00000","1.19604","0.20001"
"1.19604","29.94421","1.30748","66.42800","0.00000","1.19604","0.20001"
"1.19604","29.92126","1.30648","66.64800","0.00000","1.19604","0.20001"
"1.19604","29.90870","1.30593","66.86800","0.00000","1.19604","0.20001"
"1.19604","29.90575","1.30580","67.08800","0.00000","1.19604","0.20001"
"1.19604","29.89783","1.30546","67.30800","0.00000","1.19604","0.20001"
"1.19604","29.88849","1.30505","67.52800","0.00000","1.19604","0.20001"
"1.19604","29.87378","1.30441","67.74800","0.00000","1.19604","0.20001"
"1.19604","29.86469","1.30401","67.96800","0.00000","1.19604","0.20001"
"1.19604","29.85961","1.30379","68.18800","0.00000","1.19604","0.20001"
"1.19604","29.84453","1.30313","68.40800","0.00000","1.19604","0.20001"
"1.19604","29.82743","1.30238","68.62800","0.00000","1.19604","0.20001"
"1.19604","29.82060","1.30208","68.84800","0.00000","1.19604","0.20001"
"1.19604","29.81542","1.30186","69.06800","0.00000","1.19604","0.20001"
"1.19604","29.80379","1.30135","69.28800","0.00000","1.19604","0.20001"
"1.19604","29.79860","1.30112","69.50800","0.00000","1.19604","0.20001"
"1.19604","29.79306","1.30088","69.72800","0.00000","1.19604","0.20001"
"1.19604","29.77125","1.29993","69.94800","0.00000","1.19604","0.20001"
"1.19604","29.77344","1.30002","70.16800","0.00000","1.19604","0.20001"
"1.19604","29.76034","1.29945","70.38800","0.00000","1.19604","0.20001"
"1.19604","29.74841","1.29893","70.60800","0.00000","1.19604","0.20001"
"1.19604","29.73873","1.29851","70.82800","0.00000","1.19604","0.20001"
"1.19604","29.72862","1.29807","71.04800","0.00000","1.19604","0.20001"
"1.19604","29.72457","1.29789","71.26800","0.00000","1.19604","0.20001"
"1.19604","29.71263","1.29737","71.48800","0.00000","1.19604","0.20001"
"1.19604","29.70015","1.29682","71.70800","0.00000","1.19604","0.20001"
"1.19604","29.70039","1.29683","71.92800","0.00000","1.19604","0.20001"
"1.19604","29.68696","1.29625","72.14800","0.00000","1.19604","0.20001"
"1.19604","29.67468","1.29571","72.36800","0.00000","1.19604","0.20001"
"1.19604","29.65759","1.29497","72.58800","0.00000","1.19604","0.20001"
"1.19604","29.65333","1.29478","72.80800","0.00000","1.19604","0.20001"
"1.19604","29.65320","1.29477","73.02800","0.00000","1.19604","0.20001"
"1.19604","29.63620","1.29403","73.24800","0.00000","1.19604","0.20001"
"1.19604","29.63248","1.29387","73.46800","0.00000","1.19604","0.20001"
"1.19604","29.62170","1.29340","73.68800","0.00000","1.19604","0.20001"
"1.19604","29.61837","1.29325","73.90800","0.00000","1.19604","0.20001"
"1.19604","29.60578","1.29270","74.12800","0.00000","1.19604","0.20001"
"1.19604","29.59453","1.29221","74.34800","0.00000","1.19604","0.20001"
"1.19604","29.59120","1.29207","74.56800","0.00000","1.19604","0.20001"
"1.19604","29.58150","1.29164","74.78800","0.00000","1.19604","0.20001"
"1.19604","29.57076","1.29118","75.00800","0.00000","1.19604","0.20001"
"1.19604","29.56921","1.29111","75.22800","0.00000","1.19604","0.20001"
"1.19604","29.56029","1.29072","75.44800","0.00000","1.19604","0.20001"
"1.19604","29.54797","1.29018","75.66800","0.00000","1.19604","0.20001"
"1.19604","29.53539","1.28963","75.88800","0.00000","1.19604","0.20001"
"1.19604","29.52839","1.28932","76.10800","0.00000","1.19604","0.20001"
"1.19604","29.53062","1.28942","76.32800","0.00000","1.19604","0.20001"
"1.19604","29.51438","1.28871","76.54800","0.00000","1.19604","0.20001"
"1.19604","29.50344","1.28824","76.76800","0.00000","1.19604","0.20001"
"1.19604","29.49930","1.28805","76.98800","0.00000","1.19604","0.20001"
"1.19604","29.49650","1.28793","77.20800","0.00000","1.19604","0.20001"
"1.19604","29.48010","1.28722","77.42800","0.00000","1.19604","0.20001"
"1.19604","29.48069","1.28724","77.64800","0.00000","1.19604","0.20001"
"1.19604","29.46640","1.28662","77.86800","0.00000","1.19604","0.20001"
"1.19604","29.45582","1.28616","78.08800","0.00000","1.19604","0.20001"
"1.19604","29.44742","1.28579","78.30800","0.00000","1.19604","0.20001"
"1.19604","29.44239","1.28557","78.52800","0.00000","1.19604","0.20001"
"1.19604","29.43583","1.28528","78.74800","0.00000","1.19604","0.20001"
"1.19604","29.42556","1.28483","78.96800","0.00000","1.19604","0.20001"
"1.19604","29.42653","1.28488","79.18800","0.00000","1.19604","0.20001"
"1.19604","29.41662","1.28444","79.40800","0.00000","1.19604","0.20001"
"1.19604","29.40942","1.28413","79.62800","0.00000","1.19604","0.20001"
"1.19604","29.40345","1.28387","79.84800","0.00000","1.19604","0.20001"
"1.19604","29.39151","1.28335","80.06800","0.00000","1.19604","0.20001"
"1.19604","29.38469","1.28305","80.28800","0.00000","1.19604","0.20001"
"1.19604","29.38096","1.28289","80.50800","0.00000","1.19604","0.20001"
"1.19604","29.37968","1.28283","80.72800","0.00000","1.19604","0.20001"
"1.19604","29.35295","1.28166","80.94800","0.00000","1.19604","0.20001"
"1.19604","29.35024","1.28155","81.16800","0.00000","1.19604","0.20001"
"1.19604","29.35739","1.28186","81.38800","0.00000","1.19604","0.20001"
"1.19604","29.34236","1.28120","81.60800","0.00000","1.19604","0.20001"
"1.19604","29.33142","1.28072","81.82800","0.00000","1.19604","0.20001"
"1.19604","29.32669","1.28052","82.04800","0.00000","1.19604","0.20001"
"1.19604","29.32001","1.28023","82.26800","0.00000","1.19604","0.20001"
"1.19604","29.31484","1.28000","82.48800","0.00000","1.19604","0.20001"
"1.19604","29.30239","1.27946","82.70800","0.00000","1.19604","0.20001"
"1.19604","29.30321","1.27949","82.92800","0.00000","1.19604","0.20001"
"1.19604","29.28378","1.27864","83.14800","0.00000","1.19604","0.20001"
"1.19604","29.28754","1.27881","83.36800","0.00000","1.19604","0.20001"
"1.19604","29.27668","1.27833","83.58800","0.00000","1.19604","0.20001"
"1.19604","29.27080","1.27808","83.80800","0.00000","1.19604","0.20001"
"1.19604","29.26270","1.27772","84.02800","0.00000","1.19604","0.20001"
"1.19604","29.26497","1.27782","84.24800","0.00000","1.19604","0.20001"
"1.19604","29.25215","1.27726","84.46800","0.00000","1.19604","0.20001"
"1.19604","29.23974","1.27672","84.68800","0.00000","1.19604","0.20001"
"1.19604","29.24028","1.27674","84.90800","0.00000","1.19604","0.20001"
"1.19604","29.22948","1.27627","85.12800","0.00000","1.19604","0.20001"
"1.19604","29.22240","1.27596","85.34800","0.00000","1.19604","0.20001"
"1.19604","29.22495","1.27608","85.56800","0.00000","1.19604","0.20001"
"1.19604","29.20575","1.27524","85.78800","0.00000","1.19604","0.20001"
"1.19604","29.21054","1.27545","86.00800","0.00000","1.19604","0.20001"
"1.19604","29.19653","1.27483","86.22800","0.00000","1.19604","0.20001"
"1.19604","29.19444","1.27474","86.44800","0.00000","1.19604","0.20001"
"1.19604","29.18363","1.27427","86.66800","0.00000","1.19604","0.20001"
"1.19604","29.17323","1.27382","86.88800","0.00000","1.19604","0.20001"
"1.19604","29.17472","1.27388","87.10800","0.00000","1.19604","0.20001"
"1.19604","29.16883","1.27363","87.32800","0.00000","1.19604","0.20001"
"1.19604","29.15487","1.27302","87.54800","0.00000","1.19604","0.20001"
"1.19604","29.15241","1.27291","87.76800","0.00000","1.19604","0.20001"
"1.19604","29.14061","1.27239","87.98800","0.00000","1.19604","0.20001"
"1.19604","29.13793","1.27228","88.20800","0.00000","1.19604","0.20001"
"1.19604","29.13212","1.27202","88.42800","0.00000","1.19604","0.20001"
"1.19604","29.12959","1.27191","88.64800","0.00000","1.19604","0.20001"
"1.19604","29.11904","1.27145","88.86800","0.00000","1.19604","0.20001"
"1.19604","29.10993","1.27105","89.08800","0.00000","1.19604","0.20001"
"1.19604","29.10664","1.27091","89.30800","0.00000","1.19604","0.20001"
"1.19604","29.10023","1.27063","89.52800","0.00000","1.19604","0.20001"
"1.19604","29.09374","1.27035","89.74800","0.00000","1.19604","0.20001"
"1.19604","29.08944","1.27016","89.96800","0.00000","1.19604","0.20001"
"1.19604","29.08497","1.26996","90.18800","0.00000","1.19604","0.20001"
"1.19604","29.07540","1.26955","90.40800","0.00000","1.19604","0.20001"
"1.19604","29.06020","1.26888","90.62800","0.00000","1.19604","0.20001"
"1.19604","29.06110","1.26892","90.84800","0.00000","1.19604","0.20001"
"1.19604","29.06174","1.26895","91.06800","0.00000","1.19604","0.20001"
"1.19604","29.05160","1.26851","91.28800","0.00000","1.19604","0.20001"
"1.19604","29.04529","1.26823","91.50800","0.00000","1.19604","0.20001"
"1.19604","29.04703","1.26831","91.72800","0.00000","1.19604","0.20001"
"1.19604","29.03469","1.26777","91.94800","0.00000","1.19604","0.20001"
"1.19604","29.02253","1.26724","92.16800","0.00000","1.19604","0.20001"
"1.19604","29.02544","1.26736","92.38800","0.00000","1.19604","0.20001"
"1.19604","29.01970","1.26711","92.60800","0.00000","1.19604","0.20001"
"1.19604","29.01647","1.26697","92.82800","0.00000","1.19604","0.20001"
"1.19604","28.99860","1.26619","93.04800","0.00000","1.19604","0.20001"
"1.19604","29.00058","1.26628","93.26800","0.00000","1.19604","0.20001"
"1.19604","28.99905","1.26621","93.48800","0.00000","1.19604","0.20001"
"1.19604","28.99061","1.26584","93.70800","0.00000","1.19604","0.20001"
"1.19604","28.98915","1.26578","93.92800","0.00000","1.19604","0.20001"
"1.19604","28.97756","1.26527","94.14800","0.00000","1.19604","0.20001"
"1.19604","28.97576","1.26519","94.36800","0.00000","1.19604","0.20001"
"1.19604","28.96871","1.26489","94.58800","0.00000","1.19604","0.20001"
"1.19604","28.96077","1.26454","94.80800","0.00000","1.19604","0.20001"
"1.19604","28.95710","1.26438","95.02800","0.00000","1.19604","0.20001"
"1.19604","28.95519","1.26430","95.24800","0.00000","1.19604","0.20001"
"1.19604","28.94897","1.26402","95.46800","0.00000","1.19604","0.20001"
"1.19604","28.94162","1.26370","95.68800","0.00000","1.19604","0.20001"
"1.19604","28.93691","1.26350","95.90800","0.00000","1.19604","0.20001"
"1.19604","28.92838","1.26313","96.12800","0.00000","1.19604","0.20001"
"1.19604","28.92209","1.26285","96.34800","0.00000","1.19604","0.20001"
"1.19604","28.92356","1.26292","96.56800","0.00000","1.19604","0.20001"
"1.19604","28.91122","1.26238","96.78800","0.00000","1.19604","0.20001"
"1.19604","28.90752","1.26222","97.00800","0.00000","1.19604","0.20001"
"1.19604","28.89870","1.26183","97.22800","0.00000","1.19604","0.20001"
"1.19604","28.89319","1.26159","97.44800","0.00000","1.19604","0.20001"
"1.19604","28.88589","1.26127","97.66800","0.00000","1.19604","0.20001"
"1.19604","28.88382","1.26118","97.88800","0.00000","1.19604","0.20001"
"1.19604","28.87966","1.26100","98.10800","0.00000","1.19604","0.20001"
"1.19604","28.87705","1.26088","98.32800","0.00000","1.19604","0.20001"
"1.19604","28.86618","1.26041","98.54800","0.00000","1.19604","0.20001"
"1.19604","28.85740","1.26003","98.76800","0.00000","1.19604","0.20001"
"1.19604","28.85379","1.25987","98.98800","0.00000","1.19604","0.20001"
"1.19604","28.85575","1.25996","99.20800","0.00000","1.19604","0.20001"
"1.19604","28.85090","1.25974","99.42800","0.00000","1.19604","0.20001"
"1.19604","28.84445","1.25946","99.64800","0.00000","1.19604","0.20001"
"1.19604","28.83982","1.25926","99.86800","0.00000","1.19604","0.20001"
"1.19604","28.84035","1.25928","100.08800","0.00000","1.19604","0.20001"
"1.19604","28.82723","1.25871","100.30800","0.00000","1.19604","0.20001"
"1.19604","28.81550","1.25820","100.52800","0.00000","1.19604","0.20001"
"1.19604","28.82249","1.25850","100.74800","0.00000","1.19604","0.20001"
"1.19604","28.81545","1.25820","100.96800","0.00000","1.19604","0.20001"
"1.19604","28.80926","1.25793","101.18800","0.00000","1.19604","0.20001"
"1.19604","28.80701","1.25783","101.40800","0.00000","1.19604","0.20001"
"1.19604","28.79218","1.25718","101.62800","0.00000","1.19604","0.20001"
"1.19604","28.78928","1.25705","101.84800","0.00000","1.19604","0.20001"
"1.19604","28.77737","1.25653","102.06800","0.00000","1.19604","0.20001"
"1.19604","28.78403","1.25682","102.28800","0.00000","1.19604","0.20001"
"1.19604","28.77752","1.25654","102.50800","0.00000","1.19604","0.20001"
"1.19604","28.77202","1.25630","102.72800","0.00000","1.19604","0.20001"
"1.19604","28.76711","1.25608","102.94800","0.00000","1.19604","0.20001"
"1.19604","28.76222","1.25587","103.16800","0.00000","1.19604","0.20001"
"1.19604","28.76723","1.25609","103.38800","0.00000","1.19604","0.20001"
"1.19604","28.74924","1.25530","103.60800","0.00000","1.19604","0.20001"
"1.19604","28.74407","1.25508","103.82800","0.00000","1.19604","0.20001"
"1.19604","28.74757","1.25523","104.04800","0.00000","1.19604","0.20001"
"1.19604","28.74394","1.25507","104.26800","0.00000","1.19604","0.20001"
"1.19604","28.74370","1.25506","104.48800","0.00000","1.19604","0.20001"
"1.19604","28.72467","1.25423","104.70800","0.00000","1.19604","0.20001"
"1.19604","28.72203","1.25412","104.92800","0.00000","1.19604","0.20001"
"1.19604","28.71818","1.25395","105.14800","0.00000","1.19604","0.20001"
"1.19604","28.71816","1.25395","105.36800","0.00000","1.19604","0.20001"
"1.19604","28.70306","1.25329","105.58800","0.00000","1.19604","0.20001"
"1.19604","28.70483","1.25336","105.80800","0.00000","1.19604","0.20001"
"1.19604","28.70057","1.25318","106.02800","0.00000","1.19604","0.20001"
"1.19604","28.69325","1.25286","106.24800","0.00000","1.19604","0.20001"
"1.19604","28.69341","1.25287","106.46800","0.00000","1.19604","0.20001"
"1.19604","28.68892","1.25267","106.68800","0.00000","1.19604","0.20001"
"1.19604","28.68641","1.25256","106.90800","0.00000","1.19604","0.20001"
"1.19604","28.67924","1.25225","107.12800","0.00000","1.19604","0.20001"
"1.19604","28.67433","1.25203","107.34800","0.00000","1.19604","0.20001"
"1.19604","28.67601","1.25211","107.56800","0.00000","1.19604","0.20001"
"1.19604","28.66330","1.25155","107.78800","0.00000","1.19604","0.20001"
"1.19604","28.65594","1.25123","108.00800","0.00000","1.19604","0.20001"
"1.19604","28.65361","1.25113","108.22800","0.00000","1.19604","0.20001"
"1.19604","28.65295","1.25110","108.44800","0.00000","1.19604","0.20001"
"1.19604","28.64602","1.25080","108.66800","0.00000","1.19604","0.20001"
"1.19604","28.64048","1.25056","108.88800","0.00000","1.19604","0.20001"
"1.19604","28.63639","1.25038","109.10800","0.00000","1.19604","0.20001"
"1.19604","28.62898","1.25005","109.32800","0.00000","1.19604","0.20001"
"1.19604","28.63083","1.25013","109.54800","0.00000","1.19604","0.20001"
"1.19604","28.62500","1.24988","109.76800","0.00000","1.19604","0.20001"
"1.19604","28.61956","1.24964","109.98800","0.00000","1.19604","0.20001"
"1.19604","28.61598","1.24949","110.20800","0.00000","1.19604","0.20001"
"1.19604","28.60953","1.24920","110.42800","0.00000","1.19604","0.20001"
"1.19604","28.60957","1.24921","110.64800","0.00000","1.19604","0.20001"
"1.19604","28.59779","1.24869","110.86800","0.00000","1.19604","0.20001"
"1.19604","28.60024","1.24880","111.08800","0.00000","1.19604","0.20001"
"1.19604","28.59624","1.24862","111.30800","0.00000","1.19604","0.20001"
"1.19604","28.58439","1.24811","111.52800","0.00000","1.19604","0.20001"
"1.19604","28.58231","1.24802","111.74800","0.00000","1.19604","0.20001"
"1.19604","28.57894","1.24787","111.96800","0.00000","1.19604","0.20001"
"1.19604","28.56738","1.24736","112.18800","0.00000","1.19604","0.20001"
"1.19604","28.57262","1.24759","112.40800","0.00000","1.19604","0.20001"
"1.19604","28.56813","1.24740","112.62800","0.00000","1.19604","0.20001"
"1.19604","28.55981","1.24703","112.84800","0.00000","1.19604","0.20001"
"1.19604","28.55202","1.24669","113.06800","0.00000","1.19604","0.20001"
"1.19604","28.55665","1.24690","113.28800","0.00000","1.19604","0.20001"
"1.19604","28.54652","1.24645","113.50800","0.00000","1.19604","0.20001"
"1.19604","28.55004","1.24661","113.72800","0.00000","1.19604","0.20001"
"1.19604","28.53971","1.24616","113.94800","0.00000","1.19604","0.20001"
"1.19604","28.52834","1.24566","114.16800","0.00000","1.19604","0.20001"
"1.19604","28.53355","1.24589","114.38800","0.00000","1.19604","0.20001"
"1.19604","28.53352","1.24589","114.60800","0.00000","1.19604","0.20001"
"1.19604","28.52814","1.24565","114.82800","0.00000","1.19604","0.20001"
"1.19604","28.51309","1.24499","115.04800","0.00000","1.19604","0.20001"
"1.19604","28.51911","1.24526","115.26800","0.00000","1.19604","0.20001"
"1.19604","28.51292","1.24499","115.48800","0.00000","1.19604","0.20001"
"1.19604","28.50727","1.24474","115.70800","0.00000","1.19604","0.20001"
"1.19604","28.49879","1.24437","115.92800","0.00000","1.19604","0.20001"
"1.19604","28.50206","1.24451","116.14800","0.00000","1.19604","0.20001"
"1.19604","28.50360","1.24458","116.36800","0.00000","1.19604","0.20001"
"1.19604","28.49063","1.24401","116.58800","0.00000","1.19604","0.20001"
"1.19604","28.48829","1.24391","116.80800","0.00000","1.19604","0.20001"
"1.19604","28.48772","1.24389","117.02800","0.00000","1.19604","0.20001"
"1.19604","28.48245","1.24365","117.24800","0.00000","1.19604","0.20001"
"1.19604","28.47054","1.24313","117.46800","0.00000","1.19604","0.20001"
"1.19604","28.47246","1.24322","117.68800","0.00000","1.19604","0.20001"
"1.19604","28.46099","1.24272","117.90800","0.00000","1.19604","0.20001"
"1.19604","28.46182","1.24275","118.12800","0.00000","1.19604","0.20001"
"1.19604","28.46070","1.24271","118.34800","0.00000","1.19604","0.20001"
"1.19604","28.44501","1.24202","118.56800","0.00000","1.19604","0.20001"
"1.19604","28.45344","1.24239","118.78800","0.00000","1.19604","0.20001"
"1.19604","28.43936","1.24177","119.00800","0.00000","1.19604","0.20001"
"1.19604","28.43953","1.24178","119.22800","0.00000","1.19604","0.20001"
"1.19604","28.43600","1.24163","119.44800","0.00000","1.19604","0.20001"
"1.19604","28.43970","1.24179","119.66800","0.00000","1.19604","0.20001"
"1.19604","28.43421","1.24155","119.88800","0.00000","1.19604","0.20001"
"1.19604","28.42761","1.24126","120.10800","0.00000","1.19604","0.20001"
"1.19604","28.42468","1.24113","120.32800","0.00000","1.19604","0.20001"
"1.19604","28.42352","1.24108","120.54800","0.00000","1.19604","0.20001"
"1.19604","28.41766","1.24083","120.76800","0.00000","1.19604","0.20001"
"1.19604","28.40340","1.24020","120.98800","0.00000","1.19604","0.20001"
"1.19604","28.40647","1.24034","121.20800","0.00000","1.19604","0.20001"
"1.19604","28.40938","1.24046","121.42800","0.00000","1.19604","0.20001"
"1.19604","28.39437","1.23981","121.64800","0.00000","1.19604","0.20001"
"1.19604","28.39567","1.23987","121.86800","0.00000","1.19604","0.20001"
"1.19604","28.39493","1.23983","122.08800","0.00000","1.19604","0.20001"
"1.19604","28.38947","1.23960","122.30800","0.00000","1.19604","0.20001"
"1.19604","28.38121","1.23923","122.52800","0.00000","1.19604","0.20001"
"1.19604","28.37589","1.23900","122.74800","0.00000","1.19604","0.20001"
"1.19604","28.37660","1.23903","122.96800","0.00000","1.19604","0.20001"
"1.19604","28.37197","1.23883","123.18800","0.00000","1.19604","0.20001"
"1.19604","28.36565","1.23856","123.40800","0.00000","1.19604","0.20001"
"1.19604","28.36501","1.23853","123.62800","0.00000","1.19604","0.20001"
"1.19604","28.36287","1.23843","123.84800","0.00000","1.19604","0.20001"
"1.19604","28.35878","1.23826","124.06800","0.00000","1.19604","0.20001"
"1.19604","28.35109","1.23792","124.28800","0.00000","1.19604","0.20001"
"1.19604","28.34921","1.23784","124.50800","0.00000","1.19604","0.20001"
"1.19604","28.34774","1.23777","124.72800","0.00000","1.19604","0.20001"
"1.19604","28.33442","1.23719","124.94800","0.00000","1.19604","0.20001"
"1.19604","28.34048","1.23746","125.16800","0.00000","1.19604","0.20001"
"1.19604","28.34170","1.23751","125.38800","0.00000","1.19604","0.20001"
"1.19604","28.32570","1.23681","125.60800","0.00000","1.19604","0.20001"
"1.19604","28.33279","1.23712","125.82800","0.00000","1.19604","0.20001"
"1.19604","28.32442","1.23676","126.04800","0.00000","1.19604","0.20001"
"1.19604","28.31702","1.23643","126.26800","0.00000","1.19604","0.20001"
"1.19604","28.31547","1.23636","126.48800","0.00000","1.19604","0.20001"
"1.19604","28.31612","1.23639","126.70800","0.00000","1.19604","0.20001"
"1.19604","28.31133","1.23618","126.92800","0.00000","1.19604","0.20001"
"1.19604","28.30849","1.23606","127.14800","0.00000","1.19604","0.20001"
"1.19604","28.30441","1.23588","127.36800","0.00000","1.19604","0.20001"
"1.19604","28.29889","1.23564","127.58800","0.00000","1.19604","0.20001"
"1.19604","28.29047","1.23527","127.80800","0.00000","1.19604","0.20001"
"1.19604","28.29621","1.23552","128.02800","0.00000","1.19604","0.20001"
"1.19604","28.28985","1.23525","128.24800","0.00000","1.19604","0.20001"
"1.19604","28.28387","1.23498","128.46800","0.00000","1.19604","0.20001"
"1.19604","28.27242","1.23448","128.68800","0.00000","1.19604","0.20001"
"1.19604","28.26954","1.23436","128.90800","0.00000","1.19604","0.20001"
"1.19604","28.27427","1.23456","129.12800","0.00000","1.19604","0.20001"
"1.19604","28.27412","1.23456","129.34800","0.00000","1.19604","0.20001"
"1.19604","28.26564","1.23419","129.56800","0.00000","1.19604","0.20001"
"1.19604","28.25732","1.23383","129.78800","0.00000","1.19604","0.20001"
"1.19604","28.25366","1.23367","130.00800","0.00000","1.19604","0.20001"
"1.19604","28.25131","1.23356","130.22800","0.00000","1.19604","0.20001"
"1.19604","28.25352","1.23366","130.44800","0.00000","1.19604","0.20001"
"1.19604","28.24988","1.23350","130.66800","0.00000","1.19604","0.20001"
"1.19604","28.24955","1.23349","130.88800","0.00000","1.19604","0.20001"
"1.19604","28.24487","1.23328","131.10800","0.00000","1.19604","0.20001"
"1.19604","28.23405","1.23281","131.32800","0.00000","1.19604","0.20001"
"1.19604","28.22768","1.23253","131.54800","0.00000","1.19604","0.20001"
"1.19604","28.23234","1.23273","131.76800","0.00000","1.19604","0.20001"
"1.19604","28.22098","1.23224","131.98800","0.00000","1.19604","0.20001"
"1.19604","28.22753","1.23252","132.20800","0.00000","1.19604","0.20001"
"1.19604","28.22406","1.23237","132.42800","0.00000","1.19604","0.20001"
"1.19604","28.20624","1.23159","132.64800","0.00000","1.19604","0.20001"
"1.19604","28.21891","1.23215","132.86800","0.00000","1.19604","0.20001"
"1.19604","28.20800","1.23167","133.08800","0.00000","1.19604","0.20001"
"1.19604","28.20432","1.23151","133.30800","0.00000","1.19604","0.20001"
"1.19604","28.20223","1.23142","133.52800","0.00000","1.19604","0.20001"
"1.19604","28.20076","1.23136","133.74800","0.00000","1.19604","0.20001"
"1.19604","28.19811","1.23124","133.96800","0.00000","1.19604","0.20001"
"1.19604","28.19130","1.23094","134.18800","0.00000","1.19604","0.20001"
"1.19604","28.19074","1.23092","134.40800","0.00000","1.19604","0.20001"
"1.19604","28.18666","1.23074","134.62800","0.00000","1.19604","0.20001"
"1.19604","28.18416","1.23063","134.84800","0.00000","1.19604","0.20001"
"1.19604","28.18539","1.23068","135.06800","0.00000","1.19604","0.20001"
"1.19604","28.16781","1.22992","135.28800","0.00000","1.19604","0.20001"
"1.19604","28.17420","1.23020","135.50800","0.00000","1.19604","0.20001"
"1.19604","28.17299","1.23014","135.72800","0.00000","1.19604","0.20001"
"1.19604","28.16152","1.22964","135.94800","0.00000","1.19604","0.20001"
"1.19604","28.15938","1.22955","136.16800","0.00000","1.19604","0.20001"
"1.19604","28.15530","1.22937","136.38800","0.00000","1.19604","0.20001"
"1.19604","28.15271","1.22926","136.60800","0.00000","1.19604","0.20001"
"1.19604","28.15607","1.22940","136.82800","0.00000","1.19604","0.20001"
"1.19604","28.15526","1.22937","137.04800","0.00000","1.19604","0.20001"
"1.19604","28.15380","1.22931","137.26800","0.00000","1.19604","0.20001"
"1.19604","28.14119","1.22875","137.48800","0.00000","1.19604","0.20001"
"1.19604","28.14421","1.22889","137.70800","0.00000","1.19604","0.20001"
"1.19604","28.12926","1.22823","137.92800","0.00000","1.19604","0.20001"
"1.19604","28.14486","1.22891","138.14800","0.00000","1.19604","0.20001"
"1.19604","28.13473","1.22847","138.36800","0.00000","1.19604","0.20001"
"1.19604","28.11660","1.22768","138.58800","0.00000","1.19604","0.20001"
"1.19604","28.12763","1.22816","138.80800","0.00000","1.19604","0.20001"
"1.19604","28.12756","1.22816","139.02800","0.00000","1.19604","0.20001"
"1.19604","28.11720","1.22771","139.24800","0.00000","1.19604","0.20001"
"1.19604","28.11402","1.22757","139.46800","0.00000","1.19604","0.20001"
"1.19604","28.11272","1.22751","139.68800","0.00000","1.19604","0.20001"
"1.19604","28.11234","1.22749","139.90800","0.00000","1.19604","0.20001"
"1.19604","28.10646","1.22724","140.12800","0.00000","1.19604","0.20001"
"1.19604","28.09543","1.22676","140.34800","0.00000","1.19604","0.20001"
"1.19604","28.09164","1.22659","140.56800","0.00000","1.19604","0.20001"
"1.19604","28.08615","1.22635","140.78800","0.00000","1.19604","0.20001"
"1.19604","28.09044","1.22654","141.00800","0.00000","1.19604","0.20001"
"1.19604","28.08523","1.22631","141.22800","0.00000","1.19604","0.20001"
"1.19604","28.08429","1.22627","141.44800","0.00000","1.19604","0.20001"
"1.19604","28.07949","1.22606","141.66800","0.00000","1.19604","0.20001"
"1.19604","28.07104","1.22569","141.88800","0.00000","1.19604","0.20001"
"1.19604","28.07188","1.22573","142.10800","0.00000","1.19604","0.20001"
"1.19604","28.07031","1.22566","142.32800","0.00000","1.19604","0.20001"
"1.19604","28.06165","1.22528","142.54800","0.00000","1.19604","0.20001"
"1.19604","28.06372","1.22537","142.76800","0.00000","1.19604","0.20001"
"1.19604","28.06027","1.22522","142.98800","0.00000","1.19604","0.20001"
"1.19604","28.06249","1.22532","143.20800","0.00000","1.19604","0.20001"
"1.19604","28.05461","1.22497","143.42800","0.00000","1.19604","0.20001"
"1.19604","28.06053","1.22523","143.64800","0.00000","1.19604","0.20001"
"1.19604","28.05799","1.22512","143.86800","0.00000","1.19604","0.20001"
"1.19604","28.03481","1.22411","144.08800","0.00000","1.19604","0.20001"
"1.19604","28.04242","1.22444","144.30800","0.00000","1.19604","0.20001"
"1.19604","28.04640","1.22462","144.52800","0.00000","1.19604","0.20001"
"1.19604","28.04214","1.22443","144.74800","0.00000","1.19604","0.20001"
"1.19604","28.03229","1.22400","144.96800","0.00000","1.19604","0.20001"
"1.19604","28.03449","1.22410","145.18800","0.00000","1.19604","0.20001"
"1.19604","28.02857","1.22384","145.40800","0.00000","1.19604","0.20001"
"1.19604","28.02357","1.22362","145.62800","0.00000","1.19604","0.20001"
"1.19604","28.01976","1.22345","145.84800","0.00000","1.19604","0.20001"
"1.19604","28.02546","1.22370","146.06800","0.00000","1.19604","0.20001"
"1.19604","28.02318","1.22360","146.28800","0.00000","1.19604","0.20001"
"1.19604","28.01447","1.22322","146.50800","0.00000","1.19604","0.20001"
"1.19604","28.00952","1.22301","146.72800","0.00000","1.19604","0.20001"
"1.19604","28.00538","1.22282","146.94800","0.00000","1.19604","0.20001"
"1.19604","28.00272","1.22271","147.16800","0.00000","1.19604","0.20001"
"1.19604","28.00554","1.22283","147.38800","0.00000","1.19604","0.20001"
"1.19604","27.99246","1.22226","147.60800","0.00000","1.19604","0.20001"
"1.19604","27.99531","1.22238","147.82800","0.00000","1.19604","0.20001"
"1.19604","27.99214","1.22225","148.04800","0.00000","1.19604","0.20001"
"1.19604","27.99280","1.22227","148.26800","0.00000","1.19604","0.20001"
"1.19604","27.99403","1.22233","148.48800","0.00000","1.19604","0.20001"
"1.19604","27.98617","1.22199","148.70800","0.00000","1.19604","0.20001"
"1.19604","27.97461","1.22148","148.92800","0.00000","1.19604","0.20001"
"1.19604","27.96713","1.22115","149.14800","0.00000","1.19604","0.20001"
"1.19604","27.97254","1.22139","149.36800","0.00000","1.19604","0.20001"
"1.19604","27.96922","1.22125","149.58800","0.00000","1.19604","0.20001"
"1.19604","27.96655","1.22113","149.80800","0.00000","1.19604","0.20001"
"1.19604","27.97087","1.22132","149.90800","0.00000","1.19604","0.20001"