File: Rubber Stress Relaxation Raw Data - Small Samples-20210211/Specimen_RawData_3.csv
Specimen properties : Specimen label,"GAI2S1R3"
Specimen properties : Anvil height,"6.08000",mm
Specimen properties : Diameter,"5.61000",mm
Test : Rate 1,"24.00000",mm/min
Test : Start of hold value,"20.00000",%
Test : Duration,"120.00000",s

Extension,Load,Compressive stress,Time,PIP count,Compressive extension,Compressive strain (Extension)
(mm),(N),(MPa),(s),,(mm),(mm/mm)
"-0.00042","-0.02523","-0.00102","0.00000","0.00000","-0.00042","-0.00007"
"0.06229","2.97703","0.12044","0.18000","0.00000","0.06229","0.01025"
"0.14083","5.74492","0.23242","0.36000","0.00000","0.14083","0.02316"
"0.21604","8.09655","0.32756","0.54000","0.00000","0.21604","0.03553"
"0.28813","10.25005","0.41468","0.72000","0.00000","0.28813","0.04739"
"0.36042","12.38432","0.50102","0.90000","0.00000","0.36042","0.05928"
"0.43271","14.47773","0.58571","1.08000","0.00000","0.43271","0.07117"
"0.50438","16.51312","0.66806","1.26000","0.00000","0.50438","0.08296"
"0.57646","18.67472","0.75551","1.44000","0.00000","0.57646","0.09481"
"0.64854","20.89277","0.84524","1.62000","0.00000","0.64854","0.10667"
"0.72021","23.11593","0.93518","1.80000","0.00000","0.72021","0.11846"
"0.79250","25.45976","1.03000","1.98000","0.00000","0.79250","0.13035"
"0.86479","27.89506","1.12853","2.16000","0.00000","0.86479","0.14224"
"0.93625","30.41262","1.23038","2.34000","0.00000","0.93625","0.15399"
"1.00854","33.08194","1.33837","2.52000","0.00000","1.00854","0.16588"
"1.08125","35.88686","1.45184","2.70000","0.00000","1.08125","0.17784"
"1.15229","38.78340","1.56903","2.88000","0.00000","1.15229","0.18952"
"1.22083","41.76561","1.68968","3.05200","0.00000","1.22083","0.20079"
"1.22563","39.18779","1.58539","3.23200","0.00000","1.22563","0.20158"
"1.22438","37.69246","1.52489","3.41200","0.00000","1.22438","0.20138"
"1.22229","36.61332","1.48123","3.59200","0.00000","1.22229","0.20103"
"1.22000","35.78563","1.44775","3.77200","0.00000","1.22000","0.20066"
"1.21833","35.15947","1.42242","3.95200","0.00000","1.21833","0.20038"
"1.21729","34.69495","1.40362","4.13200","0.00000","1.21729","0.20021"
"1.21688","34.35461","1.38985","4.31200","0.00000","1.21688","0.20014"
"1.21667","34.09217","1.37924","4.49200","0.00000","1.21667","0.20011"
"1.21646","33.84715","1.36932","4.67200","0.00000","1.21646","0.20008"
"1.21646","33.64486","1.36114","4.85200","0.00000","1.21646","0.20008"
"1.21646","33.44747","1.35316","5.03200","0.00000","1.21646","0.20008"
"1.21646","33.27853","1.34632","5.21200","0.00000","1.21646","0.20008"
"1.21646","33.11319","1.33963","5.39200","0.00000","1.21646","0.20008"
"1.21625","32.94274","1.33274","5.57200","0.00000","1.21625","0.20004"
"1.21625","32.80771","1.32727","5.75200","0.00000","1.21625","0.20004"
"1.21625","32.67711","1.32199","5.93200","0.00000","1.21625","0.20004"
"1.21625","32.55999","1.31725","6.11200","0.00000","1.21625","0.20004"
"1.21625","32.43921","1.31236","6.29200","0.00000","1.21625","0.20004"
"1.21625","32.33855","1.30829","6.47200","0.00000","1.21625","0.20004"
"1.21625","32.23898","1.30426","6.65200","0.00000","1.21625","0.20004"
"1.21625","32.12671","1.29972","6.83200","0.00000","1.21625","0.20004"
"1.21625","32.03834","1.29615","7.01200","0.00000","1.21625","0.20004"
"1.21625","31.94361","1.29232","7.19200","0.00000","1.21625","0.20004"
"1.21625","31.85100","1.28857","7.37200","0.00000","1.21625","0.20004"
"1.21625","31.77895","1.28565","7.55200","0.00000","1.21625","0.20004"
"1.21625","31.69665","1.28232","7.73200","0.00000","1.21625","0.20004"
"1.21625","31.62418","1.27939","7.91200","0.00000","1.21625","0.20004"
"1.21625","31.54700","1.27627","8.09200","0.00000","1.21625","0.20004"
"1.21625","31.47773","1.27347","8.27200","0.00000","1.21625","0.20004"
"1.21625","31.41503","1.27093","8.45200","0.00000","1.21625","0.20004"
"1.21625","31.34382","1.26805","8.63200","0.00000","1.21625","0.20004"
"1.21625","31.28472","1.26566","8.81200","0.00000","1.21625","0.20004"
"1.21625","31.22638","1.26330","8.99200","0.00000","1.21625","0.20004"
"1.21625","31.16465","1.26080","9.17200","0.00000","1.21625","0.20004"
"1.21625","31.10929","1.25856","9.35200","0.00000","1.21625","0.20004"
"1.21625","31.05528","1.25638","9.53200","0.00000","1.21625","0.20004"
"1.21688","31.04254","1.25586","9.71200","0.00000","1.21688","0.20014"
"1.21688","30.98638","1.25359","9.89200","0.00000","1.21688","0.20014"
"1.21688","30.94031","1.25173","10.07200","0.00000","1.21688","0.20014"
"1.21688","30.87850","1.24923","10.25200","0.00000","1.21688","0.20014"
"1.21688","30.82831","1.24719","10.43200","0.00000","1.21688","0.20014"
"1.21688","30.77395","1.24500","10.61200","0.00000","1.21688","0.20014"
"1.21688","30.73705","1.24350","10.79200","0.00000","1.21688","0.20014"
"1.21688","30.67890","1.24115","10.97200","0.00000","1.21688","0.20014"
"1.21688","30.63663","1.23944","11.15200","0.00000","1.21688","0.20014"
"1.21688","30.59253","1.23766","11.33200","0.00000","1.21688","0.20014"
"1.21688","30.54800","1.23585","11.51200","0.00000","1.21688","0.20014"
"1.21646","30.47060","1.23272","11.69200","0.00000","1.21646","0.20008"
"1.21646","30.44581","1.23172","11.87200","0.00000","1.21646","0.20008"
"1.21646","30.40946","1.23025","12.05200","0.00000","1.21646","0.20008"
"1.21646","30.36979","1.22864","12.23200","0.00000","1.21646","0.20008"
"1.21646","30.33560","1.22726","12.41200","0.00000","1.21646","0.20008"
"1.21646","30.28064","1.22504","12.59200","0.00000","1.21646","0.20008"
"1.21646","30.26342","1.22434","12.77200","0.00000","1.21646","0.20008"
"1.21646","30.23019","1.22300","12.95200","0.00000","1.21646","0.20008"
"1.21646","30.18604","1.22121","13.13200","0.00000","1.21646","0.20008"
"1.21646","30.15950","1.22014","13.31200","0.00000","1.21646","0.20008"
"1.21646","30.12973","1.21893","13.49200","0.00000","1.21646","0.20008"
"1.21646","30.08553","1.21714","13.67200","0.00000","1.21646","0.20008"
"1.21646","30.05179","1.21578","13.85200","0.00000","1.21646","0.20008"
"1.21646","30.02882","1.21485","14.03200","0.00000","1.21646","0.20008"
"1.21646","29.99976","1.21367","14.21200","0.00000","1.21646","0.20008"
"1.21646","29.96445","1.21225","14.39200","0.00000","1.21646","0.20008"
"1.21646","29.93483","1.21105","14.57200","0.00000","1.21646","0.20008"
"1.21646","29.90814","1.20997","14.75200","0.00000","1.21646","0.20008"
"1.21646","29.89212","1.20932","14.93200","0.00000","1.21646","0.20008"
"1.21646","29.84986","1.20761","15.11200","0.00000","1.21646","0.20008"
"1.21646","29.81901","1.20636","15.29200","0.00000","1.21646","0.20008"
"1.21646","29.78795","1.20511","15.47200","0.00000","1.21646","0.20008"
"1.21646","29.78659","1.20505","15.65200","0.00000","1.21646","0.20008"
"1.21646","29.76503","1.20418","15.83200","0.00000","1.21646","0.20008"
"1.21646","29.69651","1.20141","16.01200","0.00000","1.21646","0.20008"
"1.21646","29.68081","1.20077","16.19200","0.00000","1.21646","0.20008"
"1.21646","29.66484","1.20012","16.37200","0.00000","1.21646","0.20008"
"1.21646","29.65494","1.19972","16.55200","0.00000","1.21646","0.20008"
"1.21646","29.63079","1.19875","16.73200","0.00000","1.21646","0.20008"
"1.21646","29.60379","1.19765","16.91200","0.00000","1.21646","0.20008"
"1.21646","29.56503","1.19609","17.09200","0.00000","1.21646","0.20008"
"1.21646","29.52685","1.19454","17.27200","0.00000","1.21646","0.20008"
"1.21646","29.51782","1.19418","17.45200","0.00000","1.21646","0.20008"
"1.21646","29.50458","1.19364","17.63200","0.00000","1.21646","0.20008"
"1.21646","29.48305","1.19277","17.81200","0.00000","1.21646","0.20008"
"1.21646","29.45490","1.19163","17.99200","0.00000","1.21646","0.20008"
"1.21646","29.42318","1.19035","18.17200","0.00000","1.21646","0.20008"
"1.21646","29.40092","1.18945","18.35200","0.00000","1.21646","0.20008"
"1.21646","29.37620","1.18845","18.53200","0.00000","1.21646","0.20008"
"1.21646","29.35515","1.18760","18.71200","0.00000","1.21646","0.20008"
"1.21646","29.34631","1.18724","18.89200","0.00000","1.21646","0.20008"
"1.21646","29.34318","1.18711","19.07200","0.00000","1.21646","0.20008"
"1.21646","29.31429","1.18594","19.25200","0.00000","1.21646","0.20008"
"1.21646","29.28004","1.18456","19.43200","0.00000","1.21646","0.20008"
"1.21646","29.25436","1.18352","19.61200","0.00000","1.21646","0.20008"
"1.21646","29.24726","1.18323","19.79200","0.00000","1.21646","0.20008"
"1.21646","29.22760","1.18244","19.97200","0.00000","1.21646","0.20008"
"1.21646","29.21841","1.18206","20.15200","0.00000","1.21646","0.20008"
"1.21646","29.20087","1.18135","20.33200","0.00000","1.21646","0.20008"
"1.21646","29.16135","1.17976","20.51200","0.00000","1.21646","0.20008"
"1.21646","29.13614","1.17874","20.69200","0.00000","1.21646","0.20008"
"1.21646","29.11903","1.17804","20.87200","0.00000","1.21646","0.20008"
"1.21646","29.11721","1.17797","21.05200","0.00000","1.21646","0.20008"
"1.21646","29.11151","1.17774","21.23200","0.00000","1.21646","0.20008"
"1.21646","29.09159","1.17693","21.41200","0.00000","1.21646","0.20008"
"1.21646","29.06854","1.17600","21.59200","0.00000","1.21646","0.20008"
"1.21646","29.03420","1.17461","21.77200","0.00000","1.21646","0.20008"
"1.21646","29.02065","1.17406","21.95200","0.00000","1.21646","0.20008"
"1.21646","29.01126","1.17368","22.13200","0.00000","1.21646","0.20008"
"1.21646","29.00396","1.17339","22.31200","0.00000","1.21646","0.20008"
"1.21646","28.98264","1.17253","22.49200","0.00000","1.21646","0.20008"
"1.21646","28.96387","1.17177","22.67200","0.00000","1.21646","0.20008"
"1.21646","28.93852","1.17074","22.85200","0.00000","1.21646","0.20008"
"1.21646","28.93406","1.17056","23.03200","0.00000","1.21646","0.20008"
"1.21646","28.91930","1.16996","23.21200","0.00000","1.21646","0.20008"
"1.21646","28.89561","1.16900","23.39200","0.00000","1.21646","0.20008"
"1.21646","28.87544","1.16819","23.57200","0.00000","1.21646","0.20008"
"1.21646","28.86948","1.16795","23.75200","0.00000","1.21646","0.20008"
"1.21646","28.84603","1.16700","23.93200","0.00000","1.21646","0.20008"
"1.21646","28.83340","1.16649","24.11200","0.00000","1.21646","0.20008"
"1.21646","28.82155","1.16601","24.29200","0.00000","1.21646","0.20008"
"1.21646","28.80549","1.16536","24.47200","0.00000","1.21646","0.20008"
"1.21646","28.79297","1.16485","24.65200","0.00000","1.21646","0.20008"
"1.21646","28.77397","1.16408","24.83200","0.00000","1.21646","0.20008"
"1.21646","28.75172","1.16318","25.01200","0.00000","1.21646","0.20008"
"1.21646","28.73561","1.16253","25.19200","0.00000","1.21646","0.20008"
"1.21646","28.73987","1.16270","25.37200","0.00000","1.21646","0.20008"
"1.21646","28.73414","1.16247","25.55200","0.00000","1.21646","0.20008"
"1.21646","28.71894","1.16186","25.73200","0.00000","1.21646","0.20008"
"1.21646","28.68157","1.16035","25.91200","0.00000","1.21646","0.20008"
"1.21646","28.66409","1.15964","26.09200","0.00000","1.21646","0.20008"
"1.21646","28.65563","1.15930","26.27200","0.00000","1.21646","0.20008"
"1.21646","28.65767","1.15938","26.45200","0.00000","1.21646","0.20008"
"1.21646","28.64295","1.15878","26.63200","0.00000","1.21646","0.20008"
"1.21646","28.62818","1.15819","26.81200","0.00000","1.21646","0.20008"
"1.21646","28.61330","1.15758","26.99200","0.00000","1.21646","0.20008"
"1.21646","28.58729","1.15653","27.17200","0.00000","1.21646","0.20008"
"1.21646","28.57941","1.15621","27.35200","0.00000","1.21646","0.20008"
"1.21646","28.56118","1.15547","27.53200","0.00000","1.21646","0.20008"
"1.21646","28.56420","1.15560","27.71200","0.00000","1.21646","0.20008"
"1.21646","28.55344","1.15516","27.89200","0.00000","1.21646","0.20008"
"1.21646","28.52913","1.15418","28.07200","0.00000","1.21646","0.20008"
"1.21646","28.51962","1.15379","28.25200","0.00000","1.21646","0.20008"
"1.21646","28.51464","1.15359","28.43200","0.00000","1.21646","0.20008"
"1.21646","28.49484","1.15279","28.61200","0.00000","1.21646","0.20008"
"1.21646","28.47919","1.15216","28.79200","0.00000","1.21646","0.20008"
"1.21646","28.47075","1.15182","28.97200","0.00000","1.21646","0.20008"
"1.21646","28.47181","1.15186","29.15200","0.00000","1.21646","0.20008"
"1.21646","28.46160","1.15145","29.33200","0.00000","1.21646","0.20008"
"1.21646","28.43300","1.15029","29.51200","0.00000","1.21646","0.20008"
"1.21646","28.41877","1.14971","29.69200","0.00000","1.21646","0.20008"
"1.21646","28.40513","1.14916","29.87200","0.00000","1.21646","0.20008"
"1.21646","28.39906","1.14892","30.05200","0.00000","1.21646","0.20008"
"1.21646","28.38611","1.14839","30.23200","0.00000","1.21646","0.20008"
"1.21646","28.38063","1.14817","30.41200","0.00000","1.21646","0.20008"
"1.21646","28.36938","1.14772","30.59200","0.00000","1.21646","0.20008"
"1.21646","28.35654","1.14720","30.77200","0.00000","1.21646","0.20008"
"1.21646","28.34335","1.14666","30.95200","0.00000","1.21646","0.20008"
"1.21646","28.32535","1.14593","31.13200","0.00000","1.21646","0.20008"
"1.21646","28.33026","1.14613","31.31200","0.00000","1.21646","0.20008"
"1.21646","28.31729","1.14561","31.49200","0.00000","1.21646","0.20008"
"1.21646","28.30619","1.14516","31.67200","0.00000","1.21646","0.20008"
"1.21646","28.29468","1.14469","31.85200","0.00000","1.21646","0.20008"
"1.21646","28.27975","1.14409","32.03200","0.00000","1.21646","0.20008"
"1.21646","28.27361","1.14384","32.21200","0.00000","1.21646","0.20008"
"1.21646","28.25945","1.14327","32.39200","0.00000","1.21646","0.20008"
"1.21646","28.24889","1.14284","32.57200","0.00000","1.21646","0.20008"
"1.21646","28.23240","1.14217","32.75200","0.00000","1.21646","0.20008"
"1.21646","28.22565","1.14190","32.93200","0.00000","1.21646","0.20008"
"1.21646","28.21132","1.14132","33.11200","0.00000","1.21646","0.20008"
"1.21646","28.20632","1.14112","33.29200","0.00000","1.21646","0.20008"
"1.21646","28.19668","1.14073","33.47200","0.00000","1.21646","0.20008"
"1.21646","28.18640","1.14031","33.65200","0.00000","1.21646","0.20008"
"1.21646","28.17920","1.14002","33.83200","0.00000","1.21646","0.20008"
"1.21646","28.16705","1.13953","34.01200","0.00000","1.21646","0.20008"
"1.21646","28.15911","1.13921","34.19200","0.00000","1.21646","0.20008"
"1.21646","28.15316","1.13897","34.37200","0.00000","1.21646","0.20008"
"1.21646","28.14733","1.13873","34.55200","0.00000","1.21646","0.20008"
"1.21646","28.13198","1.13811","34.73200","0.00000","1.21646","0.20008"
"1.21646","28.12204","1.13771","34.91200","0.00000","1.21646","0.20008"
"1.21646","28.10604","1.13706","35.09200","0.00000","1.21646","0.20008"
"1.21646","28.10441","1.13700","35.27200","0.00000","1.21646","0.20008"
"1.21646","28.09699","1.13670","35.45200","0.00000","1.21646","0.20008"
"1.21646","28.09030","1.13643","35.63200","0.00000","1.21646","0.20008"
"1.21646","28.07285","1.13572","35.81200","0.00000","1.21646","0.20008"
"1.21646","28.06405","1.13536","35.99200","0.00000","1.21646","0.20008"
"1.21646","28.05658","1.13506","36.17200","0.00000","1.21646","0.20008"
"1.21646","28.04243","1.13449","36.35200","0.00000","1.21646","0.20008"
"1.21646","28.03134","1.13404","36.53200","0.00000","1.21646","0.20008"
"1.21646","28.02947","1.13396","36.71200","0.00000","1.21646","0.20008"
"1.21646","28.02386","1.13374","36.89200","0.00000","1.21646","0.20008"
"1.21646","28.01090","1.13321","37.07200","0.00000","1.21646","0.20008"
"1.21646","28.00314","1.13290","37.25200","0.00000","1.21646","0.20008"
"1.21646","27.99696","1.13265","37.43200","0.00000","1.21646","0.20008"
"1.21646","27.99427","1.13254","37.61200","0.00000","1.21646","0.20008"
"1.21646","27.97184","1.13163","37.79200","0.00000","1.21646","0.20008"
"1.21646","27.97162","1.13162","37.97200","0.00000","1.21646","0.20008"
"1.21646","27.96594","1.13139","38.15200","0.00000","1.21646","0.20008"
"1.21646","27.94721","1.13064","38.33200","0.00000","1.21646","0.20008"
"1.21646","27.94934","1.13072","38.51200","0.00000","1.21646","0.20008"
"1.21646","27.92692","1.12982","38.69200","0.00000","1.21646","0.20008"
"1.21646","27.92378","1.12969","38.87200","0.00000","1.21646","0.20008"
"1.21646","27.92143","1.12959","39.05200","0.00000","1.21646","0.20008"
"1.21646","27.91403","1.12929","39.23200","0.00000","1.21646","0.20008"
"1.21646","27.90386","1.12888","39.41200","0.00000","1.21646","0.20008"
"1.21646","27.90481","1.12892","39.59200","0.00000","1.21646","0.20008"
"1.21646","27.88249","1.12802","39.77200","0.00000","1.21646","0.20008"
"1.21646","27.87360","1.12766","39.95200","0.00000","1.21646","0.20008"
"1.21646","27.87249","1.12761","40.13200","0.00000","1.21646","0.20008"
"1.21646","27.86630","1.12736","40.31200","0.00000","1.21646","0.20008"
"1.21646","27.84926","1.12667","40.49200","0.00000","1.21646","0.20008"
"1.21646","27.85047","1.12672","40.67200","0.00000","1.21646","0.20008"
"1.21646","27.83511","1.12610","40.85200","0.00000","1.21646","0.20008"
"1.21646","27.82693","1.12577","41.03200","0.00000","1.21646","0.20008"
"1.21646","27.81025","1.12510","41.21200","0.00000","1.21646","0.20008"
"1.21646","27.82117","1.12554","41.39200","0.00000","1.21646","0.20008"
"1.21646","27.82046","1.12551","41.57200","0.00000","1.21646","0.20008"
"1.21646","27.79307","1.12440","41.75200","0.00000","1.21646","0.20008"
"1.21646","27.78031","1.12388","41.93200","0.00000","1.21646","0.20008"
"1.21646","27.78397","1.12403","42.11200","0.00000","1.21646","0.20008"
"1.21646","27.77131","1.12352","42.29200","0.00000","1.21646","0.20008"
"1.21646","27.75809","1.12299","42.47200","0.00000","1.21646","0.20008"
"1.21646","27.76684","1.12334","42.65200","0.00000","1.21646","0.20008"
"1.21646","27.76807","1.12339","42.83200","0.00000","1.21646","0.20008"
"1.21646","27.73952","1.12223","43.01200","0.00000","1.21646","0.20008"
"1.21646","27.72318","1.12157","43.19200","0.00000","1.21646","0.20008"
"1.21646","27.72886","1.12180","43.37200","0.00000","1.21646","0.20008"
"1.21646","27.72943","1.12183","43.55200","0.00000","1.21646","0.20008"
"1.21646","27.72862","1.12179","43.73200","0.00000","1.21646","0.20008"
"1.21646","27.71379","1.12119","43.91200","0.00000","1.21646","0.20008"
"1.21646","27.70366","1.12078","44.09200","0.00000","1.21646","0.20008"
"1.21646","27.70358","1.12078","44.27200","0.00000","1.21646","0.20008"
"1.21646","27.69202","1.12031","44.45200","0.00000","1.21646","0.20008"
"1.21646","27.67771","1.11973","44.63200","0.00000","1.21646","0.20008"
"1.21646","27.67188","1.11950","44.81200","0.00000","1.21646","0.20008"
"1.21646","27.66498","1.11922","44.99200","0.00000","1.21646","0.20008"
"1.21646","27.66190","1.11909","45.17200","0.00000","1.21646","0.20008"
"1.21646","27.65347","1.11875","45.35200","0.00000","1.21646","0.20008"
"1.21646","27.65120","1.11866","45.53200","0.00000","1.21646","0.20008"
"1.21646","27.65468","1.11880","45.71200","0.00000","1.21646","0.20008"
"1.21646","27.64160","1.11827","45.89200","0.00000","1.21646","0.20008"
"1.21646","27.62373","1.11755","46.07200","0.00000","1.21646","0.20008"
"1.21646","27.60706","1.11687","46.25200","0.00000","1.21646","0.20008"
"1.21646","27.60487","1.11679","46.43200","0.00000","1.21646","0.20008"
"1.21646","27.61677","1.11727","46.61200","0.00000","1.21646","0.20008"
"1.21646","27.61668","1.11726","46.79200","0.00000","1.21646","0.20008"
"1.21646","27.61173","1.11706","46.97200","0.00000","1.21646","0.20008"
"1.21646","27.58175","1.11585","47.15200","0.00000","1.21646","0.20008"
"1.21646","27.57583","1.11561","47.33200","0.00000","1.21646","0.20008"
"1.21646","27.57390","1.11553","47.51200","0.00000","1.21646","0.20008"
"1.21646","27.55612","1.11481","47.69200","0.00000","1.21646","0.20008"
"1.21646","27.56605","1.11522","47.87200","0.00000","1.21646","0.20008"
"1.21646","27.56271","1.11508","48.05200","0.00000","1.21646","0.20008"
"1.21646","27.55810","1.11489","48.23200","0.00000","1.21646","0.20008"
"1.21646","27.53827","1.11409","48.41200","0.00000","1.21646","0.20008"
"1.21646","27.51979","1.11334","48.59200","0.00000","1.21646","0.20008"
"1.21646","27.49795","1.11246","48.77200","0.00000","1.21646","0.20008"
"1.21646","27.50385","1.11270","48.95200","0.00000","1.21646","0.20008"
"1.21646","27.50349","1.11269","49.13200","0.00000","1.21646","0.20008"
"1.21646","27.52185","1.11343","49.31200","0.00000","1.21646","0.20008"
"1.21646","27.54554","1.11439","49.49200","0.00000","1.21646","0.20008"
"1.21646","27.51329","1.11308","49.67200","0.00000","1.21646","0.20008"
"1.21646","27.48237","1.11183","49.85200","0.00000","1.21646","0.20008"
"1.21646","27.44445","1.11030","50.03200","0.00000","1.21646","0.20008"
"1.21646","27.46902","1.11129","50.21200","0.00000","1.21646","0.20008"
"1.21646","27.48433","1.11191","50.39200","0.00000","1.21646","0.20008"
"1.21646","27.49320","1.11227","50.57200","0.00000","1.21646","0.20008"
"1.21646","27.45355","1.11066","50.75200","0.00000","1.21646","0.20008"
"1.21646","27.44471","1.11031","50.93200","0.00000","1.21646","0.20008"
"1.21646","27.43860","1.11006","51.11200","0.00000","1.21646","0.20008"
"1.21646","27.45303","1.11064","51.29200","0.00000","1.21646","0.20008"
"1.21646","27.44863","1.11047","51.47200","0.00000","1.21646","0.20008"
"1.21646","27.44950","1.11050","51.65200","0.00000","1.21646","0.20008"
"1.21646","27.43266","1.10982","51.83200","0.00000","1.21646","0.20008"
"1.21646","27.41320","1.10903","52.01200","0.00000","1.21646","0.20008"
"1.21646","27.39945","1.10848","52.19200","0.00000","1.21646","0.20008"
"1.21646","27.40543","1.10872","52.37200","0.00000","1.21646","0.20008"
"1.21646","27.40382","1.10865","52.55200","0.00000","1.21646","0.20008"
"1.21646","27.40286","1.10861","52.73200","0.00000","1.21646","0.20008"
"1.21646","27.39767","1.10840","52.91200","0.00000","1.21646","0.20008"
"1.21646","27.38660","1.10796","53.09200","0.00000","1.21646","0.20008"
"1.21646","27.38230","1.10778","53.27200","0.00000","1.21646","0.20008"
"1.21646","27.38157","1.10775","53.45200","0.00000","1.21646","0.20008"
"1.21646","27.36598","1.10712","53.63200","0.00000","1.21646","0.20008"
"1.21646","27.36898","1.10724","53.81200","0.00000","1.21646","0.20008"
"1.21646","27.35907","1.10684","53.99200","0.00000","1.21646","0.20008"
"1.21646","27.35050","1.10650","54.17200","0.00000","1.21646","0.20008"
"1.21646","27.34331","1.10620","54.35200","0.00000","1.21646","0.20008"
"1.21646","27.33443","1.10585","54.53200","0.00000","1.21646","0.20008"
"1.21646","27.33908","1.10603","54.71200","0.00000","1.21646","0.20008"
"1.21646","27.32967","1.10565","54.89200","0.00000","1.21646","0.20008"
"1.21646","27.32672","1.10553","55.07200","0.00000","1.21646","0.20008"
"1.21646","27.31458","1.10504","55.25200","0.00000","1.21646","0.20008"
"1.21646","27.31276","1.10497","55.43200","0.00000","1.21646","0.20008"
"1.21646","27.31180","1.10493","55.61200","0.00000","1.21646","0.20008"
"1.21646","27.30116","1.10450","55.79200","0.00000","1.21646","0.20008"
"1.21646","27.30801","1.10478","55.97200","0.00000","1.21646","0.20008"
"1.21646","27.27702","1.10352","56.15200","0.00000","1.21646","0.20008"
"1.21646","27.28576","1.10388","56.33200","0.00000","1.21646","0.20008"
"1.21646","27.26908","1.10320","56.51200","0.00000","1.21646","0.20008"
"1.21646","27.26995","1.10324","56.69200","0.00000","1.21646","0.20008"
"1.21646","27.27512","1.10345","56.87200","0.00000","1.21646","0.20008"
"1.21646","27.26563","1.10306","57.05200","0.00000","1.21646","0.20008"
"1.21646","27.25821","1.10276","57.23200","0.00000","1.21646","0.20008"
"1.21646","27.24855","1.10237","57.41200","0.00000","1.21646","0.20008"
"1.21646","27.23323","1.10175","57.59200","0.00000","1.21646","0.20008"
"1.21646","27.24264","1.10213","57.77200","0.00000","1.21646","0.20008"
"1.21646","27.24977","1.10242","57.95200","0.00000","1.21646","0.20008"
"1.21646","27.24344","1.10216","58.13200","0.00000","1.21646","0.20008"
"1.21646","27.22570","1.10145","58.31200","0.00000","1.21646","0.20008"
"1.21646","27.22453","1.10140","58.49200","0.00000","1.21646","0.20008"
"1.21646","27.21458","1.10100","58.67200","0.00000","1.21646","0.20008"
"1.21646","27.21141","1.10087","58.85200","0.00000","1.21646","0.20008"
"1.21646","27.21411","1.10098","59.03200","0.00000","1.21646","0.20008"
"1.21646","27.20395","1.10057","59.21200","0.00000","1.21646","0.20008"
"1.21646","27.19594","1.10024","59.39200","0.00000","1.21646","0.20008"
"1.21646","27.18492","1.09980","59.57200","0.00000","1.21646","0.20008"
"1.21646","27.18773","1.09991","59.75200","0.00000","1.21646","0.20008"
"1.21646","27.18207","1.09968","59.93200","0.00000","1.21646","0.20008"
"1.21646","27.18429","1.09977","60.11200","0.00000","1.21646","0.20008"
"1.21646","27.16225","1.09888","60.29200","0.00000","1.21646","0.20008"
"1.21646","27.13874","1.09793","60.47200","0.00000","1.21646","0.20008"
"1.21646","27.14585","1.09822","60.65200","0.00000","1.21646","0.20008"
"1.21646","27.14911","1.09835","60.83200","0.00000","1.21646","0.20008"
"1.21646","27.17406","1.09936","61.01200","0.00000","1.21646","0.20008"
"1.21646","27.16719","1.09908","61.19200","0.00000","1.21646","0.20008"
"1.21646","27.14883","1.09834","61.37200","0.00000","1.21646","0.20008"
"1.21646","27.13463","1.09776","61.55200","0.00000","1.21646","0.20008"
"1.21646","27.12370","1.09732","61.73200","0.00000","1.21646","0.20008"
"1.21646","27.13187","1.09765","61.91200","0.00000","1.21646","0.20008"
"1.21646","27.14097","1.09802","62.09200","0.00000","1.21646","0.20008"
"1.21646","27.12466","1.09736","62.27200","0.00000","1.21646","0.20008"
"1.21646","27.11684","1.09704","62.45200","0.00000","1.21646","0.20008"
"1.21646","27.10451","1.09654","62.63200","0.00000","1.21646","0.20008"
"1.21646","27.09866","1.09631","62.81200","0.00000","1.21646","0.20008"
"1.21646","27.10625","1.09661","62.99200","0.00000","1.21646","0.20008"
"1.21646","27.10495","1.09656","63.17200","0.00000","1.21646","0.20008"
"1.21646","27.09560","1.09618","63.35200","0.00000","1.21646","0.20008"
"1.21646","27.09368","1.09611","63.53200","0.00000","1.21646","0.20008"
"1.21646","27.08131","1.09561","63.71200","0.00000","1.21646","0.20008"
"1.21646","27.07384","1.09530","63.89200","0.00000","1.21646","0.20008"
"1.21646","27.07073","1.09518","64.07200","0.00000","1.21646","0.20008"
"1.21646","27.07464","1.09534","64.25200","0.00000","1.21646","0.20008"
"1.21646","27.06514","1.09495","64.43200","0.00000","1.21646","0.20008"
"1.21646","27.06501","1.09495","64.61200","0.00000","1.21646","0.20008"
"1.21646","27.04995","1.09434","64.79200","0.00000","1.21646","0.20008"
"1.21646","27.04696","1.09422","64.97200","0.00000","1.21646","0.20008"
"1.21646","27.05172","1.09441","65.15200","0.00000","1.21646","0.20008"
"1.21646","27.04985","1.09433","65.33200","0.00000","1.21646","0.20008"
"1.21646","27.04624","1.09419","65.51200","0.00000","1.21646","0.20008"
"1.21646","27.02328","1.09326","65.69200","0.00000","1.21646","0.20008"
"1.21646","27.02777","1.09344","65.87200","0.00000","1.21646","0.20008"
"1.21646","27.02102","1.09317","66.05200","0.00000","1.21646","0.20008"
"1.21646","27.02092","1.09316","66.23200","0.00000","1.21646","0.20008"
"1.21646","27.01184","1.09279","66.41200","0.00000","1.21646","0.20008"
"1.21646","27.00754","1.09262","66.59200","0.00000","1.21646","0.20008"
"1.21646","27.00813","1.09264","66.77200","0.00000","1.21646","0.20008"
"1.21646","27.00748","1.09262","66.95200","0.00000","1.21646","0.20008"
"1.21646","26.99748","1.09221","67.13200","0.00000","1.21646","0.20008"
"1.21646","26.99804","1.09224","67.31200","0.00000","1.21646","0.20008"
"1.21646","26.99173","1.09198","67.49200","0.00000","1.21646","0.20008"
"1.21646","26.97942","1.09148","67.67200","0.00000","1.21646","0.20008"
"1.21646","26.97646","1.09136","67.85200","0.00000","1.21646","0.20008"
"1.21646","26.97232","1.09120","68.03200","0.00000","1.21646","0.20008"
"1.21646","26.97759","1.09141","68.21200","0.00000","1.21646","0.20008"
"1.21646","26.97027","1.09111","68.39200","0.00000","1.21646","0.20008"
"1.21646","26.96804","1.09102","68.57200","0.00000","1.21646","0.20008"
"1.21646","26.95567","1.09052","68.75200","0.00000","1.21646","0.20008"
"1.21646","26.95926","1.09067","68.93200","0.00000","1.21646","0.20008"
"1.21646","26.95083","1.09033","69.11200","0.00000","1.21646","0.20008"
"1.21646","26.94291","1.09001","69.29200","0.00000","1.21646","0.20008"
"1.21646","26.94496","1.09009","69.47200","0.00000","1.21646","0.20008"
"1.21646","26.93601","1.08973","69.65200","0.00000","1.21646","0.20008"
"1.21646","26.93442","1.08966","69.83200","0.00000","1.21646","0.20008"
"1.21646","26.93030","1.08950","70.01200","0.00000","1.21646","0.20008"
"1.21646","26.92191","1.08916","70.19200","0.00000","1.21646","0.20008"
"1.21646","26.92168","1.08915","70.37200","0.00000","1.21646","0.20008"
"1.21646","26.91804","1.08900","70.55200","0.00000","1.21646","0.20008"
"1.21646","26.91121","1.08872","70.73200","0.00000","1.21646","0.20008"
"1.21646","26.90798","1.08859","70.91200","0.00000","1.21646","0.20008"
"1.21646","26.90336","1.08841","71.09200","0.00000","1.21646","0.20008"
"1.21646","26.89430","1.08804","71.27200","0.00000","1.21646","0.20008"
"1.21646","26.90257","1.08837","71.45200","0.00000","1.21646","0.20008"
"1.21646","26.89095","1.08790","71.63200","0.00000","1.21646","0.20008"
"1.21646","26.88501","1.08766","71.81200","0.00000","1.21646","0.20008"
"1.21646","26.88408","1.08763","71.99200","0.00000","1.21646","0.20008"
"1.21646","26.88174","1.08753","72.17200","0.00000","1.21646","0.20008"
"1.21646","26.88127","1.08751","72.35200","0.00000","1.21646","0.20008"
"1.21646","26.86579","1.08689","72.53200","0.00000","1.21646","0.20008"
"1.21646","26.86932","1.08703","72.71200","0.00000","1.21646","0.20008"
"1.21646","26.86799","1.08698","72.89200","0.00000","1.21646","0.20008"
"1.21646","26.85826","1.08658","73.07200","0.00000","1.21646","0.20008"
"1.21646","26.85188","1.08632","73.25200","0.00000","1.21646","0.20008"
"1.21646","26.85240","1.08634","73.43200","0.00000","1.21646","0.20008"
"1.21646","26.84804","1.08617","73.61200","0.00000","1.21646","0.20008"
"1.21646","26.84063","1.08587","73.79200","0.00000","1.21646","0.20008"
"1.21646","26.83863","1.08579","73.97200","0.00000","1.21646","0.20008"
"1.21646","26.84035","1.08586","74.15200","0.00000","1.21646","0.20008"
"1.21646","26.83280","1.08555","74.33200","0.00000","1.21646","0.20008"
"1.21646","26.83230","1.08553","74.51200","0.00000","1.21646","0.20008"
"1.21646","26.82509","1.08524","74.69200","0.00000","1.21646","0.20008"
"1.21646","26.82861","1.08538","74.87200","0.00000","1.21646","0.20008"
"1.21646","26.82051","1.08505","75.05200","0.00000","1.21646","0.20008"
"1.21646","26.81424","1.08480","75.23200","0.00000","1.21646","0.20008"
"1.21646","26.80974","1.08462","75.41200","0.00000","1.21646","0.20008"
"1.21646","26.81518","1.08484","75.59200","0.00000","1.21646","0.20008"
"1.21646","26.80075","1.08425","75.77200","0.00000","1.21646","0.20008"
"1.21646","26.79945","1.08420","75.95200","0.00000","1.21646","0.20008"
"1.21646","26.78621","1.08367","76.13200","0.00000","1.21646","0.20008"
"1.21646","26.79406","1.08398","76.31200","0.00000","1.21646","0.20008"
"1.21646","26.78839","1.08375","76.49200","0.00000","1.21646","0.20008"
"1.21646","26.78556","1.08364","76.67200","0.00000","1.21646","0.20008"
"1.21646","26.77757","1.08332","76.85200","0.00000","1.21646","0.20008"
"1.21646","26.77198","1.08309","77.03200","0.00000","1.21646","0.20008"
"1.21646","26.77684","1.08329","77.21200","0.00000","1.21646","0.20008"
"1.21646","26.77342","1.08315","77.39200","0.00000","1.21646","0.20008"
"1.21646","26.76378","1.08276","77.57200","0.00000","1.21646","0.20008"
"1.21646","26.75659","1.08247","77.75200","0.00000","1.21646","0.20008"
"1.21646","26.75632","1.08246","77.93200","0.00000","1.21646","0.20008"
"1.21646","26.75466","1.08239","78.11200","0.00000","1.21646","0.20008"
"1.21646","26.75358","1.08235","78.29200","0.00000","1.21646","0.20008"
"1.21646","26.74573","1.08203","78.47200","0.00000","1.21646","0.20008"
"1.21646","26.73685","1.08167","78.65200","0.00000","1.21646","0.20008"
"1.21646","26.73850","1.08174","78.83200","0.00000","1.21646","0.20008"
"1.21646","26.73806","1.08172","79.01200","0.00000","1.21646","0.20008"
"1.21646","26.73175","1.08146","79.19200","0.00000","1.21646","0.20008"
"1.21646","26.72408","1.08115","79.37200","0.00000","1.21646","0.20008"
"1.21646","26.72355","1.08113","79.55200","0.00000","1.21646","0.20008"
"1.21646","26.72280","1.08110","79.73200","0.00000","1.21646","0.20008"
"1.21646","26.71451","1.08077","79.91200","0.00000","1.21646","0.20008"
"1.21646","26.71433","1.08076","80.09200","0.00000","1.21646","0.20008"
"1.21646","26.71216","1.08067","80.27200","0.00000","1.21646","0.20008"
"1.21646","26.70863","1.08053","80.45200","0.00000","1.21646","0.20008"
"1.21646","26.70614","1.08043","80.63200","0.00000","1.21646","0.20008"
"1.21646","26.69667","1.08004","80.81200","0.00000","1.21646","0.20008"
"1.21646","26.69816","1.08010","80.99200","0.00000","1.21646","0.20008"
"1.21646","26.69803","1.08010","81.17200","0.00000","1.21646","0.20008"
"1.21646","26.68943","1.07975","81.35200","0.00000","1.21646","0.20008"
"1.21646","26.68778","1.07968","81.53200","0.00000","1.21646","0.20008"
"1.21646","26.68546","1.07959","81.71200","0.00000","1.21646","0.20008"
"1.21646","26.68125","1.07942","81.89200","0.00000","1.21646","0.20008"
"1.21646","26.68008","1.07937","82.07200","0.00000","1.21646","0.20008"
"1.21646","26.67428","1.07914","82.25200","0.00000","1.21646","0.20008"
"1.21646","26.66810","1.07889","82.43200","0.00000","1.21646","0.20008"
"1.21646","26.66298","1.07868","82.61200","0.00000","1.21646","0.20008"
"1.21646","26.66635","1.07882","82.79200","0.00000","1.21646","0.20008"
"1.21646","26.66244","1.07866","82.97200","0.00000","1.21646","0.20008"
"1.21646","26.65398","1.07832","83.15200","0.00000","1.21646","0.20008"
"1.21646","26.65307","1.07828","83.33200","0.00000","1.21646","0.20008"
"1.21646","26.65430","1.07833","83.51200","0.00000","1.21646","0.20008"
"1.21646","26.64631","1.07801","83.69200","0.00000","1.21646","0.20008"
"1.21646","26.65130","1.07821","83.87200","0.00000","1.21646","0.20008"
"1.21646","26.64890","1.07811","84.05200","0.00000","1.21646","0.20008"
"1.21646","26.64123","1.07780","84.23200","0.00000","1.21646","0.20008"
"1.21646","26.63239","1.07744","84.41200","0.00000","1.21646","0.20008"
"1.21646","26.63523","1.07756","84.59200","0.00000","1.21646","0.20008"
"1.21646","26.62759","1.07725","84.77200","0.00000","1.21646","0.20008"
"1.21646","26.62631","1.07720","84.95200","0.00000","1.21646","0.20008"
"1.21646","26.62281","1.07706","85.13200","0.00000","1.21646","0.20008"
"1.21646","26.62479","1.07714","85.31200","0.00000","1.21646","0.20008"
"1.21646","26.61582","1.07677","85.49200","0.00000","1.21646","0.20008"
"1.21646","26.61376","1.07669","85.67200","0.00000","1.21646","0.20008"
"1.21646","26.60479","1.07633","85.85200","0.00000","1.21646","0.20008"
"1.21646","26.60384","1.07629","86.03200","0.00000","1.21646","0.20008"
"1.21646","26.59922","1.07610","86.21200","0.00000","1.21646","0.20008"
"1.21646","26.59592","1.07597","86.39200","0.00000","1.21646","0.20008"
"1.21646","26.60000","1.07613","86.57200","0.00000","1.21646","0.20008"
"1.21646","26.59403","1.07589","86.75200","0.00000","1.21646","0.20008"
"1.21646","26.58681","1.07560","86.93200","0.00000","1.21646","0.20008"
"1.21646","26.58315","1.07545","87.11200","0.00000","1.21646","0.20008"
"1.21646","26.58557","1.07555","87.29200","0.00000","1.21646","0.20008"
"1.21646","26.57844","1.07526","87.47200","0.00000","1.21646","0.20008"
"1.21646","26.58078","1.07536","87.65200","0.00000","1.21646","0.20008"
"1.21646","26.57485","1.07512","87.83200","0.00000","1.21646","0.20008"
"1.21646","26.57522","1.07513","88.01200","0.00000","1.21646","0.20008"
"1.21646","26.56927","1.07489","88.19200","0.00000","1.21646","0.20008"
"1.21646","26.56735","1.07481","88.37200","0.00000","1.21646","0.20008"
"1.21646","26.56478","1.07471","88.55200","0.00000","1.21646","0.20008"
"1.21646","26.55328","1.07424","88.73200","0.00000","1.21646","0.20008"
"1.21646","26.55462","1.07430","88.91200","0.00000","1.21646","0.20008"
"1.21646","26.55066","1.07414","89.09200","0.00000","1.21646","0.20008"
"1.21646","26.55042","1.07413","89.27200","0.00000","1.21646","0.20008"
"1.21646","26.54139","1.07376","89.45200","0.00000","1.21646","0.20008"
"1.21646","26.53504","1.07351","89.63200","0.00000","1.21646","0.20008"
"1.21646","26.53631","1.07356","89.81200","0.00000","1.21646","0.20008"
"1.21646","26.53537","1.07352","89.99200","0.00000","1.21646","0.20008"
"1.21646","26.52728","1.07319","90.17200","0.00000","1.21646","0.20008"
"1.21646","26.53154","1.07336","90.35200","0.00000","1.21646","0.20008"
"1.21646","26.52675","1.07317","90.53200","0.00000","1.21646","0.20008"
"1.21646","26.51273","1.07260","90.71200","0.00000","1.21646","0.20008"
"1.21646","26.51173","1.07256","90.89200","0.00000","1.21646","0.20008"
"1.21646","26.51867","1.07284","91.07200","0.00000","1.21646","0.20008"
"1.21646","26.50626","1.07234","91.25200","0.00000","1.21646","0.20008"
"1.21646","26.51204","1.07257","91.43200","0.00000","1.21646","0.20008"
"1.21646","26.51725","1.07279","91.61200","0.00000","1.21646","0.20008"
"1.21646","26.50138","1.07214","91.79200","0.00000","1.21646","0.20008"
"1.21646","26.49752","1.07199","91.97200","0.00000","1.21646","0.20008"
"1.21646","26.49769","1.07199","92.15200","0.00000","1.21646","0.20008"
"1.21646","26.49325","1.07181","92.33200","0.00000","1.21646","0.20008"
"1.21646","26.48797","1.07160","92.51200","0.00000","1.21646","0.20008"
"1.21646","26.49012","1.07169","92.69200","0.00000","1.21646","0.20008"
"1.21646","26.47935","1.07125","92.87200","0.00000","1.21646","0.20008"
"1.21646","26.48446","1.07146","93.05200","0.00000","1.21646","0.20008"
"1.21646","26.46891","1.07083","93.23200","0.00000","1.21646","0.20008"
"1.21646","26.47701","1.07116","93.41200","0.00000","1.21646","0.20008"
"1.21646","26.47558","1.07110","93.59200","0.00000","1.21646","0.20008"
"1.21646","26.47251","1.07098","93.77200","0.00000","1.21646","0.20008"
"1.21646","26.46675","1.07074","93.95200","0.00000","1.21646","0.20008"
"1.21646","26.46930","1.07085","94.13200","0.00000","1.21646","0.20008"
"1.21646","26.45746","1.07037","94.31200","0.00000","1.21646","0.20008"
"1.21646","26.45988","1.07046","94.49200","0.00000","1.21646","0.20008"
"1.21646","26.45347","1.07021","94.67200","0.00000","1.21646","0.20008"
"1.21646","26.45698","1.07035","94.85200","0.00000","1.21646","0.20008"
"1.21646","26.44714","1.06995","95.03200","0.00000","1.21646","0.20008"
"1.21646","26.44361","1.06981","95.21200","0.00000","1.21646","0.20008"
"1.21646","26.44808","1.06999","95.39200","0.00000","1.21646","0.20008"
"1.21646","26.44481","1.06985","95.57200","0.00000","1.21646","0.20008"
"1.21646","26.44199","1.06974","95.75200","0.00000","1.21646","0.20008"
"1.21646","26.43718","1.06955","95.93200","0.00000","1.21646","0.20008"
"1.21646","26.42974","1.06925","96.11200","0.00000","1.21646","0.20008"
"1.21646","26.43766","1.06957","96.29200","0.00000","1.21646","0.20008"
"1.21646","26.42249","1.06895","96.47200","0.00000","1.21646","0.20008"
"1.21646","26.42548","1.06907","96.65200","0.00000","1.21646","0.20008"
"1.21646","26.42132","1.06890","96.83200","0.00000","1.21646","0.20008"
"1.21646","26.41724","1.06874","97.01200","0.00000","1.21646","0.20008"
"1.21646","26.41013","1.06845","97.19200","0.00000","1.21646","0.20008"
"1.21646","26.41459","1.06863","97.37200","0.00000","1.21646","0.20008"
"1.21646","26.41238","1.06854","97.55200","0.00000","1.21646","0.20008"
"1.21646","26.41452","1.06863","97.73200","0.00000","1.21646","0.20008"
"1.21646","26.39602","1.06788","97.91200","0.00000","1.21646","0.20008"
"1.21646","26.40793","1.06836","98.09200","0.00000","1.21646","0.20008"
"1.21646","26.40151","1.06810","98.27200","0.00000","1.21646","0.20008"
"1.21646","26.39341","1.06778","98.45200","0.00000","1.21646","0.20008"
"1.21646","26.39179","1.06771","98.63200","0.00000","1.21646","0.20008"
"1.21646","26.38725","1.06753","98.81200","0.00000","1.21646","0.20008"
"1.21646","26.39106","1.06768","98.99200","0.00000","1.21646","0.20008"
"1.21646","26.38890","1.06759","99.17200","0.00000","1.21646","0.20008"
"1.21646","26.39199","1.06772","99.35200","0.00000","1.21646","0.20008"
"1.21646","26.38134","1.06729","99.53200","0.00000","1.21646","0.20008"
"1.21646","26.37795","1.06715","99.71200","0.00000","1.21646","0.20008"
"1.21646","26.37332","1.06696","99.89200","0.00000","1.21646","0.20008"
"1.21646","26.37144","1.06689","100.07200","0.00000","1.21646","0.20008"
"1.21646","26.36946","1.06681","100.25200","0.00000","1.21646","0.20008"
"1.21646","26.37281","1.06694","100.43200","0.00000","1.21646","0.20008"
"1.21646","26.36613","1.06667","100.61200","0.00000","1.21646","0.20008"
"1.21646","26.36934","1.06680","100.79200","0.00000","1.21646","0.20008"
"1.21646","26.35684","1.06630","100.97200","0.00000","1.21646","0.20008"
"1.21646","26.35637","1.06628","101.15200","0.00000","1.21646","0.20008"
"1.21646","26.36387","1.06658","101.33200","0.00000","1.21646","0.20008"
"1.21646","26.35931","1.06640","101.51200","0.00000","1.21646","0.20008"
"1.21646","26.35303","1.06614","101.69200","0.00000","1.21646","0.20008"
"1.21646","26.35001","1.06602","101.87200","0.00000","1.21646","0.20008"
"1.21646","26.34254","1.06572","102.05200","0.00000","1.21646","0.20008"
"1.21646","26.34010","1.06562","102.23200","0.00000","1.21646","0.20008"
"1.21646","26.33573","1.06544","102.41200","0.00000","1.21646","0.20008"
"1.21646","26.33288","1.06533","102.59200","0.00000","1.21646","0.20008"
"1.21646","26.32916","1.06518","102.77200","0.00000","1.21646","0.20008"
"1.21646","26.32638","1.06506","102.95200","0.00000","1.21646","0.20008"
"1.21646","26.32670","1.06508","103.13200","0.00000","1.21646","0.20008"
"1.21646","26.32792","1.06513","103.31200","0.00000","1.21646","0.20008"
"1.21646","26.32063","1.06483","103.49200","0.00000","1.21646","0.20008"
"1.21646","26.31779","1.06472","103.67200","0.00000","1.21646","0.20008"
"1.21646","26.31440","1.06458","103.85200","0.00000","1.21646","0.20008"
"1.21646","26.32408","1.06497","104.03200","0.00000","1.21646","0.20008"
"1.21646","26.31726","1.06469","104.21200","0.00000","1.21646","0.20008"
"1.21646","26.30806","1.06432","104.39200","0.00000","1.21646","0.20008"
"1.21646","26.29654","1.06386","104.57200","0.00000","1.21646","0.20008"
"1.21646","26.30855","1.06434","104.75200","0.00000","1.21646","0.20008"
"1.21646","26.30548","1.06422","104.93200","0.00000","1.21646","0.20008"
"1.21646","26.29721","1.06388","105.11200","0.00000","1.21646","0.20008"
"1.21646","26.29465","1.06378","105.29200","0.00000","1.21646","0.20008"
"1.21646","26.29369","1.06374","105.47200","0.00000","1.21646","0.20008"
"1.21646","26.28698","1.06347","105.65200","0.00000","1.21646","0.20008"
"1.21646","26.28658","1.06345","105.83200","0.00000","1.21646","0.20008"
"1.21646","26.28816","1.06352","106.01200","0.00000","1.21646","0.20008"
"1.21646","26.28432","1.06336","106.19200","0.00000","1.21646","0.20008"
"1.21646","26.27897","1.06315","106.37200","0.00000","1.21646","0.20008"
"1.21646","26.27997","1.06319","106.55200","0.00000","1.21646","0.20008"
"1.21646","26.27738","1.06308","106.73200","0.00000","1.21646","0.20008"
"1.21646","26.27371","1.06293","106.91200","0.00000","1.21646","0.20008"
"1.21646","26.26878","1.06273","107.09200","0.00000","1.21646","0.20008"
"1.21646","26.26924","1.06275","107.27200","0.00000","1.21646","0.20008"
"1.21646","26.25437","1.06215","107.45200","0.00000","1.21646","0.20008"
"1.21646","26.26024","1.06239","107.63200","0.00000","1.21646","0.20008"
"1.21646","26.26299","1.06250","107.81200","0.00000","1.21646","0.20008"
"1.21646","26.25071","1.06200","107.99200","0.00000","1.21646","0.20008"
"1.21646","26.25569","1.06220","108.17200","0.00000","1.21646","0.20008"
"1.21646","26.25068","1.06200","108.35200","0.00000","1.21646","0.20008"
"1.21646","26.25377","1.06213","108.53200","0.00000","1.21646","0.20008"
"1.21646","26.24043","1.06159","108.71200","0.00000","1.21646","0.20008"
"1.21646","26.24614","1.06182","108.89200","0.00000","1.21646","0.20008"
"1.21646","26.23959","1.06155","109.07200","0.00000","1.21646","0.20008"
"1.21646","26.24106","1.06161","109.25200","0.00000","1.21646","0.20008"
"1.21646","26.24423","1.06174","109.43200","0.00000","1.21646","0.20008"
"1.21646","26.23615","1.06141","109.61200","0.00000","1.21646","0.20008"
"1.21646","26.22416","1.06093","109.79200","0.00000","1.21646","0.20008"
"1.21646","26.25208","1.06206","109.97200","0.00000","1.21646","0.20008"
"1.21646","26.23206","1.06125","110.15200","0.00000","1.21646","0.20008"
"1.21646","26.21807","1.06068","110.33200","0.00000","1.21646","0.20008"
"1.21646","26.22057","1.06078","110.51200","0.00000","1.21646","0.20008"
"1.21646","26.21680","1.06063","110.69200","0.00000","1.21646","0.20008"
"1.21646","26.21817","1.06069","110.87200","0.00000","1.21646","0.20008"
"1.21646","26.22241","1.06086","111.05200","0.00000","1.21646","0.20008"
"1.21646","26.21955","1.06074","111.23200","0.00000","1.21646","0.20008"
"1.21646","26.21209","1.06044","111.41200","0.00000","1.21646","0.20008"
"1.21646","26.19770","1.05986","111.59200","0.00000","1.21646","0.20008"
"1.21646","26.20476","1.06014","111.77200","0.00000","1.21646","0.20008"
"1.21646","26.20790","1.06027","111.95200","0.00000","1.21646","0.20008"
"1.21646","26.19908","1.05991","112.13200","0.00000","1.21646","0.20008"
"1.21646","26.20255","1.06005","112.31200","0.00000","1.21646","0.20008"
"1.21646","26.18981","1.05954","112.49200","0.00000","1.21646","0.20008"
"1.21646","26.18947","1.05952","112.67200","0.00000","1.21646","0.20008"
"1.21646","26.18585","1.05938","112.85200","0.00000","1.21646","0.20008"
"1.21646","26.18422","1.05931","113.03200","0.00000","1.21646","0.20008"
"1.21646","26.18593","1.05938","113.21200","0.00000","1.21646","0.20008"
"1.21646","26.19072","1.05958","113.39200","0.00000","1.21646","0.20008"
"1.21646","26.18026","1.05915","113.57200","0.00000","1.21646","0.20008"
"1.21646","26.17773","1.05905","113.75200","0.00000","1.21646","0.20008"
"1.21646","26.18428","1.05931","113.93200","0.00000","1.21646","0.20008"
"1.21646","26.18007","1.05914","114.11200","0.00000","1.21646","0.20008"
"1.21646","26.17102","1.05878","114.29200","0.00000","1.21646","0.20008"
"1.21646","26.17010","1.05874","114.47200","0.00000","1.21646","0.20008"
"1.21646","26.16178","1.05840","114.65200","0.00000","1.21646","0.20008"
"1.21646","26.17182","1.05881","114.83200","0.00000","1.21646","0.20008"
"1.21646","26.16485","1.05853","115.01200","0.00000","1.21646","0.20008"
"1.21646","26.16294","1.05845","115.19200","0.00000","1.21646","0.20008"
"1.21646","26.15845","1.05827","115.37200","0.00000","1.21646","0.20008"
"1.21646","26.16348","1.05847","115.55200","0.00000","1.21646","0.20008"
"1.21646","26.15848","1.05827","115.73200","0.00000","1.21646","0.20008"
"1.21646","26.14987","1.05792","115.91200","0.00000","1.21646","0.20008"
"1.21646","26.14839","1.05786","116.09200","0.00000","1.21646","0.20008"
"1.21646","26.14469","1.05771","116.27200","0.00000","1.21646","0.20008"
"1.21646","26.15136","1.05798","116.45200","0.00000","1.21646","0.20008"
"1.21646","26.14867","1.05787","116.63200","0.00000","1.21646","0.20008"
"1.21646","26.13873","1.05747","116.81200","0.00000","1.21646","0.20008"
"1.21646","26.13319","1.05725","116.99200","0.00000","1.21646","0.20008"
"1.21646","26.13454","1.05730","117.17200","0.00000","1.21646","0.20008"
"1.21646","26.12642","1.05697","117.35200","0.00000","1.21646","0.20008"
"1.21646","26.12734","1.05701","117.53200","0.00000","1.21646","0.20008"
"1.21646","26.12565","1.05694","117.71200","0.00000","1.21646","0.20008"
"1.21646","26.12734","1.05701","117.89200","0.00000","1.21646","0.20008"
"1.21646","26.12807","1.05704","118.07200","0.00000","1.21646","0.20008"
"1.21646","26.11730","1.05661","118.25200","0.00000","1.21646","0.20008"
"1.21646","26.12460","1.05690","118.43200","0.00000","1.21646","0.20008"
"1.21646","26.12186","1.05679","118.61200","0.00000","1.21646","0.20008"
"1.21646","26.10541","1.05612","118.79200","0.00000","1.21646","0.20008"
"1.21646","26.11900","1.05667","118.97200","0.00000","1.21646","0.20008"
"1.21646","26.10627","1.05616","119.15200","0.00000","1.21646","0.20008"
"1.21646","26.10589","1.05614","119.33200","0.00000","1.21646","0.20008"
"1.21646","26.11047","1.05633","119.51200","0.00000","1.21646","0.20008"
"1.21646","26.10951","1.05629","119.69200","0.00000","1.21646","0.20008"
"1.21646","26.10620","1.05616","119.87200","0.00000","1.21646","0.20008"
"1.21646","26.09889","1.05586","120.05200","0.00000","1.21646","0.20008"
"1.21646","26.09923","1.05587","120.23200","0.00000","1.21646","0.20008"
"1.21646","26.09680","1.05578","120.41200","0.00000","1.21646","0.20008"
"1.21646","26.09097","1.05554","120.59200","0.00000","1.21646","0.20008"
"1.21646","26.09644","1.05576","120.77200","0.00000","1.21646","0.20008"
"1.21646","26.08991","1.05550","120.95200","0.00000","1.21646","0.20008"
"1.21646","26.09503","1.05570","121.13200","0.00000","1.21646","0.20008"
"1.21646","26.08723","1.05539","121.31200","0.00000","1.21646","0.20008"
"1.21646","26.08450","1.05528","121.49200","0.00000","1.21646","0.20008"
"1.21646","26.07931","1.05507","121.67200","0.00000","1.21646","0.20008"
"1.21646","26.08365","1.05524","121.85200","0.00000","1.21646","0.20008"
"1.21646","26.08349","1.05524","122.03200","0.00000","1.21646","0.20008"
"1.21646","26.07779","1.05501","122.21200","0.00000","1.21646","0.20008"
"1.21646","26.07067","1.05472","122.39200","0.00000","1.21646","0.20008"
"1.21646","26.07351","1.05483","122.57200","0.00000","1.21646","0.20008"
"1.21646","26.06670","1.05456","122.75200","0.00000","1.21646","0.20008"
"1.21646","26.06709","1.05457","122.93200","0.00000","1.21646","0.20008"
"1.21646","26.06779","1.05460","123.04200","0.00000","1.21646","0.20008"