File: Rubber Stress Relaxation Raw Data - Small Samples-20210211/Specimen_RawData_9.csv
Specimen properties : Specimen label,"GCI2S1R3"
Specimen properties : Anvil height,"5.99000",mm
Specimen properties : Diameter,"5.22000",mm
Test : Rate 1,"24.00000",mm/min
Test : Start of hold value,"20.00000",%
Test : Duration,"120.00000",s

Extension,Load,Compressive stress,Time,PIP count,Compressive extension,Compressive strain (Extension)
(mm),(N),(MPa),(s),,(mm),(mm/mm)
"0.00000","0.09308","0.00435","0.00000","0.00000","0.00000","0.00000"
"0.05958","2.62705","0.12275","0.18000","0.00000","0.05958","0.00995"
"0.14021","5.27877","0.24666","0.36000","0.00000","0.14021","0.02341"
"0.21500","7.38587","0.34512","0.54000","0.00000","0.21500","0.03589"
"0.28813","9.32609","0.43578","0.72000","0.00000","0.28813","0.04810"
"0.36104","11.20642","0.52364","0.90000","0.00000","0.36104","0.06027"
"0.43292","13.03325","0.60901","1.08000","0.00000","0.43292","0.07227"
"0.50458","14.89065","0.69580","1.26000","0.00000","0.50458","0.08424"
"0.57667","16.71922","0.78124","1.44000","0.00000","0.57667","0.09627"
"0.64896","18.61258","0.86971","1.62000","0.00000","0.64896","0.10834"
"0.72125","20.57182","0.96126","1.80000","0.00000","0.72125","0.12041"
"0.79271","22.58497","1.05533","1.98000","0.00000","0.79271","0.13234"
"0.86479","24.70379","1.15434","2.16000","0.00000","0.86479","0.14437"
"0.93729","26.95590","1.25957","2.34000","0.00000","0.93729","0.15648"
"1.00896","29.29323","1.36879","2.52000","0.00000","1.00896","0.16844"
"1.08063","31.86793","1.48910","2.70000","0.00000","1.08063","0.18040"
"1.15313","34.67428","1.62023","2.88000","0.00000","1.15313","0.19251"
"1.20688","36.95043","1.72659","3.04600","0.00000","1.20688","0.20148"
"1.20667","34.87796","1.62975","3.22600","0.00000","1.20667","0.20145"
"1.20563","33.92821","1.58537","3.40600","0.00000","1.20563","0.20127"
"1.20375","33.18336","1.55056","3.58600","0.00000","1.20375","0.20096"
"1.20167","32.58743","1.52272","3.76600","0.00000","1.20167","0.20061"
"1.20021","32.12209","1.50097","3.94600","0.00000","1.20021","0.20037"
"1.19938","31.78297","1.48513","4.12600","0.00000","1.19938","0.20023"
"1.19875","31.53208","1.47340","4.30600","0.00000","1.19875","0.20013"
"1.19854","31.30696","1.46288","4.48600","0.00000","1.19854","0.20009"
"1.19854","31.13441","1.45482","4.66600","0.00000","1.19854","0.20009"
"1.19833","30.97787","1.44751","4.84600","0.00000","1.19833","0.20006"
"1.19833","30.82382","1.44031","5.02600","0.00000","1.19833","0.20006"
"1.19833","30.68601","1.43387","5.20600","0.00000","1.19833","0.20006"
"1.19833","30.56465","1.42820","5.38600","0.00000","1.19833","0.20006"
"1.19833","30.45305","1.42298","5.56600","0.00000","1.19833","0.20006"
"1.19833","30.33645","1.41754","5.74600","0.00000","1.19833","0.20006"
"1.19833","30.23444","1.41277","5.92600","0.00000","1.19833","0.20006"
"1.19833","30.13798","1.40826","6.10600","0.00000","1.19833","0.20006"
"1.19813","30.04279","1.40381","6.28600","0.00000","1.19813","0.20002"
"1.19813","29.96121","1.40000","6.46600","0.00000","1.19813","0.20002"
"1.19813","29.87313","1.39589","6.64600","0.00000","1.19813","0.20002"
"1.19813","29.80068","1.39250","6.82600","0.00000","1.19813","0.20002"
"1.19813","29.73272","1.38932","7.00600","0.00000","1.19813","0.20002"
"1.19813","29.65824","1.38584","7.18600","0.00000","1.19813","0.20002"
"1.19813","29.59619","1.38295","7.36600","0.00000","1.19813","0.20002"
"1.19813","29.53941","1.38029","7.54600","0.00000","1.19813","0.20002"
"1.19813","29.46291","1.37672","7.72600","0.00000","1.19813","0.20002"
"1.19813","29.41439","1.37445","7.90600","0.00000","1.19813","0.20002"
"1.19813","29.35956","1.37189","8.08600","0.00000","1.19813","0.20002"
"1.19813","29.30618","1.36939","8.26600","0.00000","1.19813","0.20002"
"1.19813","29.25131","1.36683","8.44600","0.00000","1.19813","0.20002"
"1.19813","29.20791","1.36480","8.62600","0.00000","1.19813","0.20002"
"1.19813","29.16054","1.36259","8.80600","0.00000","1.19813","0.20002"
"1.19813","29.11054","1.36025","8.98600","0.00000","1.19813","0.20002"
"1.19813","29.06731","1.35823","9.16600","0.00000","1.19813","0.20002"
"1.19854","29.05790","1.35779","9.34600","0.00000","1.19854","0.20009"
"1.19854","29.00790","1.35546","9.52600","0.00000","1.19854","0.20009"
"1.19854","28.96462","1.35343","9.70600","0.00000","1.19854","0.20009"
"1.19854","28.91949","1.35132","9.88600","0.00000","1.19854","0.20009"
"1.19854","28.88964","1.34993","10.06600","0.00000","1.19854","0.20009"
"1.19854","28.85046","1.34810","10.24600","0.00000","1.19854","0.20009"
"1.19854","28.80578","1.34601","10.42600","0.00000","1.19854","0.20009"
"1.19854","28.77349","1.34450","10.60600","0.00000","1.19854","0.20009"
"1.19854","28.73207","1.34257","10.78600","0.00000","1.19854","0.20009"
"1.19854","28.70376","1.34124","10.96600","0.00000","1.19854","0.20009"
"1.19854","28.66071","1.33923","11.14600","0.00000","1.19854","0.20009"
"1.19854","28.64551","1.33852","11.32600","0.00000","1.19854","0.20009"
"1.19854","28.61158","1.33694","11.50600","0.00000","1.19854","0.20009"
"1.19854","28.57159","1.33507","11.68600","0.00000","1.19854","0.20009"
"1.19854","28.53651","1.33343","11.86600","0.00000","1.19854","0.20009"
"1.19854","28.50458","1.33194","12.04600","0.00000","1.19854","0.20009"
"1.19854","28.47938","1.33076","12.22600","0.00000","1.19854","0.20009"
"1.19854","28.45684","1.32971","12.40600","0.00000","1.19854","0.20009"
"1.19854","28.42791","1.32835","12.58600","0.00000","1.19854","0.20009"
"1.19854","28.39394","1.32677","12.76600","0.00000","1.19854","0.20009"
"1.19854","28.37456","1.32586","12.94600","0.00000","1.19854","0.20009"
"1.19854","28.34628","1.32454","13.12600","0.00000","1.19854","0.20009"
"1.19854","28.32555","1.32357","13.30600","0.00000","1.19854","0.20009"
"1.19854","28.29524","1.32216","13.48600","0.00000","1.19854","0.20009"
"1.19854","28.27523","1.32122","13.66600","0.00000","1.19854","0.20009"
"1.19854","28.25236","1.32015","13.84600","0.00000","1.19854","0.20009"
"1.19854","28.21945","1.31861","14.02600","0.00000","1.19854","0.20009"
"1.19854","28.20185","1.31779","14.20600","0.00000","1.19854","0.20009"
"1.19854","28.18600","1.31705","14.38600","0.00000","1.19854","0.20009"
"1.19854","28.15335","1.31553","14.56600","0.00000","1.19854","0.20009"
"1.19854","28.13166","1.31451","14.74600","0.00000","1.19854","0.20009"
"1.19854","28.11457","1.31371","14.92600","0.00000","1.19854","0.20009"
"1.19854","28.09621","1.31286","15.10600","0.00000","1.19854","0.20009"
"1.19854","28.06614","1.31145","15.28600","0.00000","1.19854","0.20009"
"1.19854","28.05426","1.31090","15.46600","0.00000","1.19854","0.20009"
"1.19854","28.02805","1.30967","15.64600","0.00000","1.19854","0.20009"
"1.19854","28.00499","1.30859","15.82600","0.00000","1.19854","0.20009"
"1.19854","27.98884","1.30784","16.00600","0.00000","1.19854","0.20009"
"1.19854","27.97036","1.30697","16.18600","0.00000","1.19854","0.20009"
"1.19854","27.95203","1.30612","16.36600","0.00000","1.19854","0.20009"
"1.19854","27.93526","1.30533","16.54600","0.00000","1.19854","0.20009"
"1.19854","27.91650","1.30446","16.72600","0.00000","1.19854","0.20009"
"1.19854","27.90255","1.30381","16.90600","0.00000","1.19854","0.20009"
"1.19854","27.88011","1.30276","17.08600","0.00000","1.19854","0.20009"
"1.19854","27.86700","1.30215","17.26600","0.00000","1.19854","0.20009"
"1.19854","27.85348","1.30151","17.44600","0.00000","1.19854","0.20009"
"1.19854","27.82835","1.30034","17.62600","0.00000","1.19854","0.20009"
"1.19854","27.81898","1.29990","17.80600","0.00000","1.19854","0.20009"
"1.19854","27.79775","1.29891","17.98600","0.00000","1.19854","0.20009"
"1.19854","27.78524","1.29832","18.16600","0.00000","1.19854","0.20009"
"1.19854","27.76213","1.29724","18.34600","0.00000","1.19854","0.20009"
"1.19854","27.74623","1.29650","18.52600","0.00000","1.19854","0.20009"
"1.19854","27.72444","1.29548","18.70600","0.00000","1.19854","0.20009"
"1.19854","27.71490","1.29504","18.88600","0.00000","1.19854","0.20009"
"1.19854","27.70055","1.29437","19.06600","0.00000","1.19854","0.20009"
"1.19854","27.68584","1.29368","19.24600","0.00000","1.19854","0.20009"
"1.19854","27.67443","1.29315","19.42600","0.00000","1.19854","0.20009"
"1.19854","27.65508","1.29224","19.60600","0.00000","1.19854","0.20009"
"1.19854","27.64348","1.29170","19.78600","0.00000","1.19854","0.20009"
"1.19854","27.62310","1.29075","19.96600","0.00000","1.19854","0.20009"
"1.19854","27.60962","1.29012","20.14600","0.00000","1.19854","0.20009"
"1.19854","27.59623","1.28949","20.32600","0.00000","1.19854","0.20009"
"1.19854","27.59218","1.28930","20.50600","0.00000","1.19854","0.20009"
"1.19854","27.57436","1.28847","20.68600","0.00000","1.19854","0.20009"
"1.19854","27.55689","1.28765","20.86600","0.00000","1.19854","0.20009"
"1.19854","27.54844","1.28726","21.04600","0.00000","1.19854","0.20009"
"1.19854","27.53782","1.28676","21.22600","0.00000","1.19854","0.20009"
"1.19854","27.51504","1.28570","21.40600","0.00000","1.19854","0.20009"
"1.19854","27.50390","1.28518","21.58600","0.00000","1.19854","0.20009"
"1.19854","27.49596","1.28481","21.76600","0.00000","1.19854","0.20009"
"1.19854","27.48389","1.28424","21.94600","0.00000","1.19854","0.20009"
"1.19854","27.46851","1.28352","22.12600","0.00000","1.19854","0.20009"
"1.19854","27.45327","1.28281","22.30600","0.00000","1.19854","0.20009"
"1.19854","27.44265","1.28232","22.48600","0.00000","1.19854","0.20009"
"1.19854","27.43620","1.28201","22.66600","0.00000","1.19854","0.20009"
"1.19854","27.41970","1.28124","22.84600","0.00000","1.19854","0.20009"
"1.19854","27.40730","1.28066","23.02600","0.00000","1.19854","0.20009"
"1.19854","27.40132","1.28038","23.20600","0.00000","1.19854","0.20009"
"1.19854","27.38732","1.27973","23.38600","0.00000","1.19854","0.20009"
"1.19854","27.37152","1.27899","23.56600","0.00000","1.19854","0.20009"
"1.19854","27.35679","1.27830","23.74600","0.00000","1.19854","0.20009"
"1.19854","27.34732","1.27786","23.92600","0.00000","1.19854","0.20009"
"1.19854","27.33779","1.27742","24.10600","0.00000","1.19854","0.20009"
"1.19854","27.32869","1.27699","24.28600","0.00000","1.19854","0.20009"
"1.19854","27.32211","1.27668","24.46600","0.00000","1.19854","0.20009"
"1.19854","27.31173","1.27620","24.64600","0.00000","1.19854","0.20009"
"1.19854","27.29937","1.27562","24.82600","0.00000","1.19854","0.20009"
"1.19854","27.28685","1.27504","25.00600","0.00000","1.19854","0.20009"
"1.19854","27.27958","1.27470","25.18600","0.00000","1.19854","0.20009"
"1.19854","27.26632","1.27408","25.36600","0.00000","1.19854","0.20009"
"1.19854","27.24835","1.27324","25.54600","0.00000","1.19854","0.20009"
"1.19854","27.24551","1.27310","25.72600","0.00000","1.19854","0.20009"
"1.19854","27.22651","1.27222","25.90600","0.00000","1.19854","0.20009"
"1.19854","27.22612","1.27220","26.08600","0.00000","1.19854","0.20009"
"1.19854","27.21301","1.27159","26.26600","0.00000","1.19854","0.20009"
"1.19854","27.20574","1.27125","26.44600","0.00000","1.19854","0.20009"
"1.19854","27.19090","1.27055","26.62600","0.00000","1.19854","0.20009"
"1.19854","27.18860","1.27045","26.80600","0.00000","1.19854","0.20009"
"1.19854","27.17241","1.26969","26.98600","0.00000","1.19854","0.20009"
"1.19854","27.16433","1.26931","27.16600","0.00000","1.19854","0.20009"
"1.19854","27.14931","1.26861","27.34600","0.00000","1.19854","0.20009"
"1.19854","27.14355","1.26834","27.52600","0.00000","1.19854","0.20009"
"1.19854","27.14159","1.26825","27.70600","0.00000","1.19854","0.20009"
"1.19854","27.13173","1.26779","27.88600","0.00000","1.19854","0.20009"
"1.19854","27.12793","1.26761","28.06600","0.00000","1.19854","0.20009"
"1.19854","27.11165","1.26685","28.24600","0.00000","1.19854","0.20009"
"1.19854","27.10665","1.26662","28.42600","0.00000","1.19854","0.20009"
"1.19854","27.09449","1.26605","28.60600","0.00000","1.19854","0.20009"
"1.19854","27.08452","1.26558","28.78600","0.00000","1.19854","0.20009"
"1.19854","27.07049","1.26493","28.96600","0.00000","1.19854","0.20009"
"1.19854","27.06182","1.26452","29.14600","0.00000","1.19854","0.20009"
"1.19854","27.05694","1.26429","29.32600","0.00000","1.19854","0.20009"
"1.19854","27.04373","1.26368","29.50600","0.00000","1.19854","0.20009"
"1.19854","27.04536","1.26375","29.68600","0.00000","1.19854","0.20009"
"1.19854","27.03534","1.26328","29.86600","0.00000","1.19854","0.20009"
"1.19854","27.02855","1.26297","30.04600","0.00000","1.19854","0.20009"
"1.19854","27.02073","1.26260","30.22600","0.00000","1.19854","0.20009"
"1.19854","27.01338","1.26226","30.40600","0.00000","1.19854","0.20009"
"1.19854","27.00244","1.26175","30.58600","0.00000","1.19854","0.20009"
"1.19854","26.98872","1.26111","30.76600","0.00000","1.19854","0.20009"
"1.19854","26.97944","1.26067","30.94600","0.00000","1.19854","0.20009"
"1.19854","26.96756","1.26012","31.12600","0.00000","1.19854","0.20009"
"1.19854","26.97121","1.26029","31.30600","0.00000","1.19854","0.20009"
"1.19854","26.96165","1.25984","31.48600","0.00000","1.19854","0.20009"
"1.19854","26.94838","1.25922","31.66600","0.00000","1.19854","0.20009"
"1.19854","26.94733","1.25917","31.84600","0.00000","1.19854","0.20009"
"1.19854","26.93448","1.25857","32.02600","0.00000","1.19854","0.20009"
"1.19854","26.92654","1.25820","32.20600","0.00000","1.19854","0.20009"
"1.19854","26.92003","1.25790","32.38600","0.00000","1.19854","0.20009"
"1.19854","26.91556","1.25769","32.56600","0.00000","1.19854","0.20009"
"1.19854","26.90322","1.25711","32.74600","0.00000","1.19854","0.20009"
"1.19854","26.89666","1.25680","32.92600","0.00000","1.19854","0.20009"
"1.19854","26.88356","1.25619","33.10600","0.00000","1.19854","0.20009"
"1.19854","26.88327","1.25618","33.28600","0.00000","1.19854","0.20009"
"1.19854","26.88278","1.25616","33.46600","0.00000","1.19854","0.20009"
"1.19854","26.87341","1.25572","33.64600","0.00000","1.19854","0.20009"
"1.19854","26.85956","1.25507","33.82600","0.00000","1.19854","0.20009"
"1.19854","26.85051","1.25465","34.00600","0.00000","1.19854","0.20009"
"1.19854","26.84736","1.25450","34.18600","0.00000","1.19854","0.20009"
"1.19854","26.84345","1.25432","34.36600","0.00000","1.19854","0.20009"
"1.19854","26.83012","1.25369","34.54600","0.00000","1.19854","0.20009"
"1.19854","26.82686","1.25354","34.72600","0.00000","1.19854","0.20009"
"1.19854","26.81852","1.25315","34.90600","0.00000","1.19854","0.20009"
"1.19854","26.81263","1.25288","35.08600","0.00000","1.19854","0.20009"
"1.19854","26.80772","1.25265","35.26600","0.00000","1.19854","0.20009"
"1.19854","26.79869","1.25223","35.44600","0.00000","1.19854","0.20009"
"1.19854","26.79580","1.25209","35.62600","0.00000","1.19854","0.20009"
"1.19854","26.78476","1.25157","35.80600","0.00000","1.19854","0.20009"
"1.19854","26.77913","1.25131","35.98600","0.00000","1.19854","0.20009"
"1.19854","26.77390","1.25107","36.16600","0.00000","1.19854","0.20009"
"1.19854","26.76911","1.25084","36.34600","0.00000","1.19854","0.20009"
"1.19854","26.75945","1.25039","36.52600","0.00000","1.19854","0.20009"
"1.19854","26.75630","1.25025","36.70600","0.00000","1.19854","0.20009"
"1.19854","26.74733","1.24983","36.88600","0.00000","1.19854","0.20009"
"1.19854","26.74273","1.24961","37.06600","0.00000","1.19854","0.20009"
"1.19854","26.73705","1.24935","37.24600","0.00000","1.19854","0.20009"
"1.19854","26.72926","1.24898","37.42600","0.00000","1.19854","0.20009"
"1.19854","26.72984","1.24901","37.60600","0.00000","1.19854","0.20009"
"1.19854","26.71848","1.24848","37.78600","0.00000","1.19854","0.20009"
"1.19854","26.71066","1.24811","37.96600","0.00000","1.19854","0.20009"
"1.19854","26.70045","1.24764","38.14600","0.00000","1.19854","0.20009"
"1.19854","26.69859","1.24755","38.32600","0.00000","1.19854","0.20009"
"1.19854","26.69143","1.24721","38.50600","0.00000","1.19854","0.20009"
"1.19854","26.68688","1.24700","38.68600","0.00000","1.19854","0.20009"
"1.19854","26.67148","1.24628","38.86600","0.00000","1.19854","0.20009"
"1.19854","26.68281","1.24681","39.04600","0.00000","1.19854","0.20009"
"1.19854","26.66115","1.24580","39.22600","0.00000","1.19854","0.20009"
"1.19854","26.66628","1.24604","39.40600","0.00000","1.19854","0.20009"
"1.19854","26.65802","1.24565","39.58600","0.00000","1.19854","0.20009"
"1.19854","26.65242","1.24539","39.76600","0.00000","1.19854","0.20009"
"1.19854","26.64374","1.24499","39.94600","0.00000","1.19854","0.20009"
"1.19854","26.63756","1.24470","40.12600","0.00000","1.19854","0.20009"
"1.19854","26.63733","1.24469","40.30600","0.00000","1.19854","0.20009"
"1.19854","26.62390","1.24406","40.48600","0.00000","1.19854","0.20009"
"1.19854","26.62055","1.24390","40.66600","0.00000","1.19854","0.20009"
"1.19854","26.60460","1.24316","40.84600","0.00000","1.19854","0.20009"
"1.19854","26.60799","1.24332","41.02600","0.00000","1.19854","0.20009"
"1.19854","26.60296","1.24308","41.20600","0.00000","1.19854","0.20009"
"1.19854","26.60209","1.24304","41.38600","0.00000","1.19854","0.20009"
"1.19854","26.58941","1.24245","41.56600","0.00000","1.19854","0.20009"
"1.19854","26.59176","1.24256","41.74600","0.00000","1.19854","0.20009"
"1.19854","26.58800","1.24238","41.92600","0.00000","1.19854","0.20009"
"1.19854","26.58062","1.24204","42.10600","0.00000","1.19854","0.20009"
"1.19854","26.57659","1.24185","42.28600","0.00000","1.19854","0.20009"
"1.19854","26.55710","1.24094","42.46600","0.00000","1.19854","0.20009"
"1.19854","26.55304","1.24075","42.64600","0.00000","1.19854","0.20009"
"1.19854","26.55472","1.24083","42.82600","0.00000","1.19854","0.20009"
"1.19854","26.54826","1.24052","43.00600","0.00000","1.19854","0.20009"
"1.19854","26.55750","1.24096","43.18600","0.00000","1.19854","0.20009"
"1.19854","26.54157","1.24021","43.36600","0.00000","1.19854","0.20009"
"1.19854","26.53608","1.23995","43.54600","0.00000","1.19854","0.20009"
"1.19854","26.52865","1.23961","43.72600","0.00000","1.19854","0.20009"
"1.19854","26.52236","1.23931","43.90600","0.00000","1.19854","0.20009"
"1.19854","26.51608","1.23902","44.08600","0.00000","1.19854","0.20009"
"1.19854","26.51983","1.23920","44.26600","0.00000","1.19854","0.20009"
"1.19854","26.51277","1.23887","44.44600","0.00000","1.19854","0.20009"
"1.19854","26.50218","1.23837","44.62600","0.00000","1.19854","0.20009"
"1.19854","26.49279","1.23793","44.80600","0.00000","1.19854","0.20009"
"1.19854","26.49193","1.23789","44.98600","0.00000","1.19854","0.20009"
"1.19854","26.48381","1.23751","45.16600","0.00000","1.19854","0.20009"
"1.19854","26.48429","1.23754","45.34600","0.00000","1.19854","0.20009"
"1.19854","26.48090","1.23738","45.52600","0.00000","1.19854","0.20009"
"1.19854","26.47442","1.23707","45.70600","0.00000","1.19854","0.20009"
"1.19854","26.46493","1.23663","45.88600","0.00000","1.19854","0.20009"
"1.19854","26.46517","1.23664","46.06600","0.00000","1.19854","0.20009"
"1.19854","26.46398","1.23659","46.24600","0.00000","1.19854","0.20009"
"1.19854","26.45398","1.23612","46.42600","0.00000","1.19854","0.20009"
"1.19854","26.45340","1.23609","46.60600","0.00000","1.19854","0.20009"
"1.19854","26.44797","1.23584","46.78600","0.00000","1.19854","0.20009"
"1.19854","26.44033","1.23548","46.96600","0.00000","1.19854","0.20009"
"1.19854","26.42979","1.23499","47.14600","0.00000","1.19854","0.20009"
"1.19854","26.43176","1.23508","47.32600","0.00000","1.19854","0.20009"
"1.19854","26.42842","1.23492","47.50600","0.00000","1.19854","0.20009"
"1.19854","26.41642","1.23436","47.68600","0.00000","1.19854","0.20009"
"1.19854","26.42146","1.23460","47.86600","0.00000","1.19854","0.20009"
"1.19854","26.40773","1.23396","48.04600","0.00000","1.19854","0.20009"
"1.19854","26.40771","1.23396","48.22600","0.00000","1.19854","0.20009"
"1.19854","26.39441","1.23333","48.40600","0.00000","1.19854","0.20009"
"1.19854","26.39868","1.23353","48.58600","0.00000","1.19854","0.20009"
"1.19854","26.39650","1.23343","48.76600","0.00000","1.19854","0.20009"
"1.19854","26.39096","1.23317","48.94600","0.00000","1.19854","0.20009"
"1.19854","26.38504","1.23290","49.12600","0.00000","1.19854","0.20009"
"1.19854","26.38053","1.23269","49.30600","0.00000","1.19854","0.20009"
"1.19854","26.37002","1.23220","49.48600","0.00000","1.19854","0.20009"
"1.19854","26.37124","1.23225","49.66600","0.00000","1.19854","0.20009"
"1.19854","26.36504","1.23196","49.84600","0.00000","1.19854","0.20009"
"1.19854","26.36321","1.23188","50.02600","0.00000","1.19854","0.20009"
"1.19854","26.36320","1.23188","50.20600","0.00000","1.19854","0.20009"
"1.19854","26.35637","1.23156","50.38600","0.00000","1.19854","0.20009"
"1.19854","26.35405","1.23145","50.56600","0.00000","1.19854","0.20009"
"1.19854","26.35032","1.23127","50.74600","0.00000","1.19854","0.20009"
"1.19854","26.33983","1.23078","50.92600","0.00000","1.19854","0.20009"
"1.19854","26.32914","1.23029","51.10600","0.00000","1.19854","0.20009"
"1.19854","26.33018","1.23033","51.28600","0.00000","1.19854","0.20009"
"1.19854","26.32310","1.23000","51.46600","0.00000","1.19854","0.20009"
"1.19854","26.31878","1.22980","51.64600","0.00000","1.19854","0.20009"
"1.19854","26.31758","1.22975","51.82600","0.00000","1.19854","0.20009"
"1.19854","26.31396","1.22958","52.00600","0.00000","1.19854","0.20009"
"1.19854","26.31845","1.22979","52.18600","0.00000","1.19854","0.20009"
"1.19854","26.30866","1.22933","52.36600","0.00000","1.19854","0.20009"
"1.19854","26.29846","1.22885","52.54600","0.00000","1.19854","0.20009"
"1.19854","26.29595","1.22873","52.72600","0.00000","1.19854","0.20009"
"1.19854","26.28988","1.22845","52.90600","0.00000","1.19854","0.20009"
"1.19854","26.28898","1.22841","53.08600","0.00000","1.19854","0.20009"
"1.19854","26.28679","1.22831","53.26600","0.00000","1.19854","0.20009"
"1.19854","26.27494","1.22775","53.44600","0.00000","1.19854","0.20009"
"1.19854","26.27785","1.22789","53.62600","0.00000","1.19854","0.20009"
"1.19854","26.27342","1.22768","53.80600","0.00000","1.19854","0.20009"
"1.19854","26.26650","1.22736","53.98600","0.00000","1.19854","0.20009"
"1.19854","26.26582","1.22733","54.16600","0.00000","1.19854","0.20009"
"1.19854","26.26201","1.22715","54.34600","0.00000","1.19854","0.20009"
"1.19854","26.24924","1.22655","54.52600","0.00000","1.19854","0.20009"
"1.19854","26.25278","1.22672","54.70600","0.00000","1.19854","0.20009"
"1.19854","26.24865","1.22652","54.88600","0.00000","1.19854","0.20009"
"1.19854","26.24527","1.22637","55.06600","0.00000","1.19854","0.20009"
"1.19854","26.24154","1.22619","55.24600","0.00000","1.19854","0.20009"
"1.19854","26.23838","1.22604","55.42600","0.00000","1.19854","0.20009"
"1.19854","26.23077","1.22569","55.60600","0.00000","1.19854","0.20009"
"1.19854","26.22341","1.22534","55.78600","0.00000","1.19854","0.20009"
"1.19854","26.22492","1.22542","55.96600","0.00000","1.19854","0.20009"
"1.19854","26.21635","1.22501","56.14600","0.00000","1.19854","0.20009"
"1.19854","26.22101","1.22523","56.32600","0.00000","1.19854","0.20009"
"1.19854","26.21967","1.22517","56.50600","0.00000","1.19854","0.20009"
"1.19854","26.21210","1.22482","56.68600","0.00000","1.19854","0.20009"
"1.19854","26.19538","1.22404","56.86600","0.00000","1.19854","0.20009"
"1.19854","26.19984","1.22424","57.04600","0.00000","1.19854","0.20009"
"1.19854","26.19444","1.22399","57.22600","0.00000","1.19854","0.20009"
"1.19854","26.19121","1.22384","57.40600","0.00000","1.19854","0.20009"
"1.19854","26.18600","1.22360","57.58600","0.00000","1.19854","0.20009"
"1.19854","26.18107","1.22337","57.76600","0.00000","1.19854","0.20009"
"1.19854","26.18448","1.22353","57.94600","0.00000","1.19854","0.20009"
"1.19854","26.18015","1.22332","58.12600","0.00000","1.19854","0.20009"
"1.19854","26.17083","1.22289","58.30600","0.00000","1.19854","0.20009"
"1.19854","26.17101","1.22290","58.48600","0.00000","1.19854","0.20009"
"1.19854","26.17402","1.22304","58.66600","0.00000","1.19854","0.20009"
"1.19854","26.16562","1.22264","58.84600","0.00000","1.19854","0.20009"
"1.19854","26.15301","1.22206","59.02600","0.00000","1.19854","0.20009"
"1.19854","26.16096","1.22243","59.20600","0.00000","1.19854","0.20009"
"1.19854","26.15564","1.22218","59.38600","0.00000","1.19854","0.20009"
"1.19854","26.14920","1.22188","59.56600","0.00000","1.19854","0.20009"
"1.19854","26.14779","1.22181","59.74600","0.00000","1.19854","0.20009"
"1.19854","26.13595","1.22126","59.92600","0.00000","1.19854","0.20009"
"1.19854","26.13390","1.22116","60.10600","0.00000","1.19854","0.20009"
"1.19854","26.13503","1.22122","60.28600","0.00000","1.19854","0.20009"
"1.19854","26.13558","1.22124","60.46600","0.00000","1.19854","0.20009"
"1.19854","26.12957","1.22096","60.64600","0.00000","1.19854","0.20009"
"1.19854","26.12351","1.22068","60.82600","0.00000","1.19854","0.20009"
"1.19854","26.13046","1.22100","61.00600","0.00000","1.19854","0.20009"
"1.19854","26.11860","1.22045","61.18600","0.00000","1.19854","0.20009"
"1.19854","26.11918","1.22047","61.36600","0.00000","1.19854","0.20009"
"1.19854","26.10780","1.21994","61.54600","0.00000","1.19854","0.20009"
"1.19854","26.10698","1.21990","61.72600","0.00000","1.19854","0.20009"
"1.19854","26.10021","1.21959","61.90600","0.00000","1.19854","0.20009"
"1.19854","26.10337","1.21974","62.08600","0.00000","1.19854","0.20009"
"1.19854","26.09869","1.21952","62.26600","0.00000","1.19854","0.20009"
"1.19854","26.09595","1.21939","62.44600","0.00000","1.19854","0.20009"
"1.19854","26.08263","1.21877","62.62600","0.00000","1.19854","0.20009"
"1.19854","26.09205","1.21921","62.80600","0.00000","1.19854","0.20009"
"1.19854","26.07822","1.21856","62.98600","0.00000","1.19854","0.20009"
"1.19854","26.07769","1.21854","63.16600","0.00000","1.19854","0.20009"
"1.19854","26.08184","1.21873","63.34600","0.00000","1.19854","0.20009"
"1.19854","26.07254","1.21830","63.52600","0.00000","1.19854","0.20009"
"1.19854","26.06882","1.21812","63.70600","0.00000","1.19854","0.20009"
"1.19854","26.07532","1.21842","63.88600","0.00000","1.19854","0.20009"
"1.19854","26.06131","1.21777","64.06600","0.00000","1.19854","0.20009"
"1.19854","26.06484","1.21794","64.24600","0.00000","1.19854","0.20009"
"1.19854","26.05811","1.21762","64.42600","0.00000","1.19854","0.20009"
"1.19854","26.05297","1.21738","64.60600","0.00000","1.19854","0.20009"
"1.19854","26.05571","1.21751","64.78600","0.00000","1.19854","0.20009"
"1.19854","26.03833","1.21670","64.96600","0.00000","1.19854","0.20009"
"1.19854","26.04196","1.21687","65.14600","0.00000","1.19854","0.20009"
"1.19854","26.04156","1.21685","65.32600","0.00000","1.19854","0.20009"
"1.19854","26.03549","1.21656","65.50600","0.00000","1.19854","0.20009"
"1.19854","26.04348","1.21694","65.68600","0.00000","1.19854","0.20009"
"1.19854","26.03051","1.21633","65.86600","0.00000","1.19854","0.20009"
"1.19854","26.02365","1.21601","66.04600","0.00000","1.19854","0.20009"
"1.19854","26.02147","1.21591","66.22600","0.00000","1.19854","0.20009"
"1.19854","26.02559","1.21610","66.40600","0.00000","1.19854","0.20009"
"1.19854","26.01681","1.21569","66.58600","0.00000","1.19854","0.20009"
"1.19854","26.01971","1.21583","66.76600","0.00000","1.19854","0.20009"
"1.19854","26.01247","1.21549","66.94600","0.00000","1.19854","0.20009"
"1.19854","26.01356","1.21554","67.12600","0.00000","1.19854","0.20009"
"1.19854","26.00563","1.21517","67.30600","0.00000","1.19854","0.20009"
"1.19854","26.00242","1.21502","67.48600","0.00000","1.19854","0.20009"
"1.19854","26.00020","1.21491","67.66600","0.00000","1.19854","0.20009"
"1.19854","25.99778","1.21480","67.84600","0.00000","1.19854","0.20009"
"1.19854","25.99991","1.21490","68.02600","0.00000","1.19854","0.20009"
"1.19854","25.99844","1.21483","68.20600","0.00000","1.19854","0.20009"
"1.19854","25.98393","1.21415","68.38600","0.00000","1.19854","0.20009"
"1.19854","25.98705","1.21430","68.56600","0.00000","1.19854","0.20009"
"1.19854","25.98922","1.21440","68.74600","0.00000","1.19854","0.20009"
"1.19854","25.98817","1.21435","68.92600","0.00000","1.19854","0.20009"
"1.19854","25.97879","1.21391","69.10600","0.00000","1.19854","0.20009"
"1.19854","25.97605","1.21379","69.28600","0.00000","1.19854","0.20009"
"1.19854","25.97244","1.21362","69.46600","0.00000","1.19854","0.20009"
"1.19854","25.96880","1.21345","69.64600","0.00000","1.19854","0.20009"
"1.19854","25.96146","1.21310","69.82600","0.00000","1.19854","0.20009"
"1.19854","25.95455","1.21278","70.00600","0.00000","1.19854","0.20009"
"1.19854","25.95634","1.21287","70.18600","0.00000","1.19854","0.20009"
"1.19854","25.95888","1.21298","70.36600","0.00000","1.19854","0.20009"
"1.19854","25.95667","1.21288","70.54600","0.00000","1.19854","0.20009"
"1.19854","25.95022","1.21258","70.72600","0.00000","1.19854","0.20009"
"1.19854","25.94639","1.21240","70.90600","0.00000","1.19854","0.20009"
"1.19854","25.94265","1.21223","71.08600","0.00000","1.19854","0.20009"
"1.19854","25.94028","1.21211","71.26600","0.00000","1.19854","0.20009"
"1.19854","25.93421","1.21183","71.44600","0.00000","1.19854","0.20009"
"1.19854","25.94009","1.21211","71.62600","0.00000","1.19854","0.20009"
"1.19854","25.93823","1.21202","71.80600","0.00000","1.19854","0.20009"
"1.19854","25.93856","1.21203","71.98600","0.00000","1.19854","0.20009"
"1.19854","25.92430","1.21137","72.16600","0.00000","1.19854","0.20009"
"1.19854","25.92187","1.21125","72.34600","0.00000","1.19854","0.20009"
"1.19854","25.92052","1.21119","72.52600","0.00000","1.19854","0.20009"
"1.19854","25.92525","1.21141","72.70600","0.00000","1.19854","0.20009"
"1.19854","25.91278","1.21083","72.88600","0.00000","1.19854","0.20009"
"1.19854","25.90794","1.21060","73.06600","0.00000","1.19854","0.20009"
"1.19854","25.92111","1.21122","73.24600","0.00000","1.19854","0.20009"
"1.19854","25.91303","1.21084","73.42600","0.00000","1.19854","0.20009"
"1.19854","25.90674","1.21055","73.60600","0.00000","1.19854","0.20009"
"1.19854","25.90367","1.21040","73.78600","0.00000","1.19854","0.20009"
"1.19854","25.90520","1.21048","73.96600","0.00000","1.19854","0.20009"
"1.19854","25.89972","1.21022","74.14600","0.00000","1.19854","0.20009"
"1.19854","25.89356","1.20993","74.32600","0.00000","1.19854","0.20009"
"1.19854","25.89402","1.20995","74.50600","0.00000","1.19854","0.20009"
"1.19854","25.88779","1.20966","74.68600","0.00000","1.19854","0.20009"
"1.19854","25.89023","1.20978","74.86600","0.00000","1.19854","0.20009"
"1.19854","25.88068","1.20933","75.04600","0.00000","1.19854","0.20009"
"1.19854","25.88377","1.20947","75.22600","0.00000","1.19854","0.20009"
"1.19854","25.87633","1.20913","75.40600","0.00000","1.19854","0.20009"
"1.19854","25.88176","1.20938","75.58600","0.00000","1.19854","0.20009"
"1.19854","25.87763","1.20919","75.76600","0.00000","1.19854","0.20009"
"1.19854","25.87457","1.20904","75.94600","0.00000","1.19854","0.20009"
"1.19854","25.87214","1.20893","76.12600","0.00000","1.19854","0.20009"
"1.19854","25.86788","1.20873","76.30600","0.00000","1.19854","0.20009"
"1.19854","25.86293","1.20850","76.48600","0.00000","1.19854","0.20009"
"1.19854","25.86499","1.20860","76.66600","0.00000","1.19854","0.20009"
"1.19854","25.86210","1.20846","76.84600","0.00000","1.19854","0.20009"
"1.19854","25.85493","1.20813","77.02600","0.00000","1.19854","0.20009"
"1.19854","25.84797","1.20780","77.20600","0.00000","1.19854","0.20009"
"1.19854","25.84680","1.20775","77.38600","0.00000","1.19854","0.20009"
"1.19854","25.85175","1.20798","77.56600","0.00000","1.19854","0.20009"
"1.19854","25.84067","1.20746","77.74600","0.00000","1.19854","0.20009"
"1.19854","25.84194","1.20752","77.92600","0.00000","1.19854","0.20009"
"1.19854","25.83915","1.20739","78.10600","0.00000","1.19854","0.20009"
"1.19854","25.84479","1.20765","78.28600","0.00000","1.19854","0.20009"
"1.19854","25.82923","1.20693","78.46600","0.00000","1.19854","0.20009"
"1.19854","25.82854","1.20689","78.64600","0.00000","1.19854","0.20009"
"1.19854","25.82273","1.20662","78.82600","0.00000","1.19854","0.20009"
"1.19854","25.82127","1.20655","79.00600","0.00000","1.19854","0.20009"
"1.19854","25.82060","1.20652","79.18600","0.00000","1.19854","0.20009"
"1.19854","25.81943","1.20647","79.36600","0.00000","1.19854","0.20009"
"1.19854","25.81808","1.20640","79.54600","0.00000","1.19854","0.20009"
"1.19854","25.82507","1.20673","79.72600","0.00000","1.19854","0.20009"
"1.19854","25.81642","1.20633","79.90600","0.00000","1.19854","0.20009"
"1.19854","25.80848","1.20596","80.08600","0.00000","1.19854","0.20009"
"1.19854","25.80576","1.20583","80.26600","0.00000","1.19854","0.20009"
"1.19854","25.80186","1.20565","80.44600","0.00000","1.19854","0.20009"
"1.19854","25.81027","1.20604","80.62600","0.00000","1.19854","0.20009"
"1.19854","25.79493","1.20532","80.80600","0.00000","1.19854","0.20009"
"1.19854","25.80591","1.20584","80.98600","0.00000","1.19854","0.20009"
"1.19854","25.79613","1.20538","81.16600","0.00000","1.19854","0.20009"
"1.19854","25.79534","1.20534","81.34600","0.00000","1.19854","0.20009"
"1.19854","25.78836","1.20502","81.52600","0.00000","1.19854","0.20009"
"1.19854","25.78995","1.20509","81.70600","0.00000","1.19854","0.20009"
"1.19854","25.78890","1.20504","81.88600","0.00000","1.19854","0.20009"
"1.19854","25.78616","1.20491","82.06600","0.00000","1.19854","0.20009"
"1.19854","25.78016","1.20463","82.24600","0.00000","1.19854","0.20009"
"1.19854","25.78100","1.20467","82.42600","0.00000","1.19854","0.20009"
"1.19854","25.77530","1.20441","82.60600","0.00000","1.19854","0.20009"
"1.19854","25.77000","1.20416","82.78600","0.00000","1.19854","0.20009"
"1.19854","25.76405","1.20388","82.96600","0.00000","1.19854","0.20009"
"1.19854","25.77514","1.20440","83.14600","0.00000","1.19854","0.20009"
"1.19854","25.77065","1.20419","83.32600","0.00000","1.19854","0.20009"
"1.19854","25.76824","1.20408","83.50600","0.00000","1.19854","0.20009"
"1.19854","25.76146","1.20376","83.68600","0.00000","1.19854","0.20009"
"1.19854","25.75649","1.20353","83.86600","0.00000","1.19854","0.20009"
"1.19854","25.76279","1.20382","84.04600","0.00000","1.19854","0.20009"
"1.19854","25.75452","1.20344","84.22600","0.00000","1.19854","0.20009"
"1.19854","25.74679","1.20307","84.40600","0.00000","1.19854","0.20009"
"1.19854","25.74166","1.20283","84.58600","0.00000","1.19854","0.20009"
"1.19854","25.74949","1.20320","84.76600","0.00000","1.19854","0.20009"
"1.19854","25.74602","1.20304","84.94600","0.00000","1.19854","0.20009"
"1.19854","25.74991","1.20322","85.12600","0.00000","1.19854","0.20009"
"1.19854","25.74644","1.20306","85.30600","0.00000","1.19854","0.20009"
"1.19854","25.74179","1.20284","85.48600","0.00000","1.19854","0.20009"
"1.19854","25.73783","1.20266","85.66600","0.00000","1.19854","0.20009"
"1.19854","25.73754","1.20264","85.84600","0.00000","1.19854","0.20009"
"1.19854","25.72993","1.20229","86.02600","0.00000","1.19854","0.20009"
"1.19854","25.72850","1.20222","86.20600","0.00000","1.19854","0.20009"
"1.19854","25.72383","1.20200","86.38600","0.00000","1.19854","0.20009"
"1.19854","25.72709","1.20215","86.56600","0.00000","1.19854","0.20009"
"1.19854","25.72152","1.20189","86.74600","0.00000","1.19854","0.20009"
"1.19854","25.72416","1.20202","86.92600","0.00000","1.19854","0.20009"
"1.19854","25.72087","1.20186","87.10600","0.00000","1.19854","0.20009"
"1.19854","25.72032","1.20184","87.28600","0.00000","1.19854","0.20009"
"1.19854","25.71868","1.20176","87.46600","0.00000","1.19854","0.20009"
"1.19854","25.71098","1.20140","87.64600","0.00000","1.19854","0.20009"
"1.19854","25.70796","1.20126","87.82600","0.00000","1.19854","0.20009"
"1.19854","25.70502","1.20112","88.00600","0.00000","1.19854","0.20009"
"1.19854","25.70497","1.20112","88.18600","0.00000","1.19854","0.20009"
"1.19854","25.70212","1.20099","88.36600","0.00000","1.19854","0.20009"
"1.19854","25.70432","1.20109","88.54600","0.00000","1.19854","0.20009"
"1.19854","25.69839","1.20081","88.72600","0.00000","1.19854","0.20009"
"1.19854","25.69382","1.20060","88.90600","0.00000","1.19854","0.20009"
"1.19854","25.68513","1.20019","89.08600","0.00000","1.19854","0.20009"
"1.19854","25.68929","1.20039","89.26600","0.00000","1.19854","0.20009"
"1.19854","25.69643","1.20072","89.44600","0.00000","1.19854","0.20009"
"1.19854","25.69428","1.20062","89.62600","0.00000","1.19854","0.20009"
"1.19854","25.67970","1.19994","89.80600","0.00000","1.19854","0.20009"
"1.19854","25.68527","1.20020","89.98600","0.00000","1.19854","0.20009"
"1.19854","25.68502","1.20019","90.16600","0.00000","1.19854","0.20009"
"1.19854","25.67663","1.19980","90.34600","0.00000","1.19854","0.20009"
"1.19854","25.66768","1.19938","90.52600","0.00000","1.19854","0.20009"
"1.19854","25.67492","1.19972","90.70600","0.00000","1.19854","0.20009"
"1.19854","25.67589","1.19976","90.88600","0.00000","1.19854","0.20009"
"1.19854","25.67554","1.19974","91.06600","0.00000","1.19854","0.20009"
"1.19854","25.66942","1.19946","91.24600","0.00000","1.19854","0.20009"
"1.19854","25.66016","1.19903","91.42600","0.00000","1.19854","0.20009"
"1.19854","25.66386","1.19920","91.60600","0.00000","1.19854","0.20009"
"1.19854","25.65940","1.19899","91.78600","0.00000","1.19854","0.20009"
"1.19854","25.65368","1.19872","91.96600","0.00000","1.19854","0.20009"
"1.19854","25.65137","1.19861","92.14600","0.00000","1.19854","0.20009"
"1.19854","25.65218","1.19865","92.32600","0.00000","1.19854","0.20009"
"1.19854","25.65657","1.19886","92.50600","0.00000","1.19854","0.20009"
"1.19854","25.65439","1.19876","92.68600","0.00000","1.19854","0.20009"
"1.19854","25.65033","1.19857","92.86600","0.00000","1.19854","0.20009"
"1.19854","25.64970","1.19854","93.04600","0.00000","1.19854","0.20009"
"1.19854","25.65089","1.19859","93.22600","0.00000","1.19854","0.20009"
"1.19854","25.64778","1.19845","93.40600","0.00000","1.19854","0.20009"
"1.19854","25.63816","1.19800","93.58600","0.00000","1.19854","0.20009"
"1.19854","25.63947","1.19806","93.76600","0.00000","1.19854","0.20009"
"1.19854","25.63449","1.19783","93.94600","0.00000","1.19854","0.20009"
"1.19854","25.63453","1.19783","94.12600","0.00000","1.19854","0.20009"
"1.19854","25.63426","1.19782","94.30600","0.00000","1.19854","0.20009"
"1.19854","25.62825","1.19753","94.48600","0.00000","1.19854","0.20009"
"1.19854","25.63138","1.19768","94.66600","0.00000","1.19854","0.20009"
"1.19854","25.61939","1.19712","94.84600","0.00000","1.19854","0.20009"
"1.19854","25.61870","1.19709","95.02600","0.00000","1.19854","0.20009"
"1.19854","25.62134","1.19721","95.20600","0.00000","1.19854","0.20009"
"1.19854","25.61986","1.19714","95.38600","0.00000","1.19854","0.20009"
"1.19854","25.62340","1.19731","95.56600","0.00000","1.19854","0.20009"
"1.19854","25.61674","1.19700","95.74600","0.00000","1.19854","0.20009"
"1.19854","25.61496","1.19691","95.92600","0.00000","1.19854","0.20009"
"1.19854","25.61328","1.19684","96.10600","0.00000","1.19854","0.20009"
"1.19854","25.60582","1.19649","96.28600","0.00000","1.19854","0.20009"
"1.19854","25.60638","1.19651","96.46600","0.00000","1.19854","0.20009"
"1.19854","25.60897","1.19663","96.64600","0.00000","1.19854","0.20009"
"1.19854","25.60486","1.19644","96.82600","0.00000","1.19854","0.20009"
"1.19854","25.60438","1.19642","97.00600","0.00000","1.19854","0.20009"
"1.19854","25.60456","1.19643","97.18600","0.00000","1.19854","0.20009"
"1.19854","25.59556","1.19601","97.36600","0.00000","1.19854","0.20009"
"1.19854","25.60099","1.19626","97.54600","0.00000","1.19854","0.20009"
"1.19854","25.59092","1.19579","97.72600","0.00000","1.19854","0.20009"
"1.19854","25.58657","1.19559","97.90600","0.00000","1.19854","0.20009"
"1.19854","25.59528","1.19599","98.08600","0.00000","1.19854","0.20009"
"1.19854","25.59158","1.19582","98.26600","0.00000","1.19854","0.20009"
"1.19854","25.58303","1.19542","98.44600","0.00000","1.19854","0.20009"
"1.19854","25.58500","1.19551","98.62600","0.00000","1.19854","0.20009"
"1.19854","25.57808","1.19519","98.80600","0.00000","1.19854","0.20009"
"1.19854","25.57739","1.19516","98.98600","0.00000","1.19854","0.20009"
"1.19854","25.58043","1.19530","99.16600","0.00000","1.19854","0.20009"
"1.19854","25.58134","1.19534","99.34600","0.00000","1.19854","0.20009"
"1.19854","25.58121","1.19534","99.52600","0.00000","1.19854","0.20009"
"1.19854","25.56936","1.19478","99.70600","0.00000","1.19854","0.20009"
"1.19854","25.56708","1.19468","99.88600","0.00000","1.19854","0.20009"
"1.19854","25.57932","1.19525","100.06600","0.00000","1.19854","0.20009"
"1.19854","25.56708","1.19468","100.24600","0.00000","1.19854","0.20009"
"1.19854","25.57004","1.19481","100.42600","0.00000","1.19854","0.20009"
"1.19854","25.56225","1.19445","100.60600","0.00000","1.19854","0.20009"
"1.19854","25.55947","1.19432","100.78600","0.00000","1.19854","0.20009"
"1.19854","25.56170","1.19442","100.96600","0.00000","1.19854","0.20009"
"1.19854","25.55794","1.19425","101.14600","0.00000","1.19854","0.20009"
"1.19854","25.55407","1.19407","101.32600","0.00000","1.19854","0.20009"
"1.19854","25.55222","1.19398","101.50600","0.00000","1.19854","0.20009"
"1.19854","25.54902","1.19383","101.68600","0.00000","1.19854","0.20009"
"1.19854","25.55668","1.19419","101.86600","0.00000","1.19854","0.20009"
"1.19854","25.54881","1.19382","102.04600","0.00000","1.19854","0.20009"
"1.19854","25.54705","1.19374","102.22600","0.00000","1.19854","0.20009"
"1.19854","25.53817","1.19333","102.40600","0.00000","1.19854","0.20009"
"1.19854","25.53744","1.19329","102.58600","0.00000","1.19854","0.20009"
"1.19854","25.53140","1.19301","102.76600","0.00000","1.19854","0.20009"
"1.19854","25.54156","1.19348","102.94600","0.00000","1.19854","0.20009"
"1.19854","25.54001","1.19341","103.12600","0.00000","1.19854","0.20009"
"1.19854","25.53724","1.19328","103.30600","0.00000","1.19854","0.20009"
"1.19854","25.52770","1.19284","103.48600","0.00000","1.19854","0.20009"
"1.19854","25.53334","1.19310","103.66600","0.00000","1.19854","0.20009"
"1.19854","25.52962","1.19293","103.84600","0.00000","1.19854","0.20009"
"1.19854","25.52918","1.19291","104.02600","0.00000","1.19854","0.20009"
"1.19854","25.52225","1.19258","104.20600","0.00000","1.19854","0.20009"
"1.19854","25.52425","1.19267","104.38600","0.00000","1.19854","0.20009"
"1.19854","25.52089","1.19252","104.56600","0.00000","1.19854","0.20009"
"1.19854","25.51650","1.19231","104.74600","0.00000","1.19854","0.20009"
"1.19854","25.52179","1.19256","104.92600","0.00000","1.19854","0.20009"
"1.19854","25.50971","1.19200","105.10600","0.00000","1.19854","0.20009"
"1.19854","25.51429","1.19221","105.28600","0.00000","1.19854","0.20009"
"1.19854","25.51446","1.19222","105.46600","0.00000","1.19854","0.20009"
"1.19854","25.51523","1.19225","105.64600","0.00000","1.19854","0.20009"
"1.19854","25.50703","1.19187","105.82600","0.00000","1.19854","0.20009"
"1.19854","25.51199","1.19210","106.00600","0.00000","1.19854","0.20009"
"1.19854","25.50500","1.19178","106.18600","0.00000","1.19854","0.20009"
"1.19854","25.50285","1.19168","106.36600","0.00000","1.19854","0.20009"
"1.19854","25.50852","1.19194","106.54600","0.00000","1.19854","0.20009"
"1.19854","25.49992","1.19154","106.72600","0.00000","1.19854","0.20009"
"1.19854","25.50106","1.19159","106.90600","0.00000","1.19854","0.20009"
"1.19854","25.49177","1.19116","107.08600","0.00000","1.19854","0.20009"
"1.19854","25.49868","1.19148","107.26600","0.00000","1.19854","0.20009"
"1.19854","25.49053","1.19110","107.44600","0.00000","1.19854","0.20009"
"1.19854","25.48859","1.19101","107.62600","0.00000","1.19854","0.20009"
"1.19854","25.49235","1.19118","107.80600","0.00000","1.19854","0.20009"
"1.19854","25.49201","1.19117","107.98600","0.00000","1.19854","0.20009"
"1.19854","25.49038","1.19109","108.16600","0.00000","1.19854","0.20009"
"1.19854","25.48401","1.19079","108.34600","0.00000","1.19854","0.20009"
"1.19854","25.48427","1.19081","108.52600","0.00000","1.19854","0.20009"
"1.19854","25.48082","1.19065","108.70600","0.00000","1.19854","0.20009"
"1.19854","25.47180","1.19022","108.88600","0.00000","1.19854","0.20009"
"1.19854","25.47672","1.19045","109.06600","0.00000","1.19854","0.20009"
"1.19854","25.47403","1.19033","109.24600","0.00000","1.19854","0.20009"
"1.19854","25.48143","1.19067","109.42600","0.00000","1.19854","0.20009"
"1.19854","25.47453","1.19035","109.60600","0.00000","1.19854","0.20009"
"1.19854","25.47386","1.19032","109.78600","0.00000","1.19854","0.20009"
"1.19854","25.46842","1.19007","109.96600","0.00000","1.19854","0.20009"
"1.19854","25.46649","1.18998","110.14600","0.00000","1.19854","0.20009"
"1.19854","25.46450","1.18988","110.32600","0.00000","1.19854","0.20009"
"1.19854","25.46654","1.18998","110.50600","0.00000","1.19854","0.20009"
"1.19854","25.46188","1.18976","110.68600","0.00000","1.19854","0.20009"
"1.19854","25.45991","1.18967","110.86600","0.00000","1.19854","0.20009"
"1.19854","25.44902","1.18916","111.04600","0.00000","1.19854","0.20009"
"1.19854","25.45627","1.18950","111.22600","0.00000","1.19854","0.20009"
"1.19854","25.45596","1.18948","111.40600","0.00000","1.19854","0.20009"
"1.19854","25.45750","1.18956","111.58600","0.00000","1.19854","0.20009"
"1.19854","25.45662","1.18951","111.76600","0.00000","1.19854","0.20009"
"1.19854","25.45228","1.18931","111.94600","0.00000","1.19854","0.20009"
"1.19854","25.45167","1.18928","112.12600","0.00000","1.19854","0.20009"
"1.19854","25.45307","1.18935","112.30600","0.00000","1.19854","0.20009"
"1.19854","25.44551","1.18900","112.48600","0.00000","1.19854","0.20009"
"1.19854","25.44192","1.18883","112.66600","0.00000","1.19854","0.20009"
"1.19854","25.44691","1.18906","112.84600","0.00000","1.19854","0.20009"
"1.19854","25.44389","1.18892","113.02600","0.00000","1.19854","0.20009"
"1.19854","25.43532","1.18852","113.20600","0.00000","1.19854","0.20009"
"1.19854","25.43590","1.18855","113.38600","0.00000","1.19854","0.20009"
"1.19854","25.43302","1.18841","113.56600","0.00000","1.19854","0.20009"
"1.19854","25.43259","1.18839","113.74600","0.00000","1.19854","0.20009"
"1.19854","25.43072","1.18830","113.92600","0.00000","1.19854","0.20009"
"1.19854","25.43215","1.18837","114.10600","0.00000","1.19854","0.20009"
"1.19854","25.42777","1.18817","114.28600","0.00000","1.19854","0.20009"
"1.19854","25.42772","1.18816","114.46600","0.00000","1.19854","0.20009"
"1.19854","25.42670","1.18812","114.64600","0.00000","1.19854","0.20009"
"1.19854","25.42495","1.18803","114.82600","0.00000","1.19854","0.20009"
"1.19854","25.41305","1.18748","115.00600","0.00000","1.19854","0.20009"
"1.19854","25.42561","1.18807","115.18600","0.00000","1.19854","0.20009"
"1.19854","25.41263","1.18746","115.36600","0.00000","1.19854","0.20009"
"1.19854","25.41917","1.18777","115.54600","0.00000","1.19854","0.20009"
"1.19854","25.41169","1.18742","115.72600","0.00000","1.19854","0.20009"
"1.19854","25.41236","1.18745","115.90600","0.00000","1.19854","0.20009"
"1.19854","25.41028","1.18735","116.08600","0.00000","1.19854","0.20009"
"1.19854","25.40763","1.18723","116.26600","0.00000","1.19854","0.20009"
"1.19854","25.40207","1.18697","116.44600","0.00000","1.19854","0.20009"
"1.19854","25.41121","1.18739","116.62600","0.00000","1.19854","0.20009"
"1.19854","25.39804","1.18678","116.80600","0.00000","1.19854","0.20009"
"1.19854","25.40751","1.18722","116.98600","0.00000","1.19854","0.20009"
"1.19854","25.40491","1.18710","117.16600","0.00000","1.19854","0.20009"
"1.19854","25.39688","1.18672","117.34600","0.00000","1.19854","0.20009"
"1.19854","25.39634","1.18670","117.52600","0.00000","1.19854","0.20009"
"1.19854","25.39784","1.18677","117.70600","0.00000","1.19854","0.20009"
"1.19854","25.39112","1.18645","117.88600","0.00000","1.19854","0.20009"
"1.19854","25.39124","1.18646","118.06600","0.00000","1.19854","0.20009"
"1.19854","25.39237","1.18651","118.24600","0.00000","1.19854","0.20009"
"1.19854","25.38466","1.18615","118.42600","0.00000","1.19854","0.20009"
"1.19854","25.39337","1.18656","118.60600","0.00000","1.19854","0.20009"
"1.19854","25.38181","1.18602","118.78600","0.00000","1.19854","0.20009"
"1.19854","25.38244","1.18605","118.96600","0.00000","1.19854","0.20009"
"1.19854","25.38816","1.18632","119.14600","0.00000","1.19854","0.20009"
"1.19854","25.38681","1.18625","119.32600","0.00000","1.19854","0.20009"
"1.19854","25.38507","1.18617","119.50600","0.00000","1.19854","0.20009"
"1.19854","25.38485","1.18616","119.68600","0.00000","1.19854","0.20009"
"1.19854","25.37134","1.18553","119.86600","0.00000","1.19854","0.20009"
"1.19854","25.38173","1.18602","120.04600","0.00000","1.19854","0.20009"
"1.19854","25.37824","1.18585","120.22600","0.00000","1.19854","0.20009"
"1.19854","25.37330","1.18562","120.40600","0.00000","1.19854","0.20009"
"1.19854","25.37599","1.18575","120.58600","0.00000","1.19854","0.20009"
"1.19854","25.37563","1.18573","120.76600","0.00000","1.19854","0.20009"
"1.19854","25.37186","1.18555","120.94600","0.00000","1.19854","0.20009"
"1.19854","25.36935","1.18544","121.12600","0.00000","1.19854","0.20009"
"1.19854","25.36067","1.18503","121.30600","0.00000","1.19854","0.20009"
"1.19854","25.37030","1.18548","121.48600","0.00000","1.19854","0.20009"
"1.19854","25.35722","1.18487","121.66600","0.00000","1.19854","0.20009"
"1.19854","25.36478","1.18522","121.84600","0.00000","1.19854","0.20009"
"1.19854","25.35981","1.18499","122.02600","0.00000","1.19854","0.20009"
"1.19854","25.35530","1.18478","122.20600","0.00000","1.19854","0.20009"
"1.19854","25.35987","1.18499","122.38600","0.00000","1.19854","0.20009"
"1.19854","25.35489","1.18476","122.56600","0.00000","1.19854","0.20009"
"1.19854","25.35446","1.18474","122.74600","0.00000","1.19854","0.20009"
"1.19854","25.35593","1.18481","122.92600","0.00000","1.19854","0.20009"
"1.19854","25.34195","1.18416","122.99600","0.00000","1.19854","0.20009"