File: Rubber Stress Relaxation Raw Data - Small Samples-20210211/Specimen_RawData_5.csv
Specimen properties : Specimen label,"GBI2S1R2"
Specimen properties : Anvil height,"6.00000",mm
Specimen properties : Diameter,"5.67000",mm
Test : Rate 1,"2.40000",mm/min
Test : Start of hold value,"20.00000",%
Test : Duration,"120.00000",s

Extension,Load,Compressive stress,Time,PIP count,Compressive extension,Compressive strain (Extension)
(mm),(N),(MPa),(s),,(mm),(mm/mm)
"0.00000","-0.03062","-0.00121","0.00000","0.00000","0.00000","0.00000"
"0.00208","0.04784","0.00189","0.22000","0.00000","0.00208","0.00035"
"0.01167","0.50960","0.02018","0.44000","0.00000","0.01167","0.00194"
"0.02417","0.99237","0.03930","0.66000","0.00000","0.02417","0.00403"
"0.03479","1.32881","0.05263","0.88000","0.00000","0.03479","0.00580"
"0.04417","1.57553","0.06240","1.10000","0.00000","0.04417","0.00736"
"0.05292","1.80082","0.07132","1.32000","0.00000","0.05292","0.00882"
"0.06167","2.01942","0.07998","1.54000","0.00000","0.06167","0.01028"
"0.07063","2.24224","0.08880","1.76000","0.00000","0.07063","0.01177"
"0.07979","2.46885","0.09778","1.98000","0.00000","0.07979","0.01330"
"0.08854","2.67806","0.10606","2.20000","0.00000","0.08854","0.01476"
"0.09688","2.85563","0.11310","2.42000","0.00000","0.09688","0.01615"
"0.10563","3.06691","0.12146","2.64000","0.00000","0.10563","0.01760"
"0.11479","3.28372","0.13005","2.86000","0.00000","0.11479","0.01913"
"0.12375","3.47306","0.13755","3.08000","0.00000","0.12375","0.02063"
"0.13208","3.64438","0.14433","3.30000","0.00000","0.13208","0.02201"
"0.14063","3.84043","0.15210","3.52000","0.00000","0.14063","0.02344"
"0.14958","4.05287","0.16051","3.74000","0.00000","0.14958","0.02493"
"0.15854","4.25386","0.16847","3.96000","0.00000","0.15854","0.02642"
"0.16750","4.44560","0.17607","4.18000","0.00000","0.16750","0.02792"
"0.17625","4.62244","0.18307","4.40000","0.00000","0.17625","0.02938"
"0.18479","4.80361","0.19024","4.62000","0.00000","0.18479","0.03080"
"0.19375","5.00335","0.19815","4.84000","0.00000","0.19375","0.03229"
"0.20271","5.19127","0.20560","5.06000","0.00000","0.20271","0.03378"
"0.21167","5.37346","0.21281","5.28000","0.00000","0.21167","0.03528"
"0.22000","5.55468","0.21999","5.50000","0.00000","0.22000","0.03667"
"0.22896","5.74209","0.22741","5.72000","0.00000","0.22896","0.03816"
"0.23771","5.93266","0.23496","5.94000","0.00000","0.23771","0.03962"
"0.24667","6.10853","0.24193","6.16000","0.00000","0.24667","0.04111"
"0.25542","6.29130","0.24916","6.38000","0.00000","0.25542","0.04257"
"0.26417","6.49501","0.25723","6.60000","0.00000","0.26417","0.04403"
"0.27313","6.69376","0.26510","6.82000","0.00000","0.27313","0.04552"
"0.28188","6.86238","0.27178","7.04000","0.00000","0.28188","0.04698"
"0.29083","7.04579","0.27904","7.26000","0.00000","0.29083","0.04847"
"0.29958","7.19987","0.28515","7.48000","0.00000","0.29958","0.04993"
"0.30833","7.39085","0.29271","7.70000","0.00000","0.30833","0.05139"
"0.31708","7.59216","0.30068","7.92000","0.00000","0.31708","0.05285"
"0.32583","7.78195","0.30820","8.14000","0.00000","0.32583","0.05431"
"0.33479","7.94496","0.31466","8.36000","0.00000","0.33479","0.05580"
"0.34354","8.13284","0.32210","8.58000","0.00000","0.34354","0.05726"
"0.35229","8.32056","0.32953","8.80000","0.00000","0.35229","0.05872"
"0.36083","8.49094","0.33628","9.02000","0.00000","0.36083","0.06014"
"0.36958","8.67665","0.34363","9.24000","0.00000","0.36958","0.06160"
"0.37875","8.91589","0.35311","9.46000","0.00000","0.37875","0.06312"
"0.38729","9.10702","0.36068","9.68000","0.00000","0.38729","0.06455"
"0.39604","9.24424","0.36611","9.90000","0.00000","0.39604","0.06601"
"0.40479","9.39558","0.37211","10.12000","0.00000","0.40479","0.06747"
"0.41375","9.57535","0.37923","10.34000","0.00000","0.41375","0.06896"
"0.42292","9.77218","0.38702","10.56000","0.00000","0.42292","0.07049"
"0.43167","9.97843","0.39519","10.78000","0.00000","0.43167","0.07194"
"0.44021","10.14349","0.40173","11.00000","0.00000","0.44021","0.07337"
"0.44896","10.31103","0.40836","11.22000","0.00000","0.44896","0.07483"
"0.45771","10.50415","0.41601","11.44000","0.00000","0.45771","0.07628"
"0.46667","10.71772","0.42447","11.66000","0.00000","0.46667","0.07778"
"0.47542","10.88173","0.43096","11.88000","0.00000","0.47542","0.07924"
"0.48396","11.05050","0.43765","12.10000","0.00000","0.48396","0.08066"
"0.49271","11.23858","0.44510","12.32000","0.00000","0.49271","0.08212"
"0.50208","11.44939","0.45345","12.54000","0.00000","0.50208","0.08368"
"0.51083","11.61456","0.45999","12.76000","0.00000","0.51083","0.08514"
"0.51938","11.78170","0.46661","12.98000","0.00000","0.51938","0.08656"
"0.52792","11.95813","0.47360","13.20000","0.00000","0.52792","0.08799"
"0.53708","12.17138","0.48204","13.42000","0.00000","0.53708","0.08951"
"0.54604","12.37530","0.49012","13.64000","0.00000","0.54604","0.09101"
"0.55458","12.53936","0.49661","13.86000","0.00000","0.55458","0.09243"
"0.56333","12.72186","0.50384","14.08000","0.00000","0.56333","0.09389"
"0.57188","12.91203","0.51137","14.30000","0.00000","0.57188","0.09531"
"0.58104","13.11660","0.51948","14.52000","0.00000","0.58104","0.09684"
"0.59021","13.33329","0.52806","14.74000","0.00000","0.59021","0.09837"
"0.59854","13.50033","0.53467","14.96000","0.00000","0.59854","0.09976"
"0.60708","13.68304","0.54191","15.18000","0.00000","0.60708","0.10118"
"0.61604","13.89602","0.55034","15.40000","0.00000","0.61604","0.10267"
"0.62542","14.12142","0.55927","15.62000","0.00000","0.62542","0.10424"
"0.63396","14.29196","0.56603","15.84000","0.00000","0.63396","0.10566"
"0.64271","14.49009","0.57387","16.06000","0.00000","0.64271","0.10712"
"0.65104","14.67584","0.58123","16.28000","0.00000","0.65104","0.10851"
"0.66021","14.89239","0.58981","16.50000","0.00000","0.66021","0.11003"
"0.66938","15.10481","0.59822","16.72000","0.00000","0.66938","0.11156"
"0.67771","15.28781","0.60547","16.94000","0.00000","0.67771","0.11295"
"0.68646","15.48745","0.61337","17.16000","0.00000","0.68646","0.11441"
"0.69521","15.70951","0.62217","17.38000","0.00000","0.69521","0.11587"
"0.70438","15.92816","0.63083","17.60000","0.00000","0.70438","0.11740"
"0.71354","16.14760","0.63952","17.82000","0.00000","0.71354","0.11892"
"0.72188","16.33833","0.64707","18.04000","0.00000","0.72188","0.12031"
"0.73021","16.52385","0.65442","18.26000","0.00000","0.73021","0.12170"
"0.73917","16.75289","0.66349","18.48000","0.00000","0.73917","0.12319"
"0.74833","16.97480","0.67228","18.70000","0.00000","0.74833","0.12472"
"0.75729","17.17954","0.68039","18.92000","0.00000","0.75729","0.12622"
"0.76563","17.38375","0.68847","19.14000","0.00000","0.76562","0.12760"
"0.77438","17.60978","0.69743","19.36000","0.00000","0.77438","0.12906"
"0.78333","17.84409","0.70671","19.58000","0.00000","0.78333","0.13056"
"0.79250","18.06972","0.71564","19.80000","0.00000","0.79250","0.13208"
"0.80104","18.29321","0.72449","20.02000","0.00000","0.80104","0.13351"
"0.80958","18.49698","0.73256","20.24000","0.00000","0.80958","0.13493"
"0.81854","18.75489","0.74278","20.46000","0.00000","0.81854","0.13642"
"0.82750","18.97657","0.75156","20.68000","0.00000","0.82750","0.13792"
"0.83646","19.22807","0.76152","20.90000","0.00000","0.83646","0.13941"
"0.84500","19.41109","0.76877","21.12000","0.00000","0.84500","0.14083"
"0.85354","19.66875","0.77897","21.34000","0.00000","0.85354","0.14226"
"0.86250","19.92703","0.78920","21.56000","0.00000","0.86250","0.14375"
"0.87146","20.16825","0.79875","21.78000","0.00000","0.87146","0.14524"
"0.88063","20.41413","0.80849","22.00000","0.00000","0.88063","0.14677"
"0.88875","20.63381","0.81719","22.22000","0.00000","0.88875","0.14813"
"0.89771","20.89555","0.82756","22.44000","0.00000","0.89771","0.14962"
"0.90667","21.16675","0.83830","22.66000","0.00000","0.90667","0.15111"
"0.91583","21.42544","0.84854","22.88000","0.00000","0.91583","0.15264"
"0.92437","21.71900","0.86017","23.10000","0.00000","0.92437","0.15406"
"0.93292","21.92387","0.86828","23.32000","0.00000","0.93292","0.15549"
"0.94167","22.15222","0.87733","23.54000","0.00000","0.94167","0.15694"
"0.95083","22.47715","0.89020","23.76000","0.00000","0.95083","0.15847"
"0.95958","22.76488","0.90159","23.98000","0.00000","0.95958","0.15993"
"0.96812","23.03422","0.91226","24.20000","0.00000","0.96812","0.16135"
"0.97667","23.29070","0.92242","24.42000","0.00000","0.97667","0.16278"
"0.98583","23.60931","0.93503","24.64000","0.00000","0.98583","0.16431"
"0.99458","23.87703","0.94564","24.86000","0.00000","0.99458","0.16576"
"1.00354","24.20085","0.95846","25.08000","0.00000","1.00354","0.16726"
"1.01208","24.48560","0.96974","25.30000","0.00000","1.01208","0.16868"
"1.02083","24.79547","0.98201","25.52000","0.00000","1.02083","0.17014"
"1.02979","25.12944","0.99524","25.74000","0.00000","1.02979","0.17163"
"1.03875","25.42570","1.00697","25.96000","0.00000","1.03875","0.17313"
"1.04750","25.75864","1.02016","26.18000","0.00000","1.04750","0.17458"
"1.05625","26.11282","1.03418","26.40000","0.00000","1.05625","0.17604"
"1.06521","26.46846","1.04827","26.62000","0.00000","1.06521","0.17753"
"1.07396","26.79816","1.06133","26.84000","0.00000","1.07396","0.17899"
"1.08292","27.18197","1.07653","27.06000","0.00000","1.08292","0.18049"
"1.09167","27.53061","1.09033","27.28000","0.00000","1.09167","0.18194"
"1.10021","27.89917","1.10493","27.50000","0.00000","1.10021","0.18337"
"1.10917","28.29641","1.12066","27.72000","0.00000","1.10917","0.18486"
"1.11792","28.68123","1.13590","27.94000","0.00000","1.11792","0.18632"
"1.12667","29.07840","1.15163","28.16000","0.00000","1.12667","0.18778"
"1.13563","29.47878","1.16749","28.38000","0.00000","1.13563","0.18927"
"1.14438","29.89925","1.18414","28.60000","0.00000","1.14438","0.19073"
"1.15313","30.32820","1.20113","28.82000","0.00000","1.15313","0.19219"
"1.16188","30.74670","1.21771","29.04000","0.00000","1.16188","0.19365"
"1.17063","31.17842","1.23480","29.26000","0.00000","1.17063","0.19510"
"1.17958","31.60589","1.25173","29.48000","0.00000","1.17958","0.19660"
"1.18813","32.01210","1.26782","29.70000","0.00000","1.18813","0.19802"
"1.19687","32.43840","1.28471","29.92000","0.00000","1.19687","0.19948"
"1.20167","32.45275","1.28527","30.12800","0.00000","1.20167","0.20028"
"1.20167","31.97603","1.26639","30.34800","0.00000","1.20167","0.20028"
"1.20167","31.67586","1.25450","30.56800","0.00000","1.20167","0.20028"
"1.20167","31.44004","1.24517","30.78800","0.00000","1.20167","0.20028"
"1.20167","31.26155","1.23810","31.00800","0.00000","1.20167","0.20028"
"1.20125","31.07911","1.23087","31.22800","0.00000","1.20125","0.20021"
"1.20125","30.93452","1.22514","31.44800","0.00000","1.20125","0.20021"
"1.20104","30.80951","1.22019","31.66800","0.00000","1.20104","0.20017"
"1.20104","30.68587","1.21530","31.88800","0.00000","1.20104","0.20017"
"1.20083","30.58356","1.21125","32.10800","0.00000","1.20083","0.20014"
"1.20083","30.47464","1.20693","32.32800","0.00000","1.20083","0.20014"
"1.20063","30.36559","1.20261","32.54800","0.00000","1.20063","0.20010"
"1.20063","30.28560","1.19944","32.76800","0.00000","1.20063","0.20010"
"1.20063","30.21323","1.19658","32.98800","0.00000","1.20063","0.20010"
"1.20042","30.12407","1.19305","33.20800","0.00000","1.20042","0.20007"
"1.20042","30.05401","1.19027","33.42800","0.00000","1.20042","0.20007"
"1.20042","29.99223","1.18783","33.64800","0.00000","1.20042","0.20007"
"1.20042","29.93627","1.18561","33.86800","0.00000","1.20042","0.20007"
"1.20042","29.86080","1.18262","34.08800","0.00000","1.20042","0.20007"
"1.20042","29.82474","1.18119","34.30800","0.00000","1.20042","0.20007"
"1.20042","29.76801","1.17895","34.52800","0.00000","1.20042","0.20007"
"1.20042","29.70541","1.17647","34.74800","0.00000","1.20042","0.20007"
"1.20042","29.65155","1.17433","34.96800","0.00000","1.20042","0.20007"
"1.20042","29.60501","1.17249","35.18800","0.00000","1.20042","0.20007"
"1.20042","29.56684","1.17098","35.40800","0.00000","1.20042","0.20007"
"1.20042","29.51283","1.16884","35.62800","0.00000","1.20042","0.20007"
"1.20042","29.45264","1.16646","35.84800","0.00000","1.20042","0.20007"
"1.20042","29.43579","1.16579","36.06800","0.00000","1.20042","0.20007"
"1.20042","29.40219","1.16446","36.28800","0.00000","1.20042","0.20007"
"1.20042","29.33064","1.16162","36.50800","0.00000","1.20042","0.20007"
"1.20042","29.30990","1.16080","36.72800","0.00000","1.20042","0.20007"
"1.20042","29.28346","1.15976","36.94800","0.00000","1.20042","0.20007"
"1.20042","29.23273","1.15775","37.16800","0.00000","1.20042","0.20007"
"1.20042","29.18480","1.15585","37.38800","0.00000","1.20042","0.20007"
"1.20042","29.16536","1.15508","37.60800","0.00000","1.20042","0.20007"
"1.20042","29.13300","1.15380","37.82800","0.00000","1.20042","0.20007"
"1.20042","29.09539","1.15231","38.04800","0.00000","1.20042","0.20007"
"1.20042","29.05276","1.15062","38.26800","0.00000","1.20042","0.20007"
"1.20042","29.02880","1.14967","38.48800","0.00000","1.20042","0.20007"
"1.20042","29.01246","1.14902","38.70800","0.00000","1.20042","0.20007"
"1.20042","28.94337","1.14629","38.92800","0.00000","1.20042","0.20007"
"1.20042","28.93052","1.14578","39.14800","0.00000","1.20042","0.20007"
"1.20042","28.90726","1.14486","39.36800","0.00000","1.20042","0.20007"
"1.20042","28.86467","1.14317","39.58800","0.00000","1.20042","0.20007"
"1.20042","28.85525","1.14280","39.80800","0.00000","1.20042","0.20007"
"1.20042","28.82193","1.14148","40.02800","0.00000","1.20042","0.20007"
"1.20042","28.78152","1.13988","40.24800","0.00000","1.20042","0.20007"
"1.20042","28.75277","1.13874","40.46800","0.00000","1.20042","0.20007"
"1.20042","28.75118","1.13867","40.68800","0.00000","1.20042","0.20007"
"1.20042","28.70908","1.13701","40.90800","0.00000","1.20042","0.20007"
"1.20042","28.67345","1.13560","41.12800","0.00000","1.20042","0.20007"
"1.20042","28.66241","1.13516","41.34800","0.00000","1.20042","0.20007"
"1.20042","28.64625","1.13452","41.56800","0.00000","1.20042","0.20007"
"1.20042","28.61162","1.13315","41.78800","0.00000","1.20042","0.20007"
"1.20042","28.58883","1.13224","42.00800","0.00000","1.20042","0.20007"
"1.20042","28.54216","1.13040","42.22800","0.00000","1.20042","0.20007"
"1.20042","28.54215","1.13040","42.44800","0.00000","1.20042","0.20007"
"1.20042","28.52810","1.12984","42.66800","0.00000","1.20042","0.20007"
"1.20042","28.50202","1.12881","42.88800","0.00000","1.20042","0.20007"
"1.20042","28.46974","1.12753","43.10800","0.00000","1.20042","0.20007"
"1.20042","28.45193","1.12682","43.32800","0.00000","1.20042","0.20007"
"1.20042","28.44016","1.12636","43.54800","0.00000","1.20042","0.20007"
"1.20042","28.42694","1.12583","43.76800","0.00000","1.20042","0.20007"
"1.20042","28.39931","1.12474","43.98800","0.00000","1.20042","0.20007"
"1.20042","28.36286","1.12330","44.20800","0.00000","1.20042","0.20007"
"1.20042","28.34592","1.12262","44.42800","0.00000","1.20042","0.20007"
"1.20042","28.33663","1.12226","44.64800","0.00000","1.20042","0.20007"
"1.20042","28.32292","1.12171","44.86800","0.00000","1.20042","0.20007"
"1.20042","28.29440","1.12058","45.08800","0.00000","1.20042","0.20007"
"1.20042","28.27621","1.11986","45.30800","0.00000","1.20042","0.20007"
"1.20042","28.26352","1.11936","45.52800","0.00000","1.20042","0.20007"
"1.20042","28.23535","1.11825","45.74800","0.00000","1.20042","0.20007"
"1.20042","28.22434","1.11781","45.96800","0.00000","1.20042","0.20007"
"1.20042","28.19830","1.11678","46.18800","0.00000","1.20042","0.20007"
"1.20042","28.17498","1.11585","46.40800","0.00000","1.20042","0.20007"
"1.20042","28.17232","1.11575","46.62800","0.00000","1.20042","0.20007"
"1.20042","28.16269","1.11537","46.84800","0.00000","1.20042","0.20007"
"1.20042","28.13853","1.11441","47.06800","0.00000","1.20042","0.20007"
"1.20042","28.11299","1.11340","47.28800","0.00000","1.20042","0.20007"
"1.20042","28.10371","1.11303","47.50800","0.00000","1.20042","0.20007"
"1.20042","28.08587","1.11233","47.72800","0.00000","1.20042","0.20007"
"1.20042","28.06416","1.11147","47.94800","0.00000","1.20042","0.20007"
"1.20042","28.05914","1.11127","48.16800","0.00000","1.20042","0.20007"
"1.20042","28.02554","1.10994","48.38800","0.00000","1.20042","0.20007"
"1.20042","28.02513","1.10992","48.60800","0.00000","1.20042","0.20007"
"1.20042","28.00960","1.10930","48.82800","0.00000","1.20042","0.20007"
"1.20042","27.98846","1.10847","49.04800","0.00000","1.20042","0.20007"
"1.20042","27.96927","1.10771","49.26800","0.00000","1.20042","0.20007"
"1.20042","27.96012","1.10735","49.48800","0.00000","1.20042","0.20007"
"1.20042","27.94827","1.10688","49.70800","0.00000","1.20042","0.20007"
"1.20042","27.93203","1.10623","49.92800","0.00000","1.20042","0.20007"
"1.20042","27.92976","1.10614","50.14800","0.00000","1.20042","0.20007"
"1.20042","27.90690","1.10524","50.36800","0.00000","1.20042","0.20007"
"1.20042","27.89649","1.10483","50.58800","0.00000","1.20042","0.20007"
"1.20042","27.88857","1.10451","50.80800","0.00000","1.20042","0.20007"
"1.20042","27.86869","1.10372","51.02800","0.00000","1.20042","0.20007"
"1.20042","27.84249","1.10269","51.24800","0.00000","1.20042","0.20007"
"1.20042","27.84610","1.10283","51.46800","0.00000","1.20042","0.20007"
"1.20042","27.81734","1.10169","51.68800","0.00000","1.20042","0.20007"
"1.20042","27.78721","1.10050","51.90800","0.00000","1.20042","0.20007"
"1.20042","27.79016","1.10061","52.12800","0.00000","1.20042","0.20007"
"1.20042","27.83949","1.10257","52.34800","0.00000","1.20042","0.20007"
"1.20042","27.76657","1.09968","52.56800","0.00000","1.20042","0.20007"
"1.20042","27.76980","1.09981","52.78800","0.00000","1.20042","0.20007"
"1.20042","27.74900","1.09898","53.00800","0.00000","1.20042","0.20007"
"1.20042","27.73480","1.09842","53.22800","0.00000","1.20042","0.20007"
"1.20042","27.72922","1.09820","53.44800","0.00000","1.20042","0.20007"
"1.20042","27.70282","1.09716","53.66800","0.00000","1.20042","0.20007"
"1.20042","27.70770","1.09735","53.88800","0.00000","1.20042","0.20007"
"1.20042","27.69017","1.09665","54.10800","0.00000","1.20042","0.20007"
"1.20042","27.67637","1.09611","54.32800","0.00000","1.20042","0.20007"
"1.20042","27.66208","1.09554","54.54800","0.00000","1.20042","0.20007"
"1.20042","27.65627","1.09531","54.76800","0.00000","1.20042","0.20007"
"1.20042","27.62775","1.09418","54.98800","0.00000","1.20042","0.20007"
"1.20042","27.62895","1.09423","55.20800","0.00000","1.20042","0.20007"
"1.20042","27.61658","1.09374","55.42800","0.00000","1.20042","0.20007"
"1.20042","27.61082","1.09351","55.64800","0.00000","1.20042","0.20007"
"1.20042","27.57976","1.09228","55.86800","0.00000","1.20042","0.20007"
"1.20042","27.59337","1.09282","56.08800","0.00000","1.20042","0.20007"
"1.20042","27.56224","1.09159","56.30800","0.00000","1.20042","0.20007"
"1.20042","27.56766","1.09180","56.52800","0.00000","1.20042","0.20007"
"1.20042","27.55979","1.09149","56.74800","0.00000","1.20042","0.20007"
"1.20042","27.53683","1.09058","56.96800","0.00000","1.20042","0.20007"
"1.20042","27.53899","1.09067","57.18800","0.00000","1.20042","0.20007"
"1.20042","27.51211","1.08960","57.40800","0.00000","1.20042","0.20007"
"1.20042","27.50853","1.08946","57.62800","0.00000","1.20042","0.20007"
"1.20042","27.50045","1.08914","57.84800","0.00000","1.20042","0.20007"
"1.20042","27.49493","1.08892","58.06800","0.00000","1.20042","0.20007"
"1.20042","27.47688","1.08821","58.28800","0.00000","1.20042","0.20007"
"1.20042","27.47553","1.08815","58.50800","0.00000","1.20042","0.20007"
"1.20042","27.45681","1.08741","58.72800","0.00000","1.20042","0.20007"
"1.20042","27.46025","1.08755","58.94800","0.00000","1.20042","0.20007"
"1.20042","27.42377","1.08610","59.16800","0.00000","1.20042","0.20007"
"1.20042","27.43678","1.08662","59.38800","0.00000","1.20042","0.20007"
"1.20042","27.41399","1.08572","59.60800","0.00000","1.20042","0.20007"
"1.20042","27.41702","1.08584","59.82800","0.00000","1.20042","0.20007"
"1.20042","27.40272","1.08527","60.04800","0.00000","1.20042","0.20007"
"1.20042","27.39512","1.08497","60.26800","0.00000","1.20042","0.20007"
"1.20042","27.38576","1.08460","60.48800","0.00000","1.20042","0.20007"
"1.20042","27.35183","1.08325","60.70800","0.00000","1.20042","0.20007"
"1.20042","27.38105","1.08441","60.92800","0.00000","1.20042","0.20007"
"1.20042","27.33622","1.08264","61.14800","0.00000","1.20042","0.20007"
"1.20042","27.34705","1.08306","61.36800","0.00000","1.20042","0.20007"
"1.20042","27.32813","1.08232","61.58800","0.00000","1.20042","0.20007"
"1.20042","27.32325","1.08212","61.80800","0.00000","1.20042","0.20007"
"1.20042","27.32128","1.08204","62.02800","0.00000","1.20042","0.20007"
"1.20042","27.30016","1.08121","62.24800","0.00000","1.20042","0.20007"
"1.20042","27.29587","1.08104","62.46800","0.00000","1.20042","0.20007"
"1.20042","27.29358","1.08095","62.68800","0.00000","1.20042","0.20007"
"1.20042","27.28338","1.08054","62.90800","0.00000","1.20042","0.20007"
"1.20042","27.27979","1.08040","63.12800","0.00000","1.20042","0.20007"
"1.20042","27.26233","1.07971","63.34800","0.00000","1.20042","0.20007"
"1.20042","27.25063","1.07925","63.56800","0.00000","1.20042","0.20007"
"1.20042","27.24958","1.07920","63.78800","0.00000","1.20042","0.20007"
"1.20042","27.24249","1.07892","64.00800","0.00000","1.20042","0.20007"
"1.20042","27.22908","1.07839","64.22800","0.00000","1.20042","0.20007"
"1.20042","27.22347","1.07817","64.44800","0.00000","1.20042","0.20007"
"1.20042","27.21414","1.07780","64.66800","0.00000","1.20042","0.20007"
"1.20042","27.20746","1.07754","64.88800","0.00000","1.20042","0.20007"
"1.20042","27.19473","1.07703","65.10800","0.00000","1.20042","0.20007"
"1.20042","27.18736","1.07674","65.32800","0.00000","1.20042","0.20007"
"1.20042","27.17769","1.07636","65.54800","0.00000","1.20042","0.20007"
"1.20042","27.16464","1.07584","65.76800","0.00000","1.20042","0.20007"
"1.20042","27.16168","1.07572","65.98800","0.00000","1.20042","0.20007"
"1.20042","27.15965","1.07564","66.20800","0.00000","1.20042","0.20007"
"1.20042","27.14275","1.07497","66.42800","0.00000","1.20042","0.20007"
"1.20042","27.13694","1.07474","66.64800","0.00000","1.20042","0.20007"
"1.20042","27.14051","1.07488","66.86800","0.00000","1.20042","0.20007"
"1.20042","27.12958","1.07445","67.08800","0.00000","1.20042","0.20007"
"1.20042","27.11226","1.07377","67.30800","0.00000","1.20042","0.20007"
"1.20042","27.11277","1.07379","67.52800","0.00000","1.20042","0.20007"
"1.20042","27.10956","1.07366","67.74800","0.00000","1.20042","0.20007"
"1.20042","27.09174","1.07295","67.96800","0.00000","1.20042","0.20007"
"1.20042","27.09666","1.07315","68.18800","0.00000","1.20042","0.20007"
"1.20042","27.07080","1.07212","68.40800","0.00000","1.20042","0.20007"
"1.20042","27.06931","1.07207","68.62800","0.00000","1.20042","0.20007"
"1.20042","27.06219","1.07178","68.84800","0.00000","1.20042","0.20007"
"1.20042","27.05821","1.07163","69.06800","0.00000","1.20042","0.20007"
"1.20042","27.04845","1.07124","69.28800","0.00000","1.20042","0.20007"
"1.20042","27.04767","1.07121","69.50800","0.00000","1.20042","0.20007"
"1.20042","27.04102","1.07094","69.72800","0.00000","1.20042","0.20007"
"1.20042","27.03035","1.07052","69.94800","0.00000","1.20042","0.20007"
"1.20042","27.02356","1.07025","70.16800","0.00000","1.20042","0.20007"
"1.20042","27.01188","1.06979","70.38800","0.00000","1.20042","0.20007"
"1.20042","26.99220","1.06901","70.60800","0.00000","1.20042","0.20007"
"1.20042","27.00197","1.06940","70.82800","0.00000","1.20042","0.20007"
"1.20042","26.98703","1.06881","71.04800","0.00000","1.20042","0.20007"
"1.20042","26.98010","1.06853","71.26800","0.00000","1.20042","0.20007"
"1.20042","26.95749","1.06764","71.48800","0.00000","1.20042","0.20007"
"1.20042","26.96313","1.06786","71.70800","0.00000","1.20042","0.20007"
"1.20042","26.98368","1.06867","71.92800","0.00000","1.20042","0.20007"
"1.20042","26.95854","1.06768","72.14800","0.00000","1.20042","0.20007"
"1.20042","26.93794","1.06686","72.36800","0.00000","1.20042","0.20007"
"1.20042","26.93958","1.06693","72.58800","0.00000","1.20042","0.20007"
"1.20042","26.93517","1.06675","72.80800","0.00000","1.20042","0.20007"
"1.20042","26.92321","1.06628","73.02800","0.00000","1.20042","0.20007"
"1.20042","26.91656","1.06602","73.24800","0.00000","1.20042","0.20007"
"1.20042","26.92314","1.06628","73.46800","0.00000","1.20042","0.20007"
"1.20042","26.88605","1.06481","73.68800","0.00000","1.20042","0.20007"
"1.20042","26.91163","1.06582","73.90800","0.00000","1.20042","0.20007"
"1.20042","26.91433","1.06593","74.12800","0.00000","1.20042","0.20007"
"1.20042","26.88084","1.06460","74.34800","0.00000","1.20042","0.20007"
"1.20042","26.89070","1.06499","74.56800","0.00000","1.20042","0.20007"
"1.20042","26.89203","1.06504","74.78800","0.00000","1.20042","0.20007"
"1.20042","26.88110","1.06461","75.00800","0.00000","1.20042","0.20007"
"1.20042","26.85848","1.06372","75.22800","0.00000","1.20042","0.20007"
"1.20042","26.86521","1.06398","75.44800","0.00000","1.20042","0.20007"
"1.20042","26.86089","1.06381","75.66800","0.00000","1.20042","0.20007"
"1.20042","26.84858","1.06332","75.88800","0.00000","1.20042","0.20007"
"1.20042","26.82871","1.06254","76.10800","0.00000","1.20042","0.20007"
"1.20042","26.83857","1.06293","76.32800","0.00000","1.20042","0.20007"
"1.20042","26.82449","1.06237","76.54800","0.00000","1.20042","0.20007"
"1.20042","26.82167","1.06226","76.76800","0.00000","1.20042","0.20007"
"1.20042","26.82213","1.06228","76.98800","0.00000","1.20042","0.20007"
"1.20042","26.80771","1.06170","77.20800","0.00000","1.20042","0.20007"
"1.20042","26.80929","1.06177","77.42800","0.00000","1.20042","0.20007"
"1.20042","26.80030","1.06141","77.64800","0.00000","1.20042","0.20007"
"1.20042","26.79164","1.06107","77.86800","0.00000","1.20042","0.20007"
"1.20042","26.77718","1.06050","78.08800","0.00000","1.20042","0.20007"
"1.20042","26.78686","1.06088","78.30800","0.00000","1.20042","0.20007"
"1.20042","26.76989","1.06021","78.52800","0.00000","1.20042","0.20007"
"1.20042","26.76557","1.06004","78.74800","0.00000","1.20042","0.20007"
"1.20042","26.77566","1.06044","78.96800","0.00000","1.20042","0.20007"
"1.20042","26.75386","1.05957","79.18800","0.00000","1.20042","0.20007"
"1.20042","26.75065","1.05944","79.40800","0.00000","1.20042","0.20007"
"1.20042","26.74227","1.05911","79.62800","0.00000","1.20042","0.20007"
"1.20042","26.74006","1.05903","79.84800","0.00000","1.20042","0.20007"
"1.20042","26.73891","1.05898","80.06800","0.00000","1.20042","0.20007"
"1.20042","26.72487","1.05842","80.28800","0.00000","1.20042","0.20007"
"1.20042","26.71579","1.05806","80.50800","0.00000","1.20042","0.20007"
"1.20042","26.70909","1.05780","80.72800","0.00000","1.20042","0.20007"
"1.20042","26.72748","1.05853","80.94800","0.00000","1.20042","0.20007"
"1.20042","26.69986","1.05743","81.16800","0.00000","1.20042","0.20007"
"1.20042","26.70098","1.05748","81.38800","0.00000","1.20042","0.20007"
"1.20042","26.69118","1.05709","81.60800","0.00000","1.20042","0.20007"
"1.20042","26.69551","1.05726","81.82800","0.00000","1.20042","0.20007"
"1.20042","26.68283","1.05676","82.04800","0.00000","1.20042","0.20007"
"1.20042","26.69582","1.05727","82.26800","0.00000","1.20042","0.20007"
"1.20042","26.68102","1.05669","82.48800","0.00000","1.20042","0.20007"
"1.20042","26.66785","1.05617","82.70800","0.00000","1.20042","0.20007"
"1.20042","26.66904","1.05621","82.92800","0.00000","1.20042","0.20007"
"1.20042","26.66158","1.05592","83.14800","0.00000","1.20042","0.20007"
"1.20042","26.64632","1.05531","83.36800","0.00000","1.20042","0.20007"
"1.20042","26.65678","1.05573","83.58800","0.00000","1.20042","0.20007"
"1.20042","26.64123","1.05511","83.80800","0.00000","1.20042","0.20007"
"1.20042","26.64780","1.05537","84.02800","0.00000","1.20042","0.20007"
"1.20042","26.63141","1.05472","84.24800","0.00000","1.20042","0.20007"
"1.20042","26.63000","1.05467","84.46800","0.00000","1.20042","0.20007"
"1.20042","26.61875","1.05422","84.68800","0.00000","1.20042","0.20007"
"1.20042","26.62121","1.05432","84.90800","0.00000","1.20042","0.20007"
"1.20042","26.60566","1.05370","85.12800","0.00000","1.20042","0.20007"
"1.20042","26.60929","1.05385","85.34800","0.00000","1.20042","0.20007"
"1.20042","26.59899","1.05344","85.56800","0.00000","1.20042","0.20007"
"1.20042","26.60328","1.05361","85.78800","0.00000","1.20042","0.20007"
"1.20042","26.59276","1.05319","86.00800","0.00000","1.20042","0.20007"
"1.20042","26.58445","1.05286","86.22800","0.00000","1.20042","0.20007"
"1.20042","26.57603","1.05253","86.44800","0.00000","1.20042","0.20007"
"1.20042","26.57335","1.05242","86.66800","0.00000","1.20042","0.20007"
"1.20042","26.56930","1.05226","86.88800","0.00000","1.20042","0.20007"
"1.20042","26.55943","1.05187","87.10800","0.00000","1.20042","0.20007"
"1.20042","26.55962","1.05188","87.32800","0.00000","1.20042","0.20007"
"1.20042","26.55768","1.05180","87.54800","0.00000","1.20042","0.20007"
"1.20042","26.54402","1.05126","87.76800","0.00000","1.20042","0.20007"
"1.20042","26.54217","1.05119","87.98800","0.00000","1.20042","0.20007"
"1.20042","26.53953","1.05108","88.20800","0.00000","1.20042","0.20007"
"1.20042","26.54036","1.05112","88.42800","0.00000","1.20042","0.20007"
"1.20042","26.53088","1.05074","88.64800","0.00000","1.20042","0.20007"
"1.20042","26.53209","1.05079","88.86800","0.00000","1.20042","0.20007"
"1.20042","26.51780","1.05022","89.08800","0.00000","1.20042","0.20007"
"1.20042","26.51993","1.05031","89.30800","0.00000","1.20042","0.20007"
"1.20042","26.51213","1.05000","89.52800","0.00000","1.20042","0.20007"
"1.20042","26.50891","1.04987","89.74800","0.00000","1.20042","0.20007"
"1.20042","26.50531","1.04973","89.96800","0.00000","1.20042","0.20007"
"1.20042","26.49988","1.04951","90.18800","0.00000","1.20042","0.20007"
"1.20042","26.49253","1.04922","90.40800","0.00000","1.20042","0.20007"
"1.20042","26.49134","1.04918","90.62800","0.00000","1.20042","0.20007"
"1.20042","26.48352","1.04887","90.84800","0.00000","1.20042","0.20007"
"1.20042","26.47438","1.04850","91.06800","0.00000","1.20042","0.20007"
"1.20042","26.47733","1.04862","91.28800","0.00000","1.20042","0.20007"
"1.20042","26.46847","1.04827","91.50800","0.00000","1.20042","0.20007"
"1.20042","26.46561","1.04816","91.72800","0.00000","1.20042","0.20007"
"1.20042","26.46926","1.04830","91.94800","0.00000","1.20042","0.20007"
"1.20042","26.45982","1.04793","92.16800","0.00000","1.20042","0.20007"
"1.20042","26.46801","1.04825","92.38800","0.00000","1.20042","0.20007"
"1.20042","26.43918","1.04711","92.60800","0.00000","1.20042","0.20007"
"1.20042","26.45002","1.04754","92.82800","0.00000","1.20042","0.20007"
"1.20042","26.44386","1.04729","93.04800","0.00000","1.20042","0.20007"
"1.20042","26.44215","1.04723","93.26800","0.00000","1.20042","0.20007"
"1.20042","26.44684","1.04741","93.48800","0.00000","1.20042","0.20007"
"1.20042","26.41673","1.04622","93.70800","0.00000","1.20042","0.20007"
"1.20042","26.43552","1.04696","93.92800","0.00000","1.20042","0.20007"
"1.20042","26.40909","1.04592","94.14800","0.00000","1.20042","0.20007"
"1.20042","26.43191","1.04682","94.36800","0.00000","1.20042","0.20007"
"1.20042","26.40524","1.04577","94.58800","0.00000","1.20042","0.20007"
"1.20042","26.39113","1.04521","94.80800","0.00000","1.20042","0.20007"
"1.20042","26.42370","1.04650","95.02800","0.00000","1.20042","0.20007"
"1.20042","26.39081","1.04519","95.24800","0.00000","1.20042","0.20007"
"1.20042","26.44793","1.04746","95.46800","0.00000","1.20042","0.20007"
"1.20042","26.38874","1.04511","95.68800","0.00000","1.20042","0.20007"
"1.20042","26.37677","1.04464","95.90800","0.00000","1.20042","0.20007"
"1.20042","26.40482","1.04575","96.12800","0.00000","1.20042","0.20007"
"1.20042","26.38762","1.04507","96.34800","0.00000","1.20042","0.20007"
"1.20042","26.36812","1.04429","96.56800","0.00000","1.20042","0.20007"
"1.20042","26.39288","1.04528","96.78800","0.00000","1.20042","0.20007"
"1.20042","26.37179","1.04444","97.00800","0.00000","1.20042","0.20007"
"1.20042","26.37004","1.04437","97.22800","0.00000","1.20042","0.20007"
"1.20042","26.35675","1.04384","97.44800","0.00000","1.20042","0.20007"
"1.20042","26.35731","1.04387","97.66800","0.00000","1.20042","0.20007"
"1.20042","26.35286","1.04369","97.88800","0.00000","1.20042","0.20007"
"1.20042","26.34618","1.04343","98.10800","0.00000","1.20042","0.20007"
"1.20042","26.33617","1.04303","98.32800","0.00000","1.20042","0.20007"
"1.20042","26.32702","1.04267","98.54800","0.00000","1.20042","0.20007"
"1.20042","26.35374","1.04373","98.76800","0.00000","1.20042","0.20007"
"1.20042","26.34081","1.04321","98.98800","0.00000","1.20042","0.20007"
"1.20042","26.30903","1.04195","99.20800","0.00000","1.20042","0.20007"
"1.20042","26.28344","1.04094","99.42800","0.00000","1.20042","0.20007"
"1.20042","26.32881","1.04274","99.64800","0.00000","1.20042","0.20007"
"1.20042","26.33836","1.04312","99.86800","0.00000","1.20042","0.20007"
"1.20042","26.31313","1.04212","100.08800","0.00000","1.20042","0.20007"
"1.20042","26.28729","1.04109","100.30800","0.00000","1.20042","0.20007"
"1.20042","26.30948","1.04197","100.52800","0.00000","1.20042","0.20007"
"1.20042","26.30600","1.04183","100.74800","0.00000","1.20042","0.20007"
"1.20042","26.31405","1.04215","100.96800","0.00000","1.20042","0.20007"
"1.20042","26.29555","1.04142","101.18800","0.00000","1.20042","0.20007"
"1.20042","26.28832","1.04113","101.40800","0.00000","1.20042","0.20007"
"1.20042","26.29007","1.04120","101.62800","0.00000","1.20042","0.20007"
"1.20042","26.27361","1.04055","101.84800","0.00000","1.20042","0.20007"
"1.20042","26.28043","1.04082","102.06800","0.00000","1.20042","0.20007"
"1.20042","26.27778","1.04072","102.28800","0.00000","1.20042","0.20007"
"1.20042","26.27432","1.04058","102.50800","0.00000","1.20042","0.20007"
"1.20042","26.26611","1.04025","102.72800","0.00000","1.20042","0.20007"
"1.20042","26.26074","1.04004","102.94800","0.00000","1.20042","0.20007"
"1.20042","26.26081","1.04004","103.16800","0.00000","1.20042","0.20007"
"1.20042","26.26178","1.04008","103.38800","0.00000","1.20042","0.20007"
"1.20042","26.24643","1.03948","103.60800","0.00000","1.20042","0.20007"
"1.20042","26.25774","1.03992","103.82800","0.00000","1.20042","0.20007"
"1.20042","26.24104","1.03926","104.04800","0.00000","1.20042","0.20007"
"1.20042","26.25073","1.03965","104.26800","0.00000","1.20042","0.20007"
"1.20042","26.24942","1.03959","104.48800","0.00000","1.20042","0.20007"
"1.20042","26.25026","1.03963","104.70800","0.00000","1.20042","0.20007"
"1.20042","26.22252","1.03853","104.92800","0.00000","1.20042","0.20007"
"1.20042","26.23530","1.03903","105.14800","0.00000","1.20042","0.20007"
"1.20042","26.22454","1.03861","105.36800","0.00000","1.20042","0.20007"
"1.20042","26.22600","1.03867","105.58800","0.00000","1.20042","0.20007"
"1.20042","26.22084","1.03846","105.80800","0.00000","1.20042","0.20007"
"1.20042","26.21873","1.03838","106.02800","0.00000","1.20042","0.20007"
"1.20042","26.19630","1.03749","106.24800","0.00000","1.20042","0.20007"
"1.20042","26.21598","1.03827","106.46800","0.00000","1.20042","0.20007"
"1.20042","26.19980","1.03763","106.68800","0.00000","1.20042","0.20007"
"1.20042","26.20250","1.03774","106.90800","0.00000","1.20042","0.20007"
"1.20042","26.20225","1.03773","107.12800","0.00000","1.20042","0.20007"
"1.20042","26.19184","1.03731","107.34800","0.00000","1.20042","0.20007"
"1.20042","26.18688","1.03712","107.56800","0.00000","1.20042","0.20007"
"1.20042","26.19230","1.03733","107.78800","0.00000","1.20042","0.20007"
"1.20042","26.17400","1.03661","108.00800","0.00000","1.20042","0.20007"
"1.20042","26.19911","1.03760","108.22800","0.00000","1.20042","0.20007"
"1.20042","26.18525","1.03705","108.44800","0.00000","1.20042","0.20007"
"1.20042","26.17840","1.03678","108.66800","0.00000","1.20042","0.20007"
"1.20042","26.17221","1.03654","108.88800","0.00000","1.20042","0.20007"
"1.20042","26.16576","1.03628","109.10800","0.00000","1.20042","0.20007"
"1.20042","26.17093","1.03649","109.32800","0.00000","1.20042","0.20007"
"1.20042","26.16130","1.03610","109.54800","0.00000","1.20042","0.20007"
"1.20042","26.15753","1.03595","109.76800","0.00000","1.20042","0.20007"
"1.20042","26.15244","1.03575","109.98800","0.00000","1.20042","0.20007"
"1.20042","26.15075","1.03569","110.20800","0.00000","1.20042","0.20007"
"1.20042","26.14518","1.03547","110.42800","0.00000","1.20042","0.20007"
"1.20042","26.14596","1.03550","110.64800","0.00000","1.20042","0.20007"
"1.20042","26.14157","1.03532","110.86800","0.00000","1.20042","0.20007"
"1.20042","26.13579","1.03509","111.08800","0.00000","1.20042","0.20007"
"1.20042","26.13408","1.03503","111.30800","0.00000","1.20042","0.20007"
"1.20042","26.12410","1.03463","111.52800","0.00000","1.20042","0.20007"
"1.20042","26.13417","1.03503","111.74800","0.00000","1.20042","0.20007"
"1.20042","26.12727","1.03476","111.96800","0.00000","1.20042","0.20007"
"1.20042","26.10766","1.03398","112.18800","0.00000","1.20042","0.20007"
"1.20042","26.12607","1.03471","112.40800","0.00000","1.20042","0.20007"
"1.20042","26.11366","1.03422","112.62800","0.00000","1.20042","0.20007"
"1.20042","26.09718","1.03356","112.84800","0.00000","1.20042","0.20007"
"1.20042","26.11135","1.03413","113.06800","0.00000","1.20042","0.20007"
"1.20042","26.09738","1.03357","113.28800","0.00000","1.20042","0.20007"
"1.20042","26.10413","1.03384","113.50800","0.00000","1.20042","0.20007"
"1.20042","26.10279","1.03379","113.72800","0.00000","1.20042","0.20007"
"1.20042","26.09260","1.03338","113.94800","0.00000","1.20042","0.20007"
"1.20042","26.09400","1.03344","114.16800","0.00000","1.20042","0.20007"
"1.20042","26.08232","1.03298","114.38800","0.00000","1.20042","0.20007"
"1.20042","26.10442","1.03385","114.60800","0.00000","1.20042","0.20007"
"1.20042","26.07826","1.03282","114.82800","0.00000","1.20042","0.20007"
"1.20042","26.08286","1.03300","115.04800","0.00000","1.20042","0.20007"
"1.20042","26.07734","1.03278","115.26800","0.00000","1.20042","0.20007"
"1.20042","26.07191","1.03256","115.48800","0.00000","1.20042","0.20007"
"1.20042","26.07286","1.03260","115.70800","0.00000","1.20042","0.20007"
"1.20042","26.07411","1.03265","115.92800","0.00000","1.20042","0.20007"
"1.20042","26.06230","1.03218","116.14800","0.00000","1.20042","0.20007"
"1.20042","26.05598","1.03193","116.36800","0.00000","1.20042","0.20007"
"1.20042","26.06154","1.03215","116.58800","0.00000","1.20042","0.20007"
"1.20042","26.04475","1.03149","116.80800","0.00000","1.20042","0.20007"
"1.20042","26.06299","1.03221","117.02800","0.00000","1.20042","0.20007"
"1.20042","26.05270","1.03180","117.24800","0.00000","1.20042","0.20007"
"1.20042","26.04457","1.03148","117.46800","0.00000","1.20042","0.20007"
"1.20042","26.05052","1.03172","117.68800","0.00000","1.20042","0.20007"
"1.20042","26.04225","1.03139","117.90800","0.00000","1.20042","0.20007"
"1.20042","26.02651","1.03077","118.12800","0.00000","1.20042","0.20007"
"1.20042","26.03278","1.03101","118.34800","0.00000","1.20042","0.20007"
"1.20042","26.03255","1.03100","118.56800","0.00000","1.20042","0.20007"
"1.20042","26.03259","1.03101","118.78800","0.00000","1.20042","0.20007"
"1.20042","26.02332","1.03064","119.00800","0.00000","1.20042","0.20007"
"1.20042","26.02136","1.03056","119.22800","0.00000","1.20042","0.20007"
"1.20042","26.02094","1.03054","119.44800","0.00000","1.20042","0.20007"
"1.20042","26.02616","1.03075","119.66800","0.00000","1.20042","0.20007"
"1.20042","26.01082","1.03014","119.88800","0.00000","1.20042","0.20007"
"1.20042","26.01624","1.03036","120.10800","0.00000","1.20042","0.20007"
"1.20042","26.01203","1.03019","120.32800","0.00000","1.20042","0.20007"
"1.20042","26.01559","1.03033","120.54800","0.00000","1.20042","0.20007"
"1.20042","26.00224","1.02980","120.76800","0.00000","1.20042","0.20007"
"1.20042","26.03348","1.03104","120.98800","0.00000","1.20042","0.20007"
"1.20042","25.98373","1.02907","121.20800","0.00000","1.20042","0.20007"
"1.20042","26.01208","1.03019","121.42800","0.00000","1.20042","0.20007"
"1.20042","25.98532","1.02913","121.64800","0.00000","1.20042","0.20007"
"1.20042","25.99898","1.02968","121.86800","0.00000","1.20042","0.20007"
"1.20042","25.98147","1.02898","122.08800","0.00000","1.20042","0.20007"
"1.20042","25.98323","1.02905","122.30800","0.00000","1.20042","0.20007"
"1.20042","25.97643","1.02878","122.52800","0.00000","1.20042","0.20007"
"1.20042","25.96547","1.02835","122.74800","0.00000","1.20042","0.20007"
"1.20042","25.98571","1.02915","122.96800","0.00000","1.20042","0.20007"
"1.20042","25.96235","1.02822","123.18800","0.00000","1.20042","0.20007"
"1.20042","25.97695","1.02880","123.40800","0.00000","1.20042","0.20007"
"1.20042","25.97066","1.02855","123.62800","0.00000","1.20042","0.20007"
"1.20042","25.97162","1.02859","123.84800","0.00000","1.20042","0.20007"
"1.20042","25.96152","1.02819","124.06800","0.00000","1.20042","0.20007"
"1.20042","25.96219","1.02822","124.28800","0.00000","1.20042","0.20007"
"1.20042","25.96367","1.02828","124.50800","0.00000","1.20042","0.20007"
"1.20042","25.96351","1.02827","124.72800","0.00000","1.20042","0.20007"
"1.20042","25.93973","1.02733","124.94800","0.00000","1.20042","0.20007"
"1.20042","25.95029","1.02775","125.16800","0.00000","1.20042","0.20007"
"1.20042","25.95630","1.02798","125.38800","0.00000","1.20042","0.20007"
"1.20042","25.94633","1.02759","125.60800","0.00000","1.20042","0.20007"
"1.20042","25.94388","1.02749","125.82800","0.00000","1.20042","0.20007"
"1.20042","25.93342","1.02708","126.04800","0.00000","1.20042","0.20007"
"1.20042","25.94477","1.02753","126.26800","0.00000","1.20042","0.20007"
"1.20042","25.92736","1.02684","126.48800","0.00000","1.20042","0.20007"
"1.20042","25.93532","1.02715","126.70800","0.00000","1.20042","0.20007"
"1.20042","25.93088","1.02698","126.92800","0.00000","1.20042","0.20007"
"1.20042","25.93129","1.02699","127.14800","0.00000","1.20042","0.20007"
"1.20042","25.93011","1.02695","127.36800","0.00000","1.20042","0.20007"
"1.20042","25.92509","1.02675","127.58800","0.00000","1.20042","0.20007"
"1.20042","25.91747","1.02645","127.80800","0.00000","1.20042","0.20007"
"1.20042","25.91191","1.02623","128.02800","0.00000","1.20042","0.20007"
"1.20042","25.92401","1.02671","128.24800","0.00000","1.20042","0.20007"
"1.20042","25.90998","1.02615","128.46800","0.00000","1.20042","0.20007"
"1.20042","25.90997","1.02615","128.68800","0.00000","1.20042","0.20007"
"1.20042","25.90601","1.02599","128.90800","0.00000","1.20042","0.20007"
"1.20042","25.90649","1.02601","129.12800","0.00000","1.20042","0.20007"
"1.20042","25.90726","1.02604","129.34800","0.00000","1.20042","0.20007"
"1.20042","25.90169","1.02582","129.56800","0.00000","1.20042","0.20007"
"1.20042","25.88743","1.02526","129.78800","0.00000","1.20042","0.20007"
"1.20042","25.88629","1.02521","130.00800","0.00000","1.20042","0.20007"
"1.20042","25.89100","1.02540","130.22800","0.00000","1.20042","0.20007"
"1.20042","25.89889","1.02571","130.44800","0.00000","1.20042","0.20007"
"1.20042","25.87870","1.02491","130.66800","0.00000","1.20042","0.20007"
"1.20042","25.88686","1.02523","130.88800","0.00000","1.20042","0.20007"
"1.20042","25.88767","1.02527","131.10800","0.00000","1.20042","0.20007"
"1.20042","25.87585","1.02480","131.32800","0.00000","1.20042","0.20007"
"1.20042","25.87172","1.02464","131.54800","0.00000","1.20042","0.20007"
"1.20042","25.86318","1.02430","131.76800","0.00000","1.20042","0.20007"
"1.20042","25.86391","1.02433","131.98800","0.00000","1.20042","0.20007"
"1.20042","25.87047","1.02459","132.20800","0.00000","1.20042","0.20007"
"1.20042","25.87010","1.02457","132.42800","0.00000","1.20042","0.20007"
"1.20042","25.85854","1.02411","132.64800","0.00000","1.20042","0.20007"
"1.20042","25.86251","1.02427","132.86800","0.00000","1.20042","0.20007"
"1.20042","25.84862","1.02372","133.08800","0.00000","1.20042","0.20007"
"1.20042","25.85187","1.02385","133.30800","0.00000","1.20042","0.20007"
"1.20042","25.85368","1.02392","133.52800","0.00000","1.20042","0.20007"
"1.20042","25.85562","1.02400","133.74800","0.00000","1.20042","0.20007"
"1.20042","25.85131","1.02383","133.96800","0.00000","1.20042","0.20007"
"1.20042","25.84916","1.02374","134.18800","0.00000","1.20042","0.20007"
"1.20042","25.83273","1.02309","134.40800","0.00000","1.20042","0.20007"
"1.20042","25.83815","1.02331","134.62800","0.00000","1.20042","0.20007"
"1.20042","25.84030","1.02339","134.84800","0.00000","1.20042","0.20007"
"1.20042","25.83315","1.02311","135.06800","0.00000","1.20042","0.20007"
"1.20042","25.83570","1.02321","135.28800","0.00000","1.20042","0.20007"
"1.20042","25.82680","1.02286","135.50800","0.00000","1.20042","0.20007"
"1.20042","25.82975","1.02297","135.72800","0.00000","1.20042","0.20007"
"1.20042","25.82147","1.02265","135.94800","0.00000","1.20042","0.20007"
"1.20042","25.81972","1.02258","136.16800","0.00000","1.20042","0.20007"
"1.20042","25.81739","1.02248","136.38800","0.00000","1.20042","0.20007"
"1.20042","25.82051","1.02261","136.60800","0.00000","1.20042","0.20007"
"1.20042","25.82256","1.02269","136.82800","0.00000","1.20042","0.20007"
"1.20042","25.80889","1.02215","137.04800","0.00000","1.20042","0.20007"
"1.20042","25.81706","1.02247","137.26800","0.00000","1.20042","0.20007"
"1.20042","25.80390","1.02195","137.48800","0.00000","1.20042","0.20007"
"1.20042","25.80103","1.02184","137.70800","0.00000","1.20042","0.20007"
"1.20042","25.80569","1.02202","137.92800","0.00000","1.20042","0.20007"
"1.20042","25.80551","1.02201","138.14800","0.00000","1.20042","0.20007"
"1.20042","25.79841","1.02173","138.36800","0.00000","1.20042","0.20007"
"1.20042","25.79984","1.02179","138.58800","0.00000","1.20042","0.20007"
"1.20042","25.79514","1.02160","138.80800","0.00000","1.20042","0.20007"
"1.20042","25.78957","1.02138","139.02800","0.00000","1.20042","0.20007"
"1.20042","25.78735","1.02129","139.24800","0.00000","1.20042","0.20007"
"1.20042","25.78565","1.02123","139.46800","0.00000","1.20042","0.20007"
"1.20042","25.78322","1.02113","139.68800","0.00000","1.20042","0.20007"
"1.20042","25.78282","1.02111","139.90800","0.00000","1.20042","0.20007"
"1.20042","25.77732","1.02090","140.12800","0.00000","1.20042","0.20007"
"1.20042","25.77442","1.02078","140.34800","0.00000","1.20042","0.20007"
"1.20042","25.77553","1.02083","140.56800","0.00000","1.20042","0.20007"
"1.20042","25.77204","1.02069","140.78800","0.00000","1.20042","0.20007"
"1.20042","25.77142","1.02066","141.00800","0.00000","1.20042","0.20007"
"1.20042","25.77276","1.02072","141.22800","0.00000","1.20042","0.20007"
"1.20042","25.76793","1.02052","141.44800","0.00000","1.20042","0.20007"
"1.20042","25.76787","1.02052","141.66800","0.00000","1.20042","0.20007"
"1.20042","25.76538","1.02042","141.88800","0.00000","1.20042","0.20007"
"1.20042","25.75735","1.02011","142.10800","0.00000","1.20042","0.20007"
"1.20042","25.76112","1.02025","142.32800","0.00000","1.20042","0.20007"
"1.20042","25.76360","1.02035","142.54800","0.00000","1.20042","0.20007"
"1.20042","25.75523","1.02002","142.76800","0.00000","1.20042","0.20007"
"1.20042","25.75479","1.02000","142.98800","0.00000","1.20042","0.20007"
"1.20042","25.74706","1.01970","143.20800","0.00000","1.20042","0.20007"
"1.20042","25.74485","1.01961","143.42800","0.00000","1.20042","0.20007"
"1.20042","25.74541","1.01963","143.64800","0.00000","1.20042","0.20007"
"1.20042","25.74020","1.01943","143.86800","0.00000","1.20042","0.20007"
"1.20042","25.74017","1.01943","144.08800","0.00000","1.20042","0.20007"
"1.20042","25.73654","1.01928","144.30800","0.00000","1.20042","0.20007"
"1.20042","25.74081","1.01945","144.52800","0.00000","1.20042","0.20007"
"1.20042","25.74080","1.01945","144.74800","0.00000","1.20042","0.20007"
"1.20042","25.73574","1.01925","144.96800","0.00000","1.20042","0.20007"
"1.20042","25.72686","1.01890","145.18800","0.00000","1.20042","0.20007"
"1.20042","25.72894","1.01898","145.40800","0.00000","1.20042","0.20007"
"1.20042","25.72305","1.01875","145.62800","0.00000","1.20042","0.20007"
"1.20042","25.72528","1.01884","145.84800","0.00000","1.20042","0.20007"
"1.20042","25.72832","1.01896","146.06800","0.00000","1.20042","0.20007"
"1.20042","25.72169","1.01869","146.28800","0.00000","1.20042","0.20007"
"1.20042","25.71714","1.01851","146.50800","0.00000","1.20042","0.20007"
"1.20042","25.71389","1.01838","146.72800","0.00000","1.20042","0.20007"
"1.20042","25.71994","1.01862","146.94800","0.00000","1.20042","0.20007"
"1.20042","25.71486","1.01842","147.16800","0.00000","1.20042","0.20007"
"1.20042","25.70906","1.01819","147.38800","0.00000","1.20042","0.20007"
"1.20042","25.70841","1.01817","147.60800","0.00000","1.20042","0.20007"
"1.20042","25.70391","1.01799","147.82800","0.00000","1.20042","0.20007"
"1.20042","25.70802","1.01815","148.04800","0.00000","1.20042","0.20007"
"1.20042","25.70757","1.01813","148.26800","0.00000","1.20042","0.20007"
"1.20042","25.69925","1.01780","148.48800","0.00000","1.20042","0.20007"
"1.20042","25.69372","1.01759","148.70800","0.00000","1.20042","0.20007"
"1.20042","25.69126","1.01749","148.92800","0.00000","1.20042","0.20007"
"1.20042","25.69077","1.01747","149.14800","0.00000","1.20042","0.20007"
"1.20042","25.68861","1.01738","149.36800","0.00000","1.20042","0.20007"
"1.20042","25.69556","1.01766","149.58800","0.00000","1.20042","0.20007"
"1.20042","25.68852","1.01738","149.80800","0.00000","1.20042","0.20007"
"1.20042","25.68655","1.01730","149.99800","0.00000","1.20042","0.20007"