File: Rubber Stress Relaxation Raw Data - Small Samples-20210211/Specimen_RawData_6.csv
Specimen properties : Specimen label,"GBI2S1R3"
Specimen properties : Anvil height,"5.90000",mm
Specimen properties : Diameter,"5.62000",mm
Test : Rate 1,"24.00000",mm/min
Test : Start of hold value,"20.00000",%
Test : Duration,"120.00000",s

Extension,Load,Compressive stress,Time,PIP count,Compressive extension,Compressive strain (Extension)
(mm),(N),(MPa),(s),,(mm),(mm/mm)
"0.00000","-0.04479","-0.00181","0.00000","0.00000","0.00000","0.00000"
"0.06417","2.34766","0.09464","0.18000","0.00000","0.06417","0.01088"
"0.14146","4.54479","0.18321","0.36000","0.00000","0.14146","0.02398"
"0.21563","6.43528","0.25942","0.54000","0.00000","0.21563","0.03655"
"0.28854","8.20681","0.33084","0.72000","0.00000","0.28854","0.04891"
"0.36062","9.94475","0.40090","0.90000","0.00000","0.36062","0.06112"
"0.43271","11.66174","0.47011","1.08000","0.00000","0.43271","0.07334"
"0.50479","13.38460","0.53956","1.26000","0.00000","0.50479","0.08556"
"0.57625","15.09350","0.60845","1.44000","0.00000","0.57625","0.09767"
"0.64833","16.93443","0.68267","1.62000","0.00000","0.64833","0.10989"
"0.72104","18.81672","0.75854","1.80000","0.00000","0.72104","0.12221"
"0.79271","20.75458","0.83666","1.98000","0.00000","0.79271","0.13436"
"0.86458","22.88119","0.92239","2.16000","0.00000","0.86458","0.14654"
"0.93687","25.16369","1.01441","2.34000","0.00000","0.93687","0.15879"
"1.00854","27.64571","1.11446","2.52000","0.00000","1.00854","0.17094"
"1.08063","30.54408","1.23130","2.70000","0.00000","1.08063","0.18316"
"1.15292","33.94712","1.36849","2.88000","0.00000","1.15292","0.19541"
"1.18938","35.21810","1.41972","3.05000","0.00000","1.18938","0.20159"
"1.18875","33.58542","1.35391","3.23000","0.00000","1.18875","0.20148"
"1.18750","32.67991","1.31740","3.41000","0.00000","1.18750","0.20127"
"1.18521","31.95916","1.28835","3.59000","0.00000","1.18521","0.20088"
"1.18333","31.36868","1.26454","3.77000","0.00000","1.18333","0.20056"
"1.18208","30.94833","1.24760","3.95000","0.00000","1.18208","0.20035"
"1.18125","30.63457","1.23495","4.13000","0.00000","1.18125","0.20021"
"1.18083","30.37855","1.22463","4.31000","0.00000","1.18083","0.20014"
"1.18083","30.20282","1.21754","4.49000","0.00000","1.18083","0.20014"
"1.18063","30.03947","1.21096","4.67000","0.00000","1.18063","0.20011"
"1.18063","29.87240","1.20423","4.85000","0.00000","1.18063","0.20011"
"1.18063","29.72863","1.19843","5.03000","0.00000","1.18063","0.20011"
"1.18042","29.58964","1.19283","5.21000","0.00000","1.18042","0.20007"
"1.18042","29.46129","1.18765","5.39000","0.00000","1.18042","0.20007"
"1.18042","29.34762","1.18307","5.57000","0.00000","1.18042","0.20007"
"1.18042","29.25093","1.17917","5.75000","0.00000","1.18042","0.20007"
"1.18042","29.14405","1.17486","5.93000","0.00000","1.18042","0.20007"
"1.18042","29.06129","1.17153","6.11000","0.00000","1.18042","0.20007"
"1.18042","28.96887","1.16780","6.29000","0.00000","1.18042","0.20007"
"1.18042","28.88631","1.16447","6.47000","0.00000","1.18042","0.20007"
"1.18042","28.80167","1.16106","6.65000","0.00000","1.18042","0.20007"
"1.18042","28.72797","1.15809","6.83000","0.00000","1.18042","0.20007"
"1.18042","28.65861","1.15529","7.01000","0.00000","1.18042","0.20007"
"1.18042","28.59649","1.15279","7.19000","0.00000","1.18042","0.20007"
"1.18042","28.52515","1.14991","7.37000","0.00000","1.18042","0.20007"
"1.18042","28.46572","1.14752","7.55000","0.00000","1.18042","0.20007"
"1.18042","28.40637","1.14513","7.73000","0.00000","1.18042","0.20007"
"1.18042","28.34912","1.14282","7.91000","0.00000","1.18042","0.20007"
"1.18042","28.28920","1.14040","8.09000","0.00000","1.18042","0.20007"
"1.18042","28.24869","1.13877","8.27000","0.00000","1.18042","0.20007"
"1.18042","28.20096","1.13685","8.45000","0.00000","1.18042","0.20007"
"1.18042","28.14451","1.13457","8.63000","0.00000","1.18042","0.20007"
"1.18042","28.09975","1.13277","8.81000","0.00000","1.18042","0.20007"
"1.18042","28.05635","1.13102","8.99000","0.00000","1.18042","0.20007"
"1.18042","28.00649","1.12901","9.17000","0.00000","1.18042","0.20007"
"1.18042","27.96263","1.12724","9.35000","0.00000","1.18042","0.20007"
"1.18042","27.91379","1.12527","9.53000","0.00000","1.18042","0.20007"
"1.18042","27.87818","1.12383","9.71000","0.00000","1.18042","0.20007"
"1.18042","27.83900","1.12225","9.89000","0.00000","1.18042","0.20007"
"1.18083","27.83103","1.12193","10.07000","0.00000","1.18083","0.20014"
"1.18083","27.77816","1.11980","10.25000","0.00000","1.18083","0.20014"
"1.18083","27.74374","1.11841","10.43000","0.00000","1.18083","0.20014"
"1.18083","27.70830","1.11699","10.61000","0.00000","1.18083","0.20014"
"1.18083","27.66696","1.11532","10.79000","0.00000","1.18083","0.20014"
"1.18083","27.63522","1.11404","10.97000","0.00000","1.18083","0.20014"
"1.18083","27.60769","1.11293","11.15000","0.00000","1.18083","0.20014"
"1.18083","27.56510","1.11121","11.33000","0.00000","1.18083","0.20014"
"1.18083","27.53429","1.10997","11.51000","0.00000","1.18083","0.20014"
"1.18083","27.49367","1.10833","11.69000","0.00000","1.18083","0.20014"
"1.18083","27.45671","1.10684","11.87000","0.00000","1.18083","0.20014"
"1.18083","27.43724","1.10606","12.05000","0.00000","1.18083","0.20014"
"1.18083","27.40902","1.10492","12.23000","0.00000","1.18083","0.20014"
"1.18083","27.37899","1.10371","12.41000","0.00000","1.18083","0.20014"
"1.18083","27.35972","1.10293","12.59000","0.00000","1.18083","0.20014"
"1.18083","27.32659","1.10160","12.77000","0.00000","1.18083","0.20014"
"1.18083","27.30393","1.10068","12.95000","0.00000","1.18083","0.20014"
"1.18083","27.28074","1.09975","13.13000","0.00000","1.18083","0.20014"
"1.18083","27.24443","1.09829","13.31000","0.00000","1.18083","0.20014"
"1.18083","27.23002","1.09770","13.49000","0.00000","1.18083","0.20014"
"1.18083","27.20126","1.09655","13.67000","0.00000","1.18083","0.20014"
"1.18083","27.17449","1.09547","13.85000","0.00000","1.18083","0.20014"
"1.18083","27.15205","1.09456","14.03000","0.00000","1.18083","0.20014"
"1.18083","27.13851","1.09402","14.21000","0.00000","1.18083","0.20014"
"1.18083","27.10271","1.09257","14.39000","0.00000","1.18083","0.20014"
"1.18083","27.08819","1.09199","14.57000","0.00000","1.18083","0.20014"
"1.18083","27.06665","1.09112","14.75000","0.00000","1.18083","0.20014"
"1.18083","27.03604","1.08988","14.93000","0.00000","1.18083","0.20014"
"1.18083","27.01218","1.08892","15.11000","0.00000","1.18083","0.20014"
"1.18083","26.97560","1.08745","15.29000","0.00000","1.18083","0.20014"
"1.18083","26.96391","1.08698","15.47000","0.00000","1.18083","0.20014"
"1.18083","26.95453","1.08660","15.65000","0.00000","1.18083","0.20014"
"1.18083","26.94292","1.08613","15.83000","0.00000","1.18083","0.20014"
"1.18083","26.91621","1.08505","16.01000","0.00000","1.18083","0.20014"
"1.18083","26.89318","1.08413","16.19000","0.00000","1.18083","0.20014"
"1.18083","26.87272","1.08330","16.37000","0.00000","1.18083","0.20014"
"1.18083","26.85683","1.08266","16.55000","0.00000","1.18083","0.20014"
"1.18083","26.84073","1.08201","16.73000","0.00000","1.18083","0.20014"
"1.18083","26.81718","1.08106","16.91000","0.00000","1.18083","0.20014"
"1.18083","26.80806","1.08069","17.09000","0.00000","1.18083","0.20014"
"1.18083","26.78972","1.07995","17.27000","0.00000","1.18083","0.20014"
"1.18083","26.77255","1.07926","17.45000","0.00000","1.18083","0.20014"
"1.18083","26.74311","1.07808","17.63000","0.00000","1.18083","0.20014"
"1.18083","26.74033","1.07796","17.81000","0.00000","1.18083","0.20014"
"1.18083","26.71660","1.07701","17.99000","0.00000","1.18083","0.20014"
"1.18083","26.69769","1.07625","18.17000","0.00000","1.18083","0.20014"
"1.18083","26.68760","1.07584","18.35000","0.00000","1.18083","0.20014"
"1.18083","26.66899","1.07509","18.53000","0.00000","1.18083","0.20014"
"1.18083","26.65076","1.07435","18.71000","0.00000","1.18083","0.20014"
"1.18083","26.63708","1.07380","18.89000","0.00000","1.18083","0.20014"
"1.18083","26.62245","1.07321","19.07000","0.00000","1.18083","0.20014"
"1.18083","26.61230","1.07280","19.25000","0.00000","1.18083","0.20014"
"1.18083","26.58697","1.07178","19.43000","0.00000","1.18083","0.20014"
"1.18083","26.57823","1.07143","19.61000","0.00000","1.18083","0.20014"
"1.18083","26.56237","1.07079","19.79000","0.00000","1.18083","0.20014"
"1.18083","26.54984","1.07028","19.97000","0.00000","1.18083","0.20014"
"1.18083","26.53824","1.06982","20.15000","0.00000","1.18083","0.20014"
"1.18083","26.51887","1.06904","20.33000","0.00000","1.18083","0.20014"
"1.18083","26.49776","1.06819","20.51000","0.00000","1.18083","0.20014"
"1.18083","26.50417","1.06844","20.69000","0.00000","1.18083","0.20014"
"1.18083","26.49129","1.06792","20.87000","0.00000","1.18083","0.20014"
"1.18083","26.46147","1.06672","21.05000","0.00000","1.18083","0.20014"
"1.18083","26.44983","1.06625","21.23000","0.00000","1.18083","0.20014"
"1.18083","26.43750","1.06576","21.41000","0.00000","1.18083","0.20014"
"1.18083","26.42758","1.06536","21.59000","0.00000","1.18083","0.20014"
"1.18083","26.41676","1.06492","21.77000","0.00000","1.18083","0.20014"
"1.18083","26.39924","1.06421","21.95000","0.00000","1.18083","0.20014"
"1.18083","26.38979","1.06383","22.13000","0.00000","1.18083","0.20014"
"1.18083","26.37482","1.06323","22.31000","0.00000","1.18083","0.20014"
"1.18083","26.36580","1.06287","22.49000","0.00000","1.18083","0.20014"
"1.18083","26.34890","1.06218","22.67000","0.00000","1.18083","0.20014"
"1.18083","26.33709","1.06171","22.85000","0.00000","1.18083","0.20014"
"1.18083","26.32425","1.06119","23.03000","0.00000","1.18083","0.20014"
"1.18083","26.32537","1.06124","23.21000","0.00000","1.18083","0.20014"
"1.18083","26.31124","1.06067","23.39000","0.00000","1.18083","0.20014"
"1.18083","26.29504","1.06001","23.57000","0.00000","1.18083","0.20014"
"1.18083","26.27481","1.05920","23.75000","0.00000","1.18083","0.20014"
"1.18083","26.27003","1.05901","23.93000","0.00000","1.18083","0.20014"
"1.18083","26.26051","1.05862","24.11000","0.00000","1.18083","0.20014"
"1.18083","26.25193","1.05828","24.29000","0.00000","1.18083","0.20014"
"1.18083","26.22791","1.05731","24.47000","0.00000","1.18083","0.20014"
"1.18083","26.22422","1.05716","24.65000","0.00000","1.18083","0.20014"
"1.18083","26.21416","1.05675","24.83000","0.00000","1.18083","0.20014"
"1.18083","26.20642","1.05644","25.01000","0.00000","1.18083","0.20014"
"1.18083","26.18809","1.05570","25.19000","0.00000","1.18083","0.20014"
"1.18083","26.18426","1.05555","25.37000","0.00000","1.18083","0.20014"
"1.18083","26.17364","1.05512","25.55000","0.00000","1.18083","0.20014"
"1.18083","26.16260","1.05467","25.73000","0.00000","1.18083","0.20014"
"1.18083","26.15280","1.05428","25.91000","0.00000","1.18083","0.20014"
"1.18083","26.13570","1.05359","26.09000","0.00000","1.18083","0.20014"
"1.18083","26.11836","1.05289","26.27000","0.00000","1.18083","0.20014"
"1.18083","26.12707","1.05324","26.45000","0.00000","1.18083","0.20014"
"1.18083","26.12685","1.05323","26.63000","0.00000","1.18083","0.20014"
"1.18083","26.09810","1.05207","26.81000","0.00000","1.18083","0.20014"
"1.18083","26.09474","1.05194","26.99000","0.00000","1.18083","0.20014"
"1.18083","26.07850","1.05128","27.17000","0.00000","1.18083","0.20014"
"1.18083","26.07484","1.05114","27.35000","0.00000","1.18083","0.20014"
"1.18083","26.06162","1.05060","27.53000","0.00000","1.18083","0.20014"
"1.18083","26.05651","1.05040","27.71000","0.00000","1.18083","0.20014"
"1.18083","26.04671","1.05000","27.89000","0.00000","1.18083","0.20014"
"1.18083","26.03096","1.04937","28.07000","0.00000","1.18083","0.20014"
"1.18083","26.02651","1.04919","28.25000","0.00000","1.18083","0.20014"
"1.18083","26.01635","1.04878","28.43000","0.00000","1.18083","0.20014"
"1.18083","26.00687","1.04840","28.61000","0.00000","1.18083","0.20014"
"1.18083","26.00214","1.04821","28.79000","0.00000","1.18083","0.20014"
"1.18083","25.98932","1.04769","28.97000","0.00000","1.18083","0.20014"
"1.18083","25.98066","1.04734","29.15000","0.00000","1.18083","0.20014"
"1.18083","25.97548","1.04713","29.33000","0.00000","1.18083","0.20014"
"1.18083","25.95959","1.04649","29.51000","0.00000","1.18083","0.20014"
"1.18083","25.95082","1.04614","29.69000","0.00000","1.18083","0.20014"
"1.18083","25.95632","1.04636","29.87000","0.00000","1.18083","0.20014"
"1.18083","25.93961","1.04568","30.05000","0.00000","1.18083","0.20014"
"1.18083","25.92867","1.04524","30.23000","0.00000","1.18083","0.20014"
"1.18083","25.92209","1.04498","30.41000","0.00000","1.18083","0.20014"
"1.18083","25.92266","1.04500","30.59000","0.00000","1.18083","0.20014"
"1.18083","25.91172","1.04456","30.77000","0.00000","1.18083","0.20014"
"1.18083","25.89801","1.04401","30.95000","0.00000","1.18083","0.20014"
"1.18083","25.89065","1.04371","31.13000","0.00000","1.18083","0.20014"
"1.18083","25.88317","1.04341","31.31000","0.00000","1.18083","0.20014"
"1.18083","25.87330","1.04301","31.49000","0.00000","1.18083","0.20014"
"1.18083","25.86668","1.04274","31.67000","0.00000","1.18083","0.20014"
"1.18083","25.85689","1.04235","31.85000","0.00000","1.18083","0.20014"
"1.18083","25.85475","1.04226","32.03000","0.00000","1.18083","0.20014"
"1.18083","25.85579","1.04231","32.21000","0.00000","1.18083","0.20014"
"1.18083","25.84236","1.04176","32.39000","0.00000","1.18083","0.20014"
"1.18083","25.82826","1.04120","32.57000","0.00000","1.18083","0.20014"
"1.18083","25.82444","1.04104","32.75000","0.00000","1.18083","0.20014"
"1.18083","25.81767","1.04077","32.93000","0.00000","1.18083","0.20014"
"1.18083","25.81266","1.04057","33.11000","0.00000","1.18083","0.20014"
"1.18083","25.80207","1.04014","33.29000","0.00000","1.18083","0.20014"
"1.18083","25.79309","1.03978","33.47000","0.00000","1.18083","0.20014"
"1.18083","25.78643","1.03951","33.65000","0.00000","1.18083","0.20014"
"1.18083","25.77615","1.03910","33.83000","0.00000","1.18083","0.20014"
"1.18083","25.77412","1.03901","34.01000","0.00000","1.18083","0.20014"
"1.18083","25.76506","1.03865","34.19000","0.00000","1.18083","0.20014"
"1.18083","25.76089","1.03848","34.37000","0.00000","1.18083","0.20014"
"1.18083","25.75341","1.03818","34.55000","0.00000","1.18083","0.20014"
"1.18083","25.74217","1.03773","34.73000","0.00000","1.18083","0.20014"
"1.18083","25.73923","1.03761","34.91000","0.00000","1.18083","0.20014"
"1.18083","25.72868","1.03718","35.09000","0.00000","1.18083","0.20014"
"1.18083","25.72485","1.03703","35.27000","0.00000","1.18083","0.20014"
"1.18083","25.71613","1.03668","35.45000","0.00000","1.18083","0.20014"
"1.18083","25.70866","1.03637","35.63000","0.00000","1.18083","0.20014"
"1.18083","25.70570","1.03626","35.81000","0.00000","1.18083","0.20014"
"1.18083","25.69413","1.03579","35.99000","0.00000","1.18083","0.20014"
"1.18083","25.69127","1.03567","36.17000","0.00000","1.18083","0.20014"
"1.18083","25.68707","1.03550","36.35000","0.00000","1.18083","0.20014"
"1.18083","25.68565","1.03545","36.53000","0.00000","1.18083","0.20014"
"1.18083","25.66731","1.03471","36.71000","0.00000","1.18083","0.20014"
"1.18083","25.66121","1.03446","36.89000","0.00000","1.18083","0.20014"
"1.18083","25.66873","1.03477","37.07000","0.00000","1.18083","0.20014"
"1.18083","25.65576","1.03424","37.25000","0.00000","1.18083","0.20014"
"1.18083","25.64290","1.03372","37.43000","0.00000","1.18083","0.20014"
"1.18083","25.63004","1.03321","37.61000","0.00000","1.18083","0.20014"
"1.18083","25.62836","1.03314","37.79000","0.00000","1.18083","0.20014"
"1.18083","25.63403","1.03337","37.97000","0.00000","1.18083","0.20014"
"1.18083","25.62708","1.03309","38.15000","0.00000","1.18083","0.20014"
"1.18083","25.61423","1.03257","38.33000","0.00000","1.18083","0.20014"
"1.18083","25.61329","1.03253","38.51000","0.00000","1.18083","0.20014"
"1.18083","25.60601","1.03224","38.69000","0.00000","1.18083","0.20014"
"1.18083","25.59791","1.03191","38.87000","0.00000","1.18083","0.20014"
"1.18083","25.59157","1.03165","39.05000","0.00000","1.18083","0.20014"
"1.18083","25.59214","1.03168","39.23000","0.00000","1.18083","0.20014"
"1.18083","25.58398","1.03135","39.41000","0.00000","1.18083","0.20014"
"1.18083","25.57442","1.03096","39.59000","0.00000","1.18083","0.20014"
"1.18083","25.57265","1.03089","39.77000","0.00000","1.18083","0.20014"
"1.18083","25.55767","1.03029","39.95000","0.00000","1.18083","0.20014"
"1.18083","25.55663","1.03025","40.13000","0.00000","1.18083","0.20014"
"1.18083","25.55129","1.03003","40.31000","0.00000","1.18083","0.20014"
"1.18083","25.51932","1.02874","40.49000","0.00000","1.18083","0.20014"
"1.18083","25.53747","1.02947","40.67000","0.00000","1.18083","0.20014"
"1.18083","25.54196","1.02966","40.85000","0.00000","1.18083","0.20014"
"1.18083","25.54070","1.02960","41.03000","0.00000","1.18083","0.20014"
"1.18083","25.52983","1.02917","41.21000","0.00000","1.18083","0.20014"
"1.18083","25.51266","1.02847","41.39000","0.00000","1.18083","0.20014"
"1.18083","25.51388","1.02852","41.57000","0.00000","1.18083","0.20014"
"1.18083","25.50312","1.02809","41.75000","0.00000","1.18083","0.20014"
"1.18083","25.50282","1.02808","41.93000","0.00000","1.18083","0.20014"
"1.18083","25.49330","1.02769","42.11000","0.00000","1.18083","0.20014"
"1.18083","25.48775","1.02747","42.29000","0.00000","1.18083","0.20014"
"1.18083","25.49466","1.02775","42.47000","0.00000","1.18083","0.20014"
"1.18083","25.48210","1.02724","42.65000","0.00000","1.18083","0.20014"
"1.18083","25.48486","1.02735","42.83000","0.00000","1.18083","0.20014"
"1.18083","25.47230","1.02685","43.01000","0.00000","1.18083","0.20014"
"1.18083","25.46343","1.02649","43.19000","0.00000","1.18083","0.20014"
"1.18083","25.46130","1.02640","43.37000","0.00000","1.18083","0.20014"
"1.18083","25.45675","1.02622","43.55000","0.00000","1.18083","0.20014"
"1.18083","25.45265","1.02605","43.73000","0.00000","1.18083","0.20014"
"1.18083","25.44879","1.02590","43.91000","0.00000","1.18083","0.20014"
"1.18083","25.44384","1.02570","44.09000","0.00000","1.18083","0.20014"
"1.18083","25.43556","1.02537","44.27000","0.00000","1.18083","0.20014"
"1.18083","25.42229","1.02483","44.45000","0.00000","1.18083","0.20014"
"1.18083","25.42341","1.02488","44.63000","0.00000","1.18083","0.20014"
"1.18083","25.43460","1.02533","44.81000","0.00000","1.18083","0.20014"
"1.18083","25.41629","1.02459","44.99000","0.00000","1.18083","0.20014"
"1.18083","25.40647","1.02419","45.17000","0.00000","1.18083","0.20014"
"1.18083","25.40814","1.02426","45.35000","0.00000","1.18083","0.20014"
"1.18083","25.40632","1.02419","45.53000","0.00000","1.18083","0.20014"
"1.18083","25.39690","1.02381","45.71000","0.00000","1.18083","0.20014"
"1.18083","25.39861","1.02388","45.89000","0.00000","1.18083","0.20014"
"1.18083","25.39224","1.02362","46.07000","0.00000","1.18083","0.20014"
"1.18083","25.38625","1.02338","46.25000","0.00000","1.18083","0.20014"
"1.18083","25.38568","1.02336","46.43000","0.00000","1.18083","0.20014"
"1.18083","25.36963","1.02271","46.61000","0.00000","1.18083","0.20014"
"1.18083","25.36398","1.02248","46.79000","0.00000","1.18083","0.20014"
"1.18083","25.36049","1.02234","46.97000","0.00000","1.18083","0.20014"
"1.18083","25.36855","1.02266","47.15000","0.00000","1.18083","0.20014"
"1.18083","25.36764","1.02263","47.33000","0.00000","1.18083","0.20014"
"1.18083","25.35131","1.02197","47.51000","0.00000","1.18083","0.20014"
"1.18083","25.35080","1.02195","47.69000","0.00000","1.18083","0.20014"
"1.18083","25.34656","1.02178","47.87000","0.00000","1.18083","0.20014"
"1.18083","25.34150","1.02157","48.05000","0.00000","1.18083","0.20014"
"1.18083","25.34129","1.02157","48.23000","0.00000","1.18083","0.20014"
"1.18083","25.33532","1.02132","48.41000","0.00000","1.18083","0.20014"
"1.18083","25.32242","1.02080","48.59000","0.00000","1.18083","0.20014"
"1.18083","25.31629","1.02056","48.77000","0.00000","1.18083","0.20014"
"1.18083","25.31169","1.02037","48.95000","0.00000","1.18083","0.20014"
"1.18083","25.31396","1.02046","49.13000","0.00000","1.18083","0.20014"
"1.18083","25.30626","1.02015","49.31000","0.00000","1.18083","0.20014"
"1.18083","25.30049","1.01992","49.49000","0.00000","1.18083","0.20014"
"1.18083","25.30002","1.01990","49.67000","0.00000","1.18083","0.20014"
"1.18083","25.28739","1.01939","49.85000","0.00000","1.18083","0.20014"
"1.18083","25.28813","1.01942","50.03000","0.00000","1.18083","0.20014"
"1.18083","25.28720","1.01939","50.21000","0.00000","1.18083","0.20014"
"1.18083","25.28854","1.01944","50.39000","0.00000","1.18083","0.20014"
"1.18083","25.27472","1.01888","50.57000","0.00000","1.18083","0.20014"
"1.18083","25.27875","1.01904","50.75000","0.00000","1.18083","0.20014"
"1.18083","25.26311","1.01841","50.93000","0.00000","1.18083","0.20014"
"1.18083","25.27139","1.01875","51.11000","0.00000","1.18083","0.20014"
"1.18083","25.25831","1.01822","51.29000","0.00000","1.18083","0.20014"
"1.18083","25.26073","1.01832","51.47000","0.00000","1.18083","0.20014"
"1.18083","25.25103","1.01793","51.65000","0.00000","1.18083","0.20014"
"1.18083","25.24809","1.01781","51.83000","0.00000","1.18083","0.20014"
"1.18083","25.23891","1.01744","52.01000","0.00000","1.18083","0.20014"
"1.18083","25.23607","1.01732","52.19000","0.00000","1.18083","0.20014"
"1.18083","25.24377","1.01763","52.37000","0.00000","1.18083","0.20014"
"1.18083","25.22105","1.01672","52.55000","0.00000","1.18083","0.20014"
"1.18083","25.21898","1.01663","52.73000","0.00000","1.18083","0.20014"
"1.18083","25.21051","1.01629","52.91000","0.00000","1.18083","0.20014"
"1.18083","25.22576","1.01691","53.09000","0.00000","1.18083","0.20014"
"1.18083","25.23006","1.01708","53.27000","0.00000","1.18083","0.20014"
"1.18083","25.22052","1.01670","53.45000","0.00000","1.18083","0.20014"
"1.18083","25.20773","1.01618","53.63000","0.00000","1.18083","0.20014"
"1.18083","25.19932","1.01584","53.81000","0.00000","1.18083","0.20014"
"1.18083","25.19795","1.01579","53.99000","0.00000","1.18083","0.20014"
"1.18083","25.19590","1.01570","54.17000","0.00000","1.18083","0.20014"
"1.18083","25.18499","1.01526","54.35000","0.00000","1.18083","0.20014"
"1.18083","25.18523","1.01527","54.53000","0.00000","1.18083","0.20014"
"1.18083","25.17778","1.01497","54.71000","0.00000","1.18083","0.20014"
"1.18083","25.18632","1.01532","54.89000","0.00000","1.18083","0.20014"
"1.18083","25.17864","1.01501","55.07000","0.00000","1.18083","0.20014"
"1.18083","25.18293","1.01518","55.25000","0.00000","1.18083","0.20014"
"1.18083","25.17179","1.01473","55.43000","0.00000","1.18083","0.20014"
"1.18083","25.16069","1.01429","55.61000","0.00000","1.18083","0.20014"
"1.18083","25.16560","1.01448","55.79000","0.00000","1.18083","0.20014"
"1.18083","25.16333","1.01439","55.97000","0.00000","1.18083","0.20014"
"1.18083","25.15686","1.01413","56.15000","0.00000","1.18083","0.20014"
"1.18083","25.15252","1.01396","56.33000","0.00000","1.18083","0.20014"
"1.18083","25.14826","1.01378","56.51000","0.00000","1.18083","0.20014"
"1.18083","25.14445","1.01363","56.69000","0.00000","1.18083","0.20014"
"1.18083","25.13366","1.01320","56.87000","0.00000","1.18083","0.20014"
"1.18083","25.13443","1.01323","57.05000","0.00000","1.18083","0.20014"
"1.18083","25.13462","1.01323","57.23000","0.00000","1.18083","0.20014"
"1.18083","25.12833","1.01298","57.41000","0.00000","1.18083","0.20014"
"1.18083","25.12259","1.01275","57.59000","0.00000","1.18083","0.20014"
"1.18083","25.11859","1.01259","57.77000","0.00000","1.18083","0.20014"
"1.18083","25.11996","1.01264","57.95000","0.00000","1.18083","0.20014"
"1.18083","25.11836","1.01258","58.13000","0.00000","1.18083","0.20014"
"1.18083","25.11924","1.01261","58.31000","0.00000","1.18083","0.20014"
"1.18083","25.11591","1.01248","58.49000","0.00000","1.18083","0.20014"
"1.18083","25.09721","1.01173","58.67000","0.00000","1.18083","0.20014"
"1.18083","25.09693","1.01171","58.85000","0.00000","1.18083","0.20014"
"1.18083","25.09113","1.01148","59.03000","0.00000","1.18083","0.20014"
"1.18083","25.09835","1.01177","59.21000","0.00000","1.18083","0.20014"
"1.18083","25.09726","1.01173","59.39000","0.00000","1.18083","0.20014"
"1.18083","25.10773","1.01215","59.57000","0.00000","1.18083","0.20014"
"1.18083","25.10550","1.01206","59.75000","0.00000","1.18083","0.20014"
"1.18083","25.06747","1.01053","59.93000","0.00000","1.18083","0.20014"
"1.18083","25.06182","1.01030","60.11000","0.00000","1.18083","0.20014"
"1.18083","25.06534","1.01044","60.29000","0.00000","1.18083","0.20014"
"1.18083","25.07262","1.01073","60.47000","0.00000","1.18083","0.20014"
"1.18083","25.07687","1.01091","60.65000","0.00000","1.18083","0.20014"
"1.18083","25.08139","1.01109","60.83000","0.00000","1.18083","0.20014"
"1.18083","25.06333","1.01036","61.01000","0.00000","1.18083","0.20014"
"1.18083","25.05250","1.00992","61.19000","0.00000","1.18083","0.20014"
"1.18083","25.05176","1.00989","61.37000","0.00000","1.18083","0.20014"
"1.18083","25.04528","1.00963","61.55000","0.00000","1.18083","0.20014"
"1.18083","25.04979","1.00981","61.73000","0.00000","1.18083","0.20014"
"1.18083","25.04954","1.00980","61.91000","0.00000","1.18083","0.20014"
"1.18083","25.03741","1.00932","62.09000","0.00000","1.18083","0.20014"
"1.18083","25.03304","1.00914","62.27000","0.00000","1.18083","0.20014"
"1.18083","25.02850","1.00896","62.45000","0.00000","1.18083","0.20014"
"1.18083","25.02256","1.00872","62.63000","0.00000","1.18083","0.20014"
"1.18083","25.03500","1.00922","62.81000","0.00000","1.18083","0.20014"
"1.18083","25.02798","1.00894","62.99000","0.00000","1.18083","0.20014"
"1.18083","25.02594","1.00885","63.17000","0.00000","1.18083","0.20014"
"1.18083","25.01770","1.00852","63.35000","0.00000","1.18083","0.20014"
"1.18083","25.01405","1.00837","63.53000","0.00000","1.18083","0.20014"
"1.18083","25.01181","1.00828","63.71000","0.00000","1.18083","0.20014"
"1.18083","25.01166","1.00828","63.89000","0.00000","1.18083","0.20014"
"1.18083","25.00080","1.00784","64.07000","0.00000","1.18083","0.20014"
"1.18083","25.00534","1.00802","64.25000","0.00000","1.18083","0.20014"
"1.18083","25.00943","1.00819","64.43000","0.00000","1.18083","0.20014"
"1.18083","24.99485","1.00760","64.61000","0.00000","1.18083","0.20014"
"1.18083","24.99759","1.00771","64.79000","0.00000","1.18083","0.20014"
"1.18083","24.99424","1.00758","64.97000","0.00000","1.18083","0.20014"
"1.18083","24.98876","1.00735","65.15000","0.00000","1.18083","0.20014"
"1.18083","24.97405","1.00676","65.33000","0.00000","1.18083","0.20014"
"1.18083","24.98268","1.00711","65.51000","0.00000","1.18083","0.20014"
"1.18083","24.97604","1.00684","65.69000","0.00000","1.18083","0.20014"
"1.18083","24.97643","1.00686","65.87000","0.00000","1.18083","0.20014"
"1.18083","24.97306","1.00672","66.05000","0.00000","1.18083","0.20014"
"1.18083","24.96303","1.00632","66.23000","0.00000","1.18083","0.20014"
"1.18083","24.97226","1.00669","66.41000","0.00000","1.18083","0.20014"
"1.18083","24.96026","1.00621","66.59000","0.00000","1.18083","0.20014"
"1.18083","24.96000","1.00619","66.77000","0.00000","1.18083","0.20014"
"1.18083","24.95670","1.00606","66.95000","0.00000","1.18083","0.20014"
"1.18083","24.96045","1.00621","67.13000","0.00000","1.18083","0.20014"
"1.18083","24.94756","1.00569","67.31000","0.00000","1.18083","0.20014"
"1.18083","24.94610","1.00563","67.49000","0.00000","1.18083","0.20014"
"1.18083","24.94093","1.00543","67.67000","0.00000","1.18083","0.20014"
"1.18083","24.93751","1.00529","67.85000","0.00000","1.18083","0.20014"
"1.18083","24.94371","1.00554","68.03000","0.00000","1.18083","0.20014"
"1.18083","24.93761","1.00529","68.21000","0.00000","1.18083","0.20014"
"1.18083","24.93324","1.00512","68.39000","0.00000","1.18083","0.20014"
"1.18083","24.93471","1.00518","68.57000","0.00000","1.18083","0.20014"
"1.18083","24.92972","1.00497","68.75000","0.00000","1.18083","0.20014"
"1.18083","24.93128","1.00504","68.93000","0.00000","1.18083","0.20014"
"1.18083","24.92896","1.00494","69.11000","0.00000","1.18083","0.20014"
"1.18083","24.91663","1.00445","69.29000","0.00000","1.18083","0.20014"
"1.18083","24.91960","1.00457","69.47000","0.00000","1.18083","0.20014"
"1.18083","24.92219","1.00467","69.65000","0.00000","1.18083","0.20014"
"1.18083","24.90789","1.00409","69.83000","0.00000","1.18083","0.20014"
"1.18083","24.91468","1.00437","70.01000","0.00000","1.18083","0.20014"
"1.18083","24.91317","1.00431","70.19000","0.00000","1.18083","0.20014"
"1.18083","24.89716","1.00366","70.37000","0.00000","1.18083","0.20014"
"1.18083","24.91139","1.00424","70.55000","0.00000","1.18083","0.20014"
"1.18083","24.89880","1.00373","70.73000","0.00000","1.18083","0.20014"
"1.18083","24.89940","1.00375","70.91000","0.00000","1.18083","0.20014"
"1.18083","24.89545","1.00359","71.09000","0.00000","1.18083","0.20014"
"1.18083","24.88740","1.00327","71.27000","0.00000","1.18083","0.20014"
"1.18083","24.89006","1.00338","71.45000","0.00000","1.18083","0.20014"
"1.18083","24.88857","1.00332","71.63000","0.00000","1.18083","0.20014"
"1.18083","24.87964","1.00296","71.81000","0.00000","1.18083","0.20014"
"1.18083","24.87800","1.00289","71.99000","0.00000","1.18083","0.20014"
"1.18083","24.89165","1.00344","72.17000","0.00000","1.18083","0.20014"
"1.18083","24.88512","1.00318","72.35000","0.00000","1.18083","0.20014"
"1.18083","24.88145","1.00303","72.53000","0.00000","1.18083","0.20014"
"1.18083","24.88303","1.00309","72.71000","0.00000","1.18083","0.20014"
"1.18083","24.88268","1.00308","72.89000","0.00000","1.18083","0.20014"
"1.18083","24.86605","1.00241","73.07000","0.00000","1.18083","0.20014"
"1.18083","24.86501","1.00237","73.25000","0.00000","1.18083","0.20014"
"1.18083","24.85786","1.00208","73.43000","0.00000","1.18083","0.20014"
"1.18083","24.85553","1.00198","73.61000","0.00000","1.18083","0.20014"
"1.18083","24.85600","1.00200","73.79000","0.00000","1.18083","0.20014"
"1.18083","24.84663","1.00162","73.97000","0.00000","1.18083","0.20014"
"1.18083","24.84361","1.00150","74.15000","0.00000","1.18083","0.20014"
"1.18083","24.84595","1.00160","74.33000","0.00000","1.18083","0.20014"
"1.18083","24.84086","1.00139","74.51000","0.00000","1.18083","0.20014"
"1.18083","24.83283","1.00107","74.69000","0.00000","1.18083","0.20014"
"1.18083","24.84209","1.00144","74.87000","0.00000","1.18083","0.20014"
"1.18083","24.83812","1.00128","75.05000","0.00000","1.18083","0.20014"
"1.18083","24.82479","1.00074","75.23000","0.00000","1.18083","0.20014"
"1.18083","24.82630","1.00080","75.41000","0.00000","1.18083","0.20014"
"1.18083","24.82875","1.00090","75.59000","0.00000","1.18083","0.20014"
"1.18083","24.82784","1.00087","75.77000","0.00000","1.18083","0.20014"
"1.18083","24.82134","1.00060","75.95000","0.00000","1.18083","0.20014"
"1.18083","24.82755","1.00086","76.13000","0.00000","1.18083","0.20014"
"1.18083","24.81823","1.00048","76.31000","0.00000","1.18083","0.20014"
"1.18083","24.81277","1.00026","76.49000","0.00000","1.18083","0.20014"
"1.18083","24.81163","1.00021","76.67000","0.00000","1.18083","0.20014"
"1.18083","24.80054","0.99977","76.85000","0.00000","1.18083","0.20014"
"1.18083","24.80974","1.00014","77.03000","0.00000","1.18083","0.20014"
"1.18083","24.79587","0.99958","77.21000","0.00000","1.18083","0.20014"
"1.18083","24.80488","0.99994","77.39000","0.00000","1.18083","0.20014"
"1.18083","24.79383","0.99950","77.57000","0.00000","1.18083","0.20014"
"1.18083","24.80491","0.99994","77.75000","0.00000","1.18083","0.20014"
"1.18083","24.79579","0.99958","77.93000","0.00000","1.18083","0.20014"
"1.18083","24.80193","0.99982","78.11000","0.00000","1.18083","0.20014"
"1.18083","24.80124","0.99979","78.29000","0.00000","1.18083","0.20014"
"1.18083","24.79756","0.99965","78.47000","0.00000","1.18083","0.20014"
"1.18083","24.79973","0.99973","78.65000","0.00000","1.18083","0.20014"
"1.18083","24.78849","0.99928","78.83000","0.00000","1.18083","0.20014"
"1.18083","24.78295","0.99906","79.01000","0.00000","1.18083","0.20014"
"1.18083","24.77946","0.99892","79.19000","0.00000","1.18083","0.20014"
"1.18083","24.78006","0.99894","79.37000","0.00000","1.18083","0.20014"
"1.18083","24.76904","0.99850","79.55000","0.00000","1.18083","0.20014"
"1.18083","24.77742","0.99883","79.73000","0.00000","1.18083","0.20014"
"1.18083","24.77541","0.99875","79.91000","0.00000","1.18083","0.20014"
"1.18083","24.77083","0.99857","80.09000","0.00000","1.18083","0.20014"
"1.18083","24.75379","0.99788","80.27000","0.00000","1.18083","0.20014"
"1.18083","24.75296","0.99785","80.45000","0.00000","1.18083","0.20014"
"1.18083","24.74960","0.99771","80.63000","0.00000","1.18083","0.20014"
"1.18083","24.75589","0.99797","80.81000","0.00000","1.18083","0.20014"
"1.18083","24.75465","0.99792","80.99000","0.00000","1.18083","0.20014"
"1.18083","24.75533","0.99794","81.17000","0.00000","1.18083","0.20014"
"1.18083","24.74178","0.99740","81.35000","0.00000","1.18083","0.20014"
"1.18083","24.74962","0.99771","81.53000","0.00000","1.18083","0.20014"
"1.18083","24.74731","0.99762","81.71000","0.00000","1.18083","0.20014"
"1.18083","24.74470","0.99752","81.89000","0.00000","1.18083","0.20014"
"1.18083","24.74390","0.99748","82.07000","0.00000","1.18083","0.20014"
"1.18083","24.74148","0.99739","82.25000","0.00000","1.18083","0.20014"
"1.18083","24.72547","0.99674","82.43000","0.00000","1.18083","0.20014"
"1.18083","24.71874","0.99647","82.61000","0.00000","1.18083","0.20014"
"1.18083","24.71714","0.99640","82.79000","0.00000","1.18083","0.20014"
"1.18083","24.72456","0.99670","82.97000","0.00000","1.18083","0.20014"
"1.18083","24.71226","0.99621","83.15000","0.00000","1.18083","0.20014"
"1.18083","24.71944","0.99650","83.33000","0.00000","1.18083","0.20014"
"1.18083","24.71043","0.99613","83.51000","0.00000","1.18083","0.20014"
"1.18083","24.71745","0.99642","83.69000","0.00000","1.18083","0.20014"
"1.18083","24.71122","0.99617","83.87000","0.00000","1.18083","0.20014"
"1.18083","24.71313","0.99624","84.05000","0.00000","1.18083","0.20014"
"1.18083","24.70875","0.99607","84.23000","0.00000","1.18083","0.20014"
"1.18083","24.70613","0.99596","84.41000","0.00000","1.18083","0.20014"
"1.18083","24.70445","0.99589","84.59000","0.00000","1.18083","0.20014"
"1.18083","24.70035","0.99573","84.77000","0.00000","1.18083","0.20014"
"1.18083","24.70106","0.99576","84.95000","0.00000","1.18083","0.20014"
"1.18083","24.69473","0.99550","85.13000","0.00000","1.18083","0.20014"
"1.18083","24.69583","0.99555","85.31000","0.00000","1.18083","0.20014"
"1.18083","24.68029","0.99492","85.49000","0.00000","1.18083","0.20014"
"1.18083","24.69237","0.99541","85.67000","0.00000","1.18083","0.20014"
"1.18083","24.68740","0.99521","85.85000","0.00000","1.18083","0.20014"
"1.18083","24.67911","0.99487","86.03000","0.00000","1.18083","0.20014"
"1.18083","24.68082","0.99494","86.21000","0.00000","1.18083","0.20014"
"1.18083","24.67954","0.99489","86.39000","0.00000","1.18083","0.20014"
"1.18083","24.67730","0.99480","86.57000","0.00000","1.18083","0.20014"
"1.18083","24.67369","0.99465","86.75000","0.00000","1.18083","0.20014"
"1.18083","24.67858","0.99485","86.93000","0.00000","1.18083","0.20014"
"1.18083","24.67018","0.99451","87.11000","0.00000","1.18083","0.20014"
"1.18083","24.67431","0.99468","87.29000","0.00000","1.18083","0.20014"
"1.18083","24.67328","0.99464","87.47000","0.00000","1.18083","0.20014"
"1.18083","24.67262","0.99461","87.65000","0.00000","1.18083","0.20014"
"1.18083","24.66861","0.99445","87.83000","0.00000","1.18083","0.20014"
"1.18083","24.66372","0.99425","88.01000","0.00000","1.18083","0.20014"
"1.18083","24.66721","0.99439","88.19000","0.00000","1.18083","0.20014"
"1.18083","24.64859","0.99364","88.37000","0.00000","1.18083","0.20014"
"1.18083","24.65470","0.99389","88.55000","0.00000","1.18083","0.20014"
"1.18083","24.65448","0.99388","88.73000","0.00000","1.18083","0.20014"
"1.18083","24.65236","0.99379","88.91000","0.00000","1.18083","0.20014"
"1.18083","24.65043","0.99372","89.09000","0.00000","1.18083","0.20014"
"1.18083","24.65267","0.99381","89.27000","0.00000","1.18083","0.20014"
"1.18083","24.64566","0.99352","89.45000","0.00000","1.18083","0.20014"
"1.18083","24.65088","0.99373","89.63000","0.00000","1.18083","0.20014"
"1.18083","24.63809","0.99322","89.81000","0.00000","1.18083","0.20014"
"1.18083","24.63899","0.99325","89.99000","0.00000","1.18083","0.20014"
"1.18083","24.64269","0.99340","90.17000","0.00000","1.18083","0.20014"
"1.18083","24.63956","0.99328","90.35000","0.00000","1.18083","0.20014"
"1.18083","24.63897","0.99325","90.53000","0.00000","1.18083","0.20014"
"1.18083","24.63296","0.99301","90.71000","0.00000","1.18083","0.20014"
"1.18083","24.62821","0.99282","90.89000","0.00000","1.18083","0.20014"
"1.18083","24.62205","0.99257","91.07000","0.00000","1.18083","0.20014"
"1.18083","24.62546","0.99271","91.25000","0.00000","1.18083","0.20014"
"1.18083","24.62198","0.99257","91.43000","0.00000","1.18083","0.20014"
"1.18083","24.62023","0.99250","91.61000","0.00000","1.18083","0.20014"
"1.18083","24.61960","0.99247","91.79000","0.00000","1.18083","0.20014"
"1.18083","24.61138","0.99214","91.97000","0.00000","1.18083","0.20014"
"1.18083","24.61161","0.99215","92.15000","0.00000","1.18083","0.20014"
"1.18083","24.62173","0.99256","92.33000","0.00000","1.18083","0.20014"
"1.18083","24.62111","0.99253","92.51000","0.00000","1.18083","0.20014"
"1.18083","24.61411","0.99225","92.69000","0.00000","1.18083","0.20014"
"1.18083","24.60729","0.99198","92.87000","0.00000","1.18083","0.20014"
"1.18083","24.60799","0.99200","93.05000","0.00000","1.18083","0.20014"
"1.18083","24.60038","0.99170","93.23000","0.00000","1.18083","0.20014"
"1.18083","24.60883","0.99204","93.41000","0.00000","1.18083","0.20014"
"1.18083","24.60534","0.99190","93.59000","0.00000","1.18083","0.20014"
"1.18083","24.59639","0.99154","93.77000","0.00000","1.18083","0.20014"
"1.18083","24.59422","0.99145","93.95000","0.00000","1.18083","0.20014"
"1.18083","24.59625","0.99153","94.13000","0.00000","1.18083","0.20014"
"1.18083","24.59569","0.99151","94.31000","0.00000","1.18083","0.20014"
"1.18083","24.59305","0.99140","94.49000","0.00000","1.18083","0.20014"
"1.18083","24.58955","0.99126","94.67000","0.00000","1.18083","0.20014"
"1.18083","24.58754","0.99118","94.85000","0.00000","1.18083","0.20014"
"1.18083","24.58198","0.99096","95.03000","0.00000","1.18083","0.20014"
"1.18083","24.58432","0.99105","95.21000","0.00000","1.18083","0.20014"
"1.18083","24.58211","0.99096","95.39000","0.00000","1.18083","0.20014"
"1.18083","24.58350","0.99102","95.57000","0.00000","1.18083","0.20014"
"1.18083","24.58487","0.99107","95.75000","0.00000","1.18083","0.20014"
"1.18083","24.58604","0.99112","95.93000","0.00000","1.18083","0.20014"
"1.18083","24.57758","0.99078","96.11000","0.00000","1.18083","0.20014"
"1.18083","24.57307","0.99060","96.29000","0.00000","1.18083","0.20014"
"1.18083","24.57153","0.99053","96.47000","0.00000","1.18083","0.20014"
"1.18083","24.56804","0.99039","96.65000","0.00000","1.18083","0.20014"
"1.18083","24.57311","0.99060","96.83000","0.00000","1.18083","0.20014"
"1.18083","24.57264","0.99058","97.01000","0.00000","1.18083","0.20014"
"1.18083","24.55672","0.98994","97.19000","0.00000","1.18083","0.20014"
"1.18083","24.56919","0.99044","97.37000","0.00000","1.18083","0.20014"
"1.18083","24.55861","0.99001","97.55000","0.00000","1.18083","0.20014"
"1.18083","24.55225","0.98976","97.73000","0.00000","1.18083","0.20014"
"1.18083","24.54789","0.98958","97.91000","0.00000","1.18083","0.20014"
"1.18083","24.54947","0.98965","98.09000","0.00000","1.18083","0.20014"
"1.18083","24.54724","0.98956","98.27000","0.00000","1.18083","0.20014"
"1.18083","24.55091","0.98970","98.45000","0.00000","1.18083","0.20014"
"1.18083","24.54696","0.98954","98.63000","0.00000","1.18083","0.20014"
"1.18083","24.54275","0.98937","98.81000","0.00000","1.18083","0.20014"
"1.18083","24.54332","0.98940","98.99000","0.00000","1.18083","0.20014"
"1.18083","24.54116","0.98931","99.17000","0.00000","1.18083","0.20014"
"1.18083","24.53734","0.98916","99.35000","0.00000","1.18083","0.20014"
"1.18083","24.54296","0.98938","99.53000","0.00000","1.18083","0.20014"
"1.18083","24.52377","0.98861","99.71000","0.00000","1.18083","0.20014"
"1.18083","24.52558","0.98868","99.89000","0.00000","1.18083","0.20014"
"1.18083","24.52514","0.98866","100.07000","0.00000","1.18083","0.20014"
"1.18083","24.53183","0.98893","100.25000","0.00000","1.18083","0.20014"
"1.18083","24.51965","0.98844","100.43000","0.00000","1.18083","0.20014"
"1.18083","24.51991","0.98845","100.61000","0.00000","1.18083","0.20014"
"1.18083","24.52625","0.98871","100.79000","0.00000","1.18083","0.20014"
"1.18083","24.52824","0.98879","100.97000","0.00000","1.18083","0.20014"
"1.18083","24.52290","0.98857","101.15000","0.00000","1.18083","0.20014"
"1.18083","24.51561","0.98828","101.33000","0.00000","1.18083","0.20014"
"1.18083","24.51865","0.98840","101.51000","0.00000","1.18083","0.20014"
"1.18083","24.51745","0.98835","101.69000","0.00000","1.18083","0.20014"
"1.18083","24.53054","0.98888","101.87000","0.00000","1.18083","0.20014"
"1.18083","24.51825","0.98839","102.05000","0.00000","1.18083","0.20014"
"1.18083","24.52707","0.98874","102.23000","0.00000","1.18083","0.20014"
"1.18083","24.52644","0.98872","102.41000","0.00000","1.18083","0.20014"
"1.18083","24.51298","0.98817","102.59000","0.00000","1.18083","0.20014"
"1.18083","24.50810","0.98798","102.77000","0.00000","1.18083","0.20014"
"1.18083","24.51285","0.98817","102.95000","0.00000","1.18083","0.20014"
"1.18083","24.51262","0.98816","103.13000","0.00000","1.18083","0.20014"
"1.18083","24.51217","0.98814","103.31000","0.00000","1.18083","0.20014"
"1.18083","24.50158","0.98771","103.49000","0.00000","1.18083","0.20014"
"1.18083","24.51076","0.98808","103.67000","0.00000","1.18083","0.20014"
"1.18083","24.51302","0.98818","103.85000","0.00000","1.18083","0.20014"
"1.18083","24.50951","0.98803","104.03000","0.00000","1.18083","0.20014"
"1.18083","24.49709","0.98753","104.21000","0.00000","1.18083","0.20014"
"1.18083","24.49815","0.98758","104.39000","0.00000","1.18083","0.20014"
"1.18083","24.48504","0.98705","104.57000","0.00000","1.18083","0.20014"
"1.18083","24.48374","0.98700","104.75000","0.00000","1.18083","0.20014"
"1.18083","24.48933","0.98722","104.93000","0.00000","1.18083","0.20014"
"1.18083","24.48237","0.98694","105.11000","0.00000","1.18083","0.20014"
"1.18083","24.48691","0.98712","105.29000","0.00000","1.18083","0.20014"
"1.18083","24.48117","0.98689","105.47000","0.00000","1.18083","0.20014"
"1.18083","24.48456","0.98703","105.65000","0.00000","1.18083","0.20014"
"1.18083","24.47448","0.98662","105.83000","0.00000","1.18083","0.20014"
"1.18083","24.47350","0.98658","106.01000","0.00000","1.18083","0.20014"
"1.18083","24.48103","0.98689","106.19000","0.00000","1.18083","0.20014"
"1.18083","24.47058","0.98647","106.37000","0.00000","1.18083","0.20014"
"1.18083","24.47957","0.98683","106.55000","0.00000","1.18083","0.20014"
"1.18083","24.47482","0.98664","106.73000","0.00000","1.18083","0.20014"
"1.18083","24.46445","0.98622","106.91000","0.00000","1.18083","0.20014"
"1.18083","24.46022","0.98605","107.09000","0.00000","1.18083","0.20014"
"1.18083","24.47179","0.98651","107.27000","0.00000","1.18083","0.20014"
"1.18083","24.45672","0.98591","107.45000","0.00000","1.18083","0.20014"
"1.18083","24.45627","0.98589","107.63000","0.00000","1.18083","0.20014"
"1.18083","24.46152","0.98610","107.81000","0.00000","1.18083","0.20014"
"1.18083","24.45192","0.98571","107.99000","0.00000","1.18083","0.20014"
"1.18083","24.44441","0.98541","108.17000","0.00000","1.18083","0.20014"
"1.18083","24.45707","0.98592","108.35000","0.00000","1.18083","0.20014"
"1.18083","24.45696","0.98592","108.53000","0.00000","1.18083","0.20014"
"1.18083","24.45622","0.98589","108.71000","0.00000","1.18083","0.20014"
"1.18083","24.44301","0.98535","108.89000","0.00000","1.18083","0.20014"
"1.18083","24.42935","0.98480","109.07000","0.00000","1.18083","0.20014"
"1.18083","24.44416","0.98540","109.25000","0.00000","1.18083","0.20014"
"1.18083","24.43619","0.98508","109.43000","0.00000","1.18083","0.20014"
"1.18083","24.43675","0.98510","109.61000","0.00000","1.18083","0.20014"
"1.18083","24.44907","0.98560","109.79000","0.00000","1.18083","0.20014"
"1.18083","24.45330","0.98577","109.97000","0.00000","1.18083","0.20014"
"1.18083","24.43842","0.98517","110.15000","0.00000","1.18083","0.20014"
"1.18083","24.42497","0.98463","110.33000","0.00000","1.18083","0.20014"
"1.18083","24.42484","0.98462","110.51000","0.00000","1.18083","0.20014"
"1.18083","24.43451","0.98501","110.69000","0.00000","1.18083","0.20014"
"1.18083","24.43736","0.98513","110.87000","0.00000","1.18083","0.20014"
"1.18083","24.43999","0.98523","111.05000","0.00000","1.18083","0.20014"
"1.18083","24.42888","0.98478","111.23000","0.00000","1.18083","0.20014"
"1.18083","24.42677","0.98470","111.41000","0.00000","1.18083","0.20014"
"1.18083","24.41937","0.98440","111.59000","0.00000","1.18083","0.20014"
"1.18083","24.42593","0.98467","111.77000","0.00000","1.18083","0.20014"
"1.18083","24.42391","0.98458","111.95000","0.00000","1.18083","0.20014"
"1.18083","24.42088","0.98446","112.13000","0.00000","1.18083","0.20014"
"1.18083","24.42163","0.98449","112.31000","0.00000","1.18083","0.20014"
"1.18083","24.41521","0.98423","112.49000","0.00000","1.18083","0.20014"
"1.18083","24.41970","0.98441","112.67000","0.00000","1.18083","0.20014"
"1.18083","24.41128","0.98407","112.85000","0.00000","1.18083","0.20014"
"1.18083","24.42181","0.98450","113.03000","0.00000","1.18083","0.20014"
"1.18083","24.41485","0.98422","113.21000","0.00000","1.18083","0.20014"
"1.18083","24.41760","0.98433","113.39000","0.00000","1.18083","0.20014"
"1.18083","24.41267","0.98413","113.57000","0.00000","1.18083","0.20014"
"1.18083","24.40645","0.98388","113.75000","0.00000","1.18083","0.20014"
"1.18083","24.40197","0.98370","113.93000","0.00000","1.18083","0.20014"
"1.18083","24.40937","0.98400","114.11000","0.00000","1.18083","0.20014"
"1.18083","24.40838","0.98396","114.29000","0.00000","1.18083","0.20014"
"1.18083","24.39685","0.98349","114.47000","0.00000","1.18083","0.20014"
"1.18083","24.40170","0.98369","114.65000","0.00000","1.18083","0.20014"
"1.18083","24.40415","0.98379","114.83000","0.00000","1.18083","0.20014"
"1.18083","24.39816","0.98355","115.01000","0.00000","1.18083","0.20014"
"1.18083","24.39418","0.98339","115.19000","0.00000","1.18083","0.20014"
"1.18083","24.39678","0.98349","115.37000","0.00000","1.18083","0.20014"
"1.18083","24.39937","0.98359","115.55000","0.00000","1.18083","0.20014"
"1.18083","24.39254","0.98332","115.73000","0.00000","1.18083","0.20014"
"1.18083","24.39269","0.98333","115.91000","0.00000","1.18083","0.20014"
"1.18083","24.38623","0.98306","116.09000","0.00000","1.18083","0.20014"
"1.18083","24.39034","0.98323","116.27000","0.00000","1.18083","0.20014"
"1.18083","24.38993","0.98321","116.45000","0.00000","1.18083","0.20014"
"1.18083","24.38236","0.98291","116.63000","0.00000","1.18083","0.20014"
"1.18083","24.38291","0.98293","116.81000","0.00000","1.18083","0.20014"
"1.18083","24.38124","0.98286","116.99000","0.00000","1.18083","0.20014"
"1.18083","24.37947","0.98279","117.17000","0.00000","1.18083","0.20014"
"1.18083","24.38175","0.98288","117.35000","0.00000","1.18083","0.20014"
"1.18083","24.37704","0.98269","117.53000","0.00000","1.18083","0.20014"
"1.18083","24.37449","0.98259","117.71000","0.00000","1.18083","0.20014"
"1.18083","24.37108","0.98245","117.89000","0.00000","1.18083","0.20014"
"1.18083","24.36403","0.98217","118.07000","0.00000","1.18083","0.20014"
"1.18083","24.36630","0.98226","118.25000","0.00000","1.18083","0.20014"
"1.18083","24.38031","0.98283","118.43000","0.00000","1.18083","0.20014"
"1.18083","24.36529","0.98222","118.61000","0.00000","1.18083","0.20014"
"1.18083","24.37045","0.98243","118.79000","0.00000","1.18083","0.20014"
"1.18083","24.36288","0.98212","118.97000","0.00000","1.18083","0.20014"
"1.18083","24.36192","0.98208","119.15000","0.00000","1.18083","0.20014"
"1.18083","24.36906","0.98237","119.33000","0.00000","1.18083","0.20014"
"1.18083","24.36837","0.98234","119.51000","0.00000","1.18083","0.20014"
"1.18083","24.36447","0.98219","119.69000","0.00000","1.18083","0.20014"
"1.18083","24.36552","0.98223","119.87000","0.00000","1.18083","0.20014"
"1.18083","24.35095","0.98164","120.05000","0.00000","1.18083","0.20014"
"1.18083","24.35484","0.98180","120.23000","0.00000","1.18083","0.20014"
"1.18083","24.34785","0.98152","120.41000","0.00000","1.18083","0.20014"
"1.18083","24.36116","0.98205","120.59000","0.00000","1.18083","0.20014"
"1.18083","24.35900","0.98197","120.77000","0.00000","1.18083","0.20014"
"1.18083","24.35314","0.98173","120.95000","0.00000","1.18083","0.20014"
"1.18083","24.34858","0.98155","121.13000","0.00000","1.18083","0.20014"
"1.18083","24.34253","0.98130","121.31000","0.00000","1.18083","0.20014"
"1.18083","24.35000","0.98160","121.49000","0.00000","1.18083","0.20014"
"1.18083","24.34242","0.98130","121.67000","0.00000","1.18083","0.20014"
"1.18083","24.33862","0.98115","121.85000","0.00000","1.18083","0.20014"
"1.18083","24.33779","0.98111","122.03000","0.00000","1.18083","0.20014"
"1.18083","24.33737","0.98110","122.21000","0.00000","1.18083","0.20014"
"1.18083","24.33776","0.98111","122.39000","0.00000","1.18083","0.20014"
"1.18083","24.34342","0.98134","122.57000","0.00000","1.18083","0.20014"
"1.18083","24.33442","0.98098","122.75000","0.00000","1.18083","0.20014"
"1.18083","24.33238","0.98089","122.93000","0.00000","1.18083","0.20014"
"1.18083","24.33690","0.98108","122.95000","0.00000","1.18083","0.20014"