File: Rubber Stress Relaxation Raw Data -Large  Samples-20210211/Specimen_RawData_4.csv
Specimen properties : Specimen label,"5"
Specimen properties : Anvil height,"6.30000",mm
Specimen properties : Diameter,"10.14000",mm
Test : Rate 1,"2.40000",mm/min
Test : Start of hold value,"20.00000",%
Test : Duration,"120.00000",s

Extension,Load,Compressive stress,Time,PIP count,Compressive extension,Compressive strain (Extension)
(mm),(N),(MPa),(s),,(mm),(mm/mm)
"0.00000","-0.00947","-0.00012","0.00000","0.00000","0.00000","0.00000"
"0.00333","0.30527","0.00378","0.23000","0.00000","0.00333","0.00053"
"0.01458","1.59310","0.01973","0.46000","0.00000","0.01458","0.00231"
"0.02625","3.06164","0.03791","0.69000","0.00000","0.02625","0.00417"
"0.03604","4.49539","0.05567","0.92000","0.00000","0.03604","0.00572"
"0.04542","5.87400","0.07274","1.15000","0.00000","0.04542","0.00721"
"0.05521","7.31220","0.09055","1.38000","0.00000","0.05521","0.00876"
"0.06458","8.61235","0.10665","1.61000","0.00000","0.06458","0.01025"
"0.07313","9.75488","0.12080","1.84000","0.00000","0.07313","0.01161"
"0.08250","11.00963","0.13633","2.07000","0.00000","0.08250","0.01310"
"0.09188","12.19978","0.15107","2.30000","0.00000","0.09188","0.01458"
"0.10146","13.41305","0.16610","2.53000","0.00000","0.10146","0.01610"
"0.11042","14.49405","0.17948","2.76000","0.00000","0.11042","0.01753"
"0.11938","15.57997","0.19293","2.99000","0.00000","0.11938","0.01895"
"0.12854","16.60987","0.20568","3.22000","0.00000","0.12854","0.02040"
"0.13813","17.74230","0.21971","3.45000","0.00000","0.13813","0.02192"
"0.14729","18.78308","0.23260","3.68000","0.00000","0.14729","0.02338"
"0.15625","19.71866","0.24418","3.91000","0.00000","0.15625","0.02480"
"0.16521","20.70099","0.25635","4.14000","0.00000","0.16521","0.02622"
"0.17458","21.73169","0.26911","4.37000","0.00000","0.17458","0.02771"
"0.18417","22.78841","0.28219","4.60000","0.00000","0.18417","0.02923"
"0.19312","23.63609","0.29269","4.83000","0.00000","0.19312","0.03065"
"0.20208","24.57307","0.30429","5.06000","0.00000","0.20208","0.03208"
"0.21125","25.54584","0.31634","5.29000","0.00000","0.21125","0.03353"
"0.22104","26.55348","0.32882","5.52000","0.00000","0.22104","0.03509"
"0.23021","27.42145","0.33957","5.75000","0.00000","0.23021","0.03654"
"0.23896","28.30042","0.35045","5.98000","0.00000","0.23896","0.03793"
"0.24813","29.19038","0.36147","6.21000","0.00000","0.24813","0.03938"
"0.25771","30.18694","0.37381","6.44000","0.00000","0.25771","0.04091"
"0.26729","31.13145","0.38551","6.67000","0.00000","0.26729","0.04243"
"0.27625","31.90557","0.39509","6.90000","0.00000","0.27625","0.04385"
"0.28479","32.73533","0.40537","7.13000","0.00000","0.28479","0.04521"
"0.29417","33.69265","0.41722","7.36000","0.00000","0.29417","0.04669"
"0.30375","34.63251","0.42886","7.59000","0.00000","0.30375","0.04821"
"0.31292","35.45786","0.43908","7.82000","0.00000","0.31292","0.04967"
"0.32167","36.25129","0.44891","8.05000","0.00000","0.32167","0.05106"
"0.33083","37.18010","0.46041","8.28000","0.00000","0.33083","0.05251"
"0.34042","38.14199","0.47232","8.51000","0.00000","0.34042","0.05403"
"0.34979","39.03439","0.48337","8.74000","0.00000","0.34979","0.05552"
"0.35875","39.78476","0.49266","8.97000","0.00000","0.35875","0.05694"
"0.36750","40.62152","0.50303","9.20000","0.00000","0.36750","0.05833"
"0.37708","41.57587","0.51484","9.43000","0.00000","0.37708","0.05985"
"0.38667","42.49728","0.52625","9.66000","0.00000","0.38667","0.06138"
"0.39583","43.33936","0.53668","9.89000","0.00000","0.39583","0.06283"
"0.40438","44.05809","0.54558","10.12000","0.00000","0.40437","0.06419"
"0.41375","44.98921","0.55711","10.35000","0.00000","0.41375","0.06567"
"0.42333","45.95065","0.56902","10.58000","0.00000","0.42333","0.06720"
"0.43271","46.76965","0.57916","10.81000","0.00000","0.43271","0.06868"
"0.44146","47.50238","0.58823","11.04000","0.00000","0.44146","0.07007"
"0.45063","48.42857","0.59970","11.27000","0.00000","0.45063","0.07153"
"0.45979","49.34837","0.61109","11.50000","0.00000","0.45979","0.07298"
"0.46938","50.26942","0.62250","11.73000","0.00000","0.46937","0.07450"
"0.47875","51.10643","0.63286","11.96000","0.00000","0.47875","0.07599"
"0.48750","51.90469","0.64275","12.19000","0.00000","0.48750","0.07738"
"0.49667","52.80342","0.65388","12.42000","0.00000","0.49667","0.07884"
"0.50625","53.74574","0.66555","12.65000","0.00000","0.50625","0.08036"
"0.51542","54.59995","0.67612","12.88000","0.00000","0.51542","0.08181"
"0.52417","55.31608","0.68499","13.11000","0.00000","0.52417","0.08320"
"0.53333","56.25782","0.69665","13.34000","0.00000","0.53333","0.08466"
"0.54271","57.20101","0.70833","13.57000","0.00000","0.54271","0.08614"
"0.55188","58.04315","0.71876","13.80000","0.00000","0.55188","0.08760"
"0.56125","58.95570","0.73006","14.03000","0.00000","0.56125","0.08909"
"0.57021","59.74377","0.73982","14.26000","0.00000","0.57021","0.09051"
"0.57938","60.72007","0.75191","14.49000","0.00000","0.57938","0.09196"
"0.58875","61.61534","0.76300","14.72000","0.00000","0.58875","0.09345"
"0.59813","62.50771","0.77405","14.95000","0.00000","0.59813","0.09494"
"0.60708","63.31953","0.78410","15.18000","0.00000","0.60708","0.09636"
"0.61646","64.26797","0.79585","15.41000","0.00000","0.61646","0.09785"
"0.62583","65.20497","0.80745","15.64000","0.00000","0.62583","0.09934"
"0.63479","66.02232","0.81757","15.87000","0.00000","0.63479","0.10076"
"0.64396","66.87531","0.82813","16.10000","0.00000","0.64396","0.10222"
"0.65292","67.75618","0.83904","16.33000","0.00000","0.65292","0.10364"
"0.66229","68.73261","0.85113","16.56000","0.00000","0.66229","0.10513"
"0.67146","69.61125","0.86201","16.79000","0.00000","0.67146","0.10658"
"0.68104","70.55830","0.87374","17.02000","0.00000","0.68104","0.10810"
"0.69000","71.38657","0.88400","17.25000","0.00000","0.69000","0.10952"
"0.69917","72.30874","0.89542","17.48000","0.00000","0.69917","0.11098"
"0.70833","73.19901","0.90644","17.71000","0.00000","0.70833","0.11243"
"0.71750","74.15108","0.91823","17.94000","0.00000","0.71750","0.11389"
"0.72688","75.08044","0.92974","18.17000","0.00000","0.72688","0.11538"
"0.73604","75.98523","0.94094","18.40000","0.00000","0.73604","0.11683"
"0.74500","76.88609","0.95210","18.63000","0.00000","0.74500","0.11825"
"0.75417","77.81251","0.96357","18.86000","0.00000","0.75417","0.11971"
"0.76354","78.72639","0.97489","19.09000","0.00000","0.76354","0.12120"
"0.77292","79.70454","0.98700","19.32000","0.00000","0.77292","0.12269"
"0.78188","80.57970","0.99784","19.55000","0.00000","0.78188","0.12411"
"0.79083","81.46247","1.00877","19.78000","0.00000","0.79083","0.12553"
"0.80021","82.41171","1.02052","20.01000","0.00000","0.80021","0.12702"
"0.80958","83.41319","1.03293","20.24000","0.00000","0.80958","0.12851"
"0.81896","84.39488","1.04508","20.47000","0.00000","0.81896","0.12999"
"0.82792","85.25858","1.05578","20.70000","0.00000","0.82792","0.13142"
"0.83708","86.20750","1.06753","20.93000","0.00000","0.83708","0.13287"
"0.84625","87.18472","1.07963","21.16000","0.00000","0.84625","0.13433"
"0.85583","88.24486","1.09276","21.39000","0.00000","0.85583","0.13585"
"0.86479","89.14108","1.10386","21.62000","0.00000","0.86479","0.13727"
"0.87375","90.07546","1.11543","21.85000","0.00000","0.87375","0.13869"
"0.88313","91.06696","1.12770","22.08000","0.00000","0.88312","0.14018"
"0.89271","92.18981","1.14161","22.31000","0.00000","0.89271","0.14170"
"0.90188","93.06394","1.15243","22.54000","0.00000","0.90187","0.14315"
"0.91083","93.98626","1.16385","22.77000","0.00000","0.91083","0.14458"
"0.91979","94.88380","1.17497","23.00000","0.00000","0.91979","0.14600"
"0.92896","95.87440","1.18724","23.23000","0.00000","0.92896","0.14745"
"0.93854","96.93842","1.20041","23.46000","0.00000","0.93854","0.14897"
"0.94729","97.73589","1.21029","23.69000","0.00000","0.94729","0.15036"
"0.95625","98.68983","1.22210","23.92000","0.00000","0.95625","0.15179"
"0.96583","99.79442","1.23578","24.15000","0.00000","0.96583","0.15331"
"0.97521","100.80064","1.24824","24.38000","0.00000","0.97521","0.15479"
"0.98417","101.72822","1.25972","24.61000","0.00000","0.98417","0.15622"
"0.99333","102.75292","1.27241","24.84000","0.00000","0.99333","0.15767"
"1.00250","103.81960","1.28562","25.07000","0.00000","1.00250","0.15913"
"1.01208","104.95929","1.29974","25.30000","0.00000","1.01208","0.16065"
"1.02167","106.01097","1.31276","25.53000","0.00000","1.02167","0.16217"
"1.03042","106.89028","1.32365","25.76000","0.00000","1.03042","0.16356"
"1.03917","107.80812","1.33501","25.99000","0.00000","1.03917","0.16495"
"1.04854","108.93798","1.34900","26.22000","0.00000","1.04854","0.16644"
"1.05833","110.17953","1.36438","26.45000","0.00000","1.05833","0.16799"
"1.06708","111.01046","1.37467","26.68000","0.00000","1.06708","0.16938"
"1.07604","112.01303","1.38708","26.91000","0.00000","1.07604","0.17080"
"1.08542","113.15848","1.40127","27.14000","0.00000","1.08542","0.17229"
"1.09500","114.43583","1.41709","27.37000","0.00000","1.09500","0.17381"
"1.10438","115.44705","1.42961","27.60000","0.00000","1.10438","0.17530"
"1.11333","116.41659","1.44161","27.83000","0.00000","1.11333","0.17672"
"1.12208","117.31997","1.45280","28.06000","0.00000","1.12208","0.17811"
"1.13146","118.52641","1.46774","28.29000","0.00000","1.13146","0.17960"
"1.14104","119.70391","1.48232","28.52000","0.00000","1.14104","0.18112"
"1.15000","120.66174","1.49418","28.75000","0.00000","1.15000","0.18254"
"1.15875","121.64946","1.50641","28.98000","0.00000","1.15875","0.18393"
"1.16813","122.88209","1.52168","29.21000","0.00000","1.16813","0.18542"
"1.17792","124.13438","1.53719","29.44000","0.00000","1.17792","0.18697"
"1.18687","125.10069","1.54915","29.67000","0.00000","1.18687","0.18839"
"1.19542","125.96597","1.55987","29.90000","0.00000","1.19542","0.18975"
"1.20479","127.25124","1.57578","30.13000","0.00000","1.20479","0.19124"
"1.21438","128.57484","1.59217","30.36000","0.00000","1.21438","0.19276"
"1.22375","129.71819","1.60633","30.59000","0.00000","1.22375","0.19425"
"1.23292","130.71715","1.61870","30.82000","0.00000","1.23292","0.19570"
"1.24188","131.76872","1.63172","31.05000","0.00000","1.24188","0.19712"
"1.25104","133.03967","1.64746","31.28000","0.00000","1.25104","0.19858"
"1.26021","134.23380","1.66225","31.50000","0.00000","1.26021","0.20003"
"1.26167","131.69373","1.63079","31.73000","0.00000","1.26167","0.20026"
"1.26167","129.47029","1.60326","31.96000","0.00000","1.26167","0.20026"
"1.26167","127.89175","1.58371","32.19000","0.00000","1.26167","0.20026"
"1.26125","126.66449","1.56852","32.42000","0.00000","1.26125","0.20020"
"1.26125","125.55468","1.55477","32.65000","0.00000","1.26125","0.20020"
"1.26104","124.64921","1.54356","32.88000","0.00000","1.26104","0.20017"
"1.26083","123.81029","1.53317","33.11000","0.00000","1.26083","0.20013"
"1.26063","123.05467","1.52382","33.34000","0.00000","1.26063","0.20010"
"1.26042","122.37023","1.51534","33.57000","0.00000","1.26042","0.20007"
"1.26042","121.81595","1.50848","33.80000","0.00000","1.26042","0.20007"
"1.26021","121.24006","1.50134","34.03000","0.00000","1.26021","0.20003"
"1.26021","120.74780","1.49525","34.26000","0.00000","1.26021","0.20003"
"1.26000","120.26026","1.48921","34.49000","0.00000","1.26000","0.20000"
"1.26000","119.85402","1.48418","34.72000","0.00000","1.26000","0.20000"
"1.26000","119.45910","1.47929","34.95000","0.00000","1.26000","0.20000"
"1.26000","119.06927","1.47446","35.18000","0.00000","1.26000","0.20000"
"1.26000","118.71559","1.47008","35.41000","0.00000","1.26000","0.20000"
"1.26000","118.38412","1.46598","35.64000","0.00000","1.26000","0.20000"
"1.26000","118.05305","1.46188","35.87000","0.00000","1.26000","0.20000"
"1.26000","117.74074","1.45801","36.10000","0.00000","1.26000","0.20000"
"1.26000","117.44262","1.45432","36.33000","0.00000","1.26000","0.20000"
"1.26000","117.15295","1.45073","36.56000","0.00000","1.26000","0.20000"
"1.26000","116.86898","1.44722","36.79000","0.00000","1.26000","0.20000"
"1.26000","116.60725","1.44398","37.02000","0.00000","1.26000","0.20000"
"1.26000","116.35081","1.44080","37.25000","0.00000","1.26000","0.20000"
"1.26000","116.09563","1.43764","37.48000","0.00000","1.26000","0.20000"
"1.26000","115.86373","1.43477","37.71000","0.00000","1.26000","0.20000"
"1.26000","115.62398","1.43180","37.94000","0.00000","1.26000","0.20000"
"1.26000","115.39635","1.42898","38.17000","0.00000","1.26000","0.20000"
"1.26000","115.18240","1.42633","38.40000","0.00000","1.26000","0.20000"
"1.26000","114.96085","1.42359","38.63000","0.00000","1.26000","0.20000"
"1.26000","114.76038","1.42111","38.86000","0.00000","1.26000","0.20000"
"1.26000","114.55962","1.41862","39.09000","0.00000","1.26000","0.20000"
"1.26000","114.36356","1.41619","39.32000","0.00000","1.26000","0.20000"
"1.26000","114.17117","1.41381","39.55000","0.00000","1.26000","0.20000"
"1.26000","113.98783","1.41154","39.78000","0.00000","1.26000","0.20000"
"1.26000","113.80403","1.40926","40.01000","0.00000","1.26000","0.20000"
"1.26000","113.61687","1.40694","40.24000","0.00000","1.26000","0.20000"
"1.26000","113.45309","1.40492","40.47000","0.00000","1.26000","0.20000"
"1.26000","113.28479","1.40283","40.70000","0.00000","1.26000","0.20000"
"1.26000","113.11376","1.40071","40.93000","0.00000","1.26000","0.20000"
"1.26000","112.95274","1.39872","41.16000","0.00000","1.26000","0.20000"
"1.26000","112.79115","1.39672","41.39000","0.00000","1.26000","0.20000"
"1.26000","112.64271","1.39488","41.62000","0.00000","1.26000","0.20000"
"1.26000","112.48753","1.39296","41.85000","0.00000","1.26000","0.20000"
"1.26000","112.34468","1.39119","42.08000","0.00000","1.26000","0.20000"
"1.26000","112.19035","1.38928","42.31000","0.00000","1.26000","0.20000"
"1.26000","112.05124","1.38756","42.54000","0.00000","1.26000","0.20000"
"1.26000","111.91098","1.38582","42.77000","0.00000","1.26000","0.20000"
"1.26000","111.76994","1.38407","43.00000","0.00000","1.26000","0.20000"
"1.26000","111.63938","1.38246","43.23000","0.00000","1.26000","0.20000"
"1.26000","111.50788","1.38083","43.46000","0.00000","1.26000","0.20000"
"1.26000","111.38139","1.37926","43.69000","0.00000","1.26000","0.20000"
"1.26000","111.24908","1.37762","43.92000","0.00000","1.26000","0.20000"
"1.26000","111.12234","1.37605","44.15000","0.00000","1.26000","0.20000"
"1.26000","111.00531","1.37461","44.38000","0.00000","1.26000","0.20000"
"1.26000","110.87947","1.37305","44.61000","0.00000","1.26000","0.20000"
"1.26000","110.75583","1.37152","44.84000","0.00000","1.26000","0.20000"
"1.26000","110.64910","1.37019","45.07000","0.00000","1.26000","0.20000"
"1.26000","110.53247","1.36875","45.30000","0.00000","1.26000","0.20000"
"1.26000","110.41404","1.36728","45.53000","0.00000","1.26000","0.20000"
"1.26000","110.29696","1.36583","45.76000","0.00000","1.26000","0.20000"
"1.26000","110.19159","1.36453","45.99000","0.00000","1.26000","0.20000"
"1.26000","110.08476","1.36321","46.22000","0.00000","1.26000","0.20000"
"1.26000","109.97156","1.36180","46.45000","0.00000","1.26000","0.20000"
"1.26000","109.86291","1.36046","46.68000","0.00000","1.26000","0.20000"
"1.26000","109.76210","1.35921","46.91000","0.00000","1.26000","0.20000"
"1.26000","109.65829","1.35792","47.14000","0.00000","1.26000","0.20000"
"1.26000","109.55418","1.35664","47.37000","0.00000","1.26000","0.20000"
"1.26000","109.46346","1.35551","47.60000","0.00000","1.26000","0.20000"
"1.26000","109.36187","1.35425","47.83000","0.00000","1.26000","0.20000"
"1.26000","109.26712","1.35308","48.06000","0.00000","1.26000","0.20000"
"1.26000","109.16926","1.35187","48.29000","0.00000","1.26000","0.20000"
"1.26000","109.06865","1.35062","48.52000","0.00000","1.26000","0.20000"
"1.26000","108.98129","1.34954","48.75000","0.00000","1.26000","0.20000"
"1.26000","108.88732","1.34838","48.98000","0.00000","1.26000","0.20000"
"1.26000","108.79565","1.34724","49.21000","0.00000","1.26000","0.20000"
"1.26000","108.71045","1.34619","49.44000","0.00000","1.26000","0.20000"
"1.26000","108.61799","1.34504","49.67000","0.00000","1.26000","0.20000"
"1.26000","108.52693","1.34391","49.90000","0.00000","1.26000","0.20000"
"1.26000","108.45218","1.34299","50.13000","0.00000","1.26000","0.20000"
"1.26000","108.35266","1.34176","50.36000","0.00000","1.26000","0.20000"
"1.26000","108.28125","1.34087","50.59000","0.00000","1.26000","0.20000"
"1.26000","108.19411","1.33979","50.82000","0.00000","1.26000","0.20000"
"1.26000","108.11139","1.33877","51.05000","0.00000","1.26000","0.20000"
"1.26000","108.02712","1.33773","51.28000","0.00000","1.26000","0.20000"
"1.26000","107.94852","1.33675","51.51000","0.00000","1.26000","0.20000"
"1.26000","107.86873","1.33576","51.74000","0.00000","1.26000","0.20000"
"1.26000","107.79234","1.33482","51.97000","0.00000","1.26000","0.20000"
"1.26000","107.71349","1.33384","52.20000","0.00000","1.26000","0.20000"
"1.26000","107.63065","1.33282","52.43000","0.00000","1.26000","0.20000"
"1.26000","107.55608","1.33189","52.66000","0.00000","1.26000","0.20000"
"1.26000","107.47779","1.33092","52.89000","0.00000","1.26000","0.20000"
"1.26000","107.39928","1.32995","53.12000","0.00000","1.26000","0.20000"
"1.26000","107.32744","1.32906","53.35000","0.00000","1.26000","0.20000"
"1.26000","107.25245","1.32813","53.58000","0.00000","1.26000","0.20000"
"1.26000","107.18539","1.32730","53.81000","0.00000","1.26000","0.20000"
"1.26000","107.11613","1.32644","54.04000","0.00000","1.26000","0.20000"
"1.26000","107.04737","1.32559","54.27000","0.00000","1.26000","0.20000"
"1.26000","106.97134","1.32465","54.50000","0.00000","1.26000","0.20000"
"1.26000","106.90146","1.32379","54.73000","0.00000","1.26000","0.20000"
"1.26000","106.83704","1.32299","54.96000","0.00000","1.26000","0.20000"
"1.26000","106.75018","1.32191","55.19000","0.00000","1.26000","0.20000"
"1.26000","106.68710","1.32113","55.42000","0.00000","1.26000","0.20000"
"1.26000","106.62080","1.32031","55.65000","0.00000","1.26000","0.20000"
"1.26000","106.55746","1.31953","55.88000","0.00000","1.26000","0.20000"
"1.26000","106.49249","1.31872","56.11000","0.00000","1.26000","0.20000"
"1.26000","106.42826","1.31793","56.34000","0.00000","1.26000","0.20000"
"1.26000","106.36278","1.31712","56.57000","0.00000","1.26000","0.20000"
"1.26000","106.30032","1.31634","56.80000","0.00000","1.26000","0.20000"
"1.26000","106.23399","1.31552","57.03000","0.00000","1.26000","0.20000"
"1.26000","106.17412","1.31478","57.26000","0.00000","1.26000","0.20000"
"1.26000","106.10701","1.31395","57.49000","0.00000","1.26000","0.20000"
"1.26000","106.05144","1.31326","57.72000","0.00000","1.26000","0.20000"
"1.26000","105.98454","1.31243","57.95000","0.00000","1.26000","0.20000"
"1.26000","105.92580","1.31170","58.18000","0.00000","1.26000","0.20000"
"1.26000","105.86938","1.31101","58.41000","0.00000","1.26000","0.20000"
"1.26000","105.79507","1.31009","58.64000","0.00000","1.26000","0.20000"
"1.26000","105.75090","1.30954","58.87000","0.00000","1.26000","0.20000"
"1.26000","105.69350","1.30883","59.10000","0.00000","1.26000","0.20000"
"1.26000","105.63240","1.30807","59.33000","0.00000","1.26000","0.20000"
"1.26000","105.56607","1.30725","59.56000","0.00000","1.26000","0.20000"
"1.26000","105.50928","1.30655","59.79000","0.00000","1.26000","0.20000"
"1.26000","105.45507","1.30588","60.02000","0.00000","1.26000","0.20000"
"1.26000","105.40231","1.30522","60.25000","0.00000","1.26000","0.20000"
"1.26000","105.34415","1.30450","60.48000","0.00000","1.26000","0.20000"
"1.26000","105.28555","1.30378","60.71000","0.00000","1.26000","0.20000"
"1.26000","105.24199","1.30324","60.94000","0.00000","1.26000","0.20000"
"1.26000","105.18415","1.30252","61.17000","0.00000","1.26000","0.20000"
"1.26000","105.12656","1.30181","61.40000","0.00000","1.26000","0.20000"
"1.26000","105.07727","1.30120","61.63000","0.00000","1.26000","0.20000"
"1.26000","105.02220","1.30051","61.86000","0.00000","1.26000","0.20000"
"1.26000","104.96606","1.29982","62.09000","0.00000","1.26000","0.20000"
"1.26000","104.91585","1.29920","62.32000","0.00000","1.26000","0.20000"
"1.26000","104.86196","1.29853","62.55000","0.00000","1.26000","0.20000"
"1.26000","104.81242","1.29792","62.78000","0.00000","1.26000","0.20000"
"1.26000","104.75372","1.29719","63.01000","0.00000","1.26000","0.20000"
"1.26000","104.70146","1.29654","63.24000","0.00000","1.26000","0.20000"
"1.26000","104.65947","1.29602","63.47000","0.00000","1.26000","0.20000"
"1.26000","104.60512","1.29535","63.70000","0.00000","1.26000","0.20000"
"1.26000","104.56420","1.29484","63.93000","0.00000","1.26000","0.20000"
"1.26000","104.51276","1.29421","64.16000","0.00000","1.26000","0.20000"
"1.26000","104.46686","1.29364","64.39000","0.00000","1.26000","0.20000"
"1.26000","104.40522","1.29287","64.62000","0.00000","1.26000","0.20000"
"1.26000","104.35845","1.29230","64.85000","0.00000","1.26000","0.20000"
"1.26000","104.30912","1.29168","65.08000","0.00000","1.26000","0.20000"
"1.26000","104.26517","1.29114","65.31000","0.00000","1.26000","0.20000"
"1.26000","104.22541","1.29065","65.54000","0.00000","1.26000","0.20000"
"1.26000","104.17081","1.28997","65.77000","0.00000","1.26000","0.20000"
"1.26000","104.12606","1.28942","66.00000","0.00000","1.26000","0.20000"
"1.26000","104.06877","1.28871","66.23000","0.00000","1.26000","0.20000"
"1.26000","104.02868","1.28821","66.46000","0.00000","1.26000","0.20000"
"1.26000","103.98197","1.28763","66.69000","0.00000","1.26000","0.20000"
"1.26000","103.94824","1.28722","66.92000","0.00000","1.26000","0.20000"
"1.26000","103.88927","1.28649","67.15000","0.00000","1.26000","0.20000"
"1.26000","103.85749","1.28609","67.38000","0.00000","1.26000","0.20000"
"1.26000","103.79968","1.28538","67.61000","0.00000","1.26000","0.20000"
"1.26000","103.76035","1.28489","67.84000","0.00000","1.26000","0.20000"
"1.26000","103.70634","1.28422","68.07000","0.00000","1.26000","0.20000"
"1.26000","103.67427","1.28382","68.30000","0.00000","1.26000","0.20000"
"1.26000","103.62263","1.28318","68.53000","0.00000","1.26000","0.20000"
"1.26000","103.58684","1.28274","68.76000","0.00000","1.26000","0.20000"
"1.26000","103.54376","1.28221","68.99000","0.00000","1.26000","0.20000"
"1.26000","103.50243","1.28170","69.22000","0.00000","1.26000","0.20000"
"1.26000","103.44967","1.28104","69.45000","0.00000","1.26000","0.20000"
"1.26000","103.41055","1.28056","69.68000","0.00000","1.26000","0.20000"
"1.26000","103.37093","1.28007","69.91000","0.00000","1.26000","0.20000"
"1.26000","103.32173","1.27946","70.14000","0.00000","1.26000","0.20000"
"1.26000","103.28906","1.27905","70.37000","0.00000","1.26000","0.20000"
"1.26000","103.24396","1.27849","70.60000","0.00000","1.26000","0.20000"
"1.26000","103.20831","1.27805","70.83000","0.00000","1.26000","0.20000"
"1.26000","103.16671","1.27754","71.06000","0.00000","1.26000","0.20000"
"1.26000","103.13087","1.27709","71.29000","0.00000","1.26000","0.20000"
"1.26000","103.08949","1.27658","71.52000","0.00000","1.26000","0.20000"
"1.26000","103.04053","1.27598","71.75000","0.00000","1.26000","0.20000"
"1.26000","103.00504","1.27554","71.98000","0.00000","1.26000","0.20000"
"1.26000","102.96102","1.27499","72.21000","0.00000","1.26000","0.20000"
"1.26000","102.92737","1.27457","72.44000","0.00000","1.26000","0.20000"
"1.26000","102.87629","1.27394","72.67000","0.00000","1.26000","0.20000"
"1.26000","102.85218","1.27364","72.90000","0.00000","1.26000","0.20000"
"1.26000","102.81755","1.27321","73.13000","0.00000","1.26000","0.20000"
"1.26000","102.77081","1.27264","73.36000","0.00000","1.26000","0.20000"
"1.26000","102.73175","1.27215","73.59000","0.00000","1.26000","0.20000"
"1.26000","102.69277","1.27167","73.82000","0.00000","1.26000","0.20000"
"1.26000","102.65636","1.27122","74.05000","0.00000","1.26000","0.20000"
"1.26000","102.61529","1.27071","74.28000","0.00000","1.26000","0.20000"
"1.26000","102.58240","1.27030","74.51000","0.00000","1.26000","0.20000"
"1.26000","102.53111","1.26967","74.74000","0.00000","1.26000","0.20000"
"1.26000","102.50185","1.26930","74.97000","0.00000","1.26000","0.20000"
"1.26000","102.46893","1.26890","75.20000","0.00000","1.26000","0.20000"
"1.26000","102.43087","1.26843","75.43000","0.00000","1.26000","0.20000"
"1.26000","102.39074","1.26793","75.66000","0.00000","1.26000","0.20000"
"1.26000","102.36256","1.26758","75.89000","0.00000","1.26000","0.20000"
"1.26000","102.32233","1.26708","76.12000","0.00000","1.26000","0.20000"
"1.26000","102.29011","1.26668","76.35000","0.00000","1.26000","0.20000"
"1.26000","102.25597","1.26626","76.58000","0.00000","1.26000","0.20000"
"1.26000","102.22210","1.26584","76.81000","0.00000","1.26000","0.20000"
"1.26000","102.18508","1.26538","77.04000","0.00000","1.26000","0.20000"
"1.26000","102.15225","1.26498","77.27000","0.00000","1.26000","0.20000"
"1.26000","102.12010","1.26458","77.50000","0.00000","1.26000","0.20000"
"1.26000","102.08527","1.26415","77.73000","0.00000","1.26000","0.20000"
"1.26000","102.05315","1.26375","77.96000","0.00000","1.26000","0.20000"
"1.26000","102.02073","1.26335","78.19000","0.00000","1.26000","0.20000"
"1.26000","101.97619","1.26280","78.42000","0.00000","1.26000","0.20000"
"1.26000","101.95480","1.26253","78.65000","0.00000","1.26000","0.20000"
"1.26000","101.91203","1.26200","78.88000","0.00000","1.26000","0.20000"
"1.26000","101.88139","1.26162","79.11000","0.00000","1.26000","0.20000"
"1.26000","101.84827","1.26121","79.34000","0.00000","1.26000","0.20000"
"1.26000","101.81522","1.26080","79.57000","0.00000","1.26000","0.20000"
"1.26000","101.78607","1.26044","79.80000","0.00000","1.26000","0.20000"
"1.26000","101.74607","1.25995","80.03000","0.00000","1.26000","0.20000"
"1.26000","101.71925","1.25961","80.26000","0.00000","1.26000","0.20000"
"1.26000","101.69221","1.25928","80.49000","0.00000","1.26000","0.20000"
"1.26000","101.65115","1.25877","80.72000","0.00000","1.26000","0.20000"
"1.26000","101.61964","1.25838","80.95000","0.00000","1.26000","0.20000"
"1.26000","101.59063","1.25802","81.18000","0.00000","1.26000","0.20000"
"1.26000","101.56160","1.25766","81.41000","0.00000","1.26000","0.20000"
"1.26000","101.51945","1.25714","81.64000","0.00000","1.26000","0.20000"
"1.26000","101.49271","1.25681","81.87000","0.00000","1.26000","0.20000"
"1.26000","101.46011","1.25640","82.10000","0.00000","1.26000","0.20000"
"1.26000","101.42374","1.25595","82.33000","0.00000","1.26000","0.20000"
"1.26000","101.39314","1.25558","82.56000","0.00000","1.26000","0.20000"
"1.26000","101.36675","1.25525","82.79000","0.00000","1.26000","0.20000"
"1.26000","101.33662","1.25488","83.02000","0.00000","1.26000","0.20000"
"1.26000","101.30557","1.25449","83.25000","0.00000","1.26000","0.20000"
"1.26000","101.27467","1.25411","83.48000","0.00000","1.26000","0.20000"
"1.26000","101.24976","1.25380","83.71000","0.00000","1.26000","0.20000"
"1.26000","101.21549","1.25338","83.94000","0.00000","1.26000","0.20000"
"1.26000","101.17509","1.25288","84.17000","0.00000","1.26000","0.20000"
"1.26000","101.15321","1.25260","84.40000","0.00000","1.26000","0.20000"
"1.26000","101.12055","1.25220","84.63000","0.00000","1.26000","0.20000"
"1.26000","101.09207","1.25185","84.86000","0.00000","1.26000","0.20000"
"1.26000","101.06037","1.25145","85.09000","0.00000","1.26000","0.20000"
"1.26000","101.03943","1.25120","85.32000","0.00000","1.26000","0.20000"
"1.26000","101.01184","1.25085","85.55000","0.00000","1.26000","0.20000"
"1.26000","100.97343","1.25038","85.78000","0.00000","1.26000","0.20000"
"1.26000","100.95103","1.25010","86.01000","0.00000","1.26000","0.20000"
"1.26000","100.92886","1.24983","86.24000","0.00000","1.26000","0.20000"
"1.26000","100.89790","1.24944","86.47000","0.00000","1.26000","0.20000"
"1.26000","100.85876","1.24896","86.70000","0.00000","1.26000","0.20000"
"1.26000","100.83357","1.24865","86.93000","0.00000","1.26000","0.20000"
"1.26000","100.80714","1.24832","87.16000","0.00000","1.26000","0.20000"
"1.26000","100.76971","1.24786","87.39000","0.00000","1.26000","0.20000"
"1.26000","100.74228","1.24752","87.62000","0.00000","1.26000","0.20000"
"1.26000","100.72205","1.24726","87.85000","0.00000","1.26000","0.20000"
"1.26000","100.70250","1.24702","88.08000","0.00000","1.26000","0.20000"
"1.26000","100.66329","1.24654","88.31000","0.00000","1.26000","0.20000"
"1.26000","100.64232","1.24628","88.54000","0.00000","1.26000","0.20000"
"1.26000","100.60873","1.24586","88.77000","0.00000","1.26000","0.20000"
"1.26000","100.58467","1.24556","89.00000","0.00000","1.26000","0.20000"
"1.26000","100.55975","1.24526","89.23000","0.00000","1.26000","0.20000"
"1.26000","100.53883","1.24500","89.46000","0.00000","1.26000","0.20000"
"1.26000","100.49691","1.24448","89.69000","0.00000","1.26000","0.20000"
"1.26000","100.47448","1.24420","89.92000","0.00000","1.26000","0.20000"
"1.26000","100.45047","1.24390","90.15000","0.00000","1.26000","0.20000"
"1.26000","100.42184","1.24355","90.38000","0.00000","1.26000","0.20000"
"1.26000","100.39725","1.24324","90.61000","0.00000","1.26000","0.20000"
"1.26000","100.36996","1.24291","90.84000","0.00000","1.26000","0.20000"
"1.26000","100.33630","1.24249","91.07000","0.00000","1.26000","0.20000"
"1.26000","100.30469","1.24210","91.30000","0.00000","1.26000","0.20000"
"1.26000","100.27963","1.24179","91.53000","0.00000","1.26000","0.20000"
"1.26000","100.25531","1.24149","91.76000","0.00000","1.26000","0.20000"
"1.26000","100.23168","1.24119","91.99000","0.00000","1.26000","0.20000"
"1.26000","100.21208","1.24095","92.22000","0.00000","1.26000","0.20000"
"1.26000","100.18295","1.24059","92.45000","0.00000","1.26000","0.20000"
"1.26000","100.15830","1.24028","92.68000","0.00000","1.26000","0.20000"
"1.26000","100.13437","1.23999","92.91000","0.00000","1.26000","0.20000"
"1.26000","100.10840","1.23967","93.14000","0.00000","1.26000","0.20000"
"1.26000","100.07919","1.23930","93.37000","0.00000","1.26000","0.20000"
"1.26000","100.05009","1.23894","93.60000","0.00000","1.26000","0.20000"
"1.26000","100.03411","1.23875","93.83000","0.00000","1.26000","0.20000"
"1.26000","100.01370","1.23849","94.06000","0.00000","1.26000","0.20000"
"1.26000","99.97283","1.23799","94.29000","0.00000","1.26000","0.20000"
"1.26000","99.95452","1.23776","94.52000","0.00000","1.26000","0.20000"
"1.26000","99.93000","1.23746","94.75000","0.00000","1.26000","0.20000"
"1.26000","99.89557","1.23703","94.98000","0.00000","1.26000","0.20000"
"1.26000","99.87843","1.23682","95.21000","0.00000","1.26000","0.20000"
"1.26000","99.84871","1.23645","95.44000","0.00000","1.26000","0.20000"
"1.26000","99.82735","1.23619","95.67000","0.00000","1.26000","0.20000"
"1.26000","99.80374","1.23589","95.90000","0.00000","1.26000","0.20000"
"1.26000","99.77969","1.23560","96.13000","0.00000","1.26000","0.20000"
"1.26000","99.75392","1.23528","96.36000","0.00000","1.26000","0.20000"
"1.26000","99.72589","1.23493","96.59000","0.00000","1.26000","0.20000"
"1.26000","99.71183","1.23476","96.82000","0.00000","1.26000","0.20000"
"1.26000","99.68722","1.23445","97.05000","0.00000","1.26000","0.20000"
"1.26000","99.65070","1.23400","97.28000","0.00000","1.26000","0.20000"
"1.26000","99.63500","1.23380","97.51000","0.00000","1.26000","0.20000"
"1.26000","99.60287","1.23341","97.74000","0.00000","1.26000","0.20000"
"1.26000","99.58738","1.23321","97.97000","0.00000","1.26000","0.20000"
"1.26000","99.56295","1.23291","98.20000","0.00000","1.26000","0.20000"
"1.26000","99.54545","1.23269","98.43000","0.00000","1.26000","0.20000"
"1.26000","99.50965","1.23225","98.66000","0.00000","1.26000","0.20000"
"1.26000","99.49431","1.23206","98.89000","0.00000","1.26000","0.20000"
"1.26000","99.46068","1.23165","99.12000","0.00000","1.26000","0.20000"
"1.26000","99.45162","1.23153","99.35000","0.00000","1.26000","0.20000"
"1.26000","99.42560","1.23121","99.58000","0.00000","1.26000","0.20000"
"1.26000","99.40276","1.23093","99.81000","0.00000","1.26000","0.20000"
"1.26000","99.36798","1.23050","100.04000","0.00000","1.26000","0.20000"
"1.26000","99.34747","1.23024","100.27000","0.00000","1.26000","0.20000"
"1.26000","99.32602","1.22998","100.50000","0.00000","1.26000","0.20000"
"1.26000","99.30769","1.22975","100.73000","0.00000","1.26000","0.20000"
"1.26000","99.29202","1.22956","100.96000","0.00000","1.26000","0.20000"
"1.26000","99.26244","1.22919","101.19000","0.00000","1.26000","0.20000"
"1.26000","99.24306","1.22895","101.42000","0.00000","1.26000","0.20000"
"1.26000","99.21997","1.22866","101.65000","0.00000","1.26000","0.20000"
"1.26000","99.18867","1.22828","101.88000","0.00000","1.26000","0.20000"
"1.26000","99.16805","1.22802","102.11000","0.00000","1.26000","0.20000"
"1.26000","99.14827","1.22778","102.34000","0.00000","1.26000","0.20000"
"1.26000","99.12378","1.22747","102.57000","0.00000","1.26000","0.20000"
"1.26000","99.11032","1.22731","102.80000","0.00000","1.26000","0.20000"
"1.26000","99.07980","1.22693","103.03000","0.00000","1.26000","0.20000"
"1.26000","99.06280","1.22672","103.26000","0.00000","1.26000","0.20000"
"1.26000","99.03737","1.22640","103.49000","0.00000","1.26000","0.20000"
"1.26000","99.02161","1.22621","103.72000","0.00000","1.26000","0.20000"
"1.26000","98.99216","1.22584","103.95000","0.00000","1.26000","0.20000"
"1.26000","98.97037","1.22557","104.18000","0.00000","1.26000","0.20000"
"1.26000","98.94803","1.22530","104.41000","0.00000","1.26000","0.20000"
"1.26000","98.93349","1.22512","104.64000","0.00000","1.26000","0.20000"
"1.26000","98.90943","1.22482","104.87000","0.00000","1.26000","0.20000"
"1.26000","98.89270","1.22461","105.10000","0.00000","1.26000","0.20000"
"1.26000","98.87344","1.22437","105.33000","0.00000","1.26000","0.20000"
"1.26000","98.84763","1.22405","105.56000","0.00000","1.26000","0.20000"
"1.26000","98.82416","1.22376","105.79000","0.00000","1.26000","0.20000"
"1.26000","98.81029","1.22359","106.02000","0.00000","1.26000","0.20000"
"1.26000","98.78648","1.22330","106.25000","0.00000","1.26000","0.20000"
"1.26000","98.75523","1.22291","106.48000","0.00000","1.26000","0.20000"
"1.26000","98.73978","1.22272","106.71000","0.00000","1.26000","0.20000"
"1.26000","98.72292","1.22251","106.94000","0.00000","1.26000","0.20000"
"1.26000","98.69862","1.22221","107.17000","0.00000","1.26000","0.20000"
"1.26000","98.67887","1.22196","107.40000","0.00000","1.26000","0.20000"
"1.26000","98.65726","1.22170","107.63000","0.00000","1.26000","0.20000"
"1.26000","98.63573","1.22143","107.86000","0.00000","1.26000","0.20000"
"1.26000","98.61549","1.22118","108.09000","0.00000","1.26000","0.20000"
"1.26000","98.59093","1.22087","108.32000","0.00000","1.26000","0.20000"
"1.26000","98.57428","1.22067","108.55000","0.00000","1.26000","0.20000"
"1.26000","98.54905","1.22036","108.78000","0.00000","1.26000","0.20000"
"1.26000","98.53030","1.22012","109.01000","0.00000","1.26000","0.20000"
"1.26000","98.50969","1.21987","109.24000","0.00000","1.26000","0.20000"
"1.26000","98.49088","1.21964","109.47000","0.00000","1.26000","0.20000"
"1.26000","98.47253","1.21941","109.70000","0.00000","1.26000","0.20000"
"1.26000","98.45374","1.21918","109.93000","0.00000","1.26000","0.20000"
"1.26000","98.42845","1.21886","110.16000","0.00000","1.26000","0.20000"
"1.26000","98.41222","1.21866","110.39000","0.00000","1.26000","0.20000"
"1.26000","98.38576","1.21833","110.62000","0.00000","1.26000","0.20000"
"1.26000","98.36578","1.21809","110.85000","0.00000","1.26000","0.20000"
"1.26000","98.35464","1.21795","111.08000","0.00000","1.26000","0.20000"
"1.26000","98.32955","1.21764","111.31000","0.00000","1.26000","0.20000"
"1.26000","98.30698","1.21736","111.54000","0.00000","1.26000","0.20000"
"1.26000","98.29165","1.21717","111.77000","0.00000","1.26000","0.20000"
"1.26000","98.27436","1.21695","112.00000","0.00000","1.26000","0.20000"
"1.26000","98.25265","1.21669","112.23000","0.00000","1.26000","0.20000"
"1.26000","98.23430","1.21646","112.46000","0.00000","1.26000","0.20000"
"1.26000","98.22326","1.21632","112.69000","0.00000","1.26000","0.20000"
"1.26000","98.18649","1.21587","112.92000","0.00000","1.26000","0.20000"
"1.26000","98.17504","1.21572","113.15000","0.00000","1.26000","0.20000"
"1.26000","98.15819","1.21552","113.38000","0.00000","1.26000","0.20000"
"1.26000","98.12903","1.21516","113.61000","0.00000","1.26000","0.20000"
"1.26000","98.11269","1.21495","113.84000","0.00000","1.26000","0.20000"
"1.26000","98.09674","1.21476","114.07000","0.00000","1.26000","0.20000"
"1.26000","98.08096","1.21456","114.30000","0.00000","1.26000","0.20000"
"1.26000","98.05479","1.21424","114.53000","0.00000","1.26000","0.20000"
"1.26000","98.05185","1.21420","114.76000","0.00000","1.26000","0.20000"
"1.26000","98.02085","1.21382","114.99000","0.00000","1.26000","0.20000"
"1.26000","98.00433","1.21361","115.22000","0.00000","1.26000","0.20000"
"1.26000","97.99075","1.21344","115.45000","0.00000","1.26000","0.20000"
"1.26000","97.96830","1.21316","115.68000","0.00000","1.26000","0.20000"
"1.26000","97.94943","1.21293","115.91000","0.00000","1.26000","0.20000"
"1.26000","97.92609","1.21264","116.14000","0.00000","1.26000","0.20000"
"1.26000","97.90415","1.21237","116.37000","0.00000","1.26000","0.20000"
"1.26000","97.89631","1.21227","116.60000","0.00000","1.26000","0.20000"
"1.26000","97.87376","1.21199","116.83000","0.00000","1.26000","0.20000"
"1.26000","97.85501","1.21176","117.06000","0.00000","1.26000","0.20000"
"1.26000","97.83830","1.21155","117.29000","0.00000","1.26000","0.20000"
"1.26000","97.81583","1.21128","117.52000","0.00000","1.26000","0.20000"
"1.26000","97.79859","1.21106","117.75000","0.00000","1.26000","0.20000"
"1.26000","97.78432","1.21089","117.98000","0.00000","1.26000","0.20000"
"1.26000","97.76231","1.21061","118.21000","0.00000","1.26000","0.20000"
"1.26000","97.75325","1.21050","118.44000","0.00000","1.26000","0.20000"
"1.26000","97.73240","1.21024","118.67000","0.00000","1.26000","0.20000"
"1.26000","97.70965","1.20996","118.90000","0.00000","1.26000","0.20000"
"1.26000","97.69453","1.20977","119.13000","0.00000","1.26000","0.20000"
"1.26000","97.67153","1.20949","119.36000","0.00000","1.26000","0.20000"
"1.26000","97.65822","1.20932","119.59000","0.00000","1.26000","0.20000"
"1.26000","97.63710","1.20906","119.82000","0.00000","1.26000","0.20000"
"1.26000","97.61516","1.20879","120.05000","0.00000","1.26000","0.20000"
"1.26000","97.60518","1.20867","120.28000","0.00000","1.26000","0.20000"
"1.26000","97.58922","1.20847","120.51000","0.00000","1.26000","0.20000"
"1.26000","97.57289","1.20827","120.74000","0.00000","1.26000","0.20000"
"1.26000","97.55132","1.20800","120.97000","0.00000","1.26000","0.20000"
"1.26000","97.53471","1.20780","121.20000","0.00000","1.26000","0.20000"
"1.26000","97.51241","1.20752","121.43000","0.00000","1.26000","0.20000"
"1.26000","97.50046","1.20737","121.66000","0.00000","1.26000","0.20000"
"1.26000","97.48151","1.20714","121.89000","0.00000","1.26000","0.20000"
"1.26000","97.46321","1.20691","122.12000","0.00000","1.26000","0.20000"
"1.26000","97.45078","1.20676","122.35000","0.00000","1.26000","0.20000"
"1.26000","97.43687","1.20658","122.58000","0.00000","1.26000","0.20000"
"1.26000","97.41630","1.20633","122.81000","0.00000","1.26000","0.20000"
"1.26000","97.39366","1.20605","123.04000","0.00000","1.26000","0.20000"
"1.26000","97.37122","1.20577","123.27000","0.00000","1.26000","0.20000"
"1.26000","97.36175","1.20565","123.50000","0.00000","1.26000","0.20000"
"1.26000","97.33856","1.20537","123.73000","0.00000","1.26000","0.20000"
"1.26000","97.31786","1.20511","123.96000","0.00000","1.26000","0.20000"
"1.26000","97.30991","1.20501","124.19000","0.00000","1.26000","0.20000"
"1.26000","97.29059","1.20477","124.42000","0.00000","1.26000","0.20000"
"1.26000","97.27876","1.20463","124.65000","0.00000","1.26000","0.20000"
"1.26000","97.26488","1.20445","124.88000","0.00000","1.26000","0.20000"
"1.26000","97.24135","1.20416","125.11000","0.00000","1.26000","0.20000"
"1.26000","97.22677","1.20398","125.34000","0.00000","1.26000","0.20000"
"1.26000","97.21118","1.20379","125.57000","0.00000","1.26000","0.20000"
"1.26000","97.19849","1.20363","125.80000","0.00000","1.26000","0.20000"
"1.26000","97.17278","1.20331","126.03000","0.00000","1.26000","0.20000"
"1.26000","97.15985","1.20315","126.26000","0.00000","1.26000","0.20000"
"1.26000","97.14164","1.20293","126.49000","0.00000","1.26000","0.20000"
"1.26000","97.12545","1.20273","126.72000","0.00000","1.26000","0.20000"
"1.26000","97.10517","1.20248","126.95000","0.00000","1.26000","0.20000"
"1.26000","97.08669","1.20225","127.18000","0.00000","1.26000","0.20000"
"1.26000","97.07190","1.20206","127.41000","0.00000","1.26000","0.20000"
"1.26000","97.06586","1.20199","127.64000","0.00000","1.26000","0.20000"
"1.26000","97.04399","1.20172","127.87000","0.00000","1.26000","0.20000"
"1.26000","97.02548","1.20149","128.10000","0.00000","1.26000","0.20000"
"1.26000","97.01838","1.20140","128.33000","0.00000","1.26000","0.20000"
"1.26000","96.99439","1.20110","128.56000","0.00000","1.26000","0.20000"
"1.26000","96.98105","1.20094","128.79000","0.00000","1.26000","0.20000"
"1.26000","96.97231","1.20083","129.02000","0.00000","1.26000","0.20000"
"1.26000","96.95129","1.20057","129.25000","0.00000","1.26000","0.20000"
"1.26000","96.93320","1.20035","129.48000","0.00000","1.26000","0.20000"
"1.26000","96.91924","1.20017","129.71000","0.00000","1.26000","0.20000"
"1.26000","96.91127","1.20008","129.94000","0.00000","1.26000","0.20000"
"1.26000","96.89037","1.19982","130.17000","0.00000","1.26000","0.20000"
"1.26000","96.86895","1.19955","130.40000","0.00000","1.26000","0.20000"
"1.26000","96.85548","1.19938","130.63000","0.00000","1.26000","0.20000"
"1.26000","96.83578","1.19914","130.86000","0.00000","1.26000","0.20000"
"1.26000","96.82104","1.19896","131.09000","0.00000","1.26000","0.20000"
"1.26000","96.80882","1.19881","131.32000","0.00000","1.26000","0.20000"
"1.26000","96.79026","1.19858","131.55000","0.00000","1.26000","0.20000"
"1.26000","96.77604","1.19840","131.78000","0.00000","1.26000","0.20000"
"1.26000","96.75695","1.19816","132.01000","0.00000","1.26000","0.20000"
"1.26000","96.74136","1.19797","132.24000","0.00000","1.26000","0.20000"
"1.26000","96.73301","1.19787","132.47000","0.00000","1.26000","0.20000"
"1.26000","96.72488","1.19777","132.70000","0.00000","1.26000","0.20000"
"1.26000","96.69463","1.19739","132.93000","0.00000","1.26000","0.20000"
"1.26000","96.68214","1.19724","133.16000","0.00000","1.26000","0.20000"
"1.26000","96.66721","1.19705","133.39000","0.00000","1.26000","0.20000"
"1.26000","96.65754","1.19693","133.62000","0.00000","1.26000","0.20000"
"1.26000","96.63865","1.19670","133.85000","0.00000","1.26000","0.20000"
"1.26000","96.61339","1.19639","134.08000","0.00000","1.26000","0.20000"
"1.26000","96.61381","1.19639","134.31000","0.00000","1.26000","0.20000"
"1.26000","96.59774","1.19619","134.54000","0.00000","1.26000","0.20000"
"1.26000","96.57999","1.19597","134.77000","0.00000","1.26000","0.20000"
"1.26000","96.55731","1.19569","135.00000","0.00000","1.26000","0.20000"
"1.26000","96.55163","1.19562","135.23000","0.00000","1.26000","0.20000"
"1.26000","96.52532","1.19530","135.46000","0.00000","1.26000","0.20000"
"1.26000","96.52861","1.19534","135.69000","0.00000","1.26000","0.20000"
"1.26000","96.49274","1.19489","135.92000","0.00000","1.26000","0.20000"
"1.26000","96.49093","1.19487","136.15000","0.00000","1.26000","0.20000"
"1.26000","96.47683","1.19470","136.38000","0.00000","1.26000","0.20000"
"1.26000","96.46139","1.19450","136.61000","0.00000","1.26000","0.20000"
"1.26000","96.45100","1.19438","136.84000","0.00000","1.26000","0.20000"
"1.26000","96.43777","1.19421","137.07000","0.00000","1.26000","0.20000"
"1.26000","96.40591","1.19382","137.30000","0.00000","1.26000","0.20000"
"1.26000","96.38553","1.19356","137.53000","0.00000","1.26000","0.20000"
"1.26000","96.38128","1.19351","137.76000","0.00000","1.26000","0.20000"
"1.26000","96.37263","1.19341","137.99000","0.00000","1.26000","0.20000"
"1.26000","96.35571","1.19320","138.22000","0.00000","1.26000","0.20000"
"1.26000","96.33520","1.19294","138.45000","0.00000","1.26000","0.20000"
"1.26000","96.33600","1.19295","138.68000","0.00000","1.26000","0.20000"
"1.26000","96.31590","1.19270","138.91000","0.00000","1.26000","0.20000"
"1.26000","96.28787","1.19236","139.14000","0.00000","1.26000","0.20000"
"1.26000","96.29074","1.19239","139.37000","0.00000","1.26000","0.20000"
"1.26000","96.26936","1.19213","139.60000","0.00000","1.26000","0.20000"
"1.26000","96.24790","1.19186","139.83000","0.00000","1.26000","0.20000"
"1.26000","96.24415","1.19181","140.06000","0.00000","1.26000","0.20000"
"1.26000","96.22073","1.19152","140.29000","0.00000","1.26000","0.20000"
"1.26000","96.21413","1.19144","140.52000","0.00000","1.26000","0.20000"
"1.26000","96.18939","1.19114","140.75000","0.00000","1.26000","0.20000"
"1.26000","96.18347","1.19106","140.98000","0.00000","1.26000","0.20000"
"1.26000","96.17625","1.19097","141.21000","0.00000","1.26000","0.20000"
"1.26000","96.15340","1.19069","141.44000","0.00000","1.26000","0.20000"
"1.26000","96.14616","1.19060","141.67000","0.00000","1.26000","0.20000"
"1.26000","96.12884","1.19039","141.90000","0.00000","1.26000","0.20000"
"1.26000","96.10782","1.19013","142.13000","0.00000","1.26000","0.20000"
"1.26000","96.09631","1.18998","142.36000","0.00000","1.26000","0.20000"
"1.26000","96.09637","1.18998","142.59000","0.00000","1.26000","0.20000"
"1.26000","96.06123","1.18955","142.82000","0.00000","1.26000","0.20000"
"1.26000","96.05797","1.18951","143.05000","0.00000","1.26000","0.20000"
"1.26000","96.03446","1.18922","143.28000","0.00000","1.26000","0.20000"
"1.26000","96.03474","1.18922","143.51000","0.00000","1.26000","0.20000"
"1.26000","96.01704","1.18900","143.74000","0.00000","1.26000","0.20000"
"1.26000","96.00765","1.18889","143.97000","0.00000","1.26000","0.20000"
"1.26000","95.99612","1.18874","144.20000","0.00000","1.26000","0.20000"
"1.26000","95.97394","1.18847","144.43000","0.00000","1.26000","0.20000"
"1.26000","95.95795","1.18827","144.66000","0.00000","1.26000","0.20000"
"1.26000","95.96612","1.18837","144.89000","0.00000","1.26000","0.20000"
"1.26000","95.92479","1.18786","145.12000","0.00000","1.26000","0.20000"
"1.26000","95.92423","1.18785","145.35000","0.00000","1.26000","0.20000"
"1.26000","95.90915","1.18767","145.58000","0.00000","1.26000","0.20000"
"1.26000","95.89639","1.18751","145.81000","0.00000","1.26000","0.20000"
"1.26000","95.88287","1.18734","146.04000","0.00000","1.26000","0.20000"
"1.26000","95.86772","1.18715","146.27000","0.00000","1.26000","0.20000"
"1.26000","95.86555","1.18713","146.50000","0.00000","1.26000","0.20000"
"1.26000","95.83668","1.18677","146.73000","0.00000","1.26000","0.20000"
"1.26000","95.83821","1.18679","146.96000","0.00000","1.26000","0.20000"
"1.26000","95.81803","1.18654","147.19000","0.00000","1.26000","0.20000"
"1.26000","95.82201","1.18659","147.42000","0.00000","1.26000","0.20000"
"1.26000","95.79926","1.18631","147.65000","0.00000","1.26000","0.20000"
"1.26000","95.78434","1.18612","147.88000","0.00000","1.26000","0.20000"
"1.26000","95.77201","1.18597","148.11000","0.00000","1.26000","0.20000"
"1.26000","95.76532","1.18588","148.34000","0.00000","1.26000","0.20000"
"1.26000","95.74489","1.18563","148.57000","0.00000","1.26000","0.20000"
"1.26000","95.74016","1.18557","148.80000","0.00000","1.26000","0.20000"
"1.26000","95.71687","1.18528","149.03000","0.00000","1.26000","0.20000"
"1.26000","95.70739","1.18517","149.26000","0.00000","1.26000","0.20000"
"1.26000","95.69621","1.18503","149.49000","0.00000","1.26000","0.20000"
"1.26000","95.68374","1.18487","149.72000","0.00000","1.26000","0.20000"
"1.26000","95.67216","1.18473","149.95000","0.00000","1.26000","0.20000"
"1.26000","95.66264","1.18461","150.18000","0.00000","1.26000","0.20000"
"1.26000","95.64511","1.18440","150.41000","0.00000","1.26000","0.20000"
"1.26000","95.63416","1.18426","150.64000","0.00000","1.26000","0.20000"
"1.26000","95.61600","1.18404","150.87000","0.00000","1.26000","0.20000"
"1.26000","95.61141","1.18398","151.10000","0.00000","1.26000","0.20000"
"1.26000","95.59552","1.18378","151.33000","0.00000","1.26000","0.20000"
"1.26000","95.58387","1.18364","151.50000","0.00000","1.26000","0.20000"