File: Rubber Stress Relaxation Raw Data -Large  Samples-20210211/Specimen_RawData_8.csv
Specimen properties : Specimen label,"9"
Specimen properties : Anvil height,"6.36000",mm
Specimen properties : Diameter,"10.68000",mm
Test : Rate 1,"24.00000",mm/min
Test : Start of hold value,"20.00000",%
Test : Duration,"120.00000",s

Extension,Load,Compressive stress,Time,PIP count,Compressive extension,Compressive strain (Extension)
(mm),(N),(MPa),(s),,(mm),(mm/mm)
"0.00042","0.01671","0.00019","0.00000","0.00000","0.00042","0.00007"
"0.05958","6.99137","0.07804","0.18000","0.00000","0.05958","0.00937"
"0.14021","19.82709","0.22132","0.36000","0.00000","0.14021","0.02205"
"0.21542","29.57025","0.33008","0.54000","0.00000","0.21542","0.03387"
"0.28813","38.18662","0.42626","0.72000","0.00000","0.28813","0.04530"
"0.36104","46.43143","0.51830","0.90000","0.00000","0.36104","0.05677"
"0.43313","54.37029","0.60692","1.08000","0.00000","0.43312","0.06810"
"0.50542","62.33936","0.69587","1.26000","0.00000","0.50542","0.07947"
"0.57771","70.45544","0.78647","1.44000","0.00000","0.57771","0.09083"
"0.64896","78.48914","0.87615","1.62000","0.00000","0.64896","0.10204"
"0.72104","86.82977","0.96925","1.80000","0.00000","0.72104","0.11337"
"0.79333","95.38986","1.06480","1.98000","0.00000","0.79333","0.12474"
"0.86500","104.01443","1.16108","2.16000","0.00000","0.86500","0.13601"
"0.93708","112.92829","1.26058","2.34000","0.00000","0.93708","0.14734"
"1.00958","122.09095","1.36286","2.52000","0.00000","1.00958","0.15874"
"1.08063","131.43242","1.46714","2.70000","0.00000","1.08063","0.16991"
"1.15271","141.48875","1.57939","2.88000","0.00000","1.15271","0.18124"
"1.22521","151.77324","1.69419","3.06000","0.00000","1.22521","0.19264"
"1.28042","159.03876","1.77530","3.23000","0.00000","1.28042","0.20132"
"1.28083","146.22542","1.63226","3.41000","0.00000","1.28083","0.20139"
"1.27979","140.67281","1.57028","3.59000","0.00000","1.27979","0.20123"
"1.27792","136.62326","1.52508","3.77000","0.00000","1.27792","0.20093"
"1.27604","133.29474","1.48792","3.95000","0.00000","1.27604","0.20064"
"1.27437","130.76579","1.45969","4.13000","0.00000","1.27437","0.20037"
"1.27333","128.90414","1.43891","4.31000","0.00000","1.27333","0.20021"
"1.27292","127.46394","1.42284","4.49000","0.00000","1.27292","0.20014"
"1.27271","126.32656","1.41014","4.67000","0.00000","1.27271","0.20011"
"1.27271","125.35718","1.39932","4.85000","0.00000","1.27271","0.20011"
"1.27250","124.42546","1.38892","5.03000","0.00000","1.27250","0.20008"
"1.27250","123.64278","1.38018","5.21000","0.00000","1.27250","0.20008"
"1.27250","122.91251","1.37203","5.39000","0.00000","1.27250","0.20008"
"1.27250","122.23038","1.36442","5.57000","0.00000","1.27250","0.20008"
"1.27250","121.60216","1.35740","5.75000","0.00000","1.27250","0.20008"
"1.27250","120.99742","1.35065","5.93000","0.00000","1.27250","0.20008"
"1.27250","120.45039","1.34455","6.11000","0.00000","1.27250","0.20008"
"1.27250","119.92001","1.33863","6.29000","0.00000","1.27250","0.20008"
"1.27250","119.43252","1.33318","6.47000","0.00000","1.27250","0.20008"
"1.27250","118.97311","1.32806","6.65000","0.00000","1.27250","0.20008"
"1.27250","118.52924","1.32310","6.83000","0.00000","1.27250","0.20008"
"1.27250","118.11932","1.31853","7.01000","0.00000","1.27250","0.20008"
"1.27250","117.72240","1.31409","7.19000","0.00000","1.27250","0.20008"
"1.27250","117.33624","1.30978","7.37000","0.00000","1.27250","0.20008"
"1.27250","116.96989","1.30569","7.55000","0.00000","1.27250","0.20008"
"1.27250","116.62793","1.30188","7.73000","0.00000","1.27250","0.20008"
"1.27250","116.29839","1.29820","7.91000","0.00000","1.27250","0.20008"
"1.27250","115.98055","1.29465","8.09000","0.00000","1.27250","0.20008"
"1.27229","115.66823","1.29116","8.27000","0.00000","1.27229","0.20005"
"1.27229","115.33449","1.28744","8.45000","0.00000","1.27229","0.20005"
"1.27229","115.06228","1.28440","8.63000","0.00000","1.27229","0.20005"
"1.27229","114.78468","1.28130","8.81000","0.00000","1.27229","0.20005"
"1.27229","114.51756","1.27832","8.99000","0.00000","1.27229","0.20005"
"1.27229","114.27113","1.27557","9.17000","0.00000","1.27229","0.20005"
"1.27229","114.02896","1.27287","9.35000","0.00000","1.27229","0.20005"
"1.27229","113.77679","1.27005","9.53000","0.00000","1.27229","0.20005"
"1.27229","113.55927","1.26762","9.71000","0.00000","1.27229","0.20005"
"1.27229","113.33220","1.26509","9.89000","0.00000","1.27229","0.20005"
"1.27229","113.11562","1.26267","10.07000","0.00000","1.27229","0.20005"
"1.27229","112.90301","1.26030","10.25000","0.00000","1.27229","0.20005"
"1.27229","112.70193","1.25805","10.43000","0.00000","1.27229","0.20005"
"1.27229","112.49266","1.25572","10.61000","0.00000","1.27229","0.20005"
"1.27229","112.30132","1.25358","10.79000","0.00000","1.27229","0.20005"
"1.27229","112.10753","1.25142","10.97000","0.00000","1.27229","0.20005"
"1.27229","111.93082","1.24945","11.15000","0.00000","1.27229","0.20005"
"1.27229","111.74119","1.24733","11.33000","0.00000","1.27229","0.20005"
"1.27229","111.56166","1.24532","11.51000","0.00000","1.27229","0.20005"
"1.27229","111.40376","1.24356","11.69000","0.00000","1.27229","0.20005"
"1.27229","111.24326","1.24177","11.87000","0.00000","1.27229","0.20005"
"1.27229","111.06052","1.23973","12.05000","0.00000","1.27229","0.20005"
"1.27229","110.90074","1.23795","12.23000","0.00000","1.27229","0.20005"
"1.27229","110.75221","1.23629","12.41000","0.00000","1.27229","0.20005"
"1.27229","110.60873","1.23469","12.59000","0.00000","1.27229","0.20005"
"1.27271","110.50443","1.23352","12.77000","0.00000","1.27271","0.20011"
"1.27271","110.38603","1.23220","12.95000","0.00000","1.27271","0.20011"
"1.27271","110.23671","1.23053","13.13000","0.00000","1.27271","0.20011"
"1.27271","110.09563","1.22896","13.31000","0.00000","1.27271","0.20011"
"1.27271","109.94676","1.22730","13.49000","0.00000","1.27271","0.20011"
"1.27271","109.80144","1.22568","13.67000","0.00000","1.27271","0.20011"
"1.27271","109.66518","1.22415","13.85000","0.00000","1.27271","0.20011"
"1.27271","109.54192","1.22278","14.03000","0.00000","1.27271","0.20011"
"1.27271","109.40295","1.22123","14.21000","0.00000","1.27271","0.20011"
"1.27271","109.27979","1.21985","14.39000","0.00000","1.27271","0.20011"
"1.27271","109.14819","1.21838","14.57000","0.00000","1.27271","0.20011"
"1.27271","109.02993","1.21706","14.75000","0.00000","1.27271","0.20011"
"1.27271","108.90526","1.21567","14.93000","0.00000","1.27271","0.20011"
"1.27271","108.77702","1.21424","15.11000","0.00000","1.27271","0.20011"
"1.27271","108.66932","1.21304","15.29000","0.00000","1.27271","0.20011"
"1.27271","108.55539","1.21177","15.47000","0.00000","1.27271","0.20011"
"1.27271","108.44228","1.21050","15.65000","0.00000","1.27271","0.20011"
"1.27271","108.32894","1.20924","15.83000","0.00000","1.27271","0.20011"
"1.27271","108.22320","1.20806","16.01000","0.00000","1.27271","0.20011"
"1.27271","108.10975","1.20679","16.19000","0.00000","1.27271","0.20011"
"1.27271","108.00543","1.20563","16.37000","0.00000","1.27271","0.20011"
"1.27271","107.91871","1.20466","16.55000","0.00000","1.27271","0.20011"
"1.27271","107.80841","1.20343","16.73000","0.00000","1.27271","0.20011"
"1.27271","107.71095","1.20234","16.91000","0.00000","1.27271","0.20011"
"1.27271","107.61292","1.20125","17.09000","0.00000","1.27271","0.20011"
"1.27271","107.50883","1.20008","17.27000","0.00000","1.27271","0.20011"
"1.27271","107.41242","1.19901","17.45000","0.00000","1.27271","0.20011"
"1.27271","107.31729","1.19795","17.63000","0.00000","1.27271","0.20011"
"1.27271","107.22366","1.19690","17.81000","0.00000","1.27271","0.20011"
"1.27271","107.13186","1.19588","17.99000","0.00000","1.27271","0.20011"
"1.27271","107.04108","1.19486","18.17000","0.00000","1.27271","0.20011"
"1.27271","106.95059","1.19385","18.35000","0.00000","1.27271","0.20011"
"1.27271","106.85767","1.19282","18.53000","0.00000","1.27271","0.20011"
"1.27271","106.77620","1.19191","18.71000","0.00000","1.27271","0.20011"
"1.27271","106.68961","1.19094","18.89000","0.00000","1.27271","0.20011"
"1.27271","106.60164","1.18996","19.07000","0.00000","1.27271","0.20011"
"1.27271","106.53314","1.18919","19.25000","0.00000","1.27271","0.20011"
"1.27271","106.44342","1.18819","19.43000","0.00000","1.27271","0.20011"
"1.27271","106.36423","1.18731","19.61000","0.00000","1.27271","0.20011"
"1.27271","106.28397","1.18641","19.79000","0.00000","1.27271","0.20011"
"1.27271","106.19686","1.18544","19.97000","0.00000","1.27271","0.20011"
"1.27271","106.12641","1.18465","20.15000","0.00000","1.27271","0.20011"
"1.27271","106.03872","1.18367","20.33000","0.00000","1.27271","0.20011"
"1.27271","105.95608","1.18275","20.51000","0.00000","1.27271","0.20011"
"1.27271","105.88246","1.18193","20.69000","0.00000","1.27271","0.20011"
"1.27271","105.80798","1.18110","20.87000","0.00000","1.27271","0.20011"
"1.27271","105.72990","1.18023","21.05000","0.00000","1.27271","0.20011"
"1.27271","105.66309","1.17948","21.23000","0.00000","1.27271","0.20011"
"1.27271","105.59106","1.17868","21.41000","0.00000","1.27271","0.20011"
"1.27271","105.52295","1.17792","21.59000","0.00000","1.27271","0.20011"
"1.27271","105.44912","1.17709","21.77000","0.00000","1.27271","0.20011"
"1.27271","105.38143","1.17634","21.95000","0.00000","1.27271","0.20011"
"1.27271","105.30080","1.17544","22.13000","0.00000","1.27271","0.20011"
"1.27271","105.24584","1.17482","22.31000","0.00000","1.27271","0.20011"
"1.27271","105.17548","1.17404","22.49000","0.00000","1.27271","0.20011"
"1.27271","105.10963","1.17330","22.67000","0.00000","1.27271","0.20011"
"1.27271","105.03593","1.17248","22.85000","0.00000","1.27271","0.20011"
"1.27271","104.97546","1.17181","23.03000","0.00000","1.27271","0.20011"
"1.27271","104.90165","1.17098","23.21000","0.00000","1.27271","0.20011"
"1.27271","104.84325","1.17033","23.39000","0.00000","1.27271","0.20011"
"1.27271","104.78805","1.16971","23.57000","0.00000","1.27271","0.20011"
"1.27271","104.72597","1.16902","23.75000","0.00000","1.27271","0.20011"
"1.27271","104.65333","1.16821","23.93000","0.00000","1.27271","0.20011"
"1.27271","104.59407","1.16755","24.11000","0.00000","1.27271","0.20011"
"1.27271","104.53629","1.16690","24.29000","0.00000","1.27271","0.20011"
"1.27271","104.47630","1.16623","24.47000","0.00000","1.27271","0.20011"
"1.27271","104.40953","1.16549","24.65000","0.00000","1.27271","0.20011"
"1.27271","104.35823","1.16492","24.83000","0.00000","1.27271","0.20011"
"1.27271","104.29813","1.16424","25.01000","0.00000","1.27271","0.20011"
"1.27271","104.24061","1.16360","25.19000","0.00000","1.27271","0.20011"
"1.27271","104.17793","1.16290","25.37000","0.00000","1.27271","0.20011"
"1.27271","104.12119","1.16227","25.55000","0.00000","1.27271","0.20011"
"1.27271","104.06554","1.16165","25.73000","0.00000","1.27271","0.20011"
"1.27271","104.00628","1.16099","25.91000","0.00000","1.27271","0.20011"
"1.27271","103.94991","1.16036","26.09000","0.00000","1.27271","0.20011"
"1.27271","103.90164","1.15982","26.27000","0.00000","1.27271","0.20011"
"1.27271","103.84545","1.15919","26.45000","0.00000","1.27271","0.20011"
"1.27271","103.78777","1.15855","26.63000","0.00000","1.27271","0.20011"
"1.27271","103.73367","1.15794","26.81000","0.00000","1.27271","0.20011"
"1.27271","103.68764","1.15743","26.99000","0.00000","1.27271","0.20011"
"1.27271","103.63352","1.15683","27.17000","0.00000","1.27271","0.20011"
"1.27271","103.57783","1.15620","27.35000","0.00000","1.27271","0.20011"
"1.27271","103.52761","1.15564","27.53000","0.00000","1.27271","0.20011"
"1.27271","103.47007","1.15500","27.71000","0.00000","1.27271","0.20011"
"1.27271","103.41265","1.15436","27.89000","0.00000","1.27271","0.20011"
"1.27271","103.38145","1.15401","28.07000","0.00000","1.27271","0.20011"
"1.27271","103.32699","1.15340","28.25000","0.00000","1.27271","0.20011"
"1.27271","103.27044","1.15277","28.43000","0.00000","1.27271","0.20011"
"1.27271","103.23641","1.15239","28.61000","0.00000","1.27271","0.20011"
"1.27271","103.18285","1.15179","28.79000","0.00000","1.27271","0.20011"
"1.27271","103.13345","1.15124","28.97000","0.00000","1.27271","0.20011"
"1.27271","103.08062","1.15065","29.15000","0.00000","1.27271","0.20011"
"1.27271","103.02986","1.15009","29.33000","0.00000","1.27271","0.20011"
"1.27271","102.98655","1.14960","29.51000","0.00000","1.27271","0.20011"
"1.27271","102.93755","1.14906","29.69000","0.00000","1.27271","0.20011"
"1.27271","102.89238","1.14855","29.87000","0.00000","1.27271","0.20011"
"1.27271","102.84547","1.14803","30.05000","0.00000","1.27271","0.20011"
"1.27271","102.79724","1.14749","30.23000","0.00000","1.27271","0.20011"
"1.27271","102.75476","1.14702","30.41000","0.00000","1.27271","0.20011"
"1.27271","102.71449","1.14657","30.59000","0.00000","1.27271","0.20011"
"1.27271","102.66848","1.14605","30.77000","0.00000","1.27271","0.20011"
"1.27271","102.62569","1.14558","30.95000","0.00000","1.27271","0.20011"
"1.27271","102.57181","1.14497","31.13000","0.00000","1.27271","0.20011"
"1.27271","102.53550","1.14457","31.31000","0.00000","1.27271","0.20011"
"1.27271","102.48690","1.14403","31.49000","0.00000","1.27271","0.20011"
"1.27271","102.45071","1.14362","31.67000","0.00000","1.27271","0.20011"
"1.27271","102.40288","1.14309","31.85000","0.00000","1.27271","0.20011"
"1.27271","102.35786","1.14259","32.03000","0.00000","1.27271","0.20011"
"1.27271","102.31709","1.14213","32.21000","0.00000","1.27271","0.20011"
"1.27271","102.27576","1.14167","32.39000","0.00000","1.27271","0.20011"
"1.27271","102.22898","1.14115","32.57000","0.00000","1.27271","0.20011"
"1.27271","102.19056","1.14072","32.75000","0.00000","1.27271","0.20011"
"1.27271","102.15301","1.14030","32.93000","0.00000","1.27271","0.20011"
"1.27271","102.10834","1.13980","33.11000","0.00000","1.27271","0.20011"
"1.27271","102.06248","1.13929","33.29000","0.00000","1.27271","0.20011"
"1.27271","102.02859","1.13891","33.47000","0.00000","1.27271","0.20011"
"1.27271","101.98463","1.13842","33.65000","0.00000","1.27271","0.20011"
"1.27271","101.94433","1.13797","33.83000","0.00000","1.27271","0.20011"
"1.27271","101.90704","1.13755","34.01000","0.00000","1.27271","0.20011"
"1.27271","101.87336","1.13718","34.19000","0.00000","1.27271","0.20011"
"1.27271","101.83564","1.13676","34.37000","0.00000","1.27271","0.20011"
"1.27271","101.78805","1.13623","34.55000","0.00000","1.27271","0.20011"
"1.27271","101.74449","1.13574","34.73000","0.00000","1.27271","0.20011"
"1.27271","101.71079","1.13536","34.91000","0.00000","1.27271","0.20011"
"1.27271","101.67607","1.13498","35.09000","0.00000","1.27271","0.20011"
"1.27271","101.63982","1.13457","35.27000","0.00000","1.27271","0.20011"
"1.27271","101.59599","1.13408","35.45000","0.00000","1.27271","0.20011"
"1.27271","101.56354","1.13372","35.63000","0.00000","1.27271","0.20011"
"1.27271","101.52203","1.13326","35.81000","0.00000","1.27271","0.20011"
"1.27271","101.48152","1.13280","35.99000","0.00000","1.27271","0.20011"
"1.27271","101.45364","1.13249","36.17000","0.00000","1.27271","0.20011"
"1.27271","101.41325","1.13204","36.35000","0.00000","1.27271","0.20011"
"1.27271","101.37325","1.13160","36.53000","0.00000","1.27271","0.20011"
"1.27271","101.34315","1.13126","36.71000","0.00000","1.27271","0.20011"
"1.27271","101.30701","1.13086","36.89000","0.00000","1.27271","0.20011"
"1.27271","101.26982","1.13044","37.07000","0.00000","1.27271","0.20011"
"1.27271","101.24104","1.13012","37.25000","0.00000","1.27271","0.20011"
"1.27271","101.18663","1.12951","37.43000","0.00000","1.27271","0.20011"
"1.27271","101.13714","1.12896","37.61000","0.00000","1.27271","0.20011"
"1.27271","101.12041","1.12877","37.79000","0.00000","1.27271","0.20011"
"1.27271","101.09108","1.12845","37.97000","0.00000","1.27271","0.20011"
"1.27271","101.05324","1.12802","38.15000","0.00000","1.27271","0.20011"
"1.27271","101.03135","1.12778","38.33000","0.00000","1.27271","0.20011"
"1.27271","100.99197","1.12734","38.51000","0.00000","1.27271","0.20011"
"1.27271","100.95991","1.12698","38.69000","0.00000","1.27271","0.20011"
"1.27271","100.93249","1.12667","38.87000","0.00000","1.27271","0.20011"
"1.27271","100.89925","1.12630","39.05000","0.00000","1.27271","0.20011"
"1.27271","100.86179","1.12589","39.23000","0.00000","1.27271","0.20011"
"1.27271","100.82587","1.12548","39.41000","0.00000","1.27271","0.20011"
"1.27271","100.79313","1.12512","39.59000","0.00000","1.27271","0.20011"
"1.27271","100.75536","1.12470","39.77000","0.00000","1.27271","0.20011"
"1.27271","100.73174","1.12443","39.95000","0.00000","1.27271","0.20011"
"1.27271","100.69151","1.12398","40.13000","0.00000","1.27271","0.20011"
"1.27271","100.66183","1.12365","40.31000","0.00000","1.27271","0.20011"
"1.27271","100.62238","1.12321","40.49000","0.00000","1.27271","0.20011"
"1.27271","100.61057","1.12308","40.67000","0.00000","1.27271","0.20011"
"1.27271","100.56659","1.12259","40.85000","0.00000","1.27271","0.20011"
"1.27271","100.54526","1.12235","41.03000","0.00000","1.27271","0.20011"
"1.27271","100.50910","1.12195","41.21000","0.00000","1.27271","0.20011"
"1.27271","100.47508","1.12157","41.39000","0.00000","1.27271","0.20011"
"1.27271","100.44314","1.12121","41.57000","0.00000","1.27271","0.20011"
"1.27271","100.42020","1.12096","41.75000","0.00000","1.27271","0.20011"
"1.27271","100.38528","1.12057","41.93000","0.00000","1.27271","0.20011"
"1.27271","100.35286","1.12020","42.11000","0.00000","1.27271","0.20011"
"1.27271","100.32249","1.11987","42.29000","0.00000","1.27271","0.20011"
"1.27271","100.28668","1.11947","42.47000","0.00000","1.27271","0.20011"
"1.27271","100.26667","1.11924","42.65000","0.00000","1.27271","0.20011"
"1.27271","100.23541","1.11889","42.83000","0.00000","1.27271","0.20011"
"1.27271","100.21095","1.11862","43.01000","0.00000","1.27271","0.20011"
"1.27271","100.18459","1.11833","43.19000","0.00000","1.27271","0.20011"
"1.27271","100.15351","1.11798","43.37000","0.00000","1.27271","0.20011"
"1.27271","100.12530","1.11766","43.55000","0.00000","1.27271","0.20011"
"1.27271","100.09650","1.11734","43.73000","0.00000","1.27271","0.20011"
"1.27271","100.06969","1.11704","43.91000","0.00000","1.27271","0.20011"
"1.27271","100.03420","1.11665","44.09000","0.00000","1.27271","0.20011"
"1.27271","100.00906","1.11637","44.27000","0.00000","1.27271","0.20011"
"1.27271","99.98190","1.11606","44.45000","0.00000","1.27271","0.20011"
"1.27271","99.95183","1.11573","44.63000","0.00000","1.27271","0.20011"
"1.27271","99.92619","1.11544","44.81000","0.00000","1.27271","0.20011"
"1.27271","99.90611","1.11522","44.99000","0.00000","1.27271","0.20011"
"1.27271","99.86990","1.11481","45.17000","0.00000","1.27271","0.20011"
"1.27271","99.83428","1.11442","45.35000","0.00000","1.27271","0.20011"
"1.27271","99.81713","1.11422","45.53000","0.00000","1.27271","0.20011"
"1.27271","99.78076","1.11382","45.71000","0.00000","1.27271","0.20011"
"1.27271","99.76444","1.11364","45.89000","0.00000","1.27271","0.20011"
"1.27271","99.73281","1.11328","46.07000","0.00000","1.27271","0.20011"
"1.27271","99.70712","1.11300","46.25000","0.00000","1.27271","0.20011"
"1.27271","99.67412","1.11263","46.43000","0.00000","1.27271","0.20011"
"1.27271","99.64996","1.11236","46.61000","0.00000","1.27271","0.20011"
"1.27271","99.63039","1.11214","46.79000","0.00000","1.27271","0.20011"
"1.27271","99.60351","1.11184","46.97000","0.00000","1.27271","0.20011"
"1.27271","99.57533","1.11153","47.15000","0.00000","1.27271","0.20011"
"1.27271","99.55324","1.11128","47.33000","0.00000","1.27271","0.20011"
"1.27271","99.51980","1.11091","47.51000","0.00000","1.27271","0.20011"
"1.27271","99.50054","1.11069","47.69000","0.00000","1.27271","0.20011"
"1.27271","99.46742","1.11032","47.87000","0.00000","1.27271","0.20011"
"1.27271","99.44482","1.11007","48.05000","0.00000","1.27271","0.20011"
"1.27271","99.41579","1.10974","48.23000","0.00000","1.27271","0.20011"
"1.27271","99.38634","1.10942","48.41000","0.00000","1.27271","0.20011"
"1.27271","99.36920","1.10922","48.59000","0.00000","1.27271","0.20011"
"1.27271","99.33614","1.10886","48.77000","0.00000","1.27271","0.20011"
"1.27271","99.32246","1.10870","48.95000","0.00000","1.27271","0.20011"
"1.27271","99.29789","1.10843","49.13000","0.00000","1.27271","0.20011"
"1.27271","99.26633","1.10808","49.31000","0.00000","1.27271","0.20011"
"1.27271","99.24598","1.10785","49.49000","0.00000","1.27271","0.20011"
"1.27271","99.22375","1.10760","49.67000","0.00000","1.27271","0.20011"
"1.27271","99.19689","1.10730","49.85000","0.00000","1.27271","0.20011"
"1.27271","99.17583","1.10707","50.03000","0.00000","1.27271","0.20011"
"1.27271","99.14774","1.10675","50.21000","0.00000","1.27271","0.20011"
"1.27271","99.12285","1.10647","50.39000","0.00000","1.27271","0.20011"
"1.27271","99.10106","1.10623","50.57000","0.00000","1.27271","0.20011"
"1.27271","99.07876","1.10598","50.75000","0.00000","1.27271","0.20011"
"1.27271","99.05254","1.10569","50.93000","0.00000","1.27271","0.20011"
"1.27271","99.03100","1.10545","51.11000","0.00000","1.27271","0.20011"
"1.27271","99.00430","1.10515","51.29000","0.00000","1.27271","0.20011"
"1.27271","98.98697","1.10496","51.47000","0.00000","1.27271","0.20011"
"1.27271","98.96729","1.10474","51.65000","0.00000","1.27271","0.20011"
"1.27271","98.93080","1.10433","51.83000","0.00000","1.27271","0.20011"
"1.27271","98.90978","1.10410","52.01000","0.00000","1.27271","0.20011"
"1.27271","98.89150","1.10389","52.19000","0.00000","1.27271","0.20011"
"1.27271","98.86829","1.10363","52.37000","0.00000","1.27271","0.20011"
"1.27271","98.83554","1.10327","52.55000","0.00000","1.27271","0.20011"
"1.27271","98.81531","1.10304","52.73000","0.00000","1.27271","0.20011"
"1.27271","98.79808","1.10285","52.91000","0.00000","1.27271","0.20011"
"1.27271","98.77321","1.10257","53.09000","0.00000","1.27271","0.20011"
"1.27271","98.75641","1.10238","53.27000","0.00000","1.27271","0.20011"
"1.27271","98.73143","1.10211","53.45000","0.00000","1.27271","0.20011"
"1.27271","98.71147","1.10188","53.63000","0.00000","1.27271","0.20011"
"1.27271","98.67901","1.10152","53.81000","0.00000","1.27271","0.20011"
"1.27271","98.66759","1.10139","53.99000","0.00000","1.27271","0.20011"
"1.27271","98.64215","1.10111","54.17000","0.00000","1.27271","0.20011"
"1.27271","98.61836","1.10084","54.35000","0.00000","1.27271","0.20011"
"1.27271","98.59866","1.10062","54.53000","0.00000","1.27271","0.20011"
"1.27271","98.57452","1.10035","54.71000","0.00000","1.27271","0.20011"
"1.27271","98.55197","1.10010","54.89000","0.00000","1.27271","0.20011"
"1.27271","98.53456","1.09991","55.07000","0.00000","1.27271","0.20011"
"1.27271","98.50869","1.09962","55.25000","0.00000","1.27271","0.20011"
"1.27271","98.49172","1.09943","55.43000","0.00000","1.27271","0.20011"
"1.27271","98.46434","1.09912","55.61000","0.00000","1.27271","0.20011"
"1.27271","98.44479","1.09891","55.79000","0.00000","1.27271","0.20011"
"1.27271","98.42486","1.09868","55.97000","0.00000","1.27271","0.20011"
"1.27271","98.40423","1.09845","56.15000","0.00000","1.27271","0.20011"
"1.27271","98.38075","1.09819","56.33000","0.00000","1.27271","0.20011"
"1.27271","98.35808","1.09794","56.51000","0.00000","1.27271","0.20011"
"1.27271","98.33165","1.09764","56.69000","0.00000","1.27271","0.20011"
"1.27271","98.31414","1.09745","56.87000","0.00000","1.27271","0.20011"
"1.27271","98.29262","1.09721","57.05000","0.00000","1.27271","0.20011"
"1.27271","98.27478","1.09701","57.23000","0.00000","1.27271","0.20011"
"1.27271","98.24608","1.09669","57.41000","0.00000","1.27271","0.20011"
"1.27271","98.22623","1.09647","57.59000","0.00000","1.27271","0.20011"
"1.27271","98.20077","1.09618","57.77000","0.00000","1.27271","0.20011"
"1.27271","98.18967","1.09606","57.95000","0.00000","1.27271","0.20011"
"1.27271","98.16714","1.09581","58.13000","0.00000","1.27271","0.20011"
"1.27271","98.14880","1.09560","58.31000","0.00000","1.27271","0.20011"
"1.27271","98.12511","1.09534","58.49000","0.00000","1.27271","0.20011"
"1.27271","98.11204","1.09519","58.67000","0.00000","1.27271","0.20011"
"1.27271","98.08836","1.09493","58.85000","0.00000","1.27271","0.20011"
"1.27271","98.06916","1.09471","59.03000","0.00000","1.27271","0.20011"
"1.27271","98.04796","1.09448","59.21000","0.00000","1.27271","0.20011"
"1.27271","98.03016","1.09428","59.39000","0.00000","1.27271","0.20011"
"1.27271","98.01192","1.09407","59.57000","0.00000","1.27271","0.20011"
"1.27271","97.99525","1.09389","59.75000","0.00000","1.27271","0.20011"
"1.27271","97.97308","1.09364","59.93000","0.00000","1.27271","0.20011"
"1.27271","97.94862","1.09337","60.11000","0.00000","1.27271","0.20011"
"1.27271","97.93075","1.09317","60.29000","0.00000","1.27271","0.20011"
"1.27271","97.90599","1.09289","60.47000","0.00000","1.27271","0.20011"
"1.27271","97.89181","1.09273","60.65000","0.00000","1.27271","0.20011"
"1.27271","97.87234","1.09252","60.83000","0.00000","1.27271","0.20011"
"1.27271","97.85208","1.09229","61.01000","0.00000","1.27271","0.20011"
"1.27271","97.82691","1.09201","61.19000","0.00000","1.27271","0.20011"
"1.27271","97.80836","1.09180","61.37000","0.00000","1.27271","0.20011"
"1.27271","97.79334","1.09163","61.55000","0.00000","1.27271","0.20011"
"1.27271","97.78366","1.09153","61.73000","0.00000","1.27271","0.20011"
"1.27271","97.75179","1.09117","61.91000","0.00000","1.27271","0.20011"
"1.27271","97.72887","1.09091","62.09000","0.00000","1.27271","0.20011"
"1.27271","97.72247","1.09084","62.27000","0.00000","1.27271","0.20011"
"1.27271","97.70194","1.09061","62.45000","0.00000","1.27271","0.20011"
"1.27271","97.67603","1.09032","62.63000","0.00000","1.27271","0.20011"
"1.27271","97.67488","1.09031","62.81000","0.00000","1.27271","0.20011"
"1.27271","97.64175","1.08994","62.99000","0.00000","1.27271","0.20011"
"1.27271","97.62795","1.08979","63.17000","0.00000","1.27271","0.20011"
"1.27271","97.61566","1.08965","63.35000","0.00000","1.27271","0.20011"
"1.27271","97.59069","1.08937","63.53000","0.00000","1.27271","0.20011"
"1.27271","97.56922","1.08913","63.71000","0.00000","1.27271","0.20011"
"1.27271","97.56065","1.08904","63.89000","0.00000","1.27271","0.20011"
"1.27271","97.53932","1.08880","64.07000","0.00000","1.27271","0.20011"
"1.27271","97.52306","1.08862","64.25000","0.00000","1.27271","0.20011"
"1.27271","97.49676","1.08832","64.43000","0.00000","1.27271","0.20011"
"1.27271","97.48721","1.08822","64.61000","0.00000","1.27271","0.20011"
"1.27271","97.46343","1.08795","64.79000","0.00000","1.27271","0.20011"
"1.27271","97.44856","1.08779","64.97000","0.00000","1.27271","0.20011"
"1.27271","97.43266","1.08761","65.15000","0.00000","1.27271","0.20011"
"1.27271","97.41518","1.08741","65.33000","0.00000","1.27271","0.20011"
"1.27271","97.39312","1.08717","65.51000","0.00000","1.27271","0.20011"
"1.27271","97.37956","1.08701","65.69000","0.00000","1.27271","0.20011"
"1.27271","97.36238","1.08682","65.87000","0.00000","1.27271","0.20011"
"1.27271","97.34431","1.08662","66.05000","0.00000","1.27271","0.20011"
"1.27271","97.32133","1.08636","66.23000","0.00000","1.27271","0.20011"
"1.27271","97.30730","1.08621","66.41000","0.00000","1.27271","0.20011"
"1.27271","97.28834","1.08600","66.59000","0.00000","1.27271","0.20011"
"1.27271","97.26538","1.08574","66.77000","0.00000","1.27271","0.20011"
"1.27271","97.25887","1.08567","66.95000","0.00000","1.27271","0.20011"
"1.27271","97.23563","1.08541","67.13000","0.00000","1.27271","0.20011"
"1.27271","97.22001","1.08523","67.31000","0.00000","1.27271","0.20011"
"1.27271","97.19777","1.08499","67.49000","0.00000","1.27271","0.20011"
"1.27271","97.18795","1.08488","67.67000","0.00000","1.27271","0.20011"
"1.27271","97.16849","1.08466","67.85000","0.00000","1.27271","0.20011"
"1.27271","97.15244","1.08448","68.03000","0.00000","1.27271","0.20011"
"1.27271","97.14371","1.08438","68.21000","0.00000","1.27271","0.20011"
"1.27271","97.12212","1.08414","68.39000","0.00000","1.27271","0.20011"
"1.27271","97.10266","1.08392","68.57000","0.00000","1.27271","0.20011"
"1.27271","97.08909","1.08377","68.75000","0.00000","1.27271","0.20011"
"1.27271","97.06882","1.08355","68.93000","0.00000","1.27271","0.20011"
"1.27271","97.05798","1.08343","69.11000","0.00000","1.27271","0.20011"
"1.27271","97.03571","1.08318","69.29000","0.00000","1.27271","0.20011"
"1.27271","97.01952","1.08300","69.47000","0.00000","1.27271","0.20011"
"1.27271","97.00234","1.08280","69.65000","0.00000","1.27271","0.20011"
"1.27271","96.99504","1.08272","69.83000","0.00000","1.27271","0.20011"
"1.27271","96.97051","1.08245","70.01000","0.00000","1.27271","0.20011"
"1.27271","96.95434","1.08227","70.19000","0.00000","1.27271","0.20011"
"1.27271","96.94830","1.08220","70.37000","0.00000","1.27271","0.20011"
"1.27271","96.92615","1.08195","70.55000","0.00000","1.27271","0.20011"
"1.27271","96.90138","1.08168","70.73000","0.00000","1.27271","0.20011"
"1.27271","96.89281","1.08158","70.91000","0.00000","1.27271","0.20011"
"1.27271","96.87739","1.08141","71.09000","0.00000","1.27271","0.20011"
"1.27271","96.86385","1.08126","71.27000","0.00000","1.27271","0.20011"
"1.27271","96.84828","1.08108","71.45000","0.00000","1.27271","0.20011"
"1.27271","96.83414","1.08093","71.63000","0.00000","1.27271","0.20011"
"1.27271","96.81841","1.08075","71.81000","0.00000","1.27271","0.20011"
"1.27271","96.79420","1.08048","71.99000","0.00000","1.27271","0.20011"
"1.27271","96.77740","1.08029","72.17000","0.00000","1.27271","0.20011"
"1.27271","96.76214","1.08012","72.35000","0.00000","1.27271","0.20011"
"1.27271","96.74820","1.07997","72.53000","0.00000","1.27271","0.20011"
"1.27271","96.73074","1.07977","72.71000","0.00000","1.27271","0.20011"
"1.27271","96.71771","1.07963","72.89000","0.00000","1.27271","0.20011"
"1.27271","96.70564","1.07949","73.07000","0.00000","1.27271","0.20011"
"1.27271","96.68316","1.07924","73.25000","0.00000","1.27271","0.20011"
"1.27271","96.66924","1.07909","73.43000","0.00000","1.27271","0.20011"
"1.27271","96.65146","1.07889","73.61000","0.00000","1.27271","0.20011"
"1.27271","96.64378","1.07880","73.79000","0.00000","1.27271","0.20011"
"1.27271","96.63046","1.07865","73.97000","0.00000","1.27271","0.20011"
"1.27271","96.60494","1.07837","74.15000","0.00000","1.27271","0.20011"
"1.27271","96.59425","1.07825","74.33000","0.00000","1.27271","0.20011"
"1.27271","96.58126","1.07810","74.51000","0.00000","1.27271","0.20011"
"1.27271","96.56280","1.07790","74.69000","0.00000","1.27271","0.20011"
"1.27271","96.54696","1.07772","74.87000","0.00000","1.27271","0.20011"
"1.27271","96.53493","1.07759","75.05000","0.00000","1.27271","0.20011"
"1.27271","96.52057","1.07743","75.23000","0.00000","1.27271","0.20011"
"1.27271","96.50420","1.07724","75.41000","0.00000","1.27271","0.20011"
"1.27271","96.50294","1.07723","75.59000","0.00000","1.27271","0.20011"
"1.27271","96.47473","1.07691","75.77000","0.00000","1.27271","0.20011"
"1.27271","96.45784","1.07673","75.95000","0.00000","1.27271","0.20011"
"1.27271","96.44140","1.07654","76.13000","0.00000","1.27271","0.20011"
"1.27271","96.43198","1.07644","76.31000","0.00000","1.27271","0.20011"
"1.27271","96.41485","1.07625","76.49000","0.00000","1.27271","0.20011"
"1.27271","96.39920","1.07607","76.67000","0.00000","1.27271","0.20011"
"1.27271","96.39214","1.07599","76.85000","0.00000","1.27271","0.20011"
"1.27271","96.37398","1.07579","77.03000","0.00000","1.27271","0.20011"
"1.27271","96.35960","1.07563","77.21000","0.00000","1.27271","0.20011"
"1.27271","96.34555","1.07547","77.39000","0.00000","1.27271","0.20011"
"1.27271","96.32991","1.07530","77.57000","0.00000","1.27271","0.20011"
"1.27271","96.31528","1.07513","77.75000","0.00000","1.27271","0.20011"
"1.27271","96.30439","1.07501","77.93000","0.00000","1.27271","0.20011"
"1.27271","96.28827","1.07483","78.11000","0.00000","1.27271","0.20011"
"1.27271","96.28431","1.07479","78.29000","0.00000","1.27271","0.20011"
"1.27271","96.25805","1.07450","78.47000","0.00000","1.27271","0.20011"
"1.27271","96.24478","1.07435","78.65000","0.00000","1.27271","0.20011"
"1.27271","96.22953","1.07418","78.83000","0.00000","1.27271","0.20011"
"1.27271","96.21865","1.07406","79.01000","0.00000","1.27271","0.20011"
"1.27271","96.20074","1.07386","79.19000","0.00000","1.27271","0.20011"
"1.27271","96.18759","1.07371","79.37000","0.00000","1.27271","0.20011"
"1.27271","96.17632","1.07358","79.55000","0.00000","1.27271","0.20011"
"1.27271","96.16513","1.07346","79.73000","0.00000","1.27271","0.20011"
"1.27271","96.15329","1.07333","79.91000","0.00000","1.27271","0.20011"
"1.27271","96.13808","1.07316","80.09000","0.00000","1.27271","0.20011"
"1.27271","96.12165","1.07297","80.27000","0.00000","1.27271","0.20011"
"1.27271","96.10531","1.07279","80.45000","0.00000","1.27271","0.20011"
"1.27271","96.09705","1.07270","80.63000","0.00000","1.27271","0.20011"
"1.27271","96.08109","1.07252","80.81000","0.00000","1.27271","0.20011"
"1.27271","96.06247","1.07231","80.99000","0.00000","1.27271","0.20011"
"1.27271","96.05152","1.07219","81.17000","0.00000","1.27271","0.20011"
"1.27271","96.02487","1.07189","81.35000","0.00000","1.27271","0.20011"
"1.27271","96.02230","1.07186","81.53000","0.00000","1.27271","0.20011"
"1.27271","96.01064","1.07173","81.71000","0.00000","1.27271","0.20011"
"1.27271","95.99715","1.07158","81.89000","0.00000","1.27271","0.20011"
"1.27271","95.97647","1.07135","82.07000","0.00000","1.27271","0.20011"
"1.27271","95.97086","1.07129","82.25000","0.00000","1.27271","0.20011"
"1.27271","95.95607","1.07112","82.43000","0.00000","1.27271","0.20011"
"1.27271","95.94514","1.07100","82.61000","0.00000","1.27271","0.20011"
"1.27271","95.93454","1.07088","82.79000","0.00000","1.27271","0.20011"
"1.27271","95.91469","1.07066","82.97000","0.00000","1.27271","0.20011"
"1.27271","95.91237","1.07064","83.15000","0.00000","1.27271","0.20011"
"1.27271","95.89151","1.07040","83.33000","0.00000","1.27271","0.20011"
"1.27271","95.87355","1.07020","83.51000","0.00000","1.27271","0.20011"
"1.27271","95.85950","1.07005","83.69000","0.00000","1.27271","0.20011"
"1.27271","95.85143","1.06996","83.87000","0.00000","1.27271","0.20011"
"1.27271","95.84193","1.06985","84.05000","0.00000","1.27271","0.20011"
"1.27271","95.82701","1.06968","84.23000","0.00000","1.27271","0.20011"
"1.27271","95.81846","1.06959","84.41000","0.00000","1.27271","0.20011"
"1.27271","95.79996","1.06938","84.59000","0.00000","1.27271","0.20011"
"1.27271","95.79114","1.06928","84.77000","0.00000","1.27271","0.20011"
"1.27271","95.78038","1.06916","84.95000","0.00000","1.27271","0.20011"
"1.27271","95.76511","1.06899","85.13000","0.00000","1.27271","0.20011"
"1.27271","95.74838","1.06881","85.31000","0.00000","1.27271","0.20011"
"1.27271","95.73173","1.06862","85.49000","0.00000","1.27271","0.20011"
"1.27271","95.72266","1.06852","85.67000","0.00000","1.27271","0.20011"
"1.27271","95.71845","1.06847","85.85000","0.00000","1.27271","0.20011"
"1.27271","95.70088","1.06828","86.03000","0.00000","1.27271","0.20011"
"1.27271","95.68794","1.06813","86.21000","0.00000","1.27271","0.20011"
"1.27271","95.67677","1.06801","86.39000","0.00000","1.27271","0.20011"
"1.27271","95.66040","1.06782","86.57000","0.00000","1.27271","0.20011"
"1.27271","95.65398","1.06775","86.75000","0.00000","1.27271","0.20011"
"1.27271","95.63470","1.06754","86.93000","0.00000","1.27271","0.20011"
"1.27271","95.63361","1.06753","87.11000","0.00000","1.27271","0.20011"
"1.27271","95.61248","1.06729","87.29000","0.00000","1.27271","0.20011"
"1.27271","95.59969","1.06715","87.47000","0.00000","1.27271","0.20011"
"1.27271","95.58296","1.06696","87.65000","0.00000","1.27271","0.20011"
"1.27271","95.56367","1.06674","87.83000","0.00000","1.27271","0.20011"
"1.27271","95.55283","1.06662","88.01000","0.00000","1.27271","0.20011"
"1.27271","95.54897","1.06658","88.19000","0.00000","1.27271","0.20011"
"1.27271","95.52753","1.06634","88.37000","0.00000","1.27271","0.20011"
"1.27271","95.52007","1.06626","88.55000","0.00000","1.27271","0.20011"
"1.27271","95.50690","1.06611","88.73000","0.00000","1.27271","0.20011"
"1.27271","95.49274","1.06595","88.91000","0.00000","1.27271","0.20011"
"1.27271","95.48077","1.06582","89.09000","0.00000","1.27271","0.20011"
"1.27271","95.46711","1.06567","89.27000","0.00000","1.27271","0.20011"
"1.27271","95.45367","1.06552","89.45000","0.00000","1.27271","0.20011"
"1.27271","95.44410","1.06541","89.63000","0.00000","1.27271","0.20011"
"1.27271","95.42546","1.06520","89.81000","0.00000","1.27271","0.20011"
"1.27271","95.42374","1.06518","89.99000","0.00000","1.27271","0.20011"
"1.27271","95.40898","1.06502","90.17000","0.00000","1.27271","0.20011"
"1.27271","95.39469","1.06486","90.35000","0.00000","1.27271","0.20011"
"1.27271","95.38648","1.06477","90.53000","0.00000","1.27271","0.20011"
"1.27271","95.36881","1.06457","90.71000","0.00000","1.27271","0.20011"
"1.27271","95.35934","1.06446","90.89000","0.00000","1.27271","0.20011"
"1.27271","95.34812","1.06434","91.07000","0.00000","1.27271","0.20011"
"1.27271","95.33042","1.06414","91.25000","0.00000","1.27271","0.20011"
"1.27271","95.32227","1.06405","91.43000","0.00000","1.27271","0.20011"
"1.27271","95.30280","1.06383","91.61000","0.00000","1.27271","0.20011"
"1.27271","95.29885","1.06379","91.79000","0.00000","1.27271","0.20011"
"1.27271","95.27758","1.06355","91.97000","0.00000","1.27271","0.20011"
"1.27271","95.27175","1.06349","92.15000","0.00000","1.27271","0.20011"
"1.27271","95.26564","1.06342","92.33000","0.00000","1.27271","0.20011"
"1.27271","95.25311","1.06328","92.51000","0.00000","1.27271","0.20011"
"1.27271","95.23320","1.06306","92.69000","0.00000","1.27271","0.20011"
"1.27271","95.22351","1.06295","92.87000","0.00000","1.27271","0.20011"
"1.27271","95.21256","1.06283","93.05000","0.00000","1.27271","0.20011"
"1.27271","95.19815","1.06266","93.23000","0.00000","1.27271","0.20011"
"1.27271","95.19779","1.06266","93.41000","0.00000","1.27271","0.20011"
"1.27271","95.18300","1.06250","93.59000","0.00000","1.27271","0.20011"
"1.27271","95.15852","1.06222","93.77000","0.00000","1.27271","0.20011"
"1.27271","95.15618","1.06220","93.95000","0.00000","1.27271","0.20011"
"1.27271","95.13815","1.06199","94.13000","0.00000","1.27271","0.20011"
"1.27271","95.12733","1.06187","94.31000","0.00000","1.27271","0.20011"
"1.27271","95.12076","1.06180","94.49000","0.00000","1.27271","0.20011"
"1.27271","95.10547","1.06163","94.67000","0.00000","1.27271","0.20011"
"1.27271","95.09484","1.06151","94.85000","0.00000","1.27271","0.20011"
"1.27271","95.08636","1.06142","95.03000","0.00000","1.27271","0.20011"
"1.27271","95.07619","1.06130","95.21000","0.00000","1.27271","0.20011"
"1.27271","95.07034","1.06124","95.39000","0.00000","1.27271","0.20011"
"1.27271","95.05102","1.06102","95.57000","0.00000","1.27271","0.20011"
"1.27271","95.04351","1.06094","95.75000","0.00000","1.27271","0.20011"
"1.27271","95.03221","1.06081","95.93000","0.00000","1.27271","0.20011"
"1.27271","95.01498","1.06062","96.11000","0.00000","1.27271","0.20011"
"1.27271","95.00918","1.06055","96.29000","0.00000","1.27271","0.20011"
"1.27271","94.99230","1.06037","96.47000","0.00000","1.27271","0.20011"
"1.27271","94.98658","1.06030","96.65000","0.00000","1.27271","0.20011"
"1.27271","94.97240","1.06014","96.83000","0.00000","1.27271","0.20011"
"1.27271","94.96575","1.06007","97.01000","0.00000","1.27271","0.20011"
"1.27271","94.94637","1.05985","97.19000","0.00000","1.27271","0.20011"
"1.27271","94.93911","1.05977","97.37000","0.00000","1.27271","0.20011"
"1.27271","94.92633","1.05963","97.55000","0.00000","1.27271","0.20011"
"1.27271","94.91505","1.05950","97.73000","0.00000","1.27271","0.20011"
"1.27271","94.90636","1.05941","97.91000","0.00000","1.27271","0.20011"
"1.27271","94.89577","1.05929","98.09000","0.00000","1.27271","0.20011"
"1.27271","94.88481","1.05917","98.27000","0.00000","1.27271","0.20011"
"1.27271","94.87435","1.05905","98.45000","0.00000","1.27271","0.20011"
"1.27271","94.85793","1.05887","98.63000","0.00000","1.27271","0.20011"
"1.27271","94.85734","1.05886","98.81000","0.00000","1.27271","0.20011"
"1.27271","94.84541","1.05873","98.99000","0.00000","1.27271","0.20011"
"1.27271","94.83367","1.05860","99.17000","0.00000","1.27271","0.20011"
"1.27271","94.81689","1.05841","99.35000","0.00000","1.27271","0.20011"
"1.27271","94.80364","1.05826","99.53000","0.00000","1.27271","0.20011"
"1.27271","94.79930","1.05821","99.71000","0.00000","1.27271","0.20011"
"1.27271","94.78862","1.05809","99.89000","0.00000","1.27271","0.20011"
"1.27271","94.78037","1.05800","100.07000","0.00000","1.27271","0.20011"
"1.27271","94.77149","1.05790","100.25000","0.00000","1.27271","0.20011"
"1.27271","94.74835","1.05764","100.43000","0.00000","1.27271","0.20011"
"1.27271","94.74451","1.05760","100.61000","0.00000","1.27271","0.20011"
"1.27271","94.73656","1.05751","100.79000","0.00000","1.27271","0.20011"
"1.27271","94.71973","1.05732","100.97000","0.00000","1.27271","0.20011"
"1.27271","94.71085","1.05722","101.15000","0.00000","1.27271","0.20011"
"1.27271","94.69867","1.05709","101.33000","0.00000","1.27271","0.20011"
"1.27271","94.69349","1.05703","101.51000","0.00000","1.27271","0.20011"
"1.27271","94.68301","1.05691","101.69000","0.00000","1.27271","0.20011"
"1.27271","94.66908","1.05676","101.87000","0.00000","1.27271","0.20011"
"1.27271","94.65559","1.05661","102.05000","0.00000","1.27271","0.20011"
"1.27271","94.65202","1.05657","102.23000","0.00000","1.27271","0.20011"
"1.27271","94.63941","1.05643","102.41000","0.00000","1.27271","0.20011"
"1.27271","94.62841","1.05630","102.59000","0.00000","1.27271","0.20011"
"1.27271","94.61411","1.05614","102.77000","0.00000","1.27271","0.20011"
"1.27271","94.61105","1.05611","102.95000","0.00000","1.27271","0.20011"
"1.27271","94.59676","1.05595","103.13000","0.00000","1.27271","0.20011"
"1.27271","94.58492","1.05582","103.31000","0.00000","1.27271","0.20011"
"1.27271","94.57930","1.05576","103.49000","0.00000","1.27271","0.20011"
"1.27271","94.56039","1.05555","103.67000","0.00000","1.27271","0.20011"
"1.27271","94.55959","1.05554","103.85000","0.00000","1.27271","0.20011"
"1.27271","94.55145","1.05545","104.03000","0.00000","1.27271","0.20011"
"1.27271","94.53817","1.05530","104.21000","0.00000","1.27271","0.20011"
"1.27271","94.52374","1.05514","104.39000","0.00000","1.27271","0.20011"
"1.27271","94.50683","1.05495","104.57000","0.00000","1.27271","0.20011"
"1.27271","94.49946","1.05487","104.75000","0.00000","1.27271","0.20011"
"1.27271","94.50111","1.05488","104.93000","0.00000","1.27271","0.20011"
"1.27271","94.47750","1.05462","105.11000","0.00000","1.27271","0.20011"
"1.27271","94.47032","1.05454","105.29000","0.00000","1.27271","0.20011"
"1.27271","94.46375","1.05447","105.47000","0.00000","1.27271","0.20011"
"1.27271","94.45189","1.05433","105.65000","0.00000","1.27271","0.20011"
"1.27271","94.44079","1.05421","105.83000","0.00000","1.27271","0.20011"
"1.27271","94.42909","1.05408","106.01000","0.00000","1.27271","0.20011"
"1.27271","94.42842","1.05407","106.19000","0.00000","1.27271","0.20011"
"1.27271","94.41030","1.05387","106.37000","0.00000","1.27271","0.20011"
"1.27271","94.40910","1.05386","106.55000","0.00000","1.27271","0.20011"
"1.27271","94.39574","1.05371","106.73000","0.00000","1.27271","0.20011"
"1.27271","94.38216","1.05356","106.91000","0.00000","1.27271","0.20011"
"1.27271","94.38116","1.05354","107.09000","0.00000","1.27271","0.20011"
"1.27271","94.36245","1.05334","107.27000","0.00000","1.27271","0.20011"
"1.27271","94.35423","1.05324","107.45000","0.00000","1.27271","0.20011"
"1.27271","94.34624","1.05315","107.63000","0.00000","1.27271","0.20011"
"1.27271","94.33933","1.05308","107.81000","0.00000","1.27271","0.20011"
"1.27271","94.32164","1.05288","107.99000","0.00000","1.27271","0.20011"
"1.27271","94.31841","1.05284","108.17000","0.00000","1.27271","0.20011"
"1.27271","94.30710","1.05272","108.35000","0.00000","1.27271","0.20011"
"1.27271","94.29453","1.05258","108.53000","0.00000","1.27271","0.20011"
"1.27271","94.28294","1.05245","108.71000","0.00000","1.27271","0.20011"
"1.27271","94.27838","1.05240","108.89000","0.00000","1.27271","0.20011"
"1.27271","94.28368","1.05246","109.07000","0.00000","1.27271","0.20011"
"1.27271","94.25629","1.05215","109.25000","0.00000","1.27271","0.20011"
"1.27271","94.24860","1.05206","109.43000","0.00000","1.27271","0.20011"
"1.27271","94.23715","1.05194","109.61000","0.00000","1.27271","0.20011"
"1.27271","94.22535","1.05181","109.79000","0.00000","1.27271","0.20011"
"1.27271","94.21945","1.05174","109.97000","0.00000","1.27271","0.20011"
"1.27271","94.21243","1.05166","110.15000","0.00000","1.27271","0.20011"
"1.27271","94.18992","1.05141","110.33000","0.00000","1.27271","0.20011"
"1.27271","94.18279","1.05133","110.51000","0.00000","1.27271","0.20011"
"1.27271","94.18089","1.05131","110.69000","0.00000","1.27271","0.20011"
"1.27271","94.16798","1.05116","110.87000","0.00000","1.27271","0.20011"
"1.27271","94.16401","1.05112","111.05000","0.00000","1.27271","0.20011"
"1.27271","94.14925","1.05096","111.23000","0.00000","1.27271","0.20011"
"1.27271","94.13941","1.05085","111.41000","0.00000","1.27271","0.20011"
"1.27271","94.13736","1.05082","111.59000","0.00000","1.27271","0.20011"
"1.27271","94.11598","1.05058","111.77000","0.00000","1.27271","0.20011"
"1.27271","94.12190","1.05065","111.95000","0.00000","1.27271","0.20011"
"1.27271","94.10899","1.05051","112.13000","0.00000","1.27271","0.20011"
"1.27271","94.10323","1.05044","112.31000","0.00000","1.27271","0.20011"
"1.27271","94.08330","1.05022","112.49000","0.00000","1.27271","0.20011"
"1.27271","94.07829","1.05016","112.67000","0.00000","1.27271","0.20011"
"1.27271","94.07915","1.05017","112.85000","0.00000","1.27271","0.20011"
"1.27271","94.06253","1.04999","113.03000","0.00000","1.27271","0.20011"
"1.27271","94.04981","1.04985","113.21000","0.00000","1.27271","0.20011"
"1.27271","94.04619","1.04981","113.39000","0.00000","1.27271","0.20011"
"1.27271","94.02721","1.04959","113.57000","0.00000","1.27271","0.20011"
"1.27271","94.02544","1.04957","113.75000","0.00000","1.27271","0.20011"
"1.27271","94.01105","1.04941","113.93000","0.00000","1.27271","0.20011"
"1.27271","94.00693","1.04937","114.11000","0.00000","1.27271","0.20011"
"1.27271","93.99511","1.04924","114.29000","0.00000","1.27271","0.20011"
"1.27271","93.98713","1.04915","114.47000","0.00000","1.27271","0.20011"
"1.27271","93.96947","1.04895","114.65000","0.00000","1.27271","0.20011"
"1.27271","94.00996","1.04940","114.83000","0.00000","1.27271","0.20011"
"1.27271","93.98953","1.04917","115.01000","0.00000","1.27271","0.20011"
"1.27271","93.95926","1.04884","115.19000","0.00000","1.27271","0.20011"
"1.27271","93.93060","1.04852","115.37000","0.00000","1.27271","0.20011"
"1.27271","93.91996","1.04840","115.55000","0.00000","1.27271","0.20011"
"1.27271","93.91451","1.04834","115.73000","0.00000","1.27271","0.20011"
"1.27271","93.91501","1.04834","115.91000","0.00000","1.27271","0.20011"
"1.27271","93.90564","1.04824","116.09000","0.00000","1.27271","0.20011"
"1.27271","93.89674","1.04814","116.27000","0.00000","1.27271","0.20011"
"1.27271","93.89045","1.04807","116.45000","0.00000","1.27271","0.20011"
"1.27271","93.87684","1.04792","116.63000","0.00000","1.27271","0.20011"
"1.27271","93.87214","1.04786","116.81000","0.00000","1.27271","0.20011"
"1.27271","93.86301","1.04776","116.99000","0.00000","1.27271","0.20011"
"1.27271","93.84915","1.04761","117.17000","0.00000","1.27271","0.20011"
"1.27271","93.84582","1.04757","117.35000","0.00000","1.27271","0.20011"
"1.27271","93.82948","1.04739","117.53000","0.00000","1.27271","0.20011"
"1.27271","93.90910","1.04828","117.71000","0.00000","1.27271","0.20011"
"1.27271","93.84854","1.04760","117.89000","0.00000","1.27271","0.20011"
"1.27271","93.78664","1.04691","118.07000","0.00000","1.27271","0.20011"
"1.27271","93.77378","1.04676","118.25000","0.00000","1.27271","0.20011"
"1.27271","93.76823","1.04670","118.43000","0.00000","1.27271","0.20011"
"1.27271","93.76254","1.04664","118.61000","0.00000","1.27271","0.20011"
"1.27271","93.77778","1.04681","118.79000","0.00000","1.27271","0.20011"
"1.27271","93.76991","1.04672","118.97000","0.00000","1.27271","0.20011"
"1.27271","93.75474","1.04655","119.15000","0.00000","1.27271","0.20011"
"1.27271","93.75761","1.04658","119.33000","0.00000","1.27271","0.20011"
"1.27271","93.74684","1.04646","119.51000","0.00000","1.27271","0.20011"
"1.27271","93.73692","1.04635","119.69000","0.00000","1.27271","0.20011"
"1.27271","93.73079","1.04628","119.87000","0.00000","1.27271","0.20011"
"1.27271","93.71920","1.04616","120.05000","0.00000","1.27271","0.20011"
"1.27271","93.70745","1.04602","120.23000","0.00000","1.27271","0.20011"
"1.27271","93.69547","1.04589","120.41000","0.00000","1.27271","0.20011"
"1.27271","93.69358","1.04587","120.59000","0.00000","1.27271","0.20011"
"1.27271","93.68532","1.04578","120.77000","0.00000","1.27271","0.20011"
"1.27271","93.67648","1.04568","120.95000","0.00000","1.27271","0.20011"
"1.27271","93.66933","1.04560","121.13000","0.00000","1.27271","0.20011"
"1.27271","93.65695","1.04546","121.31000","0.00000","1.27271","0.20011"
"1.27271","93.65710","1.04546","121.49000","0.00000","1.27271","0.20011"
"1.27271","93.64925","1.04537","121.67000","0.00000","1.27271","0.20011"
"1.27271","93.62858","1.04514","121.85000","0.00000","1.27271","0.20011"
"1.27271","93.62406","1.04509","122.03000","0.00000","1.27271","0.20011"
"1.27271","93.61884","1.04504","122.21000","0.00000","1.27271","0.20011"
"1.27271","93.61289","1.04497","122.39000","0.00000","1.27271","0.20011"
"1.27271","93.60268","1.04485","122.57000","0.00000","1.27271","0.20011"
"1.27271","93.59598","1.04478","122.75000","0.00000","1.27271","0.20011"
"1.27271","93.57384","1.04453","122.93000","0.00000","1.27271","0.20011"
"1.27271","93.57333","1.04453","123.11000","0.00000","1.27271","0.20011"
"1.27271","93.57156","1.04451","123.18000","0.00000","1.27271","0.20011"