File: Rubber Stress Relaxation Raw Data -Large  Samples-20210211/Specimen_RawData_1.csv
Specimen properties : Specimen label,"2"
Specimen properties : Anvil height,"6.30000",mm
Specimen properties : Diameter,"10.30000",mm
Test : Rate 1,"0.24000",mm/min
Test : Start of hold value,"20.00000",%
Test : Duration,"120.00000",s

Extension,Load,Compressive stress,Time,PIP count,Compressive extension,Compressive strain (Extension)
(mm),(N),(MPa),(s),,(mm),(mm/mm)
"-0.00021","0.00851","0.00010","0.00000","0.00000","-0.00021","-0.00003"
"0.00063","0.04020","0.00048","0.64000","0.00000","0.00063","0.00010"
"0.00354","0.39702","0.00476","1.28000","0.00000","0.00354","0.00056"
"0.00708","0.78101","0.00937","1.92000","0.00000","0.00708","0.00112"
"0.01000","1.05658","0.01268","2.56000","0.00000","0.01000","0.00159"
"0.01250","1.30997","0.01572","3.20000","0.00000","0.01250","0.00198"
"0.01521","1.58286","0.01900","3.84000","0.00000","0.01521","0.00241"
"0.01771","1.83335","0.02200","4.48000","0.00000","0.01771","0.00281"
"0.02021","2.09573","0.02515","5.12000","0.00000","0.02021","0.00321"
"0.02292","2.35752","0.02829","5.76000","0.00000","0.02292","0.00364"
"0.02542","2.61694","0.03141","6.40000","0.00000","0.02542","0.00403"
"0.02792","2.88186","0.03459","7.04000","0.00000","0.02792","0.00443"
"0.03063","3.14384","0.03773","7.68000","0.00000","0.03063","0.00486"
"0.03333","3.42064","0.04105","8.32000","0.00000","0.03333","0.00529"
"0.03583","3.68858","0.04427","8.96000","0.00000","0.03583","0.00569"
"0.03854","3.97441","0.04770","9.60000","0.00000","0.03854","0.00612"
"0.04104","4.21157","0.05055","10.24000","0.00000","0.04104","0.00651"
"0.04354","4.44575","0.05336","10.88000","0.00000","0.04354","0.00691"
"0.04604","4.74576","0.05696","11.52000","0.00000","0.04604","0.00731"
"0.04854","5.01904","0.06024","12.16000","0.00000","0.04854","0.00771"
"0.05104","5.29123","0.06350","12.80000","0.00000","0.05104","0.00810"
"0.05354","5.55319","0.06665","13.44000","0.00000","0.05354","0.00850"
"0.05625","5.83137","0.06999","14.08000","0.00000","0.05625","0.00893"
"0.05875","6.11821","0.07343","14.72000","0.00000","0.05875","0.00933"
"0.06125","6.37694","0.07653","15.36000","0.00000","0.06125","0.00972"
"0.06375","6.62838","0.07955","16.00000","0.00000","0.06375","0.01012"
"0.06646","6.91668","0.08301","16.64000","0.00000","0.06646","0.01055"
"0.06896","7.17954","0.08617","17.28000","0.00000","0.06896","0.01095"
"0.07146","7.45049","0.08942","17.92000","0.00000","0.07146","0.01134"
"0.07417","7.72782","0.09275","18.56000","0.00000","0.07417","0.01177"
"0.07688","8.00130","0.09603","19.20000","0.00000","0.07688","0.01220"
"0.07937","8.27981","0.09937","19.84000","0.00000","0.07937","0.01260"
"0.08208","8.53132","0.10239","20.48000","0.00000","0.08208","0.01303"
"0.08458","8.77857","0.10536","21.12000","0.00000","0.08458","0.01343"
"0.08708","9.05568","0.10868","21.76000","0.00000","0.08708","0.01382"
"0.08958","9.28320","0.11141","22.40000","0.00000","0.08958","0.01422"
"0.09188","9.51498","0.11419","23.04000","0.00000","0.09188","0.01458"
"0.09458","9.80041","0.11762","23.68000","0.00000","0.09458","0.01501"
"0.09708","10.06469","0.12079","24.32000","0.00000","0.09708","0.01541"
"0.09979","10.33155","0.12399","24.96000","0.00000","0.09979","0.01584"
"0.10229","10.57965","0.12697","25.60000","0.00000","0.10229","0.01624"
"0.10479","10.84160","0.13012","26.24000","0.00000","0.10479","0.01663"
"0.10729","11.11320","0.13338","26.88000","0.00000","0.10729","0.01703"
"0.11000","11.37157","0.13648","27.52000","0.00000","0.11000","0.01746"
"0.11271","11.64895","0.13980","28.16000","0.00000","0.11271","0.01789"
"0.11500","11.86629","0.14241","28.80000","0.00000","0.11500","0.01825"
"0.11771","12.13862","0.14568","29.44000","0.00000","0.11771","0.01868"
"0.12042","12.38957","0.14869","30.08000","0.00000","0.12042","0.01911"
"0.12292","12.66019","0.15194","30.72000","0.00000","0.12292","0.01951"
"0.12563","12.89047","0.15471","31.36000","0.00000","0.12563","0.01994"
"0.12792","13.12810","0.15756","32.00000","0.00000","0.12792","0.02030"
"0.13063","13.39225","0.16073","32.64000","0.00000","0.13063","0.02073"
"0.13292","13.61641","0.16342","33.28000","0.00000","0.13292","0.02110"
"0.13563","13.87883","0.16657","33.92000","0.00000","0.13563","0.02153"
"0.13813","14.14328","0.16974","34.56000","0.00000","0.13813","0.02192"
"0.14063","14.38868","0.17269","35.20000","0.00000","0.14063","0.02232"
"0.14313","14.62710","0.17555","35.84000","0.00000","0.14313","0.02272"
"0.14583","14.89935","0.17881","36.48000","0.00000","0.14583","0.02315"
"0.14833","15.12230","0.18149","37.12000","0.00000","0.14833","0.02354"
"0.15104","15.41118","0.18496","37.76000","0.00000","0.15104","0.02397"
"0.15354","15.63503","0.18764","38.40000","0.00000","0.15354","0.02437"
"0.15604","15.90906","0.19093","39.04000","0.00000","0.15604","0.02477"
"0.15875","16.16645","0.19402","39.68000","0.00000","0.15875","0.02520"
"0.16146","16.41684","0.19703","40.32000","0.00000","0.16146","0.02563"
"0.16396","16.64763","0.19980","40.96000","0.00000","0.16396","0.02603"
"0.16646","16.89389","0.20275","41.60000","0.00000","0.16646","0.02642"
"0.16896","17.13759","0.20568","42.24000","0.00000","0.16896","0.02682"
"0.17146","17.33743","0.20808","42.88000","0.00000","0.17146","0.02722"
"0.17396","17.61497","0.21141","43.52000","0.00000","0.17396","0.02761"
"0.17646","17.88844","0.21469","44.16000","0.00000","0.17646","0.02801"
"0.17917","18.12593","0.21754","44.80000","0.00000","0.17917","0.02844"
"0.18146","18.35805","0.22032","45.44000","0.00000","0.18146","0.02880"
"0.18417","18.61441","0.22340","46.08000","0.00000","0.18417","0.02923"
"0.18667","18.87217","0.22649","46.72000","0.00000","0.18667","0.02963"
"0.18937","19.12389","0.22952","47.36000","0.00000","0.18937","0.03006"
"0.19188","19.40660","0.23291","48.00000","0.00000","0.19188","0.03046"
"0.19438","19.64100","0.23572","48.64000","0.00000","0.19438","0.03085"
"0.19729","19.93421","0.23924","49.28000","0.00000","0.19729","0.03132"
"0.19979","20.18226","0.24222","49.92000","0.00000","0.19979","0.03171"
"0.20229","20.41461","0.24501","50.56000","0.00000","0.20229","0.03211"
"0.20500","20.66454","0.24801","51.20000","0.00000","0.20500","0.03254"
"0.20750","20.91194","0.25097","51.84000","0.00000","0.20750","0.03294"
"0.21000","21.15375","0.25388","52.48000","0.00000","0.21000","0.03333"
"0.21229","21.36566","0.25642","53.12000","0.00000","0.21229","0.03370"
"0.21479","21.64683","0.25979","53.76000","0.00000","0.21479","0.03409"
"0.21750","21.89815","0.26281","54.40000","0.00000","0.21750","0.03452"
"0.22000","22.15337","0.26587","55.04000","0.00000","0.22000","0.03492"
"0.22250","22.33711","0.26808","55.68000","0.00000","0.22250","0.03532"
"0.22521","22.68770","0.27229","56.32000","0.00000","0.22521","0.03575"
"0.22771","22.90766","0.27493","56.96000","0.00000","0.22771","0.03614"
"0.23021","23.19276","0.27835","57.60000","0.00000","0.23021","0.03654"
"0.23271","23.43214","0.28122","58.24000","0.00000","0.23271","0.03694"
"0.23542","23.71494","0.28462","58.88000","0.00000","0.23542","0.03737"
"0.23813","23.97206","0.28770","59.52000","0.00000","0.23813","0.03780"
"0.24083","24.21644","0.29063","60.16000","0.00000","0.24083","0.03823"
"0.24333","24.44213","0.29334","60.80000","0.00000","0.24333","0.03862"
"0.24583","24.70420","0.29649","61.44000","0.00000","0.24583","0.03902"
"0.24854","24.92764","0.29917","62.08000","0.00000","0.24854","0.03945"
"0.25104","25.16182","0.30198","62.72000","0.00000","0.25104","0.03985"
"0.25333","25.39504","0.30478","63.36000","0.00000","0.25333","0.04021"
"0.25604","25.63383","0.30764","64.00000","0.00000","0.25604","0.04064"
"0.25854","25.88493","0.31066","64.64000","0.00000","0.25854","0.04104"
"0.26104","26.10613","0.31331","65.28000","0.00000","0.26104","0.04144"
"0.26354","26.34866","0.31622","65.92000","0.00000","0.26354","0.04183"
"0.26604","26.60977","0.31936","66.56000","0.00000","0.26604","0.04223"
"0.26854","26.83458","0.32206","67.20000","0.00000","0.26854","0.04263"
"0.27125","27.08076","0.32501","67.84000","0.00000","0.27125","0.04306"
"0.27375","27.31145","0.32778","68.48000","0.00000","0.27375","0.04345"
"0.27646","27.53095","0.33041","69.12000","0.00000","0.27646","0.04388"
"0.27896","27.76274","0.33319","69.76000","0.00000","0.27896","0.04428"
"0.28167","27.98581","0.33587","70.40000","0.00000","0.28167","0.04471"
"0.28417","28.21726","0.33865","71.04000","0.00000","0.28417","0.04511"
"0.28688","28.42425","0.34113","71.68000","0.00000","0.28688","0.04554"
"0.28938","28.63922","0.34371","72.32000","0.00000","0.28938","0.04593"
"0.29188","28.84829","0.34622","72.96000","0.00000","0.29188","0.04633"
"0.29417","29.07032","0.34889","73.60000","0.00000","0.29417","0.04669"
"0.29688","29.30668","0.35172","74.24000","0.00000","0.29688","0.04712"
"0.29937","29.52870","0.35439","74.88000","0.00000","0.29937","0.04752"
"0.30187","29.76875","0.35727","75.52000","0.00000","0.30187","0.04792"
"0.30458","30.01570","0.36023","76.16000","0.00000","0.30458","0.04835"
"0.30708","30.23289","0.36284","76.80000","0.00000","0.30708","0.04874"
"0.30958","30.49100","0.36594","77.44000","0.00000","0.30958","0.04914"
"0.31208","30.70162","0.36847","78.08000","0.00000","0.31208","0.04954"
"0.31479","30.92305","0.37112","78.72000","0.00000","0.31479","0.04997"
"0.31729","31.16735","0.37406","79.36000","0.00000","0.31729","0.05036"
"0.32021","31.41343","0.37701","80.00000","0.00000","0.32021","0.05083"
"0.32271","31.58558","0.37907","80.64000","0.00000","0.32271","0.05122"
"0.32521","31.78504","0.38147","81.28000","0.00000","0.32521","0.05162"
"0.32771","31.99143","0.38395","81.92000","0.00000","0.32771","0.05202"
"0.33042","32.21258","0.38660","82.56000","0.00000","0.33042","0.05245"
"0.33271","32.38890","0.38872","83.20000","0.00000","0.33271","0.05281"
"0.33521","32.59306","0.39117","83.84000","0.00000","0.33521","0.05321"
"0.33771","32.81537","0.39383","84.48000","0.00000","0.33771","0.05360"
"0.34021","33.02457","0.39634","85.12000","0.00000","0.34021","0.05400"
"0.34292","33.25942","0.39916","85.76000","0.00000","0.34292","0.05443"
"0.34542","33.49017","0.40193","86.40000","0.00000","0.34542","0.05483"
"0.34792","33.69304","0.40437","87.04000","0.00000","0.34792","0.05522"
"0.35042","33.86909","0.40648","87.68000","0.00000","0.35042","0.05562"
"0.35333","34.13589","0.40968","88.32000","0.00000","0.35333","0.05608"
"0.35583","34.32579","0.41196","88.96000","0.00000","0.35583","0.05648"
"0.35833","34.54386","0.41458","89.60000","0.00000","0.35833","0.05688"
"0.36104","34.75366","0.41710","90.24000","0.00000","0.36104","0.05731"
"0.36354","34.97146","0.41971","90.88000","0.00000","0.36354","0.05771"
"0.36625","35.16881","0.42208","91.52000","0.00000","0.36625","0.05813"
"0.36875","35.38245","0.42464","92.16000","0.00000","0.36875","0.05853"
"0.37125","35.56532","0.42684","92.80000","0.00000","0.37125","0.05893"
"0.37396","35.80915","0.42976","93.44000","0.00000","0.37396","0.05936"
"0.37646","36.02407","0.43234","94.08000","0.00000","0.37646","0.05976"
"0.37896","36.21437","0.43463","94.72000","0.00000","0.37896","0.06015"
"0.38125","36.37688","0.43658","95.36000","0.00000","0.38125","0.06052"
"0.38375","36.62327","0.43953","96.00000","0.00000","0.38375","0.06091"
"0.38646","36.83068","0.44202","96.64000","0.00000","0.38646","0.06134"
"0.38896","37.06739","0.44486","97.28000","0.00000","0.38896","0.06174"
"0.39167","37.29539","0.44760","97.92000","0.00000","0.39167","0.06217"
"0.39417","37.52661","0.45038","98.56000","0.00000","0.39417","0.06257"
"0.39688","37.73206","0.45284","99.20000","0.00000","0.39688","0.06300"
"0.39938","37.93848","0.45532","99.84000","0.00000","0.39937","0.06339"
"0.40208","38.12374","0.45754","100.48000","0.00000","0.40208","0.06382"
"0.40458","38.33232","0.46005","101.12000","0.00000","0.40458","0.06422"
"0.40708","38.55248","0.46269","101.76000","0.00000","0.40708","0.06462"
"0.40979","38.73992","0.46494","102.40000","0.00000","0.40979","0.06505"
"0.41229","38.93165","0.46724","103.04000","0.00000","0.41229","0.06544"
"0.41479","39.14544","0.46980","103.68000","0.00000","0.41479","0.06584"
"0.41729","39.33080","0.47203","104.32000","0.00000","0.41729","0.06624"
"0.41979","39.50232","0.47409","104.96000","0.00000","0.41979","0.06663"
"0.42229","39.69725","0.47643","105.60000","0.00000","0.42229","0.06703"
"0.42479","39.93544","0.47929","106.24000","0.00000","0.42479","0.06743"
"0.42729","40.13749","0.48171","106.88000","0.00000","0.42729","0.06782"
"0.42979","40.30669","0.48374","107.52000","0.00000","0.42979","0.06822"
"0.43250","40.54199","0.48656","108.16000","0.00000","0.43250","0.06865"
"0.43500","40.75095","0.48907","108.80000","0.00000","0.43500","0.06905"
"0.43771","40.97008","0.49170","109.44000","0.00000","0.43771","0.06948"
"0.44021","41.12975","0.49362","110.08000","0.00000","0.44021","0.06987"
"0.44292","41.37648","0.49658","110.72000","0.00000","0.44292","0.07030"
"0.44542","41.60266","0.49929","111.36000","0.00000","0.44542","0.07070"
"0.44813","41.80190","0.50169","112.00000","0.00000","0.44813","0.07113"
"0.45063","41.99546","0.50401","112.64000","0.00000","0.45063","0.07153"
"0.45333","42.18225","0.50625","113.28000","0.00000","0.45333","0.07196"
"0.45583","42.37390","0.50855","113.92000","0.00000","0.45583","0.07235"
"0.45833","42.57828","0.51100","114.56000","0.00000","0.45833","0.07275"
"0.46063","42.76316","0.51322","115.20000","0.00000","0.46063","0.07312"
"0.46312","42.97630","0.51578","115.84000","0.00000","0.46312","0.07351"
"0.46583","43.19783","0.51844","116.48000","0.00000","0.46583","0.07394"
"0.46833","43.43521","0.52129","117.12000","0.00000","0.46833","0.07434"
"0.47083","43.66866","0.52409","117.76000","0.00000","0.47083","0.07474"
"0.47354","43.88649","0.52670","118.40000","0.00000","0.47354","0.07517"
"0.47604","44.08178","0.52905","119.04000","0.00000","0.47604","0.07556"
"0.47875","44.33386","0.53207","119.68000","0.00000","0.47875","0.07599"
"0.48146","44.51586","0.53426","120.32000","0.00000","0.48146","0.07642"
"0.48396","44.69827","0.53645","120.96000","0.00000","0.48396","0.07682"
"0.48646","44.92632","0.53918","121.60000","0.00000","0.48646","0.07722"
"0.48896","45.09320","0.54119","122.24000","0.00000","0.48896","0.07761"
"0.49146","45.27988","0.54343","122.88000","0.00000","0.49146","0.07801"
"0.49417","45.50727","0.54616","123.52000","0.00000","0.49417","0.07844"
"0.49667","45.70186","0.54849","124.16000","0.00000","0.49667","0.07884"
"0.49917","45.87123","0.55052","124.80000","0.00000","0.49917","0.07923"
"0.50167","46.03117","0.55244","125.44000","0.00000","0.50167","0.07963"
"0.50417","46.24016","0.55495","126.08000","0.00000","0.50417","0.08003"
"0.50667","46.44260","0.55738","126.72000","0.00000","0.50667","0.08042"
"0.50917","46.61972","0.55951","127.36000","0.00000","0.50917","0.08082"
"0.51188","46.88328","0.56267","128.00000","0.00000","0.51188","0.08125"
"0.51438","47.08106","0.56504","128.64000","0.00000","0.51438","0.08165"
"0.51708","47.30273","0.56770","129.28000","0.00000","0.51708","0.08208"
"0.51958","47.48067","0.56984","129.92000","0.00000","0.51958","0.08247"
"0.52208","47.70278","0.57251","130.56000","0.00000","0.52208","0.08287"
"0.52458","47.92031","0.57512","131.20000","0.00000","0.52458","0.08327"
"0.52729","48.14660","0.57783","131.84000","0.00000","0.52729","0.08370"
"0.52979","48.30231","0.57970","132.48000","0.00000","0.52979","0.08409"
"0.53250","48.54882","0.58266","133.12000","0.00000","0.53250","0.08452"
"0.53521","48.81286","0.58583","133.76000","0.00000","0.53521","0.08495"
"0.53771","48.99340","0.58799","134.40000","0.00000","0.53771","0.08535"
"0.54021","49.19290","0.59039","135.04000","0.00000","0.54021","0.08575"
"0.54271","49.35978","0.59239","135.68000","0.00000","0.54271","0.08614"
"0.54521","49.58969","0.59515","136.32000","0.00000","0.54521","0.08654"
"0.54771","49.81570","0.59786","136.96000","0.00000","0.54771","0.08694"
"0.55021","50.03835","0.60054","137.60000","0.00000","0.55021","0.08733"
"0.55292","50.26196","0.60322","138.24000","0.00000","0.55292","0.08776"
"0.55542","50.46992","0.60571","138.88000","0.00000","0.55542","0.08816"
"0.55813","50.72234","0.60874","139.52000","0.00000","0.55813","0.08859"
"0.56063","50.93053","0.61124","140.16000","0.00000","0.56063","0.08899"
"0.56333","51.13436","0.61369","140.80000","0.00000","0.56333","0.08942"
"0.56583","51.34687","0.61624","141.44000","0.00000","0.56583","0.08981"
"0.56833","51.52169","0.61834","142.08000","0.00000","0.56833","0.09021"
"0.57083","51.68502","0.62030","142.72000","0.00000","0.57083","0.09061"
"0.57354","51.93201","0.62326","143.36000","0.00000","0.57354","0.09104"
"0.57604","52.11785","0.62549","144.00000","0.00000","0.57604","0.09144"
"0.57854","52.28936","0.62755","144.64000","0.00000","0.57854","0.09183"
"0.58104","52.47404","0.62977","145.28000","0.00000","0.58104","0.09223"
"0.58354","52.64378","0.63180","145.92000","0.00000","0.58354","0.09263"
"0.58604","52.83059","0.63405","146.56000","0.00000","0.58604","0.09302"
"0.58854","52.99993","0.63608","147.20000","0.00000","0.58854","0.09342"
"0.59146","53.32589","0.63999","147.84000","0.00000","0.59146","0.09388"
"0.59396","53.51084","0.64221","148.48000","0.00000","0.59396","0.09428"
"0.59646","53.73025","0.64484","149.12000","0.00000","0.59646","0.09468"
"0.59917","53.90215","0.64691","149.76000","0.00000","0.59917","0.09511"
"0.60167","54.12394","0.64957","150.40000","0.00000","0.60167","0.09550"
"0.60417","54.30103","0.65169","151.04000","0.00000","0.60417","0.09590"
"0.60688","54.49959","0.65408","151.68000","0.00000","0.60688","0.09633"
"0.60917","54.66159","0.65602","152.32000","0.00000","0.60917","0.09669"
"0.61167","54.87752","0.65861","152.96000","0.00000","0.61167","0.09709"
"0.61438","55.11964","0.66152","153.60000","0.00000","0.61438","0.09752"
"0.61708","55.33282","0.66408","154.24000","0.00000","0.61708","0.09795"
"0.61958","55.50638","0.66616","154.88000","0.00000","0.61958","0.09835"
"0.62208","55.71105","0.66862","155.52000","0.00000","0.62208","0.09874"
"0.62458","55.93107","0.67126","156.16000","0.00000","0.62458","0.09914"
"0.62708","56.12584","0.67359","156.80000","0.00000","0.62708","0.09954"
"0.62958","56.33785","0.67614","157.44000","0.00000","0.62958","0.09993"
"0.63208","56.57016","0.67893","158.08000","0.00000","0.63208","0.10033"
"0.63479","56.77042","0.68133","158.72000","0.00000","0.63479","0.10076"
"0.63729","57.00544","0.68415","159.36000","0.00000","0.63729","0.10116"
"0.63979","57.19188","0.68639","160.00000","0.00000","0.63979","0.10155"
"0.64250","57.39503","0.68883","160.64000","0.00000","0.64250","0.10198"
"0.64500","57.62361","0.69157","161.28000","0.00000","0.64500","0.10238"
"0.64750","57.81351","0.69385","161.92000","0.00000","0.64750","0.10278"
"0.65021","58.02735","0.69642","162.56000","0.00000","0.65021","0.10321"
"0.65292","58.26541","0.69927","163.20000","0.00000","0.65292","0.10364"
"0.65542","58.48143","0.70187","163.84000","0.00000","0.65542","0.10403"
"0.65792","58.64252","0.70380","164.48000","0.00000","0.65792","0.10443"
"0.66042","58.82240","0.70596","165.12000","0.00000","0.66042","0.10483"
"0.66313","59.05093","0.70870","165.76000","0.00000","0.66313","0.10526"
"0.66563","59.25685","0.71117","166.40000","0.00000","0.66563","0.10565"
"0.66813","59.44288","0.71340","167.04000","0.00000","0.66813","0.10605"
"0.67063","59.59082","0.71518","167.68000","0.00000","0.67063","0.10645"
"0.67313","59.79792","0.71766","168.32000","0.00000","0.67313","0.10685"
"0.67563","60.02906","0.72044","168.96000","0.00000","0.67563","0.10724"
"0.67813","60.23130","0.72287","169.60000","0.00000","0.67813","0.10764"
"0.68083","60.48846","0.72595","170.24000","0.00000","0.68083","0.10807"
"0.68333","60.67070","0.72814","170.88000","0.00000","0.68333","0.10847"
"0.68604","60.87803","0.73063","171.52000","0.00000","0.68604","0.10890"
"0.68854","61.07799","0.73303","172.16000","0.00000","0.68854","0.10929"
"0.69104","61.28883","0.73556","172.80000","0.00000","0.69104","0.10969"
"0.69375","61.50520","0.73815","173.44000","0.00000","0.69375","0.11012"
"0.69625","61.72348","0.74077","174.08000","0.00000","0.69625","0.11052"
"0.69896","61.92818","0.74323","174.72000","0.00000","0.69896","0.11095"
"0.70125","62.10472","0.74535","175.36000","0.00000","0.70125","0.11131"
"0.70396","62.32244","0.74796","176.00000","0.00000","0.70396","0.11174"
"0.70667","62.58652","0.75113","176.64000","0.00000","0.70667","0.11217"
"0.70917","62.76650","0.75329","177.28000","0.00000","0.70917","0.11257"
"0.71167","63.01995","0.75633","177.92000","0.00000","0.71167","0.11296"
"0.71417","63.22434","0.75879","178.56000","0.00000","0.71417","0.11336"
"0.71667","63.43522","0.76132","179.20000","0.00000","0.71667","0.11376"
"0.71938","63.66366","0.76406","179.84000","0.00000","0.71938","0.11419"
"0.72188","63.90780","0.76699","180.48000","0.00000","0.72188","0.11458"
"0.72438","64.11815","0.76951","181.12000","0.00000","0.72438","0.11498"
"0.72688","64.26488","0.77128","181.76000","0.00000","0.72688","0.11538"
"0.72938","64.50621","0.77417","182.40000","0.00000","0.72938","0.11577"
"0.73208","64.73084","0.77687","183.04000","0.00000","0.73208","0.11620"
"0.73458","64.94598","0.77945","183.68000","0.00000","0.73458","0.11660"
"0.73708","65.16178","0.78204","184.32000","0.00000","0.73708","0.11700"
"0.73958","65.37364","0.78458","184.96000","0.00000","0.73958","0.11739"
"0.74229","65.59364","0.78722","185.60000","0.00000","0.74229","0.11782"
"0.74500","65.81799","0.78991","186.24000","0.00000","0.74500","0.11825"
"0.74771","66.06880","0.79293","186.88000","0.00000","0.74771","0.11868"
"0.75000","66.17391","0.79419","187.52000","0.00000","0.75000","0.11905"
"0.75271","66.45930","0.79761","188.16000","0.00000","0.75271","0.11948"
"0.75521","66.65154","0.79992","188.80000","0.00000","0.75521","0.11987"
"0.75771","66.80489","0.80176","189.44000","0.00000","0.75771","0.12027"
"0.76021","67.02795","0.80444","190.08000","0.00000","0.76021","0.12067"
"0.76271","67.24802","0.80708","190.72000","0.00000","0.76271","0.12106"
"0.76521","67.44254","0.80941","191.36000","0.00000","0.76521","0.12146"
"0.76792","67.66618","0.81210","192.00000","0.00000","0.76792","0.12189"
"0.77042","67.89004","0.81478","192.64000","0.00000","0.77042","0.12229"
"0.77292","68.12180","0.81756","193.28000","0.00000","0.77292","0.12269"
"0.77563","68.32443","0.82000","193.92000","0.00000","0.77563","0.12312"
"0.77812","68.55682","0.82278","194.56000","0.00000","0.77812","0.12351"
"0.78063","68.72592","0.82481","195.20000","0.00000","0.78063","0.12391"
"0.78333","68.97689","0.82783","195.84000","0.00000","0.78333","0.12434"
"0.78604","69.23746","0.83095","196.48000","0.00000","0.78604","0.12477"
"0.78854","69.41216","0.83305","197.12000","0.00000","0.78854","0.12517"
"0.79104","69.64399","0.83583","197.76000","0.00000","0.79104","0.12556"
"0.79375","69.87920","0.83866","198.40000","0.00000","0.79375","0.12599"
"0.79625","70.07112","0.84096","199.04000","0.00000","0.79625","0.12639"
"0.79875","70.28703","0.84355","199.68000","0.00000","0.79875","0.12679"
"0.80146","70.55759","0.84680","200.32000","0.00000","0.80146","0.12722"
"0.80396","70.76287","0.84926","200.96000","0.00000","0.80396","0.12761"
"0.80625","70.93736","0.85135","201.60000","0.00000","0.80625","0.12798"
"0.80896","71.17181","0.85417","202.24000","0.00000","0.80896","0.12841"
"0.81146","71.42989","0.85727","202.88000","0.00000","0.81146","0.12880"
"0.81417","71.62130","0.85956","203.52000","0.00000","0.81417","0.12923"
"0.81667","71.82307","0.86198","204.16000","0.00000","0.81667","0.12963"
"0.81896","71.95377","0.86355","204.80000","0.00000","0.81896","0.12999"
"0.82167","72.21169","0.86665","205.44000","0.00000","0.82167","0.13042"
"0.82417","72.44186","0.86941","206.08000","0.00000","0.82417","0.13082"
"0.82688","72.72723","0.87284","206.72000","0.00000","0.82687","0.13125"
"0.82938","72.87340","0.87459","207.36000","0.00000","0.82938","0.13165"
"0.83208","73.13568","0.87774","208.00000","0.00000","0.83208","0.13208"
"0.83458","73.34055","0.88020","208.64000","0.00000","0.83458","0.13247"
"0.83708","73.50051","0.88212","209.28000","0.00000","0.83708","0.13287"
"0.83958","73.75692","0.88519","209.92000","0.00000","0.83958","0.13327"
"0.84208","73.95307","0.88755","210.56000","0.00000","0.84208","0.13366"
"0.84479","74.17941","0.89026","211.20000","0.00000","0.84479","0.13409"
"0.84708","74.40131","0.89293","211.84000","0.00000","0.84708","0.13446"
"0.84979","74.64345","0.89583","212.48000","0.00000","0.84979","0.13489"
"0.85229","74.87290","0.89859","213.12000","0.00000","0.85229","0.13528"
"0.85479","75.10084","0.90132","213.76000","0.00000","0.85479","0.13568"
"0.85729","75.29639","0.90367","214.40000","0.00000","0.85729","0.13608"
"0.86000","75.55728","0.90680","215.04000","0.00000","0.86000","0.13651"
"0.86271","75.79353","0.90964","215.68000","0.00000","0.86271","0.13694"
"0.86542","76.05517","0.91278","216.32000","0.00000","0.86542","0.13737"
"0.86792","76.23206","0.91490","216.96000","0.00000","0.86792","0.13776"
"0.87063","76.47466","0.91781","217.60000","0.00000","0.87063","0.13819"
"0.87313","76.67072","0.92016","218.24000","0.00000","0.87313","0.13859"
"0.87563","76.88992","0.92279","218.88000","0.00000","0.87563","0.13899"
"0.87813","77.13054","0.92568","219.52000","0.00000","0.87813","0.13938"
"0.88083","77.36024","0.92844","220.16000","0.00000","0.88083","0.13981"
"0.88333","77.58267","0.93111","220.80000","0.00000","0.88333","0.14021"
"0.88563","77.74077","0.93301","221.44000","0.00000","0.88563","0.14058"
"0.88813","78.00454","0.93617","222.08000","0.00000","0.88813","0.14097"
"0.89083","78.25069","0.93913","222.72000","0.00000","0.89083","0.14140"
"0.89333","78.45203","0.94154","223.36000","0.00000","0.89333","0.14180"
"0.89583","78.69704","0.94448","224.00000","0.00000","0.89583","0.14220"
"0.89833","78.91824","0.94714","224.64000","0.00000","0.89833","0.14259"
"0.90104","79.16132","0.95005","225.28000","0.00000","0.90104","0.14302"
"0.90354","79.36508","0.95250","225.92000","0.00000","0.90354","0.14342"
"0.90625","79.64118","0.95581","226.56000","0.00000","0.90625","0.14385"
"0.90875","79.81596","0.95791","227.20000","0.00000","0.90875","0.14425"
"0.91125","80.08215","0.96111","227.84000","0.00000","0.91125","0.14464"
"0.91396","80.34015","0.96420","228.48000","0.00000","0.91396","0.14507"
"0.91646","80.52172","0.96638","229.12000","0.00000","0.91646","0.14547"
"0.91917","80.73714","0.96897","229.76000","0.00000","0.91917","0.14590"
"0.92167","80.96835","0.97174","230.40000","0.00000","0.92167","0.14630"
"0.92417","81.17198","0.97419","231.04000","0.00000","0.92417","0.14669"
"0.92646","81.37187","0.97658","231.68000","0.00000","0.92646","0.14706"
"0.92917","81.60648","0.97940","232.32000","0.00000","0.92917","0.14749"
"0.93167","81.85321","0.98236","232.96000","0.00000","0.93167","0.14788"
"0.93417","82.08015","0.98509","233.60000","0.00000","0.93417","0.14828"
"0.93667","82.20919","0.98663","234.24000","0.00000","0.93667","0.14868"
"0.93938","82.49236","0.99003","234.88000","0.00000","0.93938","0.14911"
"0.94188","82.72963","0.99288","235.52000","0.00000","0.94188","0.14950"
"0.94458","83.00570","0.99619","236.16000","0.00000","0.94458","0.14993"
"0.94708","83.19769","0.99850","236.80000","0.00000","0.94708","0.15033"
"0.94979","83.44493","1.00146","237.44000","0.00000","0.94979","0.15076"
"0.95229","83.69218","1.00443","238.08000","0.00000","0.95229","0.15116"
"0.95500","83.92888","1.00727","238.72000","0.00000","0.95500","0.15159"
"0.95750","84.14150","1.00982","239.36000","0.00000","0.95750","0.15198"
"0.96000","84.33739","1.01218","240.00000","0.00000","0.96000","0.15238"
"0.96250","84.56245","1.01488","240.64000","0.00000","0.96250","0.15278"
"0.96500","84.71794","1.01674","241.28000","0.00000","0.96500","0.15317"
"0.96750","84.99304","1.02004","241.92000","0.00000","0.96750","0.15357"
"0.97021","85.26155","1.02327","242.56000","0.00000","0.97021","0.15400"
"0.97271","85.52699","1.02645","243.20000","0.00000","0.97271","0.15440"
"0.97521","85.70709","1.02861","243.84000","0.00000","0.97521","0.15479"
"0.97771","85.97289","1.03180","244.48000","0.00000","0.97771","0.15519"
"0.98042","86.21371","1.03469","245.12000","0.00000","0.98042","0.15562"
"0.98292","86.45018","1.03753","245.76000","0.00000","0.98292","0.15602"
"0.98563","86.75089","1.04114","246.40000","0.00000","0.98563","0.15645"
"0.98813","86.94502","1.04347","247.04000","0.00000","0.98813","0.15685"
"0.99083","87.17886","1.04628","247.68000","0.00000","0.99083","0.15728"
"0.99354","87.44582","1.04948","248.32000","0.00000","0.99354","0.15771"
"0.99583","87.61659","1.05153","248.96000","0.00000","0.99583","0.15807"
"0.99854","87.83751","1.05418","249.60000","0.00000","0.99854","0.15850"
"1.00104","88.08768","1.05718","250.24000","0.00000","1.00104","0.15890"
"1.00354","88.29775","1.05971","250.88000","0.00000","1.00354","0.15929"
"1.00604","88.49872","1.06212","251.52000","0.00000","1.00604","0.15969"
"1.00854","88.77064","1.06538","252.16000","0.00000","1.00854","0.16009"
"1.01104","89.03410","1.06854","252.80000","0.00000","1.01104","0.16048"
"1.01375","89.26046","1.07126","253.44000","0.00000","1.01375","0.16091"
"1.01604","89.47449","1.07383","254.08000","0.00000","1.01604","0.16128"
"1.01875","89.72684","1.07686","254.72000","0.00000","1.01875","0.16171"
"1.02125","89.98798","1.07999","255.36000","0.00000","1.02125","0.16210"
"1.02396","90.24013","1.08302","256.00000","0.00000","1.02396","0.16253"
"1.02646","90.42283","1.08521","256.64000","0.00000","1.02646","0.16293"
"1.02917","90.72918","1.08889","257.28000","0.00000","1.02917","0.16336"
"1.03188","91.00813","1.09223","257.92000","0.00000","1.03188","0.16379"
"1.03438","91.20316","1.09458","258.56000","0.00000","1.03438","0.16419"
"1.03688","91.41860","1.09716","259.20000","0.00000","1.03688","0.16458"
"1.03938","91.66331","1.10010","259.84000","0.00000","1.03938","0.16498"
"1.04208","91.87321","1.10262","260.48000","0.00000","1.04208","0.16541"
"1.04438","92.05113","1.10475","261.12000","0.00000","1.04438","0.16577"
"1.04688","92.27309","1.10742","261.76000","0.00000","1.04688","0.16617"
"1.04938","92.57048","1.11098","262.40000","0.00000","1.04938","0.16657"
"1.05208","92.80691","1.11382","263.04000","0.00000","1.05208","0.16700"
"1.05458","93.03395","1.11655","263.68000","0.00000","1.05458","0.16739"
"1.05708","93.29544","1.11969","264.32000","0.00000","1.05708","0.16779"
"1.05958","93.51157","1.12228","264.96000","0.00000","1.05958","0.16819"
"1.06229","93.79672","1.12570","265.60000","0.00000","1.06229","0.16862"
"1.06479","93.98276","1.12793","266.24000","0.00000","1.06479","0.16901"
"1.06750","94.25467","1.13120","266.88000","0.00000","1.06750","0.16944"
"1.07021","94.54132","1.13464","267.52000","0.00000","1.07021","0.16987"
"1.07271","94.78155","1.13752","268.16000","0.00000","1.07271","0.17027"
"1.07542","94.98553","1.13997","268.80000","0.00000","1.07542","0.17070"
"1.07792","95.18716","1.14239","269.44000","0.00000","1.07792","0.17110"
"1.08042","95.44585","1.14549","270.08000","0.00000","1.08042","0.17149"
"1.08292","95.68233","1.14833","270.72000","0.00000","1.08292","0.17189"
"1.08542","95.87175","1.15061","271.36000","0.00000","1.08542","0.17229"
"1.08792","96.15298","1.15398","272.00000","0.00000","1.08792","0.17269"
"1.09063","96.41920","1.15718","272.64000","0.00000","1.09063","0.17312"
"1.09313","96.67505","1.16025","273.28000","0.00000","1.09313","0.17351"
"1.09542","96.83366","1.16215","273.92000","0.00000","1.09542","0.17388"
"1.09812","97.14030","1.16583","274.56000","0.00000","1.09812","0.17431"
"1.10063","97.39896","1.16893","275.20000","0.00000","1.10063","0.17470"
"1.10333","97.69287","1.17246","275.84000","0.00000","1.10333","0.17513"
"1.10583","97.89977","1.17494","276.48000","0.00000","1.10583","0.17553"
"1.10833","98.14737","1.17792","277.12000","0.00000","1.10833","0.17593"
"1.11104","98.44432","1.18148","277.76000","0.00000","1.11104","0.17636"
"1.11375","98.67490","1.18425","278.40000","0.00000","1.11375","0.17679"
"1.11625","98.90486","1.18701","279.04000","0.00000","1.11625","0.17718"
"1.11875","99.16631","1.19014","279.68000","0.00000","1.11875","0.17758"
"1.12146","99.39481","1.19289","280.32000","0.00000","1.12146","0.17801"
"1.12396","99.60161","1.19537","280.96000","0.00000","1.12396","0.17841"
"1.12646","99.83971","1.19823","281.60000","0.00000","1.12646","0.17880"
"1.12896","100.08862","1.20121","282.24000","0.00000","1.12896","0.17920"
"1.13146","100.33799","1.20421","282.88000","0.00000","1.13146","0.17960"
"1.13396","100.60414","1.20740","283.52000","0.00000","1.13396","0.17999"
"1.13646","100.89774","1.21092","284.16000","0.00000","1.13646","0.18039"
"1.13896","101.15654","1.21403","284.80000","0.00000","1.13896","0.18079"
"1.14167","101.42763","1.21728","285.44000","0.00000","1.14167","0.18122"
"1.14417","101.64924","1.21994","286.08000","0.00000","1.14417","0.18161"
"1.14688","101.96004","1.22367","286.72000","0.00000","1.14688","0.18204"
"1.14938","102.23168","1.22693","287.36000","0.00000","1.14938","0.18244"
"1.15208","102.53545","1.23058","288.00000","0.00000","1.15208","0.18287"
"1.15458","102.73079","1.23292","288.64000","0.00000","1.15458","0.18327"
"1.15729","102.98054","1.23592","289.28000","0.00000","1.15729","0.18370"
"1.15979","103.20441","1.23861","289.92000","0.00000","1.15979","0.18409"
"1.16229","103.47647","1.24187","290.56000","0.00000","1.16229","0.18449"
"1.16479","103.69238","1.24446","291.20000","0.00000","1.16479","0.18489"
"1.16729","103.89532","1.24690","291.84000","0.00000","1.16729","0.18528"
"1.16979","104.17213","1.25022","292.48000","0.00000","1.16979","0.18568"
"1.17229","104.44366","1.25348","293.12000","0.00000","1.17229","0.18608"
"1.17479","104.66752","1.25617","293.76000","0.00000","1.17479","0.18647"
"1.17729","104.97522","1.25986","294.40000","0.00000","1.17729","0.18687"
"1.18000","105.25809","1.26326","295.04000","0.00000","1.18000","0.18730"
"1.18271","105.56904","1.26699","295.68000","0.00000","1.18271","0.18773"
"1.18521","105.80697","1.26984","296.32000","0.00000","1.18521","0.18813"
"1.18771","106.10091","1.27337","296.96000","0.00000","1.18771","0.18853"
"1.19042","106.33045","1.27613","297.60000","0.00000","1.19042","0.18896"
"1.19313","106.61944","1.27959","298.24000","0.00000","1.19313","0.18938"
"1.19563","106.85318","1.28240","298.88000","0.00000","1.19563","0.18978"
"1.19813","107.11799","1.28558","299.52000","0.00000","1.19813","0.19018"
"1.20083","107.36111","1.28849","300.16000","0.00000","1.20083","0.19061"
"1.20333","107.58636","1.29120","300.80000","0.00000","1.20333","0.19101"
"1.20583","107.84492","1.29430","301.44000","0.00000","1.20583","0.19140"
"1.20833","108.08461","1.29718","302.08000","0.00000","1.20833","0.19180"
"1.21083","108.34077","1.30025","302.72000","0.00000","1.21083","0.19220"
"1.21333","108.54252","1.30267","303.36000","0.00000","1.21333","0.19259"
"1.21583","108.80270","1.30580","304.00000","0.00000","1.21583","0.19299"
"1.21833","109.10675","1.30945","304.64000","0.00000","1.21833","0.19339"
"1.22104","109.38045","1.31273","305.28000","0.00000","1.22104","0.19382"
"1.22354","109.60670","1.31545","305.92000","0.00000","1.22354","0.19421"
"1.22625","109.98609","1.32000","306.56000","0.00000","1.22625","0.19464"
"1.22875","110.25246","1.32320","307.20000","0.00000","1.22875","0.19504"
"1.23146","110.51972","1.32640","307.84000","0.00000","1.23146","0.19547"
"1.23396","110.75241","1.32920","308.48000","0.00000","1.23396","0.19587"
"1.23667","111.01839","1.33239","309.12000","0.00000","1.23667","0.19630"
"1.23917","111.25598","1.33524","309.76000","0.00000","1.23917","0.19669"
"1.24167","111.51379","1.33833","310.40000","0.00000","1.24167","0.19709"
"1.24417","111.72320","1.34085","311.04000","0.00000","1.24417","0.19749"
"1.24688","112.03165","1.34455","311.68000","0.00000","1.24688","0.19792"
"1.24938","112.26505","1.34735","312.32000","0.00000","1.24938","0.19831"
"1.25188","112.51543","1.35035","312.96000","0.00000","1.25188","0.19871"
"1.25417","112.65501","1.35203","313.60000","0.00000","1.25417","0.19907"
"1.25667","112.98426","1.35598","314.24000","0.00000","1.25667","0.19947"
"1.25937","113.24908","1.35916","314.88000","0.00000","1.25937","0.19990"
"1.26063","112.86435","1.35454","315.50400","0.00000","1.26063","0.20010"
"1.26063","112.00214","1.34419","316.14400","0.00000","1.26063","0.20010"
"1.26063","111.34520","1.33631","316.78400","0.00000","1.26063","0.20010"
"1.26063","110.80682","1.32985","317.42400","0.00000","1.26063","0.20010"
"1.26063","110.34467","1.32430","318.06400","0.00000","1.26063","0.20010"
"1.26063","109.92051","1.31921","318.70400","0.00000","1.26063","0.20010"
"1.26063","109.54179","1.31467","319.34400","0.00000","1.26063","0.20010"
"1.26021","109.11892","1.30959","319.98400","0.00000","1.26021","0.20003"
"1.26021","108.82380","1.30605","320.62400","0.00000","1.26021","0.20003"
"1.26021","108.52789","1.30250","321.26400","0.00000","1.26021","0.20003"
"1.26021","108.25324","1.29920","321.90400","0.00000","1.26021","0.20003"
"1.26021","107.99641","1.29612","322.54400","0.00000","1.26021","0.20003"
"1.26021","107.74587","1.29311","323.18400","0.00000","1.26021","0.20003"
"1.26021","107.52288","1.29044","323.82400","0.00000","1.26021","0.20003"
"1.26021","107.29727","1.28773","324.46400","0.00000","1.26021","0.20003"
"1.26021","107.08605","1.28519","325.10400","0.00000","1.26021","0.20003"
"1.26021","106.88129","1.28274","325.74400","0.00000","1.26021","0.20003"
"1.26021","106.69832","1.28054","326.38400","0.00000","1.26021","0.20003"
"1.26021","106.50857","1.27826","327.02400","0.00000","1.26021","0.20003"
"1.26021","106.32573","1.27607","327.66400","0.00000","1.26021","0.20003"
"1.26021","106.15141","1.27398","328.30400","0.00000","1.26021","0.20003"
"1.26021","105.97803","1.27190","328.94400","0.00000","1.26021","0.20003"
"1.26021","105.82389","1.27005","329.58400","0.00000","1.26021","0.20003"
"1.26021","105.65165","1.26798","330.22400","0.00000","1.26021","0.20003"
"1.26021","105.51774","1.26637","330.86400","0.00000","1.26021","0.20003"
"1.26021","105.36194","1.26450","331.50400","0.00000","1.26021","0.20003"
"1.26021","105.21545","1.26274","332.14400","0.00000","1.26021","0.20003"
"1.26021","105.07903","1.26111","332.78400","0.00000","1.26021","0.20003"
"1.26021","104.94464","1.25949","333.42400","0.00000","1.26021","0.20003"
"1.26021","104.81978","1.25800","334.06400","0.00000","1.26021","0.20003"
"1.26021","104.68112","1.25633","334.70400","0.00000","1.26021","0.20003"
"1.26021","104.55803","1.25485","335.34400","0.00000","1.26021","0.20003"
"1.26021","104.43215","1.25334","335.98400","0.00000","1.26021","0.20003"
"1.26021","104.30937","1.25187","336.62400","0.00000","1.26021","0.20003"
"1.26021","104.20712","1.25064","337.26400","0.00000","1.26021","0.20003"
"1.26021","104.09080","1.24925","337.90400","0.00000","1.26021","0.20003"
"1.26021","103.96834","1.24778","338.54400","0.00000","1.26021","0.20003"
"1.26021","103.86348","1.24652","339.18400","0.00000","1.26021","0.20003"
"1.26021","103.76004","1.24528","339.82400","0.00000","1.26021","0.20003"
"1.26021","103.64635","1.24391","340.46400","0.00000","1.26021","0.20003"
"1.26021","103.55384","1.24280","341.10400","0.00000","1.26021","0.20003"
"1.26021","103.45127","1.24157","341.74400","0.00000","1.26021","0.20003"
"1.26021","103.36198","1.24050","342.38400","0.00000","1.26021","0.20003"
"1.26021","103.27075","1.23940","343.02400","0.00000","1.26021","0.20003"
"1.26021","103.16389","1.23812","343.66400","0.00000","1.26021","0.20003"
"1.26021","103.07314","1.23703","344.30400","0.00000","1.26021","0.20003"
"1.26021","102.95543","1.23562","344.94400","0.00000","1.26021","0.20003"
"1.26021","102.88697","1.23480","345.58400","0.00000","1.26021","0.20003"
"1.26021","102.80944","1.23387","346.22400","0.00000","1.26021","0.20003"
"1.26021","102.71251","1.23270","346.86400","0.00000","1.26021","0.20003"
"1.26021","102.63205","1.23174","347.50400","0.00000","1.26021","0.20003"
"1.26021","102.52507","1.23046","348.14400","0.00000","1.26021","0.20003"
"1.26021","102.45875","1.22966","348.78400","0.00000","1.26021","0.20003"
"1.26021","102.37022","1.22860","349.42400","0.00000","1.26021","0.20003"
"1.26021","102.28644","1.22759","350.06400","0.00000","1.26021","0.20003"
"1.26021","102.20890","1.22666","350.70400","0.00000","1.26021","0.20003"
"1.26021","102.13696","1.22580","351.34400","0.00000","1.26021","0.20003"
"1.26021","102.06653","1.22495","351.98400","0.00000","1.26021","0.20003"
"1.26021","101.97886","1.22390","352.62400","0.00000","1.26021","0.20003"
"1.26021","101.90079","1.22296","353.26400","0.00000","1.26021","0.20003"
"1.26021","101.83894","1.22222","353.90400","0.00000","1.26021","0.20003"
"1.26021","101.75943","1.22127","354.54400","0.00000","1.26021","0.20003"
"1.26021","101.68897","1.22042","355.18400","0.00000","1.26021","0.20003"
"1.26021","101.61443","1.21953","355.82400","0.00000","1.26021","0.20003"
"1.26021","101.54774","1.21873","356.46400","0.00000","1.26021","0.20003"
"1.26021","101.47466","1.21785","357.10400","0.00000","1.26021","0.20003"
"1.26021","101.40015","1.21695","357.74400","0.00000","1.26021","0.20003"
"1.26021","101.34093","1.21624","358.38400","0.00000","1.26021","0.20003"
"1.26021","101.27779","1.21549","359.02400","0.00000","1.26021","0.20003"
"1.26021","101.20428","1.21460","359.66400","0.00000","1.26021","0.20003"
"1.26021","101.14659","1.21391","360.30400","0.00000","1.26021","0.20003"
"1.26021","101.07726","1.21308","360.94400","0.00000","1.26021","0.20003"
"1.26021","101.01472","1.21233","361.58400","0.00000","1.26021","0.20003"
"1.26021","100.97131","1.21181","362.22400","0.00000","1.26021","0.20003"
"1.26021","100.88972","1.21083","362.86400","0.00000","1.26021","0.20003"
"1.26021","100.82793","1.21009","363.50400","0.00000","1.26021","0.20003"
"1.26021","100.76756","1.20936","364.14400","0.00000","1.26021","0.20003"
"1.26021","100.71323","1.20871","364.78400","0.00000","1.26021","0.20003"
"1.26021","100.65746","1.20804","365.42400","0.00000","1.26021","0.20003"
"1.26021","100.58525","1.20717","366.06400","0.00000","1.26021","0.20003"
"1.26021","100.53912","1.20662","366.70400","0.00000","1.26021","0.20003"
"1.26021","100.47474","1.20585","367.34400","0.00000","1.26021","0.20003"
"1.26021","100.42419","1.20524","367.98400","0.00000","1.26021","0.20003"
"1.26021","100.36639","1.20455","368.62400","0.00000","1.26021","0.20003"
"1.26021","100.30428","1.20380","369.26400","0.00000","1.26021","0.20003"
"1.26021","100.26302","1.20331","369.90400","0.00000","1.26021","0.20003"
"1.26021","100.21963","1.20279","370.54400","0.00000","1.26021","0.20003"
"1.26021","100.14552","1.20190","371.18400","0.00000","1.26021","0.20003"
"1.26021","100.10361","1.20139","371.82400","0.00000","1.26021","0.20003"
"1.26021","100.04752","1.20072","372.46400","0.00000","1.26021","0.20003"
"1.26021","99.98847","1.20001","373.10400","0.00000","1.26021","0.20003"
"1.26021","99.94222","1.19946","373.74400","0.00000","1.26021","0.20003"
"1.26021","99.89835","1.19893","374.38400","0.00000","1.26021","0.20003"
"1.26021","99.84663","1.19831","375.02400","0.00000","1.26021","0.20003"
"1.26021","99.79726","1.19772","375.66400","0.00000","1.26021","0.20003"
"1.26021","99.74982","1.19715","376.30400","0.00000","1.26021","0.20003"
"1.26021","99.70461","1.19661","376.94400","0.00000","1.26021","0.20003"
"1.26021","99.66021","1.19607","377.58400","0.00000","1.26021","0.20003"
"1.26021","99.60215","1.19538","378.22400","0.00000","1.26021","0.20003"
"1.26021","99.56255","1.19490","378.86400","0.00000","1.26021","0.20003"
"1.26021","99.51538","1.19433","379.50400","0.00000","1.26021","0.20003"
"1.26021","99.46209","1.19369","380.14400","0.00000","1.26021","0.20003"
"1.26021","99.42229","1.19322","380.78400","0.00000","1.26021","0.20003"
"1.26021","99.37345","1.19263","381.42400","0.00000","1.26021","0.20003"
"1.26021","99.32489","1.19205","382.06400","0.00000","1.26021","0.20003"
"1.26021","99.28147","1.19153","382.70400","0.00000","1.26021","0.20003"
"1.26021","99.23941","1.19102","383.34400","0.00000","1.26021","0.20003"
"1.26021","99.19509","1.19049","383.98400","0.00000","1.26021","0.20003"
"1.26021","99.16002","1.19007","384.62400","0.00000","1.26021","0.20003"
"1.26021","99.11837","1.18957","385.26400","0.00000","1.26021","0.20003"
"1.26021","99.06274","1.18890","385.90400","0.00000","1.26021","0.20003"
"1.26021","99.02958","1.18850","386.54400","0.00000","1.26021","0.20003"
"1.26021","98.97890","1.18790","387.18400","0.00000","1.26021","0.20003"
"1.26021","98.95322","1.18759","387.82400","0.00000","1.26021","0.20003"
"1.26021","98.89907","1.18694","388.46400","0.00000","1.26021","0.20003"
"1.26021","98.85382","1.18639","389.10400","0.00000","1.26021","0.20003"
"1.26021","98.80537","1.18581","389.74400","0.00000","1.26021","0.20003"
"1.26021","98.76559","1.18534","390.38400","0.00000","1.26021","0.20003"
"1.26021","98.72326","1.18483","391.02400","0.00000","1.26021","0.20003"
"1.26021","98.69257","1.18446","391.66400","0.00000","1.26021","0.20003"
"1.26021","98.64783","1.18392","392.30400","0.00000","1.26021","0.20003"
"1.26021","98.61050","1.18347","392.94400","0.00000","1.26021","0.20003"
"1.26021","98.57249","1.18302","393.58400","0.00000","1.26021","0.20003"
"1.26021","98.53319","1.18255","394.22400","0.00000","1.26021","0.20003"
"1.26021","98.48997","1.18203","394.86400","0.00000","1.26021","0.20003"
"1.26021","98.45615","1.18162","395.50400","0.00000","1.26021","0.20003"
"1.26021","98.41660","1.18115","396.14400","0.00000","1.26021","0.20003"
"1.26021","98.38255","1.18074","396.78400","0.00000","1.26021","0.20003"
"1.26021","98.34678","1.18031","397.42400","0.00000","1.26021","0.20003"
"1.26021","98.30079","1.17976","398.06400","0.00000","1.26021","0.20003"
"1.26021","98.26638","1.17934","398.70400","0.00000","1.26021","0.20003"
"1.26021","98.24178","1.17905","399.34400","0.00000","1.26021","0.20003"
"1.26021","98.19186","1.17845","399.98400","0.00000","1.26021","0.20003"
"1.26021","98.15972","1.17806","400.62400","0.00000","1.26021","0.20003"
"1.26021","98.12435","1.17764","401.26400","0.00000","1.26021","0.20003"
"1.26021","98.08978","1.17722","401.90400","0.00000","1.26021","0.20003"
"1.26021","98.05473","1.17680","402.54400","0.00000","1.26021","0.20003"
"1.26021","98.00912","1.17626","403.18400","0.00000","1.26021","0.20003"
"1.26021","97.98652","1.17599","403.82400","0.00000","1.26021","0.20003"
"1.26021","97.94584","1.17550","404.46400","0.00000","1.26021","0.20003"
"1.26021","97.91042","1.17507","405.10400","0.00000","1.26021","0.20003"
"1.26021","97.87148","1.17460","405.74400","0.00000","1.26021","0.20003"
"1.26021","97.84103","1.17424","406.38400","0.00000","1.26021","0.20003"
"1.26021","97.80807","1.17384","407.02400","0.00000","1.26021","0.20003"
"1.26021","97.78039","1.17351","407.66400","0.00000","1.26021","0.20003"
"1.26021","97.73246","1.17294","408.30400","0.00000","1.26021","0.20003"
"1.26021","97.70496","1.17261","408.94400","0.00000","1.26021","0.20003"
"1.26021","97.68983","1.17242","409.58400","0.00000","1.26021","0.20003"
"1.26021","97.64641","1.17190","410.22400","0.00000","1.26021","0.20003"
"1.26021","97.61638","1.17154","410.86400","0.00000","1.26021","0.20003"
"1.26021","97.57374","1.17103","411.50400","0.00000","1.26021","0.20003"
"1.26021","97.55666","1.17083","412.14400","0.00000","1.26021","0.20003"
"1.26021","97.50847","1.17025","412.78400","0.00000","1.26021","0.20003"
"1.26021","97.48434","1.16996","413.42400","0.00000","1.26021","0.20003"
"1.26021","97.45310","1.16958","414.06400","0.00000","1.26021","0.20003"
"1.26021","97.42045","1.16919","414.70400","0.00000","1.26021","0.20003"
"1.26021","97.35036","1.16835","415.34400","0.00000","1.26021","0.20003"
"1.26021","97.36799","1.16856","415.98400","0.00000","1.26021","0.20003"
"1.26021","97.32507","1.16805","416.62400","0.00000","1.26021","0.20003"
"1.26021","97.31640","1.16794","417.26400","0.00000","1.26021","0.20003"
"1.26021","97.26343","1.16731","417.90400","0.00000","1.26021","0.20003"
"1.26021","97.23777","1.16700","418.54400","0.00000","1.26021","0.20003"
"1.26021","97.20133","1.16656","419.18400","0.00000","1.26021","0.20003"
"1.26021","97.17359","1.16623","419.82400","0.00000","1.26021","0.20003"
"1.26021","97.14687","1.16591","420.46400","0.00000","1.26021","0.20003"
"1.26021","97.13368","1.16575","421.10400","0.00000","1.26021","0.20003"
"1.26021","97.06629","1.16494","421.74400","0.00000","1.26021","0.20003"
"1.26021","97.04002","1.16463","422.38400","0.00000","1.26021","0.20003"
"1.26021","97.01404","1.16431","423.02400","0.00000","1.26021","0.20003"
"1.26021","96.98106","1.16392","423.66400","0.00000","1.26021","0.20003"
"1.26021","96.95984","1.16366","424.30400","0.00000","1.26021","0.20003"
"1.26021","96.92564","1.16325","424.94400","0.00000","1.26021","0.20003"
"1.26021","96.90699","1.16303","425.58400","0.00000","1.26021","0.20003"
"1.26021","96.87320","1.16262","426.22400","0.00000","1.26021","0.20003"
"1.26021","96.86552","1.16253","426.86400","0.00000","1.26021","0.20003"
"1.26021","96.83054","1.16211","427.50400","0.00000","1.26021","0.20003"
"1.26021","96.78904","1.16161","428.14400","0.00000","1.26021","0.20003"
"1.26021","96.75578","1.16121","428.78400","0.00000","1.26021","0.20003"
"1.26021","96.74899","1.16113","429.42400","0.00000","1.26021","0.20003"
"1.26021","96.70498","1.16061","430.06400","0.00000","1.26021","0.20003"
"1.26021","96.68790","1.16040","430.70400","0.00000","1.26021","0.20003"
"1.26021","96.65982","1.16006","431.34400","0.00000","1.26021","0.20003"
"1.26021","96.60864","1.15945","431.98400","0.00000","1.26021","0.20003"
"1.26021","96.59817","1.15932","432.62400","0.00000","1.26021","0.20003"
"1.26021","96.56545","1.15893","433.26400","0.00000","1.26021","0.20003"
"1.26021","96.53129","1.15852","433.90400","0.00000","1.26021","0.20003"
"1.26021","96.51462","1.15832","434.54400","0.00000","1.26021","0.20003"
"1.26021","96.48319","1.15794","435.07400","0.00000","1.26021","0.20003"