File: Rubber Stress Relaxation Raw Data -Large  Samples-20210211/Specimen_RawData_2.csv
Specimen properties : Specimen label,"3"
Specimen properties : Anvil height,"6.37000",mm
Specimen properties : Diameter,"10.32000",mm
Test : Rate 1,"0.24000",mm/min
Test : Start of hold value,"20.00000",%
Test : Duration,"120.00000",s

Extension,Load,Compressive stress,Time,PIP count,Compressive extension,Compressive strain (Extension)
(mm),(N),(MPa),(s),,(mm),(mm/mm)
"0.00000","-0.02667","-0.00032","0.00000","0.00000","0.00000","0.00000"
"0.00083","-0.00712","-0.00009","0.64000","0.00000","0.00083","0.00013"
"0.00458","0.20499","0.00245","1.28000","0.00000","0.00458","0.00072"
"0.00750","0.31845","0.00381","1.92000","0.00000","0.00750","0.00118"
"0.01000","0.42166","0.00504","2.56000","0.00000","0.01000","0.00157"
"0.01250","0.51642","0.00617","3.20000","0.00000","0.01250","0.00196"
"0.01521","0.63832","0.00763","3.84000","0.00000","0.01521","0.00239"
"0.01771","0.74563","0.00891","4.48000","0.00000","0.01771","0.00278"
"0.02021","0.87045","0.01041","5.12000","0.00000","0.02021","0.00317"
"0.02271","0.98659","0.01179","5.76000","0.00000","0.02271","0.00356"
"0.02521","1.10864","0.01325","6.40000","0.00000","0.02521","0.00396"
"0.02792","1.24117","0.01484","7.04000","0.00000","0.02792","0.00438"
"0.03042","1.36899","0.01637","7.68000","0.00000","0.03042","0.00477"
"0.03313","1.52458","0.01823","8.32000","0.00000","0.03313","0.00520"
"0.03563","1.65577","0.01979","8.96000","0.00000","0.03563","0.00559"
"0.03833","1.80607","0.02159","9.60000","0.00000","0.03833","0.00602"
"0.04083","1.95679","0.02339","10.24000","0.00000","0.04083","0.00641"
"0.04333","2.09739","0.02507","10.88000","0.00000","0.04333","0.00680"
"0.04583","2.27988","0.02726","11.52000","0.00000","0.04583","0.00720"
"0.04833","2.44925","0.02928","12.16000","0.00000","0.04833","0.00759"
"0.05083","2.61744","0.03129","12.80000","0.00000","0.05083","0.00798"
"0.05354","2.81496","0.03365","13.44000","0.00000","0.05354","0.00841"
"0.05604","3.02169","0.03612","14.08000","0.00000","0.05604","0.00880"
"0.05854","3.21592","0.03845","14.72000","0.00000","0.05854","0.00919"
"0.06125","3.42263","0.04092","15.36000","0.00000","0.06125","0.00962"
"0.06375","3.62845","0.04338","16.00000","0.00000","0.06375","0.01001"
"0.06625","3.86366","0.04619","16.64000","0.00000","0.06625","0.01040"
"0.06896","4.09777","0.04899","17.28000","0.00000","0.06896","0.01083"
"0.07167","4.34534","0.05195","17.92000","0.00000","0.07167","0.01125"
"0.07417","4.57658","0.05471","18.56000","0.00000","0.07417","0.01164"
"0.07688","4.84639","0.05794","19.20000","0.00000","0.07688","0.01207"
"0.07937","5.09929","0.06096","19.84000","0.00000","0.07937","0.01246"
"0.08188","5.33627","0.06380","20.48000","0.00000","0.08188","0.01285"
"0.08438","5.63118","0.06732","21.12000","0.00000","0.08438","0.01325"
"0.08708","5.91712","0.07074","21.76000","0.00000","0.08708","0.01367"
"0.08958","6.18498","0.07394","22.40000","0.00000","0.08958","0.01406"
"0.09208","6.44116","0.07700","23.04000","0.00000","0.09208","0.01446"
"0.09458","6.72236","0.08037","23.68000","0.00000","0.09458","0.01485"
"0.09708","7.02137","0.08394","24.32000","0.00000","0.09708","0.01524"
"0.09979","7.29029","0.08716","24.96000","0.00000","0.09979","0.01567"
"0.10229","7.56142","0.09040","25.60000","0.00000","0.10229","0.01606"
"0.10458","7.82590","0.09356","26.24000","0.00000","0.10458","0.01642"
"0.10729","8.11350","0.09700","26.88000","0.00000","0.10729","0.01684"
"0.11000","8.38708","0.10027","27.52000","0.00000","0.11000","0.01727"
"0.11271","8.68485","0.10383","28.16000","0.00000","0.11271","0.01769"
"0.11521","8.92715","0.10672","28.80000","0.00000","0.11521","0.01809"
"0.11771","9.20325","0.11003","29.44000","0.00000","0.11771","0.01848"
"0.12042","9.46667","0.11317","30.08000","0.00000","0.12042","0.01890"
"0.12271","9.70696","0.11605","30.72000","0.00000","0.12271","0.01926"
"0.12542","9.99289","0.11947","31.36000","0.00000","0.12542","0.01969"
"0.12792","10.25974","0.12266","32.00000","0.00000","0.12792","0.02008"
"0.13042","10.52603","0.12584","32.64000","0.00000","0.13042","0.02047"
"0.13292","10.76749","0.12873","33.28000","0.00000","0.13292","0.02087"
"0.13542","11.02516","0.13181","33.92000","0.00000","0.13542","0.02126"
"0.13792","11.27412","0.13478","34.56000","0.00000","0.13792","0.02165"
"0.14063","11.52979","0.13784","35.20000","0.00000","0.14063","0.02208"
"0.14313","11.77427","0.14076","35.84000","0.00000","0.14313","0.02247"
"0.14563","12.03926","0.14393","36.48000","0.00000","0.14563","0.02286"
"0.14833","12.29832","0.14703","37.12000","0.00000","0.14833","0.02329"
"0.15104","12.57181","0.15030","37.76000","0.00000","0.15104","0.02371"
"0.15354","12.79017","0.15291","38.40000","0.00000","0.15354","0.02410"
"0.15625","13.07437","0.15630","39.04000","0.00000","0.15625","0.02453"
"0.15875","13.31100","0.15913","39.68000","0.00000","0.15875","0.02492"
"0.16125","13.54168","0.16189","40.32000","0.00000","0.16125","0.02531"
"0.16375","13.76556","0.16457","40.96000","0.00000","0.16375","0.02571"
"0.16625","14.02306","0.16765","41.60000","0.00000","0.16625","0.02610"
"0.16875","14.28556","0.17078","42.24000","0.00000","0.16875","0.02649"
"0.17125","14.46521","0.17293","42.88000","0.00000","0.17125","0.02688"
"0.17396","14.78749","0.17678","43.52000","0.00000","0.17396","0.02731"
"0.17646","15.02090","0.17958","44.16000","0.00000","0.17646","0.02770"
"0.17917","15.25518","0.18238","44.80000","0.00000","0.17917","0.02813"
"0.18167","15.48516","0.18513","45.44000","0.00000","0.18167","0.02852"
"0.18417","15.68657","0.18753","46.08000","0.00000","0.18417","0.02891"
"0.18667","15.92174","0.19034","46.72000","0.00000","0.18667","0.02930"
"0.18917","16.16217","0.19322","47.36000","0.00000","0.18917","0.02970"
"0.19188","16.43342","0.19646","48.00000","0.00000","0.19188","0.03012"
"0.19438","16.64397","0.19898","48.64000","0.00000","0.19438","0.03051"
"0.19708","16.87844","0.20178","49.28000","0.00000","0.19708","0.03094"
"0.19979","17.10420","0.20448","49.92000","0.00000","0.19979","0.03136"
"0.20229","17.31511","0.20700","50.56000","0.00000","0.20229","0.03176"
"0.20479","17.53863","0.20967","51.20000","0.00000","0.20479","0.03215"
"0.20729","17.76558","0.21239","51.84000","0.00000","0.20729","0.03254"
"0.20979","17.98088","0.21496","52.48000","0.00000","0.20979","0.03293"
"0.21229","18.19089","0.21747","53.12000","0.00000","0.21229","0.03333"
"0.21479","18.43544","0.22040","53.76000","0.00000","0.21479","0.03372"
"0.21750","18.67352","0.22324","54.40000","0.00000","0.21750","0.03414"
"0.22000","18.88176","0.22573","55.04000","0.00000","0.22000","0.03454"
"0.22229","19.08052","0.22811","55.68000","0.00000","0.22229","0.03490"
"0.22500","19.32996","0.23109","56.32000","0.00000","0.22500","0.03532"
"0.22750","19.53124","0.23350","56.96000","0.00000","0.22750","0.03571"
"0.23021","19.79393","0.23664","57.60000","0.00000","0.23021","0.03614"
"0.23271","19.97902","0.23885","58.24000","0.00000","0.23271","0.03653"
"0.23542","20.23082","0.24186","58.88000","0.00000","0.23542","0.03696"
"0.23813","20.43721","0.24433","59.52000","0.00000","0.23813","0.03738"
"0.24063","20.64864","0.24686","60.16000","0.00000","0.24063","0.03777"
"0.24313","20.84436","0.24919","60.80000","0.00000","0.24312","0.03817"
"0.24563","21.05431","0.25170","61.44000","0.00000","0.24563","0.03856"
"0.24833","21.27132","0.25430","62.08000","0.00000","0.24833","0.03898"
"0.25063","21.43990","0.25631","62.72000","0.00000","0.25063","0.03934"
"0.25313","21.67588","0.25914","63.36000","0.00000","0.25313","0.03974"
"0.25583","21.90654","0.26189","64.00000","0.00000","0.25583","0.04016"
"0.25833","22.11992","0.26444","64.64000","0.00000","0.25833","0.04055"
"0.26083","22.31523","0.26678","65.28000","0.00000","0.26083","0.04095"
"0.26333","22.53894","0.26945","65.92000","0.00000","0.26333","0.04134"
"0.26604","22.74492","0.27192","66.56000","0.00000","0.26604","0.04176"
"0.26854","22.97735","0.27469","67.20000","0.00000","0.26854","0.04216"
"0.27125","23.19199","0.27726","67.84000","0.00000","0.27125","0.04258"
"0.27375","23.40184","0.27977","68.48000","0.00000","0.27375","0.04297"
"0.27646","23.61525","0.28232","69.12000","0.00000","0.27646","0.04340"
"0.27917","23.84446","0.28506","69.76000","0.00000","0.27917","0.04383"
"0.28167","24.03608","0.28735","70.40000","0.00000","0.28167","0.04422"
"0.28417","24.22571","0.28962","71.04000","0.00000","0.28417","0.04461"
"0.28667","24.44300","0.29222","71.68000","0.00000","0.28667","0.04500"
"0.28917","24.64686","0.29465","72.32000","0.00000","0.28917","0.04540"
"0.29167","24.83533","0.29691","72.96000","0.00000","0.29167","0.04579"
"0.29417","25.05230","0.29950","73.60000","0.00000","0.29417","0.04618"
"0.29667","25.27452","0.30216","74.24000","0.00000","0.29667","0.04657"
"0.29937","25.46907","0.30448","74.88000","0.00000","0.29937","0.04700"
"0.30187","25.66886","0.30687","75.52000","0.00000","0.30187","0.04739"
"0.30438","25.88130","0.30941","76.16000","0.00000","0.30438","0.04778"
"0.30688","26.08185","0.31181","76.80000","0.00000","0.30688","0.04818"
"0.30958","26.29912","0.31441","77.44000","0.00000","0.30958","0.04860"
"0.31208","26.46777","0.31642","78.08000","0.00000","0.31208","0.04899"
"0.31479","26.70975","0.31932","78.72000","0.00000","0.31479","0.04942"
"0.31750","26.93021","0.32195","79.36000","0.00000","0.31750","0.04984"
"0.32000","27.12186","0.32424","80.00000","0.00000","0.32000","0.05024"
"0.32250","27.29817","0.32635","80.64000","0.00000","0.32250","0.05063"
"0.32521","27.51222","0.32891","81.28000","0.00000","0.32521","0.05105"
"0.32771","27.70605","0.33123","81.92000","0.00000","0.32771","0.05145"
"0.33000","27.86021","0.33307","82.56000","0.00000","0.33000","0.05181"
"0.33250","28.09056","0.33582","83.20000","0.00000","0.33250","0.05220"
"0.33521","28.32498","0.33863","83.84000","0.00000","0.33521","0.05262"
"0.33771","28.53161","0.34110","84.48000","0.00000","0.33771","0.05302"
"0.34021","28.71872","0.34333","85.12000","0.00000","0.34021","0.05341"
"0.34271","28.96537","0.34628","85.76000","0.00000","0.34271","0.05380"
"0.34542","29.16310","0.34865","86.40000","0.00000","0.34542","0.05423"
"0.34792","29.37398","0.35117","87.04000","0.00000","0.34792","0.05462"
"0.35042","29.58234","0.35366","87.68000","0.00000","0.35042","0.05501"
"0.35313","29.79853","0.35624","88.32000","0.00000","0.35313","0.05544"
"0.35583","30.02082","0.35890","88.96000","0.00000","0.35583","0.05586"
"0.35854","30.22877","0.36139","89.60000","0.00000","0.35854","0.05629"
"0.36104","30.40611","0.36351","90.24000","0.00000","0.36104","0.05668"
"0.36354","30.59554","0.36577","90.88000","0.00000","0.36354","0.05707"
"0.36604","30.80341","0.36826","91.52000","0.00000","0.36604","0.05746"
"0.36875","30.98063","0.37037","92.16000","0.00000","0.36875","0.05789"
"0.37104","31.14213","0.37231","92.80000","0.00000","0.37104","0.05825"
"0.37354","31.35620","0.37486","93.44000","0.00000","0.37354","0.05864"
"0.37604","31.55969","0.37730","94.08000","0.00000","0.37604","0.05903"
"0.37875","31.76317","0.37973","94.72000","0.00000","0.37875","0.05946"
"0.38125","31.95829","0.38206","95.36000","0.00000","0.38125","0.05985"
"0.38375","32.17802","0.38469","96.00000","0.00000","0.38375","0.06024"
"0.38625","32.38873","0.38721","96.64000","0.00000","0.38625","0.06064"
"0.38896","32.58031","0.38950","97.28000","0.00000","0.38896","0.06106"
"0.39146","32.78991","0.39200","97.92000","0.00000","0.39146","0.06145"
"0.39396","32.99360","0.39444","98.56000","0.00000","0.39396","0.06185"
"0.39667","33.19890","0.39689","99.20000","0.00000","0.39667","0.06227"
"0.39938","33.40303","0.39933","99.84000","0.00000","0.39937","0.06270"
"0.40188","33.59853","0.40167","100.48000","0.00000","0.40188","0.06309"
"0.40458","33.80096","0.40409","101.12000","0.00000","0.40458","0.06351"
"0.40708","33.98445","0.40629","101.76000","0.00000","0.40708","0.06391"
"0.40958","34.14694","0.40823","102.40000","0.00000","0.40958","0.06430"
"0.41188","34.33745","0.41051","103.04000","0.00000","0.41188","0.06466"
"0.41458","34.55240","0.41308","103.68000","0.00000","0.41458","0.06508"
"0.41708","34.77373","0.41572","104.32000","0.00000","0.41708","0.06548"
"0.41958","34.95181","0.41785","104.96000","0.00000","0.41958","0.06587"
"0.42208","35.18222","0.42060","105.60000","0.00000","0.42208","0.06626"
"0.42458","35.38927","0.42308","106.24000","0.00000","0.42458","0.06665"
"0.42729","35.61382","0.42576","106.88000","0.00000","0.42729","0.06708"
"0.42979","35.78373","0.42780","107.52000","0.00000","0.42979","0.06747"
"0.43250","36.03745","0.43083","108.16000","0.00000","0.43250","0.06790"
"0.43500","36.24139","0.43327","108.80000","0.00000","0.43500","0.06829"
"0.43771","36.47819","0.43610","109.44000","0.00000","0.43771","0.06871"
"0.44021","36.67199","0.43841","110.08000","0.00000","0.44021","0.06911"
"0.44292","36.86226","0.44069","110.72000","0.00000","0.44292","0.06953"
"0.44542","37.07427","0.44322","111.36000","0.00000","0.44542","0.06992"
"0.44792","37.24151","0.44522","112.00000","0.00000","0.44792","0.07032"
"0.45042","37.40731","0.44721","112.64000","0.00000","0.45042","0.07071"
"0.45292","37.57528","0.44921","113.28000","0.00000","0.45292","0.07110"
"0.45542","37.77945","0.45165","113.92000","0.00000","0.45542","0.07149"
"0.45792","37.98361","0.45410","114.56000","0.00000","0.45792","0.07189"
"0.46042","38.16925","0.45631","115.20000","0.00000","0.46042","0.07228"
"0.46312","38.39307","0.45899","115.84000","0.00000","0.46313","0.07270"
"0.46563","38.60545","0.46153","116.48000","0.00000","0.46563","0.07310"
"0.46833","38.80867","0.46396","117.12000","0.00000","0.46833","0.07352"
"0.47083","39.05017","0.46685","117.76000","0.00000","0.47083","0.07391"
"0.47354","39.22972","0.46899","118.40000","0.00000","0.47354","0.07434"
"0.47604","39.45203","0.47165","119.04000","0.00000","0.47604","0.07473"
"0.47875","39.66289","0.47417","119.68000","0.00000","0.47875","0.07516"
"0.48125","39.85199","0.47643","120.32000","0.00000","0.48125","0.07555"
"0.48396","40.06945","0.47903","120.96000","0.00000","0.48396","0.07597"
"0.48646","40.26657","0.48139","121.60000","0.00000","0.48646","0.07637"
"0.48896","40.44363","0.48350","122.24000","0.00000","0.48896","0.07676"
"0.49146","40.67118","0.48623","122.88000","0.00000","0.49146","0.07715"
"0.49396","40.85043","0.48837","123.52000","0.00000","0.49396","0.07754"
"0.49646","41.03028","0.49052","124.16000","0.00000","0.49646","0.07794"
"0.49896","41.19133","0.49244","124.80000","0.00000","0.49896","0.07833"
"0.50146","41.43335","0.49534","125.44000","0.00000","0.50146","0.07872"
"0.50396","41.62930","0.49768","126.08000","0.00000","0.50396","0.07911"
"0.50667","41.83935","0.50019","126.72000","0.00000","0.50667","0.07954"
"0.50917","41.99291","0.50203","127.36000","0.00000","0.50917","0.07993"
"0.51188","42.26073","0.50523","128.00000","0.00000","0.51188","0.08036"
"0.51458","42.48203","0.50787","128.64000","0.00000","0.51458","0.08078"
"0.51708","42.67432","0.51017","129.28000","0.00000","0.51708","0.08117"
"0.51958","42.86633","0.51247","129.92000","0.00000","0.51958","0.08157"
"0.52229","43.05531","0.51473","130.56000","0.00000","0.52229","0.08199"
"0.52479","43.26162","0.51719","131.20000","0.00000","0.52479","0.08238"
"0.52729","43.43838","0.51931","131.84000","0.00000","0.52729","0.08278"
"0.52979","43.61668","0.52144","132.48000","0.00000","0.52979","0.08317"
"0.53250","43.82470","0.52393","133.12000","0.00000","0.53250","0.08359"
"0.53500","44.01602","0.52621","133.76000","0.00000","0.53500","0.08399"
"0.53750","44.20742","0.52850","134.40000","0.00000","0.53750","0.08438"
"0.53979","44.35441","0.53026","135.04000","0.00000","0.53979","0.08474"
"0.54250","44.56598","0.53279","135.68000","0.00000","0.54250","0.08516"
"0.54500","44.76634","0.53518","136.32000","0.00000","0.54500","0.08556"
"0.54771","44.99276","0.53789","136.96000","0.00000","0.54771","0.08598"
"0.55021","45.17389","0.54006","137.60000","0.00000","0.55021","0.08637"
"0.55271","45.40171","0.54278","138.24000","0.00000","0.55271","0.08677"
"0.55542","45.62840","0.54549","138.88000","0.00000","0.55542","0.08719"
"0.55813","45.82439","0.54783","139.52000","0.00000","0.55813","0.08762"
"0.56063","46.00225","0.54996","140.16000","0.00000","0.56063","0.08801"
"0.56313","46.22552","0.55263","140.80000","0.00000","0.56313","0.08840"
"0.56583","46.41511","0.55489","141.44000","0.00000","0.56583","0.08883"
"0.56833","46.61232","0.55725","142.08000","0.00000","0.56833","0.08922"
"0.57083","46.81463","0.55967","142.72000","0.00000","0.57083","0.08961"
"0.57354","47.01530","0.56207","143.36000","0.00000","0.57354","0.09004"
"0.57604","47.20151","0.56430","144.00000","0.00000","0.57604","0.09043"
"0.57854","47.40891","0.56678","144.64000","0.00000","0.57854","0.09082"
"0.58083","47.59552","0.56901","145.28000","0.00000","0.58083","0.09118"
"0.58354","47.82718","0.57178","145.92000","0.00000","0.58354","0.09161"
"0.58604","48.05058","0.57445","146.56000","0.00000","0.58604","0.09200"
"0.58854","48.22514","0.57653","147.20000","0.00000","0.58854","0.09239"
"0.59125","48.52741","0.58015","147.84000","0.00000","0.59125","0.09282"
"0.59375","48.73063","0.58258","148.48000","0.00000","0.59375","0.09321"
"0.59646","48.96168","0.58534","149.12000","0.00000","0.59646","0.09364"
"0.59896","49.13553","0.58742","149.76000","0.00000","0.59896","0.09403"
"0.60167","49.36564","0.59017","150.40000","0.00000","0.60167","0.09445"
"0.60417","49.57180","0.59263","151.04000","0.00000","0.60417","0.09485"
"0.60667","49.76959","0.59500","151.68000","0.00000","0.60667","0.09524"
"0.60917","49.95222","0.59718","152.32000","0.00000","0.60917","0.09563"
"0.61188","50.17034","0.59979","152.96000","0.00000","0.61188","0.09606"
"0.61438","50.37572","0.60224","153.60000","0.00000","0.61438","0.09645"
"0.61687","50.57506","0.60463","154.24000","0.00000","0.61687","0.09684"
"0.61917","50.71927","0.60635","154.88000","0.00000","0.61917","0.09720"
"0.62188","50.94165","0.60901","155.52000","0.00000","0.62188","0.09763"
"0.62437","51.17336","0.61178","156.16000","0.00000","0.62437","0.09802"
"0.62688","51.40779","0.61458","156.80000","0.00000","0.62688","0.09841"
"0.62958","51.62475","0.61718","157.44000","0.00000","0.62958","0.09884"
"0.63208","51.80558","0.61934","158.08000","0.00000","0.63208","0.09923"
"0.63458","52.04732","0.62223","158.72000","0.00000","0.63458","0.09962"
"0.63729","52.23917","0.62452","159.36000","0.00000","0.63729","0.10005"
"0.63979","52.42319","0.62672","160.00000","0.00000","0.63979","0.10044"
"0.64229","52.64321","0.62935","160.64000","0.00000","0.64229","0.10083"
"0.64500","52.82915","0.63157","161.28000","0.00000","0.64500","0.10126"
"0.64750","52.99474","0.63355","161.92000","0.00000","0.64750","0.10165"
"0.65000","53.20681","0.63609","162.56000","0.00000","0.65000","0.10204"
"0.65271","53.45069","0.63900","163.20000","0.00000","0.65271","0.10247"
"0.65542","53.61559","0.64098","163.84000","0.00000","0.65542","0.10289"
"0.65792","53.81853","0.64340","164.48000","0.00000","0.65792","0.10328"
"0.66042","53.98566","0.64540","165.12000","0.00000","0.66042","0.10368"
"0.66271","54.19456","0.64790","165.76000","0.00000","0.66271","0.10404"
"0.66542","54.43723","0.65080","166.40000","0.00000","0.66542","0.10446"
"0.66771","54.63050","0.65311","167.04000","0.00000","0.66771","0.10482"
"0.67063","54.93131","0.65671","167.68000","0.00000","0.67063","0.10528"
"0.67313","55.14695","0.65928","168.32000","0.00000","0.67313","0.10567"
"0.67583","55.41702","0.66251","168.96000","0.00000","0.67583","0.10610"
"0.67833","55.60635","0.66478","169.60000","0.00000","0.67833","0.10649"
"0.68104","55.85373","0.66773","170.24000","0.00000","0.68104","0.10691"
"0.68354","56.06862","0.67030","170.88000","0.00000","0.68354","0.10731"
"0.68604","56.27052","0.67272","171.52000","0.00000","0.68604","0.10770"
"0.68854","56.43373","0.67467","172.16000","0.00000","0.68854","0.10809"
"0.69104","56.68790","0.67771","172.80000","0.00000","0.69104","0.10848"
"0.69375","56.90262","0.68027","173.44000","0.00000","0.69375","0.10891"
"0.69625","57.10475","0.68269","174.08000","0.00000","0.69625","0.10930"
"0.69875","57.27534","0.68473","174.72000","0.00000","0.69875","0.10969"
"0.70125","57.46818","0.68703","175.36000","0.00000","0.70125","0.11009"
"0.70375","57.66375","0.68937","176.00000","0.00000","0.70375","0.11048"
"0.70625","57.89746","0.69217","176.64000","0.00000","0.70625","0.11087"
"0.70896","58.15692","0.69527","177.28000","0.00000","0.70896","0.11130"
"0.71167","58.39553","0.69812","177.92000","0.00000","0.71167","0.11172"
"0.71417","58.61583","0.70075","178.56000","0.00000","0.71417","0.11211"
"0.71667","58.84703","0.70352","179.20000","0.00000","0.71667","0.11251"
"0.71938","59.06554","0.70613","179.84000","0.00000","0.71938","0.11293"
"0.72188","59.28934","0.70881","180.48000","0.00000","0.72188","0.11332"
"0.72438","59.48713","0.71117","181.12000","0.00000","0.72438","0.11372"
"0.72688","59.68125","0.71349","181.76000","0.00000","0.72688","0.11411"
"0.72938","59.88786","0.71596","182.40000","0.00000","0.72938","0.11450"
"0.73208","60.11417","0.71867","183.04000","0.00000","0.73208","0.11493"
"0.73479","60.34661","0.72145","183.68000","0.00000","0.73479","0.11535"
"0.73729","60.52772","0.72361","184.32000","0.00000","0.73729","0.11574"
"0.73979","60.72596","0.72598","184.96000","0.00000","0.73979","0.11614"
"0.74229","60.95735","0.72875","185.60000","0.00000","0.74229","0.11653"
"0.74479","61.17939","0.73140","186.24000","0.00000","0.74479","0.11692"
"0.74729","61.34417","0.73337","186.88000","0.00000","0.74729","0.11731"
"0.74979","61.56352","0.73599","187.52000","0.00000","0.74979","0.11771"
"0.75250","61.78128","0.73860","188.16000","0.00000","0.75250","0.11813"
"0.75500","62.02391","0.74150","188.80000","0.00000","0.75500","0.11852"
"0.75750","62.23497","0.74402","189.44000","0.00000","0.75750","0.11892"
"0.76000","62.41464","0.74617","190.08000","0.00000","0.76000","0.11931"
"0.76271","62.60543","0.74845","190.72000","0.00000","0.76271","0.11973"
"0.76542","62.84653","0.75133","191.36000","0.00000","0.76542","0.12016"
"0.76771","63.02363","0.75345","192.00000","0.00000","0.76771","0.12052"
"0.77042","63.28950","0.75663","192.64000","0.00000","0.77042","0.12094"
"0.77313","63.52522","0.75945","193.28000","0.00000","0.77313","0.12137"
"0.77563","63.70691","0.76162","193.92000","0.00000","0.77563","0.12176"
"0.77833","63.90886","0.76403","194.56000","0.00000","0.77833","0.12219"
"0.78083","64.11362","0.76648","195.20000","0.00000","0.78083","0.12258"
"0.78333","64.33659","0.76915","195.84000","0.00000","0.78333","0.12297"
"0.78583","64.55977","0.77181","196.48000","0.00000","0.78583","0.12336"
"0.78813","64.69944","0.77348","197.12000","0.00000","0.78813","0.12372"
"0.79083","64.99583","0.77703","197.76000","0.00000","0.79083","0.12415"
"0.79333","65.24470","0.78000","198.40000","0.00000","0.79333","0.12454"
"0.79583","65.43970","0.78233","199.04000","0.00000","0.79583","0.12493"
"0.79854","65.70789","0.78554","199.68000","0.00000","0.79854","0.12536"
"0.80104","65.93473","0.78825","200.32000","0.00000","0.80104","0.12575"
"0.80375","66.17860","0.79117","200.96000","0.00000","0.80375","0.12618"
"0.80625","66.41035","0.79394","201.60000","0.00000","0.80625","0.12657"
"0.80875","66.64211","0.79671","202.24000","0.00000","0.80875","0.12696"
"0.81146","66.86934","0.79943","202.88000","0.00000","0.81146","0.12739"
"0.81417","67.11118","0.80232","203.52000","0.00000","0.81417","0.12781"
"0.81667","67.30698","0.80466","204.16000","0.00000","0.81667","0.12821"
"0.81917","67.49392","0.80689","204.80000","0.00000","0.81917","0.12860"
"0.82167","67.70919","0.80947","205.44000","0.00000","0.82167","0.12899"
"0.82417","67.96127","0.81248","206.08000","0.00000","0.82417","0.12938"
"0.82688","68.17760","0.81507","206.72000","0.00000","0.82688","0.12981"
"0.82938","68.36065","0.81725","207.36000","0.00000","0.82938","0.13020"
"0.83188","68.57561","0.81982","208.00000","0.00000","0.83188","0.13059"
"0.83438","68.76659","0.82211","208.64000","0.00000","0.83438","0.13099"
"0.83688","68.95224","0.82433","209.28000","0.00000","0.83688","0.13138"
"0.83958","69.21532","0.82747","209.92000","0.00000","0.83958","0.13180"
"0.84208","69.46484","0.83045","210.56000","0.00000","0.84208","0.13220"
"0.84458","69.69408","0.83319","211.20000","0.00000","0.84458","0.13259"
"0.84708","69.87694","0.83538","211.84000","0.00000","0.84708","0.13298"
"0.84958","70.12397","0.83833","212.48000","0.00000","0.84958","0.13337"
"0.85229","70.35660","0.84112","213.12000","0.00000","0.85229","0.13380"
"0.85479","70.57549","0.84373","213.76000","0.00000","0.85479","0.13419"
"0.85729","70.75955","0.84593","214.40000","0.00000","0.85729","0.13458"
"0.85979","70.98391","0.84861","215.04000","0.00000","0.85979","0.13498"
"0.86250","71.21793","0.85141","215.68000","0.00000","0.86250","0.13540"
"0.86521","71.44953","0.85418","216.32000","0.00000","0.86521","0.13583"
"0.86771","71.62674","0.85630","216.96000","0.00000","0.86771","0.13622"
"0.87042","71.91100","0.85970","217.60000","0.00000","0.87042","0.13664"
"0.87292","72.12717","0.86228","218.24000","0.00000","0.87292","0.13704"
"0.87542","72.31664","0.86455","218.88000","0.00000","0.87542","0.13743"
"0.87792","72.51939","0.86697","219.52000","0.00000","0.87792","0.13782"
"0.88042","72.76132","0.86986","220.16000","0.00000","0.88042","0.13821"
"0.88292","72.97886","0.87246","220.80000","0.00000","0.88292","0.13861"
"0.88542","73.15820","0.87461","221.44000","0.00000","0.88542","0.13900"
"0.88813","73.39867","0.87748","222.08000","0.00000","0.88813","0.13942"
"0.89062","73.63563","0.88032","222.72000","0.00000","0.89062","0.13982"
"0.89333","73.87284","0.88315","223.36000","0.00000","0.89333","0.14024"
"0.89583","74.10188","0.88589","224.00000","0.00000","0.89583","0.14063"
"0.89833","74.26256","0.88781","224.64000","0.00000","0.89833","0.14103"
"0.90083","74.53505","0.89107","225.28000","0.00000","0.90083","0.14142"
"0.90354","74.77851","0.89398","225.92000","0.00000","0.90354","0.14184"
"0.90625","75.05819","0.89732","226.56000","0.00000","0.90625","0.14227"
"0.90875","75.24785","0.89959","227.20000","0.00000","0.90875","0.14266"
"0.91146","75.48116","0.90238","227.84000","0.00000","0.91146","0.14309"
"0.91396","75.72083","0.90524","228.48000","0.00000","0.91396","0.14348"
"0.91625","75.91370","0.90755","229.12000","0.00000","0.91625","0.14384"
"0.91896","76.16186","0.91052","229.76000","0.00000","0.91896","0.14426"
"0.92146","76.44658","0.91392","230.40000","0.00000","0.92146","0.14466"
"0.92417","76.66709","0.91656","231.04000","0.00000","0.92417","0.14508"
"0.92646","76.87489","0.91904","231.68000","0.00000","0.92646","0.14544"
"0.92917","77.11813","0.92195","232.32000","0.00000","0.92917","0.14587"
"0.93167","77.35802","0.92482","232.96000","0.00000","0.93167","0.14626"
"0.93417","77.59273","0.92762","233.60000","0.00000","0.93417","0.14665"
"0.93667","77.75616","0.92958","234.24000","0.00000","0.93667","0.14704"
"0.93938","78.01850","0.93271","234.88000","0.00000","0.93938","0.14747"
"0.94188","78.25613","0.93555","235.52000","0.00000","0.94188","0.14786"
"0.94458","78.53163","0.93885","236.16000","0.00000","0.94458","0.14829"
"0.94708","78.72150","0.94112","236.80000","0.00000","0.94708","0.14868"
"0.94979","79.01044","0.94457","237.44000","0.00000","0.94979","0.14910"
"0.95229","79.23863","0.94730","238.08000","0.00000","0.95229","0.14950"
"0.95479","79.43472","0.94964","238.72000","0.00000","0.95479","0.14989"
"0.95729","79.66843","0.95244","239.36000","0.00000","0.95729","0.15028"
"0.95979","79.90433","0.95526","240.00000","0.00000","0.95979","0.15067"
"0.96229","80.15524","0.95826","240.64000","0.00000","0.96229","0.15107"
"0.96479","80.39608","0.96114","241.28000","0.00000","0.96479","0.15146"
"0.96750","80.65426","0.96422","241.92000","0.00000","0.96750","0.15188"
"0.97000","80.86493","0.96674","242.56000","0.00000","0.97000","0.15228"
"0.97250","81.12066","0.96980","243.20000","0.00000","0.97250","0.15267"
"0.97500","81.34731","0.97251","243.84000","0.00000","0.97500","0.15306"
"0.97771","81.57834","0.97527","244.48000","0.00000","0.97771","0.15349"
"0.98042","81.85804","0.97862","245.12000","0.00000","0.98042","0.15391"
"0.98313","82.11805","0.98172","245.76000","0.00000","0.98313","0.15434"
"0.98563","82.35086","0.98451","246.40000","0.00000","0.98563","0.15473"
"0.98813","82.54669","0.98685","247.04000","0.00000","0.98813","0.15512"
"0.99063","82.77897","0.98963","247.68000","0.00000","0.99063","0.15551"
"0.99333","83.00104","0.99228","248.32000","0.00000","0.99333","0.15594"
"0.99583","83.19970","0.99466","248.96000","0.00000","0.99583","0.15633"
"0.99833","83.47401","0.99793","249.60000","0.00000","0.99833","0.15672"
"1.00104","83.71704","1.00084","250.24000","0.00000","1.00104","0.15715"
"1.00333","83.91555","1.00321","250.88000","0.00000","1.00333","0.15751"
"1.00583","84.11228","1.00556","251.52000","0.00000","1.00583","0.15790"
"1.00854","84.36938","1.00864","252.16000","0.00000","1.00854","0.15833"
"1.01104","84.59259","1.01131","252.80000","0.00000","1.01104","0.15872"
"1.01354","84.80946","1.01390","253.44000","0.00000","1.01354","0.15911"
"1.01604","84.97224","1.01585","254.08000","0.00000","1.01604","0.15950"
"1.01854","85.25076","1.01918","254.72000","0.00000","1.01854","0.15990"
"1.02125","85.45293","1.02159","255.36000","0.00000","1.02125","0.16032"
"1.02396","85.73805","1.02500","256.00000","0.00000","1.02396","0.16075"
"1.02646","85.93122","1.02731","256.64000","0.00000","1.02646","0.16114"
"1.02896","86.18113","1.03030","257.28000","0.00000","1.02896","0.16153"
"1.03167","86.42475","1.03321","257.92000","0.00000","1.03167","0.16196"
"1.03417","86.63052","1.03567","258.56000","0.00000","1.03417","0.16235"
"1.03688","86.83437","1.03811","259.20000","0.00000","1.03688","0.16277"
"1.03938","87.02717","1.04041","259.84000","0.00000","1.03938","0.16317"
"1.04188","87.24757","1.04305","260.48000","0.00000","1.04188","0.16356"
"1.04417","87.42343","1.04515","261.12000","0.00000","1.04417","0.16392"
"1.04688","87.73154","1.04883","261.76000","0.00000","1.04688","0.16434"
"1.04938","88.01691","1.05224","262.40000","0.00000","1.04938","0.16474"
"1.05188","88.26341","1.05519","263.04000","0.00000","1.05188","0.16513"
"1.05438","88.50601","1.05809","263.68000","0.00000","1.05438","0.16552"
"1.05708","88.75992","1.06113","264.32000","0.00000","1.05708","0.16595"
"1.05958","89.06030","1.06472","264.96000","0.00000","1.05958","0.16634"
"1.06229","89.31898","1.06781","265.60000","0.00000","1.06229","0.16676"
"1.06479","89.62477","1.07147","266.24000","0.00000","1.06479","0.16716"
"1.06729","89.81076","1.07369","266.88000","0.00000","1.06729","0.16755"
"1.07000","90.09496","1.07709","267.52000","0.00000","1.07000","0.16797"
"1.07271","90.35945","1.08025","268.16000","0.00000","1.07271","0.16840"
"1.07521","90.56877","1.08275","268.80000","0.00000","1.07521","0.16879"
"1.07771","90.78847","1.08538","269.44000","0.00000","1.07771","0.16919"
"1.08021","91.02512","1.08821","270.08000","0.00000","1.08021","0.16958"
"1.08271","91.26075","1.09103","270.72000","0.00000","1.08271","0.16997"
"1.08521","91.51491","1.09406","271.36000","0.00000","1.08521","0.17036"
"1.08771","91.77418","1.09716","272.00000","0.00000","1.08771","0.17075"
"1.09042","92.04657","1.10042","272.64000","0.00000","1.09042","0.17118"
"1.09292","92.26504","1.10303","273.28000","0.00000","1.09292","0.17157"
"1.09542","92.49084","1.10573","273.92000","0.00000","1.09542","0.17196"
"1.09792","92.77494","1.10913","274.56000","0.00000","1.09792","0.17236"
"1.10063","92.99806","1.11179","275.20000","0.00000","1.10063","0.17278"
"1.10333","93.27778","1.11514","275.84000","0.00000","1.10333","0.17321"
"1.10563","93.42663","1.11692","276.48000","0.00000","1.10563","0.17357"
"1.10833","93.69749","1.12016","277.12000","0.00000","1.10833","0.17399"
"1.11104","93.92764","1.12291","277.76000","0.00000","1.11104","0.17442"
"1.11354","94.16058","1.12569","278.40000","0.00000","1.11354","0.17481"
"1.11625","94.40342","1.12860","279.04000","0.00000","1.11625","0.17524"
"1.11875","94.61696","1.13115","279.68000","0.00000","1.11875","0.17563"
"1.12125","94.88556","1.13436","280.32000","0.00000","1.12125","0.17602"
"1.12354","95.07052","1.13657","280.96000","0.00000","1.12354","0.17638"
"1.12625","95.38221","1.14030","281.60000","0.00000","1.12625","0.17681"
"1.12875","95.71014","1.14422","282.24000","0.00000","1.12875","0.17720"
"1.13146","95.96872","1.14731","282.88000","0.00000","1.13146","0.17762"
"1.13396","96.18394","1.14988","283.52000","0.00000","1.13396","0.17802"
"1.13646","96.43727","1.15291","284.16000","0.00000","1.13646","0.17841"
"1.13896","96.71587","1.15624","284.80000","0.00000","1.13896","0.17880"
"1.14146","96.98473","1.15946","285.44000","0.00000","1.14146","0.17919"
"1.14417","97.27888","1.16297","286.08000","0.00000","1.14417","0.17962"
"1.14667","97.51664","1.16581","286.72000","0.00000","1.14667","0.18001"
"1.14938","97.81003","1.16932","287.36000","0.00000","1.14938","0.18044"
"1.15208","98.06781","1.17240","288.00000","0.00000","1.15208","0.18086"
"1.15458","98.27381","1.17487","288.64000","0.00000","1.15458","0.18125"
"1.15708","98.54618","1.17812","289.28000","0.00000","1.15708","0.18165"
"1.15979","98.78777","1.18101","289.92000","0.00000","1.15979","0.18207"
"1.16229","99.01815","1.18377","290.56000","0.00000","1.16229","0.18246"
"1.16458","99.17803","1.18568","291.20000","0.00000","1.16458","0.18282"
"1.16708","99.48313","1.18932","291.84000","0.00000","1.16708","0.18322"
"1.16979","99.74516","1.19246","292.48000","0.00000","1.16979","0.18364"
"1.17229","99.97508","1.19521","293.12000","0.00000","1.17229","0.18403"
"1.17479","100.21017","1.19802","293.76000","0.00000","1.17479","0.18443"
"1.17729","100.44555","1.20083","294.40000","0.00000","1.17729","0.18482"
"1.18000","100.70030","1.20388","295.04000","0.00000","1.18000","0.18524"
"1.18250","100.95494","1.20692","295.68000","0.00000","1.18250","0.18564"
"1.18500","101.16401","1.20942","296.32000","0.00000","1.18500","0.18603"
"1.18771","101.46718","1.21304","296.96000","0.00000","1.18771","0.18645"
"1.19042","101.71455","1.21600","297.60000","0.00000","1.19042","0.18688"
"1.19292","101.96268","1.21897","298.24000","0.00000","1.19292","0.18727"
"1.19542","102.17240","1.22147","298.88000","0.00000","1.19542","0.18766"
"1.19813","102.41975","1.22443","299.52000","0.00000","1.19813","0.18809"
"1.20063","102.67407","1.22747","300.16000","0.00000","1.20063","0.18848"
"1.20313","102.89154","1.23007","300.80000","0.00000","1.20313","0.18887"
"1.20563","103.18063","1.23353","301.44000","0.00000","1.20563","0.18927"
"1.20812","103.46287","1.23690","302.08000","0.00000","1.20812","0.18966"
"1.21083","103.74571","1.24028","302.72000","0.00000","1.21083","0.19008"
"1.21313","103.98136","1.24310","303.36000","0.00000","1.21313","0.19044"
"1.21583","104.25814","1.24641","304.00000","0.00000","1.21583","0.19087"
"1.21833","104.52444","1.24959","304.64000","0.00000","1.21833","0.19126"
"1.22083","104.81474","1.25306","305.28000","0.00000","1.22083","0.19165"
"1.22354","105.10397","1.25652","305.92000","0.00000","1.22354","0.19208"
"1.22604","105.37328","1.25974","306.56000","0.00000","1.22604","0.19247"
"1.22875","105.67250","1.26332","307.20000","0.00000","1.22875","0.19290"
"1.23125","105.96248","1.26678","307.84000","0.00000","1.23125","0.19329"
"1.23396","106.21127","1.26976","308.48000","0.00000","1.23396","0.19371"
"1.23646","106.45341","1.27265","309.12000","0.00000","1.23646","0.19411"
"1.23896","106.72069","1.27585","309.76000","0.00000","1.23896","0.19450"
"1.24167","106.96262","1.27874","310.40000","0.00000","1.24167","0.19492"
"1.24417","107.20689","1.28166","311.04000","0.00000","1.24417","0.19532"
"1.24667","107.46559","1.28475","311.68000","0.00000","1.24667","0.19571"
"1.24917","107.72633","1.28787","312.32000","0.00000","1.24917","0.19610"
"1.25146","107.97864","1.29089","312.96000","0.00000","1.25146","0.19646"
"1.25417","108.26411","1.29430","313.60000","0.00000","1.25417","0.19689"
"1.25667","108.56123","1.29785","314.24000","0.00000","1.25667","0.19728"
"1.25937","108.86672","1.30151","314.88000","0.00000","1.25937","0.19770"
"1.26188","109.17381","1.30518","315.52000","0.00000","1.26188","0.19810"
"1.26438","109.41445","1.30805","316.16000","0.00000","1.26438","0.19849"
"1.26708","109.72209","1.31173","316.80000","0.00000","1.26708","0.19891"
"1.26958","110.03514","1.31547","317.44000","0.00000","1.26958","0.19931"
"1.27229","110.34389","1.31916","318.08000","0.00000","1.27229","0.19973"
"1.27437","110.33251","1.31903","318.70800","0.00000","1.27437","0.20006"
"1.27437","109.39361","1.30780","319.34800","0.00000","1.27437","0.20006"
"1.27437","108.72581","1.29982","319.98800","0.00000","1.27437","0.20006"
"1.27437","108.18401","1.29334","320.62800","0.00000","1.27437","0.20006"
"1.27437","107.71301","1.28771","321.26800","0.00000","1.27437","0.20006"
"1.27437","107.29239","1.28268","321.90800","0.00000","1.27437","0.20006"
"1.27396","106.83167","1.27718","322.54800","0.00000","1.27396","0.19999"
"1.27396","106.51511","1.27339","323.18800","0.00000","1.27396","0.19999"
"1.27396","106.21077","1.26975","323.82800","0.00000","1.27396","0.19999"
"1.27396","105.92332","1.26632","324.46800","0.00000","1.27396","0.19999"
"1.27396","105.66046","1.26317","325.10800","0.00000","1.27396","0.19999"
"1.27396","105.39985","1.26006","325.74800","0.00000","1.27396","0.19999"
"1.27396","105.15242","1.25710","326.38800","0.00000","1.27396","0.19999"
"1.27396","104.94099","1.25457","327.02800","0.00000","1.27396","0.19999"
"1.27396","104.71569","1.25188","327.66800","0.00000","1.27396","0.19999"
"1.27396","104.50635","1.24938","328.30800","0.00000","1.27396","0.19999"
"1.27396","104.30960","1.24702","328.94800","0.00000","1.27396","0.19999"
"1.27396","104.11628","1.24471","329.58800","0.00000","1.27396","0.19999"
"1.27396","103.94152","1.24262","330.22800","0.00000","1.27396","0.19999"
"1.27396","103.76565","1.24052","330.86800","0.00000","1.27396","0.19999"
"1.27396","103.59109","1.23843","331.50800","0.00000","1.27396","0.19999"
"1.27396","103.43626","1.23658","332.14800","0.00000","1.27396","0.19999"
"1.27396","103.27096","1.23461","332.78800","0.00000","1.27396","0.19999"
"1.27396","103.11509","1.23274","333.42800","0.00000","1.27396","0.19999"
"1.27396","102.96837","1.23099","334.06800","0.00000","1.27396","0.19999"
"1.27396","102.82011","1.22922","334.70800","0.00000","1.27396","0.19999"
"1.27396","102.68544","1.22761","335.34800","0.00000","1.27396","0.19999"
"1.27396","102.55202","1.22601","335.98800","0.00000","1.27396","0.19999"
"1.27396","102.40882","1.22430","336.62800","0.00000","1.27396","0.19999"
"1.27396","102.29456","1.22293","337.26800","0.00000","1.27396","0.19999"
"1.27396","102.16212","1.22135","337.90800","0.00000","1.27396","0.19999"
"1.27396","102.03425","1.21982","338.54800","0.00000","1.27396","0.19999"
"1.27396","101.92049","1.21846","339.18800","0.00000","1.27396","0.19999"
"1.27396","101.80133","1.21704","339.82800","0.00000","1.27396","0.19999"
"1.27396","101.68336","1.21563","340.46800","0.00000","1.27396","0.19999"
"1.27396","101.57207","1.21430","341.10800","0.00000","1.27396","0.19999"
"1.27396","101.46198","1.21298","341.74800","0.00000","1.27396","0.19999"
"1.27396","101.35971","1.21176","342.38800","0.00000","1.27396","0.19999"
"1.27396","101.24931","1.21044","343.02800","0.00000","1.27396","0.19999"
"1.27396","101.15034","1.20926","343.66800","0.00000","1.27396","0.19999"
"1.27396","101.05166","1.20808","344.30800","0.00000","1.27396","0.19999"
"1.27396","100.95358","1.20690","344.94800","0.00000","1.27396","0.19999"
"1.27396","100.85753","1.20575","345.58800","0.00000","1.27396","0.19999"
"1.27396","100.76132","1.20460","346.22800","0.00000","1.27396","0.19999"
"1.27396","100.66464","1.20345","346.86800","0.00000","1.27396","0.19999"
"1.27396","100.57821","1.20242","347.50800","0.00000","1.27396","0.19999"
"1.27396","100.48431","1.20129","348.14800","0.00000","1.27396","0.19999"
"1.27396","100.39285","1.20020","348.78800","0.00000","1.27396","0.19999"
"1.27396","100.31097","1.19922","349.42800","0.00000","1.27396","0.19999"
"1.27396","100.22514","1.19819","350.06800","0.00000","1.27396","0.19999"
"1.27396","100.14066","1.19718","350.70800","0.00000","1.27396","0.19999"
"1.27396","100.06731","1.19631","351.34800","0.00000","1.27396","0.19999"
"1.27396","99.97950","1.19526","351.98800","0.00000","1.27396","0.19999"
"1.27396","99.90390","1.19435","352.62800","0.00000","1.27396","0.19999"
"1.27396","99.82751","1.19344","353.26800","0.00000","1.27396","0.19999"
"1.27396","99.75323","1.19255","353.90800","0.00000","1.27396","0.19999"
"1.27396","99.66727","1.19153","354.54800","0.00000","1.27396","0.19999"
"1.27396","99.58710","1.19057","355.18800","0.00000","1.27396","0.19999"
"1.27396","99.51752","1.18974","355.82800","0.00000","1.27396","0.19999"
"1.27396","99.45020","1.18893","356.46800","0.00000","1.27396","0.19999"
"1.27396","99.37255","1.18800","357.10800","0.00000","1.27396","0.19999"
"1.27396","99.30448","1.18719","357.74800","0.00000","1.27396","0.19999"
"1.27396","99.22738","1.18627","358.38800","0.00000","1.27396","0.19999"
"1.27396","99.16894","1.18557","359.02800","0.00000","1.27396","0.19999"
"1.27396","99.10043","1.18475","359.66800","0.00000","1.27396","0.19999"
"1.27396","99.02589","1.18386","360.30800","0.00000","1.27396","0.19999"
"1.27396","98.96794","1.18316","360.94800","0.00000","1.27396","0.19999"
"1.27396","98.90363","1.18240","361.58800","0.00000","1.27396","0.19999"
"1.27396","98.83558","1.18158","362.22800","0.00000","1.27396","0.19999"
"1.27396","98.76827","1.18078","362.86800","0.00000","1.27396","0.19999"
"1.27396","98.71721","1.18017","363.50800","0.00000","1.27396","0.19999"
"1.27396","98.65401","1.17941","364.14800","0.00000","1.27396","0.19999"
"1.27396","98.58282","1.17856","364.78800","0.00000","1.27396","0.19999"
"1.27396","98.51349","1.17773","365.42800","0.00000","1.27396","0.19999"
"1.27396","98.46912","1.17720","366.06800","0.00000","1.27396","0.19999"
"1.27396","98.40749","1.17646","366.70800","0.00000","1.27396","0.19999"
"1.27396","98.34631","1.17573","367.34800","0.00000","1.27396","0.19999"
"1.27396","98.28889","1.17505","367.98800","0.00000","1.27396","0.19999"
"1.27396","98.22721","1.17431","368.62800","0.00000","1.27396","0.19999"
"1.27396","98.16832","1.17361","369.26800","0.00000","1.27396","0.19999"
"1.27396","98.11599","1.17298","369.90800","0.00000","1.27396","0.19999"
"1.27396","98.05758","1.17228","370.54800","0.00000","1.27396","0.19999"
"1.27396","98.00806","1.17169","371.18800","0.00000","1.27396","0.19999"
"1.27396","97.96111","1.17113","371.82800","0.00000","1.27396","0.19999"
"1.27396","97.89197","1.17030","372.46800","0.00000","1.27396","0.19999"
"1.27396","97.83707","1.16965","373.10800","0.00000","1.27396","0.19999"
"1.27396","97.79298","1.16912","373.74800","0.00000","1.27396","0.19999"
"1.27396","97.73683","1.16845","374.38800","0.00000","1.27396","0.19999"
"1.27396","97.68137","1.16778","375.02800","0.00000","1.27396","0.19999"
"1.27396","97.63065","1.16718","375.66800","0.00000","1.27396","0.19999"
"1.27396","97.58127","1.16659","376.30800","0.00000","1.27396","0.19999"
"1.27396","97.52732","1.16594","376.94800","0.00000","1.27396","0.19999"
"1.27396","97.48188","1.16540","377.58800","0.00000","1.27396","0.19999"
"1.27396","97.43503","1.16484","378.22800","0.00000","1.27396","0.19999"
"1.27396","97.38071","1.16419","378.86800","0.00000","1.27396","0.19999"
"1.27396","97.33335","1.16362","379.50800","0.00000","1.27396","0.19999"
"1.27396","97.27965","1.16298","380.14800","0.00000","1.27396","0.19999"
"1.27396","97.23755","1.16248","380.78800","0.00000","1.27396","0.19999"
"1.27396","97.19093","1.16192","381.42800","0.00000","1.27396","0.19999"
"1.27396","97.14310","1.16135","382.06800","0.00000","1.27396","0.19999"
"1.27396","97.09052","1.16072","382.70800","0.00000","1.27396","0.19999"
"1.27396","97.05350","1.16028","383.34800","0.00000","1.27396","0.19999"
"1.27396","97.00376","1.15968","383.98800","0.00000","1.27396","0.19999"
"1.27396","96.96122","1.15917","384.62800","0.00000","1.27396","0.19999"
"1.27396","96.91149","1.15858","385.26800","0.00000","1.27396","0.19999"
"1.27396","96.87386","1.15813","385.90800","0.00000","1.27396","0.19999"
"1.27396","96.83058","1.15761","386.54800","0.00000","1.27396","0.19999"
"1.27396","96.77987","1.15701","387.18800","0.00000","1.27396","0.19999"
"1.27396","96.73852","1.15651","387.82800","0.00000","1.27396","0.19999"
"1.27396","96.69879","1.15604","388.46800","0.00000","1.27396","0.19999"
"1.27396","96.66140","1.15559","389.10800","0.00000","1.27396","0.19999"
"1.27396","96.61512","1.15504","389.74800","0.00000","1.27396","0.19999"
"1.27396","96.57341","1.15454","390.38800","0.00000","1.27396","0.19999"
"1.27396","96.52974","1.15402","391.02800","0.00000","1.27396","0.19999"
"1.27396","96.47677","1.15338","391.66800","0.00000","1.27396","0.19999"
"1.27396","96.43809","1.15292","392.30800","0.00000","1.27396","0.19999"
"1.27396","96.39323","1.15238","392.94800","0.00000","1.27396","0.19999"
"1.27396","96.34630","1.15182","393.58800","0.00000","1.27396","0.19999"
"1.27396","96.32043","1.15151","394.22800","0.00000","1.27396","0.19999"
"1.27396","96.27253","1.15094","394.86800","0.00000","1.27396","0.19999"
"1.27396","96.23486","1.15049","395.50800","0.00000","1.27396","0.19999"
"1.27396","96.19073","1.14996","396.14800","0.00000","1.27396","0.19999"
"1.27396","96.15732","1.14956","396.78800","0.00000","1.27396","0.19999"
"1.27396","96.10622","1.14895","397.42800","0.00000","1.27396","0.19999"
"1.27396","96.07373","1.14856","398.06800","0.00000","1.27396","0.19999"
"1.27396","96.05936","1.14839","398.70800","0.00000","1.27396","0.19999"
"1.27396","96.00806","1.14778","399.34800","0.00000","1.27396","0.19999"
"1.27396","95.96124","1.14722","399.98800","0.00000","1.27396","0.19999"
"1.27396","95.94169","1.14699","400.62800","0.00000","1.27396","0.19999"
"1.27396","95.89474","1.14642","401.26800","0.00000","1.27396","0.19999"
"1.27396","95.86567","1.14608","401.90800","0.00000","1.27396","0.19999"
"1.27396","95.82615","1.14560","402.54800","0.00000","1.27396","0.19999"
"1.27396","95.79101","1.14518","403.18800","0.00000","1.27396","0.19999"
"1.27396","95.76254","1.14484","403.82800","0.00000","1.27396","0.19999"
"1.27396","95.71822","1.14431","404.46800","0.00000","1.27396","0.19999"
"1.27396","95.68984","1.14398","405.10800","0.00000","1.27396","0.19999"
"1.27396","95.65853","1.14360","405.74800","0.00000","1.27396","0.19999"
"1.27396","95.62299","1.14318","406.38800","0.00000","1.27396","0.19999"
"1.27396","95.59196","1.14280","407.02800","0.00000","1.27396","0.19999"
"1.27396","95.55502","1.14236","407.66800","0.00000","1.27396","0.19999"
"1.27396","95.51087","1.14184","408.30800","0.00000","1.27396","0.19999"
"1.27396","95.48695","1.14155","408.94800","0.00000","1.27396","0.19999"
"1.27396","95.44754","1.14108","409.58800","0.00000","1.27396","0.19999"
"1.27396","95.41221","1.14066","410.22800","0.00000","1.27396","0.19999"
"1.27396","95.38675","1.14035","410.86800","0.00000","1.27396","0.19999"
"1.27396","95.35242","1.13994","411.50800","0.00000","1.27396","0.19999"
"1.27396","95.32123","1.13957","412.14800","0.00000","1.27396","0.19999"
"1.27396","95.28181","1.13910","412.78800","0.00000","1.27396","0.19999"
"1.27396","95.25756","1.13881","413.42800","0.00000","1.27396","0.19999"
"1.27396","95.22831","1.13846","414.06800","0.00000","1.27396","0.19999"
"1.27396","95.19047","1.13801","414.70800","0.00000","1.27396","0.19999"
"1.27396","95.15549","1.13759","415.34800","0.00000","1.27396","0.19999"
"1.27396","95.13013","1.13728","415.98800","0.00000","1.27396","0.19999"
"1.27396","95.10000","1.13692","416.62800","0.00000","1.27396","0.19999"
"1.27396","95.07096","1.13658","417.26800","0.00000","1.27396","0.19999"
"1.27396","95.04127","1.13622","417.90800","0.00000","1.27396","0.19999"
"1.27396","95.01048","1.13585","418.54800","0.00000","1.27396","0.19999"
"1.27396","94.98402","1.13554","419.18800","0.00000","1.27396","0.19999"
"1.27396","94.95044","1.13514","419.82800","0.00000","1.27396","0.19999"
"1.27396","94.91294","1.13469","420.46800","0.00000","1.27396","0.19999"
"1.27396","94.88851","1.13440","421.10800","0.00000","1.27396","0.19999"
"1.27396","94.85670","1.13401","421.74800","0.00000","1.27396","0.19999"
"1.27396","94.82659","1.13365","422.38800","0.00000","1.27396","0.19999"
"1.27396","94.79893","1.13332","423.02800","0.00000","1.27396","0.19999"
"1.27396","94.76336","1.13290","423.66800","0.00000","1.27396","0.19999"
"1.27396","94.73896","1.13261","424.30800","0.00000","1.27396","0.19999"
"1.27396","94.70853","1.13224","424.94800","0.00000","1.27396","0.19999"
"1.27396","94.67578","1.13185","425.58800","0.00000","1.27396","0.19999"
"1.27396","94.64787","1.13152","426.22800","0.00000","1.27396","0.19999"
"1.27396","94.61266","1.13110","426.86800","0.00000","1.27396","0.19999"
"1.27396","94.59193","1.13085","427.50800","0.00000","1.27396","0.19999"
"1.27396","94.55617","1.13042","428.14800","0.00000","1.27396","0.19999"
"1.27396","94.52313","1.13003","428.78800","0.00000","1.27396","0.19999"
"1.27396","94.50166","1.12977","429.42800","0.00000","1.27396","0.19999"
"1.27396","94.47559","1.12946","430.06800","0.00000","1.27396","0.19999"
"1.27396","94.44703","1.12912","430.70800","0.00000","1.27396","0.19999"
"1.27396","94.40987","1.12867","431.34800","0.00000","1.27396","0.19999"
"1.27396","94.39402","1.12848","431.98800","0.00000","1.27396","0.19999"
"1.27396","94.36779","1.12817","432.62800","0.00000","1.27396","0.19999"
"1.27396","94.33174","1.12774","433.26800","0.00000","1.27396","0.19999"
"1.27396","94.30666","1.12744","433.90800","0.00000","1.27396","0.19999"
"1.27396","94.28133","1.12714","434.54800","0.00000","1.27396","0.19999"
"1.27396","94.25198","1.12679","435.18800","0.00000","1.27396","0.19999"
"1.27396","94.22955","1.12652","435.82800","0.00000","1.27396","0.19999"
"1.27396","94.19231","1.12607","436.46800","0.00000","1.27396","0.19999"
"1.27396","94.17714","1.12589","437.10800","0.00000","1.27396","0.19999"
"1.27396","94.14526","1.12551","437.74800","0.00000","1.27396","0.19999"
"1.27396","94.11578","1.12516","438.38800","0.00000","1.27396","0.19999"
"1.27396","94.12024","1.12521","438.52800","0.00000","1.27396","0.19999"