File: Rubber Stress Relaxation Raw Data -Large  Samples-20210211/Specimen_RawData_9.csv
Specimen properties : Specimen label,"specimen 1"
Specimen properties : Anvil height,"6.38000",mm
Specimen properties : Diameter,"10.11000",mm
Test : Rate 1,"0.24000",mm/min
Test : Start of hold value,"20.00000",%
Test : Duration,"120.00000",s

Extension,Load,Compressive stress,Time,PIP count,Compressive extension,Compressive strain (Extension)
(mm),(N),(MPa),(s),,(mm),(mm/mm)
"0.00000","-0.00072","-0.00001","0.00000","0.00000","0.00000","0.00000"
"0.00042","0.02551","0.00032","0.64000","0.00000","0.00042","0.00007"
"0.00354","0.27082","0.00337","1.28000","0.00000","0.00354","0.00056"
"0.00708","0.56088","0.00699","1.92000","0.00000","0.00708","0.00111"
"0.01000","0.77414","0.00964","2.56000","0.00000","0.01000","0.00157"
"0.01271","0.94836","0.01181","3.20000","0.00000","0.01271","0.00199"
"0.01521","1.13267","0.01411","3.84000","0.00000","0.01521","0.00238"
"0.01792","1.32485","0.01650","4.48000","0.00000","0.01792","0.00281"
"0.02042","1.51074","0.01882","5.12000","0.00000","0.02042","0.00320"
"0.02292","1.70719","0.02127","5.76000","0.00000","0.02292","0.00359"
"0.02562","1.90201","0.02369","6.40000","0.00000","0.02562","0.00402"
"0.02813","2.09586","0.02611","7.04000","0.00000","0.02813","0.00441"
"0.03063","2.29819","0.02863","7.68000","0.00000","0.03063","0.00480"
"0.03313","2.51417","0.03132","8.32000","0.00000","0.03313","0.00519"
"0.03583","2.71391","0.03381","8.96000","0.00000","0.03583","0.00562"
"0.03833","2.93782","0.03660","9.60000","0.00000","0.03833","0.00601"
"0.04104","3.17321","0.03953","10.24000","0.00000","0.04104","0.00643"
"0.04375","3.38165","0.04212","10.88000","0.00000","0.04375","0.00686"
"0.04625","3.60961","0.04496","11.52000","0.00000","0.04625","0.00725"
"0.04875","3.84475","0.04789","12.16000","0.00000","0.04875","0.00764"
"0.05146","4.07739","0.05079","12.80000","0.00000","0.05146","0.00807"
"0.05396","4.32423","0.05387","13.44000","0.00000","0.05396","0.00846"
"0.05646","4.55660","0.05676","14.08000","0.00000","0.05646","0.00885"
"0.05896","4.78376","0.05959","14.72000","0.00000","0.05896","0.00924"
"0.06146","5.02096","0.06255","15.36000","0.00000","0.06146","0.00963"
"0.06396","5.27659","0.06573","16.00000","0.00000","0.06396","0.01002"
"0.06646","5.52579","0.06883","16.64000","0.00000","0.06646","0.01042"
"0.06917","5.77481","0.07194","17.28000","0.00000","0.06917","0.01084"
"0.07146","6.01458","0.07492","17.92000","0.00000","0.07146","0.01120"
"0.07417","6.27348","0.07815","18.56000","0.00000","0.07417","0.01162"
"0.07688","6.53545","0.08141","19.20000","0.00000","0.07688","0.01205"
"0.07958","6.81077","0.08484","19.84000","0.00000","0.07958","0.01247"
"0.08188","7.00184","0.08722","20.48000","0.00000","0.08188","0.01283"
"0.08458","7.27597","0.09064","21.12000","0.00000","0.08458","0.01326"
"0.08729","7.50824","0.09353","21.76000","0.00000","0.08729","0.01368"
"0.08979","7.74152","0.09643","22.40000","0.00000","0.08979","0.01407"
"0.09229","7.98503","0.09947","23.04000","0.00000","0.09229","0.01447"
"0.09479","8.22537","0.10246","23.68000","0.00000","0.09479","0.01486"
"0.09729","8.46100","0.10540","24.32000","0.00000","0.09729","0.01525"
"0.09979","8.68063","0.10813","24.96000","0.00000","0.09979","0.01564"
"0.10229","8.92939","0.11123","25.60000","0.00000","0.10229","0.01603"
"0.10500","9.17649","0.11431","26.24000","0.00000","0.10500","0.01646"
"0.10750","9.41231","0.11725","26.88000","0.00000","0.10750","0.01685"
"0.11000","9.63777","0.12006","27.52000","0.00000","0.11000","0.01724"
"0.11250","9.89542","0.12327","28.16000","0.00000","0.11250","0.01763"
"0.11521","10.12813","0.12616","28.80000","0.00000","0.11521","0.01806"
"0.11771","10.36394","0.12910","29.44000","0.00000","0.11771","0.01845"
"0.12042","10.63476","0.13248","30.08000","0.00000","0.12042","0.01887"
"0.12313","10.85532","0.13522","30.72000","0.00000","0.12313","0.01930"
"0.12563","11.08431","0.13808","31.36000","0.00000","0.12563","0.01969"
"0.12812","11.32128","0.14103","32.00000","0.00000","0.12812","0.02008"
"0.13063","11.52541","0.14357","32.64000","0.00000","0.13063","0.02047"
"0.13313","11.77333","0.14666","33.28000","0.00000","0.13313","0.02087"
"0.13583","12.00630","0.14956","33.92000","0.00000","0.13583","0.02129"
"0.13813","12.22002","0.15222","34.56000","0.00000","0.13813","0.02165"
"0.14083","12.46367","0.15526","35.20000","0.00000","0.14083","0.02207"
"0.14333","12.71496","0.15839","35.84000","0.00000","0.14333","0.02247"
"0.14583","12.96205","0.16147","36.48000","0.00000","0.14583","0.02286"
"0.14833","13.17794","0.16416","37.12000","0.00000","0.14833","0.02325"
"0.15104","13.40305","0.16696","37.76000","0.00000","0.15104","0.02367"
"0.15354","13.64783","0.17001","38.40000","0.00000","0.15354","0.02407"
"0.15625","13.89637","0.17310","39.04000","0.00000","0.15625","0.02449"
"0.15875","14.12376","0.17594","39.68000","0.00000","0.15875","0.02488"
"0.16146","14.34397","0.17868","40.32000","0.00000","0.16146","0.02531"
"0.16396","14.59995","0.18187","40.96000","0.00000","0.16396","0.02570"
"0.16667","14.81474","0.18454","41.60000","0.00000","0.16667","0.02612"
"0.16917","15.03204","0.18725","42.24000","0.00000","0.16917","0.02652"
"0.17167","15.27402","0.19027","42.88000","0.00000","0.17167","0.02691"
"0.17417","15.49745","0.19305","43.52000","0.00000","0.17417","0.02730"
"0.17667","15.71124","0.19571","44.16000","0.00000","0.17667","0.02769"
"0.17917","15.93262","0.19847","44.80000","0.00000","0.17917","0.02808"
"0.18167","16.17281","0.20146","45.44000","0.00000","0.18167","0.02847"
"0.18438","16.41459","0.20447","46.08000","0.00000","0.18438","0.02890"
"0.18688","16.63524","0.20722","46.72000","0.00000","0.18688","0.02929"
"0.18937","16.83610","0.20972","47.36000","0.00000","0.18937","0.02968"
"0.19188","17.08511","0.21283","48.00000","0.00000","0.19188","0.03007"
"0.19458","17.32156","0.21577","48.64000","0.00000","0.19458","0.03050"
"0.19708","17.56888","0.21885","49.28000","0.00000","0.19708","0.03089"
"0.19979","17.79311","0.22165","49.92000","0.00000","0.19979","0.03132"
"0.20229","18.02721","0.22456","50.56000","0.00000","0.20229","0.03171"
"0.20500","18.26824","0.22756","51.20000","0.00000","0.20500","0.03213"
"0.20750","18.48877","0.23031","51.84000","0.00000","0.20750","0.03252"
"0.21000","18.70610","0.23302","52.48000","0.00000","0.21000","0.03292"
"0.21271","18.93008","0.23581","53.12000","0.00000","0.21271","0.03334"
"0.21521","19.14720","0.23851","53.76000","0.00000","0.21521","0.03373"
"0.21750","19.33044","0.24080","54.40000","0.00000","0.21750","0.03409"
"0.22000","19.59403","0.24408","55.04000","0.00000","0.22000","0.03448"
"0.22271","19.83031","0.24702","55.68000","0.00000","0.22271","0.03491"
"0.22521","20.08745","0.25023","56.32000","0.00000","0.22521","0.03530"
"0.22771","20.29533","0.25282","56.96000","0.00000","0.22771","0.03569"
"0.23021","20.52774","0.25571","57.60000","0.00000","0.23021","0.03608"
"0.23292","20.76105","0.25862","58.24000","0.00000","0.23292","0.03651"
"0.23542","20.98989","0.26147","58.88000","0.00000","0.23542","0.03690"
"0.23813","21.22009","0.26434","59.52000","0.00000","0.23813","0.03732"
"0.24063","21.42238","0.26686","60.16000","0.00000","0.24063","0.03772"
"0.24333","21.68014","0.27007","60.80000","0.00000","0.24333","0.03814"
"0.24604","21.89914","0.27279","61.44000","0.00000","0.24604","0.03856"
"0.24854","22.11888","0.27553","62.08000","0.00000","0.24854","0.03896"
"0.25104","22.30851","0.27789","62.72000","0.00000","0.25104","0.03935"
"0.25354","22.51463","0.28046","63.36000","0.00000","0.25354","0.03974"
"0.25604","22.71856","0.28300","64.00000","0.00000","0.25604","0.04013"
"0.25854","22.88261","0.28504","64.64000","0.00000","0.25854","0.04052"
"0.26104","23.12511","0.28807","65.28000","0.00000","0.26104","0.04092"
"0.26375","23.35120","0.29088","65.92000","0.00000","0.26375","0.04134"
"0.26625","23.54022","0.29324","66.56000","0.00000","0.26625","0.04173"
"0.26875","23.73608","0.29568","67.20000","0.00000","0.26875","0.04212"
"0.27125","23.96829","0.29857","67.84000","0.00000","0.27125","0.04252"
"0.27396","24.18974","0.30133","68.48000","0.00000","0.27396","0.04294"
"0.27646","24.38704","0.30379","69.12000","0.00000","0.27646","0.04333"
"0.27896","24.56848","0.30605","69.76000","0.00000","0.27896","0.04372"
"0.28167","24.81205","0.30908","70.40000","0.00000","0.28167","0.04415"
"0.28438","25.03783","0.31189","71.04000","0.00000","0.28438","0.04457"
"0.28688","25.23003","0.31429","71.68000","0.00000","0.28688","0.04496"
"0.28938","25.42072","0.31666","72.32000","0.00000","0.28938","0.04536"
"0.29208","25.62284","0.31918","72.96000","0.00000","0.29208","0.04578"
"0.29458","25.79656","0.32134","73.60000","0.00000","0.29458","0.04617"
"0.29708","25.96717","0.32347","74.24000","0.00000","0.29708","0.04656"
"0.29937","26.15679","0.32583","74.88000","0.00000","0.29937","0.04692"
"0.30208","26.35882","0.32835","75.52000","0.00000","0.30208","0.04735"
"0.30458","26.57204","0.33100","76.16000","0.00000","0.30458","0.04774"
"0.30708","26.76577","0.33342","76.80000","0.00000","0.30708","0.04813"
"0.30958","26.94187","0.33561","77.44000","0.00000","0.30958","0.04852"
"0.31229","27.13411","0.33801","78.08000","0.00000","0.31229","0.04895"
"0.31479","27.34189","0.34059","78.72000","0.00000","0.31479","0.04934"
"0.31750","27.52080","0.34282","79.36000","0.00000","0.31750","0.04976"
"0.32000","27.68914","0.34492","80.00000","0.00000","0.32000","0.05016"
"0.32250","27.87728","0.34726","80.64000","0.00000","0.32250","0.05055"
"0.32542","28.11221","0.35019","81.28000","0.00000","0.32542","0.05101"
"0.32792","28.28756","0.35237","81.92000","0.00000","0.32792","0.05140"
"0.33042","28.47421","0.35470","82.56000","0.00000","0.33042","0.05179"
"0.33312","28.66654","0.35709","83.20000","0.00000","0.33312","0.05221"
"0.33563","28.85622","0.35946","83.84000","0.00000","0.33563","0.05261"
"0.33792","29.01025","0.36138","84.48000","0.00000","0.33792","0.05297"
"0.34042","29.20784","0.36384","85.12000","0.00000","0.34042","0.05336"
"0.34313","29.40266","0.36626","85.76000","0.00000","0.34313","0.05378"
"0.34563","29.59677","0.36868","86.40000","0.00000","0.34563","0.05417"
"0.34813","29.75171","0.37061","87.04000","0.00000","0.34813","0.05457"
"0.35063","29.96557","0.37328","87.68000","0.00000","0.35063","0.05496"
"0.35333","30.17830","0.37593","88.32000","0.00000","0.35333","0.05538"
"0.35583","30.37190","0.37834","88.96000","0.00000","0.35583","0.05577"
"0.35833","30.51007","0.38006","89.60000","0.00000","0.35833","0.05617"
"0.36104","30.74079","0.38293","90.24000","0.00000","0.36104","0.05659"
"0.36354","30.93473","0.38535","90.88000","0.00000","0.36354","0.05698"
"0.36625","31.13369","0.38783","91.52000","0.00000","0.36625","0.05741"
"0.36875","31.31821","0.39013","92.16000","0.00000","0.36875","0.05780"
"0.37146","31.49143","0.39228","92.80000","0.00000","0.37146","0.05822"
"0.37396","31.64962","0.39425","93.44000","0.00000","0.37396","0.05861"
"0.37646","31.83805","0.39660","94.08000","0.00000","0.37646","0.05901"
"0.37896","31.98932","0.39849","94.72000","0.00000","0.37896","0.05940"
"0.38146","32.18171","0.40088","95.36000","0.00000","0.38146","0.05979"
"0.38396","32.36883","0.40321","96.00000","0.00000","0.38396","0.06018"
"0.38646","32.52363","0.40514","96.64000","0.00000","0.38646","0.06057"
"0.38917","32.72176","0.40761","97.28000","0.00000","0.38917","0.06100"
"0.39167","32.89243","0.40974","97.92000","0.00000","0.39167","0.06139"
"0.39417","33.07761","0.41204","98.56000","0.00000","0.39417","0.06178"
"0.39688","33.29057","0.41470","99.20000","0.00000","0.39688","0.06221"
"0.39938","33.46436","0.41686","99.84000","0.00000","0.39938","0.06260"
"0.40188","33.66574","0.41937","100.48000","0.00000","0.40188","0.06299"
"0.40458","33.85963","0.42178","101.12000","0.00000","0.40458","0.06341"
"0.40729","34.07024","0.42441","101.76000","0.00000","0.40729","0.06384"
"0.40979","34.24084","0.42653","102.40000","0.00000","0.40979","0.06423"
"0.41229","34.42271","0.42880","103.04000","0.00000","0.41229","0.06462"
"0.41500","34.61131","0.43115","103.68000","0.00000","0.41500","0.06505"
"0.41750","34.77545","0.43319","104.32000","0.00000","0.41750","0.06544"
"0.42000","34.94723","0.43533","104.96000","0.00000","0.42000","0.06583"
"0.42250","35.11958","0.43748","105.60000","0.00000","0.42250","0.06622"
"0.42479","35.30415","0.43978","106.24000","0.00000","0.42479","0.06658"
"0.42729","35.47568","0.44191","106.88000","0.00000","0.42729","0.06697"
"0.43000","35.66045","0.44422","107.52000","0.00000","0.43000","0.06740"
"0.43271","35.87528","0.44689","108.16000","0.00000","0.43271","0.06782"
"0.43521","36.03945","0.44894","108.80000","0.00000","0.43521","0.06821"
"0.43771","36.23700","0.45140","109.44000","0.00000","0.43771","0.06861"
"0.44021","36.42926","0.45379","110.08000","0.00000","0.44021","0.06900"
"0.44292","36.60431","0.45597","110.72000","0.00000","0.44292","0.06942"
"0.44563","36.81052","0.45854","111.36000","0.00000","0.44563","0.06985"
"0.44813","36.96601","0.46048","112.00000","0.00000","0.44813","0.07024"
"0.45083","37.15344","0.46281","112.64000","0.00000","0.45083","0.07066"
"0.45333","37.32212","0.46492","113.28000","0.00000","0.45333","0.07106"
"0.45583","37.46077","0.46664","113.92000","0.00000","0.45583","0.07145"
"0.45833","37.60707","0.46847","114.56000","0.00000","0.45833","0.07184"
"0.46104","37.76733","0.47046","115.20000","0.00000","0.46104","0.07226"
"0.46354","37.93752","0.47258","115.84000","0.00000","0.46354","0.07266"
"0.46604","38.11760","0.47482","116.48000","0.00000","0.46604","0.07305"
"0.46833","38.29433","0.47703","117.12000","0.00000","0.46833","0.07341"
"0.47104","38.49232","0.47949","117.76000","0.00000","0.47104","0.07383"
"0.47354","38.70430","0.48213","118.40000","0.00000","0.47354","0.07422"
"0.47604","38.91113","0.48471","119.04000","0.00000","0.47604","0.07461"
"0.47875","39.09446","0.48699","119.68000","0.00000","0.47875","0.07504"
"0.48146","39.32628","0.48988","120.32000","0.00000","0.48146","0.07546"
"0.48417","39.53098","0.49243","120.96000","0.00000","0.48417","0.07589"
"0.48667","39.69637","0.49449","121.60000","0.00000","0.48667","0.07628"
"0.48917","39.88926","0.49689","122.24000","0.00000","0.48917","0.07667"
"0.49167","40.07325","0.49919","122.88000","0.00000","0.49167","0.07706"
"0.49438","40.25362","0.50143","123.52000","0.00000","0.49437","0.07749"
"0.49688","40.40988","0.50338","124.16000","0.00000","0.49687","0.07788"
"0.49938","40.61833","0.50598","124.80000","0.00000","0.49938","0.07827"
"0.50187","40.79006","0.50812","125.44000","0.00000","0.50187","0.07866"
"0.50438","40.97747","0.51045","126.08000","0.00000","0.50438","0.07906"
"0.50688","41.10261","0.51201","126.72000","0.00000","0.50688","0.07945"
"0.50938","41.28896","0.51433","127.36000","0.00000","0.50938","0.07984"
"0.51188","41.48943","0.51683","128.00000","0.00000","0.51188","0.08023"
"0.51458","41.69582","0.51940","128.64000","0.00000","0.51458","0.08066"
"0.51708","41.84012","0.52120","129.28000","0.00000","0.51708","0.08105"
"0.51958","42.05777","0.52391","129.92000","0.00000","0.51958","0.08144"
"0.52229","42.24159","0.52620","130.56000","0.00000","0.52229","0.08186"
"0.52500","42.43059","0.52855","131.20000","0.00000","0.52500","0.08229"
"0.52750","42.57149","0.53031","131.84000","0.00000","0.52750","0.08268"
"0.53021","42.78327","0.53294","132.48000","0.00000","0.53021","0.08310"
"0.53271","42.96072","0.53515","133.12000","0.00000","0.53271","0.08350"
"0.53521","43.15312","0.53755","133.76000","0.00000","0.53521","0.08389"
"0.53792","43.34502","0.53994","134.40000","0.00000","0.53792","0.08431"
"0.54042","43.51487","0.54206","135.04000","0.00000","0.54042","0.08470"
"0.54292","43.69694","0.54433","135.68000","0.00000","0.54292","0.08510"
"0.54542","43.89109","0.54674","136.32000","0.00000","0.54542","0.08549"
"0.54771","44.03982","0.54860","136.96000","0.00000","0.54771","0.08585"
"0.55021","44.25460","0.55127","137.60000","0.00000","0.55021","0.08624"
"0.55292","44.47827","0.55406","138.24000","0.00000","0.55292","0.08666"
"0.55542","44.67770","0.55654","138.88000","0.00000","0.55542","0.08706"
"0.55813","44.88757","0.55916","139.52000","0.00000","0.55813","0.08748"
"0.56063","45.09552","0.56175","140.16000","0.00000","0.56063","0.08787"
"0.56333","45.29674","0.56425","140.80000","0.00000","0.56333","0.08830"
"0.56604","45.49582","0.56673","141.44000","0.00000","0.56604","0.08872"
"0.56854","45.67493","0.56897","142.08000","0.00000","0.56854","0.08911"
"0.57104","45.87089","0.57141","142.72000","0.00000","0.57104","0.08950"
"0.57354","46.06192","0.57379","143.36000","0.00000","0.57354","0.08990"
"0.57625","46.23350","0.57592","144.00000","0.00000","0.57625","0.09032"
"0.57875","46.40800","0.57810","144.64000","0.00000","0.57875","0.09071"
"0.58125","46.60415","0.58054","145.28000","0.00000","0.58125","0.09111"
"0.58396","46.76349","0.58253","145.92000","0.00000","0.58396","0.09153"
"0.58625","46.93174","0.58462","146.56000","0.00000","0.58625","0.09189"
"0.58875","47.08525","0.58653","147.20000","0.00000","0.58875","0.09228"
"0.59125","47.30408","0.58926","147.84000","0.00000","0.59125","0.09267"
"0.59375","47.47985","0.59145","148.48000","0.00000","0.59375","0.09306"
"0.59646","47.63980","0.59344","149.12000","0.00000","0.59646","0.09349"
"0.59896","47.86203","0.59621","149.76000","0.00000","0.59896","0.09388"
"0.60167","48.04046","0.59843","150.40000","0.00000","0.60167","0.09431"
"0.60417","48.26035","0.60117","151.04000","0.00000","0.60417","0.09470"
"0.60667","48.43336","0.60333","151.68000","0.00000","0.60667","0.09509"
"0.60917","48.64101","0.60591","152.32000","0.00000","0.60917","0.09548"
"0.61188","48.85167","0.60854","152.96000","0.00000","0.61188","0.09591"
"0.61458","49.07728","0.61135","153.60000","0.00000","0.61458","0.09633"
"0.61687","49.22467","0.61318","154.24000","0.00000","0.61687","0.09669"
"0.61958","49.45166","0.61601","154.88000","0.00000","0.61958","0.09711"
"0.62229","49.65218","0.61851","155.52000","0.00000","0.62229","0.09754"
"0.62479","49.83132","0.62074","156.16000","0.00000","0.62479","0.09793"
"0.62729","49.98111","0.62261","156.80000","0.00000","0.62729","0.09832"
"0.62979","50.17038","0.62496","157.44000","0.00000","0.62979","0.09871"
"0.63229","50.39677","0.62778","158.08000","0.00000","0.63229","0.09911"
"0.63479","50.58086","0.63008","158.72000","0.00000","0.63479","0.09950"
"0.63729","50.76640","0.63239","159.36000","0.00000","0.63729","0.09989"
"0.64000","50.97467","0.63498","160.00000","0.00000","0.64000","0.10031"
"0.64271","51.19188","0.63769","160.64000","0.00000","0.64271","0.10074"
"0.64521","51.37334","0.63995","161.28000","0.00000","0.64521","0.10113"
"0.64792","51.59883","0.64276","161.92000","0.00000","0.64792","0.10155"
"0.65042","51.78199","0.64504","162.56000","0.00000","0.65042","0.10195"
"0.65292","51.97479","0.64744","163.20000","0.00000","0.65292","0.10234"
"0.65542","52.14152","0.64952","163.84000","0.00000","0.65542","0.10273"
"0.65792","52.30599","0.65157","164.48000","0.00000","0.65792","0.10312"
"0.66063","52.53895","0.65447","165.12000","0.00000","0.66063","0.10355"
"0.66333","52.70406","0.65653","165.76000","0.00000","0.66333","0.10397"
"0.66583","52.87933","0.65871","166.40000","0.00000","0.66583","0.10436"
"0.66833","53.04657","0.66079","167.04000","0.00000","0.66833","0.10475"
"0.67063","53.23323","0.66312","167.68000","0.00000","0.67063","0.10511"
"0.67333","53.44355","0.66574","168.32000","0.00000","0.67333","0.10554"
"0.67563","53.59246","0.66759","168.96000","0.00000","0.67563","0.10590"
"0.67833","53.90239","0.67145","169.60000","0.00000","0.67833","0.10632"
"0.68104","54.08244","0.67370","170.24000","0.00000","0.68104","0.10675"
"0.68375","54.31607","0.67661","170.88000","0.00000","0.68375","0.10717"
"0.68625","54.50153","0.67892","171.52000","0.00000","0.68625","0.10756"
"0.68875","54.68881","0.68125","172.16000","0.00000","0.68875","0.10795"
"0.69146","54.87388","0.68356","172.80000","0.00000","0.69146","0.10838"
"0.69396","55.07304","0.68604","173.44000","0.00000","0.69396","0.10877"
"0.69646","55.24256","0.68815","174.08000","0.00000","0.69646","0.10916"
"0.69896","55.45174","0.69075","174.72000","0.00000","0.69896","0.10955"
"0.70167","55.67567","0.69354","175.36000","0.00000","0.70167","0.10998"
"0.70417","55.85982","0.69584","176.00000","0.00000","0.70417","0.11037"
"0.70667","56.01371","0.69775","176.64000","0.00000","0.70667","0.11076"
"0.70917","56.22297","0.70036","177.28000","0.00000","0.70917","0.11115"
"0.71188","56.43172","0.70296","177.92000","0.00000","0.71188","0.11158"
"0.71438","56.61692","0.70527","178.56000","0.00000","0.71438","0.11197"
"0.71688","56.80826","0.70765","179.20000","0.00000","0.71688","0.11236"
"0.71938","56.99447","0.70997","179.84000","0.00000","0.71938","0.11275"
"0.72188","57.18092","0.71229","180.48000","0.00000","0.72188","0.11315"
"0.72458","57.37805","0.71475","181.12000","0.00000","0.72458","0.11357"
"0.72708","57.57861","0.71725","181.76000","0.00000","0.72708","0.11396"
"0.72958","57.79539","0.71995","182.40000","0.00000","0.72958","0.11435"
"0.73229","57.98618","0.72232","183.04000","0.00000","0.73229","0.11478"
"0.73458","58.14918","0.72435","183.68000","0.00000","0.73458","0.11514"
"0.73729","58.42181","0.72775","184.32000","0.00000","0.73729","0.11556"
"0.74000","58.66098","0.73073","184.96000","0.00000","0.74000","0.11599"
"0.74271","58.85298","0.73312","185.60000","0.00000","0.74271","0.11641"
"0.74521","59.02907","0.73532","186.24000","0.00000","0.74521","0.11680"
"0.74771","59.21156","0.73759","186.88000","0.00000","0.74771","0.11720"
"0.75021","59.42348","0.74023","187.52000","0.00000","0.75021","0.11759"
"0.75292","59.62848","0.74278","188.16000","0.00000","0.75292","0.11801"
"0.75521","59.72760","0.74402","188.80000","0.00000","0.75521","0.11837"
"0.75771","59.97047","0.74704","189.44000","0.00000","0.75771","0.11876"
"0.76021","60.19751","0.74987","190.08000","0.00000","0.76021","0.11915"
"0.76292","60.42137","0.75266","190.72000","0.00000","0.76292","0.11958"
"0.76542","60.63519","0.75532","191.36000","0.00000","0.76542","0.11997"
"0.76812","60.85695","0.75809","192.00000","0.00000","0.76812","0.12040"
"0.77062","61.02760","0.76021","192.64000","0.00000","0.77062","0.12079"
"0.77313","61.25617","0.76306","193.28000","0.00000","0.77313","0.12118"
"0.77583","61.44162","0.76537","193.92000","0.00000","0.77583","0.12160"
"0.77833","61.63555","0.76778","194.56000","0.00000","0.77833","0.12200"
"0.78083","61.84296","0.77037","195.20000","0.00000","0.78083","0.12239"
"0.78354","62.04993","0.77295","195.84000","0.00000","0.78354","0.12281"
"0.78604","62.20604","0.77489","196.48000","0.00000","0.78604","0.12320"
"0.78854","62.37909","0.77705","197.12000","0.00000","0.78854","0.12360"
"0.79125","62.60519","0.77986","197.76000","0.00000","0.79125","0.12402"
"0.79375","62.81562","0.78248","198.40000","0.00000","0.79375","0.12441"
"0.79625","62.99504","0.78472","199.04000","0.00000","0.79625","0.12480"
"0.79875","63.19955","0.78727","199.68000","0.00000","0.79875","0.12520"
"0.80125","63.39582","0.78971","200.32000","0.00000","0.80125","0.12559"
"0.80375","63.56073","0.79177","200.96000","0.00000","0.80375","0.12598"
"0.80646","63.81241","0.79490","201.60000","0.00000","0.80646","0.12640"
"0.80896","64.02486","0.79755","202.24000","0.00000","0.80896","0.12680"
"0.81167","64.24097","0.80024","202.88000","0.00000","0.81167","0.12722"
"0.81396","64.39397","0.80215","203.52000","0.00000","0.81396","0.12758"
"0.81667","64.63882","0.80520","204.16000","0.00000","0.81667","0.12800"
"0.81917","64.86752","0.80804","204.80000","0.00000","0.81917","0.12840"
"0.82187","65.08784","0.81079","205.44000","0.00000","0.82187","0.12882"
"0.82438","65.27635","0.81314","206.08000","0.00000","0.82437","0.12921"
"0.82688","65.47846","0.81565","206.72000","0.00000","0.82688","0.12960"
"0.82938","65.71129","0.81855","207.36000","0.00000","0.82937","0.13000"
"0.83208","65.91293","0.82107","208.00000","0.00000","0.83208","0.13042"
"0.83479","66.15035","0.82402","208.64000","0.00000","0.83479","0.13085"
"0.83729","66.33819","0.82636","209.28000","0.00000","0.83729","0.13124"
"0.83979","66.55028","0.82901","209.92000","0.00000","0.83979","0.13163"
"0.84250","66.77115","0.83176","210.56000","0.00000","0.84250","0.13205"
"0.84479","66.90575","0.83343","211.20000","0.00000","0.84479","0.13241"
"0.84729","67.13113","0.83624","211.84000","0.00000","0.84729","0.13280"
"0.84979","67.34641","0.83892","212.48000","0.00000","0.84979","0.13320"
"0.85229","67.52462","0.84114","213.12000","0.00000","0.85229","0.13359"
"0.85500","67.73238","0.84373","213.76000","0.00000","0.85500","0.13401"
"0.85750","67.93999","0.84632","214.40000","0.00000","0.85750","0.13440"
"0.86021","68.12453","0.84862","215.04000","0.00000","0.86021","0.13483"
"0.86271","68.32137","0.85107","215.68000","0.00000","0.86271","0.13522"
"0.86521","68.48491","0.85311","216.32000","0.00000","0.86521","0.13561"
"0.86792","68.72414","0.85609","216.96000","0.00000","0.86792","0.13604"
"0.87042","68.94044","0.85878","217.60000","0.00000","0.87042","0.13643"
"0.87313","69.17847","0.86175","218.24000","0.00000","0.87312","0.13685"
"0.87563","69.35612","0.86396","218.88000","0.00000","0.87563","0.13725"
"0.87833","69.59457","0.86693","219.52000","0.00000","0.87833","0.13767"
"0.88083","69.78946","0.86936","220.16000","0.00000","0.88083","0.13806"
"0.88333","69.98972","0.87185","220.80000","0.00000","0.88333","0.13845"
"0.88583","70.23638","0.87492","221.44000","0.00000","0.88583","0.13885"
"0.88854","70.45889","0.87769","222.08000","0.00000","0.88854","0.13927"
"0.89104","70.68411","0.88050","222.72000","0.00000","0.89104","0.13966"
"0.89333","70.83994","0.88244","223.36000","0.00000","0.89333","0.14002"
"0.89604","71.07796","0.88541","224.00000","0.00000","0.89604","0.14045"
"0.89854","71.31691","0.88838","224.64000","0.00000","0.89854","0.14084"
"0.90104","71.51711","0.89088","225.28000","0.00000","0.90104","0.14123"
"0.90354","71.71633","0.89336","225.92000","0.00000","0.90354","0.14162"
"0.90625","71.92057","0.89590","226.56000","0.00000","0.90625","0.14205"
"0.90875","72.13597","0.89859","227.20000","0.00000","0.90875","0.14244"
"0.91146","72.35734","0.90134","227.84000","0.00000","0.91146","0.14286"
"0.91417","72.60912","0.90448","228.48000","0.00000","0.91417","0.14329"
"0.91667","72.79901","0.90685","229.12000","0.00000","0.91667","0.14368"
"0.91938","73.01209","0.90950","229.76000","0.00000","0.91938","0.14410"
"0.92188","73.18484","0.91165","230.40000","0.00000","0.92188","0.14449"
"0.92417","73.35679","0.91379","231.04000","0.00000","0.92417","0.14485"
"0.92688","73.58351","0.91662","231.68000","0.00000","0.92688","0.14528"
"0.92937","73.78174","0.91909","232.32000","0.00000","0.92937","0.14567"
"0.93188","74.00525","0.92187","232.96000","0.00000","0.93187","0.14606"
"0.93438","74.22719","0.92464","233.60000","0.00000","0.93438","0.14645"
"0.93687","74.45781","0.92751","234.24000","0.00000","0.93687","0.14685"
"0.93958","74.68996","0.93040","234.88000","0.00000","0.93958","0.14727"
"0.94208","74.88481","0.93283","235.52000","0.00000","0.94208","0.14766"
"0.94458","75.08344","0.93530","236.16000","0.00000","0.94458","0.14805"
"0.94729","75.34627","0.93858","236.80000","0.00000","0.94729","0.14848"
"0.94979","75.59157","0.94163","237.44000","0.00000","0.94979","0.14887"
"0.95250","75.84124","0.94474","238.08000","0.00000","0.95250","0.14929"
"0.95500","76.00443","0.94677","238.72000","0.00000","0.95500","0.14969"
"0.95771","76.25699","0.94992","239.36000","0.00000","0.95771","0.15011"
"0.96021","76.45902","0.95244","240.00000","0.00000","0.96021","0.15050"
"0.96271","76.65610","0.95489","240.64000","0.00000","0.96271","0.15089"
"0.96542","76.88122","0.95770","241.28000","0.00000","0.96542","0.15132"
"0.96792","77.09573","0.96037","241.92000","0.00000","0.96792","0.15171"
"0.97042","77.30727","0.96300","242.56000","0.00000","0.97042","0.15210"
"0.97271","77.48709","0.96524","243.20000","0.00000","0.97271","0.15246"
"0.97542","77.72122","0.96816","243.84000","0.00000","0.97542","0.15289"
"0.97792","77.94344","0.97093","244.48000","0.00000","0.97792","0.15328"
"0.98042","78.15128","0.97352","245.12000","0.00000","0.98042","0.15367"
"0.98292","78.34805","0.97597","245.76000","0.00000","0.98292","0.15406"
"0.98563","78.57498","0.97880","246.40000","0.00000","0.98563","0.15449"
"0.98813","78.79880","0.98158","247.04000","0.00000","0.98813","0.15488"
"0.99063","79.00394","0.98414","247.68000","0.00000","0.99063","0.15527"
"0.99333","79.26214","0.98736","248.32000","0.00000","0.99333","0.15569"
"0.99583","79.48062","0.99008","248.96000","0.00000","0.99583","0.15609"
"0.99854","79.71743","0.99303","249.60000","0.00000","0.99854","0.15651"
"1.00125","79.95718","0.99601","250.24000","0.00000","1.00125","0.15694"
"1.00375","80.16991","0.99866","250.88000","0.00000","1.00375","0.15733"
"1.00625","80.41258","1.00169","251.52000","0.00000","1.00625","0.15772"
"1.00875","80.58394","1.00382","252.16000","0.00000","1.00875","0.15811"
"1.01104","80.73162","1.00566","252.80000","0.00000","1.01104","0.15847"
"1.01375","81.01795","1.00923","253.44000","0.00000","1.01375","0.15890"
"1.01625","81.27212","1.01239","254.08000","0.00000","1.01625","0.15929"
"1.01875","81.49847","1.01521","254.72000","0.00000","1.01875","0.15968"
"1.02146","81.72285","1.01801","255.36000","0.00000","1.02146","0.16010"
"1.02375","81.86413","1.01977","256.00000","0.00000","1.02375","0.16046"
"1.02646","82.14529","1.02327","256.64000","0.00000","1.02646","0.16089"
"1.02896","82.36236","1.02597","257.28000","0.00000","1.02896","0.16128"
"1.03167","82.64455","1.02949","257.92000","0.00000","1.03167","0.16170"
"1.03417","82.79794","1.03140","258.56000","0.00000","1.03417","0.16210"
"1.03688","83.04240","1.03445","259.20000","0.00000","1.03688","0.16252"
"1.03958","83.27687","1.03737","259.84000","0.00000","1.03958","0.16294"
"1.04208","83.47517","1.03984","260.48000","0.00000","1.04208","0.16334"
"1.04458","83.69981","1.04264","261.12000","0.00000","1.04458","0.16373"
"1.04708","83.89615","1.04508","261.76000","0.00000","1.04708","0.16412"
"1.04958","84.12999","1.04799","262.40000","0.00000","1.04958","0.16451"
"1.05208","84.30573","1.05018","263.04000","0.00000","1.05208","0.16490"
"1.05458","84.60738","1.05394","263.68000","0.00000","1.05458","0.16530"
"1.05729","84.83478","1.05677","264.32000","0.00000","1.05729","0.16572"
"1.05979","85.07954","1.05982","264.96000","0.00000","1.05979","0.16611"
"1.06229","85.27147","1.06221","265.60000","0.00000","1.06229","0.16650"
"1.06479","85.52924","1.06542","266.24000","0.00000","1.06479","0.16690"
"1.06750","85.77818","1.06852","266.88000","0.00000","1.06750","0.16732"
"1.07000","86.03867","1.07177","267.52000","0.00000","1.07000","0.16771"
"1.07271","86.28210","1.07480","268.16000","0.00000","1.07271","0.16814"
"1.07542","86.49881","1.07750","268.80000","0.00000","1.07542","0.16856"
"1.07792","86.74296","1.08054","269.44000","0.00000","1.07792","0.16895"
"1.08063","86.95663","1.08320","270.08000","0.00000","1.08063","0.16938"
"1.08312","87.15540","1.08568","270.72000","0.00000","1.08312","0.16977"
"1.08563","87.35872","1.08821","271.36000","0.00000","1.08563","0.17016"
"1.08812","87.58466","1.09103","272.00000","0.00000","1.08812","0.17055"
"1.09042","87.71969","1.09271","272.64000","0.00000","1.09042","0.17091"
"1.09313","87.99427","1.09613","273.28000","0.00000","1.09313","0.17134"
"1.09563","88.26795","1.09954","273.92000","0.00000","1.09563","0.17173"
"1.09833","88.50081","1.10244","274.56000","0.00000","1.09833","0.17215"
"1.10083","88.72525","1.10524","275.20000","0.00000","1.10083","0.17254"
"1.10333","88.95154","1.10805","275.84000","0.00000","1.10333","0.17294"
"1.10583","89.21288","1.11131","276.48000","0.00000","1.10583","0.17333"
"1.10833","89.42614","1.11397","277.12000","0.00000","1.10833","0.17372"
"1.11104","89.72402","1.11768","277.76000","0.00000","1.11104","0.17414"
"1.11354","89.92054","1.12013","278.40000","0.00000","1.11354","0.17454"
"1.11625","90.22069","1.12386","279.04000","0.00000","1.11625","0.17496"
"1.11896","90.43985","1.12659","279.68000","0.00000","1.11896","0.17539"
"1.12146","90.65679","1.12930","280.32000","0.00000","1.12146","0.17578"
"1.12396","90.87515","1.13202","280.96000","0.00000","1.12396","0.17617"
"1.12667","91.10185","1.13484","281.60000","0.00000","1.12667","0.17659"
"1.12917","91.31707","1.13752","282.24000","0.00000","1.12917","0.17699"
"1.13146","91.48959","1.13967","282.88000","0.00000","1.13146","0.17734"
"1.13396","91.74818","1.14289","283.52000","0.00000","1.13396","0.17774"
"1.13667","92.01479","1.14621","284.16000","0.00000","1.13667","0.17816"
"1.13917","92.24971","1.14914","284.80000","0.00000","1.13917","0.17855"
"1.14167","92.46775","1.15186","285.44000","0.00000","1.14167","0.17894"
"1.14417","92.73713","1.15521","286.08000","0.00000","1.14417","0.17934"
"1.14688","92.97890","1.15822","286.72000","0.00000","1.14688","0.17976"
"1.14938","93.22344","1.16127","287.36000","0.00000","1.14938","0.18015"
"1.15188","93.36268","1.16300","288.00000","0.00000","1.15188","0.18054"
"1.15458","93.74751","1.16780","288.64000","0.00000","1.15458","0.18097"
"1.15729","93.97559","1.17064","289.28000","0.00000","1.15729","0.18139"
"1.16000","94.24297","1.17397","289.92000","0.00000","1.16000","0.18182"
"1.16250","94.43262","1.17633","290.56000","0.00000","1.16250","0.18221"
"1.16500","94.65430","1.17909","291.20000","0.00000","1.16500","0.18260"
"1.16750","94.89733","1.18212","291.84000","0.00000","1.16750","0.18299"
"1.17021","95.12869","1.18500","292.48000","0.00000","1.17021","0.18342"
"1.17250","95.29948","1.18713","293.12000","0.00000","1.17250","0.18378"
"1.17500","95.59266","1.19078","293.76000","0.00000","1.17500","0.18417"
"1.17771","95.84667","1.19395","294.40000","0.00000","1.17771","0.18459"
"1.18021","96.09627","1.19706","295.04000","0.00000","1.18021","0.18499"
"1.18271","96.27514","1.19928","295.68000","0.00000","1.18271","0.18538"
"1.18521","96.61423","1.20351","296.32000","0.00000","1.18521","0.18577"
"1.18771","96.80585","1.20589","296.96000","0.00000","1.18771","0.18616"
"1.19042","97.06220","1.20909","297.60000","0.00000","1.19042","0.18659"
"1.19292","97.33286","1.21246","298.24000","0.00000","1.19292","0.18698"
"1.19563","97.55088","1.21518","298.88000","0.00000","1.19563","0.18740"
"1.19813","97.82372","1.21857","299.52000","0.00000","1.19813","0.18779"
"1.20083","98.02026","1.22102","300.16000","0.00000","1.20083","0.18822"
"1.20333","98.27261","1.22417","300.80000","0.00000","1.20333","0.18861"
"1.20604","98.48374","1.22680","301.44000","0.00000","1.20604","0.18903"
"1.20854","98.69664","1.22945","302.08000","0.00000","1.20854","0.18943"
"1.21104","98.87624","1.23169","302.72000","0.00000","1.21104","0.18982"
"1.21333","99.10201","1.23450","303.36000","0.00000","1.21333","0.19018"
"1.21604","99.35249","1.23762","304.00000","0.00000","1.21604","0.19060"
"1.21854","99.60274","1.24074","304.64000","0.00000","1.21854","0.19099"
"1.22104","99.83013","1.24357","305.28000","0.00000","1.22104","0.19139"
"1.22354","100.11848","1.24716","305.92000","0.00000","1.22354","0.19178"
"1.22625","100.35628","1.25012","306.56000","0.00000","1.22625","0.19220"
"1.22875","100.62743","1.25350","307.20000","0.00000","1.22875","0.19259"
"1.23125","100.81005","1.25577","307.84000","0.00000","1.23125","0.19299"
"1.23396","101.15533","1.26008","308.48000","0.00000","1.23396","0.19341"
"1.23646","101.37067","1.26276","309.12000","0.00000","1.23646","0.19380"
"1.23938","101.68806","1.26671","309.76000","0.00000","1.23938","0.19426"
"1.24167","101.83926","1.26860","310.40000","0.00000","1.24167","0.19462"
"1.24437","102.08212","1.27162","311.04000","0.00000","1.24437","0.19504"
"1.24688","102.34306","1.27487","311.68000","0.00000","1.24688","0.19543"
"1.24958","102.56474","1.27763","312.32000","0.00000","1.24958","0.19586"
"1.25188","102.76013","1.28007","312.96000","0.00000","1.25188","0.19622"
"1.25438","102.96429","1.28261","313.60000","0.00000","1.25438","0.19661"
"1.25688","103.25792","1.28627","314.24000","0.00000","1.25688","0.19700"
"1.25937","103.53319","1.28970","314.88000","0.00000","1.25937","0.19739"
"1.26188","103.77864","1.29275","315.52000","0.00000","1.26188","0.19779"
"1.26458","104.11229","1.29691","316.16000","0.00000","1.26458","0.19821"
"1.26708","104.33998","1.29975","316.80000","0.00000","1.26708","0.19860"
"1.26979","104.59256","1.30289","317.44000","0.00000","1.26979","0.19903"
"1.27229","104.88639","1.30655","318.08000","0.00000","1.27229","0.19942"
"1.27500","105.12859","1.30957","318.72000","0.00000","1.27500","0.19984"
"1.27625","104.76297","1.30502","319.34600","0.00000","1.27625","0.20004"
"1.27625","103.96869","1.29512","319.98600","0.00000","1.27625","0.20004"
"1.27625","103.38935","1.28790","320.62600","0.00000","1.27625","0.20004"
"1.27625","102.91113","1.28195","321.26600","0.00000","1.27625","0.20004"
"1.27625","102.50835","1.27693","321.90600","0.00000","1.27625","0.20004"
"1.27625","102.13492","1.27228","322.54600","0.00000","1.27625","0.20004"
"1.27625","101.80939","1.26822","323.18600","0.00000","1.27625","0.20004"
"1.27625","101.50929","1.26448","323.82600","0.00000","1.27625","0.20004"
"1.27583","101.13969","1.25988","324.46600","0.00000","1.27583","0.19997"
"1.27583","100.89497","1.25683","325.10600","0.00000","1.27583","0.19997"
"1.27583","100.65701","1.25387","325.74600","0.00000","1.27583","0.19997"
"1.27583","100.43752","1.25113","326.38600","0.00000","1.27583","0.19997"
"1.27583","100.23260","1.24858","327.02600","0.00000","1.27583","0.19997"
"1.27583","100.02932","1.24605","327.66600","0.00000","1.27583","0.19997"
"1.27583","99.83645","1.24365","328.30600","0.00000","1.27583","0.19997"
"1.27583","99.64682","1.24128","328.94600","0.00000","1.27583","0.19997"
"1.27583","99.48047","1.23921","329.58600","0.00000","1.27583","0.19997"
"1.27583","99.30145","1.23698","330.22600","0.00000","1.27583","0.19997"
"1.27583","99.15176","1.23512","330.86600","0.00000","1.27583","0.19997"
"1.27583","98.99315","1.23314","331.50600","0.00000","1.27583","0.19997"
"1.27583","98.83613","1.23119","332.14600","0.00000","1.27583","0.19997"
"1.27583","98.70497","1.22955","332.78600","0.00000","1.27583","0.19997"
"1.27583","98.55527","1.22769","333.42600","0.00000","1.27583","0.19997"
"1.27583","98.42245","1.22603","334.06600","0.00000","1.27583","0.19997"
"1.27583","98.27724","1.22422","334.70600","0.00000","1.27583","0.19997"
"1.27583","98.16206","1.22279","335.34600","0.00000","1.27583","0.19997"
"1.27583","98.03370","1.22119","335.98600","0.00000","1.27583","0.19997"
"1.27583","97.92306","1.21981","336.62600","0.00000","1.27583","0.19997"
"1.27583","97.80624","1.21836","337.26600","0.00000","1.27583","0.19997"
"1.27583","97.68284","1.21682","337.90600","0.00000","1.27583","0.19997"
"1.27583","97.57597","1.21549","338.54600","0.00000","1.27583","0.19997"
"1.27583","97.46887","1.21415","339.18600","0.00000","1.27583","0.19997"
"1.27583","97.36754","1.21289","339.82600","0.00000","1.27583","0.19997"
"1.27583","97.25382","1.21148","340.46600","0.00000","1.27583","0.19997"
"1.27583","97.16161","1.21033","341.10600","0.00000","1.27583","0.19997"
"1.27583","97.06565","1.20913","341.74600","0.00000","1.27583","0.19997"
"1.27583","96.96001","1.20782","342.38600","0.00000","1.27583","0.19997"
"1.27583","96.86417","1.20662","343.02600","0.00000","1.27583","0.19997"
"1.27583","96.78162","1.20559","343.66600","0.00000","1.27583","0.19997"
"1.27583","96.69034","1.20446","344.30600","0.00000","1.27583","0.19997"
"1.27583","96.60040","1.20334","344.94600","0.00000","1.27583","0.19997"
"1.27583","96.50832","1.20219","345.58600","0.00000","1.27583","0.19997"
"1.27583","96.42458","1.20115","346.22600","0.00000","1.27583","0.19997"
"1.27583","96.33997","1.20009","346.86600","0.00000","1.27583","0.19997"
"1.27583","96.25558","1.19904","347.50600","0.00000","1.27583","0.19997"
"1.27583","96.18198","1.19812","348.14600","0.00000","1.27583","0.19997"
"1.27583","96.11145","1.19724","348.78600","0.00000","1.27583","0.19997"
"1.27583","96.02964","1.19623","349.42600","0.00000","1.27583","0.19997"
"1.27583","95.95397","1.19528","350.06600","0.00000","1.27583","0.19997"
"1.27583","95.87793","1.19434","350.70600","0.00000","1.27583","0.19997"
"1.27583","95.80090","1.19338","351.34600","0.00000","1.27583","0.19997"
"1.27583","95.73444","1.19255","351.98600","0.00000","1.27583","0.19997"
"1.27583","95.65425","1.19155","352.62600","0.00000","1.27583","0.19997"
"1.27583","95.59269","1.19078","353.26600","0.00000","1.27583","0.19997"
"1.27583","95.52049","1.18988","353.90600","0.00000","1.27583","0.19997"
"1.27583","95.44327","1.18892","354.54600","0.00000","1.27583","0.19997"
"1.27583","95.38210","1.18816","355.18600","0.00000","1.27583","0.19997"
"1.27583","95.32136","1.18740","355.82600","0.00000","1.27583","0.19997"
"1.27583","95.24963","1.18651","356.46600","0.00000","1.27583","0.19997"
"1.27583","95.17910","1.18563","357.10600","0.00000","1.27583","0.19997"
"1.27583","95.12483","1.18495","357.74600","0.00000","1.27583","0.19997"
"1.27583","95.05888","1.18413","358.38600","0.00000","1.27583","0.19997"
"1.27583","94.99216","1.18330","359.02600","0.00000","1.27583","0.19997"
"1.27583","94.93514","1.18259","359.66600","0.00000","1.27583","0.19997"
"1.27583","94.88421","1.18196","360.30600","0.00000","1.27583","0.19997"
"1.27583","94.81060","1.18104","360.94600","0.00000","1.27583","0.19997"
"1.27583","94.75292","1.18032","361.58600","0.00000","1.27583","0.19997"
"1.27583","94.69998","1.17966","362.22600","0.00000","1.27583","0.19997"
"1.27583","94.63970","1.17891","362.86600","0.00000","1.27583","0.19997"
"1.27583","94.58082","1.17818","363.50600","0.00000","1.27583","0.19997"
"1.27583","94.53544","1.17761","364.14600","0.00000","1.27583","0.19997"
"1.27583","94.48032","1.17693","364.78600","0.00000","1.27583","0.19997"
"1.27583","94.41929","1.17617","365.42600","0.00000","1.27583","0.19997"
"1.27583","94.36466","1.17549","366.06600","0.00000","1.27583","0.19997"
"1.27583","94.31342","1.17485","366.70600","0.00000","1.27583","0.19997"
"1.27583","94.26382","1.17423","367.34600","0.00000","1.27583","0.19997"
"1.27583","94.21240","1.17359","367.98600","0.00000","1.27583","0.19997"
"1.27583","94.16100","1.17295","368.62600","0.00000","1.27583","0.19997"
"1.27583","94.11185","1.17234","369.26600","0.00000","1.27583","0.19997"
"1.27583","94.05775","1.17166","369.90600","0.00000","1.27583","0.19997"
"1.27583","94.00975","1.17106","370.54600","0.00000","1.27583","0.19997"
"1.27583","93.95580","1.17039","371.18600","0.00000","1.27583","0.19997"
"1.27583","93.91106","1.16983","371.82600","0.00000","1.27583","0.19997"
"1.27583","93.86732","1.16929","372.46600","0.00000","1.27583","0.19997"
"1.27583","93.80843","1.16856","373.10600","0.00000","1.27583","0.19997"
"1.27583","93.78023","1.16821","373.74600","0.00000","1.27583","0.19997"
"1.27583","93.72238","1.16748","374.38600","0.00000","1.27583","0.19997"
"1.27583","93.67433","1.16689","375.02600","0.00000","1.27583","0.19997"
"1.27583","93.62616","1.16629","375.66600","0.00000","1.27583","0.19997"
"1.27583","93.59521","1.16590","376.30600","0.00000","1.27583","0.19997"
"1.27583","93.53480","1.16515","376.94600","0.00000","1.27583","0.19997"
"1.27583","93.50285","1.16475","377.58600","0.00000","1.27583","0.19997"
"1.27583","93.45235","1.16412","378.22600","0.00000","1.27583","0.19997"
"1.27583","93.41171","1.16361","378.86600","0.00000","1.27583","0.19997"
"1.27583","93.36519","1.16304","379.50600","0.00000","1.27583","0.19997"
"1.27583","93.32396","1.16252","380.14600","0.00000","1.27583","0.19997"
"1.27583","93.28300","1.16201","380.78600","0.00000","1.27583","0.19997"
"1.27583","93.24657","1.16156","381.42600","0.00000","1.27583","0.19997"
"1.27583","93.19727","1.16094","382.06600","0.00000","1.27583","0.19997"
"1.27583","93.16674","1.16056","382.70600","0.00000","1.27583","0.19997"
"1.27583","93.12016","1.15998","383.34600","0.00000","1.27583","0.19997"
"1.27583","93.08160","1.15950","383.98600","0.00000","1.27583","0.19997"
"1.27583","93.04236","1.15901","384.62600","0.00000","1.27583","0.19997"
"1.27583","92.99403","1.15841","385.26600","0.00000","1.27583","0.19997"
"1.27583","92.95735","1.15795","385.90600","0.00000","1.27583","0.19997"
"1.27583","92.92052","1.15750","386.54600","0.00000","1.27583","0.19997"
"1.27583","92.87991","1.15699","387.18600","0.00000","1.27583","0.19997"
"1.27583","92.84334","1.15653","387.82600","0.00000","1.27583","0.19997"
"1.27583","92.80735","1.15609","388.46600","0.00000","1.27583","0.19997"
"1.27583","92.75895","1.15548","389.10600","0.00000","1.27583","0.19997"
"1.27583","92.72639","1.15508","389.74600","0.00000","1.27583","0.19997"
"1.27583","92.68274","1.15453","390.38600","0.00000","1.27583","0.19997"
"1.27583","92.65820","1.15423","391.02600","0.00000","1.27583","0.19997"
"1.27583","92.61456","1.15368","391.66600","0.00000","1.27583","0.19997"
"1.27583","92.57714","1.15322","392.30600","0.00000","1.27583","0.19997"
"1.27583","92.53752","1.15272","392.94600","0.00000","1.27583","0.19997"
"1.27583","92.50613","1.15233","393.58600","0.00000","1.27583","0.19997"
"1.27583","92.46731","1.15185","394.22600","0.00000","1.27583","0.19997"
"1.27583","92.43679","1.15147","394.86600","0.00000","1.27583","0.19997"
"1.27583","92.39360","1.15093","395.50600","0.00000","1.27583","0.19997"
"1.27583","92.36594","1.15059","396.14600","0.00000","1.27583","0.19997"
"1.27583","92.33045","1.15015","396.78600","0.00000","1.27583","0.19997"
"1.27583","92.29353","1.14969","397.42600","0.00000","1.27583","0.19997"
"1.27583","92.25318","1.14918","398.06600","0.00000","1.27583","0.19997"
"1.27583","92.22311","1.14881","398.70600","0.00000","1.27583","0.19997"
"1.27583","92.19206","1.14842","399.34600","0.00000","1.27583","0.19997"
"1.27583","92.15556","1.14797","399.98600","0.00000","1.27583","0.19997"
"1.27583","92.12364","1.14757","400.62600","0.00000","1.27583","0.19997"
"1.27583","92.09845","1.14726","401.26600","0.00000","1.27583","0.19997"
"1.27583","92.06232","1.14681","401.90600","0.00000","1.27583","0.19997"
"1.27583","92.02160","1.14630","402.54600","0.00000","1.27583","0.19997"
"1.27583","92.00068","1.14604","403.18600","0.00000","1.27583","0.19997"
"1.27583","91.96015","1.14553","403.82600","0.00000","1.27583","0.19997"
"1.27583","91.92998","1.14516","404.46600","0.00000","1.27583","0.19997"
"1.27583","91.90409","1.14483","405.10600","0.00000","1.27583","0.19997"
"1.27583","91.86996","1.14441","405.74600","0.00000","1.27583","0.19997"
"1.27583","91.84174","1.14406","406.38600","0.00000","1.27583","0.19997"
"1.27583","91.81263","1.14370","407.02600","0.00000","1.27583","0.19997"
"1.27583","91.79044","1.14342","407.66600","0.00000","1.27583","0.19997"
"1.27583","91.75846","1.14302","408.30600","0.00000","1.27583","0.19997"
"1.27583","91.71603","1.14249","408.94600","0.00000","1.27583","0.19997"
"1.27583","91.69913","1.14228","409.58600","0.00000","1.27583","0.19997"
"1.27583","91.66176","1.14182","410.22600","0.00000","1.27583","0.19997"
"1.27583","91.63448","1.14148","410.86600","0.00000","1.27583","0.19997"
"1.27583","91.60384","1.14109","411.50600","0.00000","1.27583","0.19997"
"1.27583","91.56598","1.14062","412.14600","0.00000","1.27583","0.19997"
"1.27583","91.54529","1.14036","412.78600","0.00000","1.27583","0.19997"
"1.27583","91.51392","1.13997","413.42600","0.00000","1.27583","0.19997"
"1.27583","91.48466","1.13961","414.06600","0.00000","1.27583","0.19997"
"1.27583","91.46177","1.13932","414.70600","0.00000","1.27583","0.19997"
"1.27583","91.43958","1.13905","415.34600","0.00000","1.27583","0.19997"
"1.27583","91.40422","1.13861","415.98600","0.00000","1.27583","0.19997"
"1.27583","91.37923","1.13830","416.62600","0.00000","1.27583","0.19997"
"1.27583","91.34991","1.13793","417.26600","0.00000","1.27583","0.19997"
"1.27583","91.32942","1.13768","417.90600","0.00000","1.27583","0.19997"
"1.27583","91.30521","1.13737","418.54600","0.00000","1.27583","0.19997"
"1.27583","91.27319","1.13698","419.18600","0.00000","1.27583","0.19997"
"1.27583","91.24251","1.13659","419.82600","0.00000","1.27583","0.19997"
"1.27583","91.22237","1.13634","420.46600","0.00000","1.27583","0.19997"
"1.27583","91.19431","1.13599","421.10600","0.00000","1.27583","0.19997"
"1.27583","91.16462","1.13562","421.74600","0.00000","1.27583","0.19997"
"1.27583","91.13934","1.13531","422.38600","0.00000","1.27583","0.19997"
"1.27583","91.10847","1.13492","423.02600","0.00000","1.27583","0.19997"
"1.27583","91.09641","1.13477","423.66600","0.00000","1.27583","0.19997"
"1.27583","91.06931","1.13444","424.30600","0.00000","1.27583","0.19997"
"1.27583","91.04868","1.13418","424.94600","0.00000","1.27583","0.19997"
"1.27583","91.00941","1.13369","425.58600","0.00000","1.27583","0.19997"
"1.27583","90.98784","1.13342","426.22600","0.00000","1.27583","0.19997"
"1.27583","90.96593","1.13315","426.86600","0.00000","1.27583","0.19997"
"1.27583","90.93987","1.13282","427.50600","0.00000","1.27583","0.19997"
"1.27583","90.91220","1.13248","428.14600","0.00000","1.27583","0.19997"
"1.27583","90.88663","1.13216","428.78600","0.00000","1.27583","0.19997"
"1.27583","90.86200","1.13185","429.42600","0.00000","1.27583","0.19997"
"1.27583","90.84040","1.13158","430.06600","0.00000","1.27583","0.19997"
"1.27583","90.81403","1.13126","430.70600","0.00000","1.27583","0.19997"
"1.27583","90.79758","1.13105","431.34600","0.00000","1.27583","0.19997"
"1.27583","90.76711","1.13067","431.98600","0.00000","1.27583","0.19997"
"1.27583","90.74310","1.13037","432.62600","0.00000","1.27583","0.19997"
"1.27583","90.72311","1.13012","433.26600","0.00000","1.27583","0.19997"
"1.27583","90.68410","1.12964","433.90600","0.00000","1.27583","0.19997"
"1.27583","90.67035","1.12947","434.54600","0.00000","1.27583","0.19997"
"1.27583","90.64271","1.12912","435.18600","0.00000","1.27583","0.19997"
"1.27583","90.62103","1.12885","435.82600","0.00000","1.27583","0.19997"
"1.27583","90.59391","1.12851","436.46600","0.00000","1.27583","0.19997"
"1.27583","90.57235","1.12825","437.10600","0.00000","1.27583","0.19997"
"1.27583","90.55452","1.12802","437.74600","0.00000","1.27583","0.19997"
"1.27583","90.53562","1.12779","438.38600","0.00000","1.27583","0.19997"
"1.27583","90.50185","1.12737","438.96600","0.00000","1.27583","0.19997"