File: Rubber Stress Relaxation Raw Data -Large  Samples-20210211/Specimen_RawData_5.csv
Specimen properties : Specimen label,"6"
Specimen properties : Anvil height,"6.30000",mm
Specimen properties : Diameter,"10.42000",mm
Test : Rate 1,"2.40000",mm/min
Test : Start of hold value,"20.00000",%
Test : Duration,"120.00000",s

Extension,Load,Compressive stress,Time,PIP count,Compressive extension,Compressive strain (Extension)
(mm),(N),(MPa),(s),,(mm),(mm/mm)
"0.00000","0.39979","0.00469","0.00000","0.00000","0.00000","0.00000"
"0.00687","1.65290","0.01938","0.23000","0.00000","0.00687","0.00109"
"0.01750","3.42823","0.04020","0.46000","0.00000","0.01750","0.00278"
"0.02750","4.77674","0.05602","0.69000","0.00000","0.02750","0.00437"
"0.03625","5.90975","0.06930","0.92000","0.00000","0.03625","0.00575"
"0.04563","7.13651","0.08369","1.15000","0.00000","0.04563","0.00724"
"0.05479","8.24145","0.09664","1.38000","0.00000","0.05479","0.00870"
"0.06417","9.38234","0.11002","1.61000","0.00000","0.06417","0.01019"
"0.07354","10.46254","0.12269","1.84000","0.00000","0.07354","0.01167"
"0.08250","11.53048","0.13521","2.07000","0.00000","0.08250","0.01310"
"0.09167","12.55438","0.14722","2.30000","0.00000","0.09167","0.01455"
"0.10125","13.62783","0.15981","2.53000","0.00000","0.10125","0.01607"
"0.11063","14.68134","0.17216","2.76000","0.00000","0.11063","0.01756"
"0.11958","15.63270","0.18332","2.99000","0.00000","0.11958","0.01898"
"0.12833","16.57519","0.19437","3.22000","0.00000","0.12833","0.02037"
"0.13771","17.58912","0.20626","3.45000","0.00000","0.13771","0.02186"
"0.14750","18.69375","0.21922","3.68000","0.00000","0.14750","0.02341"
"0.15646","19.58805","0.22970","3.91000","0.00000","0.15646","0.02483"
"0.16542","20.56502","0.24116","4.14000","0.00000","0.16542","0.02626"
"0.17458","21.55022","0.25271","4.37000","0.00000","0.17458","0.02771"
"0.18438","22.60820","0.26512","4.60000","0.00000","0.18438","0.02927"
"0.19375","23.59457","0.27669","4.83000","0.00000","0.19375","0.03075"
"0.20250","24.50422","0.28735","5.06000","0.00000","0.20250","0.03214"
"0.21146","25.41040","0.29798","5.29000","0.00000","0.21146","0.03356"
"0.22063","26.45654","0.31025","5.52000","0.00000","0.22062","0.03502"
"0.23021","27.48224","0.32228","5.75000","0.00000","0.23021","0.03654"
"0.23938","28.42314","0.33331","5.98000","0.00000","0.23938","0.03800"
"0.24813","29.34677","0.34414","6.21000","0.00000","0.24813","0.03938"
"0.25750","30.41259","0.35664","6.44000","0.00000","0.25750","0.04087"
"0.26688","31.49205","0.36930","6.67000","0.00000","0.26688","0.04236"
"0.27625","32.50584","0.38119","6.90000","0.00000","0.27625","0.04385"
"0.28500","33.42231","0.39193","7.13000","0.00000","0.28500","0.04524"
"0.29396","34.49401","0.40450","7.36000","0.00000","0.29396","0.04666"
"0.30354","35.65442","0.41811","7.59000","0.00000","0.30354","0.04818"
"0.31313","36.78369","0.43135","7.82000","0.00000","0.31313","0.04970"
"0.32208","37.82037","0.44351","8.05000","0.00000","0.32208","0.05112"
"0.33104","38.86638","0.45577","8.28000","0.00000","0.33104","0.05255"
"0.34042","40.06894","0.46988","8.51000","0.00000","0.34042","0.05403"
"0.34979","41.26831","0.48394","8.74000","0.00000","0.34979","0.05552"
"0.35917","42.43706","0.49765","8.97000","0.00000","0.35917","0.05701"
"0.36792","43.50075","0.51012","9.20000","0.00000","0.36792","0.05840"
"0.37708","44.76031","0.52489","9.43000","0.00000","0.37708","0.05985"
"0.38646","46.01869","0.53965","9.66000","0.00000","0.38646","0.06134"
"0.39604","47.29441","0.55461","9.89000","0.00000","0.39604","0.06286"
"0.40500","48.34746","0.56695","10.12000","0.00000","0.40500","0.06429"
"0.41375","49.46434","0.58005","10.35000","0.00000","0.41375","0.06567"
"0.42313","50.71084","0.59467","10.58000","0.00000","0.42313","0.06716"
"0.43271","51.83969","0.60791","10.81000","0.00000","0.43271","0.06868"
"0.44188","52.90770","0.62043","11.04000","0.00000","0.44188","0.07014"
"0.45063","53.81274","0.63104","11.27000","0.00000","0.45063","0.07153"
"0.45979","54.97001","0.64462","11.50000","0.00000","0.45979","0.07298"
"0.46896","55.98871","0.65656","11.73000","0.00000","0.46896","0.07444"
"0.47833","57.02050","0.66866","11.96000","0.00000","0.47833","0.07593"
"0.48771","57.98261","0.67994","12.19000","0.00000","0.48771","0.07741"
"0.49667","58.93360","0.69109","12.42000","0.00000","0.49667","0.07884"
"0.50583","59.92090","0.70267","12.65000","0.00000","0.50583","0.08029"
"0.51500","60.85448","0.71362","12.88000","0.00000","0.51500","0.08175"
"0.52438","61.83277","0.72509","13.11000","0.00000","0.52438","0.08323"
"0.53333","62.68594","0.73510","13.34000","0.00000","0.53333","0.08466"
"0.54271","63.74504","0.74752","13.57000","0.00000","0.54271","0.08614"
"0.55208","64.72042","0.75896","13.80000","0.00000","0.55208","0.08763"
"0.56125","65.66707","0.77006","14.03000","0.00000","0.56125","0.08909"
"0.57042","66.57423","0.78069","14.26000","0.00000","0.57042","0.09054"
"0.57958","67.53780","0.79199","14.49000","0.00000","0.57958","0.09200"
"0.58896","68.55460","0.80392","14.72000","0.00000","0.58896","0.09349"
"0.59833","69.51537","0.81518","14.95000","0.00000","0.59833","0.09497"
"0.60750","70.41084","0.82568","15.18000","0.00000","0.60750","0.09643"
"0.61646","71.31785","0.83632","15.41000","0.00000","0.61646","0.09785"
"0.62563","72.29117","0.84773","15.64000","0.00000","0.62563","0.09931"
"0.63479","73.29228","0.85947","15.87000","0.00000","0.63479","0.10076"
"0.64417","74.26443","0.87087","16.10000","0.00000","0.64417","0.10225"
"0.65333","75.19751","0.88182","16.33000","0.00000","0.65333","0.10370"
"0.66229","76.08004","0.89217","16.56000","0.00000","0.66229","0.10513"
"0.67146","77.01459","0.90312","16.79000","0.00000","0.67146","0.10658"
"0.68063","78.04794","0.91524","17.02000","0.00000","0.68063","0.10804"
"0.69000","79.01853","0.92662","17.25000","0.00000","0.69000","0.10952"
"0.69937","80.04210","0.93863","17.48000","0.00000","0.69937","0.11101"
"0.70833","80.94858","0.94926","17.71000","0.00000","0.70833","0.11243"
"0.71750","81.89931","0.96041","17.94000","0.00000","0.71750","0.11389"
"0.72667","82.81988","0.97120","18.17000","0.00000","0.72667","0.11534"
"0.73625","83.85882","0.98338","18.40000","0.00000","0.73625","0.11687"
"0.74542","84.86884","0.99523","18.63000","0.00000","0.74542","0.11832"
"0.75437","85.77788","1.00589","18.86000","0.00000","0.75437","0.11974"
"0.76333","86.69080","1.01659","19.09000","0.00000","0.76333","0.12116"
"0.77271","87.74999","1.02902","19.32000","0.00000","0.77271","0.12265"
"0.78229","88.80315","1.04137","19.55000","0.00000","0.78229","0.12417"
"0.79104","89.72955","1.05223","19.78000","0.00000","0.79104","0.12556"
"0.80021","90.68800","1.06347","20.01000","0.00000","0.80021","0.12702"
"0.80958","91.75950","1.07603","20.24000","0.00000","0.80958","0.12851"
"0.81917","92.87606","1.08913","20.47000","0.00000","0.81917","0.13003"
"0.82813","93.74639","1.09933","20.70000","0.00000","0.82813","0.13145"
"0.83729","94.72306","1.11079","20.93000","0.00000","0.83729","0.13290"
"0.84625","95.66872","1.12188","21.16000","0.00000","0.84625","0.13433"
"0.85563","96.73147","1.13434","21.39000","0.00000","0.85563","0.13581"
"0.86500","97.79573","1.14682","21.62000","0.00000","0.86500","0.13730"
"0.87396","98.67499","1.15713","21.85000","0.00000","0.87396","0.13872"
"0.88292","99.64687","1.16853","22.08000","0.00000","0.88292","0.14015"
"0.89229","100.77039","1.18170","22.31000","0.00000","0.89229","0.14163"
"0.90188","101.90099","1.19496","22.54000","0.00000","0.90187","0.14315"
"0.91063","102.75102","1.20493","22.77000","0.00000","0.91062","0.14454"
"0.91958","103.79784","1.21720","23.00000","0.00000","0.91958","0.14597"
"0.92917","104.95967","1.23083","23.23000","0.00000","0.92917","0.14749"
"0.93875","106.10465","1.24425","23.46000","0.00000","0.93875","0.14901"
"0.94792","107.08196","1.25571","23.69000","0.00000","0.94792","0.15046"
"0.95688","108.02546","1.26678","23.92000","0.00000","0.95687","0.15188"
"0.96583","109.02811","1.27854","24.15000","0.00000","0.96583","0.15331"
"0.97521","110.22220","1.29254","24.38000","0.00000","0.97521","0.15479"
"0.98479","111.36066","1.30589","24.61000","0.00000","0.98479","0.15632"
"0.99354","112.23653","1.31616","24.84000","0.00000","0.99354","0.15771"
"1.00250","113.24904","1.32803","25.07000","0.00000","1.00250","0.15913"
"1.01188","114.44585","1.34207","25.30000","0.00000","1.01188","0.16062"
"1.02167","115.72924","1.35712","25.53000","0.00000","1.02167","0.16217"
"1.03063","116.65338","1.36796","25.76000","0.00000","1.03063","0.16359"
"1.03958","117.66089","1.37977","25.99000","0.00000","1.03958","0.16501"
"1.04854","118.71363","1.39212","26.22000","0.00000","1.04854","0.16644"
"1.05813","119.94725","1.40658","26.45000","0.00000","1.05813","0.16796"
"1.06750","121.10056","1.42011","26.68000","0.00000","1.06750","0.16944"
"1.07625","122.03608","1.43108","26.91000","0.00000","1.07625","0.17083"
"1.08521","123.12984","1.44390","27.14000","0.00000","1.08521","0.17226"
"1.09479","124.39220","1.45871","27.37000","0.00000","1.09479","0.17378"
"1.10438","125.60266","1.47290","27.60000","0.00000","1.10438","0.17530"
"1.11333","126.53368","1.48382","27.83000","0.00000","1.11333","0.17672"
"1.12188","127.50488","1.49521","28.06000","0.00000","1.12188","0.17808"
"1.13125","128.79243","1.51031","28.29000","0.00000","1.13125","0.17956"
"1.14083","130.06825","1.52527","28.52000","0.00000","1.14083","0.18108"
"1.15021","131.21336","1.53870","28.75000","0.00000","1.15021","0.18257"
"1.15917","132.16345","1.54984","28.98000","0.00000","1.15917","0.18399"
"1.16813","133.34149","1.56365","29.21000","0.00000","1.16813","0.18542"
"1.17771","134.68788","1.57944","29.44000","0.00000","1.17771","0.18694"
"1.18708","135.92004","1.59389","29.67000","0.00000","1.18708","0.18843"
"1.19625","136.98961","1.60643","29.90000","0.00000","1.19625","0.18988"
"1.20500","138.00310","1.61832","30.13000","0.00000","1.20500","0.19127"
"1.21438","139.31030","1.63365","30.36000","0.00000","1.21438","0.19276"
"1.22375","140.62663","1.64908","30.59000","0.00000","1.22375","0.19425"
"1.23333","141.87146","1.66368","30.82000","0.00000","1.23333","0.19577"
"1.24188","142.76227","1.67413","31.05000","0.00000","1.24188","0.19712"
"1.25104","143.96223","1.68820","31.28000","0.00000","1.25104","0.19858"
"1.26021","145.31146","1.70402","31.50400","0.00000","1.26021","0.20003"
"1.26167","142.80472","1.67462","31.72600","0.00000","1.26167","0.20026"
"1.26167","140.27011","1.64490","31.95600","0.00000","1.26167","0.20026"
"1.26167","138.45003","1.62356","32.18600","0.00000","1.26167","0.20026"
"1.26167","137.00603","1.60662","32.41600","0.00000","1.26167","0.20026"
"1.26167","135.80153","1.59250","32.64600","0.00000","1.26167","0.20026"
"1.26104","134.61890","1.57863","32.87600","0.00000","1.26104","0.20017"
"1.26104","133.73427","1.56826","33.10600","0.00000","1.26104","0.20017"
"1.26104","132.93666","1.55890","33.33600","0.00000","1.26104","0.20017"
"1.26104","132.15419","1.54973","33.56600","0.00000","1.26104","0.20017"
"1.26083","131.44073","1.54136","33.79600","0.00000","1.26083","0.20013"
"1.26063","130.73373","1.53307","34.02600","0.00000","1.26063","0.20010"
"1.26063","130.17566","1.52653","34.25600","0.00000","1.26063","0.20010"
"1.26042","129.58522","1.51960","34.48600","0.00000","1.26042","0.20007"
"1.26042","129.08495","1.51374","34.71600","0.00000","1.26042","0.20007"
"1.26042","128.60144","1.50807","34.94600","0.00000","1.26042","0.20007"
"1.26021","128.10172","1.50221","35.17600","0.00000","1.26021","0.20003"
"1.26021","127.68330","1.49730","35.40600","0.00000","1.26021","0.20003"
"1.26021","127.29642","1.49276","35.63600","0.00000","1.26021","0.20003"
"1.26021","126.90228","1.48814","35.86600","0.00000","1.26021","0.20003"
"1.26021","126.53628","1.48385","36.09600","0.00000","1.26021","0.20003"
"1.26021","126.19038","1.47979","36.32600","0.00000","1.26021","0.20003"
"1.26021","125.85108","1.47581","36.55600","0.00000","1.26021","0.20003"
"1.26021","125.53640","1.47212","36.78600","0.00000","1.26021","0.20003"
"1.26021","125.20683","1.46826","37.01600","0.00000","1.26021","0.20003"
"1.26021","124.92799","1.46499","37.24600","0.00000","1.26021","0.20003"
"1.26021","124.62543","1.46144","37.47600","0.00000","1.26021","0.20003"
"1.26021","124.34584","1.45816","37.70600","0.00000","1.26021","0.20003"
"1.26021","124.08650","1.45512","37.93600","0.00000","1.26021","0.20003"
"1.26021","123.80385","1.45181","38.16600","0.00000","1.26021","0.20003"
"1.26021","123.56509","1.44901","38.39600","0.00000","1.26021","0.20003"
"1.26021","123.31493","1.44607","38.62600","0.00000","1.26021","0.20003"
"1.26021","123.07140","1.44322","38.85600","0.00000","1.26021","0.20003"
"1.26021","122.84669","1.44058","39.08600","0.00000","1.26021","0.20003"
"1.26021","122.60984","1.43781","39.31600","0.00000","1.26021","0.20003"
"1.26021","122.39952","1.43534","39.54600","0.00000","1.26021","0.20003"
"1.26021","122.17664","1.43273","39.77600","0.00000","1.26021","0.20003"
"1.26021","121.96801","1.43028","40.00600","0.00000","1.26021","0.20003"
"1.26021","121.76452","1.42789","40.23600","0.00000","1.26021","0.20003"
"1.26021","121.56343","1.42553","40.46600","0.00000","1.26021","0.20003"
"1.26021","121.37302","1.42330","40.69600","0.00000","1.26021","0.20003"
"1.26021","121.17448","1.42097","40.92600","0.00000","1.26021","0.20003"
"1.26021","120.99788","1.41890","41.15600","0.00000","1.26021","0.20003"
"1.26021","120.81051","1.41670","41.38600","0.00000","1.26021","0.20003"
"1.26021","120.63104","1.41460","41.61600","0.00000","1.26021","0.20003"
"1.26021","120.45472","1.41253","41.84600","0.00000","1.26021","0.20003"
"1.26021","120.27773","1.41046","42.07600","0.00000","1.26021","0.20003"
"1.26021","120.11440","1.40854","42.30600","0.00000","1.26021","0.20003"
"1.26021","119.95377","1.40666","42.53600","0.00000","1.26021","0.20003"
"1.26021","119.80136","1.40487","42.76600","0.00000","1.26021","0.20003"
"1.26021","119.62661","1.40282","42.99600","0.00000","1.26021","0.20003"
"1.26021","119.48760","1.40119","43.22600","0.00000","1.26021","0.20003"
"1.26021","119.32308","1.39926","43.45600","0.00000","1.26021","0.20003"
"1.26021","119.18473","1.39764","43.68600","0.00000","1.26021","0.20003"
"1.26021","119.03098","1.39584","43.91600","0.00000","1.26021","0.20003"
"1.26021","118.88828","1.39416","44.14600","0.00000","1.26021","0.20003"
"1.26021","118.75740","1.39263","44.37600","0.00000","1.26021","0.20003"
"1.26021","118.60983","1.39090","44.60600","0.00000","1.26021","0.20003"
"1.26021","118.46825","1.38924","44.83600","0.00000","1.26021","0.20003"
"1.26021","118.34235","1.38776","45.06600","0.00000","1.26021","0.20003"
"1.26021","118.21624","1.38628","45.29600","0.00000","1.26021","0.20003"
"1.26021","118.07780","1.38466","45.52600","0.00000","1.26021","0.20003"
"1.26021","117.95961","1.38327","45.75600","0.00000","1.26021","0.20003"
"1.26021","117.82446","1.38169","45.98600","0.00000","1.26021","0.20003"
"1.26021","117.71265","1.38038","46.21600","0.00000","1.26021","0.20003"
"1.26021","117.57717","1.37879","46.44600","0.00000","1.26021","0.20003"
"1.26021","117.47012","1.37753","46.67600","0.00000","1.26021","0.20003"
"1.26021","117.33235","1.37592","46.90600","0.00000","1.26021","0.20003"
"1.26021","117.23212","1.37474","47.13600","0.00000","1.26021","0.20003"
"1.26021","117.10522","1.37325","47.36600","0.00000","1.26021","0.20003"
"1.26021","117.01291","1.37217","47.59600","0.00000","1.26021","0.20003"
"1.26021","116.89179","1.37075","47.82600","0.00000","1.26021","0.20003"
"1.26021","116.78285","1.36947","48.05600","0.00000","1.26021","0.20003"
"1.26021","116.66908","1.36814","48.28600","0.00000","1.26021","0.20003"
"1.26021","116.56398","1.36691","48.51600","0.00000","1.26021","0.20003"
"1.26021","116.46355","1.36573","48.74600","0.00000","1.26021","0.20003"
"1.26021","116.35716","1.36448","48.97600","0.00000","1.26021","0.20003"
"1.26021","116.25176","1.36325","49.20600","0.00000","1.26021","0.20003"
"1.26021","116.15213","1.36208","49.43600","0.00000","1.26021","0.20003"
"1.26021","116.05624","1.36095","49.66600","0.00000","1.26021","0.20003"
"1.26021","115.95368","1.35975","49.89600","0.00000","1.26021","0.20003"
"1.26021","115.85308","1.35857","50.12600","0.00000","1.26021","0.20003"
"1.26021","115.75806","1.35746","50.35600","0.00000","1.26021","0.20003"
"1.26021","115.66620","1.35638","50.58600","0.00000","1.26021","0.20003"
"1.26021","115.56947","1.35524","50.81600","0.00000","1.26021","0.20003"
"1.26021","115.49220","1.35434","51.04600","0.00000","1.26021","0.20003"
"1.26021","115.38545","1.35309","51.27600","0.00000","1.26021","0.20003"
"1.26021","115.31223","1.35223","51.50600","0.00000","1.26021","0.20003"
"1.26021","115.21602","1.35110","51.73600","0.00000","1.26021","0.20003"
"1.26021","115.13042","1.35010","51.96600","0.00000","1.26021","0.20003"
"1.26021","115.03561","1.34898","52.19600","0.00000","1.26021","0.20003"
"1.26021","114.95456","1.34803","52.42600","0.00000","1.26021","0.20003"
"1.26021","114.85810","1.34690","52.65600","0.00000","1.26021","0.20003"
"1.26021","114.78831","1.34608","52.88600","0.00000","1.26021","0.20003"
"1.26021","114.69445","1.34498","53.11600","0.00000","1.26021","0.20003"
"1.26021","114.62171","1.34413","53.34600","0.00000","1.26021","0.20003"
"1.26021","114.53534","1.34312","53.57600","0.00000","1.26021","0.20003"
"1.26021","114.45409","1.34217","53.80600","0.00000","1.26021","0.20003"
"1.26021","114.38409","1.34134","54.03600","0.00000","1.26021","0.20003"
"1.26021","114.29852","1.34034","54.26600","0.00000","1.26021","0.20003"
"1.26021","114.22169","1.33944","54.49600","0.00000","1.26021","0.20003"
"1.26021","114.14167","1.33850","54.72600","0.00000","1.26021","0.20003"
"1.26021","114.06019","1.33755","54.95600","0.00000","1.26021","0.20003"
"1.26021","113.98635","1.33668","55.18600","0.00000","1.26021","0.20003"
"1.26021","113.91933","1.33589","55.41600","0.00000","1.26021","0.20003"
"1.26021","113.83541","1.33491","55.64600","0.00000","1.26021","0.20003"
"1.26021","113.77302","1.33418","55.87600","0.00000","1.26021","0.20003"
"1.26021","113.68803","1.33318","56.10600","0.00000","1.26021","0.20003"
"1.26021","113.63284","1.33253","56.33600","0.00000","1.26021","0.20003"
"1.26021","113.54798","1.33154","56.56600","0.00000","1.26021","0.20003"
"1.26021","113.48367","1.33079","56.79600","0.00000","1.26021","0.20003"
"1.26021","113.41266","1.32995","57.02600","0.00000","1.26021","0.20003"
"1.26021","113.34291","1.32913","57.25600","0.00000","1.26021","0.20003"
"1.26021","113.28084","1.32841","57.48600","0.00000","1.26021","0.20003"
"1.26021","113.20145","1.32748","57.71600","0.00000","1.26021","0.20003"
"1.26021","113.14220","1.32678","57.94600","0.00000","1.26021","0.20003"
"1.26021","113.07844","1.32603","58.17600","0.00000","1.26021","0.20003"
"1.26021","113.00694","1.32520","58.40600","0.00000","1.26021","0.20003"
"1.26021","112.93922","1.32440","58.63600","0.00000","1.26021","0.20003"
"1.26021","112.88355","1.32375","58.86600","0.00000","1.26021","0.20003"
"1.26021","112.80479","1.32282","59.09600","0.00000","1.26021","0.20003"
"1.26021","112.74963","1.32218","59.32600","0.00000","1.26021","0.20003"
"1.26021","112.68195","1.32138","59.55600","0.00000","1.26021","0.20003"
"1.26021","112.62589","1.32073","59.78600","0.00000","1.26021","0.20003"
"1.26021","112.56520","1.32001","60.01600","0.00000","1.26021","0.20003"
"1.26021","112.50708","1.31933","60.24600","0.00000","1.26021","0.20003"
"1.26021","112.45138","1.31868","60.47600","0.00000","1.26021","0.20003"
"1.26021","112.38577","1.31791","60.70600","0.00000","1.26021","0.20003"
"1.26021","112.32034","1.31714","60.93600","0.00000","1.26021","0.20003"
"1.26021","112.26572","1.31650","61.16600","0.00000","1.26021","0.20003"
"1.26021","112.20317","1.31577","61.39600","0.00000","1.26021","0.20003"
"1.26021","112.14227","1.31506","61.62600","0.00000","1.26021","0.20003"
"1.26021","112.09566","1.31451","61.85600","0.00000","1.26021","0.20003"
"1.26021","112.02352","1.31366","62.08600","0.00000","1.26021","0.20003"
"1.26021","111.96782","1.31301","62.31600","0.00000","1.26021","0.20003"
"1.26021","111.91623","1.31240","62.54600","0.00000","1.26021","0.20003"
"1.26021","111.85019","1.31163","62.77600","0.00000","1.26021","0.20003"
"1.26021","111.80913","1.31115","63.00600","0.00000","1.26021","0.20003"
"1.26021","111.74670","1.31042","63.23600","0.00000","1.26021","0.20003"
"1.26021","111.68817","1.30973","63.46600","0.00000","1.26021","0.20003"
"1.26021","111.63908","1.30915","63.69600","0.00000","1.26021","0.20003"
"1.26021","111.58289","1.30850","63.92600","0.00000","1.26021","0.20003"
"1.26021","111.52950","1.30787","64.15600","0.00000","1.26021","0.20003"
"1.26021","111.46903","1.30716","64.38600","0.00000","1.26021","0.20003"
"1.26021","111.42104","1.30660","64.61600","0.00000","1.26021","0.20003"
"1.26021","111.36494","1.30594","64.84600","0.00000","1.26021","0.20003"
"1.26021","111.31839","1.30539","65.07600","0.00000","1.26021","0.20003"
"1.26021","111.26573","1.30478","65.30600","0.00000","1.26021","0.20003"
"1.26021","111.21193","1.30415","65.53600","0.00000","1.26021","0.20003"
"1.26021","111.16227","1.30356","65.76600","0.00000","1.26021","0.20003"
"1.26021","111.10661","1.30291","65.99600","0.00000","1.26021","0.20003"
"1.26021","111.05711","1.30233","66.22600","0.00000","1.26021","0.20003"
"1.26021","111.01074","1.30179","66.45600","0.00000","1.26021","0.20003"
"1.26021","110.95525","1.30114","66.68600","0.00000","1.26021","0.20003"
"1.26021","110.90881","1.30059","66.91600","0.00000","1.26021","0.20003"
"1.26021","110.86702","1.30010","67.14600","0.00000","1.26021","0.20003"
"1.26021","110.81076","1.29944","67.37600","0.00000","1.26021","0.20003"
"1.26021","110.76148","1.29886","67.60600","0.00000","1.26021","0.20003"
"1.26021","110.72050","1.29838","67.83600","0.00000","1.26021","0.20003"
"1.26021","110.67294","1.29783","68.06600","0.00000","1.26021","0.20003"
"1.26021","110.62560","1.29727","68.29600","0.00000","1.26021","0.20003"
"1.26021","110.57781","1.29671","68.52600","0.00000","1.26021","0.20003"
"1.26021","110.52540","1.29609","68.75600","0.00000","1.26021","0.20003"
"1.26021","110.48665","1.29564","68.98600","0.00000","1.26021","0.20003"
"1.26021","110.43836","1.29507","69.21600","0.00000","1.26021","0.20003"
"1.26021","110.40266","1.29466","69.44600","0.00000","1.26021","0.20003"
"1.26021","110.34982","1.29404","69.67600","0.00000","1.26021","0.20003"
"1.26021","110.30207","1.29348","69.90600","0.00000","1.26021","0.20003"
"1.26021","110.25685","1.29295","70.13600","0.00000","1.26021","0.20003"
"1.26021","110.22405","1.29256","70.36600","0.00000","1.26021","0.20003"
"1.26021","110.16666","1.29189","70.59600","0.00000","1.26021","0.20003"
"1.26021","110.13588","1.29153","70.82600","0.00000","1.26021","0.20003"
"1.26021","110.07869","1.29086","71.05600","0.00000","1.26021","0.20003"
"1.26021","110.05361","1.29056","71.28600","0.00000","1.26021","0.20003"
"1.26021","109.99842","1.28992","71.51600","0.00000","1.26021","0.20003"
"1.26021","109.96095","1.28948","71.74600","0.00000","1.26021","0.20003"
"1.26021","109.90318","1.28880","71.97600","0.00000","1.26021","0.20003"
"1.26021","109.86966","1.28841","72.20600","0.00000","1.26021","0.20003"
"1.26021","109.82580","1.28789","72.43600","0.00000","1.26021","0.20003"
"1.26021","109.77448","1.28729","72.66600","0.00000","1.26021","0.20003"
"1.26021","109.73952","1.28688","72.89600","0.00000","1.26021","0.20003"
"1.26021","109.70050","1.28642","73.12600","0.00000","1.26021","0.20003"
"1.26021","109.65402","1.28588","73.35600","0.00000","1.26021","0.20003"
"1.26021","109.61885","1.28546","73.58600","0.00000","1.26021","0.20003"
"1.26021","109.57655","1.28497","73.81600","0.00000","1.26021","0.20003"
"1.26021","109.53549","1.28449","74.04600","0.00000","1.26021","0.20003"
"1.26021","109.48690","1.28392","74.27600","0.00000","1.26021","0.20003"
"1.26021","109.45938","1.28359","74.50600","0.00000","1.26021","0.20003"
"1.26021","109.41676","1.28309","74.73600","0.00000","1.26021","0.20003"
"1.26021","109.36811","1.28252","74.96600","0.00000","1.26021","0.20003"
"1.26021","109.33389","1.28212","75.19600","0.00000","1.26021","0.20003"
"1.26021","109.29359","1.28165","75.42600","0.00000","1.26021","0.20003"
"1.26021","109.25898","1.28124","75.65600","0.00000","1.26021","0.20003"
"1.26021","109.22427","1.28084","75.88600","0.00000","1.26021","0.20003"
"1.26021","109.18027","1.28032","76.11600","0.00000","1.26021","0.20003"
"1.26021","109.13839","1.27983","76.34600","0.00000","1.26021","0.20003"
"1.26021","109.10767","1.27947","76.57600","0.00000","1.26021","0.20003"
"1.26021","109.07041","1.27903","76.80600","0.00000","1.26021","0.20003"
"1.26021","109.02438","1.27849","77.03600","0.00000","1.26021","0.20003"
"1.26021","109.00312","1.27824","77.26600","0.00000","1.26021","0.20003"
"1.26021","108.95145","1.27764","77.49600","0.00000","1.26021","0.20003"
"1.26021","108.92479","1.27733","77.72600","0.00000","1.26021","0.20003"
"1.26021","108.88523","1.27686","77.95600","0.00000","1.26021","0.20003"
"1.26021","108.84335","1.27637","78.18600","0.00000","1.26021","0.20003"
"1.26021","108.81252","1.27601","78.41600","0.00000","1.26021","0.20003"
"1.26021","108.77711","1.27559","78.64600","0.00000","1.26021","0.20003"
"1.26021","108.73525","1.27510","78.87600","0.00000","1.26021","0.20003"
"1.26021","108.70528","1.27475","79.10600","0.00000","1.26021","0.20003"
"1.26021","108.67017","1.27434","79.33600","0.00000","1.26021","0.20003"
"1.26021","108.62620","1.27382","79.56600","0.00000","1.26021","0.20003"
"1.26021","108.59316","1.27344","79.79600","0.00000","1.26021","0.20003"
"1.26021","108.55959","1.27304","80.02600","0.00000","1.26021","0.20003"
"1.26021","108.52503","1.27264","80.25600","0.00000","1.26021","0.20003"
"1.26021","108.49575","1.27229","80.48600","0.00000","1.26021","0.20003"
"1.26021","108.44929","1.27175","80.71600","0.00000","1.26021","0.20003"
"1.26021","108.42930","1.27151","80.94600","0.00000","1.26021","0.20003"
"1.26021","108.39695","1.27114","81.17600","0.00000","1.26021","0.20003"
"1.26021","108.35894","1.27069","81.40600","0.00000","1.26021","0.20003"
"1.26021","108.31801","1.27021","81.63600","0.00000","1.26021","0.20003"
"1.26021","108.28339","1.26980","81.86600","0.00000","1.26021","0.20003"
"1.26021","108.25036","1.26942","82.09600","0.00000","1.26021","0.20003"
"1.26021","108.22060","1.26907","82.32600","0.00000","1.26021","0.20003"
"1.26021","108.18575","1.26866","82.55600","0.00000","1.26021","0.20003"
"1.26021","108.16209","1.26838","82.78600","0.00000","1.26021","0.20003"
"1.26021","108.11854","1.26787","83.01600","0.00000","1.26021","0.20003"
"1.26021","108.09529","1.26760","83.24600","0.00000","1.26021","0.20003"
"1.26021","108.06022","1.26719","83.47600","0.00000","1.26021","0.20003"
"1.26021","108.02848","1.26681","83.70600","0.00000","1.26021","0.20003"
"1.26021","107.98750","1.26633","83.93600","0.00000","1.26021","0.20003"
"1.26021","107.96545","1.26608","84.16600","0.00000","1.26021","0.20003"
"1.26021","107.92465","1.26560","84.39600","0.00000","1.26021","0.20003"
"1.26021","107.89137","1.26521","84.62600","0.00000","1.26021","0.20003"
"1.26021","107.86410","1.26489","84.85600","0.00000","1.26021","0.20003"
"1.26021","107.82674","1.26445","85.08600","0.00000","1.26021","0.20003"
"1.26021","107.79604","1.26409","85.31600","0.00000","1.26021","0.20003"
"1.26021","107.76680","1.26375","85.54600","0.00000","1.26021","0.20003"
"1.26021","107.74004","1.26343","85.77600","0.00000","1.26021","0.20003"
"1.26021","107.70502","1.26302","86.00600","0.00000","1.26021","0.20003"
"1.26021","107.67506","1.26267","86.23600","0.00000","1.26021","0.20003"
"1.26021","107.64497","1.26232","86.46600","0.00000","1.26021","0.20003"
"1.26021","107.61583","1.26198","86.69600","0.00000","1.26021","0.20003"
"1.26021","107.58913","1.26166","86.92600","0.00000","1.26021","0.20003"
"1.26021","107.54946","1.26120","87.15600","0.00000","1.26021","0.20003"
"1.26021","107.52606","1.26092","87.38600","0.00000","1.26021","0.20003"
"1.26021","107.49412","1.26055","87.61600","0.00000","1.26021","0.20003"
"1.26021","107.47569","1.26033","87.84600","0.00000","1.26021","0.20003"
"1.26021","107.43376","1.25984","88.07600","0.00000","1.26021","0.20003"
"1.26021","107.39600","1.25940","88.30600","0.00000","1.26021","0.20003"
"1.26021","107.37809","1.25919","88.53600","0.00000","1.26021","0.20003"
"1.26021","107.34966","1.25885","88.76600","0.00000","1.26021","0.20003"
"1.26021","107.32486","1.25856","88.99600","0.00000","1.26021","0.20003"
"1.26021","107.29214","1.25818","89.22600","0.00000","1.26021","0.20003"
"1.26021","107.25942","1.25780","89.45600","0.00000","1.26021","0.20003"
"1.26021","107.23824","1.25755","89.68600","0.00000","1.26021","0.20003"
"1.26021","107.20557","1.25716","89.91600","0.00000","1.26021","0.20003"
"1.26021","107.18440","1.25692","90.14600","0.00000","1.26021","0.20003"
"1.26021","107.14913","1.25650","90.37600","0.00000","1.26021","0.20003"
"1.26021","107.11459","1.25610","90.60600","0.00000","1.26021","0.20003"
"1.26021","107.09937","1.25592","90.83600","0.00000","1.26021","0.20003"
"1.26021","107.06748","1.25555","91.06600","0.00000","1.26021","0.20003"
"1.26021","107.03751","1.25519","91.29600","0.00000","1.26021","0.20003"
"1.26021","107.01424","1.25492","91.52600","0.00000","1.26021","0.20003"
"1.26021","106.98435","1.25457","91.75600","0.00000","1.26021","0.20003"
"1.26021","106.95332","1.25421","91.98600","0.00000","1.26021","0.20003"
"1.26021","106.92712","1.25390","92.21600","0.00000","1.26021","0.20003"
"1.26021","106.90860","1.25368","92.44600","0.00000","1.26021","0.20003"
"1.26021","106.87933","1.25334","92.67600","0.00000","1.26021","0.20003"
"1.26021","106.85126","1.25301","92.90600","0.00000","1.26021","0.20003"
"1.26021","106.83121","1.25277","93.13600","0.00000","1.26021","0.20003"
"1.26021","106.80302","1.25244","93.36600","0.00000","1.26021","0.20003"
"1.26021","106.76187","1.25196","93.59600","0.00000","1.26021","0.20003"
"1.26021","106.75231","1.25185","93.82600","0.00000","1.26021","0.20003"
"1.26021","106.71929","1.25146","94.05600","0.00000","1.26021","0.20003"
"1.26021","106.68830","1.25110","94.28600","0.00000","1.26021","0.20003"
"1.26021","106.66071","1.25077","94.51600","0.00000","1.26021","0.20003"
"1.26021","106.64106","1.25054","94.74600","0.00000","1.26021","0.20003"
"1.26021","106.61650","1.25026","94.97600","0.00000","1.26021","0.20003"
"1.26021","106.58672","1.24991","95.20600","0.00000","1.26021","0.20003"
"1.26021","106.56383","1.24964","95.43600","0.00000","1.26021","0.20003"
"1.26021","106.53089","1.24925","95.66600","0.00000","1.26021","0.20003"
"1.26021","106.50991","1.24901","95.89600","0.00000","1.26021","0.20003"
"1.26021","106.48990","1.24877","96.12600","0.00000","1.26021","0.20003"
"1.26021","106.45626","1.24838","96.35600","0.00000","1.26021","0.20003"
"1.26021","106.43430","1.24812","96.58600","0.00000","1.26021","0.20003"
"1.26021","106.41048","1.24784","96.81600","0.00000","1.26021","0.20003"
"1.26021","106.38387","1.24753","97.04600","0.00000","1.26021","0.20003"
"1.26021","106.35982","1.24725","97.27600","0.00000","1.26021","0.20003"
"1.26021","106.33748","1.24698","97.50600","0.00000","1.26021","0.20003"
"1.26021","106.30464","1.24660","97.73600","0.00000","1.26021","0.20003"
"1.26021","106.28205","1.24633","97.96600","0.00000","1.26021","0.20003"
"1.26021","106.26176","1.24610","98.19600","0.00000","1.26021","0.20003"
"1.26021","106.23490","1.24578","98.42600","0.00000","1.26021","0.20003"
"1.26021","106.21266","1.24552","98.65600","0.00000","1.26021","0.20003"
"1.26021","106.17674","1.24510","98.88600","0.00000","1.26021","0.20003"
"1.26021","106.15826","1.24488","99.11600","0.00000","1.26021","0.20003"
"1.26021","106.14246","1.24470","99.34600","0.00000","1.26021","0.20003"
"1.26021","106.11379","1.24436","99.57600","0.00000","1.26021","0.20003"
"1.26021","106.09191","1.24410","99.80600","0.00000","1.26021","0.20003"
"1.26021","106.06074","1.24374","100.03600","0.00000","1.26021","0.20003"
"1.26021","106.04515","1.24356","100.26600","0.00000","1.26021","0.20003"
"1.26021","106.01211","1.24317","100.49600","0.00000","1.26021","0.20003"
"1.26021","105.99844","1.24301","100.72600","0.00000","1.26021","0.20003"
"1.26021","105.97123","1.24269","100.95600","0.00000","1.26021","0.20003"
"1.26021","105.94608","1.24239","101.18600","0.00000","1.26021","0.20003"
"1.26021","105.92439","1.24214","101.41600","0.00000","1.26021","0.20003"
"1.26021","105.89158","1.24176","101.64600","0.00000","1.26021","0.20003"
"1.26021","105.86944","1.24150","101.87600","0.00000","1.26021","0.20003"
"1.26021","105.85075","1.24128","102.10600","0.00000","1.26021","0.20003"
"1.26021","105.82759","1.24101","102.33600","0.00000","1.26021","0.20003"
"1.26021","105.80863","1.24078","102.56600","0.00000","1.26021","0.20003"
"1.26021","105.77816","1.24043","102.79600","0.00000","1.26021","0.20003"
"1.26021","105.76115","1.24023","103.02600","0.00000","1.26021","0.20003"
"1.26021","105.72562","1.23981","103.25600","0.00000","1.26021","0.20003"
"1.26021","105.71767","1.23972","103.48600","0.00000","1.26021","0.20003"
"1.26021","105.69820","1.23949","103.71600","0.00000","1.26021","0.20003"
"1.26021","105.66966","1.23915","103.94600","0.00000","1.26021","0.20003"
"1.26021","105.64007","1.23881","104.17600","0.00000","1.26021","0.20003"
"1.26021","105.62469","1.23863","104.40600","0.00000","1.26021","0.20003"
"1.26021","105.59766","1.23831","104.63600","0.00000","1.26021","0.20003"
"1.26021","105.58675","1.23818","104.86600","0.00000","1.26021","0.20003"
"1.26021","105.55954","1.23786","105.09600","0.00000","1.26021","0.20003"
"1.26021","105.53728","1.23760","105.32600","0.00000","1.26021","0.20003"
"1.26021","105.51950","1.23739","105.55600","0.00000","1.26021","0.20003"
"1.26021","105.49459","1.23710","105.78600","0.00000","1.26021","0.20003"
"1.26021","105.47763","1.23690","106.01600","0.00000","1.26021","0.20003"
"1.26021","105.46875","1.23680","106.24600","0.00000","1.26021","0.20003"
"1.26021","105.42433","1.23628","106.47600","0.00000","1.26021","0.20003"
"1.26021","105.41181","1.23613","106.70600","0.00000","1.26021","0.20003"
"1.26021","105.39084","1.23588","106.93600","0.00000","1.26021","0.20003"
"1.26021","105.37770","1.23573","107.16600","0.00000","1.26021","0.20003"
"1.26021","105.34528","1.23535","107.39600","0.00000","1.26021","0.20003"
"1.26021","105.33581","1.23524","107.62600","0.00000","1.26021","0.20003"
"1.26021","105.29724","1.23479","107.85600","0.00000","1.26021","0.20003"
"1.26021","105.28328","1.23462","108.08600","0.00000","1.26021","0.20003"
"1.26021","105.27892","1.23457","108.31600","0.00000","1.26021","0.20003"
"1.26021","105.21927","1.23387","108.54600","0.00000","1.26021","0.20003"
"1.26021","105.20982","1.23376","108.77600","0.00000","1.26021","0.20003"
"1.26021","105.20110","1.23366","109.00600","0.00000","1.26021","0.20003"
"1.26021","105.17090","1.23330","109.23600","0.00000","1.26021","0.20003"
"1.26021","105.14175","1.23296","109.46600","0.00000","1.26021","0.20003"
"1.26021","105.14206","1.23297","109.69600","0.00000","1.26021","0.20003"
"1.26021","105.10079","1.23248","109.92600","0.00000","1.26021","0.20003"
"1.26021","105.08458","1.23229","110.15600","0.00000","1.26021","0.20003"
"1.26021","105.08514","1.23230","110.38600","0.00000","1.26021","0.20003"
"1.26021","105.04433","1.23182","110.61600","0.00000","1.26021","0.20003"
"1.26021","105.03809","1.23175","110.84600","0.00000","1.26021","0.20003"
"1.26021","105.00892","1.23140","111.07600","0.00000","1.26021","0.20003"
"1.26021","104.98711","1.23115","111.30600","0.00000","1.26021","0.20003"
"1.26021","104.97479","1.23100","111.53600","0.00000","1.26021","0.20003"
"1.26021","104.94989","1.23071","111.76600","0.00000","1.26021","0.20003"
"1.26021","104.93212","1.23050","111.99600","0.00000","1.26021","0.20003"
"1.26021","104.90395","1.23017","112.22600","0.00000","1.26021","0.20003"
"1.26021","104.89382","1.23006","112.45600","0.00000","1.26021","0.20003"
"1.26021","104.87650","1.22985","112.68600","0.00000","1.26021","0.20003"
"1.26021","104.85320","1.22958","112.91600","0.00000","1.26021","0.20003"
"1.26021","104.82506","1.22925","113.14600","0.00000","1.26021","0.20003"
"1.26021","104.82095","1.22920","113.37600","0.00000","1.26021","0.20003"
"1.26021","104.78654","1.22880","113.60600","0.00000","1.26021","0.20003"
"1.26021","104.76859","1.22859","113.83600","0.00000","1.26021","0.20003"
"1.26021","104.75320","1.22841","114.06600","0.00000","1.26021","0.20003"
"1.26021","104.73386","1.22818","114.29600","0.00000","1.26021","0.20003"
"1.26021","104.71308","1.22794","114.52600","0.00000","1.26021","0.20003"
"1.26021","104.69720","1.22775","114.75600","0.00000","1.26021","0.20003"
"1.26021","104.67368","1.22747","114.98600","0.00000","1.26021","0.20003"
"1.26021","104.66770","1.22740","115.21600","0.00000","1.26021","0.20003"
"1.26021","104.64044","1.22708","115.44600","0.00000","1.26021","0.20003"
"1.26021","104.61375","1.22677","115.67600","0.00000","1.26021","0.20003"
"1.26021","104.59879","1.22660","115.90600","0.00000","1.26021","0.20003"
"1.26021","104.58164","1.22639","116.13600","0.00000","1.26021","0.20003"
"1.26021","104.56540","1.22620","116.36600","0.00000","1.26021","0.20003"
"1.26021","104.54088","1.22592","116.59600","0.00000","1.26021","0.20003"
"1.26021","104.52409","1.22572","116.82600","0.00000","1.26021","0.20003"
"1.26021","104.51109","1.22557","117.05600","0.00000","1.26021","0.20003"
"1.26021","104.49033","1.22532","117.28600","0.00000","1.26021","0.20003"
"1.26021","104.47200","1.22511","117.51600","0.00000","1.26021","0.20003"
"1.26021","104.45119","1.22486","117.74600","0.00000","1.26021","0.20003"
"1.26021","104.43725","1.22470","117.97600","0.00000","1.26021","0.20003"
"1.26021","104.41733","1.22447","118.20600","0.00000","1.26021","0.20003"
"1.26021","104.40421","1.22431","118.43600","0.00000","1.26021","0.20003"
"1.26021","104.37546","1.22398","118.66600","0.00000","1.26021","0.20003"
"1.26021","104.37092","1.22392","118.89600","0.00000","1.26021","0.20003"
"1.26021","104.33836","1.22354","119.12600","0.00000","1.26021","0.20003"
"1.26021","104.33353","1.22348","119.35600","0.00000","1.26021","0.20003"
"1.26021","104.30001","1.22309","119.58600","0.00000","1.26021","0.20003"
"1.26021","104.29409","1.22302","119.81600","0.00000","1.26021","0.20003"
"1.26021","104.26744","1.22271","120.04600","0.00000","1.26021","0.20003"
"1.26021","104.25511","1.22257","120.27600","0.00000","1.26021","0.20003"
"1.26021","104.22946","1.22226","120.50600","0.00000","1.26021","0.20003"
"1.26021","104.21651","1.22211","120.73600","0.00000","1.26021","0.20003"
"1.26021","104.19386","1.22185","120.96600","0.00000","1.26021","0.20003"
"1.26021","104.20938","1.22203","121.19600","0.00000","1.26021","0.20003"
"1.26021","104.13486","1.22116","121.42600","0.00000","1.26021","0.20003"
"1.26021","104.16779","1.22154","121.65600","0.00000","1.26021","0.20003"
"1.26021","104.12916","1.22109","121.88600","0.00000","1.26021","0.20003"
"1.26021","104.11656","1.22094","122.11600","0.00000","1.26021","0.20003"
"1.26021","104.09885","1.22073","122.34600","0.00000","1.26021","0.20003"
"1.26021","104.11061","1.22087","122.57600","0.00000","1.26021","0.20003"
"1.26021","104.01122","1.21971","122.80600","0.00000","1.26021","0.20003"
"1.26021","104.12238","1.22101","123.03600","0.00000","1.26021","0.20003"
"1.26021","103.97458","1.21928","123.26600","0.00000","1.26021","0.20003"
"1.26021","104.04345","1.22008","123.49600","0.00000","1.26021","0.20003"
"1.26021","103.98032","1.21934","123.72600","0.00000","1.26021","0.20003"
"1.26021","103.98325","1.21938","123.95600","0.00000","1.26021","0.20003"
"1.26021","103.98038","1.21934","124.18600","0.00000","1.26021","0.20003"
"1.26021","103.92297","1.21867","124.41600","0.00000","1.26021","0.20003"
"1.26021","103.94746","1.21896","124.64600","0.00000","1.26021","0.20003"
"1.26021","103.90095","1.21841","124.87600","0.00000","1.26021","0.20003"
"1.26021","103.89832","1.21838","125.10600","0.00000","1.26021","0.20003"
"1.26021","103.88995","1.21828","125.33600","0.00000","1.26021","0.20003"
"1.26021","103.84223","1.21772","125.56600","0.00000","1.26021","0.20003"
"1.26021","103.85390","1.21786","125.79600","0.00000","1.26021","0.20003"
"1.26021","103.80370","1.21727","126.02600","0.00000","1.26021","0.20003"
"1.26021","103.81615","1.21742","126.25600","0.00000","1.26021","0.20003"
"1.26021","103.78223","1.21702","126.48600","0.00000","1.26021","0.20003"
"1.26021","103.77148","1.21689","126.71600","0.00000","1.26021","0.20003"
"1.26021","103.74581","1.21659","126.94600","0.00000","1.26021","0.20003"
"1.26021","103.74894","1.21663","127.17600","0.00000","1.26021","0.20003"
"1.26021","103.72868","1.21639","127.40600","0.00000","1.26021","0.20003"
"1.26021","103.71621","1.21625","127.63600","0.00000","1.26021","0.20003"
"1.26021","103.68275","1.21585","127.86600","0.00000","1.26021","0.20003"
"1.26021","103.68294","1.21586","128.09600","0.00000","1.26021","0.20003"
"1.26021","103.65593","1.21554","128.32600","0.00000","1.26021","0.20003"
"1.26021","103.65085","1.21548","128.55600","0.00000","1.26021","0.20003"
"1.26021","103.62535","1.21518","128.78600","0.00000","1.26021","0.20003"
"1.26021","103.60946","1.21499","129.01600","0.00000","1.26021","0.20003"
"1.26021","103.60793","1.21498","129.24600","0.00000","1.26021","0.20003"
"1.26021","103.58353","1.21469","129.47600","0.00000","1.26021","0.20003"
"1.26021","103.56726","1.21450","129.70600","0.00000","1.26021","0.20003"
"1.26021","103.54784","1.21427","129.93600","0.00000","1.26021","0.20003"
"1.26021","103.54053","1.21419","130.16600","0.00000","1.26021","0.20003"
"1.26021","103.53575","1.21413","130.39600","0.00000","1.26021","0.20003"
"1.26021","103.49318","1.21363","130.62600","0.00000","1.26021","0.20003"
"1.26021","103.48822","1.21357","130.85600","0.00000","1.26021","0.20003"
"1.26021","103.48056","1.21348","131.08600","0.00000","1.26021","0.20003"
"1.26021","103.45825","1.21322","131.31600","0.00000","1.26021","0.20003"
"1.26021","103.44515","1.21307","131.54600","0.00000","1.26021","0.20003"
"1.26021","103.42392","1.21282","131.77600","0.00000","1.26021","0.20003"
"1.26021","103.41853","1.21275","132.00600","0.00000","1.26021","0.20003"
"1.26021","103.40266","1.21257","132.23600","0.00000","1.26021","0.20003"
"1.26021","103.37650","1.21226","132.46600","0.00000","1.26021","0.20003"
"1.26021","103.37093","1.21220","132.69600","0.00000","1.26021","0.20003"
"1.26021","103.33882","1.21182","132.92600","0.00000","1.26021","0.20003"
"1.26021","103.33696","1.21180","133.15600","0.00000","1.26021","0.20003"
"1.26021","103.32285","1.21163","133.38600","0.00000","1.26021","0.20003"
"1.26021","103.30362","1.21141","133.61600","0.00000","1.26021","0.20003"
"1.26021","103.30505","1.21142","133.84600","0.00000","1.26021","0.20003"
"1.26021","103.26981","1.21101","134.07600","0.00000","1.26021","0.20003"
"1.26021","103.27292","1.21105","134.30600","0.00000","1.26021","0.20003"
"1.26021","103.23164","1.21056","134.53600","0.00000","1.26021","0.20003"
"1.26021","103.22761","1.21052","134.76600","0.00000","1.26021","0.20003"
"1.26021","103.20988","1.21031","134.99600","0.00000","1.26021","0.20003"
"1.26021","103.20224","1.21022","135.22600","0.00000","1.26021","0.20003"
"1.26021","103.18479","1.21001","135.45600","0.00000","1.26021","0.20003"
"1.26021","103.16827","1.20982","135.68600","0.00000","1.26021","0.20003"
"1.26021","103.14243","1.20952","135.91600","0.00000","1.26021","0.20003"
"1.26021","103.14960","1.20960","136.14600","0.00000","1.26021","0.20003"
"1.26021","103.11654","1.20921","136.37600","0.00000","1.26021","0.20003"
"1.26021","103.11005","1.20914","136.60600","0.00000","1.26021","0.20003"
"1.26021","103.09129","1.20892","136.83600","0.00000","1.26021","0.20003"
"1.26021","103.07140","1.20868","137.06600","0.00000","1.26021","0.20003"
"1.26021","103.06615","1.20862","137.29600","0.00000","1.26021","0.20003"
"1.26021","103.04964","1.20843","137.52600","0.00000","1.26021","0.20003"
"1.26021","103.02814","1.20818","137.75600","0.00000","1.26021","0.20003"
"1.26021","103.02827","1.20818","137.98600","0.00000","1.26021","0.20003"
"1.26021","102.98239","1.20764","138.21600","0.00000","1.26021","0.20003"
"1.26021","103.01036","1.20797","138.44600","0.00000","1.26021","0.20003"
"1.26021","102.96057","1.20738","138.67600","0.00000","1.26021","0.20003"
"1.26021","102.97416","1.20754","138.90600","0.00000","1.26021","0.20003"
"1.26021","102.94574","1.20721","139.13600","0.00000","1.26021","0.20003"
"1.26021","102.92735","1.20700","139.36600","0.00000","1.26021","0.20003"
"1.26021","102.92229","1.20694","139.59600","0.00000","1.26021","0.20003"
"1.26021","102.89603","1.20663","139.82600","0.00000","1.26021","0.20003"
"1.26021","102.90926","1.20678","140.05600","0.00000","1.26021","0.20003"
"1.26021","102.86430","1.20626","140.28600","0.00000","1.26021","0.20003"
"1.26021","102.87673","1.20640","140.51600","0.00000","1.26021","0.20003"
"1.26021","102.85103","1.20610","140.74600","0.00000","1.26021","0.20003"
"1.26021","102.81772","1.20571","140.97600","0.00000","1.26021","0.20003"
"1.26021","102.82784","1.20583","141.20600","0.00000","1.26021","0.20003"
"1.26021","102.79117","1.20540","141.43600","0.00000","1.26021","0.20003"
"1.26021","102.81146","1.20564","141.66600","0.00000","1.26021","0.20003"
"1.26021","102.76639","1.20511","141.89600","0.00000","1.26021","0.20003"
"1.26021","102.78633","1.20534","142.12600","0.00000","1.26021","0.20003"
"1.26021","102.74488","1.20486","142.35600","0.00000","1.26021","0.20003"
"1.26021","102.75636","1.20499","142.58600","0.00000","1.26021","0.20003"
"1.26021","102.72980","1.20468","142.81600","0.00000","1.26021","0.20003"
"1.26021","102.70357","1.20437","143.04600","0.00000","1.26021","0.20003"
"1.26021","102.70901","1.20443","143.27600","0.00000","1.26021","0.20003"
"1.26021","102.68224","1.20412","143.50600","0.00000","1.26021","0.20003"
"1.26021","102.66001","1.20386","143.73600","0.00000","1.26021","0.20003"
"1.26021","102.64393","1.20367","143.96600","0.00000","1.26021","0.20003"
"1.26021","102.64652","1.20370","144.19600","0.00000","1.26021","0.20003"
"1.26021","102.62715","1.20347","144.42600","0.00000","1.26021","0.20003"
"1.26021","102.58564","1.20299","144.65600","0.00000","1.26021","0.20003"
"1.26021","102.61305","1.20331","144.88600","0.00000","1.26021","0.20003"
"1.26021","102.58437","1.20297","145.11600","0.00000","1.26021","0.20003"
"1.26021","102.58129","1.20294","145.34600","0.00000","1.26021","0.20003"
"1.26021","102.58248","1.20295","145.57600","0.00000","1.26021","0.20003"
"1.26021","102.52537","1.20228","145.80600","0.00000","1.26021","0.20003"
"1.26021","102.55254","1.20260","146.03600","0.00000","1.26021","0.20003"
"1.26021","102.50871","1.20209","146.26600","0.00000","1.26021","0.20003"
"1.26021","102.52029","1.20222","146.49600","0.00000","1.26021","0.20003"
"1.26021","102.49165","1.20189","146.72600","0.00000","1.26021","0.20003"
"1.26021","102.48600","1.20182","146.95600","0.00000","1.26021","0.20003"
"1.26021","102.46909","1.20162","147.18600","0.00000","1.26021","0.20003"
"1.26021","102.45890","1.20150","147.41600","0.00000","1.26021","0.20003"
"1.26021","102.44534","1.20134","147.64600","0.00000","1.26021","0.20003"
"1.26021","102.43237","1.20119","147.87600","0.00000","1.26021","0.20003"
"1.26021","102.40257","1.20084","148.10600","0.00000","1.26021","0.20003"
"1.26021","102.41021","1.20093","148.33600","0.00000","1.26021","0.20003"
"1.26021","102.39127","1.20071","148.56600","0.00000","1.26021","0.20003"
"1.26021","102.38960","1.20069","148.79600","0.00000","1.26021","0.20003"
"1.26021","102.40774","1.20090","149.02600","0.00000","1.26021","0.20003"
"1.26021","102.32752","1.19996","149.25600","0.00000","1.26021","0.20003"
"1.26021","102.32793","1.19997","149.48600","0.00000","1.26021","0.20003"
"1.26021","102.32948","1.19998","149.71600","0.00000","1.26021","0.20003"
"1.26021","102.28618","1.19948","149.94600","0.00000","1.26021","0.20003"
"1.26021","102.33250","1.20002","150.17600","0.00000","1.26021","0.20003"
"1.26021","102.27650","1.19936","150.40600","0.00000","1.26021","0.20003"
"1.26021","102.30170","1.19966","150.63600","0.00000","1.26021","0.20003"
"1.26021","102.22099","1.19871","150.86600","0.00000","1.26021","0.20003"
"1.26021","102.24718","1.19902","151.09600","0.00000","1.26021","0.20003"
"1.26021","102.24355","1.19898","151.32600","0.00000","1.26021","0.20003"
"1.26021","102.24490","1.19899","151.50600","0.00000","1.26021","0.20003"