File: Rubber Stress Relaxation Raw Data -Large  Samples-20210211/Specimen_RawData_7.csv
Specimen properties : Specimen label,"8"
Specimen properties : Anvil height,"6.25000",mm
Specimen properties : Diameter,"10.25000",mm
Test : Rate 1,"24.00000",mm/min
Test : Start of hold value,"20.00000",%
Test : Duration,"120.00000",s

Extension,Load,Compressive stress,Time,PIP count,Compressive extension,Compressive strain (Extension)
(mm),(N),(MPa),(s),,(mm),(mm/mm)
"0.00042","0.05228","0.00063","0.00000","0.00000","0.00042","0.00007"
"0.05979","10.07324","0.12208","0.18000","0.00000","0.05979","0.00957"
"0.13958","23.51094","0.28493","0.36000","0.00000","0.13958","0.02233"
"0.21500","33.10805","0.40123","0.54000","0.00000","0.21500","0.03440"
"0.28854","41.72179","0.50562","0.72000","0.00000","0.28854","0.04617"
"0.36042","49.76380","0.60308","0.90000","0.00000","0.36042","0.05767"
"0.43292","58.09889","0.70409","1.08000","0.00000","0.43292","0.06927"
"0.50500","66.33585","0.80392","1.26000","0.00000","0.50500","0.08080"
"0.57708","74.60765","0.90416","1.44000","0.00000","0.57708","0.09233"
"0.64896","83.02847","1.00621","1.62000","0.00000","0.64896","0.10383"
"0.72083","91.59777","1.11006","1.80000","0.00000","0.72083","0.11533"
"0.79292","100.25655","1.21500","1.98000","0.00000","0.79292","0.12687"
"0.86479","109.29138","1.32449","2.16000","0.00000","0.86479","0.13837"
"0.93667","118.52016","1.43633","2.34000","0.00000","0.93667","0.14987"
"1.00875","128.15141","1.55305","2.52000","0.00000","1.00875","0.16140"
"1.08104","137.74890","1.66936","2.70000","0.00000","1.08104","0.17297"
"1.15292","148.02650","1.79392","2.88000","0.00000","1.15292","0.18447"
"1.22458","158.82405","1.92477","3.06000","0.00000","1.22458","0.19593"
"1.25937","157.95856","1.91428","3.22600","0.00000","1.25937","0.20150"
"1.25875","147.84462","1.79171","3.40600","0.00000","1.25875","0.20140"
"1.25771","142.73367","1.72977","3.58600","0.00000","1.25771","0.20123"
"1.25542","138.67957","1.68064","3.76600","0.00000","1.25542","0.20087"
"1.25354","135.52502","1.64241","3.94600","0.00000","1.25354","0.20057"
"1.25208","133.15637","1.61371","4.12600","0.00000","1.25208","0.20033"
"1.25125","131.39493","1.59236","4.30600","0.00000","1.25125","0.20020"
"1.25083","129.99318","1.57537","4.48600","0.00000","1.25083","0.20013"
"1.25083","128.93007","1.56249","4.66600","0.00000","1.25083","0.20013"
"1.25063","127.91943","1.55024","4.84600","0.00000","1.25063","0.20010"
"1.25063","127.05115","1.53972","5.02600","0.00000","1.25063","0.20010"
"1.25063","126.24441","1.52994","5.20600","0.00000","1.25063","0.20010"
"1.25063","125.50207","1.52094","5.38600","0.00000","1.25063","0.20010"
"1.25063","124.81486","1.51262","5.56600","0.00000","1.25063","0.20010"
"1.25063","124.17701","1.50489","5.74600","0.00000","1.25063","0.20010"
"1.25042","123.53437","1.49710","5.92600","0.00000","1.25042","0.20007"
"1.25042","122.99197","1.49052","6.10600","0.00000","1.25042","0.20007"
"1.25042","122.45741","1.48405","6.28600","0.00000","1.25042","0.20007"
"1.25042","121.96448","1.47807","6.46600","0.00000","1.25042","0.20007"
"1.25042","121.48151","1.47222","6.64600","0.00000","1.25042","0.20007"
"1.25042","121.04811","1.46697","6.82600","0.00000","1.25042","0.20007"
"1.25042","120.62627","1.46185","7.00600","0.00000","1.25042","0.20007"
"1.25042","120.23015","1.45705","7.18600","0.00000","1.25042","0.20007"
"1.25042","119.82937","1.45220","7.36600","0.00000","1.25042","0.20007"
"1.25042","119.45704","1.44769","7.54600","0.00000","1.25042","0.20007"
"1.25042","119.10403","1.44341","7.72600","0.00000","1.25042","0.20007"
"1.25042","118.76343","1.43928","7.90600","0.00000","1.25042","0.20007"
"1.25042","118.45499","1.43554","8.08600","0.00000","1.25042","0.20007"
"1.25042","118.14197","1.43175","8.26600","0.00000","1.25042","0.20007"
"1.25042","117.81890","1.42783","8.44600","0.00000","1.25042","0.20007"
"1.25042","117.53445","1.42439","8.62600","0.00000","1.25042","0.20007"
"1.25042","117.24631","1.42089","8.80600","0.00000","1.25042","0.20007"
"1.25042","116.98147","1.41768","8.98600","0.00000","1.25042","0.20007"
"1.25042","116.72524","1.41458","9.16600","0.00000","1.25042","0.20007"
"1.25042","116.46783","1.41146","9.34600","0.00000","1.25042","0.20007"
"1.25042","116.22418","1.40851","9.52600","0.00000","1.25042","0.20007"
"1.25042","115.97565","1.40549","9.70600","0.00000","1.25042","0.20007"
"1.25042","115.73183","1.40254","9.88600","0.00000","1.25042","0.20007"
"1.25042","115.51453","1.39991","10.06600","0.00000","1.25042","0.20007"
"1.25042","115.29020","1.39719","10.24600","0.00000","1.25042","0.20007"
"1.25042","115.07967","1.39464","10.42600","0.00000","1.25042","0.20007"
"1.25042","114.85670","1.39193","10.60600","0.00000","1.25042","0.20007"
"1.25042","114.66869","1.38966","10.78600","0.00000","1.25042","0.20007"
"1.25042","114.48077","1.38738","10.96600","0.00000","1.25042","0.20007"
"1.25042","114.28523","1.38501","11.14600","0.00000","1.25042","0.20007"
"1.25042","114.10917","1.38288","11.32600","0.00000","1.25042","0.20007"
"1.25083","114.02745","1.38188","11.50600","0.00000","1.25083","0.20013"
"1.25083","113.81031","1.37925","11.68600","0.00000","1.25083","0.20013"
"1.25083","113.62999","1.37707","11.86600","0.00000","1.25083","0.20013"
"1.25083","113.45069","1.37490","12.04600","0.00000","1.25083","0.20013"
"1.25083","113.28147","1.37284","12.22600","0.00000","1.25083","0.20013"
"1.25083","113.10987","1.37076","12.40600","0.00000","1.25083","0.20013"
"1.25083","112.94228","1.36873","12.58600","0.00000","1.25083","0.20013"
"1.25083","112.78503","1.36683","12.76600","0.00000","1.25083","0.20013"
"1.25083","112.62778","1.36492","12.94600","0.00000","1.25083","0.20013"
"1.25083","112.47433","1.36306","13.12600","0.00000","1.25083","0.20013"
"1.25083","112.32101","1.36120","13.30600","0.00000","1.25083","0.20013"
"1.25083","112.16311","1.35929","13.48600","0.00000","1.25083","0.20013"
"1.25083","112.02602","1.35763","13.66600","0.00000","1.25083","0.20013"
"1.25083","111.88968","1.35598","13.84600","0.00000","1.25083","0.20013"
"1.25083","111.74210","1.35419","14.02600","0.00000","1.25083","0.20013"
"1.25083","111.60915","1.35258","14.20600","0.00000","1.25083","0.20013"
"1.25083","111.47791","1.35099","14.38600","0.00000","1.25083","0.20013"
"1.25083","111.34827","1.34942","14.56600","0.00000","1.25083","0.20013"
"1.25083","111.21751","1.34783","14.74600","0.00000","1.25083","0.20013"
"1.25083","111.09722","1.34637","14.92600","0.00000","1.25083","0.20013"
"1.25083","110.97177","1.34485","15.10600","0.00000","1.25083","0.20013"
"1.25083","110.83890","1.34324","15.28600","0.00000","1.25083","0.20013"
"1.25083","110.72948","1.34192","15.46600","0.00000","1.25083","0.20013"
"1.25083","110.60698","1.34043","15.64600","0.00000","1.25083","0.20013"
"1.25083","110.48833","1.33899","15.82600","0.00000","1.25083","0.20013"
"1.25083","110.37262","1.33759","16.00600","0.00000","1.25083","0.20013"
"1.25083","110.25626","1.33618","16.18600","0.00000","1.25083","0.20013"
"1.25083","110.15106","1.33491","16.36600","0.00000","1.25083","0.20013"
"1.25083","110.04722","1.33365","16.54600","0.00000","1.25083","0.20013"
"1.25083","109.93914","1.33234","16.72600","0.00000","1.25083","0.20013"
"1.25083","109.82861","1.33100","16.90600","0.00000","1.25083","0.20013"
"1.25083","109.72469","1.32974","17.08600","0.00000","1.25083","0.20013"
"1.25083","109.61988","1.32847","17.26600","0.00000","1.25083","0.20013"
"1.25083","109.52316","1.32730","17.44600","0.00000","1.25083","0.20013"
"1.25083","109.42174","1.32607","17.62600","0.00000","1.25083","0.20013"
"1.25083","109.33172","1.32498","17.80600","0.00000","1.25083","0.20013"
"1.25083","109.23359","1.32379","17.98600","0.00000","1.25083","0.20013"
"1.25083","109.12775","1.32251","18.16600","0.00000","1.25083","0.20013"
"1.25083","109.03470","1.32138","18.34600","0.00000","1.25083","0.20013"
"1.25083","108.95193","1.32038","18.52600","0.00000","1.25083","0.20013"
"1.25083","108.84998","1.31914","18.70600","0.00000","1.25083","0.20013"
"1.25083","108.75922","1.31804","18.88600","0.00000","1.25083","0.20013"
"1.25083","108.67145","1.31698","19.06600","0.00000","1.25083","0.20013"
"1.25083","108.57941","1.31586","19.24600","0.00000","1.25083","0.20013"
"1.25083","108.49233","1.31481","19.42600","0.00000","1.25083","0.20013"
"1.25083","108.40337","1.31373","19.60600","0.00000","1.25083","0.20013"
"1.25083","108.32041","1.31272","19.78600","0.00000","1.25083","0.20013"
"1.25083","108.23600","1.31170","19.96600","0.00000","1.25083","0.20013"
"1.25083","108.14929","1.31065","20.14600","0.00000","1.25083","0.20013"
"1.25083","108.07112","1.30970","20.32600","0.00000","1.25083","0.20013"
"1.25083","107.99745","1.30881","20.50600","0.00000","1.25083","0.20013"
"1.25083","107.91384","1.30779","20.68600","0.00000","1.25083","0.20013"
"1.25083","107.83546","1.30684","20.86600","0.00000","1.25083","0.20013"
"1.25083","107.75512","1.30587","21.04600","0.00000","1.25083","0.20013"
"1.25083","107.67851","1.30494","21.22600","0.00000","1.25083","0.20013"
"1.25083","107.59994","1.30399","21.40600","0.00000","1.25083","0.20013"
"1.25083","107.52642","1.30310","21.58600","0.00000","1.25083","0.20013"
"1.25083","107.44425","1.30210","21.76600","0.00000","1.25083","0.20013"
"1.25083","107.36916","1.30119","21.94600","0.00000","1.25083","0.20013"
"1.25083","107.29593","1.30031","22.12600","0.00000","1.25083","0.20013"
"1.25083","107.22274","1.29942","22.30600","0.00000","1.25083","0.20013"
"1.25083","107.14664","1.29850","22.48600","0.00000","1.25083","0.20013"
"1.25083","107.07326","1.29761","22.66600","0.00000","1.25083","0.20013"
"1.25083","107.00592","1.29679","22.84600","0.00000","1.25083","0.20013"
"1.25083","106.94726","1.29608","23.02600","0.00000","1.25083","0.20013"
"1.25083","106.87601","1.29522","23.20600","0.00000","1.25083","0.20013"
"1.25083","106.79425","1.29423","23.38600","0.00000","1.25083","0.20013"
"1.25083","106.73370","1.29349","23.56600","0.00000","1.25083","0.20013"
"1.25083","106.66666","1.29268","23.74600","0.00000","1.25083","0.20013"
"1.25083","106.60367","1.29192","23.92600","0.00000","1.25083","0.20013"
"1.25083","106.54084","1.29116","24.10600","0.00000","1.25083","0.20013"
"1.25083","106.46835","1.29028","24.28600","0.00000","1.25083","0.20013"
"1.25083","106.40772","1.28954","24.46600","0.00000","1.25083","0.20013"
"1.25083","106.34568","1.28879","24.64600","0.00000","1.25083","0.20013"
"1.25083","106.28065","1.28800","24.82600","0.00000","1.25083","0.20013"
"1.25083","106.21450","1.28720","25.00600","0.00000","1.25083","0.20013"
"1.25083","106.15990","1.28654","25.18600","0.00000","1.25083","0.20013"
"1.25083","106.09430","1.28574","25.36600","0.00000","1.25083","0.20013"
"1.25083","106.03220","1.28499","25.54600","0.00000","1.25083","0.20013"
"1.25083","105.97456","1.28429","25.72600","0.00000","1.25083","0.20013"
"1.25083","105.91326","1.28355","25.90600","0.00000","1.25083","0.20013"
"1.25083","105.85025","1.28279","26.08600","0.00000","1.25083","0.20013"
"1.25083","105.79543","1.28212","26.26600","0.00000","1.25083","0.20013"
"1.25083","105.73499","1.28139","26.44600","0.00000","1.25083","0.20013"
"1.25083","105.68263","1.28075","26.62600","0.00000","1.25083","0.20013"
"1.25083","105.62828","1.28010","26.80600","0.00000","1.25083","0.20013"
"1.25083","105.56532","1.27933","26.98600","0.00000","1.25083","0.20013"
"1.25083","105.50535","1.27861","27.16600","0.00000","1.25083","0.20013"
"1.25083","105.45242","1.27796","27.34600","0.00000","1.25083","0.20013"
"1.25083","105.40142","1.27735","27.52600","0.00000","1.25083","0.20013"
"1.25083","105.34677","1.27668","27.70600","0.00000","1.25083","0.20013"
"1.25083","105.28342","1.27592","27.88600","0.00000","1.25083","0.20013"
"1.25083","105.23179","1.27529","28.06600","0.00000","1.25083","0.20013"
"1.25083","105.17712","1.27463","28.24600","0.00000","1.25083","0.20013"
"1.25083","105.12976","1.27405","28.42600","0.00000","1.25083","0.20013"
"1.25083","105.07596","1.27340","28.60600","0.00000","1.25083","0.20013"
"1.25083","105.02882","1.27283","28.78600","0.00000","1.25083","0.20013"
"1.25083","104.97362","1.27216","28.96600","0.00000","1.25083","0.20013"
"1.25083","104.91966","1.27151","29.14600","0.00000","1.25083","0.20013"
"1.25083","104.87691","1.27099","29.32600","0.00000","1.25083","0.20013"
"1.25083","104.81805","1.27028","29.50600","0.00000","1.25083","0.20013"
"1.25083","104.77119","1.26971","29.68600","0.00000","1.25083","0.20013"
"1.25083","104.71749","1.26906","29.86600","0.00000","1.25083","0.20013"
"1.25083","104.67399","1.26853","30.04600","0.00000","1.25083","0.20013"
"1.25083","104.62360","1.26792","30.22600","0.00000","1.25083","0.20013"
"1.25083","104.56746","1.26724","30.40600","0.00000","1.25083","0.20013"
"1.25083","104.51929","1.26666","30.58600","0.00000","1.25083","0.20013"
"1.25083","104.47616","1.26613","30.76600","0.00000","1.25083","0.20013"
"1.25083","104.43781","1.26567","30.94600","0.00000","1.25083","0.20013"
"1.25083","104.37831","1.26495","31.12600","0.00000","1.25083","0.20013"
"1.25083","104.33251","1.26439","31.30600","0.00000","1.25083","0.20013"
"1.25083","104.28448","1.26381","31.48600","0.00000","1.25083","0.20013"
"1.25083","104.23730","1.26324","31.66600","0.00000","1.25083","0.20013"
"1.25083","104.18945","1.26266","31.84600","0.00000","1.25083","0.20013"
"1.25083","104.15186","1.26220","32.02600","0.00000","1.25083","0.20013"
"1.25083","104.10287","1.26161","32.20600","0.00000","1.25083","0.20013"
"1.25083","104.05492","1.26103","32.38600","0.00000","1.25083","0.20013"
"1.25083","104.00755","1.26045","32.56600","0.00000","1.25083","0.20013"
"1.25083","103.97185","1.26002","32.74600","0.00000","1.25083","0.20013"
"1.25083","103.92091","1.25940","32.92600","0.00000","1.25083","0.20013"
"1.25083","103.87597","1.25886","33.10600","0.00000","1.25083","0.20013"
"1.25083","103.83934","1.25842","33.28600","0.00000","1.25083","0.20013"
"1.25083","103.79932","1.25793","33.46600","0.00000","1.25083","0.20013"
"1.25083","103.75620","1.25741","33.64600","0.00000","1.25083","0.20013"
"1.25083","103.70910","1.25684","33.82600","0.00000","1.25083","0.20013"
"1.25083","103.66644","1.25632","34.00600","0.00000","1.25083","0.20013"
"1.25083","103.62183","1.25578","34.18600","0.00000","1.25083","0.20013"
"1.25083","103.58279","1.25531","34.36600","0.00000","1.25083","0.20013"
"1.25083","103.54591","1.25486","34.54600","0.00000","1.25083","0.20013"
"1.25083","103.49998","1.25430","34.72600","0.00000","1.25083","0.20013"
"1.25083","103.45495","1.25376","34.90600","0.00000","1.25083","0.20013"
"1.25083","103.41660","1.25329","35.08600","0.00000","1.25083","0.20013"
"1.25083","103.37924","1.25284","35.26600","0.00000","1.25083","0.20013"
"1.25083","103.33759","1.25234","35.44600","0.00000","1.25083","0.20013"
"1.25083","103.30064","1.25189","35.62600","0.00000","1.25083","0.20013"
"1.25083","103.25315","1.25131","35.80600","0.00000","1.25083","0.20013"
"1.25083","103.21437","1.25084","35.98600","0.00000","1.25083","0.20013"
"1.25083","103.18275","1.25046","36.16600","0.00000","1.25083","0.20013"
"1.25083","103.13364","1.24986","36.34600","0.00000","1.25083","0.20013"
"1.25083","103.10199","1.24948","36.52600","0.00000","1.25083","0.20013"
"1.25083","103.06337","1.24901","36.70600","0.00000","1.25083","0.20013"
"1.25083","103.02125","1.24850","36.88600","0.00000","1.25083","0.20013"
"1.25083","102.98316","1.24804","37.06600","0.00000","1.25083","0.20013"
"1.25083","102.95509","1.24770","37.24600","0.00000","1.25083","0.20013"
"1.25083","102.91898","1.24726","37.42600","0.00000","1.25083","0.20013"
"1.25083","102.87476","1.24673","37.60600","0.00000","1.25083","0.20013"
"1.25083","102.83183","1.24621","37.78600","0.00000","1.25083","0.20013"
"1.25083","102.79445","1.24575","37.96600","0.00000","1.25083","0.20013"
"1.25083","102.75613","1.24529","38.14600","0.00000","1.25083","0.20013"
"1.25083","102.71992","1.24485","38.32600","0.00000","1.25083","0.20013"
"1.25083","102.68398","1.24441","38.50600","0.00000","1.25083","0.20013"
"1.25083","102.64851","1.24398","38.68600","0.00000","1.25083","0.20013"
"1.25083","102.61540","1.24358","38.86600","0.00000","1.25083","0.20013"
"1.25083","102.58144","1.24317","39.04600","0.00000","1.25083","0.20013"
"1.25083","102.54626","1.24275","39.22600","0.00000","1.25083","0.20013"
"1.25083","102.50751","1.24228","39.40600","0.00000","1.25083","0.20013"
"1.25083","102.47675","1.24190","39.58600","0.00000","1.25083","0.20013"
"1.25083","102.44496","1.24152","39.76600","0.00000","1.25083","0.20013"
"1.25083","102.40508","1.24103","39.94600","0.00000","1.25083","0.20013"
"1.25083","102.37006","1.24061","40.12600","0.00000","1.25083","0.20013"
"1.25083","102.34065","1.24025","40.30600","0.00000","1.25083","0.20013"
"1.25083","102.30637","1.23984","40.48600","0.00000","1.25083","0.20013"
"1.25083","102.27461","1.23945","40.66600","0.00000","1.25083","0.20013"
"1.25083","102.23614","1.23899","40.84600","0.00000","1.25083","0.20013"
"1.25083","102.19949","1.23854","41.02600","0.00000","1.25083","0.20013"
"1.25083","102.16804","1.23816","41.20600","0.00000","1.25083","0.20013"
"1.25083","102.13448","1.23776","41.38600","0.00000","1.25083","0.20013"
"1.25083","102.10423","1.23739","41.56600","0.00000","1.25083","0.20013"
"1.25083","102.07446","1.23703","41.74600","0.00000","1.25083","0.20013"
"1.25083","102.03687","1.23657","41.92600","0.00000","1.25083","0.20013"
"1.25083","102.00746","1.23622","42.10600","0.00000","1.25083","0.20013"
"1.25083","101.97271","1.23579","42.28600","0.00000","1.25083","0.20013"
"1.25083","101.93726","1.23537","42.46600","0.00000","1.25083","0.20013"
"1.25083","101.91491","1.23509","42.64600","0.00000","1.25083","0.20013"
"1.25083","101.88245","1.23470","42.82600","0.00000","1.25083","0.20013"
"1.25083","101.83752","1.23416","43.00600","0.00000","1.25083","0.20013"
"1.25083","101.81674","1.23390","43.18600","0.00000","1.25083","0.20013"
"1.25083","101.78019","1.23346","43.36600","0.00000","1.25083","0.20013"
"1.25083","101.75848","1.23320","43.54600","0.00000","1.25083","0.20013"
"1.25083","101.72555","1.23280","43.72600","0.00000","1.25083","0.20013"
"1.25083","101.69438","1.23242","43.90600","0.00000","1.25083","0.20013"
"1.25083","101.66756","1.23210","44.08600","0.00000","1.25083","0.20013"
"1.25083","101.63464","1.23170","44.26600","0.00000","1.25083","0.20013"
"1.25083","101.60051","1.23128","44.44600","0.00000","1.25083","0.20013"
"1.25083","101.57223","1.23094","44.62600","0.00000","1.25083","0.20013"
"1.25083","101.54250","1.23058","44.80600","0.00000","1.25083","0.20013"
"1.25083","101.51999","1.23031","44.98600","0.00000","1.25083","0.20013"
"1.25083","101.48234","1.22985","45.16600","0.00000","1.25083","0.20013"
"1.25083","101.46125","1.22960","45.34600","0.00000","1.25083","0.20013"
"1.25083","101.43002","1.22922","45.52600","0.00000","1.25083","0.20013"
"1.25083","101.40067","1.22886","45.70600","0.00000","1.25083","0.20013"
"1.25083","101.37121","1.22851","45.88600","0.00000","1.25083","0.20013"
"1.25083","101.34101","1.22814","46.06600","0.00000","1.25083","0.20013"
"1.25083","101.31288","1.22780","46.24600","0.00000","1.25083","0.20013"
"1.25083","101.27779","1.22737","46.42600","0.00000","1.25083","0.20013"
"1.25083","101.25257","1.22707","46.60600","0.00000","1.25083","0.20013"
"1.25083","101.21512","1.22661","46.78600","0.00000","1.25083","0.20013"
"1.25083","101.18865","1.22629","46.96600","0.00000","1.25083","0.20013"
"1.25083","101.16644","1.22602","47.14600","0.00000","1.25083","0.20013"
"1.25083","101.12855","1.22556","47.32600","0.00000","1.25083","0.20013"
"1.25083","101.09791","1.22519","47.50600","0.00000","1.25083","0.20013"
"1.25083","101.05944","1.22473","47.68600","0.00000","1.25083","0.20013"
"1.25083","101.04089","1.22450","47.86600","0.00000","1.25083","0.20013"
"1.25083","101.01918","1.22424","48.04600","0.00000","1.25083","0.20013"
"1.25083","100.99046","1.22389","48.22600","0.00000","1.25083","0.20013"
"1.25083","100.96297","1.22356","48.40600","0.00000","1.25083","0.20013"
"1.25083","100.93700","1.22324","48.58600","0.00000","1.25083","0.20013"
"1.25083","100.90895","1.22290","48.76600","0.00000","1.25083","0.20013"
"1.25083","100.88459","1.22261","48.94600","0.00000","1.25083","0.20013"
"1.25083","100.85689","1.22227","49.12600","0.00000","1.25083","0.20013"
"1.25083","100.83002","1.22195","49.30600","0.00000","1.25083","0.20013"
"1.25083","100.80733","1.22167","49.48600","0.00000","1.25083","0.20013"
"1.25083","100.78238","1.22137","49.66600","0.00000","1.25083","0.20013"
"1.25083","100.75433","1.22103","49.84600","0.00000","1.25083","0.20013"
"1.25083","100.72402","1.22066","50.02600","0.00000","1.25083","0.20013"
"1.25083","100.70403","1.22042","50.20600","0.00000","1.25083","0.20013"
"1.25083","100.67743","1.22010","50.38600","0.00000","1.25083","0.20013"
"1.25083","100.65144","1.21978","50.56600","0.00000","1.25083","0.20013"
"1.25083","100.62253","1.21943","50.74600","0.00000","1.25083","0.20013"
"1.25083","100.59674","1.21912","50.92600","0.00000","1.25083","0.20013"
"1.25083","100.58144","1.21893","51.10600","0.00000","1.25083","0.20013"
"1.25083","100.54108","1.21845","51.28600","0.00000","1.25083","0.20013"
"1.25083","100.52233","1.21822","51.46600","0.00000","1.25083","0.20013"
"1.25083","100.49878","1.21793","51.64600","0.00000","1.25083","0.20013"
"1.25083","100.46184","1.21748","51.82600","0.00000","1.25083","0.20013"
"1.25083","100.45135","1.21736","52.00600","0.00000","1.25083","0.20013"
"1.25083","100.41342","1.21690","52.18600","0.00000","1.25083","0.20013"
"1.25083","100.40151","1.21675","52.36600","0.00000","1.25083","0.20013"
"1.25083","100.37183","1.21639","52.54600","0.00000","1.25083","0.20013"
"1.25083","100.34164","1.21603","52.72600","0.00000","1.25083","0.20013"
"1.25083","100.31575","1.21571","52.90600","0.00000","1.25083","0.20013"
"1.25083","100.29365","1.21545","53.08600","0.00000","1.25083","0.20013"
"1.25083","100.27702","1.21524","53.26600","0.00000","1.25083","0.20013"
"1.25083","100.24152","1.21481","53.44600","0.00000","1.25083","0.20013"
"1.25083","100.22413","1.21460","53.62600","0.00000","1.25083","0.20013"
"1.25083","100.19814","1.21429","53.80600","0.00000","1.25083","0.20013"
"1.25083","100.17300","1.21398","53.98600","0.00000","1.25083","0.20013"
"1.25083","100.15224","1.21373","54.16600","0.00000","1.25083","0.20013"
"1.25083","100.12278","1.21338","54.34600","0.00000","1.25083","0.20013"
"1.25083","100.10073","1.21311","54.52600","0.00000","1.25083","0.20013"
"1.25083","100.08465","1.21291","54.70600","0.00000","1.25083","0.20013"
"1.25083","100.05309","1.21253","54.88600","0.00000","1.25083","0.20013"
"1.25083","100.03310","1.21229","55.06600","0.00000","1.25083","0.20013"
"1.25083","100.00577","1.21196","55.24600","0.00000","1.25083","0.20013"
"1.25083","99.98966","1.21176","55.42600","0.00000","1.25083","0.20013"
"1.25083","99.96824","1.21150","55.60600","0.00000","1.25083","0.20013"
"1.25083","99.94365","1.21120","55.78600","0.00000","1.25083","0.20013"
"1.25083","99.92214","1.21094","55.96600","0.00000","1.25083","0.20013"
"1.25083","99.89404","1.21060","56.14600","0.00000","1.25083","0.20013"
"1.25083","99.87101","1.21032","56.32600","0.00000","1.25083","0.20013"
"1.25083","99.85640","1.21015","56.50600","0.00000","1.25083","0.20013"
"1.25083","99.82845","1.20981","56.68600","0.00000","1.25083","0.20013"
"1.25083","99.80620","1.20954","56.86600","0.00000","1.25083","0.20013"
"1.25083","99.78468","1.20928","57.04600","0.00000","1.25083","0.20013"
"1.25083","99.76355","1.20902","57.22600","0.00000","1.25083","0.20013"
"1.25083","99.73505","1.20868","57.40600","0.00000","1.25083","0.20013"
"1.25083","99.71341","1.20841","57.58600","0.00000","1.25083","0.20013"
"1.25083","99.68243","1.20804","57.76600","0.00000","1.25083","0.20013"
"1.25083","99.67262","1.20792","57.94600","0.00000","1.25083","0.20013"
"1.25083","99.64296","1.20756","58.12600","0.00000","1.25083","0.20013"
"1.25083","99.62019","1.20728","58.30600","0.00000","1.25083","0.20013"
"1.25083","99.59744","1.20701","58.48600","0.00000","1.25083","0.20013"
"1.25083","99.58466","1.20685","58.66600","0.00000","1.25083","0.20013"
"1.25083","99.55847","1.20654","58.84600","0.00000","1.25083","0.20013"
"1.25083","99.53953","1.20631","59.02600","0.00000","1.25083","0.20013"
"1.25083","99.52242","1.20610","59.20600","0.00000","1.25083","0.20013"
"1.25083","99.49673","1.20579","59.38600","0.00000","1.25083","0.20013"
"1.25083","99.48073","1.20559","59.56600","0.00000","1.25083","0.20013"
"1.25083","99.44952","1.20522","59.74600","0.00000","1.25083","0.20013"
"1.25083","99.42452","1.20491","59.92600","0.00000","1.25083","0.20013"
"1.25083","99.42374","1.20490","60.10600","0.00000","1.25083","0.20013"
"1.25083","99.38605","1.20445","60.28600","0.00000","1.25083","0.20013"
"1.25083","99.37074","1.20426","60.46600","0.00000","1.25083","0.20013"
"1.25083","99.34996","1.20401","60.64600","0.00000","1.25083","0.20013"
"1.25083","99.32611","1.20372","60.82600","0.00000","1.25083","0.20013"
"1.25083","99.30962","1.20352","61.00600","0.00000","1.25083","0.20013"
"1.25083","99.28716","1.20325","61.18600","0.00000","1.25083","0.20013"
"1.25083","99.26488","1.20298","61.36600","0.00000","1.25083","0.20013"
"1.25083","99.24753","1.20277","61.54600","0.00000","1.25083","0.20013"
"1.25083","99.23349","1.20260","61.72600","0.00000","1.25083","0.20013"
"1.25083","99.20369","1.20224","61.90600","0.00000","1.25083","0.20013"
"1.25083","99.17002","1.20183","62.08600","0.00000","1.25083","0.20013"
"1.25083","99.15249","1.20162","62.26600","0.00000","1.25083","0.20013"
"1.25083","99.13635","1.20142","62.44600","0.00000","1.25083","0.20013"
"1.25083","99.11658","1.20118","62.62600","0.00000","1.25083","0.20013"
"1.25083","99.10311","1.20102","62.80600","0.00000","1.25083","0.20013"
"1.25083","99.08640","1.20082","62.98600","0.00000","1.25083","0.20013"
"1.25083","99.06289","1.20053","63.16600","0.00000","1.25083","0.20013"
"1.25083","99.03959","1.20025","63.34600","0.00000","1.25083","0.20013"
"1.25083","99.02001","1.20001","63.52600","0.00000","1.25083","0.20013"
"1.25083","99.00224","1.19980","63.70600","0.00000","1.25083","0.20013"
"1.25083","98.98119","1.19954","63.88600","0.00000","1.25083","0.20013"
"1.25083","98.96182","1.19931","64.06600","0.00000","1.25083","0.20013"
"1.25083","98.94901","1.19915","64.24600","0.00000","1.25083","0.20013"
"1.25083","98.92444","1.19885","64.42600","0.00000","1.25083","0.20013"
"1.25083","98.91017","1.19868","64.60600","0.00000","1.25083","0.20013"
"1.25083","98.89252","1.19847","64.78600","0.00000","1.25083","0.20013"
"1.25083","98.87418","1.19824","64.96600","0.00000","1.25083","0.20013"
"1.25083","98.86220","1.19810","65.14600","0.00000","1.25083","0.20013"
"1.25083","98.83111","1.19772","65.32600","0.00000","1.25083","0.20013"
"1.25083","98.80947","1.19746","65.50600","0.00000","1.25083","0.20013"
"1.25083","98.79431","1.19728","65.68600","0.00000","1.25083","0.20013"
"1.25083","98.77365","1.19703","65.86600","0.00000","1.25083","0.20013"
"1.25083","98.75573","1.19681","66.04600","0.00000","1.25083","0.20013"
"1.25083","98.73994","1.19662","66.22600","0.00000","1.25083","0.20013"
"1.25083","98.71802","1.19635","66.40600","0.00000","1.25083","0.20013"
"1.25083","98.69712","1.19610","66.58600","0.00000","1.25083","0.20013"
"1.25083","98.68509","1.19595","66.76600","0.00000","1.25083","0.20013"
"1.25083","98.65792","1.19562","66.94600","0.00000","1.25083","0.20013"
"1.25083","98.64573","1.19548","67.12600","0.00000","1.25083","0.20013"
"1.25083","98.62164","1.19518","67.30600","0.00000","1.25083","0.20013"
"1.25083","98.60466","1.19498","67.48600","0.00000","1.25083","0.20013"
"1.25083","98.59505","1.19486","67.66600","0.00000","1.25083","0.20013"
"1.25083","98.57418","1.19461","67.84600","0.00000","1.25083","0.20013"
"1.25083","98.55457","1.19437","68.02600","0.00000","1.25083","0.20013"
"1.25083","98.53945","1.19419","68.20600","0.00000","1.25083","0.20013"
"1.25083","98.51219","1.19386","68.38600","0.00000","1.25083","0.20013"
"1.25083","98.49260","1.19362","68.56600","0.00000","1.25083","0.20013"
"1.25083","98.47372","1.19339","68.74600","0.00000","1.25083","0.20013"
"1.25083","98.46353","1.19327","68.92600","0.00000","1.25083","0.20013"
"1.25083","98.44175","1.19300","69.10600","0.00000","1.25083","0.20013"
"1.25083","98.42445","1.19279","69.28600","0.00000","1.25083","0.20013"
"1.25083","98.40949","1.19261","69.46600","0.00000","1.25083","0.20013"
"1.25083","98.39052","1.19238","69.64600","0.00000","1.25083","0.20013"
"1.25083","98.37009","1.19214","69.82600","0.00000","1.25083","0.20013"
"1.25083","98.35421","1.19194","70.00600","0.00000","1.25083","0.20013"
"1.25083","98.33155","1.19167","70.18600","0.00000","1.25083","0.20013"
"1.25083","98.31850","1.19151","70.36600","0.00000","1.25083","0.20013"
"1.25083","98.29652","1.19124","70.54600","0.00000","1.25083","0.20013"
"1.25083","98.27482","1.19098","70.72600","0.00000","1.25083","0.20013"
"1.25083","98.25811","1.19078","70.90600","0.00000","1.25083","0.20013"
"1.25083","98.24387","1.19061","71.08600","0.00000","1.25083","0.20013"
"1.25083","98.21961","1.19031","71.26600","0.00000","1.25083","0.20013"
"1.25083","98.21625","1.19027","71.44600","0.00000","1.25083","0.20013"
"1.25083","98.18910","1.18994","71.62600","0.00000","1.25083","0.20013"
"1.25083","98.17192","1.18973","71.80600","0.00000","1.25083","0.20013"
"1.25083","98.15980","1.18959","71.98600","0.00000","1.25083","0.20013"
"1.25083","98.14547","1.18941","72.16600","0.00000","1.25083","0.20013"
"1.25083","98.12618","1.18918","72.34600","0.00000","1.25083","0.20013"
"1.25083","98.11112","1.18900","72.52600","0.00000","1.25083","0.20013"
"1.25083","98.08971","1.18874","72.70600","0.00000","1.25083","0.20013"
"1.25083","98.07507","1.18856","72.88600","0.00000","1.25083","0.20013"
"1.25083","98.05615","1.18833","73.06600","0.00000","1.25083","0.20013"
"1.25083","98.04099","1.18815","73.24600","0.00000","1.25083","0.20013"
"1.25083","98.02316","1.18793","73.42600","0.00000","1.25083","0.20013"
"1.25083","98.00242","1.18768","73.60600","0.00000","1.25083","0.20013"
"1.25083","97.99191","1.18755","73.78600","0.00000","1.25083","0.20013"
"1.25083","97.98082","1.18742","73.96600","0.00000","1.25083","0.20013"
"1.25083","97.96214","1.18719","74.14600","0.00000","1.25083","0.20013"
"1.25083","97.93989","1.18692","74.32600","0.00000","1.25083","0.20013"
"1.25083","97.93575","1.18687","74.50600","0.00000","1.25083","0.20013"
"1.25083","97.91176","1.18658","74.68600","0.00000","1.25083","0.20013"
"1.25083","97.89609","1.18639","74.86600","0.00000","1.25083","0.20013"
"1.25083","97.87758","1.18617","75.04600","0.00000","1.25083","0.20013"
"1.25083","97.85753","1.18592","75.22600","0.00000","1.25083","0.20013"
"1.25083","97.84541","1.18578","75.40600","0.00000","1.25083","0.20013"
"1.25083","97.83118","1.18560","75.58600","0.00000","1.25083","0.20013"
"1.25083","97.81721","1.18543","75.76600","0.00000","1.25083","0.20013"
"1.25083","97.80078","1.18524","75.94600","0.00000","1.25083","0.20013"
"1.25083","97.78422","1.18503","76.12600","0.00000","1.25083","0.20013"
"1.25083","97.76405","1.18479","76.30600","0.00000","1.25083","0.20013"
"1.25083","97.75133","1.18464","76.48600","0.00000","1.25083","0.20013"
"1.25083","97.73790","1.18447","76.66600","0.00000","1.25083","0.20013"
"1.25083","97.71607","1.18421","76.84600","0.00000","1.25083","0.20013"
"1.25083","97.71018","1.18414","77.02600","0.00000","1.25083","0.20013"
"1.25083","97.69320","1.18393","77.20600","0.00000","1.25083","0.20013"
"1.25083","97.67163","1.18367","77.38600","0.00000","1.25083","0.20013"
"1.25083","97.65935","1.18352","77.56600","0.00000","1.25083","0.20013"
"1.25083","97.63888","1.18327","77.74600","0.00000","1.25083","0.20013"
"1.25083","97.62631","1.18312","77.92600","0.00000","1.25083","0.20013"
"1.25083","97.61415","1.18297","78.10600","0.00000","1.25083","0.20013"
"1.25083","97.59867","1.18279","78.28600","0.00000","1.25083","0.20013"
"1.25083","97.58369","1.18260","78.46600","0.00000","1.25083","0.20013"
"1.25083","97.56689","1.18240","78.64600","0.00000","1.25083","0.20013"
"1.25083","97.55322","1.18224","78.82600","0.00000","1.25083","0.20013"
"1.25083","97.53507","1.18202","79.00600","0.00000","1.25083","0.20013"
"1.25083","97.51933","1.18182","79.18600","0.00000","1.25083","0.20013"
"1.25083","97.51227","1.18174","79.36600","0.00000","1.25083","0.20013"
"1.25083","97.48797","1.18144","79.54600","0.00000","1.25083","0.20013"
"1.25083","97.47691","1.18131","79.72600","0.00000","1.25083","0.20013"
"1.25083","97.46075","1.18111","79.90600","0.00000","1.25083","0.20013"
"1.25083","97.43984","1.18086","80.08600","0.00000","1.25083","0.20013"
"1.25083","97.42726","1.18071","80.26600","0.00000","1.25083","0.20013"
"1.25083","97.41737","1.18059","80.44600","0.00000","1.25083","0.20013"
"1.25083","97.40553","1.18045","80.62600","0.00000","1.25083","0.20013"
"1.25083","97.37697","1.18010","80.80600","0.00000","1.25083","0.20013"
"1.25083","97.36994","1.18001","80.98600","0.00000","1.25083","0.20013"
"1.25083","97.35809","1.17987","81.16600","0.00000","1.25083","0.20013"
"1.25083","97.33604","1.17960","81.34600","0.00000","1.25083","0.20013"
"1.25083","97.33118","1.17954","81.52600","0.00000","1.25083","0.20013"
"1.25083","97.30996","1.17929","81.70600","0.00000","1.25083","0.20013"
"1.25083","97.29155","1.17906","81.88600","0.00000","1.25083","0.20013"
"1.25083","97.28571","1.17899","82.06600","0.00000","1.25083","0.20013"
"1.25083","97.27734","1.17889","82.24600","0.00000","1.25083","0.20013"
"1.25083","97.25405","1.17861","82.42600","0.00000","1.25083","0.20013"
"1.25083","97.23978","1.17844","82.60600","0.00000","1.25083","0.20013"
"1.25083","97.22503","1.17826","82.78600","0.00000","1.25083","0.20013"
"1.25083","97.20277","1.17799","82.96600","0.00000","1.25083","0.20013"
"1.25083","97.18698","1.17780","83.14600","0.00000","1.25083","0.20013"
"1.25083","97.17838","1.17769","83.32600","0.00000","1.25083","0.20013"
"1.25083","97.16012","1.17747","83.50600","0.00000","1.25083","0.20013"
"1.25083","97.14611","1.17730","83.68600","0.00000","1.25083","0.20013"
"1.25083","97.13272","1.17714","83.86600","0.00000","1.25083","0.20013"
"1.25083","97.12282","1.17702","84.04600","0.00000","1.25083","0.20013"
"1.25083","97.10922","1.17685","84.22600","0.00000","1.25083","0.20013"
"1.25083","97.09043","1.17663","84.40600","0.00000","1.25083","0.20013"
"1.25083","97.08196","1.17652","84.58600","0.00000","1.25083","0.20013"
"1.25083","97.06171","1.17628","84.76600","0.00000","1.25083","0.20013"
"1.25083","97.04487","1.17607","84.94600","0.00000","1.25083","0.20013"
"1.25083","97.03532","1.17596","85.12600","0.00000","1.25083","0.20013"
"1.25083","97.02195","1.17580","85.30600","0.00000","1.25083","0.20013"
"1.25083","97.00881","1.17564","85.48600","0.00000","1.25083","0.20013"
"1.25083","97.00060","1.17554","85.66600","0.00000","1.25083","0.20013"
"1.25083","96.98518","1.17535","85.84600","0.00000","1.25083","0.20013"
"1.25083","96.96838","1.17515","86.02600","0.00000","1.25083","0.20013"
"1.25083","96.95708","1.17501","86.20600","0.00000","1.25083","0.20013"
"1.25083","96.94341","1.17485","86.38600","0.00000","1.25083","0.20013"
"1.25083","96.92766","1.17465","86.56600","0.00000","1.25083","0.20013"
"1.25083","96.90700","1.17440","86.74600","0.00000","1.25083","0.20013"
"1.25083","96.89932","1.17431","86.92600","0.00000","1.25083","0.20013"
"1.25083","96.89078","1.17421","87.10600","0.00000","1.25083","0.20013"
"1.25083","96.87222","1.17398","87.28600","0.00000","1.25083","0.20013"
"1.25083","96.86086","1.17384","87.46600","0.00000","1.25083","0.20013"
"1.25083","96.84012","1.17359","87.64600","0.00000","1.25083","0.20013"
"1.25083","96.83084","1.17348","87.82600","0.00000","1.25083","0.20013"
"1.25083","96.81432","1.17328","88.00600","0.00000","1.25083","0.20013"
"1.25083","96.80015","1.17311","88.18600","0.00000","1.25083","0.20013"
"1.25083","96.78971","1.17298","88.36600","0.00000","1.25083","0.20013"
"1.25083","96.77718","1.17283","88.54600","0.00000","1.25083","0.20013"
"1.25083","96.76141","1.17264","88.72600","0.00000","1.25083","0.20013"
"1.25083","96.75414","1.17255","88.90600","0.00000","1.25083","0.20013"
"1.25083","96.73315","1.17230","89.08600","0.00000","1.25083","0.20013"
"1.25083","96.72234","1.17217","89.26600","0.00000","1.25083","0.20013"
"1.25083","96.71330","1.17206","89.44600","0.00000","1.25083","0.20013"
"1.25083","96.69563","1.17184","89.62600","0.00000","1.25083","0.20013"
"1.25083","96.68260","1.17168","89.80600","0.00000","1.25083","0.20013"
"1.25083","96.67464","1.17159","89.98600","0.00000","1.25083","0.20013"
"1.25083","96.66271","1.17144","90.16600","0.00000","1.25083","0.20013"
"1.25083","96.64649","1.17125","90.34600","0.00000","1.25083","0.20013"
"1.25083","96.63210","1.17107","90.52600","0.00000","1.25083","0.20013"
"1.25083","96.62025","1.17093","90.70600","0.00000","1.25083","0.20013"
"1.25083","96.60573","1.17075","90.88600","0.00000","1.25083","0.20013"
"1.25083","96.59423","1.17061","91.06600","0.00000","1.25083","0.20013"
"1.25083","96.58212","1.17047","91.24600","0.00000","1.25083","0.20013"
"1.25083","96.57269","1.17035","91.42600","0.00000","1.25083","0.20013"
"1.25083","96.55630","1.17015","91.60600","0.00000","1.25083","0.20013"
"1.25083","96.54476","1.17001","91.78600","0.00000","1.25083","0.20013"
"1.25083","96.52905","1.16982","91.96600","0.00000","1.25083","0.20013"
"1.25083","96.51713","1.16968","92.14600","0.00000","1.25083","0.20013"
"1.25083","96.50123","1.16949","92.32600","0.00000","1.25083","0.20013"
"1.25083","96.48788","1.16932","92.50600","0.00000","1.25083","0.20013"
"1.25083","96.47497","1.16917","92.68600","0.00000","1.25083","0.20013"
"1.25083","96.47149","1.16913","92.86600","0.00000","1.25083","0.20013"
"1.25083","96.45514","1.16893","93.04600","0.00000","1.25083","0.20013"
"1.25083","96.44189","1.16877","93.22600","0.00000","1.25083","0.20013"
"1.25083","96.42488","1.16856","93.40600","0.00000","1.25083","0.20013"
"1.25083","96.41564","1.16845","93.58600","0.00000","1.25083","0.20013"
"1.25083","96.40018","1.16826","93.76600","0.00000","1.25083","0.20013"
"1.25083","96.39533","1.16820","93.94600","0.00000","1.25083","0.20013"
"1.25083","96.38262","1.16805","94.12600","0.00000","1.25083","0.20013"
"1.25083","96.37035","1.16790","94.30600","0.00000","1.25083","0.20013"
"1.25083","96.34807","1.16763","94.48600","0.00000","1.25083","0.20013"
"1.25083","96.34998","1.16765","94.66600","0.00000","1.25083","0.20013"
"1.25083","96.33212","1.16744","94.84600","0.00000","1.25083","0.20013"
"1.25083","96.31843","1.16727","95.02600","0.00000","1.25083","0.20013"
"1.25083","96.30858","1.16715","95.20600","0.00000","1.25083","0.20013"
"1.25083","96.29610","1.16700","95.38600","0.00000","1.25083","0.20013"
"1.25083","96.28498","1.16687","95.56600","0.00000","1.25083","0.20013"
"1.25083","96.26502","1.16662","95.74600","0.00000","1.25083","0.20013"
"1.25083","96.26108","1.16658","95.92600","0.00000","1.25083","0.20013"
"1.25083","96.25310","1.16648","96.10600","0.00000","1.25083","0.20013"
"1.25083","96.23059","1.16621","96.28600","0.00000","1.25083","0.20013"
"1.25083","96.21360","1.16600","96.46600","0.00000","1.25083","0.20013"
"1.25083","96.21046","1.16596","96.64600","0.00000","1.25083","0.20013"
"1.25083","96.19854","1.16582","96.82600","0.00000","1.25083","0.20013"
"1.25083","96.18359","1.16564","97.00600","0.00000","1.25083","0.20013"
"1.25083","96.17720","1.16556","97.18600","0.00000","1.25083","0.20013"
"1.25083","96.16352","1.16539","97.36600","0.00000","1.25083","0.20013"
"1.25083","96.14658","1.16519","97.54600","0.00000","1.25083","0.20013"
"1.25083","96.13895","1.16510","97.72600","0.00000","1.25083","0.20013"
"1.25083","96.12560","1.16493","97.90600","0.00000","1.25083","0.20013"
"1.25083","96.11482","1.16480","98.08600","0.00000","1.25083","0.20013"
"1.25083","96.09795","1.16460","98.26600","0.00000","1.25083","0.20013"
"1.25083","96.09665","1.16458","98.44600","0.00000","1.25083","0.20013"
"1.25083","96.08572","1.16445","98.62600","0.00000","1.25083","0.20013"
"1.25083","96.06474","1.16420","98.80600","0.00000","1.25083","0.20013"
"1.25083","96.05967","1.16414","98.98600","0.00000","1.25083","0.20013"
"1.25083","96.04146","1.16391","99.16600","0.00000","1.25083","0.20013"
"1.25083","96.03896","1.16388","99.34600","0.00000","1.25083","0.20013"
"1.25083","96.02573","1.16372","99.52600","0.00000","1.25083","0.20013"
"1.25083","96.01350","1.16358","99.70600","0.00000","1.25083","0.20013"
"1.25083","95.99496","1.16335","99.88600","0.00000","1.25083","0.20013"
"1.25083","95.98424","1.16322","100.06600","0.00000","1.25083","0.20013"
"1.25083","95.97449","1.16310","100.24600","0.00000","1.25083","0.20013"
"1.25083","95.95988","1.16293","100.42600","0.00000","1.25083","0.20013"
"1.25083","95.95390","1.16285","100.60600","0.00000","1.25083","0.20013"
"1.25083","95.94435","1.16274","100.78600","0.00000","1.25083","0.20013"
"1.25083","95.93306","1.16260","100.96600","0.00000","1.25083","0.20013"
"1.25083","95.91591","1.16239","101.14600","0.00000","1.25083","0.20013"
"1.25083","95.90812","1.16230","101.32600","0.00000","1.25083","0.20013"
"1.25083","95.90147","1.16222","101.50600","0.00000","1.25083","0.20013"
"1.25083","95.88213","1.16198","101.68600","0.00000","1.25083","0.20013"
"1.25083","95.87582","1.16191","101.86600","0.00000","1.25083","0.20013"
"1.25083","95.86460","1.16177","102.04600","0.00000","1.25083","0.20013"
"1.25083","95.84294","1.16151","102.22600","0.00000","1.25083","0.20013"
"1.25083","95.83649","1.16143","102.40600","0.00000","1.25083","0.20013"
"1.25083","95.82676","1.16131","102.58600","0.00000","1.25083","0.20013"
"1.25083","95.81590","1.16118","102.76600","0.00000","1.25083","0.20013"
"1.25083","95.80002","1.16099","102.94600","0.00000","1.25083","0.20013"
"1.25083","95.79303","1.16090","103.12600","0.00000","1.25083","0.20013"
"1.25083","95.78398","1.16079","103.30600","0.00000","1.25083","0.20013"
"1.25083","95.76933","1.16062","103.48600","0.00000","1.25083","0.20013"
"1.25083","95.76405","1.16055","103.66600","0.00000","1.25083","0.20013"
"1.25083","95.75328","1.16042","103.84600","0.00000","1.25083","0.20013"
"1.25083","95.74332","1.16030","104.02600","0.00000","1.25083","0.20013"
"1.25083","95.72739","1.16011","104.20600","0.00000","1.25083","0.20013"
"1.25083","95.72236","1.16005","104.38600","0.00000","1.25083","0.20013"
"1.25083","95.70301","1.15981","104.56600","0.00000","1.25083","0.20013"
"1.25083","95.69279","1.15969","104.74600","0.00000","1.25083","0.20013"
"1.25083","95.68433","1.15959","104.92600","0.00000","1.25083","0.20013"
"1.25083","95.67292","1.15945","105.10600","0.00000","1.25083","0.20013"
"1.25083","95.67030","1.15942","105.28600","0.00000","1.25083","0.20013"
"1.25083","95.65987","1.15929","105.46600","0.00000","1.25083","0.20013"
"1.25083","95.64144","1.15907","105.64600","0.00000","1.25083","0.20013"
"1.25083","95.63210","1.15895","105.82600","0.00000","1.25083","0.20013"
"1.25083","95.61674","1.15877","106.00600","0.00000","1.25083","0.20013"
"1.25083","95.61064","1.15869","106.18600","0.00000","1.25083","0.20013"
"1.25083","95.60544","1.15863","106.36600","0.00000","1.25083","0.20013"
"1.25083","95.57758","1.15829","106.54600","0.00000","1.25083","0.20013"
"1.25083","95.58015","1.15832","106.72600","0.00000","1.25083","0.20013"
"1.25083","95.55988","1.15808","106.90600","0.00000","1.25083","0.20013"
"1.25083","95.54901","1.15795","107.08600","0.00000","1.25083","0.20013"
"1.25083","95.55134","1.15797","107.26600","0.00000","1.25083","0.20013"
"1.25083","95.53356","1.15776","107.44600","0.00000","1.25083","0.20013"
"1.25083","95.53587","1.15779","107.62600","0.00000","1.25083","0.20013"
"1.25083","95.51132","1.15749","107.80600","0.00000","1.25083","0.20013"
"1.25083","95.50582","1.15742","107.98600","0.00000","1.25083","0.20013"
"1.25083","95.48743","1.15720","108.16600","0.00000","1.25083","0.20013"
"1.25083","95.48800","1.15721","108.34600","0.00000","1.25083","0.20013"
"1.25083","95.47937","1.15710","108.52600","0.00000","1.25083","0.20013"
"1.25083","95.46252","1.15690","108.70600","0.00000","1.25083","0.20013"
"1.25083","95.45016","1.15675","108.88600","0.00000","1.25083","0.20013"
"1.25083","95.44508","1.15669","109.06600","0.00000","1.25083","0.20013"
"1.25083","95.43214","1.15653","109.24600","0.00000","1.25083","0.20013"
"1.25083","95.41399","1.15631","109.42600","0.00000","1.25083","0.20013"
"1.25083","95.40423","1.15619","109.60600","0.00000","1.25083","0.20013"
"1.25083","95.40633","1.15622","109.78600","0.00000","1.25083","0.20013"
"1.25083","95.38666","1.15598","109.96600","0.00000","1.25083","0.20013"
"1.25083","95.37616","1.15585","110.14600","0.00000","1.25083","0.20013"
"1.25083","95.37357","1.15582","110.32600","0.00000","1.25083","0.20013"
"1.25083","95.35913","1.15565","110.50600","0.00000","1.25083","0.20013"
"1.25083","95.34882","1.15552","110.68600","0.00000","1.25083","0.20013"
"1.25083","95.33140","1.15531","110.86600","0.00000","1.25083","0.20013"
"1.25083","95.32213","1.15520","111.04600","0.00000","1.25083","0.20013"
"1.25083","95.31715","1.15514","111.22600","0.00000","1.25083","0.20013"
"1.25083","95.30563","1.15500","111.40600","0.00000","1.25083","0.20013"
"1.25083","95.29375","1.15485","111.58600","0.00000","1.25083","0.20013"
"1.25083","95.28484","1.15475","111.76600","0.00000","1.25083","0.20013"
"1.25083","95.28000","1.15469","111.94600","0.00000","1.25083","0.20013"
"1.25083","95.26988","1.15456","112.12600","0.00000","1.25083","0.20013"
"1.25083","95.26225","1.15447","112.30600","0.00000","1.25083","0.20013"
"1.25083","95.23599","1.15415","112.48600","0.00000","1.25083","0.20013"
"1.25083","95.23907","1.15419","112.66600","0.00000","1.25083","0.20013"
"1.25083","95.22619","1.15403","112.84600","0.00000","1.25083","0.20013"
"1.25083","95.21697","1.15392","113.02600","0.00000","1.25083","0.20013"
"1.25083","95.21911","1.15395","113.20600","0.00000","1.25083","0.20013"
"1.25083","95.20470","1.15377","113.38600","0.00000","1.25083","0.20013"
"1.25083","95.18917","1.15359","113.56600","0.00000","1.25083","0.20013"
"1.25083","95.17337","1.15339","113.74600","0.00000","1.25083","0.20013"
"1.25083","95.16285","1.15327","113.92600","0.00000","1.25083","0.20013"
"1.25083","95.15624","1.15319","114.10600","0.00000","1.25083","0.20013"
"1.25083","95.14394","1.15304","114.28600","0.00000","1.25083","0.20013"
"1.25083","95.13333","1.15291","114.46600","0.00000","1.25083","0.20013"
"1.25083","95.13568","1.15294","114.64600","0.00000","1.25083","0.20013"
"1.25083","95.12281","1.15278","114.82600","0.00000","1.25083","0.20013"
"1.25083","95.10883","1.15261","115.00600","0.00000","1.25083","0.20013"
"1.25083","95.09044","1.15239","115.18600","0.00000","1.25083","0.20013"
"1.25083","95.08698","1.15235","115.36600","0.00000","1.25083","0.20013"
"1.25083","95.07858","1.15225","115.54600","0.00000","1.25083","0.20013"
"1.25083","95.06892","1.15213","115.72600","0.00000","1.25083","0.20013"
"1.25083","95.05936","1.15201","115.90600","0.00000","1.25083","0.20013"
"1.25083","95.03571","1.15173","116.08600","0.00000","1.25083","0.20013"
"1.25083","95.04311","1.15182","116.26600","0.00000","1.25083","0.20013"
"1.25083","95.03558","1.15172","116.44600","0.00000","1.25083","0.20013"
"1.25083","95.01842","1.15152","116.62600","0.00000","1.25083","0.20013"
"1.25083","95.00995","1.15141","116.80600","0.00000","1.25083","0.20013"
"1.25083","95.00368","1.15134","116.98600","0.00000","1.25083","0.20013"
"1.25083","95.00098","1.15131","117.16600","0.00000","1.25083","0.20013"
"1.25083","94.99931","1.15129","117.34600","0.00000","1.25083","0.20013"
"1.25083","94.97914","1.15104","117.52600","0.00000","1.25083","0.20013"
"1.25083","94.96450","1.15086","117.70600","0.00000","1.25083","0.20013"
"1.25083","94.95567","1.15076","117.88600","0.00000","1.25083","0.20013"
"1.25083","94.94636","1.15064","118.06600","0.00000","1.25083","0.20013"
"1.25083","94.93718","1.15053","118.24600","0.00000","1.25083","0.20013"
"1.25083","94.92981","1.15044","118.42600","0.00000","1.25083","0.20013"
"1.25083","94.91841","1.15030","118.60600","0.00000","1.25083","0.20013"
"1.25083","94.90134","1.15010","118.78600","0.00000","1.25083","0.20013"
"1.25083","94.89339","1.15000","118.96600","0.00000","1.25083","0.20013"
"1.25083","94.89104","1.14997","119.14600","0.00000","1.25083","0.20013"
"1.25083","94.88369","1.14988","119.32600","0.00000","1.25083","0.20013"
"1.25083","94.86988","1.14972","119.50600","0.00000","1.25083","0.20013"
"1.25083","94.85927","1.14959","119.68600","0.00000","1.25083","0.20013"
"1.25083","94.85382","1.14952","119.86600","0.00000","1.25083","0.20013"
"1.25083","94.85029","1.14948","120.04600","0.00000","1.25083","0.20013"
"1.25083","94.83019","1.14924","120.22600","0.00000","1.25083","0.20013"
"1.25083","94.82201","1.14914","120.40600","0.00000","1.25083","0.20013"
"1.25083","94.81093","1.14900","120.58600","0.00000","1.25083","0.20013"
"1.25083","94.80244","1.14890","120.76600","0.00000","1.25083","0.20013"
"1.25083","94.79080","1.14876","120.94600","0.00000","1.25083","0.20013"
"1.25083","94.79213","1.14877","121.12600","0.00000","1.25083","0.20013"
"1.25083","94.77660","1.14859","121.30600","0.00000","1.25083","0.20013"
"1.25083","94.76917","1.14850","121.48600","0.00000","1.25083","0.20013"
"1.25083","94.75368","1.14831","121.66600","0.00000","1.25083","0.20013"
"1.25083","94.74404","1.14819","121.84600","0.00000","1.25083","0.20013"
"1.25083","94.73875","1.14813","122.02600","0.00000","1.25083","0.20013"
"1.25083","94.73056","1.14803","122.20600","0.00000","1.25083","0.20013"
"1.25083","94.72684","1.14798","122.38600","0.00000","1.25083","0.20013"
"1.25083","94.70846","1.14776","122.56600","0.00000","1.25083","0.20013"
"1.25083","94.70836","1.14776","122.74600","0.00000","1.25083","0.20013"
"1.25083","94.69848","1.14764","122.92600","0.00000","1.25083","0.20013"
"1.25083","94.68423","1.14747","123.10600","0.00000","1.25083","0.20013"
"1.25083","94.68681","1.14750","123.12600","0.00000","1.25083","0.20013"