File: Rubber Stress Relaxation Raw Data -Large  Samples-20210211/Specimen_RawData_3.csv
Specimen properties : Specimen label,"4"
Specimen properties : Anvil height,"6.34000",mm
Specimen properties : Diameter,"10.28000",mm
Test : Rate 1,"2.40000",mm/min
Test : Start of hold value,"20.00000",%
Test : Duration,"120.00000",s

Extension,Load,Compressive stress,Time,PIP count,Compressive extension,Compressive strain (Extension)
(mm),(N),(MPa),(s),,(mm),(mm/mm)
"0.00000","0.00089","0.00001","0.00000","0.00000","0.00000","0.00000"
"0.00271","0.17723","0.00214","0.23000","0.00000","0.00271","0.00043"
"0.01375","1.10168","0.01327","0.46000","0.00000","0.01375","0.00217"
"0.02646","2.32548","0.02802","0.69000","0.00000","0.02646","0.00417"
"0.03625","3.35880","0.04047","0.92000","0.00000","0.03625","0.00572"
"0.04542","4.42862","0.05336","1.15000","0.00000","0.04542","0.00716"
"0.05500","5.68927","0.06855","1.38000","0.00000","0.05500","0.00868"
"0.06417","6.98358","0.08414","1.61000","0.00000","0.06417","0.01012"
"0.07333","8.30122","0.10002","1.84000","0.00000","0.07333","0.01157"
"0.08229","9.59319","0.11558","2.07000","0.00000","0.08229","0.01298"
"0.09188","11.00169","0.13255","2.30000","0.00000","0.09188","0.01449"
"0.10146","12.28150","0.14797","2.53000","0.00000","0.10146","0.01600"
"0.11042","13.43011","0.16181","2.76000","0.00000","0.11042","0.01742"
"0.11958","14.57817","0.17564","2.99000","0.00000","0.11958","0.01886"
"0.12875","15.63440","0.18837","3.22000","0.00000","0.12875","0.02031"
"0.13833","16.75052","0.20181","3.45000","0.00000","0.13833","0.02182"
"0.14729","17.74550","0.21380","3.68000","0.00000","0.14729","0.02323"
"0.15625","18.74865","0.22589","3.91000","0.00000","0.15625","0.02465"
"0.16542","19.73025","0.23771","4.14000","0.00000","0.16542","0.02609"
"0.17479","20.72403","0.24969","4.37000","0.00000","0.17479","0.02757"
"0.18417","21.72848","0.26179","4.60000","0.00000","0.18417","0.02905"
"0.19312","22.62982","0.27265","4.83000","0.00000","0.19312","0.03046"
"0.20208","23.52467","0.28343","5.06000","0.00000","0.20208","0.03187"
"0.21146","24.52875","0.29553","5.29000","0.00000","0.21146","0.03335"
"0.22104","25.52284","0.30751","5.52000","0.00000","0.22104","0.03486"
"0.23000","26.32584","0.31718","5.75000","0.00000","0.23000","0.03628"
"0.23896","27.23425","0.32813","5.98000","0.00000","0.23896","0.03769"
"0.24813","28.13399","0.33897","6.21000","0.00000","0.24813","0.03914"
"0.25792","29.09973","0.35060","6.44000","0.00000","0.25792","0.04068"
"0.26708","29.95517","0.36091","6.67000","0.00000","0.26708","0.04213"
"0.27583","30.73385","0.37029","6.90000","0.00000","0.27583","0.04351"
"0.28479","31.53434","0.37993","7.13000","0.00000","0.28479","0.04492"
"0.29417","32.41299","0.39052","7.36000","0.00000","0.29417","0.04640"
"0.30396","33.35966","0.40193","7.59000","0.00000","0.30396","0.04794"
"0.31292","34.09287","0.41076","7.82000","0.00000","0.31292","0.04936"
"0.32188","34.90447","0.42054","8.05000","0.00000","0.32188","0.05077"
"0.33104","35.80422","0.43138","8.28000","0.00000","0.33104","0.05221"
"0.34083","36.79889","0.44336","8.51000","0.00000","0.34083","0.05376"
"0.35000","37.57278","0.45269","8.74000","0.00000","0.35000","0.05521"
"0.35875","38.36083","0.46218","8.97000","0.00000","0.35875","0.05659"
"0.36771","39.20073","0.47230","9.20000","0.00000","0.36771","0.05800"
"0.37708","40.09846","0.48312","9.43000","0.00000","0.37708","0.05948"
"0.38667","41.02425","0.49427","9.66000","0.00000","0.38667","0.06099"
"0.39563","41.77914","0.50337","9.89000","0.00000","0.39563","0.06240"
"0.40458","42.57870","0.51300","10.12000","0.00000","0.40458","0.06381"
"0.41375","43.50713","0.52418","10.35000","0.00000","0.41375","0.06526"
"0.42354","44.44368","0.53547","10.58000","0.00000","0.42354","0.06680"
"0.43271","45.21615","0.54478","10.81000","0.00000","0.43271","0.06825"
"0.44125","45.93759","0.55347","11.04000","0.00000","0.44125","0.06960"
"0.45042","46.87773","0.56479","11.27000","0.00000","0.45042","0.07104"
"0.46000","47.83168","0.57629","11.50000","0.00000","0.46000","0.07256"
"0.46958","48.72128","0.58701","11.73000","0.00000","0.46958","0.07407"
"0.47833","49.46780","0.59600","11.96000","0.00000","0.47833","0.07545"
"0.48750","50.34459","0.60656","12.19000","0.00000","0.48750","0.07689"
"0.49688","51.29124","0.61797","12.42000","0.00000","0.49688","0.07837"
"0.50625","52.20434","0.62897","12.65000","0.00000","0.50625","0.07985"
"0.51563","53.02030","0.63880","12.88000","0.00000","0.51563","0.08133"
"0.52417","53.74998","0.64759","13.11000","0.00000","0.52417","0.08268"
"0.53333","54.68648","0.65888","13.34000","0.00000","0.53333","0.08412"
"0.54271","55.61628","0.67008","13.57000","0.00000","0.54271","0.08560"
"0.55250","56.57167","0.68159","13.80000","0.00000","0.55250","0.08715"
"0.56125","57.27996","0.69012","14.03000","0.00000","0.56125","0.08853"
"0.57021","58.16355","0.70077","14.26000","0.00000","0.57021","0.08994"
"0.57979","59.15443","0.71271","14.49000","0.00000","0.57979","0.09145"
"0.58896","60.04271","0.72341","14.72000","0.00000","0.58896","0.09290"
"0.59813","60.85453","0.73319","14.95000","0.00000","0.59813","0.09434"
"0.60688","61.65863","0.74288","15.18000","0.00000","0.60688","0.09572"
"0.61625","62.66412","0.75499","15.41000","0.00000","0.61625","0.09720"
"0.62563","63.56020","0.76579","15.64000","0.00000","0.62563","0.09868"
"0.63500","64.49950","0.77711","15.87000","0.00000","0.63500","0.10016"
"0.64417","65.33399","0.78716","16.10000","0.00000","0.64417","0.10160"
"0.65313","66.23267","0.79799","16.33000","0.00000","0.65313","0.10302"
"0.66250","67.21938","0.80988","16.56000","0.00000","0.66250","0.10450"
"0.67167","68.10430","0.82054","16.79000","0.00000","0.67167","0.10594"
"0.68083","68.95686","0.83081","17.02000","0.00000","0.68083","0.10739"
"0.68979","69.79382","0.84089","17.25000","0.00000","0.68979","0.10880"
"0.69917","70.82699","0.85334","17.48000","0.00000","0.69917","0.11028"
"0.70833","71.70598","0.86393","17.71000","0.00000","0.70833","0.11172"
"0.71771","72.62229","0.87497","17.94000","0.00000","0.71771","0.11320"
"0.72667","73.49567","0.88549","18.17000","0.00000","0.72667","0.11462"
"0.73583","74.48952","0.89747","18.40000","0.00000","0.73583","0.11606"
"0.74521","75.44795","0.90902","18.63000","0.00000","0.74521","0.11754"
"0.75458","76.43238","0.92088","18.86000","0.00000","0.75458","0.11902"
"0.76396","77.29279","0.93124","19.09000","0.00000","0.76396","0.12050"
"0.77292","78.18591","0.94200","19.32000","0.00000","0.77292","0.12191"
"0.78208","79.12814","0.95336","19.55000","0.00000","0.78208","0.12336"
"0.79125","80.07976","0.96482","19.78000","0.00000","0.79125","0.12480"
"0.80021","80.96391","0.97547","20.01000","0.00000","0.80021","0.12622"
"0.80979","81.98770","0.98781","20.24000","0.00000","0.80979","0.12773"
"0.81875","82.91015","0.99892","20.47000","0.00000","0.81875","0.12914"
"0.82771","83.81368","1.00981","20.70000","0.00000","0.82771","0.13055"
"0.83688","84.75688","1.02117","20.93000","0.00000","0.83688","0.13200"
"0.84646","85.78692","1.03358","21.16000","0.00000","0.84646","0.13351"
"0.85563","86.76077","1.04532","21.39000","0.00000","0.85563","0.13496"
"0.86458","87.61692","1.05563","21.62000","0.00000","0.86458","0.13637"
"0.87396","88.65437","1.06813","21.85000","0.00000","0.87396","0.13785"
"0.88313","89.61849","1.07975","22.08000","0.00000","0.88313","0.13929"
"0.89271","90.70773","1.09287","22.31000","0.00000","0.89271","0.14081"
"0.90167","91.63630","1.10406","22.54000","0.00000","0.90167","0.14222"
"0.91083","92.60651","1.11575","22.77000","0.00000","0.91083","0.14366"
"0.91979","93.48992","1.12639","23.00000","0.00000","0.91979","0.14508"
"0.92917","94.55499","1.13922","23.23000","0.00000","0.92917","0.14656"
"0.93854","95.59019","1.15169","23.46000","0.00000","0.93854","0.14803"
"0.94750","96.53594","1.16309","23.69000","0.00000","0.94750","0.14945"
"0.95646","97.46101","1.17423","23.92000","0.00000","0.95646","0.15086"
"0.96625","98.68510","1.18898","24.15000","0.00000","0.96625","0.15241"
"0.97562","99.67982","1.20097","24.38000","0.00000","0.97563","0.15388"
"0.98458","100.57913","1.21180","24.61000","0.00000","0.98458","0.15530"
"0.99354","101.60855","1.22421","24.84000","0.00000","0.99354","0.15671"
"1.00250","102.56123","1.23568","25.07000","0.00000","1.00250","0.15812"
"1.01208","103.71619","1.24960","25.30000","0.00000","1.01208","0.15963"
"1.02125","104.71062","1.26158","25.53000","0.00000","1.02125","0.16108"
"1.03021","105.66319","1.27306","25.76000","0.00000","1.03021","0.16249"
"1.03917","106.62378","1.28463","25.99000","0.00000","1.03917","0.16391"
"1.04875","107.79110","1.29869","26.22000","0.00000","1.04875","0.16542"
"1.05833","108.88731","1.31190","26.45000","0.00000","1.05833","0.16693"
"1.06688","109.73698","1.32214","26.68000","0.00000","1.06688","0.16828"
"1.07604","110.81128","1.33508","26.91000","0.00000","1.07604","0.16972"
"1.08542","111.99495","1.34934","27.14000","0.00000","1.08542","0.17120"
"1.09521","113.18512","1.36368","27.37000","0.00000","1.09521","0.17275"
"1.10417","114.02936","1.37385","27.60000","0.00000","1.10417","0.17416"
"1.11292","114.99312","1.38547","27.83000","0.00000","1.11292","0.17554"
"1.12208","116.07868","1.39854","28.06000","0.00000","1.12208","0.17698"
"1.13188","117.27878","1.41300","28.29000","0.00000","1.13188","0.17853"
"1.14104","118.32562","1.42562","28.52000","0.00000","1.14104","0.17998"
"1.15000","119.23884","1.43662","28.75000","0.00000","1.15000","0.18139"
"1.15896","120.27405","1.44909","28.98000","0.00000","1.15896","0.18280"
"1.16833","121.54393","1.46439","29.21000","0.00000","1.16833","0.18428"
"1.17813","122.80396","1.47957","29.44000","0.00000","1.17813","0.18582"
"1.18708","123.72330","1.49065","29.67000","0.00000","1.18708","0.18724"
"1.19583","124.70014","1.50242","29.90000","0.00000","1.19583","0.18862"
"1.20500","125.91348","1.51704","30.13000","0.00000","1.20500","0.19006"
"1.21458","127.13467","1.53175","30.36000","0.00000","1.21458","0.19157"
"1.22375","128.21246","1.54474","30.59000","0.00000","1.22375","0.19302"
"1.23250","129.19449","1.55657","30.82000","0.00000","1.23250","0.19440"
"1.24167","130.46646","1.57189","31.05000","0.00000","1.24167","0.19585"
"1.25125","131.74182","1.58726","31.28000","0.00000","1.25125","0.19736"
"1.26083","132.92552","1.60152","31.51000","0.00000","1.26083","0.19887"
"1.26896","133.80927","1.61217","31.73200","0.00000","1.26896","0.20015"
"1.26958","131.04356","1.57885","31.96200","0.00000","1.26958","0.20025"
"1.26958","129.03909","1.55470","32.19200","0.00000","1.26958","0.20025"
"1.26958","127.58169","1.53714","32.42200","0.00000","1.26958","0.20025"
"1.26958","126.43204","1.52328","32.65200","0.00000","1.26958","0.20025"
"1.26917","125.37164","1.51051","32.88200","0.00000","1.26917","0.20018"
"1.26896","124.51118","1.50014","33.11200","0.00000","1.26896","0.20015"
"1.26896","123.78394","1.49138","33.34200","0.00000","1.26896","0.20015"
"1.26875","123.04954","1.48253","33.57200","0.00000","1.26875","0.20012"
"1.26875","122.45081","1.47532","33.80200","0.00000","1.26875","0.20012"
"1.26854","121.85929","1.46819","34.03200","0.00000","1.26854","0.20009"
"1.26833","121.29317","1.46137","34.26200","0.00000","1.26833","0.20005"
"1.26833","120.84749","1.45600","34.49200","0.00000","1.26833","0.20005"
"1.26833","120.40179","1.45063","34.72200","0.00000","1.26833","0.20005"
"1.26813","119.97021","1.44543","34.95200","0.00000","1.26813","0.20002"
"1.26813","119.59467","1.44091","35.18200","0.00000","1.26813","0.20002"
"1.26813","119.23866","1.43662","35.41200","0.00000","1.26813","0.20002"
"1.26813","118.90229","1.43256","35.64200","0.00000","1.26813","0.20002"
"1.26813","118.57380","1.42861","35.87200","0.00000","1.26813","0.20002"
"1.26813","118.26050","1.42483","36.10200","0.00000","1.26813","0.20002"
"1.26813","117.95624","1.42117","36.33200","0.00000","1.26813","0.20002"
"1.26813","117.68293","1.41787","36.56200","0.00000","1.26813","0.20002"
"1.26813","117.40247","1.41449","36.79200","0.00000","1.26813","0.20002"
"1.26813","117.13718","1.41130","37.02200","0.00000","1.26813","0.20002"
"1.26813","116.89448","1.40837","37.25200","0.00000","1.26813","0.20002"
"1.26813","116.63753","1.40528","37.48200","0.00000","1.26813","0.20002"
"1.26813","116.40540","1.40248","37.71200","0.00000","1.26813","0.20002"
"1.26813","116.17447","1.39970","37.94200","0.00000","1.26813","0.20002"
"1.26813","115.95178","1.39702","38.17200","0.00000","1.26813","0.20002"
"1.26813","115.73470","1.39440","38.40200","0.00000","1.26813","0.20002"
"1.26813","115.52377","1.39186","38.63200","0.00000","1.26813","0.20002"
"1.26813","115.32733","1.38949","38.86200","0.00000","1.26813","0.20002"
"1.26813","115.12467","1.38705","39.09200","0.00000","1.26813","0.20002"
"1.26813","114.94403","1.38487","39.32200","0.00000","1.26813","0.20002"
"1.26813","114.75046","1.38254","39.55200","0.00000","1.26813","0.20002"
"1.26813","114.57121","1.38038","39.78200","0.00000","1.26813","0.20002"
"1.26813","114.39285","1.37823","40.01200","0.00000","1.26813","0.20002"
"1.26813","114.21946","1.37614","40.24200","0.00000","1.26813","0.20002"
"1.26813","114.04909","1.37409","40.47200","0.00000","1.26813","0.20002"
"1.26813","113.88461","1.37211","40.70200","0.00000","1.26813","0.20002"
"1.26813","113.73360","1.37029","40.93200","0.00000","1.26813","0.20002"
"1.26813","113.57365","1.36836","41.16200","0.00000","1.26813","0.20002"
"1.26813","113.41772","1.36648","41.39200","0.00000","1.26813","0.20002"
"1.26813","113.26247","1.36461","41.62200","0.00000","1.26813","0.20002"
"1.26813","113.11458","1.36283","41.85200","0.00000","1.26813","0.20002"
"1.26813","112.97563","1.36116","42.08200","0.00000","1.26813","0.20002"
"1.26813","112.83299","1.35944","42.31200","0.00000","1.26813","0.20002"
"1.26813","112.69508","1.35778","42.54200","0.00000","1.26813","0.20002"
"1.26813","112.55839","1.35613","42.77200","0.00000","1.26813","0.20002"
"1.26813","112.42687","1.35455","43.00200","0.00000","1.26813","0.20002"
"1.26813","112.29174","1.35292","43.23200","0.00000","1.26813","0.20002"
"1.26813","112.17002","1.35145","43.46200","0.00000","1.26813","0.20002"
"1.26813","112.03912","1.34988","43.69200","0.00000","1.26813","0.20002"
"1.26813","111.91942","1.34843","43.92200","0.00000","1.26813","0.20002"
"1.26813","111.80414","1.34704","44.15200","0.00000","1.26813","0.20002"
"1.26813","111.67507","1.34549","44.38200","0.00000","1.26813","0.20002"
"1.26813","111.56144","1.34412","44.61200","0.00000","1.26813","0.20002"
"1.26813","111.44641","1.34273","44.84200","0.00000","1.26813","0.20002"
"1.26813","111.33343","1.34137","45.07200","0.00000","1.26813","0.20002"
"1.26813","111.21780","1.33998","45.30200","0.00000","1.26813","0.20002"
"1.26813","111.11386","1.33873","45.53200","0.00000","1.26813","0.20002"
"1.26813","111.00172","1.33738","45.76200","0.00000","1.26813","0.20002"
"1.26813","110.90324","1.33619","45.99200","0.00000","1.26813","0.20002"
"1.26813","110.78783","1.33480","46.22200","0.00000","1.26813","0.20002"
"1.26813","110.70220","1.33377","46.45200","0.00000","1.26813","0.20002"
"1.26813","110.58475","1.33235","46.68200","0.00000","1.26813","0.20002"
"1.26813","110.50272","1.33136","46.91200","0.00000","1.26813","0.20002"
"1.26813","110.39188","1.33003","47.14200","0.00000","1.26813","0.20002"
"1.26813","110.29665","1.32888","47.37200","0.00000","1.26813","0.20002"
"1.26813","110.20427","1.32777","47.60200","0.00000","1.26813","0.20002"
"1.26813","110.10411","1.32656","47.83200","0.00000","1.26813","0.20002"
"1.26813","110.00912","1.32542","48.06200","0.00000","1.26813","0.20002"
"1.26813","109.93037","1.32447","48.29200","0.00000","1.26813","0.20002"
"1.26813","109.82616","1.32321","48.52200","0.00000","1.26813","0.20002"
"1.26813","109.73885","1.32216","48.75200","0.00000","1.26813","0.20002"
"1.26813","109.65388","1.32114","48.98200","0.00000","1.26813","0.20002"
"1.26813","109.56915","1.32012","49.21200","0.00000","1.26813","0.20002"
"1.26813","109.48814","1.31914","49.44200","0.00000","1.26813","0.20002"
"1.26813","109.39341","1.31800","49.67200","0.00000","1.26813","0.20002"
"1.26813","109.31799","1.31709","49.90200","0.00000","1.26813","0.20002"
"1.26813","109.22987","1.31603","50.13200","0.00000","1.26813","0.20002"
"1.26813","109.16042","1.31519","50.36200","0.00000","1.26813","0.20002"
"1.26813","109.06667","1.31406","50.59200","0.00000","1.26813","0.20002"
"1.26813","108.99377","1.31318","50.82200","0.00000","1.26813","0.20002"
"1.26813","108.90528","1.31212","51.05200","0.00000","1.26813","0.20002"
"1.26813","108.83259","1.31124","51.28200","0.00000","1.26813","0.20002"
"1.26813","108.75827","1.31035","51.51200","0.00000","1.26813","0.20002"
"1.26813","108.68120","1.30942","51.74200","0.00000","1.26813","0.20002"
"1.26813","108.60564","1.30851","51.97200","0.00000","1.26813","0.20002"
"1.26813","108.53425","1.30765","52.20200","0.00000","1.26813","0.20002"
"1.26813","108.45559","1.30670","52.43200","0.00000","1.26813","0.20002"
"1.26813","108.38499","1.30585","52.66200","0.00000","1.26813","0.20002"
"1.26813","108.31992","1.30507","52.89200","0.00000","1.26813","0.20002"
"1.26813","108.23650","1.30406","53.12200","0.00000","1.26813","0.20002"
"1.26813","108.16725","1.30323","53.35200","0.00000","1.26813","0.20002"
"1.26813","108.10916","1.30253","53.58200","0.00000","1.26813","0.20002"
"1.26813","108.03591","1.30164","53.81200","0.00000","1.26813","0.20002"
"1.26813","107.96891","1.30084","54.04200","0.00000","1.26813","0.20002"
"1.26813","107.89811","1.29998","54.27200","0.00000","1.26813","0.20002"
"1.26813","107.82072","1.29905","54.50200","0.00000","1.26813","0.20002"
"1.26813","107.76075","1.29833","54.73200","0.00000","1.26813","0.20002"
"1.26813","107.70295","1.29763","54.96200","0.00000","1.26813","0.20002"
"1.26813","107.63715","1.29684","55.19200","0.00000","1.26813","0.20002"
"1.26813","107.57311","1.29607","55.42200","0.00000","1.26813","0.20002"
"1.26813","107.50500","1.29525","55.65200","0.00000","1.26813","0.20002"
"1.26813","107.45525","1.29465","55.88200","0.00000","1.26813","0.20002"
"1.26813","107.38689","1.29382","56.11200","0.00000","1.26813","0.20002"
"1.26813","107.32329","1.29306","56.34200","0.00000","1.26813","0.20002"
"1.26813","107.27085","1.29243","56.57200","0.00000","1.26813","0.20002"
"1.26813","107.20190","1.29160","56.80200","0.00000","1.26813","0.20002"
"1.26813","107.14336","1.29089","57.03200","0.00000","1.26813","0.20002"
"1.26813","107.08501","1.29019","57.26200","0.00000","1.26813","0.20002"
"1.26813","107.02355","1.28945","57.49200","0.00000","1.26813","0.20002"
"1.26813","106.96561","1.28875","57.72200","0.00000","1.26813","0.20002"
"1.26813","106.91821","1.28818","57.95200","0.00000","1.26813","0.20002"
"1.26813","106.85107","1.28737","58.18200","0.00000","1.26813","0.20002"
"1.26813","106.79465","1.28669","58.41200","0.00000","1.26813","0.20002"
"1.26813","106.73502","1.28597","58.64200","0.00000","1.26813","0.20002"
"1.26813","106.68255","1.28534","58.87200","0.00000","1.26813","0.20002"
"1.26813","106.62656","1.28466","59.10200","0.00000","1.26813","0.20002"
"1.26813","106.57586","1.28405","59.33200","0.00000","1.26813","0.20002"
"1.26813","106.51844","1.28336","59.56200","0.00000","1.26813","0.20002"
"1.26813","106.47421","1.28283","59.79200","0.00000","1.26813","0.20002"
"1.26813","106.41380","1.28210","60.02200","0.00000","1.26813","0.20002"
"1.26813","106.36533","1.28152","60.25200","0.00000","1.26813","0.20002"
"1.26813","106.30341","1.28077","60.48200","0.00000","1.26813","0.20002"
"1.26813","106.26481","1.28030","60.71200","0.00000","1.26813","0.20002"
"1.26813","106.20289","1.27956","60.94200","0.00000","1.26813","0.20002"
"1.26813","106.16166","1.27906","61.17200","0.00000","1.26813","0.20002"
"1.26813","106.10374","1.27836","61.40200","0.00000","1.26813","0.20002"
"1.26813","106.05424","1.27777","61.63200","0.00000","1.26813","0.20002"
"1.26813","106.00037","1.27712","61.86200","0.00000","1.26813","0.20002"
"1.26813","105.96007","1.27663","62.09200","0.00000","1.26813","0.20002"
"1.26813","105.91173","1.27605","62.32200","0.00000","1.26813","0.20002"
"1.26813","105.85710","1.27539","62.55200","0.00000","1.26813","0.20002"
"1.26813","105.80779","1.27480","62.78200","0.00000","1.26813","0.20002"
"1.26813","105.76234","1.27425","63.01200","0.00000","1.26813","0.20002"
"1.26813","105.71143","1.27364","63.24200","0.00000","1.26813","0.20002"
"1.26813","105.66931","1.27313","63.47200","0.00000","1.26813","0.20002"
"1.26813","105.62414","1.27259","63.70200","0.00000","1.26813","0.20002"
"1.26813","105.57514","1.27200","63.93200","0.00000","1.26813","0.20002"
"1.26813","105.53094","1.27146","64.16200","0.00000","1.26813","0.20002"
"1.26813","105.48360","1.27089","64.39200","0.00000","1.26813","0.20002"
"1.26813","105.43326","1.27029","64.62200","0.00000","1.26813","0.20002"
"1.26813","105.38298","1.26968","64.85200","0.00000","1.26813","0.20002"
"1.26813","105.34563","1.26923","65.08200","0.00000","1.26813","0.20002"
"1.26813","105.30132","1.26870","65.31200","0.00000","1.26813","0.20002"
"1.26813","105.26112","1.26821","65.54200","0.00000","1.26813","0.20002"
"1.26813","105.20416","1.26753","65.77200","0.00000","1.26813","0.20002"
"1.26813","105.16877","1.26710","66.00200","0.00000","1.26813","0.20002"
"1.26813","105.11729","1.26648","66.23200","0.00000","1.26813","0.20002"
"1.26813","105.08048","1.26604","66.46200","0.00000","1.26813","0.20002"
"1.26813","105.02936","1.26542","66.69200","0.00000","1.26813","0.20002"
"1.26813","104.98625","1.26490","66.92200","0.00000","1.26813","0.20002"
"1.26813","104.94815","1.26444","67.15200","0.00000","1.26813","0.20002"
"1.26813","104.91414","1.26403","67.38200","0.00000","1.26813","0.20002"
"1.26813","104.86166","1.26340","67.61200","0.00000","1.26813","0.20002"
"1.26813","104.82085","1.26291","67.84200","0.00000","1.26813","0.20002"
"1.26813","104.78626","1.26249","68.07200","0.00000","1.26813","0.20002"
"1.26813","104.73878","1.26192","68.30200","0.00000","1.26813","0.20002"
"1.26813","104.70872","1.26156","68.53200","0.00000","1.26813","0.20002"
"1.26813","104.64787","1.26082","68.76200","0.00000","1.26813","0.20002"
"1.26813","104.63210","1.26063","68.99200","0.00000","1.26813","0.20002"
"1.26813","104.57599","1.25996","69.22200","0.00000","1.26813","0.20002"
"1.26813","104.54022","1.25953","69.45200","0.00000","1.26813","0.20002"
"1.26813","104.50172","1.25906","69.68200","0.00000","1.26813","0.20002"
"1.26813","104.46087","1.25857","69.91200","0.00000","1.26813","0.20002"
"1.26813","104.42494","1.25814","70.14200","0.00000","1.26813","0.20002"
"1.26813","104.38296","1.25763","70.37200","0.00000","1.26813","0.20002"
"1.26813","104.34091","1.25713","70.60200","0.00000","1.26813","0.20002"
"1.26813","104.30721","1.25672","70.83200","0.00000","1.26813","0.20002"
"1.26813","104.26863","1.25625","71.06200","0.00000","1.26813","0.20002"
"1.26813","104.23471","1.25585","71.29200","0.00000","1.26813","0.20002"
"1.26813","104.19386","1.25535","71.52200","0.00000","1.26813","0.20002"
"1.26813","104.16192","1.25497","71.75200","0.00000","1.26813","0.20002"
"1.26813","104.11773","1.25444","71.98200","0.00000","1.26813","0.20002"
"1.26813","104.07954","1.25398","72.21200","0.00000","1.26813","0.20002"
"1.26813","104.03788","1.25347","72.44200","0.00000","1.26813","0.20002"
"1.26813","104.01012","1.25314","72.67200","0.00000","1.26813","0.20002"
"1.26813","103.96738","1.25262","72.90200","0.00000","1.26813","0.20002"
"1.26813","103.92725","1.25214","73.13200","0.00000","1.26813","0.20002"
"1.26813","103.89858","1.25180","73.36200","0.00000","1.26813","0.20002"
"1.26813","103.86456","1.25139","73.59200","0.00000","1.26813","0.20002"
"1.26813","103.83445","1.25102","73.82200","0.00000","1.26813","0.20002"
"1.26813","103.80060","1.25062","74.05200","0.00000","1.26813","0.20002"
"1.26813","103.76074","1.25014","74.28200","0.00000","1.26813","0.20002"
"1.26813","103.72060","1.24965","74.51200","0.00000","1.26813","0.20002"
"1.26813","103.69133","1.24930","74.74200","0.00000","1.26813","0.20002"
"1.26813","103.65864","1.24890","74.97200","0.00000","1.26813","0.20002"
"1.26813","103.61861","1.24842","75.20200","0.00000","1.26813","0.20002"
"1.26813","103.58637","1.24803","75.43200","0.00000","1.26813","0.20002"
"1.26813","103.55489","1.24765","75.66200","0.00000","1.26813","0.20002"
"1.26813","103.51729","1.24720","75.89200","0.00000","1.26813","0.20002"
"1.26813","103.49367","1.24692","76.12200","0.00000","1.26813","0.20002"
"1.26813","103.45911","1.24650","76.35200","0.00000","1.26813","0.20002"
"1.26813","103.42333","1.24607","76.58200","0.00000","1.26813","0.20002"
"1.26813","103.39243","1.24570","76.81200","0.00000","1.26813","0.20002"
"1.26813","103.36083","1.24532","77.04200","0.00000","1.26813","0.20002"
"1.26813","103.33156","1.24496","77.27200","0.00000","1.26813","0.20002"
"1.26813","103.28791","1.24444","77.50200","0.00000","1.26813","0.20002"
"1.26813","103.26054","1.24411","77.73200","0.00000","1.26813","0.20002"
"1.26813","103.22691","1.24370","77.96200","0.00000","1.26813","0.20002"
"1.26813","103.19221","1.24329","78.19200","0.00000","1.26813","0.20002"
"1.26813","103.16644","1.24297","78.42200","0.00000","1.26813","0.20002"
"1.26813","103.13107","1.24255","78.65200","0.00000","1.26813","0.20002"
"1.26813","103.10992","1.24229","78.88200","0.00000","1.26813","0.20002"
"1.26813","103.06672","1.24177","79.11200","0.00000","1.26813","0.20002"
"1.26813","103.03936","1.24144","79.34200","0.00000","1.26813","0.20002"
"1.26813","103.00993","1.24109","79.57200","0.00000","1.26813","0.20002"
"1.26813","102.98310","1.24077","79.80200","0.00000","1.26813","0.20002"
"1.26813","102.94453","1.24030","80.03200","0.00000","1.26813","0.20002"
"1.26813","102.91995","1.24001","80.26200","0.00000","1.26813","0.20002"
"1.26813","102.88992","1.23964","80.49200","0.00000","1.26813","0.20002"
"1.26813","102.85472","1.23922","80.72200","0.00000","1.26813","0.20002"
"1.26813","102.82487","1.23886","80.95200","0.00000","1.26813","0.20002"
"1.26813","102.79944","1.23855","81.18200","0.00000","1.26813","0.20002"
"1.26813","102.76870","1.23818","81.41200","0.00000","1.26813","0.20002"
"1.26813","102.73312","1.23775","81.64200","0.00000","1.26813","0.20002"
"1.26813","102.71097","1.23749","81.87200","0.00000","1.26813","0.20002"
"1.26813","102.68279","1.23715","82.10200","0.00000","1.26813","0.20002"
"1.26813","102.64474","1.23669","82.33200","0.00000","1.26813","0.20002"
"1.26813","102.61759","1.23636","82.56200","0.00000","1.26813","0.20002"
"1.26813","102.59545","1.23610","82.79200","0.00000","1.26813","0.20002"
"1.26813","102.56087","1.23568","83.02200","0.00000","1.26813","0.20002"
"1.26813","102.53658","1.23539","83.25200","0.00000","1.26813","0.20002"
"1.26813","102.50515","1.23501","83.48200","0.00000","1.26813","0.20002"
"1.26813","102.48258","1.23474","83.71200","0.00000","1.26813","0.20002"
"1.26813","102.44701","1.23431","83.94200","0.00000","1.26813","0.20002"
"1.26813","102.42834","1.23408","84.17200","0.00000","1.26813","0.20002"
"1.26813","102.39871","1.23373","84.40200","0.00000","1.26813","0.20002"
"1.26813","102.36170","1.23328","84.63200","0.00000","1.26813","0.20002"
"1.26813","102.34352","1.23306","84.86200","0.00000","1.26813","0.20002"
"1.26813","102.30658","1.23262","85.09200","0.00000","1.26813","0.20002"
"1.26813","102.29204","1.23244","85.32200","0.00000","1.26813","0.20002"
"1.26813","102.25692","1.23202","85.55200","0.00000","1.26813","0.20002"
"1.26813","102.23123","1.23171","85.78200","0.00000","1.26813","0.20002"
"1.26813","102.20334","1.23137","86.01200","0.00000","1.26813","0.20002"
"1.26813","102.18304","1.23113","86.24200","0.00000","1.26813","0.20002"
"1.26813","102.15611","1.23080","86.47200","0.00000","1.26813","0.20002"
"1.26813","102.12840","1.23047","86.70200","0.00000","1.26813","0.20002"
"1.26813","102.10570","1.23019","86.93200","0.00000","1.26813","0.20002"
"1.26813","102.07805","1.22986","87.16200","0.00000","1.26813","0.20002"
"1.26813","102.05066","1.22953","87.39200","0.00000","1.26813","0.20002"
"1.26813","102.02435","1.22921","87.62200","0.00000","1.26813","0.20002"
"1.26813","101.99593","1.22887","87.85200","0.00000","1.26813","0.20002"
"1.26813","101.97120","1.22857","88.08200","0.00000","1.26813","0.20002"
"1.26813","101.94210","1.22822","88.31200","0.00000","1.26813","0.20002"
"1.26813","101.92301","1.22799","88.54200","0.00000","1.26813","0.20002"
"1.26813","101.89057","1.22760","88.77200","0.00000","1.26813","0.20002"
"1.26813","101.87227","1.22738","89.00200","0.00000","1.26813","0.20002"
"1.26813","101.84516","1.22706","89.23200","0.00000","1.26813","0.20002"
"1.26813","101.81321","1.22667","89.46200","0.00000","1.26813","0.20002"
"1.26813","101.79875","1.22650","89.69200","0.00000","1.26813","0.20002"
"1.26813","101.76019","1.22603","89.92200","0.00000","1.26813","0.20002"
"1.26813","101.73411","1.22572","90.15200","0.00000","1.26813","0.20002"
"1.26813","101.71672","1.22551","90.38200","0.00000","1.26813","0.20002"
"1.26813","101.68801","1.22516","90.61200","0.00000","1.26813","0.20002"
"1.26813","101.67067","1.22495","90.84200","0.00000","1.26813","0.20002"
"1.26813","101.64259","1.22462","91.07200","0.00000","1.26813","0.20002"
"1.26813","101.62582","1.22441","91.30200","0.00000","1.26813","0.20002"
"1.26813","101.59782","1.22408","91.53200","0.00000","1.26813","0.20002"
"1.26813","101.56704","1.22370","91.76200","0.00000","1.26813","0.20002"
"1.26813","101.54376","1.22342","91.99200","0.00000","1.26813","0.20002"
"1.26813","101.52493","1.22320","92.22200","0.00000","1.26813","0.20002"
"1.26813","101.50800","1.22299","92.45200","0.00000","1.26813","0.20002"
"1.26813","101.47216","1.22256","92.68200","0.00000","1.26813","0.20002"
"1.26813","101.45459","1.22235","92.91200","0.00000","1.26813","0.20002"
"1.26813","101.42470","1.22199","93.14200","0.00000","1.26813","0.20002"
"1.26813","101.40596","1.22176","93.37200","0.00000","1.26813","0.20002"
"1.26813","101.37794","1.22143","93.60200","0.00000","1.26813","0.20002"
"1.26813","101.35381","1.22114","93.83200","0.00000","1.26813","0.20002"
"1.26813","101.33672","1.22093","94.06200","0.00000","1.26813","0.20002"
"1.26813","101.31379","1.22065","94.29200","0.00000","1.26813","0.20002"
"1.26813","101.29802","1.22046","94.52200","0.00000","1.26813","0.20002"
"1.26813","101.26897","1.22011","94.75200","0.00000","1.26813","0.20002"
"1.26813","101.23910","1.21975","94.98200","0.00000","1.26813","0.20002"
"1.26813","101.22060","1.21953","95.21200","0.00000","1.26813","0.20002"
"1.26813","101.20635","1.21936","95.44200","0.00000","1.26813","0.20002"
"1.26813","101.17114","1.21894","95.67200","0.00000","1.26813","0.20002"
"1.26813","101.15923","1.21879","95.90200","0.00000","1.26813","0.20002"
"1.26813","101.12687","1.21840","96.13200","0.00000","1.26813","0.20002"
"1.26813","101.10670","1.21816","96.36200","0.00000","1.26813","0.20002"
"1.26813","101.08970","1.21795","96.59200","0.00000","1.26813","0.20002"
"1.26813","101.07128","1.21773","96.82200","0.00000","1.26813","0.20002"
"1.26813","101.03716","1.21732","97.05200","0.00000","1.26813","0.20002"
"1.26813","101.02957","1.21723","97.28200","0.00000","1.26813","0.20002"
"1.26813","100.99387","1.21680","97.51200","0.00000","1.26813","0.20002"
"1.26813","100.97095","1.21652","97.74200","0.00000","1.26813","0.20002"
"1.26813","100.96048","1.21640","97.97200","0.00000","1.26813","0.20002"
"1.26813","100.93761","1.21612","98.20200","0.00000","1.26813","0.20002"
"1.26813","100.90966","1.21578","98.43200","0.00000","1.26813","0.20002"
"1.26813","100.89356","1.21559","98.66200","0.00000","1.26813","0.20002"
"1.26813","100.86700","1.21527","98.89200","0.00000","1.26813","0.20002"
"1.26813","100.85008","1.21507","99.12200","0.00000","1.26813","0.20002"
"1.26813","100.82314","1.21474","99.35200","0.00000","1.26813","0.20002"
"1.26813","100.80275","1.21450","99.58200","0.00000","1.26813","0.20002"
"1.26813","100.78571","1.21429","99.81200","0.00000","1.26813","0.20002"
"1.26813","100.76305","1.21402","100.04200","0.00000","1.26813","0.20002"
"1.26813","100.74159","1.21376","100.27200","0.00000","1.26813","0.20002"
"1.26813","100.72533","1.21356","100.50200","0.00000","1.26813","0.20002"
"1.26813","100.69285","1.21317","100.73200","0.00000","1.26813","0.20002"
"1.26813","100.67500","1.21296","100.96200","0.00000","1.26813","0.20002"
"1.26813","100.66133","1.21279","101.19200","0.00000","1.26813","0.20002"
"1.26813","100.63850","1.21252","101.42200","0.00000","1.26813","0.20002"
"1.26813","100.61964","1.21229","101.65200","0.00000","1.26813","0.20002"
"1.26813","100.59666","1.21201","101.88200","0.00000","1.26813","0.20002"
"1.26813","100.57464","1.21175","102.11200","0.00000","1.26813","0.20002"
"1.26813","100.55791","1.21155","102.34200","0.00000","1.26813","0.20002"
"1.26813","100.53239","1.21124","102.57200","0.00000","1.26813","0.20002"
"1.26813","100.51615","1.21104","102.80200","0.00000","1.26813","0.20002"
"1.26813","100.49347","1.21077","103.03200","0.00000","1.26813","0.20002"
"1.26813","100.47068","1.21050","103.26200","0.00000","1.26813","0.20002"
"1.26813","100.45266","1.21028","103.49200","0.00000","1.26813","0.20002"
"1.26813","100.43856","1.21011","103.72200","0.00000","1.26813","0.20002"
"1.26813","100.41811","1.20986","103.95200","0.00000","1.26813","0.20002"
"1.26813","100.38969","1.20952","104.18200","0.00000","1.26813","0.20002"
"1.26813","100.37576","1.20935","104.41200","0.00000","1.26813","0.20002"
"1.26813","100.35130","1.20906","104.64200","0.00000","1.26813","0.20002"
"1.26813","100.34305","1.20896","104.87200","0.00000","1.26813","0.20002"
"1.26813","100.31325","1.20860","105.10200","0.00000","1.26813","0.20002"
"1.26813","100.29919","1.20843","105.33200","0.00000","1.26813","0.20002"
"1.26813","100.27081","1.20809","105.56200","0.00000","1.26813","0.20002"
"1.26813","100.26199","1.20798","105.79200","0.00000","1.26813","0.20002"
"1.26813","100.23813","1.20769","106.02200","0.00000","1.26813","0.20002"
"1.26813","100.21353","1.20740","106.25200","0.00000","1.26813","0.20002"
"1.26813","100.19640","1.20719","106.48200","0.00000","1.26813","0.20002"
"1.26813","100.17803","1.20697","106.71200","0.00000","1.26813","0.20002"
"1.26813","100.16347","1.20679","106.94200","0.00000","1.26813","0.20002"
"1.26813","100.13803","1.20649","107.17200","0.00000","1.26813","0.20002"
"1.26813","100.12427","1.20632","107.40200","0.00000","1.26813","0.20002"
"1.26813","100.10465","1.20609","107.63200","0.00000","1.26813","0.20002"
"1.26813","100.08982","1.20591","107.86200","0.00000","1.26813","0.20002"
"1.26813","100.07613","1.20574","108.09200","0.00000","1.26813","0.20002"
"1.26813","100.05553","1.20549","108.32200","0.00000","1.26813","0.20002"
"1.26813","100.03170","1.20521","108.55200","0.00000","1.26813","0.20002"
"1.26813","100.01418","1.20500","108.78200","0.00000","1.26813","0.20002"
"1.26813","99.99656","1.20478","109.01200","0.00000","1.26813","0.20002"
"1.26813","99.98260","1.20462","109.24200","0.00000","1.26813","0.20002"
"1.26813","99.96215","1.20437","109.47200","0.00000","1.26813","0.20002"
"1.26813","99.93975","1.20410","109.70200","0.00000","1.26813","0.20002"
"1.26813","99.92123","1.20388","109.93200","0.00000","1.26813","0.20002"
"1.26813","99.90688","1.20370","110.16200","0.00000","1.26813","0.20002"
"1.26813","99.88519","1.20344","110.39200","0.00000","1.26813","0.20002"
"1.26813","99.87670","1.20334","110.62200","0.00000","1.26813","0.20002"
"1.26813","99.85664","1.20310","110.85200","0.00000","1.26813","0.20002"
"1.26813","99.84498","1.20296","111.08200","0.00000","1.26813","0.20002"
"1.26813","99.82220","1.20268","111.31200","0.00000","1.26813","0.20002"
"1.26813","99.80064","1.20242","111.54200","0.00000","1.26813","0.20002"
"1.26813","99.79160","1.20231","111.77200","0.00000","1.26813","0.20002"
"1.26813","99.76919","1.20204","112.00200","0.00000","1.26813","0.20002"
"1.26813","99.75549","1.20188","112.23200","0.00000","1.26813","0.20002"
"1.26813","99.73546","1.20164","112.46200","0.00000","1.26813","0.20002"
"1.26813","99.71478","1.20139","112.69200","0.00000","1.26813","0.20002"
"1.26813","99.70543","1.20128","112.92200","0.00000","1.26813","0.20002"
"1.26813","99.66646","1.20081","113.15200","0.00000","1.26813","0.20002"
"1.26813","99.65456","1.20066","113.38200","0.00000","1.26813","0.20002"
"1.26813","99.64262","1.20052","113.61200","0.00000","1.26813","0.20002"
"1.26813","99.62740","1.20034","113.84200","0.00000","1.26813","0.20002"
"1.26813","99.60303","1.20004","114.07200","0.00000","1.26813","0.20002"
"1.26813","99.59363","1.19993","114.30200","0.00000","1.26813","0.20002"
"1.26813","99.56407","1.19957","114.53200","0.00000","1.26813","0.20002"
"1.26813","99.56345","1.19957","114.76200","0.00000","1.26813","0.20002"
"1.26813","99.53593","1.19923","114.99200","0.00000","1.26813","0.20002"
"1.26813","99.52019","1.19904","115.22200","0.00000","1.26813","0.20002"
"1.26813","99.51018","1.19892","115.45200","0.00000","1.26813","0.20002"
"1.26813","99.49010","1.19868","115.68200","0.00000","1.26813","0.20002"
"1.26813","99.47670","1.19852","115.91200","0.00000","1.26813","0.20002"
"1.26813","99.45228","1.19823","116.14200","0.00000","1.26813","0.20002"
"1.26813","99.44344","1.19812","116.37200","0.00000","1.26813","0.20002"
"1.26813","99.42411","1.19789","116.60200","0.00000","1.26813","0.20002"
"1.26813","99.40771","1.19769","116.83200","0.00000","1.26813","0.20002"
"1.26813","99.39183","1.19750","117.06200","0.00000","1.26813","0.20002"
"1.26813","99.36834","1.19721","117.29200","0.00000","1.26813","0.20002"
"1.26813","99.35432","1.19705","117.52200","0.00000","1.26813","0.20002"
"1.26813","99.33643","1.19683","117.75200","0.00000","1.26813","0.20002"
"1.26813","99.32647","1.19671","117.98200","0.00000","1.26813","0.20002"
"1.26813","99.31010","1.19651","118.21200","0.00000","1.26813","0.20002"
"1.26813","99.29010","1.19627","118.44200","0.00000","1.26813","0.20002"
"1.26813","99.27473","1.19609","118.67200","0.00000","1.26813","0.20002"
"1.26813","99.26456","1.19596","118.90200","0.00000","1.26813","0.20002"
"1.26813","99.24551","1.19573","119.13200","0.00000","1.26813","0.20002"
"1.26813","99.22581","1.19550","119.36200","0.00000","1.26813","0.20002"
"1.26813","99.21110","1.19532","119.59200","0.00000","1.26813","0.20002"
"1.26813","99.20160","1.19521","119.82200","0.00000","1.26813","0.20002"
"1.26813","99.17800","1.19492","120.05200","0.00000","1.26813","0.20002"
"1.26813","99.16196","1.19473","120.28200","0.00000","1.26813","0.20002"
"1.26813","99.15404","1.19463","120.51200","0.00000","1.26813","0.20002"
"1.26813","99.13497","1.19440","120.74200","0.00000","1.26813","0.20002"
"1.26813","99.12291","1.19426","120.97200","0.00000","1.26813","0.20002"
"1.26813","99.10000","1.19398","121.20200","0.00000","1.26813","0.20002"
"1.26813","99.08998","1.19386","121.43200","0.00000","1.26813","0.20002"
"1.26813","99.07117","1.19363","121.66200","0.00000","1.26813","0.20002"
"1.26813","99.06104","1.19351","121.89200","0.00000","1.26813","0.20002"
"1.26813","99.03800","1.19323","122.12200","0.00000","1.26813","0.20002"
"1.26813","99.02777","1.19311","122.35200","0.00000","1.26813","0.20002"
"1.26813","99.00978","1.19289","122.58200","0.00000","1.26813","0.20002"
"1.26813","98.99587","1.19273","122.81200","0.00000","1.26813","0.20002"
"1.26813","98.97410","1.19246","123.04200","0.00000","1.26813","0.20002"
"1.26813","98.96928","1.19241","123.27200","0.00000","1.26813","0.20002"
"1.26813","98.94902","1.19216","123.50200","0.00000","1.26813","0.20002"
"1.26813","98.93916","1.19204","123.73200","0.00000","1.26813","0.20002"
"1.26813","98.91817","1.19179","123.96200","0.00000","1.26813","0.20002"
"1.26813","98.90674","1.19165","124.19200","0.00000","1.26813","0.20002"
"1.26813","98.88833","1.19143","124.42200","0.00000","1.26813","0.20002"
"1.26813","98.87827","1.19131","124.65200","0.00000","1.26813","0.20002"
"1.26813","98.86401","1.19114","124.88200","0.00000","1.26813","0.20002"
"1.26813","98.84485","1.19091","125.11200","0.00000","1.26813","0.20002"
"1.26813","98.84037","1.19085","125.34200","0.00000","1.26813","0.20002"
"1.26813","98.81239","1.19052","125.57200","0.00000","1.26813","0.20002"
"1.26813","98.80014","1.19037","125.80200","0.00000","1.26813","0.20002"
"1.26813","98.79031","1.19025","126.03200","0.00000","1.26813","0.20002"
"1.26813","98.76838","1.18999","126.26200","0.00000","1.26813","0.20002"
"1.26813","98.76178","1.18991","126.49200","0.00000","1.26813","0.20002"
"1.26813","98.74570","1.18971","126.72200","0.00000","1.26813","0.20002"
"1.26813","98.73376","1.18957","126.95200","0.00000","1.26813","0.20002"
"1.26813","98.70659","1.18924","127.18200","0.00000","1.26813","0.20002"
"1.26813","98.69572","1.18911","127.41200","0.00000","1.26813","0.20002"
"1.26813","98.69086","1.18905","127.64200","0.00000","1.26813","0.20002"
"1.26813","98.66826","1.18878","127.87200","0.00000","1.26813","0.20002"
"1.26813","98.66521","1.18874","128.10200","0.00000","1.26813","0.20002"
"1.26813","98.64352","1.18848","128.33200","0.00000","1.26813","0.20002"
"1.26813","98.62933","1.18831","128.56200","0.00000","1.26813","0.20002"
"1.26813","98.61791","1.18817","128.79200","0.00000","1.26813","0.20002"
"1.26813","98.59985","1.18796","129.02200","0.00000","1.26813","0.20002"
"1.26813","98.58235","1.18774","129.25200","0.00000","1.26813","0.20002"
"1.26813","98.56527","1.18754","129.48200","0.00000","1.26813","0.20002"
"1.26813","98.56293","1.18751","129.71200","0.00000","1.26813","0.20002"
"1.26813","98.54213","1.18726","129.94200","0.00000","1.26813","0.20002"
"1.26813","98.52944","1.18711","130.17200","0.00000","1.26813","0.20002"
"1.26813","98.50508","1.18681","130.40200","0.00000","1.26813","0.20002"
"1.26813","98.50327","1.18679","130.63200","0.00000","1.26813","0.20002"
"1.26813","98.47977","1.18651","130.86200","0.00000","1.26813","0.20002"
"1.26813","98.47059","1.18640","131.09200","0.00000","1.26813","0.20002"
"1.26813","98.46055","1.18628","131.32200","0.00000","1.26813","0.20002"
"1.26813","98.44599","1.18610","131.55200","0.00000","1.26813","0.20002"
"1.26813","98.42682","1.18587","131.78200","0.00000","1.26813","0.20002"
"1.26813","98.40973","1.18566","132.01200","0.00000","1.26813","0.20002"
"1.26813","98.40079","1.18556","132.24200","0.00000","1.26813","0.20002"
"1.26813","98.38258","1.18534","132.47200","0.00000","1.26813","0.20002"
"1.26813","98.37413","1.18524","132.70200","0.00000","1.26813","0.20002"
"1.26813","98.35323","1.18498","132.93200","0.00000","1.26813","0.20002"
"1.26813","98.34813","1.18492","133.16200","0.00000","1.26813","0.20002"
"1.26813","98.32725","1.18467","133.39200","0.00000","1.26813","0.20002"
"1.26813","98.31551","1.18453","133.62200","0.00000","1.26813","0.20002"
"1.26813","98.29929","1.18433","133.85200","0.00000","1.26813","0.20002"
"1.26813","98.30025","1.18435","134.08200","0.00000","1.26813","0.20002"
"1.26813","98.27174","1.18400","134.31200","0.00000","1.26813","0.20002"
"1.26813","98.26814","1.18396","134.54200","0.00000","1.26813","0.20002"
"1.26813","98.24215","1.18365","134.77200","0.00000","1.26813","0.20002"
"1.26813","98.22923","1.18349","135.00200","0.00000","1.26813","0.20002"
"1.26813","98.22313","1.18342","135.23200","0.00000","1.26813","0.20002"
"1.26813","98.21243","1.18329","135.46200","0.00000","1.26813","0.20002"
"1.26813","98.20092","1.18315","135.69200","0.00000","1.26813","0.20002"
"1.26813","98.18678","1.18298","135.92200","0.00000","1.26813","0.20002"
"1.26813","98.17020","1.18278","136.15200","0.00000","1.26813","0.20002"
"1.26813","98.15755","1.18263","136.38200","0.00000","1.26813","0.20002"
"1.26813","98.14217","1.18244","136.61200","0.00000","1.26813","0.20002"
"1.26813","98.13153","1.18231","136.84200","0.00000","1.26813","0.20002"
"1.26813","98.12213","1.18220","137.07200","0.00000","1.26813","0.20002"
"1.26813","98.10252","1.18196","137.30200","0.00000","1.26813","0.20002"
"1.26813","98.09560","1.18188","137.53200","0.00000","1.26813","0.20002"
"1.26813","98.08523","1.18176","137.76200","0.00000","1.26813","0.20002"
"1.26813","98.06449","1.18151","137.99200","0.00000","1.26813","0.20002"
"1.26813","98.05890","1.18144","138.22200","0.00000","1.26813","0.20002"
"1.26813","98.04284","1.18124","138.45200","0.00000","1.26813","0.20002"
"1.26813","98.01811","1.18095","138.68200","0.00000","1.26813","0.20002"
"1.26813","98.01910","1.18096","138.91200","0.00000","1.26813","0.20002"
"1.26813","98.00076","1.18074","139.14200","0.00000","1.26813","0.20002"
"1.26813","97.98499","1.18055","139.37200","0.00000","1.26813","0.20002"
"1.26813","97.98402","1.18054","139.60200","0.00000","1.26813","0.20002"
"1.26813","97.95883","1.18023","139.83200","0.00000","1.26813","0.20002"
"1.26813","97.94215","1.18003","140.06200","0.00000","1.26813","0.20002"
"1.26813","97.93884","1.17999","140.29200","0.00000","1.26813","0.20002"
"1.26813","97.92129","1.17978","140.52200","0.00000","1.26813","0.20002"
"1.26813","97.91045","1.17965","140.75200","0.00000","1.26813","0.20002"
"1.26813","97.90328","1.17956","140.98200","0.00000","1.26813","0.20002"
"1.26813","97.88654","1.17936","141.21200","0.00000","1.26813","0.20002"
"1.26813","97.88055","1.17929","141.44200","0.00000","1.26813","0.20002"
"1.26813","97.87045","1.17917","141.67200","0.00000","1.26813","0.20002"
"1.26813","97.84895","1.17891","141.90200","0.00000","1.26813","0.20002"
"1.26813","97.83234","1.17871","142.13200","0.00000","1.26813","0.20002"
"1.26813","97.83048","1.17869","142.36200","0.00000","1.26813","0.20002"
"1.26813","97.81368","1.17848","142.59200","0.00000","1.26813","0.20002"
"1.26813","97.79800","1.17829","142.82200","0.00000","1.26813","0.20002"
"1.26813","97.78109","1.17809","143.05200","0.00000","1.26813","0.20002"
"1.26813","97.76967","1.17795","143.28200","0.00000","1.26813","0.20002"
"1.26813","97.76492","1.17790","143.51200","0.00000","1.26813","0.20002"
"1.26813","97.75275","1.17775","143.74200","0.00000","1.26813","0.20002"
"1.26813","97.73994","1.17760","143.97200","0.00000","1.26813","0.20002"
"1.26813","97.71729","1.17732","144.20200","0.00000","1.26813","0.20002"
"1.26813","97.71925","1.17735","144.43200","0.00000","1.26813","0.20002"
"1.26813","97.70097","1.17713","144.66200","0.00000","1.26813","0.20002"
"1.26813","97.68996","1.17699","144.89200","0.00000","1.26813","0.20002"
"1.26813","97.67426","1.17680","145.12200","0.00000","1.26813","0.20002"
"1.26813","97.65958","1.17663","145.35200","0.00000","1.26813","0.20002"
"1.26813","97.65322","1.17655","145.58200","0.00000","1.26813","0.20002"
"1.26813","97.64051","1.17640","145.81200","0.00000","1.26813","0.20002"
"1.26813","97.62676","1.17623","146.04200","0.00000","1.26813","0.20002"
"1.26813","97.61401","1.17608","146.27200","0.00000","1.26813","0.20002"
"1.26813","97.60076","1.17592","146.50200","0.00000","1.26813","0.20002"
"1.26813","97.58785","1.17576","146.73200","0.00000","1.26813","0.20002"
"1.26813","97.58447","1.17572","146.96200","0.00000","1.26813","0.20002"
"1.26813","97.55788","1.17540","147.19200","0.00000","1.26813","0.20002"
"1.26813","97.55844","1.17541","147.42200","0.00000","1.26813","0.20002"
"1.26813","97.54433","1.17524","147.65200","0.00000","1.26813","0.20002"
"1.26813","97.53899","1.17517","147.88200","0.00000","1.26813","0.20002"
"1.26813","97.51738","1.17491","148.11200","0.00000","1.26813","0.20002"
"1.26813","97.50827","1.17480","148.34200","0.00000","1.26813","0.20002"
"1.26813","97.49751","1.17467","148.57200","0.00000","1.26813","0.20002"
"1.26813","97.49210","1.17461","148.80200","0.00000","1.26813","0.20002"
"1.26813","97.46397","1.17427","149.03200","0.00000","1.26813","0.20002"
"1.26813","97.46502","1.17428","149.26200","0.00000","1.26813","0.20002"
"1.26813","97.43255","1.17389","149.49200","0.00000","1.26813","0.20002"
"1.26813","97.44933","1.17409","149.72200","0.00000","1.26813","0.20002"
"1.26813","97.42176","1.17376","149.95200","0.00000","1.26813","0.20002"
"1.26813","97.40984","1.17362","150.18200","0.00000","1.26813","0.20002"
"1.26813","97.40057","1.17351","150.41200","0.00000","1.26813","0.20002"
"1.26813","97.39407","1.17343","150.64200","0.00000","1.26813","0.20002"
"1.26813","97.37444","1.17319","150.87200","0.00000","1.26813","0.20002"
"1.26813","97.37185","1.17316","151.10200","0.00000","1.26813","0.20002"
"1.26813","97.35804","1.17299","151.33200","0.00000","1.26813","0.20002"
"1.26813","97.34479","1.17283","151.56200","0.00000","1.26813","0.20002"
"1.26813","97.34023","1.17278","151.70200","0.00000","1.26813","0.20002"