File: Rubber Stress Relaxation Raw Data -Large  Samples-20210211/Specimen_RawData_6.csv
Specimen properties : Specimen label,"7"
Specimen properties : Anvil height,"6.34000",mm
Specimen properties : Diameter,"10.25000",mm
Test : Rate 1,"24.00000",mm/min
Test : Start of hold value,"20.00000",%
Test : Duration,"120.00000",s

Extension,Load,Compressive stress,Time,PIP count,Compressive extension,Compressive strain (Extension)
(mm),(N),(MPa),(s),,(mm),(mm/mm)
"-0.00042","-0.00786","-0.00010","0.00000","0.00000","-0.00042","-0.00007"
"0.06333","5.67377","0.06876","0.18000","0.00000","0.06333","0.00999"
"0.14104","18.21444","0.22074","0.36000","0.00000","0.14104","0.02225"
"0.21479","29.31096","0.35522","0.54000","0.00000","0.21479","0.03388"
"0.28792","38.26665","0.46375","0.72000","0.00000","0.28792","0.04541"
"0.36083","46.64426","0.56528","0.90000","0.00000","0.36083","0.05691"
"0.43208","54.67405","0.66259","1.08000","0.00000","0.43208","0.06815"
"0.50438","62.94565","0.76283","1.26000","0.00000","0.50438","0.07955"
"0.57646","71.05151","0.86106","1.44000","0.00000","0.57646","0.09092"
"0.64833","79.34769","0.96161","1.62000","0.00000","0.64833","0.10226"
"0.72042","87.88064","1.06501","1.80000","0.00000","0.72042","0.11363"
"0.79250","96.50674","1.16955","1.98000","0.00000","0.79250","0.12500"
"0.86438","105.25734","1.27560","2.16000","0.00000","0.86438","0.13634"
"0.93625","114.37699","1.38612","2.34000","0.00000","0.93625","0.14767"
"1.00833","123.78484","1.50013","2.52000","0.00000","1.00833","0.15904"
"1.08021","133.49046","1.61775","2.70000","0.00000","1.08021","0.17038"
"1.15250","143.43700","1.73830","2.88000","0.00000","1.15250","0.18178"
"1.22417","153.79355","1.86381","3.06000","0.00000","1.22417","0.19309"
"1.27792","161.25772","1.95426","3.22400","0.00000","1.27792","0.20156"
"1.27813","148.00539","1.79366","3.40400","0.00000","1.27813","0.20160"
"1.27688","142.31139","1.72465","3.58400","0.00000","1.27688","0.20140"
"1.27479","138.09651","1.67357","3.76400","0.00000","1.27479","0.20107"
"1.27250","134.70154","1.63243","3.94400","0.00000","1.27250","0.20071"
"1.27083","132.20781","1.60221","4.12400","0.00000","1.27083","0.20045"
"1.27000","130.39943","1.58029","4.30400","0.00000","1.27000","0.20032"
"1.26958","128.99300","1.56325","4.48400","0.00000","1.26958","0.20025"
"1.26938","127.87323","1.54968","4.66400","0.00000","1.26938","0.20022"
"1.26938","126.90941","1.53800","4.84400","0.00000","1.26938","0.20022"
"1.26917","125.99310","1.52690","5.02400","0.00000","1.26917","0.20018"
"1.26917","125.19436","1.51722","5.20400","0.00000","1.26917","0.20018"
"1.26917","124.45106","1.50821","5.38400","0.00000","1.26917","0.20018"
"1.26917","123.81499","1.50050","5.56400","0.00000","1.26917","0.20018"
"1.26917","123.16029","1.49256","5.74400","0.00000","1.26917","0.20018"
"1.26917","122.59859","1.48576","5.92400","0.00000","1.26917","0.20018"
"1.26917","122.04028","1.47899","6.10400","0.00000","1.26917","0.20018"
"1.26917","121.49040","1.47233","6.28400","0.00000","1.26917","0.20018"
"1.26917","121.00260","1.46642","6.46400","0.00000","1.26917","0.20018"
"1.26917","120.53120","1.46070","6.64400","0.00000","1.26917","0.20018"
"1.26896","120.03962","1.45475","6.82400","0.00000","1.26896","0.20015"
"1.26896","119.62675","1.44974","7.00400","0.00000","1.26896","0.20015"
"1.26896","119.23174","1.44495","7.18400","0.00000","1.26896","0.20015"
"1.26896","118.88495","1.44075","7.36400","0.00000","1.26896","0.20015"
"1.26896","118.52046","1.43633","7.54400","0.00000","1.26896","0.20015"
"1.26896","118.18908","1.43232","7.72400","0.00000","1.26896","0.20015"
"1.26896","117.85455","1.42826","7.90400","0.00000","1.26896","0.20015"
"1.26896","117.53678","1.42441","8.08400","0.00000","1.26896","0.20015"
"1.26896","117.27947","1.42130","8.26400","0.00000","1.26896","0.20015"
"1.26896","116.96322","1.41746","8.44400","0.00000","1.26896","0.20015"
"1.26896","116.65163","1.41369","8.62400","0.00000","1.26896","0.20015"
"1.26896","116.36662","1.41023","8.80400","0.00000","1.26896","0.20015"
"1.26896","116.09351","1.40692","8.98400","0.00000","1.26896","0.20015"
"1.26896","115.83481","1.40379","9.16400","0.00000","1.26896","0.20015"
"1.26896","115.59060","1.40083","9.34400","0.00000","1.26896","0.20015"
"1.26896","115.35696","1.39800","9.52400","0.00000","1.26896","0.20015"
"1.26896","115.12012","1.39513","9.70400","0.00000","1.26896","0.20015"
"1.26896","114.90855","1.39256","9.88400","0.00000","1.26896","0.20015"
"1.26938","114.85110","1.39187","10.06400","0.00000","1.26938","0.20022"
"1.26938","114.61256","1.38898","10.24400","0.00000","1.26938","0.20022"
"1.26938","114.39156","1.38630","10.42400","0.00000","1.26938","0.20022"
"1.26938","114.17860","1.38372","10.60400","0.00000","1.26938","0.20022"
"1.26938","113.97638","1.38127","10.78400","0.00000","1.26938","0.20022"
"1.26938","113.78009","1.37889","10.96400","0.00000","1.26938","0.20022"
"1.26938","113.58910","1.37657","11.14400","0.00000","1.26938","0.20022"
"1.26938","113.40030","1.37428","11.32400","0.00000","1.26938","0.20022"
"1.26938","113.21764","1.37207","11.50400","0.00000","1.26938","0.20022"
"1.26938","113.04298","1.36995","11.68400","0.00000","1.26938","0.20022"
"1.26938","112.87712","1.36794","11.86400","0.00000","1.26938","0.20022"
"1.26938","112.69422","1.36573","12.04400","0.00000","1.26938","0.20022"
"1.26938","112.52827","1.36372","12.22400","0.00000","1.26938","0.20022"
"1.26938","112.37288","1.36183","12.40400","0.00000","1.26938","0.20022"
"1.26938","112.21568","1.35993","12.58400","0.00000","1.26938","0.20022"
"1.26938","112.05054","1.35793","12.76400","0.00000","1.26938","0.20022"
"1.26938","111.90969","1.35622","12.94400","0.00000","1.26938","0.20022"
"1.26938","111.75590","1.35436","13.12400","0.00000","1.26938","0.20022"
"1.26938","111.61676","1.35267","13.30400","0.00000","1.26938","0.20022"
"1.26938","111.47514","1.35095","13.48400","0.00000","1.26938","0.20022"
"1.26938","111.33379","1.34924","13.66400","0.00000","1.26938","0.20022"
"1.26938","111.19880","1.34760","13.84400","0.00000","1.26938","0.20022"
"1.26938","111.06743","1.34601","14.02400","0.00000","1.26938","0.20022"
"1.26938","110.93100","1.34436","14.20400","0.00000","1.26938","0.20022"
"1.26938","110.80630","1.34285","14.38400","0.00000","1.26938","0.20022"
"1.26938","110.68353","1.34136","14.56400","0.00000","1.26938","0.20022"
"1.26938","110.56794","1.33996","14.74400","0.00000","1.26938","0.20022"
"1.26938","110.43870","1.33839","14.92400","0.00000","1.26938","0.20022"
"1.26938","110.31860","1.33694","15.10400","0.00000","1.26938","0.20022"
"1.26938","110.21432","1.33567","15.28400","0.00000","1.26938","0.20022"
"1.26938","110.08416","1.33410","15.46400","0.00000","1.26938","0.20022"
"1.26938","109.96590","1.33266","15.64400","0.00000","1.26938","0.20022"
"1.26938","109.85023","1.33126","15.82400","0.00000","1.26938","0.20022"
"1.26938","109.74598","1.33000","16.00400","0.00000","1.26938","0.20022"
"1.26938","109.64176","1.32874","16.18400","0.00000","1.26938","0.20022"
"1.26938","109.54523","1.32757","16.36400","0.00000","1.26938","0.20022"
"1.26938","109.42888","1.32616","16.54400","0.00000","1.26938","0.20022"
"1.26938","109.32449","1.32489","16.72400","0.00000","1.26938","0.20022"
"1.26938","109.23553","1.32381","16.90400","0.00000","1.26938","0.20022"
"1.26938","109.12724","1.32250","17.08400","0.00000","1.26938","0.20022"
"1.26938","109.02684","1.32128","17.26400","0.00000","1.26938","0.20022"
"1.26938","108.92749","1.32008","17.44400","0.00000","1.26938","0.20022"
"1.26938","108.83290","1.31893","17.62400","0.00000","1.26938","0.20022"
"1.26938","108.73997","1.31781","17.80400","0.00000","1.26938","0.20022"
"1.26938","108.64217","1.31662","17.98400","0.00000","1.26938","0.20022"
"1.26938","108.55372","1.31555","18.16400","0.00000","1.26938","0.20022"
"1.26938","108.46736","1.31450","18.34400","0.00000","1.26938","0.20022"
"1.26938","108.37602","1.31340","18.52400","0.00000","1.26938","0.20022"
"1.26938","108.29005","1.31235","18.70400","0.00000","1.26938","0.20022"
"1.26938","108.20380","1.31131","18.88400","0.00000","1.26938","0.20022"
"1.26938","108.12237","1.31032","19.06400","0.00000","1.26938","0.20022"
"1.26938","108.03915","1.30931","19.24400","0.00000","1.26938","0.20022"
"1.26938","107.92452","1.30792","19.42400","0.00000","1.26938","0.20022"
"1.26938","107.85566","1.30709","19.60400","0.00000","1.26938","0.20022"
"1.26938","107.77795","1.30615","19.78400","0.00000","1.26938","0.20022"
"1.26938","107.69911","1.30519","19.96400","0.00000","1.26938","0.20022"
"1.26938","107.61837","1.30421","20.14400","0.00000","1.26938","0.20022"
"1.26938","107.53230","1.30317","20.32400","0.00000","1.26938","0.20022"
"1.26938","107.45993","1.30229","20.50400","0.00000","1.26938","0.20022"
"1.26938","107.37357","1.30125","20.68400","0.00000","1.26938","0.20022"
"1.26938","107.29573","1.30030","20.86400","0.00000","1.26938","0.20022"
"1.26938","107.22533","1.29945","21.04400","0.00000","1.26938","0.20022"
"1.26938","107.15613","1.29861","21.22400","0.00000","1.26938","0.20022"
"1.26938","107.08710","1.29778","21.40400","0.00000","1.26938","0.20022"
"1.26938","107.01572","1.29691","21.58400","0.00000","1.26938","0.20022"
"1.26938","106.91438","1.29568","21.76400","0.00000","1.26938","0.20022"
"1.26938","106.85954","1.29502","21.94400","0.00000","1.26938","0.20022"
"1.26938","106.78489","1.29411","22.12400","0.00000","1.26938","0.20022"
"1.26938","106.72105","1.29334","22.30400","0.00000","1.26938","0.20022"
"1.26938","106.65015","1.29248","22.48400","0.00000","1.26938","0.20022"
"1.26938","106.59326","1.29179","22.66400","0.00000","1.26938","0.20022"
"1.26938","106.52380","1.29095","22.84400","0.00000","1.26938","0.20022"
"1.26938","106.47076","1.29031","23.02400","0.00000","1.26938","0.20022"
"1.26938","106.40881","1.28956","23.20400","0.00000","1.26938","0.20022"
"1.26938","106.32933","1.28859","23.38400","0.00000","1.26938","0.20022"
"1.26938","106.26465","1.28781","23.56400","0.00000","1.26938","0.20022"
"1.26938","106.19659","1.28698","23.74400","0.00000","1.26938","0.20022"
"1.26938","106.13162","1.28620","23.92400","0.00000","1.26938","0.20022"
"1.26938","106.07419","1.28550","24.10400","0.00000","1.26938","0.20022"
"1.26938","106.01197","1.28475","24.28400","0.00000","1.26938","0.20022"
"1.26938","105.94393","1.28392","24.46400","0.00000","1.26938","0.20022"
"1.26938","105.88545","1.28321","24.64400","0.00000","1.26938","0.20022"
"1.26938","105.83075","1.28255","24.82400","0.00000","1.26938","0.20022"
"1.26938","105.77333","1.28185","25.00400","0.00000","1.26938","0.20022"
"1.26938","105.71313","1.28112","25.18400","0.00000","1.26938","0.20022"
"1.26938","105.64949","1.28035","25.36400","0.00000","1.26938","0.20022"
"1.26938","105.60522","1.27982","25.54400","0.00000","1.26938","0.20022"
"1.26938","105.52985","1.27890","25.72400","0.00000","1.26938","0.20022"
"1.26938","105.47900","1.27829","25.90400","0.00000","1.26938","0.20022"
"1.26938","105.41030","1.27745","26.08400","0.00000","1.26938","0.20022"
"1.26938","105.35296","1.27676","26.26400","0.00000","1.26938","0.20022"
"1.26938","105.31094","1.27625","26.44400","0.00000","1.26938","0.20022"
"1.26938","105.25086","1.27552","26.62400","0.00000","1.26938","0.20022"
"1.26938","105.20631","1.27498","26.80400","0.00000","1.26938","0.20022"
"1.26938","105.15430","1.27435","26.98400","0.00000","1.26938","0.20022"
"1.26938","105.09039","1.27358","27.16400","0.00000","1.26938","0.20022"
"1.26938","105.03665","1.27293","27.34400","0.00000","1.26938","0.20022"
"1.26938","104.97794","1.27221","27.52400","0.00000","1.26938","0.20022"
"1.26938","104.93007","1.27163","27.70400","0.00000","1.26938","0.20022"
"1.26938","104.87955","1.27102","27.88400","0.00000","1.26938","0.20022"
"1.26938","104.82529","1.27036","28.06400","0.00000","1.26938","0.20022"
"1.26938","104.77787","1.26979","28.24400","0.00000","1.26938","0.20022"
"1.26938","104.72785","1.26918","28.42400","0.00000","1.26938","0.20022"
"1.26938","104.67437","1.26854","28.60400","0.00000","1.26938","0.20022"
"1.26938","104.62851","1.26798","28.78400","0.00000","1.26938","0.20022"
"1.26938","104.57679","1.26735","28.96400","0.00000","1.26938","0.20022"
"1.26938","104.53288","1.26682","29.14400","0.00000","1.26938","0.20022"
"1.26938","104.48477","1.26624","29.32400","0.00000","1.26938","0.20022"
"1.26938","104.43154","1.26559","29.50400","0.00000","1.26938","0.20022"
"1.26938","104.38271","1.26500","29.68400","0.00000","1.26938","0.20022"
"1.26938","104.33463","1.26442","29.86400","0.00000","1.26938","0.20022"
"1.26938","104.28690","1.26384","30.04400","0.00000","1.26938","0.20022"
"1.26938","104.24880","1.26338","30.22400","0.00000","1.26938","0.20022"
"1.26938","104.20517","1.26285","30.40400","0.00000","1.26938","0.20022"
"1.26938","104.13487","1.26200","30.58400","0.00000","1.26938","0.20022"
"1.26938","104.09924","1.26157","30.76400","0.00000","1.26938","0.20022"
"1.26938","104.06564","1.26116","30.94400","0.00000","1.26938","0.20022"
"1.26938","104.00818","1.26046","31.12400","0.00000","1.26938","0.20022"
"1.26938","103.95152","1.25978","31.30400","0.00000","1.26938","0.20022"
"1.26938","103.91673","1.25935","31.48400","0.00000","1.26938","0.20022"
"1.26938","103.85256","1.25858","31.66400","0.00000","1.26938","0.20022"
"1.26938","103.82722","1.25827","31.84400","0.00000","1.26938","0.20022"
"1.26938","103.79090","1.25783","32.02400","0.00000","1.26938","0.20022"
"1.26938","103.75074","1.25734","32.20400","0.00000","1.26938","0.20022"
"1.26938","103.71712","1.25694","32.38400","0.00000","1.26938","0.20022"
"1.26938","103.66833","1.25634","32.56400","0.00000","1.26938","0.20022"
"1.26938","103.62789","1.25585","32.74400","0.00000","1.26938","0.20022"
"1.26938","103.56975","1.25515","32.92400","0.00000","1.26938","0.20022"
"1.26938","103.54110","1.25480","33.10400","0.00000","1.26938","0.20022"
"1.26938","103.49921","1.25429","33.28400","0.00000","1.26938","0.20022"
"1.26938","103.45136","1.25371","33.46400","0.00000","1.26938","0.20022"
"1.26938","103.41750","1.25330","33.64400","0.00000","1.26938","0.20022"
"1.26938","103.37357","1.25277","33.82400","0.00000","1.26938","0.20022"
"1.26938","103.33380","1.25229","34.00400","0.00000","1.26938","0.20022"
"1.26938","103.29656","1.25184","34.18400","0.00000","1.26938","0.20022"
"1.26938","103.24516","1.25122","34.36400","0.00000","1.26938","0.20022"
"1.26938","103.21368","1.25083","34.54400","0.00000","1.26938","0.20022"
"1.26938","103.17786","1.25040","34.72400","0.00000","1.26938","0.20022"
"1.26938","103.13956","1.24994","34.90400","0.00000","1.26938","0.20022"
"1.26938","103.11253","1.24961","35.08400","0.00000","1.26938","0.20022"
"1.26938","103.06097","1.24898","35.26400","0.00000","1.26938","0.20022"
"1.26938","103.01421","1.24842","35.44400","0.00000","1.26938","0.20022"
"1.26938","102.97551","1.24795","35.62400","0.00000","1.26938","0.20022"
"1.26938","102.95078","1.24765","35.80400","0.00000","1.26938","0.20022"
"1.26938","102.92110","1.24729","35.98400","0.00000","1.26938","0.20022"
"1.26938","102.88426","1.24684","36.16400","0.00000","1.26938","0.20022"
"1.26938","102.85900","1.24654","36.34400","0.00000","1.26938","0.20022"
"1.26938","102.79565","1.24577","36.52400","0.00000","1.26938","0.20022"
"1.26938","102.75603","1.24529","36.70400","0.00000","1.26938","0.20022"
"1.26938","102.72220","1.24488","36.88400","0.00000","1.26938","0.20022"
"1.26938","102.70626","1.24468","37.06400","0.00000","1.26938","0.20022"
"1.26938","102.68008","1.24437","37.24400","0.00000","1.26938","0.20022"
"1.26938","102.64695","1.24397","37.42400","0.00000","1.26938","0.20022"
"1.26938","102.58881","1.24326","37.60400","0.00000","1.26938","0.20022"
"1.26938","102.53848","1.24265","37.78400","0.00000","1.26938","0.20022"
"1.26938","102.49027","1.24207","37.96400","0.00000","1.26938","0.20022"
"1.26938","102.45931","1.24169","38.14400","0.00000","1.26938","0.20022"
"1.26938","102.43319","1.24138","38.32400","0.00000","1.26938","0.20022"
"1.26938","102.38980","1.24085","38.50400","0.00000","1.26938","0.20022"
"1.26938","102.36569","1.24056","38.68400","0.00000","1.26938","0.20022"
"1.26938","102.34362","1.24029","38.86400","0.00000","1.26938","0.20022"
"1.26938","102.32088","1.24001","39.04400","0.00000","1.26938","0.20022"
"1.26938","102.28821","1.23962","39.22400","0.00000","1.26938","0.20022"
"1.26938","102.25178","1.23918","39.40400","0.00000","1.26938","0.20022"
"1.26938","102.20123","1.23856","39.58400","0.00000","1.26938","0.20022"
"1.26938","102.16675","1.23815","39.76400","0.00000","1.26938","0.20022"
"1.26938","102.12986","1.23770","39.94400","0.00000","1.26938","0.20022"
"1.26938","102.10364","1.23738","40.12400","0.00000","1.26938","0.20022"
"1.26938","102.07465","1.23703","40.30400","0.00000","1.26938","0.20022"
"1.26938","102.04069","1.23662","40.48400","0.00000","1.26938","0.20022"
"1.26938","102.00572","1.23619","40.66400","0.00000","1.26938","0.20022"
"1.26938","101.97398","1.23581","40.84400","0.00000","1.26938","0.20022"
"1.26938","101.94231","1.23543","41.02400","0.00000","1.26938","0.20022"
"1.26938","101.91491","1.23509","41.20400","0.00000","1.26938","0.20022"
"1.26938","101.88457","1.23473","41.38400","0.00000","1.26938","0.20022"
"1.26938","101.85536","1.23437","41.56400","0.00000","1.26938","0.20022"
"1.26938","101.82173","1.23397","41.74400","0.00000","1.26938","0.20022"
"1.26938","101.79206","1.23361","41.92400","0.00000","1.26938","0.20022"
"1.26938","101.75496","1.23316","42.10400","0.00000","1.26938","0.20022"
"1.26938","101.72737","1.23282","42.28400","0.00000","1.26938","0.20022"
"1.26938","101.70931","1.23260","42.46400","0.00000","1.26938","0.20022"
"1.26938","101.66979","1.23212","42.64400","0.00000","1.26938","0.20022"
"1.26938","101.64062","1.23177","42.82400","0.00000","1.26938","0.20022"
"1.26938","101.63598","1.23171","43.00400","0.00000","1.26938","0.20022"
"1.26938","101.58550","1.23110","43.18400","0.00000","1.26938","0.20022"
"1.26938","101.54556","1.23062","43.36400","0.00000","1.26938","0.20022"
"1.26938","101.50481","1.23012","43.54400","0.00000","1.26938","0.20022"
"1.26938","101.46696","1.22967","43.72400","0.00000","1.26938","0.20022"
"1.26938","101.44538","1.22940","43.90400","0.00000","1.26938","0.20022"
"1.26938","101.43185","1.22924","44.08400","0.00000","1.26938","0.20022"
"1.26938","101.39507","1.22879","44.26400","0.00000","1.26938","0.20022"
"1.26938","101.36942","1.22848","44.44400","0.00000","1.26938","0.20022"
"1.26938","101.34470","1.22818","44.62400","0.00000","1.26938","0.20022"
"1.26938","101.31558","1.22783","44.80400","0.00000","1.26938","0.20022"
"1.26938","101.28732","1.22749","44.98400","0.00000","1.26938","0.20022"
"1.26938","101.24716","1.22700","45.16400","0.00000","1.26938","0.20022"
"1.26938","101.21838","1.22665","45.34400","0.00000","1.26938","0.20022"
"1.26938","101.19547","1.22638","45.52400","0.00000","1.26938","0.20022"
"1.26938","101.16447","1.22600","45.70400","0.00000","1.26938","0.20022"
"1.26938","101.15105","1.22584","45.88400","0.00000","1.26938","0.20022"
"1.26938","101.12188","1.22548","46.06400","0.00000","1.26938","0.20022"
"1.26938","101.09595","1.22517","46.24400","0.00000","1.26938","0.20022"
"1.26938","101.05968","1.22473","46.42400","0.00000","1.26938","0.20022"
"1.26938","101.03278","1.22440","46.60400","0.00000","1.26938","0.20022"
"1.26938","101.00424","1.22406","46.78400","0.00000","1.26938","0.20022"
"1.26938","100.97730","1.22373","46.96400","0.00000","1.26938","0.20022"
"1.26938","100.95219","1.22343","47.14400","0.00000","1.26938","0.20022"
"1.26938","100.92941","1.22315","47.32400","0.00000","1.26938","0.20022"
"1.26938","100.90412","1.22284","47.50400","0.00000","1.26938","0.20022"
"1.26938","100.87009","1.22243","47.68400","0.00000","1.26938","0.20022"
"1.26938","100.85151","1.22221","47.86400","0.00000","1.26938","0.20022"
"1.26938","100.81613","1.22178","48.04400","0.00000","1.26938","0.20022"
"1.26938","100.79551","1.22153","48.22400","0.00000","1.26938","0.20022"
"1.26938","100.76307","1.22114","48.40400","0.00000","1.26938","0.20022"
"1.26938","100.73698","1.22082","48.58400","0.00000","1.26938","0.20022"
"1.26938","100.71703","1.22058","48.76400","0.00000","1.26938","0.20022"
"1.26938","100.68821","1.22023","48.94400","0.00000","1.26938","0.20022"
"1.26938","100.67082","1.22002","49.12400","0.00000","1.26938","0.20022"
"1.26938","100.64378","1.21969","49.30400","0.00000","1.26938","0.20022"
"1.26938","100.61224","1.21931","49.48400","0.00000","1.26938","0.20022"
"1.26938","100.58471","1.21897","49.66400","0.00000","1.26938","0.20022"
"1.26938","100.55637","1.21863","49.84400","0.00000","1.26938","0.20022"
"1.26938","100.54118","1.21845","50.02400","0.00000","1.26938","0.20022"
"1.26938","100.50936","1.21806","50.20400","0.00000","1.26938","0.20022"
"1.26938","100.48804","1.21780","50.38400","0.00000","1.26938","0.20022"
"1.26938","100.46819","1.21756","50.56400","0.00000","1.26938","0.20022"
"1.26938","100.44006","1.21722","50.74400","0.00000","1.26938","0.20022"
"1.26938","100.42171","1.21700","50.92400","0.00000","1.26938","0.20022"
"1.26938","100.39737","1.21670","51.10400","0.00000","1.26938","0.20022"
"1.26938","100.37125","1.21639","51.28400","0.00000","1.26938","0.20022"
"1.26938","100.34379","1.21605","51.46400","0.00000","1.26938","0.20022"
"1.26938","100.31845","1.21575","51.64400","0.00000","1.26938","0.20022"
"1.26938","100.30155","1.21554","51.82400","0.00000","1.26938","0.20022"
"1.26938","100.27080","1.21517","52.00400","0.00000","1.26938","0.20022"
"1.26938","100.25082","1.21493","52.18400","0.00000","1.26938","0.20022"
"1.26938","100.22220","1.21458","52.36400","0.00000","1.26938","0.20022"
"1.26938","100.20707","1.21440","52.54400","0.00000","1.26938","0.20022"
"1.26938","100.17665","1.21403","52.72400","0.00000","1.26938","0.20022"
"1.26938","100.15826","1.21381","52.90400","0.00000","1.26938","0.20022"
"1.26938","100.12506","1.21340","53.08400","0.00000","1.26938","0.20022"
"1.26938","100.10905","1.21321","53.26400","0.00000","1.26938","0.20022"
"1.26938","100.09011","1.21298","53.44400","0.00000","1.26938","0.20022"
"1.26938","100.05837","1.21260","53.62400","0.00000","1.26938","0.20022"
"1.26938","100.04263","1.21240","53.80400","0.00000","1.26938","0.20022"
"1.26938","100.02089","1.21214","53.98400","0.00000","1.26938","0.20022"
"1.26938","99.99923","1.21188","54.16400","0.00000","1.26938","0.20022"
"1.26938","99.97509","1.21159","54.34400","0.00000","1.26938","0.20022"
"1.26938","99.94563","1.21123","54.52400","0.00000","1.26938","0.20022"
"1.26938","99.92741","1.21101","54.70400","0.00000","1.26938","0.20022"
"1.26938","99.90754","1.21077","54.88400","0.00000","1.26938","0.20022"
"1.26938","99.87706","1.21040","55.06400","0.00000","1.26938","0.20022"
"1.26938","99.86211","1.21022","55.24400","0.00000","1.26938","0.20022"
"1.26938","99.83650","1.20991","55.42400","0.00000","1.26938","0.20022"
"1.26938","99.81857","1.20969","55.60400","0.00000","1.26938","0.20022"
"1.26938","99.80145","1.20948","55.78400","0.00000","1.26938","0.20022"
"1.26938","99.77338","1.20914","55.96400","0.00000","1.26938","0.20022"
"1.26938","99.75425","1.20891","56.14400","0.00000","1.26938","0.20022"
"1.26938","99.72593","1.20857","56.32400","0.00000","1.26938","0.20022"
"1.26938","99.71062","1.20838","56.50400","0.00000","1.26938","0.20022"
"1.26938","99.68671","1.20809","56.68400","0.00000","1.26938","0.20022"
"1.26938","99.67142","1.20791","56.86400","0.00000","1.26938","0.20022"
"1.26938","99.65558","1.20771","57.04400","0.00000","1.26938","0.20022"
"1.26938","99.63354","1.20745","57.22400","0.00000","1.26938","0.20022"
"1.26938","99.61178","1.20718","57.40400","0.00000","1.26938","0.20022"
"1.26938","99.57989","1.20680","57.58400","0.00000","1.26938","0.20022"
"1.26938","99.55717","1.20652","57.76400","0.00000","1.26938","0.20022"
"1.26938","99.54385","1.20636","57.94400","0.00000","1.26938","0.20022"
"1.26938","99.52058","1.20608","58.12400","0.00000","1.26938","0.20022"
"1.26938","99.49821","1.20581","58.30400","0.00000","1.26938","0.20022"
"1.26938","99.48199","1.20561","58.48400","0.00000","1.26938","0.20022"
"1.26938","99.46338","1.20538","58.66400","0.00000","1.26938","0.20022"
"1.26938","99.43145","1.20500","58.84400","0.00000","1.26938","0.20022"
"1.26938","99.41891","1.20485","59.02400","0.00000","1.26938","0.20022"
"1.26938","99.40889","1.20472","59.20400","0.00000","1.26938","0.20022"
"1.26938","99.37632","1.20433","59.38400","0.00000","1.26938","0.20022"
"1.26938","99.35351","1.20405","59.56400","0.00000","1.26938","0.20022"
"1.26938","99.32851","1.20375","59.74400","0.00000","1.26938","0.20022"
"1.26938","99.31773","1.20362","59.92400","0.00000","1.26938","0.20022"
"1.26938","99.29872","1.20339","60.10400","0.00000","1.26938","0.20022"
"1.26938","99.27625","1.20312","60.28400","0.00000","1.26938","0.20022"
"1.26938","99.26369","1.20296","60.46400","0.00000","1.26938","0.20022"
"1.26938","99.23772","1.20265","60.64400","0.00000","1.26938","0.20022"
"1.26938","99.22514","1.20250","60.82400","0.00000","1.26938","0.20022"
"1.26938","99.20002","1.20219","61.00400","0.00000","1.26938","0.20022"
"1.26938","99.17440","1.20188","61.18400","0.00000","1.26938","0.20022"
"1.26938","99.16982","1.20183","61.36400","0.00000","1.26938","0.20022"
"1.26938","99.13876","1.20145","61.54400","0.00000","1.26938","0.20022"
"1.26938","99.11480","1.20116","61.72400","0.00000","1.26938","0.20022"
"1.26938","99.10282","1.20101","61.90400","0.00000","1.26938","0.20022"
"1.26938","99.08110","1.20075","62.08400","0.00000","1.26938","0.20022"
"1.26938","99.06908","1.20061","62.26400","0.00000","1.26938","0.20022"
"1.26938","99.05180","1.20040","62.44400","0.00000","1.26938","0.20022"
"1.26938","99.02069","1.20002","62.62400","0.00000","1.26938","0.20022"
"1.26938","99.00907","1.19988","62.80400","0.00000","1.26938","0.20022"
"1.26938","98.99126","1.19966","62.98400","0.00000","1.26938","0.20022"
"1.26938","98.97530","1.19947","63.16400","0.00000","1.26938","0.20022"
"1.26938","98.95528","1.19923","63.34400","0.00000","1.26938","0.20022"
"1.26938","98.93326","1.19896","63.52400","0.00000","1.26938","0.20022"
"1.26938","98.91219","1.19870","63.70400","0.00000","1.26938","0.20022"
"1.26938","98.89539","1.19850","63.88400","0.00000","1.26938","0.20022"
"1.26938","98.87818","1.19829","64.06400","0.00000","1.26938","0.20022"
"1.26938","98.86614","1.19815","64.24400","0.00000","1.26938","0.20022"
"1.26938","98.85205","1.19798","64.42400","0.00000","1.26938","0.20022"
"1.26938","98.82999","1.19771","64.60400","0.00000","1.26938","0.20022"
"1.26938","98.80373","1.19739","64.78400","0.00000","1.26938","0.20022"
"1.26938","98.77872","1.19709","64.96400","0.00000","1.26938","0.20022"
"1.26938","98.76628","1.19694","65.14400","0.00000","1.26938","0.20022"
"1.26938","98.74860","1.19672","65.32400","0.00000","1.26938","0.20022"
"1.26938","98.72986","1.19650","65.50400","0.00000","1.26938","0.20022"
"1.26938","98.71615","1.19633","65.68400","0.00000","1.26938","0.20022"
"1.26938","98.69687","1.19610","65.86400","0.00000","1.26938","0.20022"
"1.26938","98.68187","1.19591","66.04400","0.00000","1.26938","0.20022"
"1.26938","98.65799","1.19562","66.22400","0.00000","1.26938","0.20022"
"1.26938","98.65080","1.19554","66.40400","0.00000","1.26938","0.20022"
"1.26938","98.63180","1.19531","66.58400","0.00000","1.26938","0.20022"
"1.26938","98.60651","1.19500","66.76400","0.00000","1.26938","0.20022"
"1.26938","98.59650","1.19488","66.94400","0.00000","1.26938","0.20022"
"1.26938","98.57058","1.19456","67.12400","0.00000","1.26938","0.20022"
"1.26938","98.56403","1.19449","67.30400","0.00000","1.26938","0.20022"
"1.26938","98.53861","1.19418","67.48400","0.00000","1.26938","0.20022"
"1.26938","98.51673","1.19391","67.66400","0.00000","1.26938","0.20022"
"1.26938","98.50158","1.19373","67.84400","0.00000","1.26938","0.20022"
"1.26938","98.47630","1.19342","68.02400","0.00000","1.26938","0.20022"
"1.26938","98.46414","1.19327","68.20400","0.00000","1.26938","0.20022"
"1.26938","98.43871","1.19297","68.38400","0.00000","1.26938","0.20022"
"1.26938","98.43128","1.19288","68.56400","0.00000","1.26938","0.20022"
"1.26938","98.41465","1.19268","68.74400","0.00000","1.26938","0.20022"
"1.26938","98.39219","1.19240","68.92400","0.00000","1.26938","0.20022"
"1.26938","98.38084","1.19227","69.10400","0.00000","1.26938","0.20022"
"1.26938","98.36872","1.19212","69.28400","0.00000","1.26938","0.20022"
"1.26938","98.35551","1.19196","69.46400","0.00000","1.26938","0.20022"
"1.26938","98.32324","1.19157","69.64400","0.00000","1.26938","0.20022"
"1.26938","98.31884","1.19151","69.82400","0.00000","1.26938","0.20022"
"1.26938","98.30279","1.19132","70.00400","0.00000","1.26938","0.20022"
"1.26938","98.28361","1.19109","70.18400","0.00000","1.26938","0.20022"
"1.26938","98.26994","1.19092","70.36400","0.00000","1.26938","0.20022"
"1.26938","98.24974","1.19068","70.54400","0.00000","1.26938","0.20022"
"1.26938","98.23415","1.19049","70.72400","0.00000","1.26938","0.20022"
"1.26938","98.20744","1.19016","70.90400","0.00000","1.26938","0.20022"
"1.26938","98.20017","1.19008","71.08400","0.00000","1.26938","0.20022"
"1.26938","98.19180","1.18997","71.26400","0.00000","1.26938","0.20022"
"1.26938","98.16669","1.18967","71.44400","0.00000","1.26938","0.20022"
"1.26938","98.15395","1.18952","71.62400","0.00000","1.26938","0.20022"
"1.26938","98.13469","1.18928","71.80400","0.00000","1.26938","0.20022"
"1.26938","98.11956","1.18910","71.98400","0.00000","1.26938","0.20022"
"1.26938","98.10296","1.18890","72.16400","0.00000","1.26938","0.20022"
"1.26938","98.09357","1.18878","72.34400","0.00000","1.26938","0.20022"
"1.26938","98.07412","1.18855","72.52400","0.00000","1.26938","0.20022"
"1.26938","98.05128","1.18827","72.70400","0.00000","1.26938","0.20022"
"1.26938","98.03876","1.18812","72.88400","0.00000","1.26938","0.20022"
"1.26938","98.02428","1.18794","73.06400","0.00000","1.26938","0.20022"
"1.26938","98.00745","1.18774","73.24400","0.00000","1.26938","0.20022"
"1.26938","97.99404","1.18758","73.42400","0.00000","1.26938","0.20022"
"1.26938","97.97466","1.18734","73.60400","0.00000","1.26938","0.20022"
"1.26938","97.97283","1.18732","73.78400","0.00000","1.26938","0.20022"
"1.26938","97.94794","1.18702","73.96400","0.00000","1.26938","0.20022"
"1.26938","97.94180","1.18694","74.14400","0.00000","1.26938","0.20022"
"1.26938","97.91383","1.18661","74.32400","0.00000","1.26938","0.20022"
"1.26938","97.91009","1.18656","74.50400","0.00000","1.26938","0.20022"
"1.26938","97.88807","1.18629","74.68400","0.00000","1.26938","0.20022"
"1.26938","97.86790","1.18605","74.86400","0.00000","1.26938","0.20022"
"1.26938","97.86115","1.18597","75.04400","0.00000","1.26938","0.20022"
"1.26938","97.84186","1.18573","75.22400","0.00000","1.26938","0.20022"
"1.26938","97.82520","1.18553","75.40400","0.00000","1.26938","0.20022"
"1.26938","97.80818","1.18533","75.58400","0.00000","1.26938","0.20022"
"1.26938","97.79222","1.18513","75.76400","0.00000","1.26938","0.20022"
"1.26938","97.76929","1.18485","75.94400","0.00000","1.26938","0.20022"
"1.26938","97.76743","1.18483","76.12400","0.00000","1.26938","0.20022"
"1.26938","97.74760","1.18459","76.30400","0.00000","1.26938","0.20022"
"1.26938","97.73334","1.18442","76.48400","0.00000","1.26938","0.20022"
"1.26938","97.71972","1.18425","76.66400","0.00000","1.26938","0.20022"
"1.26938","97.70282","1.18405","76.84400","0.00000","1.26938","0.20022"
"1.26938","97.68699","1.18386","77.02400","0.00000","1.26938","0.20022"
"1.26938","97.68096","1.18378","77.20400","0.00000","1.26938","0.20022"
"1.26938","97.65591","1.18348","77.38400","0.00000","1.26938","0.20022"
"1.26938","97.65610","1.18348","77.56400","0.00000","1.26938","0.20022"
"1.26938","97.62653","1.18312","77.74400","0.00000","1.26938","0.20022"
"1.26938","97.61366","1.18297","77.92400","0.00000","1.26938","0.20022"
"1.26938","97.60883","1.18291","78.10400","0.00000","1.26938","0.20022"
"1.26938","97.58989","1.18268","78.28400","0.00000","1.26938","0.20022"
"1.26938","97.57226","1.18247","78.46400","0.00000","1.26938","0.20022"
"1.26938","97.55403","1.18225","78.64400","0.00000","1.26938","0.20022"
"1.26938","97.54429","1.18213","78.82400","0.00000","1.26938","0.20022"
"1.26938","97.52715","1.18192","79.00400","0.00000","1.26938","0.20022"
"1.26938","97.51859","1.18182","79.18400","0.00000","1.26938","0.20022"
"1.26938","97.50370","1.18164","79.36400","0.00000","1.26938","0.20022"
"1.26938","97.49104","1.18148","79.54400","0.00000","1.26938","0.20022"
"1.26938","97.48122","1.18136","79.72400","0.00000","1.26938","0.20022"
"1.26938","97.46588","1.18118","79.90400","0.00000","1.26938","0.20022"
"1.26938","97.44917","1.18097","80.08400","0.00000","1.26938","0.20022"
"1.26938","97.43394","1.18079","80.26400","0.00000","1.26938","0.20022"
"1.26938","97.42021","1.18062","80.44400","0.00000","1.26938","0.20022"
"1.26938","97.40034","1.18038","80.62400","0.00000","1.26938","0.20022"
"1.26938","97.38844","1.18024","80.80400","0.00000","1.26938","0.20022"
"1.26938","97.37443","1.18007","80.98400","0.00000","1.26938","0.20022"
"1.26938","97.36510","1.17996","81.16400","0.00000","1.26938","0.20022"
"1.26938","97.35020","1.17978","81.34400","0.00000","1.26938","0.20022"
"1.26938","97.34288","1.17969","81.52400","0.00000","1.26938","0.20022"
"1.26938","97.32410","1.17946","81.70400","0.00000","1.26938","0.20022"
"1.26938","97.30621","1.17924","81.88400","0.00000","1.26938","0.20022"
"1.26938","97.30051","1.17917","82.06400","0.00000","1.26938","0.20022"
"1.26938","97.28295","1.17896","82.24400","0.00000","1.26938","0.20022"
"1.26938","97.26172","1.17870","82.42400","0.00000","1.26938","0.20022"
"1.26938","97.26345","1.17872","82.60400","0.00000","1.26938","0.20022"
"1.26938","97.23317","1.17836","82.78400","0.00000","1.26938","0.20022"
"1.26938","97.22283","1.17823","82.96400","0.00000","1.26938","0.20022"
"1.26938","97.22363","1.17824","83.14400","0.00000","1.26938","0.20022"
"1.26938","97.20193","1.17798","83.32400","0.00000","1.26938","0.20022"
"1.26938","97.18093","1.17772","83.50400","0.00000","1.26938","0.20022"
"1.26938","97.16814","1.17757","83.68400","0.00000","1.26938","0.20022"
"1.26938","97.15594","1.17742","83.86400","0.00000","1.26938","0.20022"
"1.26938","97.14609","1.17730","84.04400","0.00000","1.26938","0.20022"
"1.26938","97.12656","1.17706","84.22400","0.00000","1.26938","0.20022"
"1.26938","97.11410","1.17691","84.40400","0.00000","1.26938","0.20022"
"1.26938","97.10477","1.17680","84.58400","0.00000","1.26938","0.20022"
"1.26938","97.09221","1.17665","84.76400","0.00000","1.26938","0.20022"
"1.26938","97.07915","1.17649","84.94400","0.00000","1.26938","0.20022"
"1.26938","97.05730","1.17623","85.12400","0.00000","1.26938","0.20022"
"1.26938","97.04649","1.17609","85.30400","0.00000","1.26938","0.20022"
"1.26938","97.03819","1.17599","85.48400","0.00000","1.26938","0.20022"
"1.26938","97.02344","1.17582","85.66400","0.00000","1.26938","0.20022"
"1.26938","97.01005","1.17565","85.84400","0.00000","1.26938","0.20022"
"1.26938","96.99592","1.17548","86.02400","0.00000","1.26938","0.20022"
"1.26938","96.98511","1.17535","86.20400","0.00000","1.26938","0.20022"
"1.26938","96.96608","1.17512","86.38400","0.00000","1.26938","0.20022"
"1.26938","96.95419","1.17498","86.56400","0.00000","1.26938","0.20022"
"1.26938","96.94228","1.17483","86.74400","0.00000","1.26938","0.20022"
"1.26938","96.93417","1.17473","86.92400","0.00000","1.26938","0.20022"
"1.26938","96.92466","1.17462","87.10400","0.00000","1.26938","0.20022"
"1.26938","96.89506","1.17426","87.28400","0.00000","1.26938","0.20022"
"1.26938","96.88927","1.17419","87.46400","0.00000","1.26938","0.20022"
"1.26938","96.87677","1.17404","87.64400","0.00000","1.26938","0.20022"
"1.26938","96.86845","1.17394","87.82400","0.00000","1.26938","0.20022"
"1.26938","96.84809","1.17369","88.00400","0.00000","1.26938","0.20022"
"1.26938","96.84255","1.17362","88.18400","0.00000","1.26938","0.20022"
"1.26938","96.82861","1.17345","88.36400","0.00000","1.26938","0.20022"
"1.26938","96.80939","1.17322","88.54400","0.00000","1.26938","0.20022"
"1.26938","96.80133","1.17312","88.72400","0.00000","1.26938","0.20022"
"1.26938","96.78468","1.17292","88.90400","0.00000","1.26938","0.20022"
"1.26938","96.78223","1.17289","89.08400","0.00000","1.26938","0.20022"
"1.26938","96.76537","1.17269","89.26400","0.00000","1.26938","0.20022"
"1.26938","96.75478","1.17256","89.44400","0.00000","1.26938","0.20022"
"1.26938","96.74503","1.17244","89.62400","0.00000","1.26938","0.20022"
"1.26938","96.72610","1.17221","89.80400","0.00000","1.26938","0.20022"
"1.26938","96.71576","1.17209","89.98400","0.00000","1.26938","0.20022"
"1.26938","96.69939","1.17189","90.16400","0.00000","1.26938","0.20022"
"1.26938","96.69189","1.17180","90.34400","0.00000","1.26938","0.20022"
"1.26938","96.68333","1.17169","90.52400","0.00000","1.26938","0.20022"
"1.26938","96.67290","1.17157","90.70400","0.00000","1.26938","0.20022"
"1.26938","96.66110","1.17142","90.88400","0.00000","1.26938","0.20022"
"1.26938","96.63982","1.17117","91.06400","0.00000","1.26938","0.20022"
"1.26938","96.62759","1.17102","91.24400","0.00000","1.26938","0.20022"
"1.26938","96.61563","1.17087","91.42400","0.00000","1.26938","0.20022"
"1.26938","96.59608","1.17064","91.60400","0.00000","1.26938","0.20022"
"1.26938","96.58601","1.17051","91.78400","0.00000","1.26938","0.20022"
"1.26938","96.58306","1.17048","91.96400","0.00000","1.26938","0.20022"
"1.26938","96.56710","1.17028","92.14400","0.00000","1.26938","0.20022"
"1.26938","96.56555","1.17027","92.32400","0.00000","1.26938","0.20022"
"1.26938","96.54342","1.17000","92.50400","0.00000","1.26938","0.20022"
"1.26938","96.53483","1.16989","92.68400","0.00000","1.26938","0.20022"
"1.26938","96.52422","1.16977","92.86400","0.00000","1.26938","0.20022"
"1.26938","96.50372","1.16952","93.04400","0.00000","1.26938","0.20022"
"1.26938","96.50513","1.16953","93.22400","0.00000","1.26938","0.20022"
"1.26938","96.49097","1.16936","93.40400","0.00000","1.26938","0.20022"
"1.26938","96.47843","1.16921","93.58400","0.00000","1.26938","0.20022"
"1.26938","96.45788","1.16896","93.76400","0.00000","1.26938","0.20022"
"1.26938","96.44604","1.16882","93.94400","0.00000","1.26938","0.20022"
"1.26938","96.44240","1.16877","94.12400","0.00000","1.26938","0.20022"
"1.26938","96.43576","1.16869","94.30400","0.00000","1.26938","0.20022"
"1.26938","96.41891","1.16849","94.48400","0.00000","1.26938","0.20022"
"1.26938","96.41119","1.16840","94.66400","0.00000","1.26938","0.20022"
"1.26938","96.39457","1.16819","94.84400","0.00000","1.26938","0.20022"
"1.26938","96.38870","1.16812","95.02400","0.00000","1.26938","0.20022"
"1.26938","96.37240","1.16793","95.20400","0.00000","1.26938","0.20022"
"1.26938","96.36559","1.16784","95.38400","0.00000","1.26938","0.20022"
"1.26938","96.35147","1.16767","95.56400","0.00000","1.26938","0.20022"
"1.26938","96.33244","1.16744","95.74400","0.00000","1.26938","0.20022"
"1.26938","96.33028","1.16741","95.92400","0.00000","1.26938","0.20022"
"1.26938","96.31396","1.16722","96.10400","0.00000","1.26938","0.20022"
"1.26938","96.31055","1.16718","96.28400","0.00000","1.26938","0.20022"
"1.26938","96.29415","1.16698","96.46400","0.00000","1.26938","0.20022"
"1.26938","96.28217","1.16683","96.64400","0.00000","1.26938","0.20022"
"1.26938","96.27022","1.16669","96.82400","0.00000","1.26938","0.20022"
"1.26938","96.25917","1.16655","97.00400","0.00000","1.26938","0.20022"
"1.26938","96.25296","1.16648","97.18400","0.00000","1.26938","0.20022"
"1.26938","96.24244","1.16635","97.36400","0.00000","1.26938","0.20022"
"1.26938","96.22509","1.16614","97.54400","0.00000","1.26938","0.20022"
"1.26938","96.21474","1.16601","97.72400","0.00000","1.26938","0.20022"
"1.26938","96.20445","1.16589","97.90400","0.00000","1.26938","0.20022"
"1.26938","96.19276","1.16575","98.08400","0.00000","1.26938","0.20022"
"1.26938","96.18458","1.16565","98.26400","0.00000","1.26938","0.20022"
"1.26938","96.17026","1.16548","98.44400","0.00000","1.26938","0.20022"
"1.26938","96.16331","1.16539","98.62400","0.00000","1.26938","0.20022"
"1.26938","96.15244","1.16526","98.80400","0.00000","1.26938","0.20022"
"1.26938","96.13472","1.16504","98.98400","0.00000","1.26938","0.20022"
"1.26938","96.13251","1.16502","99.16400","0.00000","1.26938","0.20022"
"1.26938","96.12147","1.16488","99.34400","0.00000","1.26938","0.20022"
"1.26938","96.11031","1.16475","99.52400","0.00000","1.26938","0.20022"
"1.26938","96.09284","1.16454","99.70400","0.00000","1.26938","0.20022"
"1.26938","96.08625","1.16446","99.88400","0.00000","1.26938","0.20022"
"1.26938","96.07297","1.16430","100.06400","0.00000","1.26938","0.20022"
"1.26938","96.05964","1.16413","100.24400","0.00000","1.26938","0.20022"
"1.26938","96.04946","1.16401","100.42400","0.00000","1.26938","0.20022"
"1.26938","96.04188","1.16392","100.60400","0.00000","1.26938","0.20022"
"1.26938","96.02577","1.16372","100.78400","0.00000","1.26938","0.20022"
"1.26938","96.02270","1.16369","100.96400","0.00000","1.26938","0.20022"
"1.26938","96.00813","1.16351","101.14400","0.00000","1.26938","0.20022"
"1.26938","95.99323","1.16333","101.32400","0.00000","1.26938","0.20022"
"1.26938","95.98421","1.16322","101.50400","0.00000","1.26938","0.20022"
"1.26938","95.97334","1.16309","101.68400","0.00000","1.26938","0.20022"
"1.26938","95.96853","1.16303","101.86400","0.00000","1.26938","0.20022"
"1.26938","95.96210","1.16295","102.04400","0.00000","1.26938","0.20022"
"1.26938","95.94538","1.16275","102.22400","0.00000","1.26938","0.20022"
"1.26938","95.93356","1.16261","102.40400","0.00000","1.26938","0.20022"
"1.26938","95.92487","1.16250","102.58400","0.00000","1.26938","0.20022"
"1.26938","95.90991","1.16232","102.76400","0.00000","1.26938","0.20022"
"1.26938","95.90311","1.16224","102.94400","0.00000","1.26938","0.20022"
"1.26938","95.89320","1.16212","103.12400","0.00000","1.26938","0.20022"
"1.26938","95.88470","1.16201","103.30400","0.00000","1.26938","0.20022"
"1.26938","95.86197","1.16174","103.48400","0.00000","1.26938","0.20022"
"1.26938","95.86138","1.16173","103.66400","0.00000","1.26938","0.20022"
"1.26938","95.85549","1.16166","103.84400","0.00000","1.26938","0.20022"
"1.26938","95.84042","1.16148","104.02400","0.00000","1.26938","0.20022"
"1.26938","95.82473","1.16129","104.20400","0.00000","1.26938","0.20022"
"1.26938","95.82391","1.16128","104.38400","0.00000","1.26938","0.20022"
"1.26938","95.80959","1.16110","104.56400","0.00000","1.26938","0.20022"
"1.26938","95.81052","1.16112","104.74400","0.00000","1.26938","0.20022"
"1.26938","95.78804","1.16084","104.92400","0.00000","1.26938","0.20022"
"1.26938","95.77927","1.16074","105.10400","0.00000","1.26938","0.20022"
"1.26938","95.76199","1.16053","105.28400","0.00000","1.26938","0.20022"
"1.26938","95.75860","1.16049","105.46400","0.00000","1.26938","0.20022"
"1.26938","95.75045","1.16039","105.64400","0.00000","1.26938","0.20022"
"1.26938","95.74049","1.16027","105.82400","0.00000","1.26938","0.20022"
"1.26938","95.71887","1.16001","106.00400","0.00000","1.26938","0.20022"
"1.26938","95.70740","1.15987","106.18400","0.00000","1.26938","0.20022"
"1.26938","95.70129","1.15979","106.36400","0.00000","1.26938","0.20022"
"1.26938","95.69153","1.15967","106.54400","0.00000","1.26938","0.20022"
"1.26938","95.67921","1.15952","106.72400","0.00000","1.26938","0.20022"
"1.26938","95.67686","1.15950","106.90400","0.00000","1.26938","0.20022"
"1.26938","95.66282","1.15933","107.08400","0.00000","1.26938","0.20022"
"1.26938","95.66932","1.15940","107.26400","0.00000","1.26938","0.20022"
"1.26938","95.64703","1.15913","107.44400","0.00000","1.26938","0.20022"
"1.26938","95.63718","1.15902","107.62400","0.00000","1.26938","0.20022"
"1.26938","95.63256","1.15896","107.80400","0.00000","1.26938","0.20022"
"1.26938","95.61970","1.15880","107.98400","0.00000","1.26938","0.20022"
"1.26938","95.61053","1.15869","108.16400","0.00000","1.26938","0.20022"
"1.26938","95.59525","1.15851","108.34400","0.00000","1.26938","0.20022"
"1.26938","95.58231","1.15835","108.52400","0.00000","1.26938","0.20022"
"1.26938","95.57597","1.15827","108.70400","0.00000","1.26938","0.20022"
"1.26938","95.57001","1.15820","108.88400","0.00000","1.26938","0.20022"
"1.26938","95.55612","1.15803","109.06400","0.00000","1.26938","0.20022"
"1.26938","95.55615","1.15803","109.24400","0.00000","1.26938","0.20022"
"1.26938","95.54585","1.15791","109.42400","0.00000","1.26938","0.20022"
"1.26938","95.52424","1.15765","109.60400","0.00000","1.26938","0.20022"
"1.26938","95.52489","1.15765","109.78400","0.00000","1.26938","0.20022"
"1.26938","95.51410","1.15752","109.96400","0.00000","1.26938","0.20022"
"1.26938","95.50471","1.15741","110.14400","0.00000","1.26938","0.20022"
"1.26938","95.49097","1.15724","110.32400","0.00000","1.26938","0.20022"
"1.26938","95.47858","1.15709","110.50400","0.00000","1.26938","0.20022"
"1.26938","95.47276","1.15702","110.68400","0.00000","1.26938","0.20022"
"1.26938","95.46697","1.15695","110.86400","0.00000","1.26938","0.20022"
"1.26938","95.45695","1.15683","111.04400","0.00000","1.26938","0.20022"
"1.26938","95.44402","1.15667","111.22400","0.00000","1.26938","0.20022"
"1.26938","95.42614","1.15646","111.40400","0.00000","1.26938","0.20022"
"1.26938","95.43027","1.15651","111.58400","0.00000","1.26938","0.20022"
"1.26938","95.41148","1.15628","111.76400","0.00000","1.26938","0.20022"
"1.26938","95.40787","1.15624","111.94400","0.00000","1.26938","0.20022"
"1.26938","95.39499","1.15608","112.12400","0.00000","1.26938","0.20022"
"1.26938","95.38058","1.15591","112.30400","0.00000","1.26938","0.20022"
"1.26938","95.38078","1.15591","112.48400","0.00000","1.26938","0.20022"
"1.26938","95.37070","1.15579","112.66400","0.00000","1.26938","0.20022"
"1.26938","95.36649","1.15573","112.84400","0.00000","1.26938","0.20022"
"1.26938","95.34019","1.15542","113.02400","0.00000","1.26938","0.20022"
"1.26938","95.33657","1.15537","113.20400","0.00000","1.26938","0.20022"
"1.26938","95.32504","1.15523","113.38400","0.00000","1.26938","0.20022"
"1.26938","95.32288","1.15521","113.56400","0.00000","1.26938","0.20022"
"1.26938","95.30270","1.15496","113.74400","0.00000","1.26938","0.20022"
"1.26938","95.29462","1.15486","113.92400","0.00000","1.26938","0.20022"
"1.26938","95.28696","1.15477","114.10400","0.00000","1.26938","0.20022"
"1.26938","95.28430","1.15474","114.28400","0.00000","1.26938","0.20022"
"1.26938","95.27698","1.15465","114.46400","0.00000","1.26938","0.20022"
"1.26938","95.26043","1.15445","114.64400","0.00000","1.26938","0.20022"
"1.26938","95.25141","1.15434","114.82400","0.00000","1.26938","0.20022"
"1.26938","95.23891","1.15419","115.00400","0.00000","1.26938","0.20022"
"1.26938","95.23923","1.15419","115.18400","0.00000","1.26938","0.20022"
"1.26938","95.22638","1.15404","115.36400","0.00000","1.26938","0.20022"
"1.26938","95.22031","1.15396","115.54400","0.00000","1.26938","0.20022"
"1.26938","95.20524","1.15378","115.72400","0.00000","1.26938","0.20022"
"1.26938","95.20210","1.15374","115.90400","0.00000","1.26938","0.20022"
"1.26938","95.18442","1.15353","116.08400","0.00000","1.26938","0.20022"
"1.26938","95.18241","1.15350","116.26400","0.00000","1.26938","0.20022"
"1.26938","95.16796","1.15333","116.44400","0.00000","1.26938","0.20022"
"1.26938","95.15701","1.15320","116.62400","0.00000","1.26938","0.20022"
"1.26938","95.14911","1.15310","116.80400","0.00000","1.26938","0.20022"
"1.26938","95.14236","1.15302","116.98400","0.00000","1.26938","0.20022"
"1.26938","95.13200","1.15289","117.16400","0.00000","1.26938","0.20022"
"1.26938","95.12702","1.15283","117.34400","0.00000","1.26938","0.20022"
"1.26938","95.11559","1.15269","117.52400","0.00000","1.26938","0.20022"
"1.26938","95.10798","1.15260","117.70400","0.00000","1.26938","0.20022"
"1.26938","95.10315","1.15254","117.88400","0.00000","1.26938","0.20022"
"1.26938","95.09122","1.15240","118.06400","0.00000","1.26938","0.20022"
"1.26938","95.08641","1.15234","118.24400","0.00000","1.26938","0.20022"
"1.26938","95.07632","1.15222","118.42400","0.00000","1.26938","0.20022"
"1.26938","95.07114","1.15216","118.60400","0.00000","1.26938","0.20022"
"1.26938","95.05567","1.15197","118.78400","0.00000","1.26938","0.20022"
"1.26938","95.04258","1.15181","118.96400","0.00000","1.26938","0.20022"
"1.26938","95.03786","1.15175","119.14400","0.00000","1.26938","0.20022"
"1.26938","95.02782","1.15163","119.32400","0.00000","1.26938","0.20022"
"1.26938","95.01913","1.15153","119.50400","0.00000","1.26938","0.20022"
"1.26938","95.00648","1.15137","119.68400","0.00000","1.26938","0.20022"
"1.26938","94.99889","1.15128","119.86400","0.00000","1.26938","0.20022"
"1.26938","94.98710","1.15114","120.04400","0.00000","1.26938","0.20022"
"1.26938","94.98357","1.15109","120.22400","0.00000","1.26938","0.20022"
"1.26938","94.97443","1.15098","120.40400","0.00000","1.26938","0.20022"
"1.26938","94.96844","1.15091","120.58400","0.00000","1.26938","0.20022"
"1.26938","94.95282","1.15072","120.76400","0.00000","1.26938","0.20022"
"1.26938","94.95793","1.15078","120.94400","0.00000","1.26938","0.20022"
"1.26938","94.93665","1.15053","121.12400","0.00000","1.26938","0.20022"
"1.26938","94.93784","1.15054","121.30400","0.00000","1.26938","0.20022"
"1.26938","94.92776","1.15042","121.48400","0.00000","1.26938","0.20022"
"1.26938","94.91855","1.15031","121.66400","0.00000","1.26938","0.20022"
"1.26938","94.90965","1.15020","121.84400","0.00000","1.26938","0.20022"
"1.26938","94.89901","1.15007","122.02400","0.00000","1.26938","0.20022"
"1.26938","94.89457","1.15002","122.20400","0.00000","1.26938","0.20022"
"1.26938","94.88536","1.14990","122.38400","0.00000","1.26938","0.20022"
"1.26938","94.86787","1.14969","122.56400","0.00000","1.26938","0.20022"
"1.26938","94.86596","1.14967","122.74400","0.00000","1.26938","0.20022"
"1.26938","94.86069","1.14961","122.92400","0.00000","1.26938","0.20022"
"1.26938","94.84366","1.14940","123.10400","0.00000","1.26938","0.20022"
"1.26938","94.83968","1.14935","123.17400","0.00000","1.26938","0.20022"